Workbook

Sheet Recommendations
B2: Recommendations: model-weighted long/short portfolio (100% gross)
B5: Summary | H5: How the weights are set
C6: Long book | F6: 0.6 | H6: Universe: the 168 models with a valuation (DCF or rNPV). Net-cash and no-data tickers are left out.
C7: Short book | F7: -0.4 | H7: Liquidity: price at least $5 and market cap at least $1B, so micro-caps and penny stocks can't drive the book.
C8: Gross exposure | F8: 1 | H8: Signal: long if upside is +15% or more, short if -15% or less; upside clipped to +100% / -60%.
C9: Net exposure | F9: 0.2 | H9: Score = upside × model confidence × size factor. Confidence: reviewed or full DCF 1.0, rNPV 0.7, basic DCF 0.5, basic DCF with an operating loss today 0.25.
C10: Long positions | F10: 16 | H10: Size factor rises from 0.25 at $1B to 1.0 at $100B+ (log scale).
C11: Short positions | F11: 28 | H11: Books: 60% long / 40% short. Caps: 8% for $50B+, 6% for $10–50B, 4% for $3–10B, 2% for $1–3B; positions under 0.5% are dropped.
C12: Weighted upside, longs | F12: 0.42585775 | H12: Basic DCFs use GAAP margins and no pipeline, so they lean negative for acquisitive big pharma; that's why they get half weight.
C13: Weighted upside, shorts | F13: -0.50604108
C14: Valuation models in universe | F14: 168
C15: Positions after filters | F15: 44
B17: # | C17: Ticker | D17: Company | E17: Side | F17: Weight | G17: Model | H17: Value / share | I17: Price | J17: Upside | K17: Mkt cap ($B) | L17: Confidence | M17: Size factor | N17: Cap | O17: Score | P17: Live upside | Q17: Event | R17: Note(s)
C18: Longs
B19: 1 | C19: SNY | D19: Sanofi SA | E19: Long | F19: 0.08 | G19: Reviewed DCF | H19: 66.822469 | I19: 41.4 | J19: 0.61406931 | K19: 100.96856 | L19: 1 | M19: 1 | N19: 0.08 | O19: 0.61406931 | P19: =IFERROR(INDEX(Pharma!$K$3:$K$677,MATCH($C19,Pharma!$B$3:$B$677,0)),"") | Q19: =IFERROR(IF(INDEX(Pharma!$M$3:$M$677,MATCH($C19,Pharma!$B$3:$B$677,0))="","",INDEX(Pharma!$M$3:$M$677,MATCH($C19,Pharma!$B$3:$B$677,0))),"") | R19: =IFERROR(T(INDEX(Pharma!$N$3:$N$677,MATCH($C19,Pharma!$B$3:$B$677,0))),"")
B20: 2 | C20: GSK | D20: GSK plc | E20: Long | F20: 0.08 | G20: Reviewed DCF | H20: 66.386169 | I20: 50.645 | J20: 0.31081388 | K20: 109.27786 | L20: 1 | M20: 1 | N20: 0.08 | O20: 0.31081388 | P20: =IFERROR(INDEX(Pharma!$K$3:$K$677,MATCH($C20,Pharma!$B$3:$B$677,0)),"") | Q20: =IFERROR(IF(INDEX(Pharma!$M$3:$M$677,MATCH($C20,Pharma!$B$3:$B$677,0))="","",INDEX(Pharma!$M$3:$M$677,MATCH($C20,Pharma!$B$3:$B$677,0))),"") | R20: =IFERROR(T(INDEX(Pharma!$N$3:$N$677,MATCH($C20,Pharma!$B$3:$B$677,0))),"")
B21: 3 | C21: ZTS | D21: Zoetis Inc | E21: Long | F21: 0.06 | G21: Reviewed DCF | H21: 103.19817 | I21: 80.04 | J21: 0.28933251 | K21: 33.074417 | L21: 1 | M21: 0.81980957 | N21: 0.06 | O21: 0.23719756 | P21: =IFERROR(INDEX(Pharma!$K$3:$K$677,MATCH($C21,Pharma!$B$3:$B$677,0)),"") | Q21: =IFERROR(IF(INDEX(Pharma!$M$3:$M$677,MATCH($C21,Pharma!$B$3:$B$677,0))="","",INDEX(Pharma!$M$3:$M$677,MATCH($C21,Pharma!$B$3:$B$677,0))),"") | R21: =IFERROR(T(INDEX(Pharma!$N$3:$N$677,MATCH($C21,Pharma!$B$3:$B$677,0))),"")
B22: 4 | C22: NBIX | D22: Neurocrine Biosciences, Inc. | E22: Long | F22: 0.06 | G22: Reviewed DCF | H22: 166.52692 | I22: 142 | J22: 0.1727248 | K22: 14.434184 | L22: 1 | M22: 0.68477209 | N22: 0.06 | O22: 0.11827712 | P22: =IFERROR(INDEX(Pharma!$K$3:$K$677,MATCH($C22,Pharma!$B$3:$B$677,0)),"") | Q22: =IFERROR(IF(INDEX(Pharma!$M$3:$M$677,MATCH($C22,Pharma!$B$3:$B$677,0))="","",INDEX(Pharma!$M$3:$M$677,MATCH($C22,Pharma!$B$3:$B$677,0))),"") | R22: =IFERROR(T(INDEX(Pharma!$N$3:$N$677,MATCH($C22,Pharma!$B$3:$B$677,0))),"")
B23: 5 | C23: ALNY | D23: Alnylam Pharmaceuticals, Inc. | E23: Long | F23: 0.059529503 | G23: Basic DCF | H23: 288.29954 | I23: 230.71 | J23: 0.24961874 | K23: 30.871102 | L23: 0.5 | M23: 0.80858205 | N23: 0.06 | O23: 0.10091861 | P23: =IFERROR(INDEX(Pharma!$K$3:$K$677,MATCH($C23,Pharma!$B$3:$B$677,0)),"") | Q23: =IFERROR(IF(INDEX(Pharma!$M$3:$M$677,MATCH($C23,Pharma!$B$3:$B$677,0))="","",INDEX(Pharma!$M$3:$M$677,MATCH($C23,Pharma!$B$3:$B$677,0))),"") | R23: =IFERROR(T(INDEX(Pharma!$N$3:$N$677,MATCH($C23,Pharma!$B$3:$B$677,0))),"")
B24: 6 | C24: BMY | D24: Bristol-Myers Squibb Company | E24: Long | F24: 0.046981691 | G24: Basic DCF | H24: 71.545789 | I24: 61.715 | J24: 0.15929336 | K24: 126.06613 | L24: 0.5 | M24: 1 | N24: 0.08 | O24: 0.079646678 | P24: =IFERROR(INDEX(Pharma!$K$3:$K$677,MATCH($C24,Pharma!$B$3:$B$677,0)),"") | Q24: =IFERROR(IF(INDEX(Pharma!$M$3:$M$677,MATCH($C24,Pharma!$B$3:$B$677,0))="","",INDEX(Pharma!$M$3:$M$677,MATCH($C24,Pharma!$B$3:$B$677,0))),"") | R24: =IFERROR(T(INDEX(Pharma!$N$3:$N$677,MATCH($C24,Pharma!$B$3:$B$677,0))),"")
B25: 7 | C25: NVS | D25: Novartis AG | E25: Long | F25: 0.045098416 | G25: Basic DCF | H25: 177.13279 | I25: 153.64 | J25: 0.15290803 | K25: 293.16842 | L25: 0.5 | M25: 1 | N25: 0.08 | O25: 0.076454017 | P25: =IFERROR(INDEX(Pharma!$K$3:$K$677,MATCH($C25,Pharma!$B$3:$B$677,0)),"") | Q25: =IFERROR(IF(INDEX(Pharma!$M$3:$M$677,MATCH($C25,Pharma!$B$3:$B$677,0))="","",INDEX(Pharma!$M$3:$M$677,MATCH($C25,Pharma!$B$3:$B$677,0))),"") | R25: =IFERROR(T(INDEX(Pharma!$N$3:$N$677,MATCH($C25,Pharma!$B$3:$B$677,0))),"")
B26: 8 | C26: LEGN | D26: Legend Biotech Corporation | E26: Long | F26: 0.020913628 | G26: Basic DCF | H26: 24.938304 | I26: 19.01 | J26: 0.31185188 | K26: 3.5157699 | L26: 0.25 | M26: 0.45475767 | N26: 0.04 | O26: 0.035454258 | P26: =IFERROR(INDEX(Pharma!$K$3:$K$677,MATCH($C26,Pharma!$B$3:$B$677,0)),"") | Q26: =IFERROR(IF(INDEX(Pharma!$M$3:$M$677,MATCH($C26,Pharma!$B$3:$B$677,0))="","",INDEX(Pharma!$M$3:$M$677,MATCH($C26,Pharma!$B$3:$B$677,0))),"") | R26: =IFERROR(T(INDEX(Pharma!$N$3:$N$677,MATCH($C26,Pharma!$B$3:$B$677,0))),"")
B27: 9 | C27: BHC | D27: Bausch Health Companies Inc. | E27: Long | F27: 0.02 | G27: Basic DCF | H27: 10.70824 | I27: 6.415 | J27: 0.66925014 | K27: 2.3991494 | L27: 0.5 | M27: 0.39252149 | N27: 0.02 | O27: 0.13134753 | P27: =IFERROR(INDEX(Pharma!$K$3:$K$677,MATCH($C27,Pharma!$B$3:$B$677,0)),"") | Q27: =IFERROR(IF(INDEX(Pharma!$M$3:$M$677,MATCH($C27,Pharma!$B$3:$B$677,0))="","",INDEX(Pharma!$M$3:$M$677,MATCH($C27,Pharma!$B$3:$B$677,0))),"") | R27: =IFERROR(T(INDEX(Pharma!$N$3:$N$677,MATCH($C27,Pharma!$B$3:$B$677,0))),"")
B28: 10 | C28: HRMY | D28: Harmony Biosciences Holdings, Inc. | E28: Long | F28: 0.02 | G28: Basic DCF | H28: 89.024702 | I28: 38.7 | J28: 1.3003799 | K28: 2.2537484 | L28: 0.5 | M28: 0.38233954 | N28: 0.02 | O28: 0.19116977 | P28: =IFERROR(INDEX(Pharma!$K$3:$K$677,MATCH($C28,Pharma!$B$3:$B$677,0)),"") | Q28: =IFERROR(IF(INDEX(Pharma!$M$3:$M$677,MATCH($C28,Pharma!$B$3:$B$677,0))="","",INDEX(Pharma!$M$3:$M$677,MATCH($C28,Pharma!$B$3:$B$677,0))),"") | R28: =IFERROR(T(INDEX(Pharma!$N$3:$N$677,MATCH($C28,Pharma!$B$3:$B$677,0))),"")
B29: 11 | C29: ANIP | D29: ANI Pharmaceuticals, Inc. | E29: Long | F29: 0.02 | G29: Basic DCF | H29: 158.06464 | I29: 72.67 | J29: 1.1751017 | K29: 1.6692555 | L29: 0.5 | M29: 0.33344605 | N29: 0.02 | O29: 0.16672303 | P29: =IFERROR(INDEX(Pharma!$K$3:$K$677,MATCH($C29,Pharma!$B$3:$B$677,0)),"") | Q29: =IFERROR(IF(INDEX(Pharma!$M$3:$M$677,MATCH($C29,Pharma!$B$3:$B$677,0))="","",INDEX(Pharma!$M$3:$M$677,MATCH($C29,Pharma!$B$3:$B$677,0))),"") | R29: =IFERROR(T(INDEX(Pharma!$N$3:$N$677,MATCH($C29,Pharma!$B$3:$B$677,0))),"")
B30: 12 | C30: PAHC | D30: Phibro Animal Health Corp | E30: Long | F30: 0.02 | G30: Basic DCF | H30: 90.16968 | I30: 38.8 | J30: 1.3239608 | K30: 1.5753422 | L30: 0.5 | M30: 0.32401559 | N30: 0.02 | O30: 0.16200779 | P30: =IFERROR(INDEX(Pharma!$K$3:$K$677,MATCH($C30,Pharma!$B$3:$B$677,0)),"") | Q30: =IFERROR(IF(INDEX(Pharma!$M$3:$M$677,MATCH($C30,Pharma!$B$3:$B$677,0))="","",INDEX(Pharma!$M$3:$M$677,MATCH($C30,Pharma!$B$3:$B$677,0))),"") | R30: =IFERROR(T(INDEX(Pharma!$N$3:$N$677,MATCH($C30,Pharma!$B$3:$B$677,0))),"")
... B34: 16 | C34: AMPH | D34: Amphastar Pharmaceuticals, Inc. | E34: Long | F34: 0.012004745 | G34: Basic DCF | H34: 29.90882 | I34: 25.94 | J34: 0.15300001 | K34: 1.1034343 | L34: 0.5 | M34: 0.26602993 | N34: 0.02 | O34: 0.02035129 | P34: =IFERROR(INDEX(Pharma!$K$3:$K$677,MATCH($C34,Pharma!$B$3:$B$677,0)),"") | Q34: =IFERROR(IF(INDEX(Pharma!$M$3:$M$677,MATCH($C34,Pharma!$B$3:$B$677,0))="","",INDEX(Pharma!$M$3:$M$677,MATCH($C34,Pharma!$B$3:$B$677,0))),"") | R34: =IFERROR(T(INDEX(Pharma!$N$3:$N$677,MATCH($C34,Pharma!$B$3:$B$677,0))),"")
D35: Total longs | F35: 0.6
C37: Shorts
B38: 1 | C38: LLY | D38: Eli Lilly and Company | E38: Short | F38: -0.032757191 | G38: Full DCF | H38: 734.21433 | I38: 1286.835 | J38: -0.42944175 | K38: 1147.0295 | L38: 1 | M38: 1 | N38: 0.08 | O38: 0.42944175 | P38: =IFERROR(INDEX(Pharma!$K$3:$K$677,MATCH($C38,Pharma!$B$3:$B$677,0)),"") | Q38: =IFERROR(IF(INDEX(Pharma!$M$3:$M$677,MATCH($C38,Pharma!$B$3:$B$677,0))="","",INDEX(Pharma!$M$3:$M$677,MATCH($C38,Pharma!$B$3:$B$677,0))),"") | R38: =IFERROR(T(INDEX(Pharma!$N$3:$N$677,MATCH($C38,Pharma!$B$3:$B$677,0))),"")
B39: 2 | C39: HALO | D39: Halozyme Therapeutics, Inc. | E39: Short | F39: -0.024971861 | G39: Reviewed DCF | H39: 64.593781 | I39: 124.37 | J39: -0.48063214 | K39: 14.115746 | L39: 1 | M39: 0.68113894 | N39: 0.06 | O39: 0.32737726 | P39: =IFERROR(INDEX(Pharma!$K$3:$K$677,MATCH($C39,Pharma!$B$3:$B$677,0)),"") | Q39: =IFERROR(IF(INDEX(Pharma!$M$3:$M$677,MATCH($C39,Pharma!$B$3:$B$677,0))="","",INDEX(Pharma!$M$3:$M$677,MATCH($C39,Pharma!$B$3:$B$677,0))),"") | R39: =IFERROR(T(INDEX(Pharma!$N$3:$N$677,MATCH($C39,Pharma!$B$3:$B$677,0))),"")
B40: 3 | C40: SMMT | D40: Summit Therapeutics Inc. | E40: Short | F40: -0.021993661 | G40: PDUFA rNPV | H40: 5.475264 | I40: 16.09 | J40: -0.65971013 | K40: 14.588893 | L40: 0.7 | M40: 0.68650838 | N40: 0.06 | O40: 0.28833352 | P40: =IFERROR(INDEX(Pharma!$K$3:$K$677,MATCH($C40,Pharma!$B$3:$B$677,0)),"") | Q40: =IFERROR(IF(INDEX(Pharma!$M$3:$M$677,MATCH($C40,Pharma!$B$3:$B$677,0))="","",INDEX(Pharma!$M$3:$M$677,MATCH($C40,Pharma!$B$3:$B$677,0))),"") | R40: =IFERROR(T(INDEX(Pharma!$N$3:$N$677,MATCH($C40,Pharma!$B$3:$B$677,0))),"")
B41: 4 | C41: ABBV | D41: AbbVie Inc. | E41: Short | F41: -0.020927843 | G41: Basic DCF | H41: 130.48714 | I41: 289.15 | J41: -0.54872163 | K41: 510.96196 | L41: 0.5 | M41: 1 | N41: 0.08 | O41: 0.27436081 | P41: =IFERROR(INDEX(Pharma!$K$3:$K$677,MATCH($C41,Pharma!$B$3:$B$677,0)),"") | Q41: =IFERROR(IF(INDEX(Pharma!$M$3:$M$677,MATCH($C41,Pharma!$B$3:$B$677,0))="","",INDEX(Pharma!$M$3:$M$677,MATCH($C41,Pharma!$B$3:$B$677,0))),"") | R41: =IFERROR(T(INDEX(Pharma!$N$3:$N$677,MATCH($C41,Pharma!$B$3:$B$677,0))),"")
B42: 5 | C42: GILD | D42: Gilead Sciences, Inc. | E42: Short | F42: -0.020712817 | G42: Basic DCF | H42: 71.511969 | I42: 156.51 | J42: -0.54308371 | K42: 194.06538 | L42: 0.5 | M42: 1 | N42: 0.08 | O42: 0.27154185 | P42: =IFERROR(INDEX(Pharma!$K$3:$K$677,MATCH($C42,Pharma!$B$3:$B$677,0)),"") | Q42: =IFERROR(IF(INDEX(Pharma!$M$3:$M$677,MATCH($C42,Pharma!$B$3:$B$677,0))="","",INDEX(Pharma!$M$3:$M$677,MATCH($C42,Pharma!$B$3:$B$677,0))),"") | R42: =IFERROR(T(INDEX(Pharma!$N$3:$N$677,MATCH($C42,Pharma!$B$3:$B$677,0))),"")
B43: 6 | C43: CORT | D43: Corcept Therapeutics Incorporated | E43: Short | F43: -0.018998549 | G43: PDUFA rNPV | H43: 53.906273 | I43: 116.45 | J43: -0.53708654 | K43: 12.588058 | L43: 0.7 | M43: 0.66248453 | N43: 0.06 | O43: 0.24906806 | P43: =IFERROR(INDEX(Pharma!$K$3:$K$677,MATCH($C43,Pharma!$B$3:$B$677,0)),"") | Q43: =IFERROR(IF(INDEX(Pharma!$M$3:$M$677,MATCH($C43,Pharma!$B$3:$B$677,0))="","",INDEX(Pharma!$M$3:$M$677,MATCH($C43,Pharma!$B$3:$B$677,0))),"") | R43: =IFERROR(T(INDEX(Pharma!$N$3:$N$677,MATCH($C43,Pharma!$B$3:$B$677,0))),"")
B44: 7 | C44: RPRX | D44: Royalty Pharma PLC | E44: Short | F44: -0.018673299 | G44: Basic DCF | H44: 25.647486 | I44: 62.25 | J44: -0.58799219 | K44: 35.793825 | L44: 0.5 | M44: 0.83267804 | N44: 0.06 | O44: 0.24480409 | P44: =IFERROR(INDEX(Pharma!$K$3:$K$677,MATCH($C44,Pharma!$B$3:$B$677,0)),"") | Q44: =IFERROR(IF(INDEX(Pharma!$M$3:$M$677,MATCH($C44,Pharma!$B$3:$B$677,0))="","",INDEX(Pharma!$M$3:$M$677,MATCH($C44,Pharma!$B$3:$B$677,0))),"") | R44: =IFERROR(T(INDEX(Pharma!$N$3:$N$677,MATCH($C44,Pharma!$B$3:$B$677,0))),"")
B45: 8 | C45: MRK | D45: Merck & Co Inc | E45: Short | F45: -0.016625809 | G45: Basic DCF | H45: 83.652529 | I45: 148.3 | J45: -0.43592361 | K45: 365.88155 | L45: 0.5 | M45: 1 | N45: 0.08 | O45: 0.21796181 | P45: =IFERROR(INDEX(Pharma!$K$3:$K$677,MATCH($C45,Pharma!$B$3:$B$677,0)),"") | Q45: =IFERROR(IF(INDEX(Pharma!$M$3:$M$677,MATCH($C45,Pharma!$B$3:$B$677,0))="","",INDEX(Pharma!$M$3:$M$677,MATCH($C45,Pharma!$B$3:$B$677,0))),"") | R45: =IFERROR(T(INDEX(Pharma!$N$3:$N$677,MATCH($C45,Pharma!$B$3:$B$677,0))),"")
B46: 9 | C46: AMGN | D46: Amgen Inc | E46: Short | F46: -0.014536795 | G46: Basic DCF | H46: 271.63789 | I46: 438.94 | J46: -0.3811503 | K46: 237.30501 | L46: 0.5 | M46: 1 | N46: 0.08 | O46: 0.19057515 | P46: =IFERROR(INDEX(Pharma!$K$3:$K$677,MATCH($C46,Pharma!$B$3:$B$677,0)),"") | Q46: =IFERROR(IF(INDEX(Pharma!$M$3:$M$677,MATCH($C46,Pharma!$B$3:$B$677,0))="","",INDEX(Pharma!$M$3:$M$677,MATCH($C46,Pharma!$B$3:$B$677,0))),"") | R46: =IFERROR(T(INDEX(Pharma!$N$3:$N$677,MATCH($C46,Pharma!$B$3:$B$677,0))),"")
B47: 10 | C47: KNSA | D47: Kiniksa Pharmaceuticals International, PLC | E47: Short | F47: -0.014448954 | G47: Basic DCF | H47: 35.801053 | I47: 83.17 | J47: -0.56954367 | K47: 12.79787 | L47: 0.5 | M47: 0.66517663 | N47: 0.06 | O47: 0.18942357 | P47: =IFERROR(INDEX(Pharma!$K$3:$K$677,MATCH($C47,Pharma!$B$3:$B$677,0)),"") | Q47: =IFERROR(IF(INDEX(Pharma!$M$3:$M$677,MATCH($C47,Pharma!$B$3:$B$677,0))="","",INDEX(Pharma!$M$3:$M$677,MATCH($C47,Pharma!$B$3:$B$677,0))),"") | R47: =IFERROR(T(INDEX(Pharma!$N$3:$N$677,MATCH($C47,Pharma!$B$3:$B$677,0))),"")
B48: 11 | C48: INCY | D48: Incyte Corp | E48: Short | F48: -0.013943314 | G48: Reviewed DCF | H48: 88.667654 | I48: 116.615 | J48: -0.23965482 | K48: 23.297596 | L48: 1 | M48: 0.76274167 | N48: 0.06 | O48: 0.18279471 | P48: =IFERROR(INDEX(Pharma!$K$3:$K$677,MATCH($C48,Pharma!$B$3:$B$677,0)),"") | Q48: =IFERROR(IF(INDEX(Pharma!$M$3:$M$677,MATCH($C48,Pharma!$B$3:$B$677,0))="","",INDEX(Pharma!$M$3:$M$677,MATCH($C48,Pharma!$B$3:$B$677,0))),"") | R48: =IFERROR(T(INDEX(Pharma!$N$3:$N$677,MATCH($C48,Pharma!$B$3:$B$677,0))),"")
...

Sheet Pharma
F1: Close 2026-10-20
B2: Ticker | C2: Name | D2: Industry | E2: Exchange | F2: Price | G2: Market Cap | H2: Enterprise V. | J2: NPV / Share | K2: Upside | L2: Model | M2: Event | N2: Note(s)
B3: LLY | C3: Eli Lilly and Company | D3: Pharmaceuticals | E3: NYSE | F3: 1286.835 | G3: =F3*[1]Main!$C$4 | H3: =G3-[1]Main!$C$7+[1]Main!$C$8 | J3: =[1]Main!$C$11 | K3: =IFERROR(J3/F3-1,"") | L3: ="rNPV ("&[1]Main!$C$14&")" | M3: 46324 | N3: Earnings Oct 29 (before open)
B4: JNJ | C4: Johnson & Johnson | D4: Pharmaceuticals | E4: NYSE | F4: 259.4 | G4: =F4*[2]Main!$C$4 | H4: =G4-[2]Main!$C$7+[2]Main!$C$8 | J4: =IF(ISNUMBER([2]Main!$C$11),[2]Main!$C$11,"") | K4: =IFERROR(J4/F4-1,"") | L4: =[2]Main!$C$15&" ("&[2]Main!$C$14&")"
B5: ABBV | C5: AbbVie Inc. | D5: Biotechnology | E5: NYSE | F5: 289.15 | G5: =F5*[3]Main!$C$4 | H5: =G5-[3]Main!$C$7+[3]Main!$C$8 | J5: =IF(ISNUMBER([3]Main!$C$11),[3]Main!$C$11,"") | K5: =IFERROR(J5/F5-1,"") | L5: =[3]Main!$C$15&" ("&[3]Main!$C$14&")" | M5: 46325 | N5: Earnings Oct 30 (before open)
B6: MRK | C6: Merck & Co Inc | D6: Pharmaceuticals | E6: NYSE | F6: 148.3 | G6: =F6*[4]Main!$C$4 | H6: =G6-[4]Main!$C$7+[4]Main!$C$8 | J6: =IF(ISNUMBER([4]Main!$C$11),[4]Main!$C$11,"") | K6: =IFERROR(J6/F6-1,"") | L6: =[4]Main!$C$15&" ("&[4]Main!$C$14&")" | M6: 46324 | N6: Earnings Oct 29 (before open)
B7: NVS | C7: Novartis AG | D7: Pharmaceuticals | E7: NYSE | F7: 153.64 | G7: =F7*[5]Main!$C$4 | H7: =G7-[5]Main!$C$7+[5]Main!$C$8 | J7: =IF(ISNUMBER([5]Main!$C$11),[5]Main!$C$11,"") | K7: =IFERROR(J7/F7-1,"") | L7: =[5]Main!$C$15&" ("&[5]Main!$C$14&")" | M7: 46322 | N7: Earnings Oct 27 (before open)
B8: AZN | C8: AstraZeneca PLC | D8: Pharmaceuticals | E8: NYSE | F8: 168.82 | G8: =F8*[6]Main!$C$4 | H8: =G8-[6]Main!$C$7+[6]Main!$C$8 | J8: =IF(ISNUMBER([6]Main!$C$11),[6]Main!$C$11,"") | K8: =IFERROR(J8/F8-1,"") | L8: =[6]Main!$C$15&" ("&[6]Main!$C$14&")" | M8: 46325 | N8: Earnings Oct 30 (before open)
B9: AMGN | C9: Amgen Inc | D9: Biotechnology | E9: NASDAQ | F9: 438.94 | G9: =F9*[7]Main!$C$4 | H9: =G9-[7]Main!$C$7+[7]Main!$C$8 | J9: =IF(ISNUMBER([7]Main!$C$11),[7]Main!$C$11,"") | K9: =IFERROR(J9/F9-1,"") | L9: =[7]Main!$C$15&" ("&[7]Main!$C$14&")" | M9: 46329 | N9: Earnings Nov 3 (after close)
B10: GILD | C10: Gilead Sciences, Inc. | D10: Biotechnology | E10: NASDAQ | F10: 156.51 | G10: =F10*[8]Main!$C$4 | H10: =G10-[8]Main!$C$7+[8]Main!$C$8 | J10: =IF(ISNUMBER([8]Main!$C$11),[8]Main!$C$11,"") | K10: =IFERROR(J10/F10-1,"") | L10: =[8]Main!$C$15&" ("&[8]Main!$C$14&")" | M10: 46324 | N10: Earnings Oct 29 (after close)
B11: NVO | C11: Novo Nordisk A/S | D11: Pharmaceuticals | E11: NYSE | F11: 39.345 | G11: =F11*[9]Main!$C$4 | H11: =G11-[9]Main!$C$7+[9]Main!$C$8 | J11: =IF(ISNUMBER([9]Main!$C$11),[9]Main!$C$11,"") | K11: =IFERROR(J11/F11-1,"") | L11: =[9]Main!$C$15&" ("&[9]Main!$C$14&")" | M11: 46330 | N11: Earnings Nov 4 (est.)
B12: PFE | C12: Pfizer Inc. | D12: Pharmaceuticals | E12: NYSE | F12: 30.13 | G12: =F12*[10]Main!$C$4 | H12: =G12-[10]Main!$C$7+[10]Main!$C$8 | J12: =IF(ISNUMBER([10]Main!$C$11),[10]Main!$C$11,"") | K12: =IFERROR(J12/F12-1,"") | L12: =[10]Main!$C$15&" ("&[10]Main!$C$14&")" | M12: 46329 | N12: Earnings Nov 3 (before open)
B13: VRTX | C13: Vertex Pharmaceuticals Incorporated | D13: Biotechnology | E13: NASDAQ | F13: 514.65 | G13: =F13*[11]Main!$C$4 | H13: =G13-[11]Main!$C$7+[11]Main!$C$8 | J13: =IF(ISNUMBER([11]Main!$C$11),[11]Main!$C$11,"") | K13: =IFERROR(J13/F13-1,"") | L13: =[11]Main!$C$15&" ("&[11]Main!$C$14&")" | M13: 46328 | N13: Earnings Nov 2 (after close)
B14: BMY | C14: Bristol-Myers Squibb Company | D14: Pharmaceuticals | E14: NYSE | F14: 61.715 | G14: =F14*[12]Main!$C$4 | H14: =G14-[12]Main!$C$7+[12]Main!$C$8 | J14: =IF(ISNUMBER([12]Main!$C$11),[12]Main!$C$11,"") | K14: =IFERROR(J14/F14-1,"") | L14: =[12]Main!$C$15&" ("&[12]Main!$C$14&")" | M14: 46324 | N14: Earnings Oct 29 (before open)
B15: GSK | C15: GSK plc | D15: Pharmaceuticals | E15: NYSE | F15: 50.645 | G15: =F15*[13]Main!$C$4 | H15: =G15-[13]Main!$C$7+[13]Main!$C$8 | J15: =IF(ISNUMBER([13]Main!$C$11),[13]Main!$C$11,"") | K15: =IFERROR(J15/F15-1,"") | L15: =[13]Main!$C$15&" ("&[13]Main!$C$14&")" | M15: 46323 | N15: Earnings Oct 28 (before open)
B16: SNY | C16: Sanofi SA | D16: Pharmaceuticals | E16: NASDAQ | F16: 41.4 | G16: =F16*[14]Main!$C$4 | H16: =G16-[14]Main!$C$7+[14]Main!$C$8 | J16: =IF(ISNUMBER([14]Main!$C$11),[14]Main!$C$11,"") | K16: =IFERROR(J16/F16-1,"") | L16: =[14]Main!$C$15&" ("&[14]Main!$C$14&")" | M16: 46325 | N16: Earnings Oct 30 (before open)
B17: MRNA | C17: Moderna, Inc. | D17: Biotechnology | E17: NASDAQ | F17: 242.08 | G17: =F17*[15]Main!$C$4 | H17: =G17-[15]Main!$C$7+[15]Main!$C$8 | J17: =IF(ISNUMBER([15]Main!$C$11),[15]Main!$C$11,"") | K17: =IFERROR(J17/F17-1,"") | L17: =[15]Main!$C$15&" ("&[15]Main!$C$14&")" | M17: 46332 | N17: Earnings Nov 6 (before open)
B18: REGN | C18: Regeneron Pharmaceuticals, Inc. | D18: Biotechnology | E18: NASDAQ | F18: 807.48 | G18: =F18*[16]Main!$C$4 | H18: =G18-[16]Main!$C$7+[16]Main!$C$8 | J18: =IF(ISNUMBER([16]Main!$C$11),[16]Main!$C$11,"") | K18: =IFERROR(J18/F18-1,"") | L18: =[16]Main!$C$15&" ("&[16]Main!$C$14&")" | M18: 46325 | N18: Earnings Oct 30 (before open)
B19: TAK | C19: Takeda Pharmaceutical Company Limited | D19: Pharmaceuticals | E19: NYSE | F19: 20.08 | G19: =F19*[17]Main!$C$4 | H19: =G19-[17]Main!$C$7+[17]Main!$C$8 | J19: =IF(ISNUMBER([17]Main!$C$11),[17]Main!$C$11,"") | K19: =IFERROR(J19/F19-1,"") | L19: =[17]Main!$C$15&" ("&[17]Main!$C$14&")" | M19: 46324 | N19: Earnings Oct 29 (before open)
B20: NTRA | C20: Natera, Inc. | D20: Biotechnology | E20: NASDAQ | F20: 405.92 | G20: =F20*[18]Main!$C$4 | H20: =G20-[18]Main!$C$7+[18]Main!$C$8 | J20: =IF(ISNUMBER([18]Main!$C$11),[18]Main!$C$11,"") | K20: =IFERROR(J20/F20-1,"") | L20: =[18]Main!$C$15&" ("&[18]Main!$C$14&")" | M20: 46331 | N20: Earnings Nov 5 (est.)
B21: ARGX | C21: argenx SE | D21: Biotechnology | E21: NASDAQ | F21: 869.72 | G21: =F21*[19]Main!$C$4 | H21: =G21-[19]Main!$C$7+[19]Main!$C$8 | J21: =IF(ISNUMBER([19]Main!$C$11),[19]Main!$C$11,"") | K21: =IFERROR(J21/F21-1,"") | L21: =[19]Main!$C$15&" ("&[19]Main!$C$14&")" | M21: 46317 | N21: Earnings Oct 22 (before open)
B22: TEVA | C22: Teva Pharmaceutical Industries Limited | D22: Pharmaceuticals | E22: NYSE | F22: 40.855 | G22: =F22*[20]Main!$C$4 | H22: =G22-[20]Main!$C$7+[20]Main!$C$8 | J22: =IF(ISNUMBER([20]Main!$C$11),[20]Main!$C$11,"") | K22: =IFERROR(J22/F22-1,"") | L22: =[20]Main!$C$15&" ("&[20]Main!$C$14&")" | M22: 46329 | N22: Earnings Nov 3 (before open)
B23: HLN | C23: Haleon PLC | D23: Pharmaceuticals | E23: NYSE | F23: 10.17 | G23: =F23*[21]Main!$C$4 | H23: =G23-[21]Main!$C$7+[21]Main!$C$8 | J23: =IF(ISNUMBER([21]Main!$C$11),[21]Main!$C$11,"") | K23: =IFERROR(J23/F23-1,"") | L23: =[21]Main!$C$15&" ("&[21]Main!$C$14&")" | M23: 46324 | N23: Earnings Oct 29 (before open)
B24: ONC | C24: BeOne Medicines AG | D24: Biotechnology | E24: NASDAQ | F24: 384.5 | G24: =F24*[22]Main!$C$4 | H24: =G24-[22]Main!$C$7+[22]Main!$C$8 | J24: =IF(ISNUMBER([22]Main!$C$11),[22]Main!$C$11,"") | K24: =IFERROR(J24/F24-1,"") | L24: =[22]Main!$C$15&" ("&[22]Main!$C$14&")" | M24: 46331 | N24: Earnings Nov 5 (est.)
B25: RVMD | C25: Revolution Medicines, Inc. | D25: Biotechnology | E25: NASDAQ | F25: 196.55 | G25: =F25*[23]Main!$C$4 | H25: =G25-[23]Main!$C$7+[23]Main!$C$8 | J25: =IF(ISNUMBER([23]Main!$C$11),[23]Main!$C$11,"") | K25: =IFERROR(J25/F25-1,"") | L25: =[23]Main!$C$15&" ("&[23]Main!$C$14&")" | M25: 46330 | N25: Earnings Nov 4 (est.) · Readout ~2026-12-31: Lung cancer, Phase 3
B26: RPRX | C26: Royalty Pharma PLC | D26: Pharmaceuticals | E26: NASDAQ | F26: 62.25 | G26: =F26*[24]Main!$C$4 | H26: =G26-[24]Main!$C$7+[24]Main!$C$8 | J26: =IF(ISNUMBER([24]Main!$C$11),[24]Main!$C$11,"") | K26: =IFERROR(J26/F26-1,"") | L26: =[24]Main!$C$15&" ("&[24]Main!$C$14&")" | M26: 46330 | N26: Earnings Nov 4 (before open)
B27: BIIB | C27: Biogen Inc. | D27: Biotechnology | E27: NASDAQ | F27: 243.1 | G27: =F27*[25]Main!$C$4 | H27: =G27-[25]Main!$C$7+[25]Main!$C$8 | J27: =IF(ISNUMBER([25]Main!$C$11),[25]Main!$C$11,"") | K27: =IFERROR(J27/F27-1,"") | L27: =[25]Main!$C$15&" ("&[25]Main!$C$14&")" | M27: 46323 | N27: Earnings Oct 28 (before open)
B28: ZTS | C28: Zoetis Inc | D28: Pharmaceuticals | E28: NYSE | F28: 80.04 | G28: =F28*[26]Main!$C$4 | H28: =G28-[26]Main!$C$7+[26]Main!$C$8 | J28: =IF(ISNUMBER([26]Main!$C$11),[26]Main!$C$11,"") | K28: =IFERROR(J28/F28-1,"") | L28: =[26]Main!$C$15&" ("&[26]Main!$C$14&")" | M28: 46331 | N28: Earnings Nov 5 (before open)
B29: ALNY | C29: Alnylam Pharmaceuticals, Inc. | D29: Biotechnology | E29: NASDAQ | F29: 230.71 | G29: =F29*[27]Main!$C$4 | H29: =G29-[27]Main!$C$7+[27]Main!$C$8 | J29: =IF(ISNUMBER([27]Main!$C$11),[27]Main!$C$11,"") | K29: =IFERROR(J29/F29-1,"") | L29: =[27]Main!$C$15&" ("&[27]Main!$C$14&")" | M29: 46324 | N29: Earnings Oct 29 (before open)
B30: ROIV | C30: Roivant Sciences Ltd | D30: Biotechnology | E30: NASDAQ | F30: 34.92 | G30: =F30*[28]Main!$C$4 | H30: =G30-[28]Main!$C$7+[28]Main!$C$8 | J30: =IF(ISNUMBER([28]Main!$C$11),[28]Main!$C$11,"") | K30: =IFERROR(J30/F30-1,"") | L30: =[28]Main!$C$15&" ("&[28]Main!$C$14&")" | M30: 46335 | N30: Earnings Nov 9 (est.) · Readout ~2026-12: Pulmonary hypertension, Phase 3
B31: GMAB | C31: Genmab A/S | D31: Biotechnology | E31: NASDAQ | F31: 39.07 | G31: =F31*[29]Main!$C$4 | H31: =G31-[29]Main!$C$7+[29]Main!$C$8 | J31: =IF(ISNUMBER([29]Main!$C$11),[29]Main!$C$11,"") | K31: =IFERROR(J31/F31-1,"") | L31: =[29]Main!$C$15&" ("&[29]Main!$C$14&")" | M31: 46331 | N31: Earnings Nov 5 (before open)
B32: UTHR | C32: United Therapeutics Corporation | D32: Biotechnology | E32: NASDAQ | F32: 553.88 | G32: =F32*[30]Main!$C$4 | H32: =G32-[30]Main!$C$7+[30]Main!$C$8 | J32: =IF(ISNUMBER([30]Main!$C$11),[30]Main!$C$11,"") | K32: =IFERROR(J32/F32-1,"") | L32: =[30]Main!$C$15&" ("&[30]Main!$C$14&")" | M32: 46330 | N32: Earnings Nov 4 (est.)
B33: INCY | C33: Incyte Corp | D33: Biotechnology | E33: NASDAQ | F33: 116.615 | G33: =F33*[31]Main!$C$4 | H33: =G33-[31]Main!$C$7+[31]Main!$C$8 | J33: =IF(ISNUMBER([31]Main!$C$11),[31]Main!$C$11,"") | K33: =IFERROR(J33/F33-1,"") | L33: =[31]Main!$C$15&" ("&[31]Main!$C$14&")" | M33: 46324 | N33: Earnings Oct 29 (before open)
B34: BNTX | C34: Biontech SE | D34: Biotechnology | E34: NASDAQ | F34: 91.17 | G34: =F34*[32]Main!$C$4 | H34: =G34-[32]Main!$C$7+[32]Main!$C$8 | J34: =IF(ISNUMBER([32]Main!$C$11),[32]Main!$C$11,"") | K34: =IFERROR(J34/F34-1,"") | L34: =[32]Main!$C$15&" ("&[32]Main!$C$14&")" | M34: 46329 | N34: Earnings Nov 3 (before open)
B35: VTRS | C35: Viatris Inc. | D35: Pharmaceuticals | E35: NASDAQ | F35: 18.65 | G35: =F35*[33]Main!$C$4 | H35: =G35-[33]Main!$C$7+[33]Main!$C$8 | J35: =IF(ISNUMBER([33]Main!$C$11),[33]Main!$C$11,"") | K35: =IFERROR(J35/F35-1,"") | L35: =[33]Main!$C$15&" ("&[33]Main!$C$14&")" | M35: 46331 | N35: Earnings Nov 5 (before open)
B36: INSM | C36: Insmed Incorporated | D36: Biotechnology | E36: NASDAQ | F36: 95.67 | G36: =F36*[34]Main!$C$4 | H36: =G36-[34]Main!$C$7+[34]Main!$C$8 | J36: =IF(ISNUMBER([34]Main!$C$11),[34]Main!$C$11,"") | K36: =IFERROR(J36/F36-1,"") | L36: =[34]Main!$C$15&" ("&[34]Main!$C$14&")" | M36: 46324 | N36: Earnings Oct 29 (before open)
B37: EXEL | C37: Exelixis Inc | D37: Biotechnology | E37: NASDAQ | F37: 64.39 | G37: =F37*[35]Main!$C$4 | H37: =G37-[35]Main!$C$7+[35]Main!$C$8 | J37: =IF(ISNUMBER([35]Main!$C$11),[35]Main!$C$11,"") | K37: =IFERROR(J37/F37-1,"") | L37: =[35]Main!$C$15&" ("&[35]Main!$C$14&")" | M37: 46324 | N37: Earnings Oct 29 (after close)
B38: ASND | C38: Ascendis Pharma A/S | D38: Biotechnology | E38: NASDAQ | F38: 234.33 | G38: =F38*[36]Main!$C$4 | H38: =G38-[36]Main!$C$7+[36]Main!$C$8 | J38: =IF(ISNUMBER([36]Main!$C$11),[36]Main!$C$11,"") | K38: =IFERROR(J38/F38-1,"") | L38: =[36]Main!$C$15&" ("&[36]Main!$C$14&")" | M38: 46337 | N38: Earnings Nov 11 (est.)
B39: HALO | C39: Halozyme Therapeutics, Inc. | D39: Biotechnology | E39: NASDAQ | F39: 124.37 | G39: =F39*[37]Main!$C$4 | H39: =G39-[37]Main!$C$7+[37]Main!$C$8 | J39: =IF(ISNUMBER([37]Main!$C$11),[37]Main!$C$11,"") | K39: =IFERROR(J39/F39-1,"") | L39: =[37]Main!$C$15&" ("&[37]Main!$C$14&")" | M39: 46328 | N39: Earnings Nov 2 (est.)
B40: NBIX | C40: Neurocrine Biosciences, Inc. | D40: Biotechnology | E40: NASDAQ | F40: 142 | G40: =F40*[38]Main!$C$4 | H40: =G40-[38]Main!$C$7+[38]Main!$C$8 | J40: =IF(ISNUMBER([38]Main!$C$11),[38]Main!$C$11,"") | K40: =IFERROR(J40/F40-1,"") | L40: =[38]Main!$C$15&" ("&[38]Main!$C$14&")" | M40: 46328 | N40: Earnings Nov 2 (after close)
...

Sheet Energy
B2: Ticker | C2: Name | D2: Industry | E2: Exchange | F2: Price | G2: Market Cap | H2: EV
