Workbook

Sheet Main
B2: Agios Pharmaceuticals, Inc.
B3: Price | C3: =INDEX([1]Pharma!$F$1:$F$1000,MATCH("AGIO",[1]Pharma!$B$1:$B$1000,0)) -> 36.64
B4: Shares | C4: =59.701882 -> 59.701882
B5: Market Cap. | C5: =C3*C4 -> 2187.477
B7: Cash | C7: =99.646+517.929+347.252 -> 964.827
B8: Debt | C8: 0
B9: Enterprise V. | C9: =C5-C7+C8 -> 1222.65
B11: rNPV / Share | C11: =NPV!C43 -> 34.937731
B12: Upside | C12: =C11/C3-1 -> -0.046459298
B13: Cash / Share | C13: =(C7-C8)/C4 -> 16.160747
B14: Scenario | C14: =Assumptions!$C$4 -> Base
B16: PDUFA Date | C16: =Assumptions!$B$30 -> 46327
B17: P(Approval) | C17: =Assumptions!$B$32 -> 0.65
B18: If Approved | C18: =Assumptions!$D$121 -> 38.238203
B19: If CRL | C19: =Assumptions!$D$120 -> 27.888497

Sheet Yearly Model
B1: 2021 | C1: 2022 | D1: 2023 | E1: 2024 | F1: 2025 | G1: 2026 | H1: 2027 | I1: 2028 | J1: 2029 | K1: 2030 | L1: 2031 | M1: 2032 | N1: 2033 | O1: 2034 | P1: 2035 | Q1: 2036 | R1: 2037 | S1: 2038 | T1: 2039 | U1: 2040 | V1: 2041 | W1: 2042 | X1: 2043 | Y1: 2044 | Z1: 2045 | AA1: 2046 | AB1: 2047 | AC1: 2048 | AD1: 2049 | AE1: 2050
A2: Revenue | B2: 0 | C2: 14.24 | D2: 26.823 | E2: 36.498 | F2: 54.028 | G2: =SUM('Quarterly Model'!F2:I2) -> 205.49 | H2: =Pipeline!C46 -> 353.392 | I2: =Pipeline!D46 -> 520.794 | J2: =Pipeline!E46 -> 707.696 | K2: =Pipeline!F46 -> 906.148 | L2: =Pipeline!G46 -> 1146.475 | M2: =Pipeline!H46 -> 1284.175 | N2: =Pipeline!I46 -> 1430.175 | O2: =Pipeline!J46 -> 1545.41 | ... AE2: =Pipeline!Z46 -> 0.40117373
A3: Cost of Sales | B3: 0 | C3: 1.704 | D3: 2.881 | E3: 4.165 | F3: 6.345 | G3: =SUM('Quarterly Model'!F3:I3) -> 12.715 | H3: =Pipeline!C47 -> 21.20352 | I3: =Pipeline!D47 -> 31.24764 | J3: =Pipeline!E47 -> 42.46176 | K3: =Pipeline!F47 -> 54.36888 | L3: =Pipeline!G47 -> 72.1345 | M3: =Pipeline!H47 -> 85.4155 | N3: =Pipeline!I47 -> 100.8675 | O3: =Pipeline!J47 -> 114.4736 | ... AE3: =Pipeline!Z47 -> 0.05191667
A4: Gross Margin | B4: =B2-B3 -> 0 | C4: =C2-C3 -> 12.536 | D4: =D2-D3 -> 23.942 | E4: =E2-E3 -> 32.333 | F4: =F2-F3 -> 47.683 | G4: =G2-G3 -> 192.775 | H4: =H2-H3 -> 332.18848 | I4: =I2-I3 -> 489.54636 | ... AE4: =AE2-AE3 -> 0.34925706
A5: Research & Dev. | B5: 256.973 | C5: 279.91 | D5: 295.526 | E5: 301.286 | F5: 339.535 | G5: =SUM('Quarterly Model'!F5:I5) -> 343.902 | H5: =Pipeline!C50 -> 265 | I5: =Pipeline!D50 -> 315.4 | J5: =Pipeline!E50 -> 335.962 | K5: =Pipeline!F50 -> 242.19086 | L5: =Pipeline!G50 -> 229.295 | M5: =Pipeline!H50 -> 256.835 | N5: =Pipeline!I50 -> 286.035 | O5: =Pipeline!J50 -> 309.082 | ... AE5: =Pipeline!Z50 -> 0.080234745
A6: General & Admin | B6: 121.445 | C6: 121.673 | D6: 119.903 | E6: 156.784 | F6: 180.28 | G6: =SUM('Quarterly Model'!F6:I6) -> 214.851 | H6: =Pipeline!C53 -> 278.0156 | I6: =Pipeline!D53 -> 295.0426 | J6: =Pipeline!E53 -> 318.61572 | K6: =Pipeline!F53 -> 380.23724 | L6: =Pipeline!G53 -> 450.59275 | M6: =Pipeline!H53 -> 493.1075 | N6: =Pipeline!I53 -> 538.0815 | O6: =Pipeline!J53 -> 565.4838 | ... AE6: =Pipeline!Z53 -> 0.16030098
A7: Operating Expense | B7: =SUM(B5:B6) -> 378.418 | C7: =SUM(C5:C6) -> 401.583 | D7: =SUM(D5:D6) -> 415.429 | E7: =SUM(E5:E6) -> 458.07 | F7: =SUM(F5:F6) -> 519.815 | G7: =SUM(G5:G6) -> 558.753 | H7: =SUM(H5:H6) -> 543.0156 | I7: =SUM(I5:I6) -> 610.4426 | ... AE7: =SUM(AE5:AE6) -> 0.24053573
A8: Operating Income | B8: =B4-B7 -> -378.418 | C8: =C4-C7 -> -389.047 | D8: =D4-D7 -> -391.487 | E8: =E4-E7 -> -425.737 | F8: =F4-F7 -> -472.132 | G8: =G4-G7 -> -365.978 | H8: =H4-H7 -> -210.82712 | I8: =I4-I7 -> -120.89624 | ... AE8: =AE4-AE7 -> 0.10872133
A9: Interest & Other | B9: 1983.418 | C9: 157.047 | D9: 39.487 | E9: 1143.981 | F9: 58.116 | G9: =SUM('Quarterly Model'!F9:I9) -> 38.219055 | H9: =Assumptions!$B$16*MAX(0,G20)-Assumptions!$B$17*Main!$C$8 -> 31.383115 | I9: =Assumptions!$B$16*MAX(0,H20)-Assumptions!$B$17*Main!$C$8 -> 24.653964 | J9: =Assumptions!$B$16*MAX(0,I20)-Assumptions!$B$17*Main!$C$8 -> 21.044879 | K9: =Assumptions!$B$16*MAX(0,J20)-Assumptions!$B$17*Main!$C$8 -> 22.233682 | L9: =Assumptions!$B$16*MAX(0,K20)-Assumptions!$B$17*Main!$C$8 -> 31.668108 | M9: =Assumptions!$B$16*MAX(0,L20)-Assumptions!$B$17*Main!$C$8 -> 47.64764 | N9: =Assumptions!$B$16*MAX(0,M20)-Assumptions!$B$17*Main!$C$8 -> 66.245956 | O9: =Assumptions!$B$16*MAX(0,N20)-Assumptions!$B$17*Main!$C$8 -> 83.174776 | ... AE9: =Assumptions!$B$16*MAX(0,AD20)-Assumptions!$B$17*Main!$C$8 -> 255.02215
A10: Pretax | B10: =B8+B9 -> 1605 | C10: =C8+C9 -> -232 | D10: =D8+D9 -> -352 | E10: =E8+E9 -> 718.244 | F10: =F8+F9 -> -414.016 | G10: =G8+G9 -> -327.75894 | H10: =H8+H9 -> -179.44401 | I10: =I8+I9 -> -96.242276 | ... AE10: =AE8+AE9 -> 255.13087
A11: Taxes | B11: 0 | C11: 0 | D11: 0 | E11: 44.244 | F11: -1.016 | G11: =SUM('Quarterly Model'!F11:I11) -> 0 | H11: =MAX(0,H10-G21)*Assumptions!$B$15 -> 0 | I11: =MAX(0,I10-H21)*Assumptions!$B$15 -> 0 | J11: =MAX(0,J10-I21)*Assumptions!$B$15 -> 0 | K11: =MAX(0,K10-J21)*Assumptions!$B$15 -> 0 | L11: =MAX(0,L10-K21)*Assumptions!$B$15 -> 0 | M11: =MAX(0,M10-L21)*Assumptions!$B$15 -> 0.50953829 | N11: =MAX(0,N10-M21)*Assumptions!$B$15 -> 120.00176 | O11: =MAX(0,O10-N21)*Assumptions!$B$15 -> 134.30453 | ... AE11: =MAX(0,AE10-AD21)*Assumptions!$B$15 -> 53.577483
A12: Net Income | B12: 1605 | C12: -232 | D12: -352 | E12: 674 | F12: -413 | G12: =G10-G11 -> -327.75894 | H12: =H10-H11 -> -179.44401 | I12: =I10-I11 -> -96.242276 | J12: =J10-J11 -> 31.701399 | K12: =K10-K11 -> 251.5847 | L12: =L10-L11 -> 426.12086 | M12: =M10-M11 -> 495.9551 | N12: =N10-N11 -> 451.4352 | ... AE12: =AE10-AE11 -> 201.55339
A13: Earnings per Share | B13: =IFERROR(B12/B14,0) -> 26.552186 | C13: =IFERROR(C12/C14,0) -> -4.2344266 | D13: =IFERROR(D12/D14,0) -> -6.3251334 | E13: =IFERROR(E12/E14,0) -> 11.642972 | F13: =IFERROR(F12/F14,0) -> -7.1241289 | G13: =IFERROR(G12/G14,0) -> -5.5080677 | H13: =IFERROR(H12/H14,0) -> -3.0056675 | I13: =IFERROR(I12/I14,0) -> -1.6120476 | ... AE13: =IFERROR(AE12/AE14,0) -> 3.3759972
A14: Shares | B14: 60.447 | C14: 54.789 | D14: 55.651 | E14: 57.889 | F14: 57.972 | G14: =AVERAGE('Quarterly Model'!F14:I14) -> 59.50525 | H14: =Main!$C$4*(1+Assumptions!$B$26)^(H1-2026) -> 59.701882 | I14: =Main!$C$4*(1+Assumptions!$B$26)^(I1-2026) -> 59.701882 | J14: =Main!$C$4*(1+Assumptions!$B$26)^(J1-2026) -> 59.701882 | K14: =Main!$C$4*(1+Assumptions!$B$26)^(K1-2026) -> 59.701882 | L14: =Main!$C$4*(1+Assumptions!$B$26)^(L1-2026) -> 59.701882 | M14: =Main!$C$4*(1+Assumptions!$B$26)^(M1-2026) -> 59.701882 | N14: =Main!$C$4*(1+Assumptions!$B$26)^(N1-2026) -> 59.701882 | O14: =Main!$C$4*(1+Assumptions!$B$26)^(O1-2026) -> 59.701882 | ... AE14: =Main!$C$4*(1+Assumptions!$B$26)^(AE1-2026) -> 59.701882
A16: Revenue Change | C16: =IFERROR(C2/B2-1,"") | D16: =IFERROR(D2/C2-1,"") -> 0.88363764 | E16: =IFERROR(E2/D2-1,"") -> 0.36069791 | F16: =IFERROR(F2/E2-1,"") -> 0.48030029 | G16: =IFERROR(G2/F2-1,"") -> 2.8033982 | H16: =IFERROR(H2/G2-1,"") -> 0.71975279 | I16: =IFERROR(I2/H2-1,"") -> 0.47370059 | J16: =IFERROR(J2/I2-1,"") -> 0.35887894 | ... AE16: =IFERROR(AE2/AD2-1,"") -> -0.6
A17: Gross Margin | B17: =IFERROR(B4/B2,"") | C17: =IFERROR(C4/C2,"") -> 0.88033708 | D17: =IFERROR(D4/D2,"") -> 0.89259218 | E17: =IFERROR(E4/E2,"") -> 0.88588416 | F17: =IFERROR(F4/F2,"") -> 0.88256089 | G17: =IFERROR(G4/G2,"") -> 0.93812351 | H17: =IFERROR(H4/H2,"") -> 0.94 | I17: =IFERROR(I4/I2,"") -> 0.94 | ... AE17: =IFERROR(AE4/AE2,"") -> 0.87058806
A19: Actual / Estimate | B19: A | C19: A | D19: A | E19: A | F19: A | G19: A+E | H19: E | I19: E | J19: E | K19: E | L19: E | M19: E | N19: E | O19: E | P19: E | Q19: E | R19: E | S19: E | T19: E | U19: E | V19: E | W19: E | X19: E | Y19: E | Z19: E | AA19: E | AB19: E | AC19: E | AD19: E | AE19: E
A20: Cash & Investments | G20: ='Quarterly Model'!I20 -> 836.88306 | H20: =G20+H12 -> 657.43905 | I20: =H20+I12 -> 561.19677 | J20: =I20+J12 -> 592.89817 | K20: =J20+K12 -> 844.48288 | L20: =K20+L12 -> 1270.6037 | M20: =L20+M12 -> 1766.5588 | N20: =M20+N12 -> 2217.994 | O20: =N20+O12 -> 2723.2349 | ... AE20: =AD20+AE12 -> 7002.144
A21: Tax-Loss Pool | F21: =Assumptions!$B$18 -> 600 | G21: =F21-MIN(F21,MAX(0,G10))+MAX(0,-G10) -> 927.75894 | H21: =G21-MIN(G21,MAX(0,H10))+MAX(0,-H10) -> 1107.2029 | I21: =H21-MIN(H21,MAX(0,I10))+MAX(0,-I10) -> 1203.4452 | J21: =I21-MIN(I21,MAX(0,J10))+MAX(0,-J10) -> 1171.7438 | K21: =J21-MIN(J21,MAX(0,K10))+MAX(0,-K10) -> 920.15912 | L21: =K21-MIN(K21,MAX(0,L10))+MAX(0,-L10) -> 494.03827 | M21: =L21-MIN(L21,MAX(0,M10))+MAX(0,-M10) -> 0 | N21: =M21-MIN(M21,MAX(0,N10))+MAX(0,-N10) -> 0 | ... AE21: =AD21-MIN(AD21,MAX(0,AE10))+MAX(0,-AE10) -> 0

Sheet Quarterly Model
B1: Q1 2025 | C1: Q2 2025 | D1: Q3 2025 | E1: Q4 2025 | F1: Q1 2026 | G1: Q2 2026 | H1: Q3 2026 | I1: Q4 2026
A2: Revenue | B2: =SUM(B24:B24) -> 8.73 | C2: =SUM(C24:C24) -> 12.46 | D2: =SUM(D24:D24) -> 12.88 | E2: =SUM(E24:E24) -> 19.97 | F2: =SUM(F24:F24) -> 20.75 | G2: =SUM(G24:G24) -> 44.74 | H2: =SUM(H24:H24) -> 62 | I2: =SUM(I24:I24) -> 78
A3: Cost of Sales | B3: 1.085 | C3: 1.702 | D3: 1.679 | E3: 1.879 | F3: 1.319 | G3: 2.996 | H3: =H2*0.06 -> 3.72 | I3: =I2*0.06 -> 4.68
A4: Gross Margin | B4: =B2-B3 -> 7.645 | C4: =C2-C3 -> 10.758 | D4: =D2-D3 -> 11.201 | E4: =E2-E3 -> 18.091 | F4: =F2-F3 -> 19.431 | G4: =G2-G3 -> 41.744 | H4: =H2-H3 -> 58.28 | I4: =I2-I3 -> 73.32
A5: Research & Dev. | B5: 72.743 | C5: 91.94 | D5: 86.796 | E5: 88.056 | F5: 81.148 | G5: 100.754 | H5: 80 | I5: 82
A6: General & Admin | B6: 41.527 | C6: 45.869 | D6: 41.274 | E6: 51.61 | F6: 48.304 | G6: 51.547 | H6: 55 | I6: 60
A7: Operating Expense | B7: =SUM(B5:B6) -> 114.27 | C7: =SUM(C5:C6) -> 137.809 | D7: =SUM(D5:D6) -> 128.07 | E7: =SUM(E5:E6) -> 139.666 | F7: =SUM(F5:F6) -> 129.452 | G7: =SUM(G5:G6) -> 152.301 | H7: =SUM(H5:H6) -> 135 | I7: =SUM(I5:I6) -> 142
A8: Operating Income | B8: =B4-B7 -> -106.625 | C8: =C4-C7 -> -127.051 | D8: =D4-D7 -> -116.869 | E8: =E4-E7 -> -121.575 | F8: =F4-F7 -> -110.021 | G8: =G4-G7 -> -110.557 | H8: =H4-H7 -> -76.72 | I8: =I4-I7 -> -68.68
A9: Interest & Other | B9: 17.34 | C9: 15.036 | D9: 13.436 | E9: 12.304 | F9: 10.914 | G9: 9.849 | H9: =Assumptions!$B$16*G20/4 -> 9.0452531 | I9: =Assumptions!$B$16*H20/4 -> 8.4108024
A10: Pretax | B10: =B8+B9 -> -89.285 | C10: =C8+C9 -> -112.015 | D10: =D8+D9 -> -103.433 | E10: =E8+E9 -> -109.271 | F10: =F8+F9 -> -99.107 | G10: =G8+G9 -> -100.708 | H10: =H8+H9 -> -67.674747 | I10: =I8+I9 -> -60.269198
A11: Taxes | B11: 0 | C11: 0 | D11: 0 | E11: -1.016 | F11: 0 | G11: 0 | H11: 0 | I11: 0
A12: Net Income | B12: =B10-B11 -> -89.285 | C12: =C10-C11 -> -112.015 | D12: =D10-D11 -> -103.433 | E12: =E10-E11 -> -108.255 | F12: =F10-F11 -> -99.107 | G12: =G10-G11 -> -100.708 | H12: =H10-H11 -> -67.674747 | I12: =I10-I11 -> -60.269198
A13: Earnings per Share | B13: =IFERROR(B12/B14,0) -> -1.5538906 | C13: =IFERROR(C12/C14,0) -> -1.9335267 | D13: =IFERROR(D12/D14,0) -> -1.779064 | E13: =IFERROR(E12/E14,0) -> -1.8550474 | F13: =IFERROR(F12/F14,0) -> -1.6860093 | G13: =IFERROR(G12/G14,0) -> -1.6928844 | H13: =IFERROR(H12/H14,0) -> -1.1316847 | I13: =IFERROR(I12/I14,0) -> -1.0053244
A14: Shares | B14: 57.459 | C14: 57.933 | D14: 58.139 | E14: 58.357 | F14: 58.782 | G14: 59.489 | H14: 59.8 | I14: 59.95
A16: Revenue Change (YoY) | F16: =IFERROR(F2/B2-1,"") -> 1.3768614 | G16: =IFERROR(G2/C2-1,"") -> 2.5906902 | H16: =IFERROR(H2/D2-1,"") -> 3.8136646 | I16: =IFERROR(I2/E2-1,"") -> 2.9058588
A17: Gross Margin | B17: =IFERROR(B4/B2,"") -> 0.87571592 | C17: =IFERROR(C4/C2,"") -> 0.86340289 | D17: =IFERROR(D4/D2,"") -> 0.86964286 | E17: =IFERROR(E4/E2,"") -> 0.90590886 | F17: =IFERROR(F4/F2,"") -> 0.93643373 | G17: =IFERROR(G4/G2,"") -> 0.93303532 | H17: =IFERROR(H4/H2,"") -> 0.94 | I17: =IFERROR(I4/I2,"") -> 0.94
A19: Actual / Estimate | B19: A | C19: A | D19: A | E19: A | F19: A | G19: A | H19: E | I19: E
A20: Cash & Investments | G20: 964.827 | H20: =G20+H12+H21 -> 897.15225 | I20: =H20+I12+I21 -> 836.88306
A21: Other Cash Flows (est.) | H21: 0 | I21: 0
A23: Revenue by Product
A24: Mitapivat | B24: 8.73 | C24: 12.46 | D24: 12.88 | E24: 19.97 | F24: 20.75 | G24: 44.74 | H24: 62 | I24: 78

Sheet Assumptions
A1: AGIO — rNPV assumptions ($mm unless noted)
A4: Scenario (1 = Bear, 2 = Base, 3 = Bull) | B4: 2 | C4: =CHOOSE($B$4,"Bear","Base","Bull") -> Base
A5: Overrides (blank = scenario value; the sensitivity tables drive these)
A6: Discount rate override
A7: PDUFA approval probability override
A8: PDUFA program peak sales override ($mm)
A10: Parameter | B10: Active | C10: Bear | D10: Base | E10: Bull
A12: Valuation & corporate
A13: Valuation date | B13: =DATE(2026,10,16) -> 46311
A14: Discount rate (cost of equity) | B14: =IF(ISNUMBER($B$6),$B$6,CHOOSE($B$4,C14,D14,E14)) -> 0.11 | C14: 0.13 | D14: 0.11 | E14: 0.095
A15: Tax rate | B15: =CHOOSE($B$4,C15,D15,E15) -> 0.21 | C15: 0.21 | D15: 0.21 | E15: 0.21
A16: Interest yield on cash | B16: =CHOOSE($B$4,C16,D16,E16) -> 0.0375 | C16: 0.0375 | D16: 0.0375 | E16: 0.0375
A17: Average cash cost of debt (P&L display only) | B17: =CHOOSE($B$4,C17,D17,E17) -> 0.025 | C17: 0.025 | D17: 0.025 | E17: 0.025
A18: Tax-loss pool at 12/31/2025 | B18: =CHOOSE($B$4,C18,D18,E18) -> 600 | C18: 600 | D18: 600 | E18: 600
A19: Corporate G&A, 2027 | B19: =CHOOSE($B$4,C19,D19,E19) -> 70 | C19: 70 | D19: 70 | E19: 70
A20: Platform / unallocated R&D, 2027 | B20: =CHOOSE($B$4,C20,D20,E20) -> 180 | C20: 180 | D20: 180 | E20: 180
A21: Cost inflation | B21: =CHOOSE($B$4,C21,D21,E21) -> 0.03 | C21: 0.03 | D21: 0.03 | E21: 0.03
A22: Corporate G&A floor, % of revenue | B22: =CHOOSE($B$4,C22,D22,E22) -> 0.1 | C22: 0.1 | D22: 0.1 | E22: 0.1
A23: Platform R&D floor, % of revenue | B23: =CHOOSE($B$4,C23,D23,E23) -> 0.2 | C23: 0.2 | D23: 0.2 | E23: 0.2
A24: Corporate cost cut after a CRL (2027+) | B24: =CHOOSE($B$4,C24,D24,E24) -> 0 | C24: 0 | D24: 0 | E24: 0
A25: Last year of base-level corporate costs (then % of revenue only) | B25: =CHOOSE($B$4,C25,D25,E25) -> 2037 | C25: 2037 | D25: 2037 | E25: 2037
A26: Annual share count growth (EPS display only) | B26: =CHOOSE($B$4,C26,D26,E26) -> 0 | C26: 0 | D26: 0 | E26: 0
A27: Wind-down cost for liquidation value | B27: =CHOOSE($B$4,C27,D27,E27) -> 40 | C27: 40 | D27: 40 | E27: 40
A29: PDUFA event
A30: PDUFA target action date | B30: =DATE(2026,11,1) -> 46327
A31: Application | B31: Mitapivat sNDA, sickle cell disease (accelerated approval)
A32: Probability of approval at this PDUFA | B32: =IF(ISNUMBER($B$7),$B$7,CHOOSE($B$4,C32,D32,E32)) -> 0.65 | C32: 0.5 | D32: 0.65 | E32: 0.8
A33: Probability of approval later, after a CRL | B33: =CHOOSE($B$4,C33,D33,E33) -> 0.55 | C33: 0.45 | D33: 0.55 | E33: 0.65
A34: Launch delay after a CRL (years) | B34: =CHOOSE($B$4,C34,D34,E34) -> 3 | C34: 3 | D34: 3 | E34: 3
A35: Probability of approval, scenario value (before override) | B35: =CHOOSE($B$4,C32,D32,E32) -> 0.65
A36: Read-through: relative cut to other programs' PoS after a CRL | B36: =CHOOSE($B$4,C36,D36,E36) -> 0 | C36: 0 | D36: 0 | E36: 0
A37: Read-through multiplier on other programs' PoS (1 = none) | B37: =1+$B$36*($B$32-$B$35)/$B$35 -> 1
A38: Expected corporate cost multiplier (2027+) | B38: =$B$32+(1-$B$32)*(1-$B$24) -> 1
A40: Commercial curves (by year since launch)
A41: Year since launch | B41: 1 | C41: 2 | D41: 3 | E41: 4 | F41: 5 | G41: 6 | H41: 7
A42: Ramp 1 — standard launch, % of peak | B42: 0.1 | C42: 0.25 | D42: 0.45 | E42: 0.65 | F42: 0.82 | G42: 0.93 | H42: 1
A43: Ramp 2 — orphan-disease launch, % of peak | B43: 0.15 | C43: 0.35 | D43: 0.55 | E43: 0.75 | F43: 0.9 | G43: 1 | H43: 1
A44: Commercial SG&A, % of sales (years 1–5; floor = program maturity %) | B44: 0.9 | C44: 0.55 | D44: 0.4 | E44: 0.32 | F44: 0.28
A46: Mitapivat — thalassemia + PKD (AQVESME / PYRUKYND) (marketed)
A47: Launch year (first commercial year) | B47: 2026
...

Sheet Pipeline
A1: AGIO — risk-adjusted program build ($mm)
A2: Year | C2: 2027 | D2: 2028 | E2: 2029 | F2: 2030 | G2: 2031 | H2: 2032 | I2: 2033 | J2: 2034 | K2: 2035 | L2: 2036 | M2: 2037 | N2: 2038 | O2: 2039 | P2: 2040 | Q2: 2041 | R2: 2042 | S2: 2043 | T2: 2044 | U2: 2045 | V2: 2046 | W2: 2047 | X2: 2048 | Y2: 2049 | Z2: 2050
A4: Mitapivat — thalassemia + PKD (AQVESME / PYRUKYND)
A5: Years since launch | C5: =C$2-Assumptions!$B$47+1 -> 2 | D5: =D$2-Assumptions!$B$47+1 -> 3 | E5: =E$2-Assumptions!$B$47+1 -> 4 | F5: =F$2-Assumptions!$B$47+1 -> 5 | G5: =G$2-Assumptions!$B$47+1 -> 6 | H5: =H$2-Assumptions!$B$47+1 -> 7 | I5: =I$2-Assumptions!$B$47+1 -> 8 | J5: =J$2-Assumptions!$B$47+1 -> 9 | ... Z5: =Z$2-Assumptions!$B$47+1 -> 25
A6: Net sales | C6: =IF(C$2>Assumptions!$B$55,Assumptions!$B$57*(1-Assumptions!$B$56),IF(C$2<Assumptions!$B$49,Assumptions!$B$57+(Assumptions!$B$48-Assumptions!$B$57)*((C$2-2026)/(Assumptions!$B$49-2026))^Assumptions!$B$50,Assumptions!$B$48)) -> 314.392 | D6: =IF(D$2>Assumptions!$B$55,C6*(1-Assumptions!$B$56),IF(D$2<Assumptions!$B$49,Assumptions!$B$57+(Assumptions!$B$48-Assumptions!$B$57)*((D$2-2026)/(Assumptions!$B$49-2026))^Assumptions!$B$50,Assumptions!$B$48)) -> 423.294 | E6: =IF(E$2>Assumptions!$B$55,D6*(1-Assumptions!$B$56),IF(E$2<Assumptions!$B$49,Assumptions!$B$57+(Assumptions!$B$48-Assumptions!$B$57)*((E$2-2026)/(Assumptions!$B$49-2026))^Assumptions!$B$50,Assumptions!$B$48)) -> 532.196 | F6: =IF(F$2>Assumptions!$B$55,E6*(1-Assumptions!$B$56),IF(F$2<Assumptions!$B$49,Assumptions!$B$57+(Assumptions!$B$48-Assumptions!$B$57)*((F$2-2026)/(Assumptions!$B$49-2026))^Assumptions!$B$50,Assumptions!$B$48)) -> 641.098 | G6: =IF(G$2>Assumptions!$B$55,F6*(1-Assumptions!$B$56),IF(G$2<Assumptions!$B$49,Assumptions!$B$57+(Assumptions!$B$48-Assumptions!$B$57)*((G$2-2026)/(Assumptions!$B$49-2026))^Assumptions!$B$50,Assumptions!$B$48)) -> 750 | H6: =IF(H$2>Assumptions!$B$55,G6*(1-Assumptions!$B$56),IF(H$2<Assumptions!$B$49,Assumptions!$B$57+(Assumptions!$B$48-Assumptions!$B$57)*((H$2-2026)/(Assumptions!$B$49-2026))^Assumptions!$B$50,Assumptions!$B$48)) -> 750 | I6: =IF(I$2>Assumptions!$B$55,H6*(1-Assumptions!$B$56),IF(I$2<Assumptions!$B$49,Assumptions!$B$57+(Assumptions!$B$48-Assumptions!$B$57)*((I$2-2026)/(Assumptions!$B$49-2026))^Assumptions!$B$50,Assumptions!$B$48)) -> 750 | J6: =IF(J$2>Assumptions!$B$55,I6*(1-Assumptions!$B$56),IF(J$2<Assumptions!$B$49,Assumptions!$B$57+(Assumptions!$B$48-Assumptions!$B$57)*((J$2-2026)/(Assumptions!$B$49-2026))^Assumptions!$B$50,Assumptions!$B$48)) -> 750 | K6: =IF(K$2>Assumptions!$B$55,J6*(1-Assumptions!$B$56),IF(K$2<Assumptions!$B$49,Assumptions!$B$57+(Assumptions!$B$48-Assumptions!$B$57)*((K$2-2026)/(Assumptions!$B$49-2026))^Assumptions!$B$50,Assumptions!$B$48)) -> 750 | ... Z6: =IF(Z$2>Assumptions!$B$55,Y6*(1-Assumptions!$B$56),IF(Z$2<Assumptions!$B$49,Assumptions!$B$57+(Assumptions!$B$48-Assumptions!$B$57)*((Z$2-2026)/(Assumptions!$B$49-2026))^Assumptions!$B$50,Assumptions!$B$48)) -> 0.0020132659
A7: Company revenue | C7: =C6*Assumptions!$B$51 -> 314.392 | D7: =D6*Assumptions!$B$51 -> 423.294 | E7: =E6*Assumptions!$B$51 -> 532.196 | F7: =F6*Assumptions!$B$51 -> 641.098 | G7: =G6*Assumptions!$B$51 -> 750 | H7: =H6*Assumptions!$B$51 -> 750 | I7: =I6*Assumptions!$B$51 -> 750 | J7: =J6*Assumptions!$B$51 -> 750 | ... Z7: =Z6*Assumptions!$B$51 -> 0.0020132659
A8: COGS + royalties | C8: =C6*(Assumptions!$B$52+Assumptions!$B$53) -> 18.86352 | D8: =D6*(Assumptions!$B$52+Assumptions!$B$53) -> 25.39764 | E8: =E6*(Assumptions!$B$52+Assumptions!$B$53) -> 31.93176 | F8: =F6*(Assumptions!$B$52+Assumptions!$B$53) -> 38.46588 | G8: =G6*(Assumptions!$B$52+Assumptions!$B$53) -> 45 | H8: =H6*(Assumptions!$B$52+Assumptions!$B$53) -> 45 | I8: =I6*(Assumptions!$B$52+Assumptions!$B$53) -> 45 | J8: =J6*(Assumptions!$B$52+Assumptions!$B$53) -> 45 | ... Z8: =Z6*(Assumptions!$B$52+Assumptions!$B$53) -> 0.00012079596
A9: Commercial SG&A | C9: =IF(Assumptions!$B$54=0,0,IF(FALSE,0,IF(C5>=1,C6*IF(OR(Assumptions!$B$51<1,C5>5),Assumptions!$B$54,MAX(Assumptions!$B$54,INDEX(Assumptions!$B$44:$F$44,C5))),0))) -> 172.9156 | D9: =IF(Assumptions!$B$54=0,0,IF(FALSE,0,IF(D5>=1,D6*IF(OR(Assumptions!$B$51<1,D5>5),Assumptions!$B$54,MAX(Assumptions!$B$54,INDEX(Assumptions!$B$44:$F$44,D5))),0))) -> 169.3176 | E9: =IF(Assumptions!$B$54=0,0,IF(FALSE,0,IF(E5>=1,E6*IF(OR(Assumptions!$B$51<1,E5>5),Assumptions!$B$54,MAX(Assumptions!$B$54,INDEX(Assumptions!$B$44:$F$44,E5))),0))) -> 170.30272 | F9: =IF(Assumptions!$B$54=0,0,IF(FALSE,0,IF(F5>=1,F6*IF(OR(Assumptions!$B$51<1,F5>5),Assumptions!$B$54,MAX(Assumptions!$B$54,INDEX(Assumptions!$B$44:$F$44,F5))),0))) -> 179.50744 | G9: =IF(Assumptions!$B$54=0,0,IF(FALSE,0,IF(G5>=1,G6*IF(OR(Assumptions!$B$51<1,G5>5),Assumptions!$B$54,MAX(Assumptions!$B$54,INDEX(Assumptions!$B$44:$F$44,G5))),0))) -> 187.5 | H9: =IF(Assumptions!$B$54=0,0,IF(FALSE,0,IF(H5>=1,H6*IF(OR(Assumptions!$B$51<1,H5>5),Assumptions!$B$54,MAX(Assumptions!$B$54,INDEX(Assumptions!$B$44:$F$44,H5))),0))) -> 187.5 | I9: =IF(Assumptions!$B$54=0,0,IF(FALSE,0,IF(I5>=1,I6*IF(OR(Assumptions!$B$51<1,I5>5),Assumptions!$B$54,MAX(Assumptions!$B$54,INDEX(Assumptions!$B$44:$F$44,I5))),0))) -> 187.5 | J9: =IF(Assumptions!$B$54=0,0,IF(FALSE,0,IF(J5>=1,J6*IF(OR(Assumptions!$B$51<1,J5>5),Assumptions!$B$54,MAX(Assumptions!$B$54,INDEX(Assumptions!$B$44:$F$44,J5))),0))) -> 187.5 | ... Z9: =IF(Assumptions!$B$54=0,0,IF(FALSE,0,IF(Z5>=1,Z6*IF(OR(Assumptions!$B$51<1,Z5>5),Assumptions!$B$54,MAX(Assumptions!$B$54,INDEX(Assumptions!$B$44:$F$44,Z5))),0))) -> 0.00050331648
A10: Development R&D | C10: =0 -> 0 | D10: =0 -> 0 | E10: =0 -> 0 | F10: =0 -> 0 | G10: =0 -> 0 | H10: =0 -> 0 | I10: =0 -> 0 | J10: =0 -> 0 | ... Z10: =0 -> 0
A11: Program contribution (pre-tax) | C11: =C7-C8-C9-C10 -> 122.61288 | D11: =D7-D8-D9-D10 -> 228.57876 | E11: =E7-E8-E9-E10 -> 329.96152 | F11: =F7-F8-F9-F10 -> 423.12468 | G11: =G7-G8-G9-G10 -> 517.5 | H11: =H7-H8-H9-H10 -> 517.5 | I11: =I7-I8-I9-I10 -> 517.5 | J11: =J7-J8-J9-J10 -> 517.5 | ... Z11: =Z7-Z8-Z9-Z10 -> 0.0013891535
A13: Mitapivat — sickle cell disease
A14: Years since launch (approved on time) | C14: =C$2-Assumptions!$B$60+1 -> 1 | D14: =D$2-Assumptions!$B$60+1 -> 2 | E14: =E$2-Assumptions!$B$60+1 -> 3 | F14: =F$2-Assumptions!$B$60+1 -> 4 | G14: =G$2-Assumptions!$B$60+1 -> 5 | H14: =H$2-Assumptions!$B$60+1 -> 6 | I14: =I$2-Assumptions!$B$60+1 -> 7 | J14: =J$2-Assumptions!$B$60+1 -> 8 | ... Z14: =Z$2-Assumptions!$B$60+1 -> 24
A15: Net sales, unrisked (approved on time) | C15: =IF(C$2>Assumptions!$B$69,0*(1-Assumptions!$B$70),IF(C14>=1,Assumptions!$B$61*CHOOSE(Assumptions!$B$68,INDEX(Assumptions!$B$42:$H$42,MIN(C14,7)),INDEX(Assumptions!$B$43:$H$43,MIN(C14,7))),0)) -> 60 | D15: =IF(D$2>Assumptions!$B$69,C15*(1-Assumptions!$B$70),IF(D14>=1,Assumptions!$B$61*CHOOSE(Assumptions!$B$68,INDEX(Assumptions!$B$42:$H$42,MIN(D14,7)),INDEX(Assumptions!$B$43:$H$43,MIN(D14,7))),0)) -> 150 | E15: =IF(E$2>Assumptions!$B$69,D15*(1-Assumptions!$B$70),IF(E14>=1,Assumptions!$B$61*CHOOSE(Assumptions!$B$68,INDEX(Assumptions!$B$42:$H$42,MIN(E14,7)),INDEX(Assumptions!$B$43:$H$43,MIN(E14,7))),0)) -> 270 | F15: =IF(F$2>Assumptions!$B$69,E15*(1-Assumptions!$B$70),IF(F14>=1,Assumptions!$B$61*CHOOSE(Assumptions!$B$68,INDEX(Assumptions!$B$42:$H$42,MIN(F14,7)),INDEX(Assumptions!$B$43:$H$43,MIN(F14,7))),0)) -> 390 | G15: =IF(G$2>Assumptions!$B$69,F15*(1-Assumptions!$B$70),IF(G14>=1,Assumptions!$B$61*CHOOSE(Assumptions!$B$68,INDEX(Assumptions!$B$42:$H$42,MIN(G14,7)),INDEX(Assumptions!$B$43:$H$43,MIN(G14,7))),0)) -> 492 | H15: =IF(H$2>Assumptions!$B$69,G15*(1-Assumptions!$B$70),IF(H14>=1,Assumptions!$B$61*CHOOSE(Assumptions!$B$68,INDEX(Assumptions!$B$42:$H$42,MIN(H14,7)),INDEX(Assumptions!$B$43:$H$43,MIN(H14,7))),0)) -> 558 | I15: =IF(I$2>Assumptions!$B$69,H15*(1-Assumptions!$B$70),IF(I14>=1,Assumptions!$B$61*CHOOSE(Assumptions!$B$68,INDEX(Assumptions!$B$42:$H$42,MIN(I14,7)),INDEX(Assumptions!$B$43:$H$43,MIN(I14,7))),0)) -> 600 | J15: =IF(J$2>Assumptions!$B$69,I15*(1-Assumptions!$B$70),IF(J14>=1,Assumptions!$B$61*CHOOSE(Assumptions!$B$68,INDEX(Assumptions!$B$42:$H$42,MIN(J14,7)),INDEX(Assumptions!$B$43:$H$43,MIN(J14,7))),0)) -> 600 | K15: =IF(K$2>Assumptions!$B$69,J15*(1-Assumptions!$B$70),IF(K14>=1,Assumptions!$B$61*CHOOSE(Assumptions!$B$68,INDEX(Assumptions!$B$42:$H$42,MIN(K14,7)),INDEX(Assumptions!$B$43:$H$43,MIN(K14,7))),0)) -> 600 | ... Z15: =IF(Z$2>Assumptions!$B$69,Y15*(1-Assumptions!$B$70),IF(Z14>=1,Assumptions!$B$61*CHOOSE(Assumptions!$B$68,INDEX(Assumptions!$B$42:$H$42,MIN(Z14,7)),INDEX(Assumptions!$B$43:$H$43,MIN(Z14,7))),0)) -> 0.0016106127
A16: Years since launch (approved after a CRL) | C16: =C$2-(Assumptions!$B$60+Assumptions!$B$34)+1 -> -2 | D16: =D$2-(Assumptions!$B$60+Assumptions!$B$34)+1 -> -1 | E16: =E$2-(Assumptions!$B$60+Assumptions!$B$34)+1 -> 0 | F16: =F$2-(Assumptions!$B$60+Assumptions!$B$34)+1 -> 1 | G16: =G$2-(Assumptions!$B$60+Assumptions!$B$34)+1 -> 2 | H16: =H$2-(Assumptions!$B$60+Assumptions!$B$34)+1 -> 3 | I16: =I$2-(Assumptions!$B$60+Assumptions!$B$34)+1 -> 4 | J16: =J$2-(Assumptions!$B$60+Assumptions!$B$34)+1 -> 5 | ... Z16: =Z$2-(Assumptions!$B$60+Assumptions!$B$34)+1 -> 21
A17: Net sales, unrisked (approved after a CRL) | C17: =IF(C$2>Assumptions!$B$69,0*(1-Assumptions!$B$70),IF(C16>=1,Assumptions!$B$61*CHOOSE(Assumptions!$B$68,INDEX(Assumptions!$B$42:$H$42,MIN(C16,7)),INDEX(Assumptions!$B$43:$H$43,MIN(C16,7))),0)) -> 0 | D17: =IF(D$2>Assumptions!$B$69,C17*(1-Assumptions!$B$70),IF(D16>=1,Assumptions!$B$61*CHOOSE(Assumptions!$B$68,INDEX(Assumptions!$B$42:$H$42,MIN(D16,7)),INDEX(Assumptions!$B$43:$H$43,MIN(D16,7))),0)) -> 0 | E17: =IF(E$2>Assumptions!$B$69,D17*(1-Assumptions!$B$70),IF(E16>=1,Assumptions!$B$61*CHOOSE(Assumptions!$B$68,INDEX(Assumptions!$B$42:$H$42,MIN(E16,7)),INDEX(Assumptions!$B$43:$H$43,MIN(E16,7))),0)) -> 0 | F17: =IF(F$2>Assumptions!$B$69,E17*(1-Assumptions!$B$70),IF(F16>=1,Assumptions!$B$61*CHOOSE(Assumptions!$B$68,INDEX(Assumptions!$B$42:$H$42,MIN(F16,7)),INDEX(Assumptions!$B$43:$H$43,MIN(F16,7))),0)) -> 60 | G17: =IF(G$2>Assumptions!$B$69,F17*(1-Assumptions!$B$70),IF(G16>=1,Assumptions!$B$61*CHOOSE(Assumptions!$B$68,INDEX(Assumptions!$B$42:$H$42,MIN(G16,7)),INDEX(Assumptions!$B$43:$H$43,MIN(G16,7))),0)) -> 150 | H17: =IF(H$2>Assumptions!$B$69,G17*(1-Assumptions!$B$70),IF(H16>=1,Assumptions!$B$61*CHOOSE(Assumptions!$B$68,INDEX(Assumptions!$B$42:$H$42,MIN(H16,7)),INDEX(Assumptions!$B$43:$H$43,MIN(H16,7))),0)) -> 270 | I17: =IF(I$2>Assumptions!$B$69,H17*(1-Assumptions!$B$70),IF(I16>=1,Assumptions!$B$61*CHOOSE(Assumptions!$B$68,INDEX(Assumptions!$B$42:$H$42,MIN(I16,7)),INDEX(Assumptions!$B$43:$H$43,MIN(I16,7))),0)) -> 390 | J17: =IF(J$2>Assumptions!$B$69,I17*(1-Assumptions!$B$70),IF(J16>=1,Assumptions!$B$61*CHOOSE(Assumptions!$B$68,INDEX(Assumptions!$B$42:$H$42,MIN(J16,7)),INDEX(Assumptions!$B$43:$H$43,MIN(J16,7))),0)) -> 492 | K17: =IF(K$2>Assumptions!$B$69,J17*(1-Assumptions!$B$70),IF(K16>=1,Assumptions!$B$61*CHOOSE(Assumptions!$B$68,INDEX(Assumptions!$B$42:$H$42,MIN(K16,7)),INDEX(Assumptions!$B$43:$H$43,MIN(K16,7))),0)) -> 558 | ... Z17: =IF(Z$2>Assumptions!$B$69,Y17*(1-Assumptions!$B$70),IF(Z16>=1,Assumptions!$B$61*CHOOSE(Assumptions!$B$68,INDEX(Assumptions!$B$42:$H$42,MIN(Z16,7)),INDEX(Assumptions!$B$43:$H$43,MIN(Z16,7))),0)) -> 0.0016106127
A18: Product net sales, risk-adjusted | C18: =Assumptions!$B$32*C15+(1-Assumptions!$B$32)*Assumptions!$B$33*C17 -> 39 | D18: =Assumptions!$B$32*D15+(1-Assumptions!$B$32)*Assumptions!$B$33*D17 -> 97.5 | E18: =Assumptions!$B$32*E15+(1-Assumptions!$B$32)*Assumptions!$B$33*E17 -> 175.5 | F18: =Assumptions!$B$32*F15+(1-Assumptions!$B$32)*Assumptions!$B$33*F17 -> 265.05 | G18: =Assumptions!$B$32*G15+(1-Assumptions!$B$32)*Assumptions!$B$33*G17 -> 348.675 | H18: =Assumptions!$B$32*H15+(1-Assumptions!$B$32)*Assumptions!$B$33*H17 -> 414.675 | I18: =Assumptions!$B$32*I15+(1-Assumptions!$B$32)*Assumptions!$B$33*I17 -> 465.075 | J18: =Assumptions!$B$32*J15+(1-Assumptions!$B$32)*Assumptions!$B$33*J17 -> 484.71 | ... Z18: =Assumptions!$B$32*Z15+(1-Assumptions!$B$32)*Assumptions!$B$33*Z17 -> 0.0013569412
A19: Company revenue, risk-adjusted (incl. milestones) | C19: =C18*Assumptions!$B$63 -> 39 | D19: =D18*Assumptions!$B$63 -> 97.5 | E19: =E18*Assumptions!$B$63 -> 175.5 | F19: =F18*Assumptions!$B$63 -> 265.05 | G19: =G18*Assumptions!$B$63 -> 348.675 | H19: =H18*Assumptions!$B$63 -> 414.675 | I19: =I18*Assumptions!$B$63 -> 465.075 | J19: =J18*Assumptions!$B$63 -> 484.71 | ... Z19: =Z18*Assumptions!$B$63 -> 0.0013569412
A20: COGS + royalties, risk-adjusted | C20: =C18*(Assumptions!$B$64+Assumptions!$B$65) -> 2.34 | D20: =D18*(Assumptions!$B$64+Assumptions!$B$65) -> 5.85 | E20: =E18*(Assumptions!$B$64+Assumptions!$B$65) -> 10.53 | F20: =F18*(Assumptions!$B$64+Assumptions!$B$65) -> 15.903 | G20: =G18*(Assumptions!$B$64+Assumptions!$B$65) -> 20.9205 | H20: =H18*(Assumptions!$B$64+Assumptions!$B$65) -> 24.8805 | I20: =I18*(Assumptions!$B$64+Assumptions!$B$65) -> 27.9045 | J20: =J18*(Assumptions!$B$64+Assumptions!$B$65) -> 29.0826 | ... Z20: =Z18*(Assumptions!$B$64+Assumptions!$B$65) -> 8.1416474e-05
A21: Commercial SG&A, risk-adjusted | C21: =Assumptions!$B$32*IF(Assumptions!$B$66=0,0,IF(C14=0,Assumptions!$B$67,IF(C14>=1,C15*IF(OR(Assumptions!$B$63<1,C14>5),Assumptions!$B$66,MAX(Assumptions!$B$66,INDEX(Assumptions!$B$44:$F$44,C14))),0)))+(1-Assumptions!$B$32)*Assumptions!$B$33*IF(Assumptions!$B$66=0,0,IF(C16=0,Assumptions!$B$67,IF(C16>=1,C17*IF(OR(Assumptions!$B$63<1,C16>5),Assumptions!$B$66,MAX(Assumptions!$B$66,INDEX(Assumptions!$B$44:$F$44,C16))),0))) -> 35.1 | D21: =Assumptions!$B$32*IF(Assumptions!$B$66=0,0,IF(D14=0,Assumptions!$B$67,IF(D14>=1,D15*IF(OR(Assumptions!$B$63<1,D14>5),Assumptions!$B$66,MAX(Assumptions!$B$66,INDEX(Assumptions!$B$44:$F$44,D14))),0)))+(1-Assumptions!$B$32)*Assumptions!$B$33*IF(Assumptions!$B$66=0,0,IF(D16=0,Assumptions!$B$67,IF(D16>=1,D17*IF(OR(Assumptions!$B$63<1,D16>5),Assumptions!$B$66,MAX(Assumptions!$B$66,INDEX(Assumptions!$B$44:$F$44,D16))),0))) -> 53.625 | E21: =Assumptions!$B$32*IF(Assumptions!$B$66=0,0,IF(E14=0,Assumptions!$B$67,IF(E14>=1,E15*IF(OR(Assumptions!$B$63<1,E14>5),Assumptions!$B$66,MAX(Assumptions!$B$66,INDEX(Assumptions!$B$44:$F$44,E14))),0)))+(1-Assumptions!$B$32)*Assumptions!$B$33*IF(Assumptions!$B$66=0,0,IF(E16=0,Assumptions!$B$67,IF(E16>=1,E17*IF(OR(Assumptions!$B$63<1,E16>5),Assumptions!$B$66,MAX(Assumptions!$B$66,INDEX(Assumptions!$B$44:$F$44,E16))),0))) -> 74.05 | F21: =Assumptions!$B$32*IF(Assumptions!$B$66=0,0,IF(F14=0,Assumptions!$B$67,IF(F14>=1,F15*IF(OR(Assumptions!$B$63<1,F14>5),Assumptions!$B$66,MAX(Assumptions!$B$66,INDEX(Assumptions!$B$44:$F$44,F14))),0)))+(1-Assumptions!$B$32)*Assumptions!$B$33*IF(Assumptions!$B$66=0,0,IF(F16=0,Assumptions!$B$67,IF(F16>=1,F17*IF(OR(Assumptions!$B$63<1,F16>5),Assumptions!$B$66,MAX(Assumptions!$B$66,INDEX(Assumptions!$B$44:$F$44,F16))),0))) -> 91.515 | G21: =Assumptions!$B$32*IF(Assumptions!$B$66=0,0,IF(G14=0,Assumptions!$B$67,IF(G14>=1,G15*IF(OR(Assumptions!$B$63<1,G14>5),Assumptions!$B$66,MAX(Assumptions!$B$66,INDEX(Assumptions!$B$44:$F$44,G14))),0)))+(1-Assumptions!$B$32)*Assumptions!$B$33*IF(Assumptions!$B$66=0,0,IF(G16=0,Assumptions!$B$67,IF(G16>=1,G17*IF(OR(Assumptions!$B$63<1,G16>5),Assumptions!$B$66,MAX(Assumptions!$B$66,INDEX(Assumptions!$B$44:$F$44,G16))),0))) -> 105.42525 | H21: =Assumptions!$B$32*IF(Assumptions!$B$66=0,0,IF(H14=0,Assumptions!$B$67,IF(H14>=1,H15*IF(OR(Assumptions!$B$63<1,H14>5),Assumptions!$B$66,MAX(Assumptions!$B$66,INDEX(Assumptions!$B$44:$F$44,H14))),0)))+(1-Assumptions!$B$32)*Assumptions!$B$33*IF(Assumptions!$B$66=0,0,IF(H16=0,Assumptions!$B$67,IF(H16>=1,H17*IF(OR(Assumptions!$B$63<1,H16>5),Assumptions!$B$66,MAX(Assumptions!$B$66,INDEX(Assumptions!$B$44:$F$44,H16))),0))) -> 111.465 | I21: =Assumptions!$B$32*IF(Assumptions!$B$66=0,0,IF(I14=0,Assumptions!$B$67,IF(I14>=1,I15*IF(OR(Assumptions!$B$63<1,I14>5),Assumptions!$B$66,MAX(Assumptions!$B$66,INDEX(Assumptions!$B$44:$F$44,I14))),0)))+(1-Assumptions!$B$32)*Assumptions!$B$33*IF(Assumptions!$B$66=0,0,IF(I16=0,Assumptions!$B$67,IF(I16>=1,I17*IF(OR(Assumptions!$B$63<1,I16>5),Assumptions!$B$66,MAX(Assumptions!$B$66,INDEX(Assumptions!$B$44:$F$44,I16))),0))) -> 121.524 | J21: =Assumptions!$B$32*IF(Assumptions!$B$66=0,0,IF(J14=0,Assumptions!$B$67,IF(J14>=1,J15*IF(OR(Assumptions!$B$63<1,J14>5),Assumptions!$B$66,MAX(Assumptions!$B$66,INDEX(Assumptions!$B$44:$F$44,J14))),0)))+(1-Assumptions!$B$32)*Assumptions!$B$33*IF(Assumptions!$B$66=0,0,IF(J16=0,Assumptions!$B$67,IF(J16>=1,J17*IF(OR(Assumptions!$B$63<1,J16>5),Assumptions!$B$66,MAX(Assumptions!$B$66,INDEX(Assumptions!$B$44:$F$44,J16))),0))) -> 124.0188 | ... Z21: =Assumptions!$B$32*IF(Assumptions!$B$66=0,0,IF(Z14=0,Assumptions!$B$67,IF(Z14>=1,Z15*IF(OR(Assumptions!$B$63<1,Z14>5),Assumptions!$B$66,MAX(Assumptions!$B$66,INDEX(Assumptions!$B$44:$F$44,Z14))),0)))+(1-Assumptions!$B$32)*Assumptions!$B$33*IF(Assumptions!$B$66=0,0,IF(Z16=0,Assumptions!$B$67,IF(Z16>=1,Z17*IF(OR(Assumptions!$B$63<1,Z16>5),Assumptions!$B$66,MAX(Assumptions!$B$66,INDEX(Assumptions!$B$44:$F$44,Z16))),0))) -> 0.00033923531
A22: Development R&D, risk-adjusted | C22: =IFERROR(INDEX(Assumptions!$B$72:$I$72,MATCH(C$2,Assumptions!$B$71:$I$71,0))*INDEX(Assumptions!$B$73:$I$73,MATCH(C$2,Assumptions!$B$71:$I$71,0)),0) -> 40 | D22: =IFERROR(INDEX(Assumptions!$B$72:$I$72,MATCH(D$2,Assumptions!$B$71:$I$71,0))*INDEX(Assumptions!$B$73:$I$73,MATCH(D$2,Assumptions!$B$71:$I$71,0)),0) -> 40 | E22: =IFERROR(INDEX(Assumptions!$B$72:$I$72,MATCH(E$2,Assumptions!$B$71:$I$71,0))*INDEX(Assumptions!$B$73:$I$73,MATCH(E$2,Assumptions!$B$71:$I$71,0)),0) -> 30 | F22: =IFERROR(INDEX(Assumptions!$B$72:$I$72,MATCH(F$2,Assumptions!$B$71:$I$71,0))*INDEX(Assumptions!$B$73:$I$73,MATCH(F$2,Assumptions!$B$71:$I$71,0)),0) -> 0 | G22: =IFERROR(INDEX(Assumptions!$B$72:$I$72,MATCH(G$2,Assumptions!$B$71:$I$71,0))*INDEX(Assumptions!$B$73:$I$73,MATCH(G$2,Assumptions!$B$71:$I$71,0)),0) -> 0 | H22: =IFERROR(INDEX(Assumptions!$B$72:$I$72,MATCH(H$2,Assumptions!$B$71:$I$71,0))*INDEX(Assumptions!$B$73:$I$73,MATCH(H$2,Assumptions!$B$71:$I$71,0)),0) -> 0 | I22: =IFERROR(INDEX(Assumptions!$B$72:$I$72,MATCH(I$2,Assumptions!$B$71:$I$71,0))*INDEX(Assumptions!$B$73:$I$73,MATCH(I$2,Assumptions!$B$71:$I$71,0)),0) -> 0 | J22: =IFERROR(INDEX(Assumptions!$B$72:$I$72,MATCH(J$2,Assumptions!$B$71:$I$71,0))*INDEX(Assumptions!$B$73:$I$73,MATCH(J$2,Assumptions!$B$71:$I$71,0)),0) -> 0 | ... Z22: =IFERROR(INDEX(Assumptions!$B$72:$I$72,MATCH(Z$2,Assumptions!$B$71:$I$71,0))*INDEX(Assumptions!$B$73:$I$73,MATCH(Z$2,Assumptions!$B$71:$I$71,0)),0) -> 0
A23: Program contribution (pre-tax) | C23: =C19-C20-C21-C22 -> -38.44 | D23: =D19-D20-D21-D22 -> -1.975 | E23: =E19-E20-E21-E22 -> 60.92 | F23: =F19-F20-F21-F22 -> 157.632 | G23: =G19-G20-G21-G22 -> 222.32925 | H23: =H19-H20-H21-H22 -> 278.3295 | I23: =I19-I20-I21-I22 -> 315.6465 | J23: =J19-J20-J21-J22 -> 331.6086 | ... Z23: =Z19-Z20-Z21-Z22 -> 0.00093628945
A25: Cevidoplenib — immune thrombocytopenia
A26: Years since launch | C26: =C$2-Assumptions!$B$76+1 -> -3 | D26: =D$2-Assumptions!$B$76+1 -> -2 | E26: =E$2-Assumptions!$B$76+1 -> -1 | F26: =F$2-Assumptions!$B$76+1 -> 0 | G26: =G$2-Assumptions!$B$76+1 -> 1 | H26: =H$2-Assumptions!$B$76+1 -> 2 | I26: =I$2-Assumptions!$B$76+1 -> 3 | J26: =J$2-Assumptions!$B$76+1 -> 4 | ... Z26: =Z$2-Assumptions!$B$76+1 -> 20
A27: Net sales, unrisked | C27: =IF(C$2>Assumptions!$B$85,0*(1-Assumptions!$B$86),IF(C26>=1,Assumptions!$B$77*CHOOSE(Assumptions!$B$84,INDEX(Assumptions!$B$42:$H$42,MIN(C26,7)),INDEX(Assumptions!$B$43:$H$43,MIN(C26,7))),0)) -> 0 | D27: =IF(D$2>Assumptions!$B$85,C27*(1-Assumptions!$B$86),IF(D26>=1,Assumptions!$B$77*CHOOSE(Assumptions!$B$84,INDEX(Assumptions!$B$42:$H$42,MIN(D26,7)),INDEX(Assumptions!$B$43:$H$43,MIN(D26,7))),0)) -> 0 | E27: =IF(E$2>Assumptions!$B$85,D27*(1-Assumptions!$B$86),IF(E26>=1,Assumptions!$B$77*CHOOSE(Assumptions!$B$84,INDEX(Assumptions!$B$42:$H$42,MIN(E26,7)),INDEX(Assumptions!$B$43:$H$43,MIN(E26,7))),0)) -> 0 | F27: =IF(F$2>Assumptions!$B$85,E27*(1-Assumptions!$B$86),IF(F26>=1,Assumptions!$B$77*CHOOSE(Assumptions!$B$84,INDEX(Assumptions!$B$42:$H$42,MIN(F26,7)),INDEX(Assumptions!$B$43:$H$43,MIN(F26,7))),0)) -> 0 | G27: =IF(G$2>Assumptions!$B$85,F27*(1-Assumptions!$B$86),IF(G26>=1,Assumptions!$B$77*CHOOSE(Assumptions!$B$84,INDEX(Assumptions!$B$42:$H$42,MIN(G26,7)),INDEX(Assumptions!$B$43:$H$43,MIN(G26,7))),0)) -> 70 | H27: =IF(H$2>Assumptions!$B$85,G27*(1-Assumptions!$B$86),IF(H26>=1,Assumptions!$B$77*CHOOSE(Assumptions!$B$84,INDEX(Assumptions!$B$42:$H$42,MIN(H26,7)),INDEX(Assumptions!$B$43:$H$43,MIN(H26,7))),0)) -> 175 | I27: =IF(I$2>Assumptions!$B$85,H27*(1-Assumptions!$B$86),IF(I26>=1,Assumptions!$B$77*CHOOSE(Assumptions!$B$84,INDEX(Assumptions!$B$42:$H$42,MIN(I26,7)),INDEX(Assumptions!$B$43:$H$43,MIN(I26,7))),0)) -> 315 | J27: =IF(J$2>Assumptions!$B$85,I27*(1-Assumptions!$B$86),IF(J26>=1,Assumptions!$B$77*CHOOSE(Assumptions!$B$84,INDEX(Assumptions!$B$42:$H$42,MIN(J26,7)),INDEX(Assumptions!$B$43:$H$43,MIN(J26,7))),0)) -> 455 | K27: =IF(K$2>Assumptions!$B$85,J27*(1-Assumptions!$B$86),IF(K26>=1,Assumptions!$B$77*CHOOSE(Assumptions!$B$84,INDEX(Assumptions!$B$42:$H$42,MIN(K26,7)),INDEX(Assumptions!$B$43:$H$43,MIN(K26,7))),0)) -> 574 | ... Z27: =IF(Z$2>Assumptions!$B$85,Y27*(1-Assumptions!$B$86),IF(Z26>=1,Assumptions!$B$77*CHOOSE(Assumptions!$B$84,INDEX(Assumptions!$B$42:$H$42,MIN(Z26,7)),INDEX(Assumptions!$B$43:$H$43,MIN(Z26,7))),0)) -> 0.1835008
A28: Product net sales, risk-adjusted | C28: =C27*MIN(1,Assumptions!$B$78*Assumptions!$B$37) -> 0 | D28: =D27*MIN(1,Assumptions!$B$78*Assumptions!$B$37) -> 0 | E28: =E27*MIN(1,Assumptions!$B$78*Assumptions!$B$37) -> 0 | F28: =F27*MIN(1,Assumptions!$B$78*Assumptions!$B$37) -> 0 | G28: =G27*MIN(1,Assumptions!$B$78*Assumptions!$B$37) -> 28 | H28: =H27*MIN(1,Assumptions!$B$78*Assumptions!$B$37) -> 70 | I28: =I27*MIN(1,Assumptions!$B$78*Assumptions!$B$37) -> 126 | J28: =J27*MIN(1,Assumptions!$B$78*Assumptions!$B$37) -> 182 | ... Z28: =Z27*MIN(1,Assumptions!$B$78*Assumptions!$B$37) -> 0.07340032
A29: Company revenue, risk-adjusted (incl. milestones) | C29: =C28*Assumptions!$B$79 -> 0 | D29: =D28*Assumptions!$B$79 -> 0 | E29: =E28*Assumptions!$B$79 -> 0 | F29: =F28*Assumptions!$B$79 -> 0 | G29: =G28*Assumptions!$B$79 -> 28 | H29: =H28*Assumptions!$B$79 -> 70 | I29: =I28*Assumptions!$B$79 -> 126 | J29: =J28*Assumptions!$B$79 -> 182 | ... Z29: =Z28*Assumptions!$B$79 -> 0.07340032
A30: COGS + royalties, risk-adjusted | C30: =C28*(Assumptions!$B$80+Assumptions!$B$81) -> 0 | D30: =D28*(Assumptions!$B$80+Assumptions!$B$81) -> 0 | E30: =E28*(Assumptions!$B$80+Assumptions!$B$81) -> 0 | F30: =F28*(Assumptions!$B$80+Assumptions!$B$81) -> 0 | G30: =G28*(Assumptions!$B$80+Assumptions!$B$81) -> 3.64 | H30: =H28*(Assumptions!$B$80+Assumptions!$B$81) -> 9.1 | I30: =I28*(Assumptions!$B$80+Assumptions!$B$81) -> 16.38 | J30: =J28*(Assumptions!$B$80+Assumptions!$B$81) -> 23.66 | ... Z30: =Z28*(Assumptions!$B$80+Assumptions!$B$81) -> 0.0095420416
A31: Commercial SG&A, risk-adjusted | C31: =MIN(1,Assumptions!$B$78*Assumptions!$B$37)*IF(Assumptions!$B$82=0,0,IF(C26=0,Assumptions!$B$83,IF(C26>=1,C27*IF(OR(Assumptions!$B$79<1,C26>5),Assumptions!$B$82,MAX(Assumptions!$B$82,INDEX(Assumptions!$B$44:$F$44,C26))),0))) -> 0 | D31: =MIN(1,Assumptions!$B$78*Assumptions!$B$37)*IF(Assumptions!$B$82=0,0,IF(D26=0,Assumptions!$B$83,IF(D26>=1,D27*IF(OR(Assumptions!$B$79<1,D26>5),Assumptions!$B$82,MAX(Assumptions!$B$82,INDEX(Assumptions!$B$44:$F$44,D26))),0))) -> 0 | E31: =MIN(1,Assumptions!$B$78*Assumptions!$B$37)*IF(Assumptions!$B$82=0,0,IF(E26=0,Assumptions!$B$83,IF(E26>=1,E27*IF(OR(Assumptions!$B$79<1,E26>5),Assumptions!$B$82,MAX(Assumptions!$B$82,INDEX(Assumptions!$B$44:$F$44,E26))),0))) -> 0 | F31: =MIN(1,Assumptions!$B$78*Assumptions!$B$37)*IF(Assumptions!$B$82=0,0,IF(F26=0,Assumptions!$B$83,IF(F26>=1,F27*IF(OR(Assumptions!$B$79<1,F26>5),Assumptions!$B$82,MAX(Assumptions!$B$82,INDEX(Assumptions!$B$44:$F$44,F26))),0))) -> 12 | G31: =MIN(1,Assumptions!$B$78*Assumptions!$B$37)*IF(Assumptions!$B$82=0,0,IF(G26=0,Assumptions!$B$83,IF(G26>=1,G27*IF(OR(Assumptions!$B$79<1,G26>5),Assumptions!$B$82,MAX(Assumptions!$B$82,INDEX(Assumptions!$B$44:$F$44,G26))),0))) -> 25.2 | H31: =MIN(1,Assumptions!$B$78*Assumptions!$B$37)*IF(Assumptions!$B$82=0,0,IF(H26=0,Assumptions!$B$83,IF(H26>=1,H27*IF(OR(Assumptions!$B$79<1,H26>5),Assumptions!$B$82,MAX(Assumptions!$B$82,INDEX(Assumptions!$B$44:$F$44,H26))),0))) -> 38.5 | I31: =MIN(1,Assumptions!$B$78*Assumptions!$B$37)*IF(Assumptions!$B$82=0,0,IF(I26=0,Assumptions!$B$83,IF(I26>=1,I27*IF(OR(Assumptions!$B$79<1,I26>5),Assumptions!$B$82,MAX(Assumptions!$B$82,INDEX(Assumptions!$B$44:$F$44,I26))),0))) -> 50.4 | J31: =MIN(1,Assumptions!$B$78*Assumptions!$B$37)*IF(Assumptions!$B$82=0,0,IF(J26=0,Assumptions!$B$83,IF(J26>=1,J27*IF(OR(Assumptions!$B$79<1,J26>5),Assumptions!$B$82,MAX(Assumptions!$B$82,INDEX(Assumptions!$B$44:$F$44,J26))),0))) -> 58.24 | ... Z31: =MIN(1,Assumptions!$B$78*Assumptions!$B$37)*IF(Assumptions!$B$82=0,0,IF(Z26=0,Assumptions!$B$83,IF(Z26>=1,Z27*IF(OR(Assumptions!$B$79<1,Z26>5),Assumptions!$B$82,MAX(Assumptions!$B$82,INDEX(Assumptions!$B$44:$F$44,Z26))),0))) -> 0.022020096
A32: Development R&D, risk-adjusted | C32: =IFERROR(INDEX(Assumptions!$B$88:$I$88,MATCH(C$2,Assumptions!$B$87:$I$87,0))*INDEX(Assumptions!$B$89:$I$89,MATCH(C$2,Assumptions!$B$87:$I$87,0)),0) -> 15 | D32: =IFERROR(INDEX(Assumptions!$B$88:$I$88,MATCH(D$2,Assumptions!$B$87:$I$87,0))*INDEX(Assumptions!$B$89:$I$89,MATCH(D$2,Assumptions!$B$87:$I$87,0)),0) -> 60 | E32: =IFERROR(INDEX(Assumptions!$B$88:$I$88,MATCH(E$2,Assumptions!$B$87:$I$87,0))*INDEX(Assumptions!$B$89:$I$89,MATCH(E$2,Assumptions!$B$87:$I$87,0)),0) -> 80 | F32: =IFERROR(INDEX(Assumptions!$B$88:$I$88,MATCH(F$2,Assumptions!$B$87:$I$87,0))*INDEX(Assumptions!$B$89:$I$89,MATCH(F$2,Assumptions!$B$87:$I$87,0)),0) -> 27.5 | G32: =IFERROR(INDEX(Assumptions!$B$88:$I$88,MATCH(G$2,Assumptions!$B$87:$I$87,0))*INDEX(Assumptions!$B$89:$I$89,MATCH(G$2,Assumptions!$B$87:$I$87,0)),0) -> 0 | H32: =IFERROR(INDEX(Assumptions!$B$88:$I$88,MATCH(H$2,Assumptions!$B$87:$I$87,0))*INDEX(Assumptions!$B$89:$I$89,MATCH(H$2,Assumptions!$B$87:$I$87,0)),0) -> 0 | I32: =IFERROR(INDEX(Assumptions!$B$88:$I$88,MATCH(I$2,Assumptions!$B$87:$I$87,0))*INDEX(Assumptions!$B$89:$I$89,MATCH(I$2,Assumptions!$B$87:$I$87,0)),0) -> 0 | J32: =IFERROR(INDEX(Assumptions!$B$88:$I$88,MATCH(J$2,Assumptions!$B$87:$I$87,0))*INDEX(Assumptions!$B$89:$I$89,MATCH(J$2,Assumptions!$B$87:$I$87,0)),0) -> 0 | ... Z32: =IFERROR(INDEX(Assumptions!$B$88:$I$88,MATCH(Z$2,Assumptions!$B$87:$I$87,0))*INDEX(Assumptions!$B$89:$I$89,MATCH(Z$2,Assumptions!$B$87:$I$87,0)),0) -> 0
A33: Program contribution (pre-tax) | C33: =C29-C30-C31-C32 -> -15 | D33: =D29-D30-D31-D32 -> -60 | E33: =E29-E30-E31-E32 -> -80 | F33: =F29-F30-F31-F32 -> -39.5 | G33: =G29-G30-G31-G32 -> -0.84 | H33: =H29-H30-H31-H32 -> 22.4 | I33: =I29-I30-I31-I32 -> 59.22 | J33: =J29-J30-J31-J32 -> 100.1 | ... Z33: =Z29-Z30-Z31-Z32 -> 0.041838182
A35: AG-236 — polycythemia vera
A36: Years since launch | C36: =C$2-Assumptions!$B$92+1 -> -3 | D36: =D$2-Assumptions!$B$92+1 -> -2 | E36: =E$2-Assumptions!$B$92+1 -> -1 | F36: =F$2-Assumptions!$B$92+1 -> 0 | G36: =G$2-Assumptions!$B$92+1 -> 1 | H36: =H$2-Assumptions!$B$92+1 -> 2 | I36: =I$2-Assumptions!$B$92+1 -> 3 | J36: =J$2-Assumptions!$B$92+1 -> 4 | ... Z36: =Z$2-Assumptions!$B$92+1 -> 20
A37: Net sales, unrisked | C37: =IF(C$2>Assumptions!$B$101,0*(1-Assumptions!$B$102),IF(C36>=1,Assumptions!$B$93*CHOOSE(Assumptions!$B$100,INDEX(Assumptions!$B$42:$H$42,MIN(C36,7)),INDEX(Assumptions!$B$43:$H$43,MIN(C36,7))),0)) -> 0 | D37: =IF(D$2>Assumptions!$B$101,C37*(1-Assumptions!$B$102),IF(D36>=1,Assumptions!$B$93*CHOOSE(Assumptions!$B$100,INDEX(Assumptions!$B$42:$H$42,MIN(D36,7)),INDEX(Assumptions!$B$43:$H$43,MIN(D36,7))),0)) -> 0 | E37: =IF(E$2>Assumptions!$B$101,D37*(1-Assumptions!$B$102),IF(E36>=1,Assumptions!$B$93*CHOOSE(Assumptions!$B$100,INDEX(Assumptions!$B$42:$H$42,MIN(E36,7)),INDEX(Assumptions!$B$43:$H$43,MIN(E36,7))),0)) -> 0 | F37: =IF(F$2>Assumptions!$B$101,E37*(1-Assumptions!$B$102),IF(F36>=1,Assumptions!$B$93*CHOOSE(Assumptions!$B$100,INDEX(Assumptions!$B$42:$H$42,MIN(F36,7)),INDEX(Assumptions!$B$43:$H$43,MIN(F36,7))),0)) -> 0 | G37: =IF(G$2>Assumptions!$B$101,F37*(1-Assumptions!$B$102),IF(G36>=1,Assumptions!$B$93*CHOOSE(Assumptions!$B$100,INDEX(Assumptions!$B$42:$H$42,MIN(G36,7)),INDEX(Assumptions!$B$43:$H$43,MIN(G36,7))),0)) -> 90 | H37: =IF(H$2>Assumptions!$B$101,G37*(1-Assumptions!$B$102),IF(H36>=1,Assumptions!$B$93*CHOOSE(Assumptions!$B$100,INDEX(Assumptions!$B$42:$H$42,MIN(H36,7)),INDEX(Assumptions!$B$43:$H$43,MIN(H36,7))),0)) -> 225 | I37: =IF(I$2>Assumptions!$B$101,H37*(1-Assumptions!$B$102),IF(I36>=1,Assumptions!$B$93*CHOOSE(Assumptions!$B$100,INDEX(Assumptions!$B$42:$H$42,MIN(I36,7)),INDEX(Assumptions!$B$43:$H$43,MIN(I36,7))),0)) -> 405 | J37: =IF(J$2>Assumptions!$B$101,I37*(1-Assumptions!$B$102),IF(J36>=1,Assumptions!$B$93*CHOOSE(Assumptions!$B$100,INDEX(Assumptions!$B$42:$H$42,MIN(J36,7)),INDEX(Assumptions!$B$43:$H$43,MIN(J36,7))),0)) -> 585 | K37: =IF(K$2>Assumptions!$B$101,J37*(1-Assumptions!$B$102),IF(K36>=1,Assumptions!$B$93*CHOOSE(Assumptions!$B$100,INDEX(Assumptions!$B$42:$H$42,MIN(K36,7)),INDEX(Assumptions!$B$43:$H$43,MIN(K36,7))),0)) -> 738 | ... Z37: =IF(Z$2>Assumptions!$B$101,Y37*(1-Assumptions!$B$102),IF(Z36>=1,Assumptions!$B$93*CHOOSE(Assumptions!$B$100,INDEX(Assumptions!$B$42:$H$42,MIN(Z36,7)),INDEX(Assumptions!$B$43:$H$43,MIN(Z36,7))),0)) -> 1.47456
A38: Product net sales, risk-adjusted | C38: =C37*MIN(1,Assumptions!$B$94*Assumptions!$B$37) -> 0 | D38: =D37*MIN(1,Assumptions!$B$94*Assumptions!$B$37) -> 0 | E38: =E37*MIN(1,Assumptions!$B$94*Assumptions!$B$37) -> 0 | F38: =F37*MIN(1,Assumptions!$B$94*Assumptions!$B$37) -> 0 | G38: =G37*MIN(1,Assumptions!$B$94*Assumptions!$B$37) -> 19.8 | H38: =H37*MIN(1,Assumptions!$B$94*Assumptions!$B$37) -> 49.5 | I38: =I37*MIN(1,Assumptions!$B$94*Assumptions!$B$37) -> 89.1 | J38: =J37*MIN(1,Assumptions!$B$94*Assumptions!$B$37) -> 128.7 | ... Z38: =Z37*MIN(1,Assumptions!$B$94*Assumptions!$B$37) -> 0.3244032
A39: Company revenue, risk-adjusted (incl. milestones) | C39: =C38*Assumptions!$B$95 -> 0 | D39: =D38*Assumptions!$B$95 -> 0 | E39: =E38*Assumptions!$B$95 -> 0 | F39: =F38*Assumptions!$B$95 -> 0 | G39: =G38*Assumptions!$B$95 -> 19.8 | H39: =H38*Assumptions!$B$95 -> 49.5 | I39: =I38*Assumptions!$B$95 -> 89.1 | J39: =J38*Assumptions!$B$95 -> 128.7 | ... Z39: =Z38*Assumptions!$B$95 -> 0.3244032
A40: COGS + royalties, risk-adjusted | C40: =C38*(Assumptions!$B$96+Assumptions!$B$97) -> 0 | D40: =D38*(Assumptions!$B$96+Assumptions!$B$97) -> 0 | E40: =E38*(Assumptions!$B$96+Assumptions!$B$97) -> 0 | F40: =F38*(Assumptions!$B$96+Assumptions!$B$97) -> 0 | G40: =G38*(Assumptions!$B$96+Assumptions!$B$97) -> 2.574 | H40: =H38*(Assumptions!$B$96+Assumptions!$B$97) -> 6.435 | I40: =I38*(Assumptions!$B$96+Assumptions!$B$97) -> 11.583 | J40: =J38*(Assumptions!$B$96+Assumptions!$B$97) -> 16.731 | ... Z40: =Z38*(Assumptions!$B$96+Assumptions!$B$97) -> 0.042172416
A41: Commercial SG&A, risk-adjusted | C41: =MIN(1,Assumptions!$B$94*Assumptions!$B$37)*IF(Assumptions!$B$98=0,0,IF(C36=0,Assumptions!$B$99,IF(C36>=1,C37*IF(OR(Assumptions!$B$95<1,C36>5),Assumptions!$B$98,MAX(Assumptions!$B$98,INDEX(Assumptions!$B$44:$F$44,C36))),0))) -> 0 | D41: =MIN(1,Assumptions!$B$94*Assumptions!$B$37)*IF(Assumptions!$B$98=0,0,IF(D36=0,Assumptions!$B$99,IF(D36>=1,D37*IF(OR(Assumptions!$B$95<1,D36>5),Assumptions!$B$98,MAX(Assumptions!$B$98,INDEX(Assumptions!$B$44:$F$44,D36))),0))) -> 0 | E41: =MIN(1,Assumptions!$B$94*Assumptions!$B$37)*IF(Assumptions!$B$98=0,0,IF(E36=0,Assumptions!$B$99,IF(E36>=1,E37*IF(OR(Assumptions!$B$95<1,E36>5),Assumptions!$B$98,MAX(Assumptions!$B$98,INDEX(Assumptions!$B$44:$F$44,E36))),0))) -> 0 | F41: =MIN(1,Assumptions!$B$94*Assumptions!$B$37)*IF(Assumptions!$B$98=0,0,IF(F36=0,Assumptions!$B$99,IF(F36>=1,F37*IF(OR(Assumptions!$B$95<1,F36>5),Assumptions!$B$98,MAX(Assumptions!$B$98,INDEX(Assumptions!$B$44:$F$44,F36))),0))) -> 6.6 | G41: =MIN(1,Assumptions!$B$94*Assumptions!$B$37)*IF(Assumptions!$B$98=0,0,IF(G36=0,Assumptions!$B$99,IF(G36>=1,G37*IF(OR(Assumptions!$B$95<1,G36>5),Assumptions!$B$98,MAX(Assumptions!$B$98,INDEX(Assumptions!$B$44:$F$44,G36))),0))) -> 17.82 | H41: =MIN(1,Assumptions!$B$94*Assumptions!$B$37)*IF(Assumptions!$B$98=0,0,IF(H36=0,Assumptions!$B$99,IF(H36>=1,H37*IF(OR(Assumptions!$B$95<1,H36>5),Assumptions!$B$98,MAX(Assumptions!$B$98,INDEX(Assumptions!$B$44:$F$44,H36))),0))) -> 27.225 | I41: =MIN(1,Assumptions!$B$94*Assumptions!$B$37)*IF(Assumptions!$B$98=0,0,IF(I36=0,Assumptions!$B$99,IF(I36>=1,I37*IF(OR(Assumptions!$B$95<1,I36>5),Assumptions!$B$98,MAX(Assumptions!$B$98,INDEX(Assumptions!$B$44:$F$44,I36))),0))) -> 35.64 | J41: =MIN(1,Assumptions!$B$94*Assumptions!$B$37)*IF(Assumptions!$B$98=0,0,IF(J36=0,Assumptions!$B$99,IF(J36>=1,J37*IF(OR(Assumptions!$B$95<1,J36>5),Assumptions!$B$98,MAX(Assumptions!$B$98,INDEX(Assumptions!$B$44:$F$44,J36))),0))) -> 41.184 | ... Z41: =MIN(1,Assumptions!$B$94*Assumptions!$B$37)*IF(Assumptions!$B$98=0,0,IF(Z36=0,Assumptions!$B$99,IF(Z36>=1,Z37*IF(OR(Assumptions!$B$95<1,Z36>5),Assumptions!$B$98,MAX(Assumptions!$B$98,INDEX(Assumptions!$B$44:$F$44,Z36))),0))) -> 0.09732096
A42: Development R&D, risk-adjusted | C42: =IFERROR(INDEX(Assumptions!$B$104:$I$104,MATCH(C$2,Assumptions!$B$103:$I$103,0))*INDEX(Assumptions!$B$105:$I$105,MATCH(C$2,Assumptions!$B$103:$I$103,0)),0) -> 30 | D42: =IFERROR(INDEX(Assumptions!$B$104:$I$104,MATCH(D$2,Assumptions!$B$103:$I$103,0))*INDEX(Assumptions!$B$105:$I$105,MATCH(D$2,Assumptions!$B$103:$I$103,0)),0) -> 30 | E42: =IFERROR(INDEX(Assumptions!$B$104:$I$104,MATCH(E$2,Assumptions!$B$103:$I$103,0))*INDEX(Assumptions!$B$105:$I$105,MATCH(E$2,Assumptions!$B$103:$I$103,0)),0) -> 35 | F42: =IFERROR(INDEX(Assumptions!$B$104:$I$104,MATCH(F$2,Assumptions!$B$103:$I$103,0))*INDEX(Assumptions!$B$105:$I$105,MATCH(F$2,Assumptions!$B$103:$I$103,0)),0) -> 18 | G42: =IFERROR(INDEX(Assumptions!$B$104:$I$104,MATCH(G$2,Assumptions!$B$103:$I$103,0))*INDEX(Assumptions!$B$105:$I$105,MATCH(G$2,Assumptions!$B$103:$I$103,0)),0) -> 0 | H42: =IFERROR(INDEX(Assumptions!$B$104:$I$104,MATCH(H$2,Assumptions!$B$103:$I$103,0))*INDEX(Assumptions!$B$105:$I$105,MATCH(H$2,Assumptions!$B$103:$I$103,0)),0) -> 0 | I42: =IFERROR(INDEX(Assumptions!$B$104:$I$104,MATCH(I$2,Assumptions!$B$103:$I$103,0))*INDEX(Assumptions!$B$105:$I$105,MATCH(I$2,Assumptions!$B$103:$I$103,0)),0) -> 0 | J42: =IFERROR(INDEX(Assumptions!$B$104:$I$104,MATCH(J$2,Assumptions!$B$103:$I$103,0))*INDEX(Assumptions!$B$105:$I$105,MATCH(J$2,Assumptions!$B$103:$I$103,0)),0) -> 0 | ... Z42: =IFERROR(INDEX(Assumptions!$B$104:$I$104,MATCH(Z$2,Assumptions!$B$103:$I$103,0))*INDEX(Assumptions!$B$105:$I$105,MATCH(Z$2,Assumptions!$B$103:$I$103,0)),0) -> 0
A43: Program contribution (pre-tax) | C43: =C39-C40-C41-C42 -> -30 | D43: =D39-D40-D41-D42 -> -30 | E43: =E39-E40-E41-E42 -> -35 | F43: =F39-F40-F41-F42 -> -24.6 | G43: =G39-G40-G41-G42 -> -0.594 | H43: =H39-H40-H41-H42 -> 15.84 | I43: =I39-I40-I41-I42 -> 41.877 | J43: =J39-J40-J41-J42 -> 70.785 | ... Z43: =Z39-Z40-Z41-Z42 -> 0.18490982
A45: Company totals (risk-adjusted)
...

Sheet NPV
A1: AGIO — risk-adjusted NPV (rNPV), $mm except per share
A3: Scenario | B3: =Assumptions!$C$4 -> Base
A4: Valuation date | B4: =Assumptions!$B$13 -> 46311
A5: Discount rate | B5: =Assumptions!$B$14 -> 0.11
A7: Period | C7: 2H 2026 | D7: 2027 | E7: 2028 | F7: 2029 | G7: 2030 | H7: 2031 | I7: 2032 | J7: 2033 | K7: 2034 | L7: 2035 | M7: 2036 | N7: 2037 | O7: 2038 | P7: 2039 | Q7: 2040 | R7: 2041 | S7: 2042 | T7: 2043 | U7: 2044 | V7: 2045 | W7: 2046 | X7: 2047 | Y7: 2048 | Z7: 2049 | AA7: 2050
A8: Revenue, risk-adjusted | C8: =SUM('Quarterly Model'!H2:I2) -> 140 | D8: ='Yearly Model'!H2 -> 353.392 | E8: ='Yearly Model'!I2 -> 520.794 | F8: ='Yearly Model'!J2 -> 707.696 | G8: ='Yearly Model'!K2 -> 906.148 | H8: ='Yearly Model'!L2 -> 1146.475 | I8: ='Yearly Model'!M2 -> 1284.175 | J8: ='Yearly Model'!N2 -> 1430.175 | K8: ='Yearly Model'!O2 -> 1545.41 | ... AA8: ='Yearly Model'!AE2 -> 0.40117373
A9: Operating income (EBIT) | C9: =SUM('Quarterly Model'!H8:I8) -> -145.4 | D9: ='Yearly Model'!H8 -> -210.82712 | E9: ='Yearly Model'!I8 -> -120.89624 | F9: ='Yearly Model'!J8 -> 10.65652 | G9: ='Yearly Model'!K8 -> 229.35102 | H9: ='Yearly Model'!L8 -> 394.45275 | I9: ='Yearly Model'!M8 -> 448.817 | J9: ='Yearly Model'!N8 -> 505.191 | K9: ='Yearly Model'!O8 -> 556.3706 | ... AA9: ='Yearly Model'!AE8 -> 0.10872133
A10: Taxes on EBIT (after tax-loss pool) | C10: 0 | D10: =IF(D9>0,MAX(0,D9-'Yearly Model'!G21)*Assumptions!$B$15,0) -> 0 | E10: =IF(E9>0,MAX(0,E9-'Yearly Model'!H21)*Assumptions!$B$15,0) -> 0 | F10: =IF(F9>0,MAX(0,F9-'Yearly Model'!I21)*Assumptions!$B$15,0) -> 0 | G10: =IF(G9>0,MAX(0,G9-'Yearly Model'!J21)*Assumptions!$B$15,0) -> 0 | H10: =IF(H9>0,MAX(0,H9-'Yearly Model'!K21)*Assumptions!$B$15,0) -> 0 | I10: =IF(I9>0,MAX(0,I9-'Yearly Model'!L21)*Assumptions!$B$15,0) -> 0 | J10: =IF(J9>0,MAX(0,J9-'Yearly Model'!M21)*Assumptions!$B$15,0) -> 106.09011 | K10: =IF(K9>0,MAX(0,K9-'Yearly Model'!N21)*Assumptions!$B$15,0) -> 116.83783 | ... AA10: =IF(AA9>0,MAX(0,AA9-'Yearly Model'!AD21)*Assumptions!$B$15,0) -> 0.02283148
A11: Unlevered free cash flow | C11: =C9-C10 -> -145.4 | D11: =D9-D10 -> -210.82712 | E11: =E9-E10 -> -120.89624 | F11: =F9-F10 -> 10.65652 | G11: =G9-G10 -> 229.35102 | H11: =H9-H10 -> 394.45275 | I11: =I9-I10 -> 448.817 | J11: =J9-J10 -> 399.10089 | ... AA11: =AA9-AA10 -> 0.085889852
A12: Cash-flow date (mid-period) | C12: =DATE(2026,10,1) -> 46296 | D12: =DATE(D7,7,1) -> 46569 | E12: =DATE(E7,7,1) -> 46935 | F12: =DATE(F7,7,1) -> 47300 | G12: =DATE(G7,7,1) -> 47665 | H12: =DATE(H7,7,1) -> 48030 | I12: =DATE(I7,7,1) -> 48396 | J12: =DATE(J7,7,1) -> 48761 | K12: =DATE(K7,7,1) -> 49126 | ... AA12: =DATE(AA7,7,1) -> 54970
A13: Years from valuation date | C13: =MAX(0,(C12-$B$4)/365.25) -> 0 | D13: =MAX(0,(D12-$B$4)/365.25) -> 0.7063655 | E13: =MAX(0,(E12-$B$4)/365.25) -> 1.7084189 | F13: =MAX(0,(F12-$B$4)/365.25) -> 2.7077344 | G13: =MAX(0,(G12-$B$4)/365.25) -> 3.70705 | H13: =MAX(0,(H12-$B$4)/365.25) -> 4.7063655 | I13: =MAX(0,(I12-$B$4)/365.25) -> 5.7084189 | J13: =MAX(0,(J12-$B$4)/365.25) -> 6.7077344 | ... AA13: =MAX(0,(AA12-$B$4)/365.25) -> 23.70705
A14: Discount factor | C14: =1/(1+$B$5)^C13 -> 1 | D14: =1/(1+$B$5)^D13 -> 0.92893518 | E14: =1/(1+$B$5)^E13 -> 0.83669923 | F14: =1/(1+$B$5)^F13 -> 0.75383693 | G14: =1/(1+$B$5)^G13 -> 0.67918088 | H14: =1/(1+$B$5)^H13 -> 0.61191838 | I14: =1/(1+$B$5)^I13 -> 0.5511597 | J14: =1/(1+$B$5)^J13 -> 0.49657574 | ... AA14: =1/(1+$B$5)^AA13 -> 0.084241458
A15: PV of free cash flow | C15: =C11*C14 -> -145.4 | D15: =D11*D14 -> -195.84473 | E15: =E11*E14 -> -101.15379 | F15: =F11*F14 -> 8.0332783 | G15: =G11*G14 -> 155.77083 | H15: =H11*H14 -> 241.37289 | I15: =I11*I14 -> 247.36984 | J15: =J11*J14 -> 198.18382 | ... AA15: =AA11*AA14 -> 0.0072354864
A17: Valuation summary
A18: PV of risk-adjusted free cash flows | C18: =SUM(C15:AA15) -> 1199.5613
A19: Cash & investments (Main; incl. post-quarter financing) | C19: =Main!C7 -> 964.827
A20: Debt, convertibles & preferred at face (Main) | C20: =Main!C8 -> 0
A21: Equity value, all claims treated as debt | C21: =C18+C19-C20 -> 2164.3883
A22: Basic shares incl. pre-funded / as-converted (Main) | C22: =Main!C4 -> 59.701882
A23: Value / share before conversions | C23: =C21/C22 -> 36.253268
A25: Convertible instruments (converted if value / share before conversions > conversion price) | B25: Face ($mm) | C25: Shares (mm) | D25: Conv. price | E25: Converted?
A26: — | B26: 0 | C26: 0 | D26: 0 | E26: =IF(AND(C26>0,$C$23>D26),1,0) -> 0
A27: — | B27: 0 | C27: 0 | D27: 0 | E27: =IF(AND(C27>0,$C$23>D27),1,0) -> 0
A28: — | B28: 0 | C28: 0 | D28: 0 | E28: =IF(AND(C28>0,$C$23>D28),1,0) -> 0
A29: — | B29: 0 | C29: 0 | D29: 0 | E29: =IF(AND(C29>0,$C$23>D29),1,0) -> 0
A30: — | B30: 0 | C30: 0 | D30: 0 | E30: =IF(AND(C30>0,$C$23>D30),1,0) -> 0
A31: Equity value (rNPV) after conversions | C31: =C21+SUMPRODUCT(B26:B30,E26:E30) -> 2164.3883
A32: Shares after conversions (mm) | C32: =C22+SUMPRODUCT(C26:C30,E26:E30) -> 59.701882
A33: Value / share before options & warrants | C33: =C31/C32 -> 36.253268
A35: Options, warrants & RSUs (treasury-stock method) | B35: Count (mm) | C35: Strike | D35: Dilution (mm)
A36: Options | B36: 6.552073 | C36: 38.33 | D36: =IF(AND(B36>0,$C$33>C36),B36*(1-C36/$C$33),0) -> 0
A37: RSUs / PSUs | B37: 2.248 | C37: 0 | D37: =IF(AND(B37>0,$C$33>C37),B37*(1-C37/$C$33),0) -> 2.248
A38: — | B38: 0 | C38: 0 | D38: =IF(AND(B38>0,$C$33>C38),B38*(1-C38/$C$33),0) -> 0
A39: — | B39: 0 | C39: 0 | D39: =IF(AND(B39>0,$C$33>C39),B39*(1-C39/$C$33),0) -> 0
A40: — | B40: 0 | C40: 0 | D40: =IF(AND(B40>0,$C$33>C40),B40*(1-C40/$C$33),0) -> 0
A41: — | B41: 0 | C41: 0 | D41: =IF(AND(B41>0,$C$33>C41),B41*(1-C41/$C$33),0) -> 0
A42: Diluted shares (mm) | C42: =C32+SUM(D36:D41) -> 61.949882
A43: rNPV / share, diluted | C43: =C31/C42 -> 34.937731
A44: Current price (Main) | C44: =Main!C3 -> 36.64
A45: Upside / (downside) to rNPV | C45: =C43/C44-1 -> -0.046459298
...

Sheet Options
A1: AGIO — PDUFA options analysis (per contract = 100 shares)
A3: Inputs
A4: Spot price (close 10/16/2026) | B4: 31.32
A5: Pricing date | B5: =DATE(2026,10,16) -> 46311
A6: PDUFA date | B6: =Assumptions!$B$30 -> 46327
A7: Expiry (first monthly after the PDUFA date) | B7: =DATE(2026,11,20) -> 46346
A8: Years to expiry (T) | B8: =(B7-B5)/365 -> 0.095890411
A9: Risk-free rate | B9: 0.04
A10: Reference IV for wide quotes (theo prices) | B10: 1.0202
A11: Contract multiplier | B11: 100
A13: Event model (two outcomes at the PDUFA)
A14: Model value / share, probability-weighted | B14: =NPV!C43 -> 34.937731
A15: Model value / share if approved | B15: =Assumptions!$D$121 -> 38.238203
A16: Model value / share if CRL | B16: =Assumptions!$D$120 -> 27.888497
A17: Model probability of approval | B17: =Assumptions!$B$32 -> 0.65
A18: Event-move scale (share of model jump priced at expiry) | B18: 1
A19: Floor after a CRL, % of est. 12/31/2026 net cash / share | B19: 0.5
A20: Floor price after a CRL | B20: =MAX(0,B19*(NPV!C47-NPV!C20)/NPV!C22) -> 7.0088499
A21: Price if approved (center of outcome) | B21: =IF(B14>0,B4*(1+B18*(B15/B14-1)),B4+B18*(B15-B14)) -> 34.278715
A22: Price if CRL (center of outcome) | B22: =MAX(B20,IF(B14>0,B4*(1+B18*(B16/B14-1)),B4+B18*(B16-B14))) -> 25.0007
A23: Model expected price after the decision | B23: =B17*B21+(1-B17)*B22 -> 31.03141
A24: Non-event volatility (6-month realized, 3 largest days removed) | B24: 0.421
A25: Model fair ATM straddle, % of spot (jump + non-event volatility) | B25: =(B17*((B21*NORMSDIST(((LN(B21/30.0)+$B$24^2*$B$8/2)/($B$24*SQRT($B$8))))-30.0*NORMSDIST((((LN(B21/30.0)+$B$24^2*$B$8/2)/($B$24*SQRT($B$8)))-$B$24*SQRT($B$8))))+(30.0*NORMSDIST(-(((LN(B21/30.0)+$B$24^2*$B$8/2)/($B$24*SQRT($B$8)))-$B$24*SQRT($B$8)))-B21*NORMSDIST(-((LN(B21/30.0)+$B$24^2*$B$8/2)/($B$24*SQRT($B$8))))))+(1-B17)*((B22*NORMSDIST(((LN(B22/30.0)+$B$24^2*$B$8/2)/($B$24*SQRT($B$8))))-30.0*NORMSDIST((((LN(B22/30.0)+$B$24^2*$B$8/2)/($B$24*SQRT($B$8)))-$B$24*SQRT($B$8))))+(30.0*NORMSDIST(-(((LN(B22/30.0)+$B$24^2*$B$8/2)/($B$24*SQRT($B$8)))-$B$24*SQRT($B$8)))-B22*NORMSDIST(-((LN(B22/30.0)+$B$24^2*$B$8/2)/($B$24*SQRT($B$8)))))))/B4 -> 0.16142222
A26: Market ATM straddle, % of spot | B26: =($G$41+$G$42)/B4 -> 0.24984036
A27: Options richness (market straddle ÷ model straddle) | B27: =B26/B25 -> 1.5477445
A28: Market snapshot — 11/20/2026 expiry (Cboe delayed quotes, 10/16/2026 close)
A29: Strike | B29: Call bid | C29: Call ask | D29: Call mid | E29: Call IV | F29: Put bid | G29: Put ask | H29: Put mid | I29: Put IV | J29: Call OI | K29: Put OI
A30: 17.5 | B30: 11.6 | C30: 16.5 | D30: =(B30+C30)/2 -> 14.05 | E30: 0.7823 | F30: 0 | G30: 4.9 | H30: =(F30+G30)/2 -> 2.45 | I30: 2.6075 | J30: 0 | K30: 8
A31: 20 | B31: 9 | C31: 13.8 | D31: =(B31+C31)/2 -> 11.4 | E31: 0 | F31: 0 | G31: 3 | H31: =(F31+G31)/2 -> 1.5 | I31: 1.7591 | J31: 0 | K31: 13
