Workbook

Sheet Main
B2: BridgeBio Pharma, Inc.
B3: Price | C3: =INDEX([1]Pharma!$F$1:$F$1000,MATCH("BBIO",[1]Pharma!$B$1:$B$1000,0)) -> 67.55
B4: Shares | C4: =195.487474 -> 195.48747
B5: Market Cap. | C5: =C3*C4 -> 13205.179
B7: Cash | C7: =677.911+42.249+1000 -> 1720.16
B8: Debt | C8: =550+747.5+575+632.5+1000 -> 3505
B9: Enterprise V. | C9: =C5-C7+C8 -> 14990.019
B11: rNPV / Share | C11: =NPV!C43 -> 54.634524
B12: Upside | C12: =C11/C3-1 -> -0.19119876
B13: Cash / Share | C13: =(C7-C8)/C4 -> -9.1302014
B14: Scenario | C14: =Assumptions!$C$4 -> Base
B16: PDUFA Date | C16: =Assumptions!$B$30 -> 46353
B17: P(Approval) | C17: =Assumptions!$B$32 -> 0.88
B18: If Approved | C18: =Assumptions!$D$168 -> 55.02037
B19: If CRL | C19: =Assumptions!$D$167 -> 51.790583

Sheet Yearly Model
B1: 2021 | C1: 2022 | D1: 2023 | E1: 2024 | F1: 2025 | G1: 2026 | H1: 2027 | I1: 2028 | J1: 2029 | K1: 2030 | L1: 2031 | M1: 2032 | N1: 2033 | O1: 2034 | P1: 2035 | Q1: 2036 | R1: 2037 | S1: 2038 | T1: 2039 | U1: 2040 | V1: 2041 | W1: 2042 | X1: 2043 | Y1: 2044 | Z1: 2045 | AA1: 2046 | AB1: 2047 | AC1: 2048 | AD1: 2049 | AE1: 2050
A2: Revenue | B2: 69.716 | C2: 77.648 | D2: 9.303 | E2: 221.902 | F2: 502.076 | G2: =SUM('Quarterly Model'!F2:I2) -> 1027.19 | H2: =Pipeline!C75 -> 1910.676 | I2: =Pipeline!D75 -> 2676.932 | J2: =Pipeline!E75 -> 3752.158 | K2: =Pipeline!F75 -> 4849.674 | L2: =Pipeline!G75 -> 5904.91 | M2: =Pipeline!H75 -> 6373.68 | N2: =Pipeline!I75 -> 6625.02 | O2: =Pipeline!J75 -> 6736.65 | ... AE2: =Pipeline!Z75 -> 0.83034636
A3: Cost of Sales | B3: 3.114 | C3: 3.434 | D3: 2.446 | E3: 3.878 | F3: 20.962 | G3: =SUM('Quarterly Model'!F3:I3) -> 61.503 | H3: =Pipeline!C76 -> 198.45732 | I3: =Pipeline!D76 -> 292.21474 | J3: =Pipeline!E76 -> 401.48426 | K3: =Pipeline!F76 -> 515.24598 | L3: =Pipeline!G76 -> 623.8604 | M3: =Pipeline!H76 -> 666.7143 | N3: =Pipeline!I76 -> 690.5736 | O3: =Pipeline!J76 -> 700.395 | ... AE3: =Pipeline!Z76 -> 0.078250928
A4: Gross Margin | B4: =B2-B3 -> 66.602 | C4: =C2-C3 -> 74.214 | D4: =D2-D3 -> 6.857 | E4: =E2-E3 -> 218.024 | F4: =F2-F3 -> 481.114 | G4: =G2-G3 -> 965.687 | H4: =H2-H3 -> 1712.2187 | I4: =I2-I3 -> 2384.7173 | ... AE4: =AE2-AE3 -> 0.75209544
A5: Research & Dev. | B5: 451.024 | C5: 399.462 | D5: 455.711 | E5: 506.461 | F5: 451.953 | G5: =SUM('Quarterly Model'!F5:I5) -> 581.084 | H5: =Pipeline!C79 -> 485 | I5: =Pipeline!D79 -> 424.9 | J5: =Pipeline!E79 -> 455.25896 | K5: =Pipeline!F79 -> 581.96088 | L5: =Pipeline!G79 -> 708.5892 | M5: =Pipeline!H79 -> 764.8416 | N5: =Pipeline!I79 -> 795.0024 | O5: =Pipeline!J79 -> 808.398 | ... AE5: =Pipeline!Z79 -> 0.099641564
A6: General & Admin | B6: 192.21 | C6: 186.954 | D6: 158.516 | E6: 304.536 | F6: 552.572 | G6: =SUM('Quarterly Model'!F6:I6) -> 740.157 | H6: =Pipeline!C82 -> 1002.5628 | I6: =Pipeline!D82 -> 1205.0914 | J6: =Pipeline!E82 -> 1479.2695 | K6: =Pipeline!F82 -> 1702.5987 | L6: =Pipeline!G82 -> 1962.8173 | M6: =Pipeline!H82 -> 2024.1071 | N6: =Pipeline!I82 -> 2082.827 | O6: =Pipeline!J82 -> 2080.673 | ... AE6: =Pipeline!Z82 -> 0.26175246
A7: Operating Expense | B7: =SUM(B5:B6) -> 643.234 | C7: =SUM(C5:C6) -> 586.416 | D7: =SUM(D5:D6) -> 614.227 | E7: =SUM(E5:E6) -> 810.997 | F7: =SUM(F5:F6) -> 1004.525 | G7: =SUM(G5:G6) -> 1321.241 | H7: =SUM(H5:H6) -> 1487.5628 | I7: =SUM(I5:I6) -> 1629.9914 | ... AE7: =SUM(AE5:AE6) -> 0.36139403
A8: Operating Income | B8: =B4-B7 -> -576.632 | C8: =C4-C7 -> -512.202 | D8: =D4-D7 -> -607.37 | E8: =E4-E7 -> -592.973 | F8: =F4-F7 -> -523.411 | G8: =G4-G7 -> -355.554 | H8: =H4-H7 -> 224.65588 | I8: =I4-I7 -> 754.72584 | ... AE8: =AE4-AE7 -> 0.39070141
A9: Interest & Other | B9: -9.822 | C9: 27.577 | D9: -45.881 | E9: 50.779 | F9: -209.092 | G9: =SUM('Quarterly Model'!F9:I9) -> -189.411 | H9: =Assumptions!$B$16*MAX(0,G20)-Assumptions!$B$17*Main!$C$8 -> -31.463425 | I9: =Assumptions!$B$16*MAX(0,H20)-Assumptions!$B$17*Main!$C$8 -> -24.218708 | J9: =Assumptions!$B$16*MAX(0,I20)-Assumptions!$B$17*Main!$C$8 -> 3.1753095 | K9: =Assumptions!$B$16*MAX(0,J20)-Assumptions!$B$17*Main!$C$8 -> 56.39983 | L9: =Assumptions!$B$16*MAX(0,K20)-Assumptions!$B$17*Main!$C$8 -> 128.26334 | M9: =Assumptions!$B$16*MAX(0,L20)-Assumptions!$B$17*Main!$C$8 -> 209.37382 | N9: =Assumptions!$B$16*MAX(0,M20)-Assumptions!$B$17*Main!$C$8 -> 302.02278 | O9: =Assumptions!$B$16*MAX(0,N20)-Assumptions!$B$17*Main!$C$8 -> 401.52248 | ... AE9: =Assumptions!$B$16*MAX(0,AD20)-Assumptions!$B$17*Main!$C$8 -> 1526.7357
A10: Pretax | B10: =B8+B9 -> -586.454 | C10: =C8+C9 -> -484.625 | D10: =D8+D9 -> -653.251 | E10: =E8+E9 -> -542.194 | F10: =F8+F9 -> -732.503 | G10: =G8+G9 -> -544.965 | H10: =H8+H9 -> 193.19245 | I10: =I8+I9 -> 730.50713 | ... AE10: =AE8+AE9 -> 1527.1264
A11: Taxes | B11: 0 | C11: 0 | D11: 0 | E11: 1.153 | F11: 0.435 | G11: =SUM('Quarterly Model'!F11:I11) -> 0 | H11: =MAX(0,H10-G21)*Assumptions!$B$15 -> 0 | I11: =MAX(0,I10-H21)*Assumptions!$B$15 -> 0 | J11: =MAX(0,J10-I21)*Assumptions!$B$15 -> 0 | K11: =MAX(0,K10-J21)*Assumptions!$B$15 -> 189.90792 | L11: =MAX(0,L10-K21)*Assumptions!$B$15 -> 574.96035 | M11: =MAX(0,M10-L21)*Assumptions!$B$15 -> 656.75207 | N11: =MAX(0,N10-M21)*Assumptions!$B$15 -> 705.31435 | O11: =MAX(0,O10-N21)*Assumptions!$B$15 -> 745.22836 | ... AE11: =MAX(0,AE10-AD21)*Assumptions!$B$15 -> 320.69655
A12: Net Income | B12: -586.454 | C12: -484.625 | D12: -653.251 | E12: -543.347 | F12: -732.938 | G12: =G10-G11 -> -544.965 | H12: =H10-H11 -> 193.19245 | I12: =I10-I11 -> 730.50713 | J12: =J10-J11 -> 1419.3205 | K12: =K10-K11 -> 1916.3604 | L12: =L10-L11 -> 2162.9461 | M12: =M10-M11 -> 2470.6387 | N12: =N10-N11 -> 2653.3254 | ... AE12: =AE10-AE11 -> 1206.4299
A13: Earnings per Share | B13: =IFERROR(B12/B14,0) -> -4.0625255 | C13: =IFERROR(C12/C14,0) -> -3.2861948 | D13: =IFERROR(D12/D14,0) -> -4.0127955 | E13: =IFERROR(E12/E14,0) -> -2.9200273 | F13: =IFERROR(F12/F14,0) -> -3.8268129 | G13: =IFERROR(G12/G14,0) -> -2.7851371 | H13: =IFERROR(H12/H14,0) -> 0.98826002 | I13: =IFERROR(I12/I14,0) -> 3.7368488 | ... AE13: =IFERROR(AE12/AE14,0) -> 6.1713923
A14: Shares | B14: 144.357 | C14: 147.473 | D14: 162.792 | E14: 186.076 | F14: 191.527 | G14: =AVERAGE('Quarterly Model'!F14:I14) -> 195.669 | H14: =Main!$C$4*(1+Assumptions!$B$26)^(H1-2026) -> 195.48747 | I14: =Main!$C$4*(1+Assumptions!$B$26)^(I1-2026) -> 195.48747 | J14: =Main!$C$4*(1+Assumptions!$B$26)^(J1-2026) -> 195.48747 | K14: =Main!$C$4*(1+Assumptions!$B$26)^(K1-2026) -> 195.48747 | L14: =Main!$C$4*(1+Assumptions!$B$26)^(L1-2026) -> 195.48747 | M14: =Main!$C$4*(1+Assumptions!$B$26)^(M1-2026) -> 195.48747 | N14: =Main!$C$4*(1+Assumptions!$B$26)^(N1-2026) -> 195.48747 | O14: =Main!$C$4*(1+Assumptions!$B$26)^(O1-2026) -> 195.48747 | ... AE14: =Main!$C$4*(1+Assumptions!$B$26)^(AE1-2026) -> 195.48747
A16: Revenue Change | C16: =IFERROR(C2/B2-1,"") -> 0.11377589 | D16: =IFERROR(D2/C2-1,"") -> -0.88019009 | E16: =IFERROR(E2/D2-1,"") -> 22.852736 | F16: =IFERROR(F2/E2-1,"") -> 1.2626024 | G16: =IFERROR(G2/F2-1,"") -> 1.0458855 | H16: =IFERROR(H2/G2-1,"") -> 0.86009988 | I16: =IFERROR(I2/H2-1,"") -> 0.40103921 | J16: =IFERROR(J2/I2-1,"") -> 0.40166355 | ... AE16: =IFERROR(AE2/AD2-1,"") -> -0.6
A17: Gross Margin | B17: =IFERROR(B4/B2,"") -> 0.95533307 | C17: =IFERROR(C4/C2,"") -> 0.95577478 | D17: =IFERROR(D4/D2,"") -> 0.73707406 | E17: =IFERROR(E4/E2,"") -> 0.98252382 | F17: =IFERROR(F4/F2,"") -> 0.95824935 | G17: =IFERROR(G4/G2,"") -> 0.940125 | H17: =IFERROR(H4/H2,"") -> 0.89613241 | I17: =IFERROR(I4/I2,"") -> 0.89083969 | ... AE17: =IFERROR(AE4/AE2,"") -> 0.9057611
A19: Actual / Estimate | B19: A | C19: A | D19: A | E19: A | F19: A | G19: A+E | H19: E | I19: E | J19: E | K19: E | L19: E | M19: E | N19: E | O19: E | P19: E | Q19: E | R19: E | S19: E | T19: E | U19: E | V19: E | W19: E | X19: E | Y19: E | Z19: E | AA19: E | AB19: E | AC19: E | AD19: E | AE19: E
A20: Cash & Investments | G20: ='Quarterly Model'!I20 -> 1497.642 | H20: =G20+H12 -> 1690.8345 | I20: =H20+I12 -> 2421.3416 | J20: =I20+J12 -> 3840.6621 | K20: =J20+K12 -> 5757.0225 | L20: =K20+L12 -> 7919.9686 | M20: =L20+M12 -> 10390.607 | N20: =M20+N12 -> 13043.933 | O20: =N20+O12 -> 15847.411 | ... AE20: =AD20+AE12 -> 44256.05
A21: Tax-Loss Pool | F21: =Assumptions!$B$18 -> 3000 | G21: =F21-MIN(F21,MAX(0,G10))+MAX(0,-G10) -> 3544.965 | H21: =G21-MIN(G21,MAX(0,H10))+MAX(0,-H10) -> 3351.7725 | I21: =H21-MIN(H21,MAX(0,I10))+MAX(0,-I10) -> 2621.2654 | J21: =I21-MIN(I21,MAX(0,J10))+MAX(0,-J10) -> 1201.9449 | K21: =J21-MIN(J21,MAX(0,K10))+MAX(0,-K10) -> 0 | L21: =K21-MIN(K21,MAX(0,L10))+MAX(0,-L10) -> 0 | M21: =L21-MIN(L21,MAX(0,M10))+MAX(0,-M10) -> 0 | N21: =M21-MIN(M21,MAX(0,N10))+MAX(0,-N10) -> 0 | ... AE21: =AD21-MIN(AD21,MAX(0,AE10))+MAX(0,-AE10) -> 0

Sheet Quarterly Model
B1: Q1 2025 | C1: Q2 2025 | D1: Q3 2025 | E1: Q4 2025 | F1: Q1 2026 | G1: Q2 2026 | H1: Q3 2026 | I1: Q4 2026
A2: Revenue | B2: =SUM(B24:B26) -> 116.63 | C2: =SUM(C24:C26) -> 110.56 | D2: =SUM(D24:D26) -> 120.7 | E2: =SUM(E24:E26) -> 154.18 | F2: =SUM(F24:F26) -> 194.52 | G2: =SUM(G24:G26) -> 243.67 | H2: =SUM(H24:H26) -> 278 | I2: =SUM(I24:I26) -> 311
A3: Cost of Sales | B3: 2.639 | C3: 3.653 | D3: 6.563 | E3: 8.107 | F3: 9.939 | G3: 15.046 | H3: =H2*0.062 -> 17.236 | I3: =I2*0.062 -> 19.282
A4: Gross Margin | B4: =B2-B3 -> 113.991 | C4: =C2-C3 -> 106.907 | D4: =D2-D3 -> 114.137 | E4: =E2-E3 -> 146.073 | F4: =F2-F3 -> 184.581 | G4: =G2-G3 -> 228.624 | H4: =H2-H3 -> 260.764 | I4: =I2-I3 -> 291.718
A5: Research & Dev. | B5: 111.431 | C5: 111.231 | D5: 112.874 | E5: 116.417 | F5: 126.636 | G5: 149.448 | H5: 150 | I5: 155
A6: General & Admin | B6: 106.935 | C6: 129.959 | D6: 146.462 | E6: 169.216 | F6: 163.896 | G6: 186.261 | H6: 190 | I6: 200
A7: Operating Expense | B7: =SUM(B5:B6) -> 218.366 | C7: =SUM(C5:C6) -> 241.19 | D7: =SUM(D5:D6) -> 259.336 | E7: =SUM(E5:E6) -> 285.633 | F7: =SUM(F5:F6) -> 290.532 | G7: =SUM(G5:G6) -> 335.709 | H7: =SUM(H5:H6) -> 340 | I7: =SUM(I5:I6) -> 355
A8: Operating Income | B8: =B4-B7 -> -104.375 | C8: =C4-C7 -> -134.283 | D8: =D4-D7 -> -145.199 | E8: =E4-E7 -> -139.56 | F8: =F4-F7 -> -105.951 | G8: =G4-G7 -> -107.085 | H8: =H4-H7 -> -79.236 | I8: =I4-I7 -> -63.282
A9: Interest & Other | B9: -65.236 | C9: -47.38 | D9: -41.283 | E9: -55.193 | F9: -60.599 | G9: -48.812 | H9: -40 | I9: -40
A10: Pretax | B10: =B8+B9 -> -169.611 | C10: =C8+C9 -> -181.663 | D10: =D8+D9 -> -186.482 | E10: =E8+E9 -> -194.753 | F10: =F8+F9 -> -166.55 | G10: =G8+G9 -> -155.897 | H10: =H8+H9 -> -119.236 | I10: =I8+I9 -> -103.282
A11: Taxes | B11: 0 | C11: 2.1 | D11: -1.545 | E11: -0.12 | F11: 0 | G11: 0 | H11: 0 | I11: 0
A12: Net Income | B12: =B10-B11 -> -169.611 | C12: =C10-C11 -> -183.763 | D12: =D10-D11 -> -184.937 | E12: =E10-E11 -> -194.633 | F12: =F10-F11 -> -166.55 | G12: =G10-G11 -> -155.897 | H12: =H10-H11 -> -119.236 | I12: =I10-I11 -> -103.282
A13: Earnings per Share | B13: =IFERROR(B12/B14,0) -> -0.89200873 | C13: =IFERROR(C12/C14,0) -> -0.9645491 | D13: =IFERROR(D12/D14,0) -> -0.96394654 | E13: =IFERROR(E12/E14,0) -> -1.0053721 | F13: =IFERROR(F12/F14,0) -> -0.85502336 | G13: =IFERROR(G12/G14,0) -> -0.79626225 | H13: =IFERROR(H12/H14,0) -> -0.60865748 | I13: =IFERROR(I12/I14,0) -> -0.52641182
A14: Shares | B14: 190.145 | C14: 190.517 | D14: 191.854 | E14: 193.593 | F14: 194.79 | G14: 195.786 | H14: 195.9 | I14: 196.2
A16: Revenue Change (YoY) | F16: =IFERROR(F2/B2-1,"") -> 0.66783846 | G16: =IFERROR(G2/C2-1,"") -> 1.2039616 | H16: =IFERROR(H2/D2-1,"") -> 1.3032312 | I16: =IFERROR(I2/E2-1,"") -> 1.0171228
A17: Gross Margin | B17: =IFERROR(B4/B2,"") -> 0.97737289 | C17: =IFERROR(C4/C2,"") -> 0.96695912 | D17: =IFERROR(D4/D2,"") -> 0.94562552 | E17: =IFERROR(E4/E2,"") -> 0.9474186 | F17: =IFERROR(F4/F2,"") -> 0.948905 | G17: =IFERROR(G4/G2,"") -> 0.93825255 | H17: =IFERROR(H4/H2,"") -> 0.938 | I17: =IFERROR(I4/I2,"") -> 0.938
A19: Actual / Estimate | B19: A | C19: A | D19: A | E19: A | F19: A | G19: A | H19: E | I19: E
A20: Cash & Investments | G20: 720.16 | H20: =G20+H12+H21 -> 1600.924 | I20: =H20+I12+I21 -> 1497.642
A21: Other Cash Flows (est.) | H21: 1000 | I21: 0
A23: Revenue by Product
A24: Attruby (U.S.) | B24: 36.74 | C24: 71.5 | D24: 110.03 | E24: 144.1 | F24: 180.6 | G24: 222.44 | H24: 255 | I24: 285
A25: Royalties | B25: 0.2 | C25: 1.62 | D25: 4.27 | E25: 5.29 | F25: 9.5 | G25: 15.43 | H25: 18 | I25: 21
A26: License & services | B26: 79.69 | C26: 37.44 | D26: 6.4 | E26: 4.79 | F26: 4.42 | G26: 5.8 | H26: 5 | I26: 5

Sheet Assumptions
A1: BBIO — rNPV assumptions ($mm unless noted)
A4: Scenario (1 = Bear, 2 = Base, 3 = Bull) | B4: 2 | C4: =CHOOSE($B$4,"Bear","Base","Bull") -> Base
A5: Overrides (blank = scenario value; the sensitivity tables drive these)
A6: Discount rate override
A7: PDUFA approval probability override
A8: PDUFA program peak sales override ($mm)
A10: Parameter | B10: Active | C10: Bear | D10: Base | E10: Bull
A12: Valuation & corporate
A13: Valuation date | B13: =DATE(2026,10,16) -> 46311
A14: Discount rate (cost of equity) | B14: =IF(ISNUMBER($B$6),$B$6,CHOOSE($B$4,C14,D14,E14)) -> 0.095 | C14: 0.11 | D14: 0.095 | E14: 0.085
A15: Tax rate | B15: =CHOOSE($B$4,C15,D15,E15) -> 0.21 | C15: 0.21 | D15: 0.21 | E15: 0.21
A16: Interest yield on cash | B16: =CHOOSE($B$4,C16,D16,E16) -> 0.0375 | C16: 0.0375 | D16: 0.0375 | E16: 0.0375
A17: Average cash cost of debt (P&L display only) | B17: =CHOOSE($B$4,C17,D17,E17) -> 0.025 | C17: 0.025 | D17: 0.025 | E17: 0.025
A18: Tax-loss pool at 12/31/2025 | B18: =CHOOSE($B$4,C18,D18,E18) -> 3000 | C18: 3000 | D18: 3000 | E18: 3000
A19: Corporate G&A, 2027 | B19: =CHOOSE($B$4,C19,D19,E19) -> 170 | C19: 170 | D19: 170 | E19: 170
A20: Platform / unallocated R&D, 2027 | B20: =CHOOSE($B$4,C20,D20,E20) -> 330 | C20: 330 | D20: 330 | E20: 330
A21: Cost inflation | B21: =CHOOSE($B$4,C21,D21,E21) -> 0.03 | C21: 0.03 | D21: 0.03 | E21: 0.03
A22: Corporate G&A floor, % of revenue | B22: =CHOOSE($B$4,C22,D22,E22) -> 0.07 | C22: 0.07 | D22: 0.07 | E22: 0.07
A23: Platform R&D floor, % of revenue | B23: =CHOOSE($B$4,C23,D23,E23) -> 0.12 | C23: 0.12 | D23: 0.12 | E23: 0.12
A24: Corporate cost cut after a CRL (2027+) | B24: =CHOOSE($B$4,C24,D24,E24) -> 0 | C24: 0 | D24: 0 | E24: 0
A25: Last year of base-level corporate costs (then % of revenue only) | B25: =CHOOSE($B$4,C25,D25,E25) -> 2038 | C25: 2038 | D25: 2038 | E25: 2038
A26: Annual share count growth (EPS display only) | B26: =CHOOSE($B$4,C26,D26,E26) -> 0 | C26: 0 | D26: 0 | E26: 0
A27: Wind-down cost for liquidation value | B27: =CHOOSE($B$4,C27,D27,E27) -> 150 | C27: 150 | D27: 150 | E27: 150
A29: PDUFA event
A30: PDUFA target action date | B30: =DATE(2026,11,27) -> 46353
A31: Application | B31: BBP-418 NDA, LGMD2I/R9 (priority; PRV-eligible)
A32: Probability of approval at this PDUFA | B32: =IF(ISNUMBER($B$7),$B$7,CHOOSE($B$4,C32,D32,E32)) -> 0.88 | C32: 0.82 | D32: 0.88 | E32: 0.93
A33: Probability of approval later, after a CRL | B33: =CHOOSE($B$4,C33,D33,E33) -> 0.8 | C33: 0.75 | D33: 0.8 | E33: 0.85
A34: Launch delay after a CRL (years) | B34: =CHOOSE($B$4,C34,D34,E34) -> 2 | C34: 2 | D34: 2 | E34: 1
A35: Probability of approval, scenario value (before override) | B35: =CHOOSE($B$4,C32,D32,E32) -> 0.88
A36: Read-through: relative cut to other programs' PoS after a CRL | B36: =CHOOSE($B$4,C36,D36,E36) -> 0 | C36: 0 | D36: 0 | E36: 0
A37: Read-through multiplier on other programs' PoS (1 = none) | B37: =1+$B$36*($B$32-$B$35)/$B$35 -> 1
A38: Expected corporate cost multiplier (2027+) | B38: =$B$32+(1-$B$32)*(1-$B$24) -> 1
A40: Commercial curves (by year since launch)
A41: Year since launch | B41: 1 | C41: 2 | D41: 3 | E41: 4 | F41: 5 | G41: 6 | H41: 7
A42: Ramp 1 — standard launch, % of peak | B42: 0.1 | C42: 0.25 | D42: 0.45 | E42: 0.65 | F42: 0.82 | G42: 0.93 | H42: 1
A43: Ramp 2 — orphan-disease launch, % of peak | B43: 0.15 | C43: 0.35 | D43: 0.55 | E43: 0.75 | F43: 0.9 | G43: 1 | H43: 1
A44: Commercial SG&A, % of sales (years 1–5; floor = program maturity %) | B44: 0.9 | C44: 0.55 | D44: 0.4 | E44: 0.32 | F44: 0.28
A46: Attruby (acoramidis) — ATTR-CM, U.S. (marketed)
A47: Launch year (first commercial year) | B47: 2025
...

Sheet Pipeline
A1: BBIO — risk-adjusted program build ($mm)
A2: Year | C2: 2027 | D2: 2028 | E2: 2029 | F2: 2030 | G2: 2031 | H2: 2032 | I2: 2033 | J2: 2034 | K2: 2035 | L2: 2036 | M2: 2037 | N2: 2038 | O2: 2039 | P2: 2040 | Q2: 2041 | R2: 2042 | S2: 2043 | T2: 2044 | U2: 2045 | V2: 2046 | W2: 2047 | X2: 2048 | Y2: 2049 | Z2: 2050
A4: Attruby (acoramidis) — ATTR-CM, U.S.
A5: Years since launch | C5: =C$2-Assumptions!$B$47+1 -> 3 | D5: =D$2-Assumptions!$B$47+1 -> 4 | E5: =E$2-Assumptions!$B$47+1 -> 5 | F5: =F$2-Assumptions!$B$47+1 -> 6 | G5: =G$2-Assumptions!$B$47+1 -> 7 | H5: =H$2-Assumptions!$B$47+1 -> 8 | I5: =I$2-Assumptions!$B$47+1 -> 9 | J5: =J$2-Assumptions!$B$47+1 -> 10 | ... Z5: =Z$2-Assumptions!$B$47+1 -> 26
A6: Net sales | C6: =IF(C$2>Assumptions!$B$55,Assumptions!$B$57*(1-Assumptions!$B$56),IF(C$2<Assumptions!$B$49,Assumptions!$B$57+(Assumptions!$B$48-Assumptions!$B$57)*((C$2-2026)/(Assumptions!$B$49-2026))^Assumptions!$B$50,Assumptions!$B$48)) -> 1354.432 | D6: =IF(D$2>Assumptions!$B$55,C6*(1-Assumptions!$B$56),IF(D$2<Assumptions!$B$49,Assumptions!$B$57+(Assumptions!$B$48-Assumptions!$B$57)*((D$2-2026)/(Assumptions!$B$49-2026))^Assumptions!$B$50,Assumptions!$B$48)) -> 1765.824 | E6: =IF(E$2>Assumptions!$B$55,D6*(1-Assumptions!$B$56),IF(E$2<Assumptions!$B$49,Assumptions!$B$57+(Assumptions!$B$48-Assumptions!$B$57)*((E$2-2026)/(Assumptions!$B$49-2026))^Assumptions!$B$50,Assumptions!$B$48)) -> 2177.216 | F6: =IF(F$2>Assumptions!$B$55,E6*(1-Assumptions!$B$56),IF(F$2<Assumptions!$B$49,Assumptions!$B$57+(Assumptions!$B$48-Assumptions!$B$57)*((F$2-2026)/(Assumptions!$B$49-2026))^Assumptions!$B$50,Assumptions!$B$48)) -> 2588.608 | G6: =IF(G$2>Assumptions!$B$55,F6*(1-Assumptions!$B$56),IF(G$2<Assumptions!$B$49,Assumptions!$B$57+(Assumptions!$B$48-Assumptions!$B$57)*((G$2-2026)/(Assumptions!$B$49-2026))^Assumptions!$B$50,Assumptions!$B$48)) -> 3000 | H6: =IF(H$2>Assumptions!$B$55,G6*(1-Assumptions!$B$56),IF(H$2<Assumptions!$B$49,Assumptions!$B$57+(Assumptions!$B$48-Assumptions!$B$57)*((H$2-2026)/(Assumptions!$B$49-2026))^Assumptions!$B$50,Assumptions!$B$48)) -> 3000 | I6: =IF(I$2>Assumptions!$B$55,H6*(1-Assumptions!$B$56),IF(I$2<Assumptions!$B$49,Assumptions!$B$57+(Assumptions!$B$48-Assumptions!$B$57)*((I$2-2026)/(Assumptions!$B$49-2026))^Assumptions!$B$50,Assumptions!$B$48)) -> 3000 | J6: =IF(J$2>Assumptions!$B$55,I6*(1-Assumptions!$B$56),IF(J$2<Assumptions!$B$49,Assumptions!$B$57+(Assumptions!$B$48-Assumptions!$B$57)*((J$2-2026)/(Assumptions!$B$49-2026))^Assumptions!$B$50,Assumptions!$B$48)) -> 3000 | K6: =IF(K$2>Assumptions!$B$55,J6*(1-Assumptions!$B$56),IF(K$2<Assumptions!$B$49,Assumptions!$B$57+(Assumptions!$B$48-Assumptions!$B$57)*((K$2-2026)/(Assumptions!$B$49-2026))^Assumptions!$B$50,Assumptions!$B$48)) -> 3000 | ... Z6: =IF(Z$2>Assumptions!$B$55,Y6*(1-Assumptions!$B$56),IF(Z$2<Assumptions!$B$49,Assumptions!$B$57+(Assumptions!$B$48-Assumptions!$B$57)*((Z$2-2026)/(Assumptions!$B$49-2026))^Assumptions!$B$50,Assumptions!$B$48)) -> 0.020132659
A7: Company revenue | C7: =C6*Assumptions!$B$51 -> 1354.432 | D7: =D6*Assumptions!$B$51 -> 1765.824 | E7: =E6*Assumptions!$B$51 -> 2177.216 | F7: =F6*Assumptions!$B$51 -> 2588.608 | G7: =G6*Assumptions!$B$51 -> 3000 | H7: =H6*Assumptions!$B$51 -> 3000 | I7: =I6*Assumptions!$B$51 -> 3000 | J7: =J6*Assumptions!$B$51 -> 3000 | ... Z7: =Z6*Assumptions!$B$51 -> 0.020132659
A8: COGS + royalties | C8: =C6*(Assumptions!$B$52+Assumptions!$B$53) -> 148.98752 | D8: =D6*(Assumptions!$B$52+Assumptions!$B$53) -> 194.24064 | E8: =E6*(Assumptions!$B$52+Assumptions!$B$53) -> 239.49376 | F8: =F6*(Assumptions!$B$52+Assumptions!$B$53) -> 284.74688 | G8: =G6*(Assumptions!$B$52+Assumptions!$B$53) -> 330 | H8: =H6*(Assumptions!$B$52+Assumptions!$B$53) -> 330 | I8: =I6*(Assumptions!$B$52+Assumptions!$B$53) -> 330 | J8: =J6*(Assumptions!$B$52+Assumptions!$B$53) -> 330 | ... Z8: =Z6*(Assumptions!$B$52+Assumptions!$B$53) -> 0.0022145925
A9: Commercial SG&A | C9: =IF(Assumptions!$B$54=0,0,IF(FALSE,0,IF(C5>=1,C6*IF(OR(Assumptions!$B$51<1,C5>5),Assumptions!$B$54,MAX(Assumptions!$B$54,INDEX(Assumptions!$B$44:$F$44,C5))),0))) -> 541.7728 | D9: =IF(Assumptions!$B$54=0,0,IF(FALSE,0,IF(D5>=1,D6*IF(OR(Assumptions!$B$51<1,D5>5),Assumptions!$B$54,MAX(Assumptions!$B$54,INDEX(Assumptions!$B$44:$F$44,D5))),0))) -> 565.06368 | E9: =IF(Assumptions!$B$54=0,0,IF(FALSE,0,IF(E5>=1,E6*IF(OR(Assumptions!$B$51<1,E5>5),Assumptions!$B$54,MAX(Assumptions!$B$54,INDEX(Assumptions!$B$44:$F$44,E5))),0))) -> 609.62048 | F9: =IF(Assumptions!$B$54=0,0,IF(FALSE,0,IF(F5>=1,F6*IF(OR(Assumptions!$B$51<1,F5>5),Assumptions!$B$54,MAX(Assumptions!$B$54,INDEX(Assumptions!$B$44:$F$44,F5))),0))) -> 647.152 | G9: =IF(Assumptions!$B$54=0,0,IF(FALSE,0,IF(G5>=1,G6*IF(OR(Assumptions!$B$51<1,G5>5),Assumptions!$B$54,MAX(Assumptions!$B$54,INDEX(Assumptions!$B$44:$F$44,G5))),0))) -> 750 | H9: =IF(Assumptions!$B$54=0,0,IF(FALSE,0,IF(H5>=1,H6*IF(OR(Assumptions!$B$51<1,H5>5),Assumptions!$B$54,MAX(Assumptions!$B$54,INDEX(Assumptions!$B$44:$F$44,H5))),0))) -> 750 | I9: =IF(Assumptions!$B$54=0,0,IF(FALSE,0,IF(I5>=1,I6*IF(OR(Assumptions!$B$51<1,I5>5),Assumptions!$B$54,MAX(Assumptions!$B$54,INDEX(Assumptions!$B$44:$F$44,I5))),0))) -> 750 | J9: =IF(Assumptions!$B$54=0,0,IF(FALSE,0,IF(J5>=1,J6*IF(OR(Assumptions!$B$51<1,J5>5),Assumptions!$B$54,MAX(Assumptions!$B$54,INDEX(Assumptions!$B$44:$F$44,J5))),0))) -> 750 | ... Z9: =IF(Assumptions!$B$54=0,0,IF(FALSE,0,IF(Z5>=1,Z6*IF(OR(Assumptions!$B$51<1,Z5>5),Assumptions!$B$54,MAX(Assumptions!$B$54,INDEX(Assumptions!$B$44:$F$44,Z5))),0))) -> 0.0050331648
A10: Development R&D | C10: =0 -> 0 | D10: =0 -> 0 | E10: =0 -> 0 | F10: =0 -> 0 | G10: =0 -> 0 | H10: =0 -> 0 | I10: =0 -> 0 | J10: =0 -> 0 | ... Z10: =0 -> 0
A11: Program contribution (pre-tax) | C11: =C7-C8-C9-C10 -> 663.67168 | D11: =D7-D8-D9-D10 -> 1006.5197 | E11: =E7-E8-E9-E10 -> 1328.1018 | F11: =F7-F8-F9-F10 -> 1656.7091 | G11: =G7-G8-G9-G10 -> 1920 | H11: =H7-H8-H9-H10 -> 1920 | I11: =I7-I8-I9-I10 -> 1920 | J11: =J7-J8-J9-J10 -> 1920 | ... Z11: =Z7-Z8-Z9-Z10 -> 0.012884902
A13: Acoramidis — ex-U.S. royalties (Bayer, Alexion)
A14: Years since launch | C14: =C$2-Assumptions!$B$60+1 -> 3 | D14: =D$2-Assumptions!$B$60+1 -> 4 | E14: =E$2-Assumptions!$B$60+1 -> 5 | F14: =F$2-Assumptions!$B$60+1 -> 6 | G14: =G$2-Assumptions!$B$60+1 -> 7 | H14: =H$2-Assumptions!$B$60+1 -> 8 | I14: =I$2-Assumptions!$B$60+1 -> 9 | J14: =J$2-Assumptions!$B$60+1 -> 10 | ... Z14: =Z$2-Assumptions!$B$60+1 -> 26
A15: Net sales | C15: =IF(C$2>Assumptions!$B$68,Assumptions!$B$70*(1-Assumptions!$B$69),IF(C$2<Assumptions!$B$62,Assumptions!$B$70+(Assumptions!$B$61-Assumptions!$B$70)*((C$2-2026)/(Assumptions!$B$62-2026))^Assumptions!$B$63,Assumptions!$B$61)) -> 101.144 | D15: =IF(D$2>Assumptions!$B$68,C15*(1-Assumptions!$B$69),IF(D$2<Assumptions!$B$62,Assumptions!$B$70+(Assumptions!$B$61-Assumptions!$B$70)*((D$2-2026)/(Assumptions!$B$62-2026))^Assumptions!$B$63,Assumptions!$B$61)) -> 138.358 | E15: =IF(E$2>Assumptions!$B$68,D15*(1-Assumptions!$B$69),IF(E$2<Assumptions!$B$62,Assumptions!$B$70+(Assumptions!$B$61-Assumptions!$B$70)*((E$2-2026)/(Assumptions!$B$62-2026))^Assumptions!$B$63,Assumptions!$B$61)) -> 175.572 | F15: =IF(F$2>Assumptions!$B$68,E15*(1-Assumptions!$B$69),IF(F$2<Assumptions!$B$62,Assumptions!$B$70+(Assumptions!$B$61-Assumptions!$B$70)*((F$2-2026)/(Assumptions!$B$62-2026))^Assumptions!$B$63,Assumptions!$B$61)) -> 212.786 | G15: =IF(G$2>Assumptions!$B$68,F15*(1-Assumptions!$B$69),IF(G$2<Assumptions!$B$62,Assumptions!$B$70+(Assumptions!$B$61-Assumptions!$B$70)*((G$2-2026)/(Assumptions!$B$62-2026))^Assumptions!$B$63,Assumptions!$B$61)) -> 250 | H15: =IF(H$2>Assumptions!$B$68,G15*(1-Assumptions!$B$69),IF(H$2<Assumptions!$B$62,Assumptions!$B$70+(Assumptions!$B$61-Assumptions!$B$70)*((H$2-2026)/(Assumptions!$B$62-2026))^Assumptions!$B$63,Assumptions!$B$61)) -> 250 | I15: =IF(I$2>Assumptions!$B$68,H15*(1-Assumptions!$B$69),IF(I$2<Assumptions!$B$62,Assumptions!$B$70+(Assumptions!$B$61-Assumptions!$B$70)*((I$2-2026)/(Assumptions!$B$62-2026))^Assumptions!$B$63,Assumptions!$B$61)) -> 250 | J15: =IF(J$2>Assumptions!$B$68,I15*(1-Assumptions!$B$69),IF(J$2<Assumptions!$B$62,Assumptions!$B$70+(Assumptions!$B$61-Assumptions!$B$70)*((J$2-2026)/(Assumptions!$B$62-2026))^Assumptions!$B$63,Assumptions!$B$61)) -> 250 | K15: =IF(K$2>Assumptions!$B$68,J15*(1-Assumptions!$B$69),IF(K$2<Assumptions!$B$62,Assumptions!$B$70+(Assumptions!$B$61-Assumptions!$B$70)*((K$2-2026)/(Assumptions!$B$62-2026))^Assumptions!$B$63,Assumptions!$B$61)) -> 250 | ... Z15: =IF(Z$2>Assumptions!$B$68,Y15*(1-Assumptions!$B$69),IF(Z$2<Assumptions!$B$62,Assumptions!$B$70+(Assumptions!$B$61-Assumptions!$B$70)*((Z$2-2026)/(Assumptions!$B$62-2026))^Assumptions!$B$63,Assumptions!$B$61)) -> 0.0016777216
A16: Company revenue | C16: =C15*Assumptions!$B$64 -> 101.144 | D16: =D15*Assumptions!$B$64 -> 138.358 | E16: =E15*Assumptions!$B$64 -> 175.572 | F16: =F15*Assumptions!$B$64 -> 212.786 | G16: =G15*Assumptions!$B$64 -> 250 | H16: =H15*Assumptions!$B$64 -> 250 | I16: =I15*Assumptions!$B$64 -> 250 | J16: =J15*Assumptions!$B$64 -> 250 | ... Z16: =Z15*Assumptions!$B$64 -> 0.0016777216
A17: COGS + royalties | C17: =C15*(Assumptions!$B$65+Assumptions!$B$66) -> 20.2288 | D17: =D15*(Assumptions!$B$65+Assumptions!$B$66) -> 27.6716 | E17: =E15*(Assumptions!$B$65+Assumptions!$B$66) -> 35.1144 | F17: =F15*(Assumptions!$B$65+Assumptions!$B$66) -> 42.5572 | G17: =G15*(Assumptions!$B$65+Assumptions!$B$66) -> 50 | H17: =H15*(Assumptions!$B$65+Assumptions!$B$66) -> 50 | I17: =I15*(Assumptions!$B$65+Assumptions!$B$66) -> 50 | J17: =J15*(Assumptions!$B$65+Assumptions!$B$66) -> 50 | ... Z17: =Z15*(Assumptions!$B$65+Assumptions!$B$66) -> 0.00033554432
A18: Commercial SG&A | C18: =IF(Assumptions!$B$67=0,0,IF(FALSE,0,IF(C14>=1,C15*IF(OR(Assumptions!$B$64<1,C14>5),Assumptions!$B$67,MAX(Assumptions!$B$67,INDEX(Assumptions!$B$44:$F$44,C14))),0))) -> 0 | D18: =IF(Assumptions!$B$67=0,0,IF(FALSE,0,IF(D14>=1,D15*IF(OR(Assumptions!$B$64<1,D14>5),Assumptions!$B$67,MAX(Assumptions!$B$67,INDEX(Assumptions!$B$44:$F$44,D14))),0))) -> 0 | E18: =IF(Assumptions!$B$67=0,0,IF(FALSE,0,IF(E14>=1,E15*IF(OR(Assumptions!$B$64<1,E14>5),Assumptions!$B$67,MAX(Assumptions!$B$67,INDEX(Assumptions!$B$44:$F$44,E14))),0))) -> 0 | F18: =IF(Assumptions!$B$67=0,0,IF(FALSE,0,IF(F14>=1,F15*IF(OR(Assumptions!$B$64<1,F14>5),Assumptions!$B$67,MAX(Assumptions!$B$67,INDEX(Assumptions!$B$44:$F$44,F14))),0))) -> 0 | G18: =IF(Assumptions!$B$67=0,0,IF(FALSE,0,IF(G14>=1,G15*IF(OR(Assumptions!$B$64<1,G14>5),Assumptions!$B$67,MAX(Assumptions!$B$67,INDEX(Assumptions!$B$44:$F$44,G14))),0))) -> 0 | H18: =IF(Assumptions!$B$67=0,0,IF(FALSE,0,IF(H14>=1,H15*IF(OR(Assumptions!$B$64<1,H14>5),Assumptions!$B$67,MAX(Assumptions!$B$67,INDEX(Assumptions!$B$44:$F$44,H14))),0))) -> 0 | I18: =IF(Assumptions!$B$67=0,0,IF(FALSE,0,IF(I14>=1,I15*IF(OR(Assumptions!$B$64<1,I14>5),Assumptions!$B$67,MAX(Assumptions!$B$67,INDEX(Assumptions!$B$44:$F$44,I14))),0))) -> 0 | J18: =IF(Assumptions!$B$67=0,0,IF(FALSE,0,IF(J14>=1,J15*IF(OR(Assumptions!$B$64<1,J14>5),Assumptions!$B$67,MAX(Assumptions!$B$67,INDEX(Assumptions!$B$44:$F$44,J14))),0))) -> 0 | ... Z18: =IF(Assumptions!$B$67=0,0,IF(FALSE,0,IF(Z14>=1,Z15*IF(OR(Assumptions!$B$64<1,Z14>5),Assumptions!$B$67,MAX(Assumptions!$B$67,INDEX(Assumptions!$B$44:$F$44,Z14))),0))) -> 0
A19: Development R&D | C19: =0 -> 0 | D19: =0 -> 0 | E19: =0 -> 0 | F19: =0 -> 0 | G19: =0 -> 0 | H19: =0 -> 0 | I19: =0 -> 0 | J19: =0 -> 0 | ... Z19: =0 -> 0
A20: Program contribution (pre-tax) | C20: =C16-C17-C18-C19 -> 80.9152 | D20: =D16-D17-D18-D19 -> 110.6864 | E20: =E16-E17-E18-E19 -> 140.4576 | F20: =F16-F17-F18-F19 -> 170.2288 | G20: =G16-G17-G18-G19 -> 200 | H20: =H16-H17-H18-H19 -> 200 | I20: =I16-I17-I18-I19 -> 200 | J20: =J16-J17-J18-J19 -> 200 | ... Z20: =Z16-Z17-Z18-Z19 -> 0.0013421773
A22: BBP-418 — LGMD2I/R9
A23: Years since launch (approved on time) | C23: =C$2-Assumptions!$B$73+1 -> 1 | D23: =D$2-Assumptions!$B$73+1 -> 2 | E23: =E$2-Assumptions!$B$73+1 -> 3 | F23: =F$2-Assumptions!$B$73+1 -> 4 | G23: =G$2-Assumptions!$B$73+1 -> 5 | H23: =H$2-Assumptions!$B$73+1 -> 6 | I23: =I$2-Assumptions!$B$73+1 -> 7 | J23: =J$2-Assumptions!$B$73+1 -> 8 | ... Z23: =Z$2-Assumptions!$B$73+1 -> 24
A24: Net sales, unrisked (approved on time) | C24: =IF(C$2>Assumptions!$B$82,0*(1-Assumptions!$B$83),IF(C23>=1,Assumptions!$B$74*CHOOSE(Assumptions!$B$81,INDEX(Assumptions!$B$42:$H$42,MIN(C23,7)),INDEX(Assumptions!$B$43:$H$43,MIN(C23,7))),0)) -> 120 | D24: =IF(D$2>Assumptions!$B$82,C24*(1-Assumptions!$B$83),IF(D23>=1,Assumptions!$B$74*CHOOSE(Assumptions!$B$81,INDEX(Assumptions!$B$42:$H$42,MIN(D23,7)),INDEX(Assumptions!$B$43:$H$43,MIN(D23,7))),0)) -> 280 | E24: =IF(E$2>Assumptions!$B$82,D24*(1-Assumptions!$B$83),IF(E23>=1,Assumptions!$B$74*CHOOSE(Assumptions!$B$81,INDEX(Assumptions!$B$42:$H$42,MIN(E23,7)),INDEX(Assumptions!$B$43:$H$43,MIN(E23,7))),0)) -> 440 | F24: =IF(F$2>Assumptions!$B$82,E24*(1-Assumptions!$B$83),IF(F23>=1,Assumptions!$B$74*CHOOSE(Assumptions!$B$81,INDEX(Assumptions!$B$42:$H$42,MIN(F23,7)),INDEX(Assumptions!$B$43:$H$43,MIN(F23,7))),0)) -> 600 | G24: =IF(G$2>Assumptions!$B$82,F24*(1-Assumptions!$B$83),IF(G23>=1,Assumptions!$B$74*CHOOSE(Assumptions!$B$81,INDEX(Assumptions!$B$42:$H$42,MIN(G23,7)),INDEX(Assumptions!$B$43:$H$43,MIN(G23,7))),0)) -> 720 | H24: =IF(H$2>Assumptions!$B$82,G24*(1-Assumptions!$B$83),IF(H23>=1,Assumptions!$B$74*CHOOSE(Assumptions!$B$81,INDEX(Assumptions!$B$42:$H$42,MIN(H23,7)),INDEX(Assumptions!$B$43:$H$43,MIN(H23,7))),0)) -> 800 | I24: =IF(I$2>Assumptions!$B$82,H24*(1-Assumptions!$B$83),IF(I23>=1,Assumptions!$B$74*CHOOSE(Assumptions!$B$81,INDEX(Assumptions!$B$42:$H$42,MIN(I23,7)),INDEX(Assumptions!$B$43:$H$43,MIN(I23,7))),0)) -> 800 | J24: =IF(J$2>Assumptions!$B$82,I24*(1-Assumptions!$B$83),IF(J23>=1,Assumptions!$B$74*CHOOSE(Assumptions!$B$81,INDEX(Assumptions!$B$42:$H$42,MIN(J23,7)),INDEX(Assumptions!$B$43:$H$43,MIN(J23,7))),0)) -> 800 | K24: =IF(K$2>Assumptions!$B$82,J24*(1-Assumptions!$B$83),IF(K23>=1,Assumptions!$B$74*CHOOSE(Assumptions!$B$81,INDEX(Assumptions!$B$42:$H$42,MIN(K23,7)),INDEX(Assumptions!$B$43:$H$43,MIN(K23,7))),0)) -> 800 | ... Z24: =IF(Z$2>Assumptions!$B$82,Y24*(1-Assumptions!$B$83),IF(Z23>=1,Assumptions!$B$74*CHOOSE(Assumptions!$B$81,INDEX(Assumptions!$B$42:$H$42,MIN(Z23,7)),INDEX(Assumptions!$B$43:$H$43,MIN(Z23,7))),0)) -> 0.08388608
A25: Years since launch (approved after a CRL) | C25: =C$2-(Assumptions!$B$73+Assumptions!$B$34)+1 -> -1 | D25: =D$2-(Assumptions!$B$73+Assumptions!$B$34)+1 -> 0 | E25: =E$2-(Assumptions!$B$73+Assumptions!$B$34)+1 -> 1 | F25: =F$2-(Assumptions!$B$73+Assumptions!$B$34)+1 -> 2 | G25: =G$2-(Assumptions!$B$73+Assumptions!$B$34)+1 -> 3 | H25: =H$2-(Assumptions!$B$73+Assumptions!$B$34)+1 -> 4 | I25: =I$2-(Assumptions!$B$73+Assumptions!$B$34)+1 -> 5 | J25: =J$2-(Assumptions!$B$73+Assumptions!$B$34)+1 -> 6 | ... Z25: =Z$2-(Assumptions!$B$73+Assumptions!$B$34)+1 -> 22
A26: Net sales, unrisked (approved after a CRL) | C26: =IF(C$2>Assumptions!$B$82,0*(1-Assumptions!$B$83),IF(C25>=1,Assumptions!$B$74*CHOOSE(Assumptions!$B$81,INDEX(Assumptions!$B$42:$H$42,MIN(C25,7)),INDEX(Assumptions!$B$43:$H$43,MIN(C25,7))),0)) -> 0 | D26: =IF(D$2>Assumptions!$B$82,C26*(1-Assumptions!$B$83),IF(D25>=1,Assumptions!$B$74*CHOOSE(Assumptions!$B$81,INDEX(Assumptions!$B$42:$H$42,MIN(D25,7)),INDEX(Assumptions!$B$43:$H$43,MIN(D25,7))),0)) -> 0 | E26: =IF(E$2>Assumptions!$B$82,D26*(1-Assumptions!$B$83),IF(E25>=1,Assumptions!$B$74*CHOOSE(Assumptions!$B$81,INDEX(Assumptions!$B$42:$H$42,MIN(E25,7)),INDEX(Assumptions!$B$43:$H$43,MIN(E25,7))),0)) -> 120 | F26: =IF(F$2>Assumptions!$B$82,E26*(1-Assumptions!$B$83),IF(F25>=1,Assumptions!$B$74*CHOOSE(Assumptions!$B$81,INDEX(Assumptions!$B$42:$H$42,MIN(F25,7)),INDEX(Assumptions!$B$43:$H$43,MIN(F25,7))),0)) -> 280 | G26: =IF(G$2>Assumptions!$B$82,F26*(1-Assumptions!$B$83),IF(G25>=1,Assumptions!$B$74*CHOOSE(Assumptions!$B$81,INDEX(Assumptions!$B$42:$H$42,MIN(G25,7)),INDEX(Assumptions!$B$43:$H$43,MIN(G25,7))),0)) -> 440 | H26: =IF(H$2>Assumptions!$B$82,G26*(1-Assumptions!$B$83),IF(H25>=1,Assumptions!$B$74*CHOOSE(Assumptions!$B$81,INDEX(Assumptions!$B$42:$H$42,MIN(H25,7)),INDEX(Assumptions!$B$43:$H$43,MIN(H25,7))),0)) -> 600 | I26: =IF(I$2>Assumptions!$B$82,H26*(1-Assumptions!$B$83),IF(I25>=1,Assumptions!$B$74*CHOOSE(Assumptions!$B$81,INDEX(Assumptions!$B$42:$H$42,MIN(I25,7)),INDEX(Assumptions!$B$43:$H$43,MIN(I25,7))),0)) -> 720 | J26: =IF(J$2>Assumptions!$B$82,I26*(1-Assumptions!$B$83),IF(J25>=1,Assumptions!$B$74*CHOOSE(Assumptions!$B$81,INDEX(Assumptions!$B$42:$H$42,MIN(J25,7)),INDEX(Assumptions!$B$43:$H$43,MIN(J25,7))),0)) -> 800 | K26: =IF(K$2>Assumptions!$B$82,J26*(1-Assumptions!$B$83),IF(K25>=1,Assumptions!$B$74*CHOOSE(Assumptions!$B$81,INDEX(Assumptions!$B$42:$H$42,MIN(K25,7)),INDEX(Assumptions!$B$43:$H$43,MIN(K25,7))),0)) -> 800 | ... Z26: =IF(Z$2>Assumptions!$B$82,Y26*(1-Assumptions!$B$83),IF(Z25>=1,Assumptions!$B$74*CHOOSE(Assumptions!$B$81,INDEX(Assumptions!$B$42:$H$42,MIN(Z25,7)),INDEX(Assumptions!$B$43:$H$43,MIN(Z25,7))),0)) -> 0.08388608
A27: Product net sales, risk-adjusted | C27: =Assumptions!$B$32*C24+(1-Assumptions!$B$32)*Assumptions!$B$33*C26 -> 105.6 | D27: =Assumptions!$B$32*D24+(1-Assumptions!$B$32)*Assumptions!$B$33*D26 -> 246.4 | E27: =Assumptions!$B$32*E24+(1-Assumptions!$B$32)*Assumptions!$B$33*E26 -> 398.72 | F27: =Assumptions!$B$32*F24+(1-Assumptions!$B$32)*Assumptions!$B$33*F26 -> 554.88 | G27: =Assumptions!$B$32*G24+(1-Assumptions!$B$32)*Assumptions!$B$33*G26 -> 675.84 | H27: =Assumptions!$B$32*H24+(1-Assumptions!$B$32)*Assumptions!$B$33*H26 -> 761.6 | I27: =Assumptions!$B$32*I24+(1-Assumptions!$B$32)*Assumptions!$B$33*I26 -> 773.12 | J27: =Assumptions!$B$32*J24+(1-Assumptions!$B$32)*Assumptions!$B$33*J26 -> 780.8 | ... Z27: =Assumptions!$B$32*Z24+(1-Assumptions!$B$32)*Assumptions!$B$33*Z26 -> 0.081872814
A28: Company revenue, risk-adjusted (incl. milestones) | C28: =C27*Assumptions!$B$76+Assumptions!$B$32*IFERROR(INDEX(Assumptions!$B$88:$K$88,MATCH(C$2-Assumptions!$B$73,Assumptions!$B$87:$K$87,0)),0)+(1-Assumptions!$B$32)*Assumptions!$B$33*IFERROR(INDEX(Assumptions!$B$88:$K$88,MATCH(C$2-Assumptions!$B$73-Assumptions!$B$34,Assumptions!$B$87:$K$87,0)),0) -> 237.6 | D28: =D27*Assumptions!$B$76+Assumptions!$B$32*IFERROR(INDEX(Assumptions!$B$88:$K$88,MATCH(D$2-Assumptions!$B$73,Assumptions!$B$87:$K$87,0)),0)+(1-Assumptions!$B$32)*Assumptions!$B$33*IFERROR(INDEX(Assumptions!$B$88:$K$88,MATCH(D$2-Assumptions!$B$73-Assumptions!$B$34,Assumptions!$B$87:$K$87,0)),0) -> 246.4 | E28: =E27*Assumptions!$B$76+Assumptions!$B$32*IFERROR(INDEX(Assumptions!$B$88:$K$88,MATCH(E$2-Assumptions!$B$73,Assumptions!$B$87:$K$87,0)),0)+(1-Assumptions!$B$32)*Assumptions!$B$33*IFERROR(INDEX(Assumptions!$B$88:$K$88,MATCH(E$2-Assumptions!$B$73-Assumptions!$B$34,Assumptions!$B$87:$K$87,0)),0) -> 413.12 | F28: =F27*Assumptions!$B$76+Assumptions!$B$32*IFERROR(INDEX(Assumptions!$B$88:$K$88,MATCH(F$2-Assumptions!$B$73,Assumptions!$B$87:$K$87,0)),0)+(1-Assumptions!$B$32)*Assumptions!$B$33*IFERROR(INDEX(Assumptions!$B$88:$K$88,MATCH(F$2-Assumptions!$B$73-Assumptions!$B$34,Assumptions!$B$87:$K$87,0)),0) -> 554.88 | G28: =G27*Assumptions!$B$76+Assumptions!$B$32*IFERROR(INDEX(Assumptions!$B$88:$K$88,MATCH(G$2-Assumptions!$B$73,Assumptions!$B$87:$K$87,0)),0)+(1-Assumptions!$B$32)*Assumptions!$B$33*IFERROR(INDEX(Assumptions!$B$88:$K$88,MATCH(G$2-Assumptions!$B$73-Assumptions!$B$34,Assumptions!$B$87:$K$87,0)),0) -> 675.84 | H28: =H27*Assumptions!$B$76+Assumptions!$B$32*IFERROR(INDEX(Assumptions!$B$88:$K$88,MATCH(H$2-Assumptions!$B$73,Assumptions!$B$87:$K$87,0)),0)+(1-Assumptions!$B$32)*Assumptions!$B$33*IFERROR(INDEX(Assumptions!$B$88:$K$88,MATCH(H$2-Assumptions!$B$73-Assumptions!$B$34,Assumptions!$B$87:$K$87,0)),0) -> 761.6 | I28: =I27*Assumptions!$B$76+Assumptions!$B$32*IFERROR(INDEX(Assumptions!$B$88:$K$88,MATCH(I$2-Assumptions!$B$73,Assumptions!$B$87:$K$87,0)),0)+(1-Assumptions!$B$32)*Assumptions!$B$33*IFERROR(INDEX(Assumptions!$B$88:$K$88,MATCH(I$2-Assumptions!$B$73-Assumptions!$B$34,Assumptions!$B$87:$K$87,0)),0) -> 773.12 | J28: =J27*Assumptions!$B$76+Assumptions!$B$32*IFERROR(INDEX(Assumptions!$B$88:$K$88,MATCH(J$2-Assumptions!$B$73,Assumptions!$B$87:$K$87,0)),0)+(1-Assumptions!$B$32)*Assumptions!$B$33*IFERROR(INDEX(Assumptions!$B$88:$K$88,MATCH(J$2-Assumptions!$B$73-Assumptions!$B$34,Assumptions!$B$87:$K$87,0)),0) -> 780.8 | ... Z28: =Z27*Assumptions!$B$76+Assumptions!$B$32*IFERROR(INDEX(Assumptions!$B$88:$K$88,MATCH(Z$2-Assumptions!$B$73,Assumptions!$B$87:$K$87,0)),0)+(1-Assumptions!$B$32)*Assumptions!$B$33*IFERROR(INDEX(Assumptions!$B$88:$K$88,MATCH(Z$2-Assumptions!$B$73-Assumptions!$B$34,Assumptions!$B$87:$K$87,0)),0) -> 0.081872814
A29: COGS + royalties, risk-adjusted | C29: =C27*(Assumptions!$B$77+Assumptions!$B$78) -> 8.448 | D29: =D27*(Assumptions!$B$77+Assumptions!$B$78) -> 19.712 | E29: =E27*(Assumptions!$B$77+Assumptions!$B$78) -> 31.8976 | F29: =F27*(Assumptions!$B$77+Assumptions!$B$78) -> 44.3904 | G29: =G27*(Assumptions!$B$77+Assumptions!$B$78) -> 54.0672 | H29: =H27*(Assumptions!$B$77+Assumptions!$B$78) -> 60.928 | I29: =I27*(Assumptions!$B$77+Assumptions!$B$78) -> 61.8496 | J29: =J27*(Assumptions!$B$77+Assumptions!$B$78) -> 62.464 | ... Z29: =Z27*(Assumptions!$B$77+Assumptions!$B$78) -> 0.0065498251
A30: Commercial SG&A, risk-adjusted | C30: =Assumptions!$B$32*IF(Assumptions!$B$79=0,0,IF(C23=0,Assumptions!$B$80,IF(C23>=1,C24*IF(OR(Assumptions!$B$76<1,C23>5),Assumptions!$B$79,MAX(Assumptions!$B$79,INDEX(Assumptions!$B$44:$F$44,C23))),0)))+(1-Assumptions!$B$32)*Assumptions!$B$33*IF(Assumptions!$B$79=0,0,IF(C25=0,Assumptions!$B$80,IF(C25>=1,C26*IF(OR(Assumptions!$B$76<1,C25>5),Assumptions!$B$79,MAX(Assumptions!$B$79,INDEX(Assumptions!$B$44:$F$44,C25))),0))) -> 95.04 | D30: =Assumptions!$B$32*IF(Assumptions!$B$79=0,0,IF(D23=0,Assumptions!$B$80,IF(D23>=1,D24*IF(OR(Assumptions!$B$76<1,D23>5),Assumptions!$B$79,MAX(Assumptions!$B$79,INDEX(Assumptions!$B$44:$F$44,D23))),0)))+(1-Assumptions!$B$32)*Assumptions!$B$33*IF(Assumptions!$B$79=0,0,IF(D25=0,Assumptions!$B$80,IF(D25>=1,D26*IF(OR(Assumptions!$B$76<1,D25>5),Assumptions!$B$79,MAX(Assumptions!$B$79,INDEX(Assumptions!$B$44:$F$44,D25))),0))) -> 138.4 | E30: =Assumptions!$B$32*IF(Assumptions!$B$79=0,0,IF(E23=0,Assumptions!$B$80,IF(E23>=1,E24*IF(OR(Assumptions!$B$76<1,E23>5),Assumptions!$B$79,MAX(Assumptions!$B$79,INDEX(Assumptions!$B$44:$F$44,E23))),0)))+(1-Assumptions!$B$32)*Assumptions!$B$33*IF(Assumptions!$B$79=0,0,IF(E25=0,Assumptions!$B$80,IF(E25>=1,E26*IF(OR(Assumptions!$B$76<1,E25>5),Assumptions!$B$79,MAX(Assumptions!$B$79,INDEX(Assumptions!$B$44:$F$44,E25))),0))) -> 165.248 | F30: =Assumptions!$B$32*IF(Assumptions!$B$79=0,0,IF(F23=0,Assumptions!$B$80,IF(F23>=1,F24*IF(OR(Assumptions!$B$76<1,F23>5),Assumptions!$B$79,MAX(Assumptions!$B$79,INDEX(Assumptions!$B$44:$F$44,F23))),0)))+(1-Assumptions!$B$32)*Assumptions!$B$33*IF(Assumptions!$B$79=0,0,IF(F25=0,Assumptions!$B$80,IF(F25>=1,F26*IF(OR(Assumptions!$B$76<1,F25>5),Assumptions!$B$79,MAX(Assumptions!$B$79,INDEX(Assumptions!$B$44:$F$44,F25))),0))) -> 183.744 | G30: =Assumptions!$B$32*IF(Assumptions!$B$79=0,0,IF(G23=0,Assumptions!$B$80,IF(G23>=1,G24*IF(OR(Assumptions!$B$76<1,G23>5),Assumptions!$B$79,MAX(Assumptions!$B$79,INDEX(Assumptions!$B$44:$F$44,G23))),0)))+(1-Assumptions!$B$32)*Assumptions!$B$33*IF(Assumptions!$B$79=0,0,IF(G25=0,Assumptions!$B$80,IF(G25>=1,G26*IF(OR(Assumptions!$B$76<1,G25>5),Assumptions!$B$79,MAX(Assumptions!$B$79,INDEX(Assumptions!$B$44:$F$44,G25))),0))) -> 194.304 | H30: =Assumptions!$B$32*IF(Assumptions!$B$79=0,0,IF(H23=0,Assumptions!$B$80,IF(H23>=1,H24*IF(OR(Assumptions!$B$76<1,H23>5),Assumptions!$B$79,MAX(Assumptions!$B$79,INDEX(Assumptions!$B$44:$F$44,H23))),0)))+(1-Assumptions!$B$32)*Assumptions!$B$33*IF(Assumptions!$B$79=0,0,IF(H25=0,Assumptions!$B$80,IF(H25>=1,H26*IF(OR(Assumptions!$B$76<1,H25>5),Assumptions!$B$79,MAX(Assumptions!$B$79,INDEX(Assumptions!$B$44:$F$44,H25))),0))) -> 194.432 | I30: =Assumptions!$B$32*IF(Assumptions!$B$79=0,0,IF(I23=0,Assumptions!$B$80,IF(I23>=1,I24*IF(OR(Assumptions!$B$76<1,I23>5),Assumptions!$B$79,MAX(Assumptions!$B$79,INDEX(Assumptions!$B$44:$F$44,I23))),0)))+(1-Assumptions!$B$32)*Assumptions!$B$33*IF(Assumptions!$B$79=0,0,IF(I25=0,Assumptions!$B$80,IF(I25>=1,I26*IF(OR(Assumptions!$B$76<1,I25>5),Assumptions!$B$79,MAX(Assumptions!$B$79,INDEX(Assumptions!$B$44:$F$44,I25))),0))) -> 195.3536 | J30: =Assumptions!$B$32*IF(Assumptions!$B$79=0,0,IF(J23=0,Assumptions!$B$80,IF(J23>=1,J24*IF(OR(Assumptions!$B$76<1,J23>5),Assumptions!$B$79,MAX(Assumptions!$B$79,INDEX(Assumptions!$B$44:$F$44,J23))),0)))+(1-Assumptions!$B$32)*Assumptions!$B$33*IF(Assumptions!$B$79=0,0,IF(J25=0,Assumptions!$B$80,IF(J25>=1,J26*IF(OR(Assumptions!$B$76<1,J25>5),Assumptions!$B$79,MAX(Assumptions!$B$79,INDEX(Assumptions!$B$44:$F$44,J25))),0))) -> 195.2 | ... Z30: =Assumptions!$B$32*IF(Assumptions!$B$79=0,0,IF(Z23=0,Assumptions!$B$80,IF(Z23>=1,Z24*IF(OR(Assumptions!$B$76<1,Z23>5),Assumptions!$B$79,MAX(Assumptions!$B$79,INDEX(Assumptions!$B$44:$F$44,Z23))),0)))+(1-Assumptions!$B$32)*Assumptions!$B$33*IF(Assumptions!$B$79=0,0,IF(Z25=0,Assumptions!$B$80,IF(Z25>=1,Z26*IF(OR(Assumptions!$B$76<1,Z25>5),Assumptions!$B$79,MAX(Assumptions!$B$79,INDEX(Assumptions!$B$44:$F$44,Z25))),0))) -> 0.020468204
A31: Development R&D, risk-adjusted | C31: =IFERROR(INDEX(Assumptions!$B$85:$I$85,MATCH(C$2,Assumptions!$B$84:$I$84,0))*INDEX(Assumptions!$B$86:$I$86,MATCH(C$2,Assumptions!$B$84:$I$84,0)),0) -> 20 | D31: =IFERROR(INDEX(Assumptions!$B$85:$I$85,MATCH(D$2,Assumptions!$B$84:$I$84,0))*INDEX(Assumptions!$B$86:$I$86,MATCH(D$2,Assumptions!$B$84:$I$84,0)),0) -> 15 | E31: =IFERROR(INDEX(Assumptions!$B$85:$I$85,MATCH(E$2,Assumptions!$B$84:$I$84,0))*INDEX(Assumptions!$B$86:$I$86,MATCH(E$2,Assumptions!$B$84:$I$84,0)),0) -> 0 | F31: =IFERROR(INDEX(Assumptions!$B$85:$I$85,MATCH(F$2,Assumptions!$B$84:$I$84,0))*INDEX(Assumptions!$B$86:$I$86,MATCH(F$2,Assumptions!$B$84:$I$84,0)),0) -> 0 | G31: =IFERROR(INDEX(Assumptions!$B$85:$I$85,MATCH(G$2,Assumptions!$B$84:$I$84,0))*INDEX(Assumptions!$B$86:$I$86,MATCH(G$2,Assumptions!$B$84:$I$84,0)),0) -> 0 | H31: =IFERROR(INDEX(Assumptions!$B$85:$I$85,MATCH(H$2,Assumptions!$B$84:$I$84,0))*INDEX(Assumptions!$B$86:$I$86,MATCH(H$2,Assumptions!$B$84:$I$84,0)),0) -> 0 | I31: =IFERROR(INDEX(Assumptions!$B$85:$I$85,MATCH(I$2,Assumptions!$B$84:$I$84,0))*INDEX(Assumptions!$B$86:$I$86,MATCH(I$2,Assumptions!$B$84:$I$84,0)),0) -> 0 | J31: =IFERROR(INDEX(Assumptions!$B$85:$I$85,MATCH(J$2,Assumptions!$B$84:$I$84,0))*INDEX(Assumptions!$B$86:$I$86,MATCH(J$2,Assumptions!$B$84:$I$84,0)),0) -> 0 | ... Z31: =IFERROR(INDEX(Assumptions!$B$85:$I$85,MATCH(Z$2,Assumptions!$B$84:$I$84,0))*INDEX(Assumptions!$B$86:$I$86,MATCH(Z$2,Assumptions!$B$84:$I$84,0)),0) -> 0
A32: Program contribution (pre-tax) | C32: =C28-C29-C30-C31 -> 114.112 | D32: =D28-D29-D30-D31 -> 73.288 | E32: =E28-E29-E30-E31 -> 215.9744 | F32: =F28-F29-F30-F31 -> 326.7456 | G32: =G28-G29-G30-G31 -> 427.4688 | H32: =H28-H29-H30-H31 -> 506.24 | I32: =I28-I29-I30-I31 -> 515.9168 | J32: =J28-J29-J30-J31 -> 523.136 | ... Z32: =Z28-Z29-Z30-Z31 -> 0.054854785
A34: Encaleret — ADH1 (PDUFA May 8, 2027)
A35: Years since launch | C35: =C$2-Assumptions!$B$91+1 -> 1 | D35: =D$2-Assumptions!$B$91+1 -> 2 | E35: =E$2-Assumptions!$B$91+1 -> 3 | F35: =F$2-Assumptions!$B$91+1 -> 4 | G35: =G$2-Assumptions!$B$91+1 -> 5 | H35: =H$2-Assumptions!$B$91+1 -> 6 | I35: =I$2-Assumptions!$B$91+1 -> 7 | J35: =J$2-Assumptions!$B$91+1 -> 8 | ... Z35: =Z$2-Assumptions!$B$91+1 -> 24
A36: Net sales, unrisked | C36: =IF(C$2>Assumptions!$B$100,0*(1-Assumptions!$B$101),IF(C35>=1,Assumptions!$B$92*CHOOSE(Assumptions!$B$99,INDEX(Assumptions!$B$42:$H$42,MIN(C35,7)),INDEX(Assumptions!$B$43:$H$43,MIN(C35,7))),0)) -> 120 | D36: =IF(D$2>Assumptions!$B$100,C36*(1-Assumptions!$B$101),IF(D35>=1,Assumptions!$B$92*CHOOSE(Assumptions!$B$99,INDEX(Assumptions!$B$42:$H$42,MIN(D35,7)),INDEX(Assumptions!$B$43:$H$43,MIN(D35,7))),0)) -> 280 | E36: =IF(E$2>Assumptions!$B$100,D36*(1-Assumptions!$B$101),IF(E35>=1,Assumptions!$B$92*CHOOSE(Assumptions!$B$99,INDEX(Assumptions!$B$42:$H$42,MIN(E35,7)),INDEX(Assumptions!$B$43:$H$43,MIN(E35,7))),0)) -> 440 | F36: =IF(F$2>Assumptions!$B$100,E36*(1-Assumptions!$B$101),IF(F35>=1,Assumptions!$B$92*CHOOSE(Assumptions!$B$99,INDEX(Assumptions!$B$42:$H$42,MIN(F35,7)),INDEX(Assumptions!$B$43:$H$43,MIN(F35,7))),0)) -> 600 | G36: =IF(G$2>Assumptions!$B$100,F36*(1-Assumptions!$B$101),IF(G35>=1,Assumptions!$B$92*CHOOSE(Assumptions!$B$99,INDEX(Assumptions!$B$42:$H$42,MIN(G35,7)),INDEX(Assumptions!$B$43:$H$43,MIN(G35,7))),0)) -> 720 | H36: =IF(H$2>Assumptions!$B$100,G36*(1-Assumptions!$B$101),IF(H35>=1,Assumptions!$B$92*CHOOSE(Assumptions!$B$99,INDEX(Assumptions!$B$42:$H$42,MIN(H35,7)),INDEX(Assumptions!$B$43:$H$43,MIN(H35,7))),0)) -> 800 | I36: =IF(I$2>Assumptions!$B$100,H36*(1-Assumptions!$B$101),IF(I35>=1,Assumptions!$B$92*CHOOSE(Assumptions!$B$99,INDEX(Assumptions!$B$42:$H$42,MIN(I35,7)),INDEX(Assumptions!$B$43:$H$43,MIN(I35,7))),0)) -> 800 | J36: =IF(J$2>Assumptions!$B$100,I36*(1-Assumptions!$B$101),IF(J35>=1,Assumptions!$B$92*CHOOSE(Assumptions!$B$99,INDEX(Assumptions!$B$42:$H$42,MIN(J35,7)),INDEX(Assumptions!$B$43:$H$43,MIN(J35,7))),0)) -> 800 | K36: =IF(K$2>Assumptions!$B$100,J36*(1-Assumptions!$B$101),IF(K35>=1,Assumptions!$B$92*CHOOSE(Assumptions!$B$99,INDEX(Assumptions!$B$42:$H$42,MIN(K35,7)),INDEX(Assumptions!$B$43:$H$43,MIN(K35,7))),0)) -> 800 | ... Z36: =IF(Z$2>Assumptions!$B$100,Y36*(1-Assumptions!$B$101),IF(Z35>=1,Assumptions!$B$92*CHOOSE(Assumptions!$B$99,INDEX(Assumptions!$B$42:$H$42,MIN(Z35,7)),INDEX(Assumptions!$B$43:$H$43,MIN(Z35,7))),0)) -> 0.2097152
A37: Product net sales, risk-adjusted | C37: =C36*MIN(1,Assumptions!$B$93*Assumptions!$B$37) -> 104.4 | D37: =D36*MIN(1,Assumptions!$B$93*Assumptions!$B$37) -> 243.6 | E37: =E36*MIN(1,Assumptions!$B$93*Assumptions!$B$37) -> 382.8 | F37: =F36*MIN(1,Assumptions!$B$93*Assumptions!$B$37) -> 522 | G37: =G36*MIN(1,Assumptions!$B$93*Assumptions!$B$37) -> 626.4 | H37: =H36*MIN(1,Assumptions!$B$93*Assumptions!$B$37) -> 696 | I37: =I36*MIN(1,Assumptions!$B$93*Assumptions!$B$37) -> 696 | J37: =J36*MIN(1,Assumptions!$B$93*Assumptions!$B$37) -> 696 | ... Z37: =Z36*MIN(1,Assumptions!$B$93*Assumptions!$B$37) -> 0.18245222
A38: Company revenue, risk-adjusted (incl. milestones) | C38: =C37*Assumptions!$B$94 -> 104.4 | D38: =D37*Assumptions!$B$94 -> 243.6 | E38: =E37*Assumptions!$B$94 -> 382.8 | F38: =F37*Assumptions!$B$94 -> 522 | G38: =G37*Assumptions!$B$94 -> 626.4 | H38: =H37*Assumptions!$B$94 -> 696 | I38: =I37*Assumptions!$B$94 -> 696 | J38: =J37*Assumptions!$B$94 -> 696 | ... Z38: =Z37*Assumptions!$B$94 -> 0.18245222
A39: COGS + royalties, risk-adjusted | C39: =C37*(Assumptions!$B$95+Assumptions!$B$96) -> 8.352 | D39: =D37*(Assumptions!$B$95+Assumptions!$B$96) -> 19.488 | E39: =E37*(Assumptions!$B$95+Assumptions!$B$96) -> 30.624 | F39: =F37*(Assumptions!$B$95+Assumptions!$B$96) -> 41.76 | G39: =G37*(Assumptions!$B$95+Assumptions!$B$96) -> 50.112 | H39: =H37*(Assumptions!$B$95+Assumptions!$B$96) -> 55.68 | I39: =I37*(Assumptions!$B$95+Assumptions!$B$96) -> 55.68 | J39: =J37*(Assumptions!$B$95+Assumptions!$B$96) -> 55.68 | ... Z39: =Z37*(Assumptions!$B$95+Assumptions!$B$96) -> 0.014596178
A40: Commercial SG&A, risk-adjusted | C40: =MIN(1,Assumptions!$B$93*Assumptions!$B$37)*IF(Assumptions!$B$97=0,0,IF(C35=0,Assumptions!$B$98,IF(C35>=1,C36*IF(OR(Assumptions!$B$94<1,C35>5),Assumptions!$B$97,MAX(Assumptions!$B$97,INDEX(Assumptions!$B$44:$F$44,C35))),0))) -> 93.96 | D40: =MIN(1,Assumptions!$B$93*Assumptions!$B$37)*IF(Assumptions!$B$97=0,0,IF(D35=0,Assumptions!$B$98,IF(D35>=1,D36*IF(OR(Assumptions!$B$94<1,D35>5),Assumptions!$B$97,MAX(Assumptions!$B$97,INDEX(Assumptions!$B$44:$F$44,D35))),0))) -> 133.98 | E40: =MIN(1,Assumptions!$B$93*Assumptions!$B$37)*IF(Assumptions!$B$97=0,0,IF(E35=0,Assumptions!$B$98,IF(E35>=1,E36*IF(OR(Assumptions!$B$94<1,E35>5),Assumptions!$B$97,MAX(Assumptions!$B$97,INDEX(Assumptions!$B$44:$F$44,E35))),0))) -> 153.12 | F40: =MIN(1,Assumptions!$B$93*Assumptions!$B$37)*IF(Assumptions!$B$97=0,0,IF(F35=0,Assumptions!$B$98,IF(F35>=1,F36*IF(OR(Assumptions!$B$94<1,F35>5),Assumptions!$B$97,MAX(Assumptions!$B$97,INDEX(Assumptions!$B$44:$F$44,F35))),0))) -> 167.04 | G40: =MIN(1,Assumptions!$B$93*Assumptions!$B$37)*IF(Assumptions!$B$97=0,0,IF(G35=0,Assumptions!$B$98,IF(G35>=1,G36*IF(OR(Assumptions!$B$94<1,G35>5),Assumptions!$B$97,MAX(Assumptions!$B$97,INDEX(Assumptions!$B$44:$F$44,G35))),0))) -> 175.392 | H40: =MIN(1,Assumptions!$B$93*Assumptions!$B$37)*IF(Assumptions!$B$97=0,0,IF(H35=0,Assumptions!$B$98,IF(H35>=1,H36*IF(OR(Assumptions!$B$94<1,H35>5),Assumptions!$B$97,MAX(Assumptions!$B$97,INDEX(Assumptions!$B$44:$F$44,H35))),0))) -> 174 | I40: =MIN(1,Assumptions!$B$93*Assumptions!$B$37)*IF(Assumptions!$B$97=0,0,IF(I35=0,Assumptions!$B$98,IF(I35>=1,I36*IF(OR(Assumptions!$B$94<1,I35>5),Assumptions!$B$97,MAX(Assumptions!$B$97,INDEX(Assumptions!$B$44:$F$44,I35))),0))) -> 174 | J40: =MIN(1,Assumptions!$B$93*Assumptions!$B$37)*IF(Assumptions!$B$97=0,0,IF(J35=0,Assumptions!$B$98,IF(J35>=1,J36*IF(OR(Assumptions!$B$94<1,J35>5),Assumptions!$B$97,MAX(Assumptions!$B$97,INDEX(Assumptions!$B$44:$F$44,J35))),0))) -> 174 | ... Z40: =MIN(1,Assumptions!$B$93*Assumptions!$B$37)*IF(Assumptions!$B$97=0,0,IF(Z35=0,Assumptions!$B$98,IF(Z35>=1,Z36*IF(OR(Assumptions!$B$94<1,Z35>5),Assumptions!$B$97,MAX(Assumptions!$B$97,INDEX(Assumptions!$B$44:$F$44,Z35))),0))) -> 0.045613056
A41: Development R&D, risk-adjusted | C41: =IFERROR(INDEX(Assumptions!$B$103:$I$103,MATCH(C$2,Assumptions!$B$102:$I$102,0))*INDEX(Assumptions!$B$104:$I$104,MATCH(C$2,Assumptions!$B$102:$I$102,0)),0) -> 10 | D41: =IFERROR(INDEX(Assumptions!$B$103:$I$103,MATCH(D$2,Assumptions!$B$102:$I$102,0))*INDEX(Assumptions!$B$104:$I$104,MATCH(D$2,Assumptions!$B$102:$I$102,0)),0) -> 0 | E41: =IFERROR(INDEX(Assumptions!$B$103:$I$103,MATCH(E$2,Assumptions!$B$102:$I$102,0))*INDEX(Assumptions!$B$104:$I$104,MATCH(E$2,Assumptions!$B$102:$I$102,0)),0) -> 0 | F41: =IFERROR(INDEX(Assumptions!$B$103:$I$103,MATCH(F$2,Assumptions!$B$102:$I$102,0))*INDEX(Assumptions!$B$104:$I$104,MATCH(F$2,Assumptions!$B$102:$I$102,0)),0) -> 0 | G41: =IFERROR(INDEX(Assumptions!$B$103:$I$103,MATCH(G$2,Assumptions!$B$102:$I$102,0))*INDEX(Assumptions!$B$104:$I$104,MATCH(G$2,Assumptions!$B$102:$I$102,0)),0) -> 0 | H41: =IFERROR(INDEX(Assumptions!$B$103:$I$103,MATCH(H$2,Assumptions!$B$102:$I$102,0))*INDEX(Assumptions!$B$104:$I$104,MATCH(H$2,Assumptions!$B$102:$I$102,0)),0) -> 0 | I41: =IFERROR(INDEX(Assumptions!$B$103:$I$103,MATCH(I$2,Assumptions!$B$102:$I$102,0))*INDEX(Assumptions!$B$104:$I$104,MATCH(I$2,Assumptions!$B$102:$I$102,0)),0) -> 0 | J41: =IFERROR(INDEX(Assumptions!$B$103:$I$103,MATCH(J$2,Assumptions!$B$102:$I$102,0))*INDEX(Assumptions!$B$104:$I$104,MATCH(J$2,Assumptions!$B$102:$I$102,0)),0) -> 0 | ... Z41: =IFERROR(INDEX(Assumptions!$B$103:$I$103,MATCH(Z$2,Assumptions!$B$102:$I$102,0))*INDEX(Assumptions!$B$104:$I$104,MATCH(Z$2,Assumptions!$B$102:$I$102,0)),0) -> 0
A42: Program contribution (pre-tax) | C42: =C38-C39-C40-C41 -> -7.912 | D42: =D38-D39-D40-D41 -> 90.132 | E42: =E38-E39-E40-E41 -> 199.056 | F42: =F38-F39-F40-F41 -> 313.2 | G42: =G38-G39-G40-G41 -> 400.896 | H42: =H38-H39-H40-H41 -> 466.32 | I42: =I38-I39-I40-I41 -> 466.32 | J42: =J38-J39-J40-J41 -> 466.32 | ... Z42: =Z38-Z39-Z40-Z41 -> 0.12224299
A44: Infigratinib — achondroplasia (PDUFA Feb 4, 2027)
A45: Years since launch | C45: =C$2-Assumptions!$B$107+1 -> 1 | D45: =D$2-Assumptions!$B$107+1 -> 2 | E45: =E$2-Assumptions!$B$107+1 -> 3 | F45: =F$2-Assumptions!$B$107+1 -> 4 | G45: =G$2-Assumptions!$B$107+1 -> 5 | H45: =H$2-Assumptions!$B$107+1 -> 6 | I45: =I$2-Assumptions!$B$107+1 -> 7 | J45: =J$2-Assumptions!$B$107+1 -> 8 | ... Z45: =Z$2-Assumptions!$B$107+1 -> 24
...

Sheet NPV
A1: BBIO — risk-adjusted NPV (rNPV), $mm except per share
A3: Scenario | B3: =Assumptions!$C$4 -> Base
A4: Valuation date | B4: =Assumptions!$B$13 -> 46311
A5: Discount rate | B5: =Assumptions!$B$14 -> 0.095
A7: Period | C7: 2H 2026 | D7: 2027 | E7: 2028 | F7: 2029 | G7: 2030 | H7: 2031 | I7: 2032 | J7: 2033 | K7: 2034 | L7: 2035 | M7: 2036 | N7: 2037 | O7: 2038 | P7: 2039 | Q7: 2040 | R7: 2041 | S7: 2042 | T7: 2043 | U7: 2044 | V7: 2045 | W7: 2046 | X7: 2047 | Y7: 2048 | Z7: 2049 | AA7: 2050
A8: Revenue, risk-adjusted | C8: =SUM('Quarterly Model'!H2:I2) -> 589 | D8: ='Yearly Model'!H2 -> 1910.676 | E8: ='Yearly Model'!I2 -> 2676.932 | F8: ='Yearly Model'!J2 -> 3752.158 | G8: ='Yearly Model'!K2 -> 4849.674 | H8: ='Yearly Model'!L2 -> 5904.91 | I8: ='Yearly Model'!M2 -> 6373.68 | J8: ='Yearly Model'!N2 -> 6625.02 | K8: ='Yearly Model'!O2 -> 6736.65 | ... AA8: ='Yearly Model'!AE2 -> 0.83034636
A9: Operating income (EBIT) | C9: =SUM('Quarterly Model'!H8:I8) -> -142.518 | D9: ='Yearly Model'!H8 -> 224.65588 | E9: ='Yearly Model'!I8 -> 754.72584 | F9: ='Yearly Model'!J8 -> 1416.1452 | G9: ='Yearly Model'!K8 -> 2049.8685 | H9: ='Yearly Model'!L8 -> 2609.6431 | I9: ='Yearly Model'!M8 -> 2918.017 | J9: ='Yearly Model'!N8 -> 3056.617 | K9: ='Yearly Model'!O8 -> 3147.184 | ... AA9: ='Yearly Model'!AE8 -> 0.39070141
A10: Taxes on EBIT (after tax-loss pool) | C10: 0 | D10: =IF(D9>0,MAX(0,D9-'Yearly Model'!G21)*Assumptions!$B$15,0) -> 0 | E10: =IF(E9>0,MAX(0,E9-'Yearly Model'!H21)*Assumptions!$B$15,0) -> 0 | F10: =IF(F9>0,MAX(0,F9-'Yearly Model'!I21)*Assumptions!$B$15,0) -> 0 | G10: =IF(G9>0,MAX(0,G9-'Yearly Model'!J21)*Assumptions!$B$15,0) -> 178.06396 | H10: =IF(H9>0,MAX(0,H9-'Yearly Model'!K21)*Assumptions!$B$15,0) -> 548.02505 | I10: =IF(I9>0,MAX(0,I9-'Yearly Model'!L21)*Assumptions!$B$15,0) -> 612.78357 | J10: =IF(J9>0,MAX(0,J9-'Yearly Model'!M21)*Assumptions!$B$15,0) -> 641.88957 | K10: =IF(K9>0,MAX(0,K9-'Yearly Model'!N21)*Assumptions!$B$15,0) -> 660.90864 | ... AA10: =IF(AA9>0,MAX(0,AA9-'Yearly Model'!AD21)*Assumptions!$B$15,0) -> 0.082047296
A11: Unlevered free cash flow | C11: =C9-C10 -> -142.518 | D11: =D9-D10 -> 224.65588 | E11: =E9-E10 -> 754.72584 | F11: =F9-F10 -> 1416.1452 | G11: =G9-G10 -> 1871.8045 | H11: =H9-H10 -> 2061.618 | I11: =I9-I10 -> 2305.2334 | J11: =J9-J10 -> 2414.7274 | ... AA11: =AA9-AA10 -> 0.30865411
A12: Cash-flow date (mid-period) | C12: =DATE(2026,10,1) -> 46296 | D12: =DATE(D7,7,1) -> 46569 | E12: =DATE(E7,7,1) -> 46935 | F12: =DATE(F7,7,1) -> 47300 | G12: =DATE(G7,7,1) -> 47665 | H12: =DATE(H7,7,1) -> 48030 | I12: =DATE(I7,7,1) -> 48396 | J12: =DATE(J7,7,1) -> 48761 | K12: =DATE(K7,7,1) -> 49126 | ... AA12: =DATE(AA7,7,1) -> 54970
A13: Years from valuation date | C13: =MAX(0,(C12-$B$4)/365.25) -> 0 | D13: =MAX(0,(D12-$B$4)/365.25) -> 0.7063655 | E13: =MAX(0,(E12-$B$4)/365.25) -> 1.7084189 | F13: =MAX(0,(F12-$B$4)/365.25) -> 2.7077344 | G13: =MAX(0,(G12-$B$4)/365.25) -> 3.70705 | H13: =MAX(0,(H12-$B$4)/365.25) -> 4.7063655 | I13: =MAX(0,(I12-$B$4)/365.25) -> 5.7084189 | J13: =MAX(0,(J12-$B$4)/365.25) -> 6.7077344 | ... AA13: =MAX(0,(AA12-$B$4)/365.25) -> 23.70705
A14: Discount factor | C14: =1/(1+$B$5)^C13 -> 1 | D14: =1/(1+$B$5)^D13 -> 0.93790581 | E14: =1/(1+$B$5)^E13 -> 0.85637538 | F14: =1/(1+$B$5)^F13 -> 0.78212656 | G14: =1/(1+$B$5)^G13 -> 0.7143152 | H14: =1/(1+$B$5)^H13 -> 0.65238317 | I14: =1/(1+$B$5)^I13 -> 0.5956727 | J14: =1/(1+$B$5)^J13 -> 0.54402713 | ... AA14: =1/(1+$B$5)^AA13 -> 0.11630744
A15: PV of free cash flow | C15: =C11*C14 -> -142.518 | D15: =D11*D14 -> 210.70605 | E15: =E11*E14 -> 646.32863 | F15: =F11*F14 -> 1107.6048 | G15: =G11*G14 -> 1337.0584 | H15: =H11*H14 -> 1344.9649 | I15: =I11*I14 -> 1373.1646 | J15: =J11*J14 -> 1313.6772 | ... AA15: =AA11*AA14 -> 0.035898771
A17: Valuation summary
A18: PV of risk-adjusted free cash flows | C18: =SUM(C15:AA15) -> 13549.072
A19: Cash & investments (Main; incl. post-quarter financing) | C19: =Main!C7 -> 1720.16
A20: Debt, convertibles & preferred at face (Main) | C20: =Main!C8 -> 3505
A21: Equity value, all claims treated as debt | C21: =C18+C19-C20 -> 11764.232
A22: Basic shares incl. pre-funded / as-converted (Main) | C22: =Main!C4 -> 195.48747
A23: Value / share before conversions | C23: =C21/C22 -> 60.178954
A25: Convertible instruments (converted if value / share before conversions > conversion price) | B25: Face ($mm) | C25: Shares (mm) | D25: Conv. price | E25: Converted?
A26: 2027 notes | B26: 550 | C26: 12.878305 | D26: 42.71 | E26: =IF(AND(C26>0,$C$23>D26),1,0) -> 1
A27: 2029 notes | B27: 747.5 | C27: 7.702988 | D27: 97.04 | E27: =IF(AND(C27>0,$C$23>D27),1,0) -> 0
A28: 2031 notes | B28: 575 | C28: 11.544448 | D28: 49.81 | E28: =IF(AND(C28>0,$C$23>D28),1,0) -> 1
A29: 2033 notes | B29: 632.5 | C29: 5.720014 | D29: 110.58 | E29: =IF(AND(C29>0,$C$23>D29),1,0) -> 0
A30: Series A preferred (7% PIK) | B30: 1000 | C30: 7.257421 | D30: 137.79 | E30: =IF(AND(C30>0,$C$23>D30),1,0) -> 0
A31: Equity value (rNPV) after conversions | C31: =C21+SUMPRODUCT(B26:B30,E26:E30) -> 12889.232
A32: Shares after conversions (mm) | C32: =C22+SUMPRODUCT(C26:C30,E26:E30) -> 219.91023
A33: Value / share before options & warrants | C33: =C31/C32 -> 58.611334
A35: Options, warrants & RSUs (treasury-stock method) | B35: Count (mm) | C35: Strike | D35: Dilution (mm)
A36: Options | B36: 10.041746 | C36: 25.76 | D36: =IF(AND(B36>0,$C$33>C36),B36*(1-C36/$C$33),0) -> 5.628344
A37: RSUs / PSUs | B37: 9.476 | C37: 0 | D37: =IF(AND(B37>0,$C$33>C37),B37*(1-C37/$C$33),0) -> 9.476
A38: Milestone awards | B38: 0.902775 | C38: 0 | D38: =IF(AND(B38>0,$C$33>C38),B38*(1-C38/$C$33),0) -> 0.902775
A39: — | B39: 0 | C39: 0 | D39: =IF(AND(B39>0,$C$33>C39),B39*(1-C39/$C$33),0) -> 0
A40: — | B40: 0 | C40: 0 | D40: =IF(AND(B40>0,$C$33>C40),B40*(1-C40/$C$33),0) -> 0
A41: — | B41: 0 | C41: 0 | D41: =IF(AND(B41>0,$C$33>C41),B41*(1-C41/$C$33),0) -> 0
A42: Diluted shares (mm) | C42: =C32+SUM(D36:D41) -> 235.91735
A43: rNPV / share, diluted | C43: =C31/C42 -> 54.634524
A44: Current price (Main) | C44: =Main!C3 -> 67.55
A45: Upside / (downside) to rNPV | C45: =C43/C44-1 -> -0.19119876
...

Sheet Options
A1: BBIO — PDUFA options analysis (per contract = 100 shares)
A3: Inputs
A4: Spot price (close 10/16/2026) | B4: 66.39
A5: Pricing date | B5: =DATE(2026,10,16) -> 46311
A6: PDUFA date | B6: =Assumptions!$B$30 -> 46353
A7: Expiry (first monthly after the PDUFA date) | B7: =DATE(2026,12,18) -> 46374
A8: Years to expiry (T) | B8: =(B7-B5)/365 -> 0.17260274
A9: Risk-free rate | B9: 0.04
A10: Reference IV for wide quotes (theo prices) | B10: 0.533
A11: Contract multiplier | B11: 100
A13: Event model (two outcomes at the PDUFA)
A14: Model value / share, probability-weighted | B14: =NPV!C43 -> 54.634524
A15: Model value / share if approved | B15: =Assumptions!$D$168 -> 55.02037
A16: Model value / share if CRL | B16: =Assumptions!$D$167 -> 51.790583
A17: Model probability of approval | B17: =Assumptions!$B$32 -> 0.88
A18: Event-move scale (share of model jump priced at expiry) | B18: 1
A19: Floor after a CRL, % of est. 12/31/2026 net cash / share | B19: 0.5
A20: Floor price after a CRL | B20: =MAX(0,B19*(NPV!C47-NPV!C20)/NPV!C22) -> 0
A21: Price if approved (center of outcome) | B21: =IF(B14>0,B4*(1+B18*(B15/B14-1)),B4+B18*(B15-B14)) -> 66.858867
A22: Price if CRL (center of outcome) | B22: =MAX(B20,IF(B14>0,B4*(1+B18*(B16/B14-1)),B4+B18*(B16-B14))) -> 62.934141
A23: Model expected price after the decision | B23: =B17*B21+(1-B17)*B22 -> 66.3879
A24: Non-event volatility (6-month realized, 3 largest days removed) | B24: 0.321
