Workbook

Sheet Main
B2: Cytokinetics, Incorporated
B3: Price | C3: =INDEX([1]Pharma!$F$1:$F$1000,MATCH("CYTK",[1]Pharma!$B$1:$B$1000,0)) -> 63.95
B4: Shares | C4: =139.023418 -> 139.02342
B5: Market Cap. | C5: =C3*C4 -> 8890.5476
B7: Cash | C7: =255.271+910.414+538.318 -> 1704.003
B8: Debt | C8: =27.358+248.202+140.5+750 -> 1166.06
B9: Enterprise V. | C9: =C5-C7+C8 -> 8352.6046
B11: rNPV / Share | C11: =NPV!C43 -> 44.742934
B12: Upside | C12: =C11/C3-1 -> -0.30034505
B13: Cash / Share | C13: =(C7-C8)/C4 -> 3.8694416
B14: Scenario | C14: =Assumptions!$C$4 -> Base
B16: PDUFA Date | C16: =Assumptions!$B$30 -> 46340
B17: P(Approval) | C17: =Assumptions!$B$32 -> 0.92
B18: If Approved | C18: =Assumptions!$D$134 -> 44.933312
B19: If CRL | C19: =Assumptions!$D$133 -> 42.393693

Sheet Yearly Model
B1: 2021 | C1: 2022 | D1: 2023 | E1: 2024 | F1: 2025 | G1: 2026 | H1: 2027 | I1: 2028 | J1: 2029 | K1: 2030 | L1: 2031 | M1: 2032 | N1: 2033 | O1: 2034 | P1: 2035 | Q1: 2036 | R1: 2037 | S1: 2038 | T1: 2039 | U1: 2040 | V1: 2041 | W1: 2042 | X1: 2043 | Y1: 2044 | Z1: 2045 | AA1: 2046 | AB1: 2047 | AC1: 2048 | AD1: 2049 | AE1: 2050
A2: Revenue | B2: 70.428 | C2: 94.588 | D2: 7.53 | E2: 18.474 | F2: 88.039 | G2: =SUM('Quarterly Model'!F2:I2) -> 143.98 | H2: =Pipeline!C56 -> 339.95744 | I2: =Pipeline!D56 -> 788.04665 | J2: =Pipeline!E56 -> 1362.2903 | K2: =Pipeline!F56 -> 2062.6163 | L2: =Pipeline!G56 -> 2794.1228 | M2: =Pipeline!H56 -> 3519.208 | N2: =Pipeline!I56 -> 3765.232 | O2: =Pipeline!J56 -> 3933.9 | ... AE2: =Pipeline!Z56 -> 1.7193079
A3: Cost of Sales | B3: 0 | C3: 0 | D3: 0 | E3: 0 | F3: 0 | G3: =SUM('Quarterly Model'!F3:I3) -> 3.84 | H3: =Pipeline!C57 -> 32.295957 | I3: =Pipeline!D57 -> 74.864432 | J3: =Pipeline!E57 -> 129.41758 | K3: =Pipeline!F57 -> 196.39855 | L3: =Pipeline!G57 -> 266.56667 | M3: =Pipeline!H57 -> 336.34976 | N3: =Pipeline!I57 -> 360.62204 | O3: =Pipeline!J57 -> 377.4105 | ... AE3: =Pipeline!Z57 -> 0.16380611
A4: Gross Margin | B4: =B2-B3 -> 70.428 | C4: =C2-C3 -> 94.588 | D4: =D2-D3 -> 7.53 | E4: =E2-E3 -> 18.474 | F4: =F2-F3 -> 88.039 | G4: =G2-G3 -> 140.14 | H4: =H2-H3 -> 307.66148 | I4: =I2-I3 -> 713.18222 | ... AE4: =AE2-AE3 -> 1.5555018
A5: Research & Dev. | B5: 159.938 | C5: 240.813 | D5: 330.123 | E5: 339.408 | F5: 416.026 | G5: =SUM('Quarterly Model'!F5:I5) -> 391.332 | H5: =Pipeline!C60 -> 380 | I5: =Pipeline!D60 -> 348.8 | J5: =Pipeline!E60 -> 324.834 | K5: =Pipeline!F60 -> 326.10902 | L5: =Pipeline!G60 -> 347.29474 | M5: =Pipeline!H60 -> 422.30496 | N5: =Pipeline!I60 -> 451.82784 | O5: =Pipeline!J60 -> 472.068 | ... AE5: =Pipeline!Z60 -> 0.20631694
A6: General & Admin | B6: 96.803 | C6: 177.977 | D6: 173.612 | E6: 215.314 | F6: 284.271 | G6: =SUM('Quarterly Model'!F6:I6) -> 444.437 | H6: =Pipeline!C63 -> 382.65659 | I6: =Pipeline!D63 -> 546.13866 | J6: =Pipeline!E63 -> 692.3289 | K6: =Pipeline!F63 -> 838.33947 | L6: =Pipeline!G63 -> 1014.5975 | M6: =Pipeline!H63 -> 1187.9237 | N6: =Pipeline!I63 -> 1228.5434 | O6: =Pipeline!J63 -> 1281.572 | ... AE6: =Pipeline!Z63 -> 0.644107
A7: Operating Expense | B7: =SUM(B5:B6) -> 256.741 | C7: =SUM(C5:C6) -> 418.79 | D7: =SUM(D5:D6) -> 503.735 | E7: =SUM(E5:E6) -> 554.722 | F7: =SUM(F5:F6) -> 700.297 | G7: =SUM(G5:G6) -> 835.769 | H7: =SUM(H5:H6) -> 762.65659 | I7: =SUM(I5:I6) -> 894.93866 | ... AE7: =SUM(AE5:AE6) -> 0.85042395
A8: Operating Income | B8: =B4-B7 -> -186.313 | C8: =C4-C7 -> -324.202 | D8: =D4-D7 -> -496.205 | E8: =E4-E7 -> -536.248 | F8: =F4-F7 -> -612.258 | G8: =G4-G7 -> -695.629 | H8: =H4-H7 -> -454.99511 | I8: =I4-I7 -> -181.75644 | ... AE8: =AE4-AE7 -> 0.70507781
A9: Interest & Other | B9: -29.001 | C9: -64.753 | D9: -30.039 | E9: -53.278 | F9: -172.697 | G9: =SUM('Quarterly Model'!F9:I9) -> -78.003 | H9: =Assumptions!$B$16*MAX(0,G20)-Assumptions!$B$17*Main!$C$8 -> 20.917112 | I9: =Assumptions!$B$16*MAX(0,H20)-Assumptions!$B$17*Main!$C$8 -> 4.6391876 | J9: =Assumptions!$B$16*MAX(0,I20)-Assumptions!$B$17*Main!$C$8 -> -2.0027094 | K9: =Assumptions!$B$16*MAX(0,J20)-Assumptions!$B$17*Main!$C$8 -> 6.0113074 | L9: =Assumptions!$B$16*MAX(0,K20)-Assumptions!$B$17*Main!$C$8 -> 32.553079 | M9: =Assumptions!$B$16*MAX(0,L20)-Assumptions!$B$17*Main!$C$8 -> 77.486216 | N9: =Assumptions!$B$16*MAX(0,M20)-Assumptions!$B$17*Main!$C$8 -> 139.36556 | O9: =Assumptions!$B$16*MAX(0,N20)-Assumptions!$B$17*Main!$C$8 -> 199.41801 | ... AE9: =Assumptions!$B$16*MAX(0,AD20)-Assumptions!$B$17*Main!$C$8 -> 846.76658
A10: Pretax | B10: =B8+B9 -> -215.314 | C10: =C8+C9 -> -388.955 | D10: =D8+D9 -> -526.244 | E10: =E8+E9 -> -589.526 | F10: =F8+F9 -> -784.955 | G10: =G8+G9 -> -773.632 | H10: =H8+H9 -> -434.078 | I10: =I8+I9 -> -177.11725 | ... AE10: =AE8+AE9 -> 847.47166
A11: Taxes | B11: 0 | C11: 0 | D11: 0 | E11: 0 | F11: 0 | G11: =SUM('Quarterly Model'!F11:I11) -> 0 | H11: =MAX(0,H10-G21)*Assumptions!$B$15 -> 0 | I11: =MAX(0,I10-H21)*Assumptions!$B$15 -> 0 | J11: =MAX(0,J10-I21)*Assumptions!$B$15 -> 0 | K11: =MAX(0,K10-J21)*Assumptions!$B$15 -> 0 | L11: =MAX(0,L10-K21)*Assumptions!$B$15 -> 0 | M11: =MAX(0,M10-L21)*Assumptions!$B$15 -> 0 | N11: =MAX(0,N10-M21)*Assumptions!$B$15 -> 262.20549 | O11: =MAX(0,O10-N21)*Assumptions!$B$15 -> 420.47618 | ... AE11: =MAX(0,AE10-AD21)*Assumptions!$B$15 -> 177.96905
A12: Net Income | B12: -215.314 | C12: -388.955 | D12: -526.244 | E12: -589.526 | F12: -784.955 | G12: =G10-G11 -> -773.632 | H12: =H10-H11 -> -434.078 | I12: =I10-I11 -> -177.11725 | J12: =J10-J11 -> 213.70712 | K12: =K10-K11 -> 707.78058 | L12: =L10-L11 -> 1198.217 | M12: =M10-M11 -> 1650.1158 | N12: =N10-N11 -> 1601.3988 | ... AE12: =AE10-AE11 -> 669.50261
A13: Earnings per Share | B13: =IFERROR(B12/B14,0) -> -2.8004318 | C13: =IFERROR(C12/C14,0) -> -4.3301419 | D13: =IFERROR(D12/D14,0) -> -5.4519498 | E13: =IFERROR(E12/E14,0) -> -5.2646121 | F13: =IFERROR(F12/F14,0) -> -6.5356819 | G13: =IFERROR(G12/G14,0) -> -5.7976128 | H13: =IFERROR(H12/H14,0) -> -3.1223373 | I13: =IFERROR(I12/I14,0) -> -1.2740102 | ... AE13: =IFERROR(AE12/AE14,0) -> 4.8157542
A14: Shares | B14: 76.886 | C14: 89.825 | D14: 96.524 | E14: 111.979 | F14: 120.103 | G14: =AVERAGE('Quarterly Model'!F14:I14) -> 133.43975 | H14: =Main!$C$4*(1+Assumptions!$B$26)^(H1-2026) -> 139.02342 | I14: =Main!$C$4*(1+Assumptions!$B$26)^(I1-2026) -> 139.02342 | J14: =Main!$C$4*(1+Assumptions!$B$26)^(J1-2026) -> 139.02342 | K14: =Main!$C$4*(1+Assumptions!$B$26)^(K1-2026) -> 139.02342 | L14: =Main!$C$4*(1+Assumptions!$B$26)^(L1-2026) -> 139.02342 | M14: =Main!$C$4*(1+Assumptions!$B$26)^(M1-2026) -> 139.02342 | N14: =Main!$C$4*(1+Assumptions!$B$26)^(N1-2026) -> 139.02342 | O14: =Main!$C$4*(1+Assumptions!$B$26)^(O1-2026) -> 139.02342 | ... AE14: =Main!$C$4*(1+Assumptions!$B$26)^(AE1-2026) -> 139.02342
A16: Revenue Change | C16: =IFERROR(C2/B2-1,"") -> 0.34304538 | D16: =IFERROR(D2/C2-1,"") -> -0.92039159 | E16: =IFERROR(E2/D2-1,"") -> 1.4533865 | F16: =IFERROR(F2/E2-1,"") -> 3.7655624 | G16: =IFERROR(G2/F2-1,"") -> 0.63541158 | H16: =IFERROR(H2/G2-1,"") -> 1.3611435 | I16: =IFERROR(I2/H2-1,"") -> 1.3180745 | J16: =IFERROR(J2/I2-1,"") -> 0.72869246 | ... AE16: =IFERROR(AE2/AD2-1,"") -> -0.6
A17: Gross Margin | B17: =IFERROR(B4/B2,"") -> 1 | C17: =IFERROR(C4/C2,"") -> 1 | D17: =IFERROR(D4/D2,"") -> 1 | E17: =IFERROR(E4/E2,"") -> 1 | F17: =IFERROR(F4/F2,"") -> 1 | G17: =IFERROR(G4/G2,"") -> 0.97332963 | H17: =IFERROR(H4/H2,"") -> 0.905 | I17: =IFERROR(I4/I2,"") -> 0.905 | ... AE17: =IFERROR(AE4/AE2,"") -> 0.90472555
A19: Actual / Estimate | B19: A | C19: A | D19: A | E19: A | F19: A | G19: A+E | H19: E | I19: E | J19: E | K19: E | L19: E | M19: E | N19: E | O19: E | P19: E | Q19: E | R19: E | S19: E | T19: E | U19: E | V19: E | W19: E | X19: E | Y19: E | Z19: E | AA19: E | AB19: E | AC19: E | AD19: E | AE19: E
A20: Cash & Investments | G20: ='Quarterly Model'!I20 -> 1335.163 | H20: =G20+H12 -> 901.085 | I20: =H20+I12 -> 723.96775 | J20: =I20+J12 -> 937.67486 | K20: =J20+K12 -> 1645.4554 | L20: =K20+L12 -> 2843.6724 | M20: =L20+M12 -> 4493.7882 | N20: =M20+N12 -> 6095.1871 | O20: =N20+O12 -> 7676.9784 | ... AE20: =AD20+AE12 -> 24027.318
A21: Tax-Loss Pool | F21: =Assumptions!$B$18 -> 3000 | G21: =F21-MIN(F21,MAX(0,G10))+MAX(0,-G10) -> 3773.632 | H21: =G21-MIN(G21,MAX(0,H10))+MAX(0,-H10) -> 4207.71 | I21: =H21-MIN(H21,MAX(0,I10))+MAX(0,-I10) -> 4384.8273 | J21: =I21-MIN(I21,MAX(0,J10))+MAX(0,-J10) -> 4171.1201 | K21: =J21-MIN(J21,MAX(0,K10))+MAX(0,-K10) -> 3463.3396 | L21: =K21-MIN(K21,MAX(0,L10))+MAX(0,-L10) -> 2265.1226 | M21: =L21-MIN(L21,MAX(0,M10))+MAX(0,-M10) -> 615.00677 | N21: =M21-MIN(M21,MAX(0,N10))+MAX(0,-N10) -> 0 | ... AE21: =AD21-MIN(AD21,MAX(0,AE10))+MAX(0,-AE10) -> 0

Sheet Quarterly Model
B1: Q1 2025 | C1: Q2 2025 | D1: Q3 2025 | E1: Q4 2025 | F1: Q1 2026 | G1: Q2 2026 | H1: Q3 2026 | I1: Q4 2026
A2: Revenue | B2: =SUM(B24:B25) -> 1.58 | C2: =SUM(C24:C25) -> 66.77 | D2: =SUM(D24:D25) -> 1.94 | E2: =SUM(E24:E25) -> 17.75 | F2: =SUM(F24:F25) -> 19.36 | G2: =SUM(G24:G25) -> 28.62 | H2: =SUM(H24:H25) -> 41 | I2: =SUM(I24:I25) -> 55
A3: Cost of Sales | B3: 0 | C3: 0 | D3: 0 | E3: 0 | F3: 0 | G3: 0 | H3: =H2*0.04 -> 1.64 | I3: =I2*0.04 -> 2.2
A4: Gross Margin | B4: =B2-B3 -> 1.58 | C4: =C2-C3 -> 66.77 | D4: =D2-D3 -> 1.94 | E4: =E2-E3 -> 17.75 | F4: =F2-F3 -> 19.36 | G4: =G2-G3 -> 28.62 | H4: =H2-H3 -> 39.36 | I4: =I2-I3 -> 52.8
A5: Research & Dev. | B5: 98.262 | C5: 110.138 | D5: 99.233 | E5: 104.398 | F5: 95.525 | G5: 97.807 | H5: 98 | I5: 100
A6: General & Admin | B6: 58.948 | C6: 68.137 | D6: 69.458 | E6: 91.723 | F6: 107.448 | G6: 109.989 | H6: 112 | I6: 115
A7: Operating Expense | B7: =SUM(B5:B6) -> 157.21 | C7: =SUM(C5:C6) -> 178.275 | D7: =SUM(D5:D6) -> 168.691 | E7: =SUM(E5:E6) -> 196.121 | F7: =SUM(F5:F6) -> 202.973 | G7: =SUM(G5:G6) -> 207.796 | H7: =SUM(H5:H6) -> 210 | I7: =SUM(I5:I6) -> 215
A8: Operating Income | B8: =B4-B7 -> -155.63 | C8: =C4-C7 -> -111.505 | D8: =D4-D7 -> -166.751 | E8: =E4-E7 -> -178.371 | F8: =F4-F7 -> -183.613 | G8: =G4-G7 -> -179.176 | H8: =H4-H7 -> -170.64 | I8: =I4-I7 -> -162.2
A9: Interest & Other | B9: -5.745 | C9: -22.864 | D9: -139.423 | E9: -4.665 | F9: -22.413 | G9: -19.59 | H9: -18 | I9: -18
A10: Pretax | B10: =B8+B9 -> -161.375 | C10: =C8+C9 -> -134.369 | D10: =D8+D9 -> -306.174 | E10: =E8+E9 -> -183.036 | F10: =F8+F9 -> -206.026 | G10: =G8+G9 -> -198.766 | H10: =H8+H9 -> -188.64 | I10: =I8+I9 -> -180.2
A11: Taxes | B11: 0 | C11: 0 | D11: 0 | E11: 0 | F11: 0 | G11: 0 | H11: 0 | I11: 0
A12: Net Income | B12: =B10-B11 -> -161.375 | C12: =C10-C11 -> -134.369 | D12: =D10-D11 -> -306.174 | E12: =E10-E11 -> -183.036 | F12: =F10-F11 -> -206.026 | G12: =G10-G11 -> -198.766 | H12: =H10-H11 -> -188.64 | I12: =I10-I11 -> -180.2
A13: Earnings per Share | B13: =IFERROR(B12/B14,0) -> -1.3618603 | C13: =IFERROR(C12/C14,0) -> -1.1248315 | D13: =IFERROR(D12/D14,0) -> -2.5518328 | E13: =IFERROR(E12/E14,0) -> -1.494452 | F13: =IFERROR(F12/F14,0) -> -1.6712987 | G13: =IFERROR(G12/G14,0) -> -1.5048226 | H13: =IFERROR(H12/H14,0) -> -1.3561467 | I13: =IFERROR(I12/I14,0) -> -1.2936109
A14: Shares | B14: 118.496 | C14: 119.457 | D14: 119.982 | E14: 122.477 | F14: 123.273 | G14: 132.086 | H14: 139.1 | I14: 139.3
A16: Revenue Change (YoY) | F16: =IFERROR(F2/B2-1,"") -> 11.253165 | G16: =IFERROR(G2/C2-1,"") -> -0.57136439 | H16: =IFERROR(H2/D2-1,"") -> 20.134021 | I16: =IFERROR(I2/E2-1,"") -> 2.0985915
A17: Gross Margin | B17: =IFERROR(B4/B2,"") -> 1 | C17: =IFERROR(C4/C2,"") -> 1 | D17: =IFERROR(D4/D2,"") -> 1 | E17: =IFERROR(E4/E2,"") -> 1 | F17: =IFERROR(F4/F2,"") -> 1 | G17: =IFERROR(G4/G2,"") -> 1 | H17: =IFERROR(H4/H2,"") -> 0.96 | I17: =IFERROR(I4/I2,"") -> 0.96
A19: Actual / Estimate | B19: A | C19: A | D19: A | E19: A | F19: A | G19: A | H19: E | I19: E
A20: Cash & Investments | G20: 1704.003 | H20: =G20+H12+H21 -> 1515.363 | I20: =H20+I12+I21 -> 1335.163
A21: Other Cash Flows (est.) | H21: 0 | I21: 0
A23: Revenue by Product
A24: MYQORZO | B24: 0 | C24: 0 | D24: 0 | E24: 0 | F24: 4.789 | G24: 25.334 | H24: 38 | I24: 52
A25: Collaboration & other | B25: 1.58 | C25: 66.77 | D25: 1.94 | E25: 17.75 | F25: 14.571 | G25: 3.286 | H25: 3 | I25: 3

Sheet Assumptions
A1: CYTK — rNPV assumptions ($mm unless noted)
A4: Scenario (1 = Bear, 2 = Base, 3 = Bull) | B4: 2 | C4: =CHOOSE($B$4,"Bear","Base","Bull") -> Base
A5: Overrides (blank = scenario value; the sensitivity tables drive these)
A6: Discount rate override
A7: PDUFA approval probability override
A8: PDUFA program peak sales override ($mm)
A10: Parameter | B10: Active | C10: Bear | D10: Base | E10: Bull
A12: Valuation & corporate
A13: Valuation date | B13: =DATE(2026,10,16) -> 46311
A14: Discount rate (cost of equity) | B14: =IF(ISNUMBER($B$6),$B$6,CHOOSE($B$4,C14,D14,E14)) -> 0.1 | C14: 0.115 | D14: 0.1 | E14: 0.09
A15: Tax rate | B15: =CHOOSE($B$4,C15,D15,E15) -> 0.21 | C15: 0.21 | D15: 0.21 | E15: 0.21
A16: Interest yield on cash | B16: =CHOOSE($B$4,C16,D16,E16) -> 0.0375 | C16: 0.0375 | D16: 0.0375 | E16: 0.0375
A17: Average cash cost of debt (P&L display only) | B17: =CHOOSE($B$4,C17,D17,E17) -> 0.025 | C17: 0.025 | D17: 0.025 | E17: 0.025
A18: Tax-loss pool at 12/31/2025 | B18: =CHOOSE($B$4,C18,D18,E18) -> 3000 | C18: 3000 | D18: 3000 | E18: 3000
A19: Corporate G&A, 2027 | B19: =CHOOSE($B$4,C19,D19,E19) -> 150 | C19: 150 | D19: 150 | E19: 150
A20: Platform / unallocated R&D, 2027 | B20: =CHOOSE($B$4,C20,D20,E20) -> 260 | C20: 260 | D20: 260 | E20: 260
A21: Cost inflation | B21: =CHOOSE($B$4,C21,D21,E21) -> 0.03 | C21: 0.03 | D21: 0.03 | E21: 0.03
A22: Corporate G&A floor, % of revenue | B22: =CHOOSE($B$4,C22,D22,E22) -> 0.08 | C22: 0.08 | D22: 0.08 | E22: 0.08
A23: Platform R&D floor, % of revenue | B23: =CHOOSE($B$4,C23,D23,E23) -> 0.12 | C23: 0.12 | D23: 0.12 | E23: 0.12
A24: Corporate cost cut after a CRL (2027+) | B24: =CHOOSE($B$4,C24,D24,E24) -> 0 | C24: 0 | D24: 0 | E24: 0
A25: Last year of base-level corporate costs (then % of revenue only) | B25: =CHOOSE($B$4,C25,D25,E25) -> 2040 | C25: 2040 | D25: 2040 | E25: 2040
A26: Annual share count growth (EPS display only) | B26: =CHOOSE($B$4,C26,D26,E26) -> 0 | C26: 0 | D26: 0 | E26: 0
A27: Wind-down cost for liquidation value | B27: =CHOOSE($B$4,C27,D27,E27) -> 100 | C27: 100 | D27: 100 | E27: 100
A29: PDUFA event
A30: PDUFA target action date | B30: =DATE(2026,11,14) -> 46340
A31: Application | B31: MYQORZO sNDA, MAPLE-HCM (superiority vs. metoprolol)
A32: Probability of approval at this PDUFA | B32: =IF(ISNUMBER($B$7),$B$7,CHOOSE($B$4,C32,D32,E32)) -> 0.92 | C32: 0.85 | D32: 0.92 | E32: 0.96
A33: Probability of approval later, after a CRL | B33: =CHOOSE($B$4,C33,D33,E33) -> 0.7 | C33: 0.65 | D33: 0.7 | E33: 0.8
A34: Launch delay after a CRL (years) | B34: =CHOOSE($B$4,C34,D34,E34) -> 1 | C34: 1 | D34: 1 | E34: 1
A35: Probability of approval, scenario value (before override) | B35: =CHOOSE($B$4,C32,D32,E32) -> 0.92
A36: Read-through: relative cut to other programs' PoS after a CRL | B36: =CHOOSE($B$4,C36,D36,E36) -> 0 | C36: 0 | D36: 0 | E36: 0
A37: Read-through multiplier on other programs' PoS (1 = none) | B37: =1+$B$36*($B$32-$B$35)/$B$35 -> 1
A38: Expected corporate cost multiplier (2027+) | B38: =$B$32+(1-$B$32)*(1-$B$24) -> 1
A40: Commercial curves (by year since launch)
A41: Year since launch | B41: 1 | C41: 2 | D41: 3 | E41: 4 | F41: 5 | G41: 6 | H41: 7
A42: Ramp 1 — standard launch, % of peak | B42: 0.1 | C42: 0.25 | D42: 0.45 | E42: 0.65 | F42: 0.82 | G42: 0.93 | H42: 1
A43: Ramp 2 — orphan-disease launch, % of peak | B43: 0.15 | C43: 0.35 | D43: 0.55 | E43: 0.75 | F43: 0.9 | G43: 1 | H43: 1
A44: Commercial SG&A, % of sales (years 1–5; floor = program maturity %) | B44: 0.9 | C44: 0.55 | D44: 0.4 | E44: 0.32 | F44: 0.28
A46: MYQORZO (aficamten) — obstructive HCM (marketed)
A47: Launch year (first commercial year) | B47: 2026
...

Sheet Pipeline
A1: CYTK — risk-adjusted program build ($mm)
A2: Year | C2: 2027 | D2: 2028 | E2: 2029 | F2: 2030 | G2: 2031 | H2: 2032 | I2: 2033 | J2: 2034 | K2: 2035 | L2: 2036 | M2: 2037 | N2: 2038 | O2: 2039 | P2: 2040 | Q2: 2041 | R2: 2042 | S2: 2043 | T2: 2044 | U2: 2045 | V2: 2046 | W2: 2047 | X2: 2048 | Y2: 2049 | Z2: 2050
A4: MYQORZO (aficamten) — obstructive HCM
A5: Years since launch | C5: =C$2-Assumptions!$B$47+1 -> 2 | D5: =D$2-Assumptions!$B$47+1 -> 3 | E5: =E$2-Assumptions!$B$47+1 -> 4 | F5: =F$2-Assumptions!$B$47+1 -> 5 | G5: =G$2-Assumptions!$B$47+1 -> 6 | H5: =H$2-Assumptions!$B$47+1 -> 7 | I5: =I$2-Assumptions!$B$47+1 -> 8 | J5: =J$2-Assumptions!$B$47+1 -> 9 | ... Z5: =Z$2-Assumptions!$B$47+1 -> 25
A6: Net sales | C6: =IF(C$2>Assumptions!$B$55,Assumptions!$B$57*(1-Assumptions!$B$56),IF(C$2<Assumptions!$B$49,Assumptions!$B$57+(Assumptions!$B$48-Assumptions!$B$57)*((C$2-2026)/(Assumptions!$B$49-2026))^Assumptions!$B$50,Assumptions!$B$48)) -> 303.15744 | D6: =IF(D$2>Assumptions!$B$55,C6*(1-Assumptions!$B$56),IF(D$2<Assumptions!$B$49,Assumptions!$B$57+(Assumptions!$B$48-Assumptions!$B$57)*((D$2-2026)/(Assumptions!$B$49-2026))^Assumptions!$B$50,Assumptions!$B$48)) -> 570.80665 | E6: =IF(E$2>Assumptions!$B$55,D6*(1-Assumptions!$B$56),IF(E$2<Assumptions!$B$49,Assumptions!$B$57+(Assumptions!$B$48-Assumptions!$B$57)*((E$2-2026)/(Assumptions!$B$49-2026))^Assumptions!$B$50,Assumptions!$B$48)) -> 883.5903 | F6: =IF(F$2>Assumptions!$B$55,E6*(1-Assumptions!$B$56),IF(F$2<Assumptions!$B$49,Assumptions!$B$57+(Assumptions!$B$48-Assumptions!$B$57)*((F$2-2026)/(Assumptions!$B$49-2026))^Assumptions!$B$50,Assumptions!$B$48)) -> 1229.8363 | G6: =IF(G$2>Assumptions!$B$55,F6*(1-Assumptions!$B$56),IF(G$2<Assumptions!$B$49,Assumptions!$B$57+(Assumptions!$B$48-Assumptions!$B$57)*((G$2-2026)/(Assumptions!$B$49-2026))^Assumptions!$B$50,Assumptions!$B$48)) -> 1603.3028 | H6: =IF(H$2>Assumptions!$B$55,G6*(1-Assumptions!$B$56),IF(H$2<Assumptions!$B$49,Assumptions!$B$57+(Assumptions!$B$48-Assumptions!$B$57)*((H$2-2026)/(Assumptions!$B$49-2026))^Assumptions!$B$50,Assumptions!$B$48)) -> 2000 | I6: =IF(I$2>Assumptions!$B$55,H6*(1-Assumptions!$B$56),IF(I$2<Assumptions!$B$49,Assumptions!$B$57+(Assumptions!$B$48-Assumptions!$B$57)*((I$2-2026)/(Assumptions!$B$49-2026))^Assumptions!$B$50,Assumptions!$B$48)) -> 2000 | J6: =IF(J$2>Assumptions!$B$55,I6*(1-Assumptions!$B$56),IF(J$2<Assumptions!$B$49,Assumptions!$B$57+(Assumptions!$B$48-Assumptions!$B$57)*((J$2-2026)/(Assumptions!$B$49-2026))^Assumptions!$B$50,Assumptions!$B$48)) -> 2000 | K6: =IF(K$2>Assumptions!$B$55,J6*(1-Assumptions!$B$56),IF(K$2<Assumptions!$B$49,Assumptions!$B$57+(Assumptions!$B$48-Assumptions!$B$57)*((K$2-2026)/(Assumptions!$B$49-2026))^Assumptions!$B$50,Assumptions!$B$48)) -> 2000 | ... Z6: =IF(Z$2>Assumptions!$B$55,Y6*(1-Assumptions!$B$56),IF(Z$2<Assumptions!$B$49,Assumptions!$B$57+(Assumptions!$B$48-Assumptions!$B$57)*((Z$2-2026)/(Assumptions!$B$49-2026))^Assumptions!$B$50,Assumptions!$B$48)) -> 0.08388608
A7: Company revenue | C7: =C6*Assumptions!$B$51 -> 303.15744 | D7: =D6*Assumptions!$B$51 -> 570.80665 | E7: =E6*Assumptions!$B$51 -> 883.5903 | F7: =F6*Assumptions!$B$51 -> 1229.8363 | G7: =G6*Assumptions!$B$51 -> 1603.3028 | H7: =H6*Assumptions!$B$51 -> 2000 | I7: =I6*Assumptions!$B$51 -> 2000 | J7: =J6*Assumptions!$B$51 -> 2000 | ... Z7: =Z6*Assumptions!$B$51 -> 0.08388608
A8: COGS + royalties | C8: =C6*(Assumptions!$B$52+Assumptions!$B$53) -> 28.799957 | D8: =D6*(Assumptions!$B$52+Assumptions!$B$53) -> 54.226632 | E8: =E6*(Assumptions!$B$52+Assumptions!$B$53) -> 83.941078 | F8: =F6*(Assumptions!$B$52+Assumptions!$B$53) -> 116.83445 | G8: =G6*(Assumptions!$B$52+Assumptions!$B$53) -> 152.31377 | H8: =H6*(Assumptions!$B$52+Assumptions!$B$53) -> 190 | I8: =I6*(Assumptions!$B$52+Assumptions!$B$53) -> 190 | J8: =J6*(Assumptions!$B$52+Assumptions!$B$53) -> 190 | ... Z8: =Z6*(Assumptions!$B$52+Assumptions!$B$53) -> 0.0079691776
A9: Commercial SG&A | C9: =IF(Assumptions!$B$54=0,0,IF(FALSE,0,IF(C5>=1,C6*IF(OR(Assumptions!$B$51<1,C5>5),Assumptions!$B$54,MAX(Assumptions!$B$54,INDEX(Assumptions!$B$44:$F$44,C5))),0))) -> 166.73659 | D9: =IF(Assumptions!$B$54=0,0,IF(FALSE,0,IF(D5>=1,D6*IF(OR(Assumptions!$B$51<1,D5>5),Assumptions!$B$54,MAX(Assumptions!$B$54,INDEX(Assumptions!$B$44:$F$44,D5))),0))) -> 228.32266 | E9: =IF(Assumptions!$B$54=0,0,IF(FALSE,0,IF(E5>=1,E6*IF(OR(Assumptions!$B$51<1,E5>5),Assumptions!$B$54,MAX(Assumptions!$B$54,INDEX(Assumptions!$B$44:$F$44,E5))),0))) -> 282.7489 | F9: =IF(Assumptions!$B$54=0,0,IF(FALSE,0,IF(F5>=1,F6*IF(OR(Assumptions!$B$51<1,F5>5),Assumptions!$B$54,MAX(Assumptions!$B$54,INDEX(Assumptions!$B$44:$F$44,F5))),0))) -> 344.35417 | G9: =IF(Assumptions!$B$54=0,0,IF(FALSE,0,IF(G5>=1,G6*IF(OR(Assumptions!$B$51<1,G5>5),Assumptions!$B$54,MAX(Assumptions!$B$54,INDEX(Assumptions!$B$44:$F$44,G5))),0))) -> 400.82571 | H9: =IF(Assumptions!$B$54=0,0,IF(FALSE,0,IF(H5>=1,H6*IF(OR(Assumptions!$B$51<1,H5>5),Assumptions!$B$54,MAX(Assumptions!$B$54,INDEX(Assumptions!$B$44:$F$44,H5))),0))) -> 500 | I9: =IF(Assumptions!$B$54=0,0,IF(FALSE,0,IF(I5>=1,I6*IF(OR(Assumptions!$B$51<1,I5>5),Assumptions!$B$54,MAX(Assumptions!$B$54,INDEX(Assumptions!$B$44:$F$44,I5))),0))) -> 500 | J9: =IF(Assumptions!$B$54=0,0,IF(FALSE,0,IF(J5>=1,J6*IF(OR(Assumptions!$B$51<1,J5>5),Assumptions!$B$54,MAX(Assumptions!$B$54,INDEX(Assumptions!$B$44:$F$44,J5))),0))) -> 500 | ... Z9: =IF(Assumptions!$B$54=0,0,IF(FALSE,0,IF(Z5>=1,Z6*IF(OR(Assumptions!$B$51<1,Z5>5),Assumptions!$B$54,MAX(Assumptions!$B$54,INDEX(Assumptions!$B$44:$F$44,Z5))),0))) -> 0.02097152
A10: Development R&D | C10: =0 -> 0 | D10: =0 -> 0 | E10: =0 -> 0 | F10: =0 -> 0 | G10: =0 -> 0 | H10: =0 -> 0 | I10: =0 -> 0 | J10: =0 -> 0 | ... Z10: =0 -> 0
A11: Program contribution (pre-tax) | C11: =C7-C8-C9-C10 -> 107.62089 | D11: =D7-D8-D9-D10 -> 288.25736 | E11: =E7-E8-E9-E10 -> 516.90032 | F11: =F7-F8-F9-F10 -> 768.6477 | G11: =G7-G8-G9-G10 -> 1050.1634 | H11: =H7-H8-H9-H10 -> 1310 | I11: =I7-I8-I9-I10 -> 1310 | J11: =J7-J8-J9-J10 -> 1310 | ... Z11: =Z7-Z8-Z9-Z10 -> 0.054945382
A13: MAPLE-HCM label — first-line use (incremental)
A14: Years since launch (approved on time) | C14: =C$2-Assumptions!$B$60+1 -> 1 | D14: =D$2-Assumptions!$B$60+1 -> 2 | E14: =E$2-Assumptions!$B$60+1 -> 3 | F14: =F$2-Assumptions!$B$60+1 -> 4 | G14: =G$2-Assumptions!$B$60+1 -> 5 | H14: =H$2-Assumptions!$B$60+1 -> 6 | I14: =I$2-Assumptions!$B$60+1 -> 7 | J14: =J$2-Assumptions!$B$60+1 -> 8 | ... Z14: =Z$2-Assumptions!$B$60+1 -> 24
A15: Net sales, unrisked (approved on time) | C15: =IF(C$2>Assumptions!$B$69,0*(1-Assumptions!$B$70),IF(C14>=1,Assumptions!$B$61*CHOOSE(Assumptions!$B$68,INDEX(Assumptions!$B$42:$H$42,MIN(C14,7)),INDEX(Assumptions!$B$43:$H$43,MIN(C14,7))),0)) -> 40 | D15: =IF(D$2>Assumptions!$B$69,C15*(1-Assumptions!$B$70),IF(D14>=1,Assumptions!$B$61*CHOOSE(Assumptions!$B$68,INDEX(Assumptions!$B$42:$H$42,MIN(D14,7)),INDEX(Assumptions!$B$43:$H$43,MIN(D14,7))),0)) -> 100 | E15: =IF(E$2>Assumptions!$B$69,D15*(1-Assumptions!$B$70),IF(E14>=1,Assumptions!$B$61*CHOOSE(Assumptions!$B$68,INDEX(Assumptions!$B$42:$H$42,MIN(E14,7)),INDEX(Assumptions!$B$43:$H$43,MIN(E14,7))),0)) -> 180 | F15: =IF(F$2>Assumptions!$B$69,E15*(1-Assumptions!$B$70),IF(F14>=1,Assumptions!$B$61*CHOOSE(Assumptions!$B$68,INDEX(Assumptions!$B$42:$H$42,MIN(F14,7)),INDEX(Assumptions!$B$43:$H$43,MIN(F14,7))),0)) -> 260 | G15: =IF(G$2>Assumptions!$B$69,F15*(1-Assumptions!$B$70),IF(G14>=1,Assumptions!$B$61*CHOOSE(Assumptions!$B$68,INDEX(Assumptions!$B$42:$H$42,MIN(G14,7)),INDEX(Assumptions!$B$43:$H$43,MIN(G14,7))),0)) -> 328 | H15: =IF(H$2>Assumptions!$B$69,G15*(1-Assumptions!$B$70),IF(H14>=1,Assumptions!$B$61*CHOOSE(Assumptions!$B$68,INDEX(Assumptions!$B$42:$H$42,MIN(H14,7)),INDEX(Assumptions!$B$43:$H$43,MIN(H14,7))),0)) -> 372 | I15: =IF(I$2>Assumptions!$B$69,H15*(1-Assumptions!$B$70),IF(I14>=1,Assumptions!$B$61*CHOOSE(Assumptions!$B$68,INDEX(Assumptions!$B$42:$H$42,MIN(I14,7)),INDEX(Assumptions!$B$43:$H$43,MIN(I14,7))),0)) -> 400 | J15: =IF(J$2>Assumptions!$B$69,I15*(1-Assumptions!$B$70),IF(J14>=1,Assumptions!$B$61*CHOOSE(Assumptions!$B$68,INDEX(Assumptions!$B$42:$H$42,MIN(J14,7)),INDEX(Assumptions!$B$43:$H$43,MIN(J14,7))),0)) -> 400 | K15: =IF(K$2>Assumptions!$B$69,J15*(1-Assumptions!$B$70),IF(K14>=1,Assumptions!$B$61*CHOOSE(Assumptions!$B$68,INDEX(Assumptions!$B$42:$H$42,MIN(K14,7)),INDEX(Assumptions!$B$43:$H$43,MIN(K14,7))),0)) -> 400 | ... Z15: =IF(Z$2>Assumptions!$B$69,Y15*(1-Assumptions!$B$70),IF(Z14>=1,Assumptions!$B$61*CHOOSE(Assumptions!$B$68,INDEX(Assumptions!$B$42:$H$42,MIN(Z14,7)),INDEX(Assumptions!$B$43:$H$43,MIN(Z14,7))),0)) -> 0.016777216
A16: Years since launch (approved after a CRL) | C16: =C$2-(Assumptions!$B$60+Assumptions!$B$34)+1 -> 0 | D16: =D$2-(Assumptions!$B$60+Assumptions!$B$34)+1 -> 1 | E16: =E$2-(Assumptions!$B$60+Assumptions!$B$34)+1 -> 2 | F16: =F$2-(Assumptions!$B$60+Assumptions!$B$34)+1 -> 3 | G16: =G$2-(Assumptions!$B$60+Assumptions!$B$34)+1 -> 4 | H16: =H$2-(Assumptions!$B$60+Assumptions!$B$34)+1 -> 5 | I16: =I$2-(Assumptions!$B$60+Assumptions!$B$34)+1 -> 6 | J16: =J$2-(Assumptions!$B$60+Assumptions!$B$34)+1 -> 7 | ... Z16: =Z$2-(Assumptions!$B$60+Assumptions!$B$34)+1 -> 23
A17: Net sales, unrisked (approved after a CRL) | C17: =IF(C$2>Assumptions!$B$69,0*(1-Assumptions!$B$70),IF(C16>=1,Assumptions!$B$61*CHOOSE(Assumptions!$B$68,INDEX(Assumptions!$B$42:$H$42,MIN(C16,7)),INDEX(Assumptions!$B$43:$H$43,MIN(C16,7))),0)) -> 0 | D17: =IF(D$2>Assumptions!$B$69,C17*(1-Assumptions!$B$70),IF(D16>=1,Assumptions!$B$61*CHOOSE(Assumptions!$B$68,INDEX(Assumptions!$B$42:$H$42,MIN(D16,7)),INDEX(Assumptions!$B$43:$H$43,MIN(D16,7))),0)) -> 40 | E17: =IF(E$2>Assumptions!$B$69,D17*(1-Assumptions!$B$70),IF(E16>=1,Assumptions!$B$61*CHOOSE(Assumptions!$B$68,INDEX(Assumptions!$B$42:$H$42,MIN(E16,7)),INDEX(Assumptions!$B$43:$H$43,MIN(E16,7))),0)) -> 100 | F17: =IF(F$2>Assumptions!$B$69,E17*(1-Assumptions!$B$70),IF(F16>=1,Assumptions!$B$61*CHOOSE(Assumptions!$B$68,INDEX(Assumptions!$B$42:$H$42,MIN(F16,7)),INDEX(Assumptions!$B$43:$H$43,MIN(F16,7))),0)) -> 180 | G17: =IF(G$2>Assumptions!$B$69,F17*(1-Assumptions!$B$70),IF(G16>=1,Assumptions!$B$61*CHOOSE(Assumptions!$B$68,INDEX(Assumptions!$B$42:$H$42,MIN(G16,7)),INDEX(Assumptions!$B$43:$H$43,MIN(G16,7))),0)) -> 260 | H17: =IF(H$2>Assumptions!$B$69,G17*(1-Assumptions!$B$70),IF(H16>=1,Assumptions!$B$61*CHOOSE(Assumptions!$B$68,INDEX(Assumptions!$B$42:$H$42,MIN(H16,7)),INDEX(Assumptions!$B$43:$H$43,MIN(H16,7))),0)) -> 328 | I17: =IF(I$2>Assumptions!$B$69,H17*(1-Assumptions!$B$70),IF(I16>=1,Assumptions!$B$61*CHOOSE(Assumptions!$B$68,INDEX(Assumptions!$B$42:$H$42,MIN(I16,7)),INDEX(Assumptions!$B$43:$H$43,MIN(I16,7))),0)) -> 372 | J17: =IF(J$2>Assumptions!$B$69,I17*(1-Assumptions!$B$70),IF(J16>=1,Assumptions!$B$61*CHOOSE(Assumptions!$B$68,INDEX(Assumptions!$B$42:$H$42,MIN(J16,7)),INDEX(Assumptions!$B$43:$H$43,MIN(J16,7))),0)) -> 400 | K17: =IF(K$2>Assumptions!$B$69,J17*(1-Assumptions!$B$70),IF(K16>=1,Assumptions!$B$61*CHOOSE(Assumptions!$B$68,INDEX(Assumptions!$B$42:$H$42,MIN(K16,7)),INDEX(Assumptions!$B$43:$H$43,MIN(K16,7))),0)) -> 400 | ... Z17: =IF(Z$2>Assumptions!$B$69,Y17*(1-Assumptions!$B$70),IF(Z16>=1,Assumptions!$B$61*CHOOSE(Assumptions!$B$68,INDEX(Assumptions!$B$42:$H$42,MIN(Z16,7)),INDEX(Assumptions!$B$43:$H$43,MIN(Z16,7))),0)) -> 0.016777216
A18: Product net sales, risk-adjusted | C18: =Assumptions!$B$32*C15+(1-Assumptions!$B$32)*Assumptions!$B$33*C17 -> 36.8 | D18: =Assumptions!$B$32*D15+(1-Assumptions!$B$32)*Assumptions!$B$33*D17 -> 94.24 | E18: =Assumptions!$B$32*E15+(1-Assumptions!$B$32)*Assumptions!$B$33*E17 -> 171.2 | F18: =Assumptions!$B$32*F15+(1-Assumptions!$B$32)*Assumptions!$B$33*F17 -> 249.28 | G18: =Assumptions!$B$32*G15+(1-Assumptions!$B$32)*Assumptions!$B$33*G17 -> 316.32 | H18: =Assumptions!$B$32*H15+(1-Assumptions!$B$32)*Assumptions!$B$33*H17 -> 360.608 | I18: =Assumptions!$B$32*I15+(1-Assumptions!$B$32)*Assumptions!$B$33*I17 -> 388.832 | J18: =Assumptions!$B$32*J15+(1-Assumptions!$B$32)*Assumptions!$B$33*J17 -> 390.4 | ... Z18: =Assumptions!$B$32*Z15+(1-Assumptions!$B$32)*Assumptions!$B$33*Z17 -> 0.016374563
A19: Company revenue, risk-adjusted (incl. milestones) | C19: =C18*Assumptions!$B$63 -> 36.8 | D19: =D18*Assumptions!$B$63 -> 94.24 | E19: =E18*Assumptions!$B$63 -> 171.2 | F19: =F18*Assumptions!$B$63 -> 249.28 | G19: =G18*Assumptions!$B$63 -> 316.32 | H19: =H18*Assumptions!$B$63 -> 360.608 | I19: =I18*Assumptions!$B$63 -> 388.832 | J19: =J18*Assumptions!$B$63 -> 390.4 | ... Z19: =Z18*Assumptions!$B$63 -> 0.016374563
A20: COGS + royalties, risk-adjusted | C20: =C18*(Assumptions!$B$64+Assumptions!$B$65) -> 3.496 | D20: =D18*(Assumptions!$B$64+Assumptions!$B$65) -> 8.9528 | E20: =E18*(Assumptions!$B$64+Assumptions!$B$65) -> 16.264 | F20: =F18*(Assumptions!$B$64+Assumptions!$B$65) -> 23.6816 | G20: =G18*(Assumptions!$B$64+Assumptions!$B$65) -> 30.0504 | H20: =H18*(Assumptions!$B$64+Assumptions!$B$65) -> 34.25776 | I20: =I18*(Assumptions!$B$64+Assumptions!$B$65) -> 36.93904 | J20: =J18*(Assumptions!$B$64+Assumptions!$B$65) -> 37.088 | ... Z20: =Z18*(Assumptions!$B$64+Assumptions!$B$65) -> 0.0015555835
A21: Commercial SG&A, risk-adjusted | C21: =Assumptions!$B$32*IF(Assumptions!$B$66=0,0,IF(C14=0,Assumptions!$B$67,IF(C14>=1,C15*IF(OR(Assumptions!$B$63<1,C14>5),Assumptions!$B$66,MAX(Assumptions!$B$66,INDEX(Assumptions!$B$44:$F$44,C14))),0)))+(1-Assumptions!$B$32)*Assumptions!$B$33*IF(Assumptions!$B$66=0,0,IF(C16=0,Assumptions!$B$67,IF(C16>=1,C17*IF(OR(Assumptions!$B$63<1,C16>5),Assumptions!$B$66,MAX(Assumptions!$B$66,INDEX(Assumptions!$B$44:$F$44,C16))),0))) -> 33.12 | D21: =Assumptions!$B$32*IF(Assumptions!$B$66=0,0,IF(D14=0,Assumptions!$B$67,IF(D14>=1,D15*IF(OR(Assumptions!$B$63<1,D14>5),Assumptions!$B$66,MAX(Assumptions!$B$66,INDEX(Assumptions!$B$44:$F$44,D14))),0)))+(1-Assumptions!$B$32)*Assumptions!$B$33*IF(Assumptions!$B$66=0,0,IF(D16=0,Assumptions!$B$67,IF(D16>=1,D17*IF(OR(Assumptions!$B$63<1,D16>5),Assumptions!$B$66,MAX(Assumptions!$B$66,INDEX(Assumptions!$B$44:$F$44,D16))),0))) -> 52.616 | E21: =Assumptions!$B$32*IF(Assumptions!$B$66=0,0,IF(E14=0,Assumptions!$B$67,IF(E14>=1,E15*IF(OR(Assumptions!$B$63<1,E14>5),Assumptions!$B$66,MAX(Assumptions!$B$66,INDEX(Assumptions!$B$44:$F$44,E14))),0)))+(1-Assumptions!$B$32)*Assumptions!$B$33*IF(Assumptions!$B$66=0,0,IF(E16=0,Assumptions!$B$67,IF(E16>=1,E17*IF(OR(Assumptions!$B$63<1,E16>5),Assumptions!$B$66,MAX(Assumptions!$B$66,INDEX(Assumptions!$B$44:$F$44,E16))),0))) -> 69.32 | F21: =Assumptions!$B$32*IF(Assumptions!$B$66=0,0,IF(F14=0,Assumptions!$B$67,IF(F14>=1,F15*IF(OR(Assumptions!$B$63<1,F14>5),Assumptions!$B$66,MAX(Assumptions!$B$66,INDEX(Assumptions!$B$44:$F$44,F14))),0)))+(1-Assumptions!$B$32)*Assumptions!$B$33*IF(Assumptions!$B$66=0,0,IF(F16=0,Assumptions!$B$67,IF(F16>=1,F17*IF(OR(Assumptions!$B$63<1,F16>5),Assumptions!$B$66,MAX(Assumptions!$B$66,INDEX(Assumptions!$B$44:$F$44,F16))),0))) -> 80.576 | G21: =Assumptions!$B$32*IF(Assumptions!$B$66=0,0,IF(G14=0,Assumptions!$B$67,IF(G14>=1,G15*IF(OR(Assumptions!$B$63<1,G14>5),Assumptions!$B$66,MAX(Assumptions!$B$66,INDEX(Assumptions!$B$44:$F$44,G14))),0)))+(1-Assumptions!$B$32)*Assumptions!$B$33*IF(Assumptions!$B$66=0,0,IF(G16=0,Assumptions!$B$67,IF(G16>=1,G17*IF(OR(Assumptions!$B$63<1,G16>5),Assumptions!$B$66,MAX(Assumptions!$B$66,INDEX(Assumptions!$B$44:$F$44,G16))),0))) -> 89.152 | H21: =Assumptions!$B$32*IF(Assumptions!$B$66=0,0,IF(H14=0,Assumptions!$B$67,IF(H14>=1,H15*IF(OR(Assumptions!$B$63<1,H14>5),Assumptions!$B$66,MAX(Assumptions!$B$66,INDEX(Assumptions!$B$44:$F$44,H14))),0)))+(1-Assumptions!$B$32)*Assumptions!$B$33*IF(Assumptions!$B$66=0,0,IF(H16=0,Assumptions!$B$67,IF(H16>=1,H17*IF(OR(Assumptions!$B$63<1,H16>5),Assumptions!$B$66,MAX(Assumptions!$B$66,INDEX(Assumptions!$B$44:$F$44,H16))),0))) -> 56.47904 | I21: =Assumptions!$B$32*IF(Assumptions!$B$66=0,0,IF(I14=0,Assumptions!$B$67,IF(I14>=1,I15*IF(OR(Assumptions!$B$63<1,I14>5),Assumptions!$B$66,MAX(Assumptions!$B$66,INDEX(Assumptions!$B$44:$F$44,I14))),0)))+(1-Assumptions!$B$32)*Assumptions!$B$33*IF(Assumptions!$B$66=0,0,IF(I16=0,Assumptions!$B$67,IF(I16>=1,I17*IF(OR(Assumptions!$B$63<1,I16>5),Assumptions!$B$66,MAX(Assumptions!$B$66,INDEX(Assumptions!$B$44:$F$44,I16))),0))) -> 58.3248 | J21: =Assumptions!$B$32*IF(Assumptions!$B$66=0,0,IF(J14=0,Assumptions!$B$67,IF(J14>=1,J15*IF(OR(Assumptions!$B$63<1,J14>5),Assumptions!$B$66,MAX(Assumptions!$B$66,INDEX(Assumptions!$B$44:$F$44,J14))),0)))+(1-Assumptions!$B$32)*Assumptions!$B$33*IF(Assumptions!$B$66=0,0,IF(J16=0,Assumptions!$B$67,IF(J16>=1,J17*IF(OR(Assumptions!$B$63<1,J16>5),Assumptions!$B$66,MAX(Assumptions!$B$66,INDEX(Assumptions!$B$44:$F$44,J16))),0))) -> 58.56 | ... Z21: =Assumptions!$B$32*IF(Assumptions!$B$66=0,0,IF(Z14=0,Assumptions!$B$67,IF(Z14>=1,Z15*IF(OR(Assumptions!$B$63<1,Z14>5),Assumptions!$B$66,MAX(Assumptions!$B$66,INDEX(Assumptions!$B$44:$F$44,Z14))),0)))+(1-Assumptions!$B$32)*Assumptions!$B$33*IF(Assumptions!$B$66=0,0,IF(Z16=0,Assumptions!$B$67,IF(Z16>=1,Z17*IF(OR(Assumptions!$B$63<1,Z16>5),Assumptions!$B$66,MAX(Assumptions!$B$66,INDEX(Assumptions!$B$44:$F$44,Z16))),0))) -> 0.0024561844
A22: Development R&D, risk-adjusted | C22: =0 -> 0 | D22: =0 -> 0 | E22: =0 -> 0 | F22: =0 -> 0 | G22: =0 -> 0 | H22: =0 -> 0 | I22: =0 -> 0 | J22: =0 -> 0 | ... Z22: =0 -> 0
A23: Program contribution (pre-tax) | C23: =C19-C20-C21-C22 -> 0.184 | D23: =D19-D20-D21-D22 -> 32.6712 | E23: =E19-E20-E21-E22 -> 85.616 | F23: =F19-F20-F21-F22 -> 145.0224 | G23: =G19-G20-G21-G22 -> 197.1176 | H23: =H19-H20-H21-H22 -> 269.8712 | I23: =I19-I20-I21-I22 -> 293.56816 | J23: =J19-J20-J21-J22 -> 294.752 | ... Z23: =Z19-Z20-Z21-Z22 -> 0.012362795
A25: Aficamten — non-obstructive HCM (sNDA Q4 2026)
A26: Years since launch | C26: =C$2-Assumptions!$B$73+1 -> 0 | D26: =D$2-Assumptions!$B$73+1 -> 1 | E26: =E$2-Assumptions!$B$73+1 -> 2 | F26: =F$2-Assumptions!$B$73+1 -> 3 | G26: =G$2-Assumptions!$B$73+1 -> 4 | H26: =H$2-Assumptions!$B$73+1 -> 5 | I26: =I$2-Assumptions!$B$73+1 -> 6 | J26: =J$2-Assumptions!$B$73+1 -> 7 | ... Z26: =Z$2-Assumptions!$B$73+1 -> 23
A27: Net sales, unrisked | C27: =IF(C$2>Assumptions!$B$82,0*(1-Assumptions!$B$83),IF(C26>=1,Assumptions!$B$74*CHOOSE(Assumptions!$B$81,INDEX(Assumptions!$B$42:$H$42,MIN(C26,7)),INDEX(Assumptions!$B$43:$H$43,MIN(C26,7))),0)) -> 0 | D27: =IF(D$2>Assumptions!$B$82,C27*(1-Assumptions!$B$83),IF(D26>=1,Assumptions!$B$74*CHOOSE(Assumptions!$B$81,INDEX(Assumptions!$B$42:$H$42,MIN(D26,7)),INDEX(Assumptions!$B$43:$H$43,MIN(D26,7))),0)) -> 150 | E27: =IF(E$2>Assumptions!$B$82,D27*(1-Assumptions!$B$83),IF(E26>=1,Assumptions!$B$74*CHOOSE(Assumptions!$B$81,INDEX(Assumptions!$B$42:$H$42,MIN(E26,7)),INDEX(Assumptions!$B$43:$H$43,MIN(E26,7))),0)) -> 375 | F27: =IF(F$2>Assumptions!$B$82,E27*(1-Assumptions!$B$83),IF(F26>=1,Assumptions!$B$74*CHOOSE(Assumptions!$B$81,INDEX(Assumptions!$B$42:$H$42,MIN(F26,7)),INDEX(Assumptions!$B$43:$H$43,MIN(F26,7))),0)) -> 675 | G27: =IF(G$2>Assumptions!$B$82,F27*(1-Assumptions!$B$83),IF(G26>=1,Assumptions!$B$74*CHOOSE(Assumptions!$B$81,INDEX(Assumptions!$B$42:$H$42,MIN(G26,7)),INDEX(Assumptions!$B$43:$H$43,MIN(G26,7))),0)) -> 975 | H27: =IF(H$2>Assumptions!$B$82,G27*(1-Assumptions!$B$83),IF(H26>=1,Assumptions!$B$74*CHOOSE(Assumptions!$B$81,INDEX(Assumptions!$B$42:$H$42,MIN(H26,7)),INDEX(Assumptions!$B$43:$H$43,MIN(H26,7))),0)) -> 1230 | I27: =IF(I$2>Assumptions!$B$82,H27*(1-Assumptions!$B$83),IF(I26>=1,Assumptions!$B$74*CHOOSE(Assumptions!$B$81,INDEX(Assumptions!$B$42:$H$42,MIN(I26,7)),INDEX(Assumptions!$B$43:$H$43,MIN(I26,7))),0)) -> 1395 | J27: =IF(J$2>Assumptions!$B$82,I27*(1-Assumptions!$B$83),IF(J26>=1,Assumptions!$B$74*CHOOSE(Assumptions!$B$81,INDEX(Assumptions!$B$42:$H$42,MIN(J26,7)),INDEX(Assumptions!$B$43:$H$43,MIN(J26,7))),0)) -> 1500 | K27: =IF(K$2>Assumptions!$B$82,J27*(1-Assumptions!$B$83),IF(K26>=1,Assumptions!$B$74*CHOOSE(Assumptions!$B$81,INDEX(Assumptions!$B$42:$H$42,MIN(K26,7)),INDEX(Assumptions!$B$43:$H$43,MIN(K26,7))),0)) -> 1500 | ... Z27: =IF(Z$2>Assumptions!$B$82,Y27*(1-Assumptions!$B$83),IF(Z26>=1,Assumptions!$B$74*CHOOSE(Assumptions!$B$81,INDEX(Assumptions!$B$42:$H$42,MIN(Z26,7)),INDEX(Assumptions!$B$43:$H$43,MIN(Z26,7))),0)) -> 0.06291456
A28: Product net sales, risk-adjusted | C28: =C27*MIN(1,Assumptions!$B$75*Assumptions!$B$37) -> 0 | D28: =D27*MIN(1,Assumptions!$B$75*Assumptions!$B$37) -> 123 | E28: =E27*MIN(1,Assumptions!$B$75*Assumptions!$B$37) -> 307.5 | F28: =F27*MIN(1,Assumptions!$B$75*Assumptions!$B$37) -> 553.5 | G28: =G27*MIN(1,Assumptions!$B$75*Assumptions!$B$37) -> 799.5 | H28: =H27*MIN(1,Assumptions!$B$75*Assumptions!$B$37) -> 1008.6 | I28: =I27*MIN(1,Assumptions!$B$75*Assumptions!$B$37) -> 1143.9 | J28: =J27*MIN(1,Assumptions!$B$75*Assumptions!$B$37) -> 1230 | ... Z28: =Z27*MIN(1,Assumptions!$B$75*Assumptions!$B$37) -> 0.051589939
A29: Company revenue, risk-adjusted (incl. milestones) | C29: =C28*Assumptions!$B$76 -> 0 | D29: =D28*Assumptions!$B$76 -> 123 | E29: =E28*Assumptions!$B$76 -> 307.5 | F29: =F28*Assumptions!$B$76 -> 553.5 | G29: =G28*Assumptions!$B$76 -> 799.5 | H29: =H28*Assumptions!$B$76 -> 1008.6 | I29: =I28*Assumptions!$B$76 -> 1143.9 | J29: =J28*Assumptions!$B$76 -> 1230 | ... Z29: =Z28*Assumptions!$B$76 -> 0.051589939
A30: COGS + royalties, risk-adjusted | C30: =C28*(Assumptions!$B$77+Assumptions!$B$78) -> 0 | D30: =D28*(Assumptions!$B$77+Assumptions!$B$78) -> 11.685 | E30: =E28*(Assumptions!$B$77+Assumptions!$B$78) -> 29.2125 | F30: =F28*(Assumptions!$B$77+Assumptions!$B$78) -> 52.5825 | G30: =G28*(Assumptions!$B$77+Assumptions!$B$78) -> 75.9525 | H30: =H28*(Assumptions!$B$77+Assumptions!$B$78) -> 95.817 | I30: =I28*(Assumptions!$B$77+Assumptions!$B$78) -> 108.6705 | J30: =J28*(Assumptions!$B$77+Assumptions!$B$78) -> 116.85 | ... Z30: =Z28*(Assumptions!$B$77+Assumptions!$B$78) -> 0.0049010442
A31: Commercial SG&A, risk-adjusted | C31: =MIN(1,Assumptions!$B$75*Assumptions!$B$37)*IF(Assumptions!$B$79=0,0,IF(C26=0,Assumptions!$B$80,IF(C26>=1,C27*IF(OR(Assumptions!$B$76<1,C26>5),Assumptions!$B$79,MAX(Assumptions!$B$79,INDEX(Assumptions!$B$44:$F$44,C26))),0))) -> 32.8 | D31: =MIN(1,Assumptions!$B$75*Assumptions!$B$37)*IF(Assumptions!$B$79=0,0,IF(D26=0,Assumptions!$B$80,IF(D26>=1,D27*IF(OR(Assumptions!$B$76<1,D26>5),Assumptions!$B$79,MAX(Assumptions!$B$79,INDEX(Assumptions!$B$44:$F$44,D26))),0))) -> 110.7 | E31: =MIN(1,Assumptions!$B$75*Assumptions!$B$37)*IF(Assumptions!$B$79=0,0,IF(E26=0,Assumptions!$B$80,IF(E26>=1,E27*IF(OR(Assumptions!$B$76<1,E26>5),Assumptions!$B$79,MAX(Assumptions!$B$79,INDEX(Assumptions!$B$44:$F$44,E26))),0))) -> 169.125 | F31: =MIN(1,Assumptions!$B$75*Assumptions!$B$37)*IF(Assumptions!$B$79=0,0,IF(F26=0,Assumptions!$B$80,IF(F26>=1,F27*IF(OR(Assumptions!$B$76<1,F26>5),Assumptions!$B$79,MAX(Assumptions!$B$79,INDEX(Assumptions!$B$44:$F$44,F26))),0))) -> 221.4 | G31: =MIN(1,Assumptions!$B$75*Assumptions!$B$37)*IF(Assumptions!$B$79=0,0,IF(G26=0,Assumptions!$B$80,IF(G26>=1,G27*IF(OR(Assumptions!$B$76<1,G26>5),Assumptions!$B$79,MAX(Assumptions!$B$79,INDEX(Assumptions!$B$44:$F$44,G26))),0))) -> 255.84 | H31: =MIN(1,Assumptions!$B$75*Assumptions!$B$37)*IF(Assumptions!$B$79=0,0,IF(H26=0,Assumptions!$B$80,IF(H26>=1,H27*IF(OR(Assumptions!$B$76<1,H26>5),Assumptions!$B$79,MAX(Assumptions!$B$79,INDEX(Assumptions!$B$44:$F$44,H26))),0))) -> 282.408 | I31: =MIN(1,Assumptions!$B$75*Assumptions!$B$37)*IF(Assumptions!$B$79=0,0,IF(I26=0,Assumptions!$B$80,IF(I26>=1,I27*IF(OR(Assumptions!$B$76<1,I26>5),Assumptions!$B$79,MAX(Assumptions!$B$79,INDEX(Assumptions!$B$44:$F$44,I26))),0))) -> 285.975 | J31: =MIN(1,Assumptions!$B$75*Assumptions!$B$37)*IF(Assumptions!$B$79=0,0,IF(J26=0,Assumptions!$B$80,IF(J26>=1,J27*IF(OR(Assumptions!$B$76<1,J26>5),Assumptions!$B$79,MAX(Assumptions!$B$79,INDEX(Assumptions!$B$44:$F$44,J26))),0))) -> 307.5 | ... Z31: =MIN(1,Assumptions!$B$75*Assumptions!$B$37)*IF(Assumptions!$B$79=0,0,IF(Z26=0,Assumptions!$B$80,IF(Z26>=1,Z27*IF(OR(Assumptions!$B$76<1,Z26>5),Assumptions!$B$79,MAX(Assumptions!$B$79,INDEX(Assumptions!$B$44:$F$44,Z26))),0))) -> 0.012897485
A32: Development R&D, risk-adjusted | C32: =IFERROR(INDEX(Assumptions!$B$85:$I$85,MATCH(C$2,Assumptions!$B$84:$I$84,0))*INDEX(Assumptions!$B$86:$I$86,MATCH(C$2,Assumptions!$B$84:$I$84,0)),0) -> 10 | D32: =IFERROR(INDEX(Assumptions!$B$85:$I$85,MATCH(D$2,Assumptions!$B$84:$I$84,0))*INDEX(Assumptions!$B$86:$I$86,MATCH(D$2,Assumptions!$B$84:$I$84,0)),0) -> 0 | E32: =IFERROR(INDEX(Assumptions!$B$85:$I$85,MATCH(E$2,Assumptions!$B$84:$I$84,0))*INDEX(Assumptions!$B$86:$I$86,MATCH(E$2,Assumptions!$B$84:$I$84,0)),0) -> 0 | F32: =IFERROR(INDEX(Assumptions!$B$85:$I$85,MATCH(F$2,Assumptions!$B$84:$I$84,0))*INDEX(Assumptions!$B$86:$I$86,MATCH(F$2,Assumptions!$B$84:$I$84,0)),0) -> 0 | G32: =IFERROR(INDEX(Assumptions!$B$85:$I$85,MATCH(G$2,Assumptions!$B$84:$I$84,0))*INDEX(Assumptions!$B$86:$I$86,MATCH(G$2,Assumptions!$B$84:$I$84,0)),0) -> 0 | H32: =IFERROR(INDEX(Assumptions!$B$85:$I$85,MATCH(H$2,Assumptions!$B$84:$I$84,0))*INDEX(Assumptions!$B$86:$I$86,MATCH(H$2,Assumptions!$B$84:$I$84,0)),0) -> 0 | I32: =IFERROR(INDEX(Assumptions!$B$85:$I$85,MATCH(I$2,Assumptions!$B$84:$I$84,0))*INDEX(Assumptions!$B$86:$I$86,MATCH(I$2,Assumptions!$B$84:$I$84,0)),0) -> 0 | J32: =IFERROR(INDEX(Assumptions!$B$85:$I$85,MATCH(J$2,Assumptions!$B$84:$I$84,0))*INDEX(Assumptions!$B$86:$I$86,MATCH(J$2,Assumptions!$B$84:$I$84,0)),0) -> 0 | ... Z32: =IFERROR(INDEX(Assumptions!$B$85:$I$85,MATCH(Z$2,Assumptions!$B$84:$I$84,0))*INDEX(Assumptions!$B$86:$I$86,MATCH(Z$2,Assumptions!$B$84:$I$84,0)),0) -> 0
A33: Program contribution (pre-tax) | C33: =C29-C30-C31-C32 -> -42.8 | D33: =D29-D30-D31-D32 -> 0.615 | E33: =E29-E30-E31-E32 -> 109.1625 | F33: =F29-F30-F31-F32 -> 279.5175 | G33: =G29-G30-G31-G32 -> 467.7075 | H33: =H29-H30-H31-H32 -> 630.375 | I33: =I29-I30-I31-I32 -> 749.2545 | J33: =J29-J30-J31-J32 -> 805.65 | ... Z33: =Z29-Z30-Z31-Z32 -> 0.03379141
A35: Omecamtiv mecarbil — HFrEF (COMET-HF)
A36: Years since launch | C36: =C$2-Assumptions!$B$89+1 -> -2 | D36: =D$2-Assumptions!$B$89+1 -> -1 | E36: =E$2-Assumptions!$B$89+1 -> 0 | F36: =F$2-Assumptions!$B$89+1 -> 1 | G36: =G$2-Assumptions!$B$89+1 -> 2 | H36: =H$2-Assumptions!$B$89+1 -> 3 | I36: =I$2-Assumptions!$B$89+1 -> 4 | J36: =J$2-Assumptions!$B$89+1 -> 5 | ... Z36: =Z$2-Assumptions!$B$89+1 -> 21
A37: Net sales, unrisked | C37: =IF(C$2>Assumptions!$B$98,0*(1-Assumptions!$B$99),IF(C36>=1,Assumptions!$B$90*CHOOSE(Assumptions!$B$97,INDEX(Assumptions!$B$42:$H$42,MIN(C36,7)),INDEX(Assumptions!$B$43:$H$43,MIN(C36,7))),0)) -> 0 | D37: =IF(D$2>Assumptions!$B$98,C37*(1-Assumptions!$B$99),IF(D36>=1,Assumptions!$B$90*CHOOSE(Assumptions!$B$97,INDEX(Assumptions!$B$42:$H$42,MIN(D36,7)),INDEX(Assumptions!$B$43:$H$43,MIN(D36,7))),0)) -> 0 | E37: =IF(E$2>Assumptions!$B$98,D37*(1-Assumptions!$B$99),IF(E36>=1,Assumptions!$B$90*CHOOSE(Assumptions!$B$97,INDEX(Assumptions!$B$42:$H$42,MIN(E36,7)),INDEX(Assumptions!$B$43:$H$43,MIN(E36,7))),0)) -> 0 | F37: =IF(F$2>Assumptions!$B$98,E37*(1-Assumptions!$B$99),IF(F36>=1,Assumptions!$B$90*CHOOSE(Assumptions!$B$97,INDEX(Assumptions!$B$42:$H$42,MIN(F36,7)),INDEX(Assumptions!$B$43:$H$43,MIN(F36,7))),0)) -> 100 | G37: =IF(G$2>Assumptions!$B$98,F37*(1-Assumptions!$B$99),IF(G36>=1,Assumptions!$B$90*CHOOSE(Assumptions!$B$97,INDEX(Assumptions!$B$42:$H$42,MIN(G36,7)),INDEX(Assumptions!$B$43:$H$43,MIN(G36,7))),0)) -> 250 | H37: =IF(H$2>Assumptions!$B$98,G37*(1-Assumptions!$B$99),IF(H36>=1,Assumptions!$B$90*CHOOSE(Assumptions!$B$97,INDEX(Assumptions!$B$42:$H$42,MIN(H36,7)),INDEX(Assumptions!$B$43:$H$43,MIN(H36,7))),0)) -> 450 | I37: =IF(I$2>Assumptions!$B$98,H37*(1-Assumptions!$B$99),IF(I36>=1,Assumptions!$B$90*CHOOSE(Assumptions!$B$97,INDEX(Assumptions!$B$42:$H$42,MIN(I36,7)),INDEX(Assumptions!$B$43:$H$43,MIN(I36,7))),0)) -> 650 | J37: =IF(J$2>Assumptions!$B$98,I37*(1-Assumptions!$B$99),IF(J36>=1,Assumptions!$B$90*CHOOSE(Assumptions!$B$97,INDEX(Assumptions!$B$42:$H$42,MIN(J36,7)),INDEX(Assumptions!$B$43:$H$43,MIN(J36,7))),0)) -> 820 | K37: =IF(K$2>Assumptions!$B$98,J37*(1-Assumptions!$B$99),IF(K36>=1,Assumptions!$B$90*CHOOSE(Assumptions!$B$97,INDEX(Assumptions!$B$42:$H$42,MIN(K36,7)),INDEX(Assumptions!$B$43:$H$43,MIN(K36,7))),0)) -> 930 | ... Z37: =IF(Z$2>Assumptions!$B$98,Y37*(1-Assumptions!$B$99),IF(Z36>=1,Assumptions!$B$90*CHOOSE(Assumptions!$B$97,INDEX(Assumptions!$B$42:$H$42,MIN(Z36,7)),INDEX(Assumptions!$B$43:$H$43,MIN(Z36,7))),0)) -> 0.1048576
A38: Product net sales, risk-adjusted | C38: =C37*MIN(1,Assumptions!$B$91*Assumptions!$B$37) -> 0 | D38: =D37*MIN(1,Assumptions!$B$91*Assumptions!$B$37) -> 0 | E38: =E37*MIN(1,Assumptions!$B$91*Assumptions!$B$37) -> 0 | F38: =F37*MIN(1,Assumptions!$B$91*Assumptions!$B$37) -> 30 | G38: =G37*MIN(1,Assumptions!$B$91*Assumptions!$B$37) -> 75 | H38: =H37*MIN(1,Assumptions!$B$91*Assumptions!$B$37) -> 135 | I38: =I37*MIN(1,Assumptions!$B$91*Assumptions!$B$37) -> 195 | J38: =J37*MIN(1,Assumptions!$B$91*Assumptions!$B$37) -> 246 | ... Z38: =Z37*MIN(1,Assumptions!$B$91*Assumptions!$B$37) -> 0.03145728
A39: Company revenue, risk-adjusted (incl. milestones) | C39: =C38*Assumptions!$B$92 -> 0 | D39: =D38*Assumptions!$B$92 -> 0 | E39: =E38*Assumptions!$B$92 -> 0 | F39: =F38*Assumptions!$B$92 -> 30 | G39: =G38*Assumptions!$B$92 -> 75 | H39: =H38*Assumptions!$B$92 -> 135 | I39: =I38*Assumptions!$B$92 -> 195 | J39: =J38*Assumptions!$B$92 -> 246 | ... Z39: =Z38*Assumptions!$B$92 -> 0.03145728
A40: COGS + royalties, risk-adjusted | C40: =C38*(Assumptions!$B$93+Assumptions!$B$94) -> 0 | D40: =D38*(Assumptions!$B$93+Assumptions!$B$94) -> 0 | E40: =E38*(Assumptions!$B$93+Assumptions!$B$94) -> 0 | F40: =F38*(Assumptions!$B$93+Assumptions!$B$94) -> 3.3 | G40: =G38*(Assumptions!$B$93+Assumptions!$B$94) -> 8.25 | H40: =H38*(Assumptions!$B$93+Assumptions!$B$94) -> 14.85 | I40: =I38*(Assumptions!$B$93+Assumptions!$B$94) -> 21.45 | J40: =J38*(Assumptions!$B$93+Assumptions!$B$94) -> 27.06 | ... Z40: =Z38*(Assumptions!$B$93+Assumptions!$B$94) -> 0.0034603008
A41: Commercial SG&A, risk-adjusted | C41: =MIN(1,Assumptions!$B$91*Assumptions!$B$37)*IF(Assumptions!$B$95=0,0,IF(C36=0,Assumptions!$B$96,IF(C36>=1,C37*IF(OR(Assumptions!$B$92<1,C36>5),Assumptions!$B$95,MAX(Assumptions!$B$95,INDEX(Assumptions!$B$44:$F$44,C36))),0))) -> 0 | D41: =MIN(1,Assumptions!$B$91*Assumptions!$B$37)*IF(Assumptions!$B$95=0,0,IF(D36=0,Assumptions!$B$96,IF(D36>=1,D37*IF(OR(Assumptions!$B$92<1,D36>5),Assumptions!$B$95,MAX(Assumptions!$B$95,INDEX(Assumptions!$B$44:$F$44,D36))),0))) -> 0 | E41: =MIN(1,Assumptions!$B$91*Assumptions!$B$37)*IF(Assumptions!$B$95=0,0,IF(E36=0,Assumptions!$B$96,IF(E36>=1,E37*IF(OR(Assumptions!$B$92<1,E36>5),Assumptions!$B$95,MAX(Assumptions!$B$95,INDEX(Assumptions!$B$44:$F$44,E36))),0))) -> 12 | F41: =MIN(1,Assumptions!$B$91*Assumptions!$B$37)*IF(Assumptions!$B$95=0,0,IF(F36=0,Assumptions!$B$96,IF(F36>=1,F37*IF(OR(Assumptions!$B$92<1,F36>5),Assumptions!$B$95,MAX(Assumptions!$B$95,INDEX(Assumptions!$B$44:$F$44,F36))),0))) -> 27 | G41: =MIN(1,Assumptions!$B$91*Assumptions!$B$37)*IF(Assumptions!$B$95=0,0,IF(G36=0,Assumptions!$B$96,IF(G36>=1,G37*IF(OR(Assumptions!$B$92<1,G36>5),Assumptions!$B$95,MAX(Assumptions!$B$95,INDEX(Assumptions!$B$44:$F$44,G36))),0))) -> 41.25 | H41: =MIN(1,Assumptions!$B$91*Assumptions!$B$37)*IF(Assumptions!$B$95=0,0,IF(H36=0,Assumptions!$B$96,IF(H36>=1,H37*IF(OR(Assumptions!$B$92<1,H36>5),Assumptions!$B$95,MAX(Assumptions!$B$95,INDEX(Assumptions!$B$44:$F$44,H36))),0))) -> 54 | I41: =MIN(1,Assumptions!$B$91*Assumptions!$B$37)*IF(Assumptions!$B$95=0,0,IF(I36=0,Assumptions!$B$96,IF(I36>=1,I37*IF(OR(Assumptions!$B$92<1,I36>5),Assumptions!$B$95,MAX(Assumptions!$B$95,INDEX(Assumptions!$B$44:$F$44,I36))),0))) -> 62.4 | J41: =MIN(1,Assumptions!$B$91*Assumptions!$B$37)*IF(Assumptions!$B$95=0,0,IF(J36=0,Assumptions!$B$96,IF(J36>=1,J37*IF(OR(Assumptions!$B$92<1,J36>5),Assumptions!$B$95,MAX(Assumptions!$B$95,INDEX(Assumptions!$B$44:$F$44,J36))),0))) -> 73.8 | ... Z41: =MIN(1,Assumptions!$B$91*Assumptions!$B$37)*IF(Assumptions!$B$95=0,0,IF(Z36=0,Assumptions!$B$96,IF(Z36>=1,Z37*IF(OR(Assumptions!$B$92<1,Z36>5),Assumptions!$B$95,MAX(Assumptions!$B$95,INDEX(Assumptions!$B$44:$F$44,Z36))),0))) -> 0.009437184
A42: Development R&D, risk-adjusted | C42: =IFERROR(INDEX(Assumptions!$B$101:$I$101,MATCH(C$2,Assumptions!$B$100:$I$100,0))*INDEX(Assumptions!$B$102:$I$102,MATCH(C$2,Assumptions!$B$100:$I$100,0)),0) -> 80 | D42: =IFERROR(INDEX(Assumptions!$B$101:$I$101,MATCH(D$2,Assumptions!$B$100:$I$100,0))*INDEX(Assumptions!$B$102:$I$102,MATCH(D$2,Assumptions!$B$100:$I$100,0)),0) -> 60 | E42: =IFERROR(INDEX(Assumptions!$B$101:$I$101,MATCH(E$2,Assumptions!$B$100:$I$100,0))*INDEX(Assumptions!$B$102:$I$102,MATCH(E$2,Assumptions!$B$100:$I$100,0)),0) -> 7 | F42: =IFERROR(INDEX(Assumptions!$B$101:$I$101,MATCH(F$2,Assumptions!$B$100:$I$100,0))*INDEX(Assumptions!$B$102:$I$102,MATCH(F$2,Assumptions!$B$100:$I$100,0)),0) -> 0 | G42: =IFERROR(INDEX(Assumptions!$B$101:$I$101,MATCH(G$2,Assumptions!$B$100:$I$100,0))*INDEX(Assumptions!$B$102:$I$102,MATCH(G$2,Assumptions!$B$100:$I$100,0)),0) -> 0 | H42: =IFERROR(INDEX(Assumptions!$B$101:$I$101,MATCH(H$2,Assumptions!$B$100:$I$100,0))*INDEX(Assumptions!$B$102:$I$102,MATCH(H$2,Assumptions!$B$100:$I$100,0)),0) -> 0 | I42: =IFERROR(INDEX(Assumptions!$B$101:$I$101,MATCH(I$2,Assumptions!$B$100:$I$100,0))*INDEX(Assumptions!$B$102:$I$102,MATCH(I$2,Assumptions!$B$100:$I$100,0)),0) -> 0 | J42: =IFERROR(INDEX(Assumptions!$B$101:$I$101,MATCH(J$2,Assumptions!$B$100:$I$100,0))*INDEX(Assumptions!$B$102:$I$102,MATCH(J$2,Assumptions!$B$100:$I$100,0)),0) -> 0 | ... Z42: =IFERROR(INDEX(Assumptions!$B$101:$I$101,MATCH(Z$2,Assumptions!$B$100:$I$100,0))*INDEX(Assumptions!$B$102:$I$102,MATCH(Z$2,Assumptions!$B$100:$I$100,0)),0) -> 0
A43: Program contribution (pre-tax) | C43: =C39-C40-C41-C42 -> -80 | D43: =D39-D40-D41-D42 -> -60 | E43: =E39-E40-E41-E42 -> -19 | F43: =F39-F40-F41-F42 -> -0.3 | G43: =G39-G40-G41-G42 -> 25.5 | H43: =H39-H40-H41-H42 -> 66.15 | I43: =I39-I40-I41-I42 -> 111.15 | J43: =J39-J40-J41-J42 -> 145.14 | ... Z43: =Z39-Z40-Z41-Z42 -> 0.018559795
A45: Ulacamten — HFpEF (Phase 2)
...

Sheet NPV
A1: CYTK — risk-adjusted NPV (rNPV), $mm except per share
A3: Scenario | B3: =Assumptions!$C$4 -> Base
A4: Valuation date | B4: =Assumptions!$B$13 -> 46311
A5: Discount rate | B5: =Assumptions!$B$14 -> 0.1
A7: Period | C7: 2H 2026 | D7: 2027 | E7: 2028 | F7: 2029 | G7: 2030 | H7: 2031 | I7: 2032 | J7: 2033 | K7: 2034 | L7: 2035 | M7: 2036 | N7: 2037 | O7: 2038 | P7: 2039 | Q7: 2040 | R7: 2041 | S7: 2042 | T7: 2043 | U7: 2044 | V7: 2045 | W7: 2046 | X7: 2047 | Y7: 2048 | Z7: 2049 | AA7: 2050
A8: Revenue, risk-adjusted | C8: =SUM('Quarterly Model'!H2:I2) -> 96 | D8: ='Yearly Model'!H2 -> 339.95744 | E8: ='Yearly Model'!I2 -> 788.04665 | F8: ='Yearly Model'!J2 -> 1362.2903 | G8: ='Yearly Model'!K2 -> 2062.6163 | H8: ='Yearly Model'!L2 -> 2794.1228 | I8: ='Yearly Model'!M2 -> 3519.208 | J8: ='Yearly Model'!N2 -> 3765.232 | K8: ='Yearly Model'!O2 -> 3933.9 | ... AA8: ='Yearly Model'!AE2 -> 1.7193079
A9: Operating income (EBIT) | C9: =SUM('Quarterly Model'!H8:I8) -> -332.84 | D9: ='Yearly Model'!H8 -> -454.99511 | E9: ='Yearly Model'!I8 -> -181.75644 | F9: ='Yearly Model'!J8 -> 215.70982 | G9: ='Yearly Model'!K8 -> 701.76927 | H9: ='Yearly Model'!L8 -> 1165.6639 | I9: ='Yearly Model'!M8 -> 1572.6296 | J9: ='Yearly Model'!N8 -> 1724.2388 | K9: ='Yearly Model'!O8 -> 1802.8495 | ... AA9: ='Yearly Model'!AE8 -> 0.70507781
A10: Taxes on EBIT (after tax-loss pool) | C10: 0 | D10: =IF(D9>0,MAX(0,D9-'Yearly Model'!G21)*Assumptions!$B$15,0) -> 0 | E10: =IF(E9>0,MAX(0,E9-'Yearly Model'!H21)*Assumptions!$B$15,0) -> 0 | F10: =IF(F9>0,MAX(0,F9-'Yearly Model'!I21)*Assumptions!$B$15,0) -> 0 | G10: =IF(G9>0,MAX(0,G9-'Yearly Model'!J21)*Assumptions!$B$15,0) -> 0 | H10: =IF(H9>0,MAX(0,H9-'Yearly Model'!K21)*Assumptions!$B$15,0) -> 0 | I10: =IF(I9>0,MAX(0,I9-'Yearly Model'!L21)*Assumptions!$B$15,0) -> 0 | J10: =IF(J9>0,MAX(0,J9-'Yearly Model'!M21)*Assumptions!$B$15,0) -> 232.93872 | K10: =IF(K9>0,MAX(0,K9-'Yearly Model'!N21)*Assumptions!$B$15,0) -> 378.5984 | ... AA10: =IF(AA9>0,MAX(0,AA9-'Yearly Model'!AD21)*Assumptions!$B$15,0) -> 0.14806634
A11: Unlevered free cash flow | C11: =C9-C10 -> -332.84 | D11: =D9-D10 -> -454.99511 | E11: =E9-E10 -> -181.75644 | F11: =F9-F10 -> 215.70982 | G11: =G9-G10 -> 701.76927 | H11: =H9-H10 -> 1165.6639 | I11: =I9-I10 -> 1572.6296 | J11: =J9-J10 -> 1491.3 | ... AA11: =AA9-AA10 -> 0.55701147
A12: Cash-flow date (mid-period) | C12: =DATE(2026,10,1) -> 46296 | D12: =DATE(D7,7,1) -> 46569 | E12: =DATE(E7,7,1) -> 46935 | F12: =DATE(F7,7,1) -> 47300 | G12: =DATE(G7,7,1) -> 47665 | H12: =DATE(H7,7,1) -> 48030 | I12: =DATE(I7,7,1) -> 48396 | J12: =DATE(J7,7,1) -> 48761 | K12: =DATE(K7,7,1) -> 49126 | ... AA12: =DATE(AA7,7,1) -> 54970
A13: Years from valuation date | C13: =MAX(0,(C12-$B$4)/365.25) -> 0 | D13: =MAX(0,(D12-$B$4)/365.25) -> 0.7063655 | E13: =MAX(0,(E12-$B$4)/365.25) -> 1.7084189 | F13: =MAX(0,(F12-$B$4)/365.25) -> 2.7077344 | G13: =MAX(0,(G12-$B$4)/365.25) -> 3.70705 | H13: =MAX(0,(H12-$B$4)/365.25) -> 4.7063655 | I13: =MAX(0,(I12-$B$4)/365.25) -> 5.7084189 | J13: =MAX(0,(J12-$B$4)/365.25) -> 6.7077344 | ... AA13: =MAX(0,(AA12-$B$4)/365.25) -> 23.70705
A14: Discount factor | C14: =1/(1+$B$5)^C13 -> 1 | D14: =1/(1+$B$5)^D13 -> 0.93489241 | E14: =1/(1+$B$5)^E13 -> 0.84973588 | F14: =1/(1+$B$5)^F13 -> 0.77253756 | G14: =1/(1+$B$5)^G13 -> 0.70235269 | H14: =1/(1+$B$5)^H13 -> 0.6385441 | I14: =1/(1+$B$5)^I13 -> 0.58038104 | J14: =1/(1+$B$5)^J13 -> 0.52765355 | ... AA14: =1/(1+$B$5)^AA13 -> 0.10440025
A15: PV of free cash flow | C15: =C11*C14 -> -332.84 | D15: =D11*D14 -> -425.37148 | E15: =E11*E14 -> -154.44497 | F15: =F11*F14 -> 166.64394 | G15: =G11*G14 -> 492.88953 | H15: =H11*H14 -> 744.3278 | I15: =I11*I14 -> 912.7244 | J15: =J11*J14 -> 786.88975 | ... AA15: =AA11*AA14 -> 0.058152138
A17: Valuation summary
A18: PV of risk-adjusted free cash flows | C18: =SUM(C15:AA15) -> 5821.8244
A19: Cash & investments (Main; incl. post-quarter financing) | C19: =Main!C7 -> 1704.003
A20: Debt, convertibles & preferred at face (Main) | C20: =Main!C8 -> 1166.06
A21: Equity value, all claims treated as debt | C21: =C18+C19-C20 -> 6359.7674
A22: Basic shares incl. pre-funded / as-converted (Main) | C22: =Main!C4 -> 139.02342
A23: Value / share before conversions | C23: =C21/C22 -> 45.746015
A25: Convertible instruments (converted if value / share before conversions > conversion price) | B25: Face ($mm) | C25: Shares (mm) | D25: Conv. price | E25: Converted?
A26: 2027 convertible notes | B26: 140.5 | C26: 2.751 | D26: 51.08 | E26: =IF(AND(C26>0,$C$23>D26),1,0) -> 0
A27: 2031 convertible notes | B27: 750 | C27: 10.962 | D27: 68.42 | E27: =IF(AND(C27>0,$C$23>D27),1,0) -> 0
A28: — | B28: 0 | C28: 0 | D28: 0 | E28: =IF(AND(C28>0,$C$23>D28),1,0) -> 0
A29: — | B29: 0 | C29: 0 | D29: 0 | E29: =IF(AND(C29>0,$C$23>D29),1,0) -> 0
A30: — | B30: 0 | C30: 0 | D30: 0 | E30: =IF(AND(C30>0,$C$23>D30),1,0) -> 0
A31: Equity value (rNPV) after conversions | C31: =C21+SUMPRODUCT(B26:B30,E26:E30) -> 6359.7674
A32: Shares after conversions (mm) | C32: =C22+SUMPRODUCT(C26:C30,E26:E30) -> 139.02342
A33: Value / share before options & warrants | C33: =C31/C32 -> 45.746015
A35: Options, warrants & RSUs (treasury-stock method) | B35: Count (mm) | C35: Strike | D35: Dilution (mm)
A36: Options (strike assumed) | B36: 10.776 | C36: 45 | D36: =IF(AND(B36>0,$C$33>C36),B36*(1-C36/$C$33),0) -> 0.17573246
A37: RSUs / PSUs | B37: 2.941 | C37: 0 | D37: =IF(AND(B37>0,$C$33>C37),B37*(1-C37/$C$33),0) -> 2.941
A38: — | B38: 0 | C38: 0 | D38: =IF(AND(B38>0,$C$33>C38),B38*(1-C38/$C$33),0) -> 0
A39: — | B39: 0 | C39: 0 | D39: =IF(AND(B39>0,$C$33>C39),B39*(1-C39/$C$33),0) -> 0
A40: — | B40: 0 | C40: 0 | D40: =IF(AND(B40>0,$C$33>C40),B40*(1-C40/$C$33),0) -> 0
A41: — | B41: 0 | C41: 0 | D41: =IF(AND(B41>0,$C$33>C41),B41*(1-C41/$C$33),0) -> 0
A42: Diluted shares (mm) | C42: =C32+SUM(D36:D41) -> 142.14015
A43: rNPV / share, diluted | C43: =C31/C42 -> 44.742934
A44: Current price (Main) | C44: =Main!C3 -> 63.95
A45: Upside / (downside) to rNPV | C45: =C43/C44-1 -> -0.30034505
...

Sheet Options
A1: CYTK — PDUFA options analysis (per contract = 100 shares)
A3: Inputs
A4: Spot price (close 10/16/2026) | B4: 61.95
A5: Pricing date | B5: =DATE(2026,10,16) -> 46311
A6: PDUFA date | B6: =Assumptions!$B$30 -> 46340
A7: Expiry (first monthly after the PDUFA date) | B7: =DATE(2026,11,20) -> 46346
A8: Years to expiry (T) | B8: =(B7-B5)/365 -> 0.095890411
A9: Risk-free rate | B9: 0.04
A10: Reference IV for wide quotes (theo prices) | B10: 0.5611
A11: Contract multiplier | B11: 100
A13: Event model (two outcomes at the PDUFA)
A14: Model value / share, probability-weighted | B14: =NPV!C43 -> 44.742934
A15: Model value / share if approved | B15: =Assumptions!$D$134 -> 44.933312
A16: Model value / share if CRL | B16: =Assumptions!$D$133 -> 42.393693
A17: Model probability of approval | B17: =Assumptions!$B$32 -> 0.92
A18: Event-move scale (share of model jump priced at expiry) | B18: 1
A19: Floor after a CRL, % of est. 12/31/2026 net cash / share | B19: 0.5
A20: Floor price after a CRL | B20: =MAX(0,B19*(NPV!C47-NPV!C20)/NPV!C22) -> 0.60818171
A21: Price if approved (center of outcome) | B21: =IF(B14>0,B4*(1+B18*(B15/B14-1)),B4+B18*(B15-B14)) -> 62.213593
A22: Price if CRL (center of outcome) | B22: =MAX(B20,IF(B14>0,B4*(1+B18*(B16/B14-1)),B4+B18*(B16-B14))) -> 58.697297
A23: Model expected price after the decision | B23: =B17*B21+(1-B17)*B22 -> 61.932289
A24: Non-event volatility (6-month realized, 3 largest days removed) | B24: 0.346
A25: Model fair ATM straddle, % of spot (jump + non-event volatility) | B25: =(B17*((B21*NORMSDIST(((LN(B21/62.5)+$B$24^2*$B$8/2)/($B$24*SQRT($B$8))))-62.5*NORMSDIST((((LN(B21/62.5)+$B$24^2*$B$8/2)/($B$24*SQRT($B$8)))-$B$24*SQRT($B$8))))+(62.5*NORMSDIST(-(((LN(B21/62.5)+$B$24^2*$B$8/2)/($B$24*SQRT($B$8)))-$B$24*SQRT($B$8)))-B21*NORMSDIST(-((LN(B21/62.5)+$B$24^2*$B$8/2)/($B$24*SQRT($B$8))))))+(1-B17)*((B22*NORMSDIST(((LN(B22/62.5)+$B$24^2*$B$8/2)/($B$24*SQRT($B$8))))-62.5*NORMSDIST((((LN(B22/62.5)+$B$24^2*$B$8/2)/($B$24*SQRT($B$8)))-$B$24*SQRT($B$8))))+(62.5*NORMSDIST(-(((LN(B22/62.5)+$B$24^2*$B$8/2)/($B$24*SQRT($B$8)))-$B$24*SQRT($B$8)))-B22*NORMSDIST(-((LN(B22/62.5)+$B$24^2*$B$8/2)/($B$24*SQRT($B$8)))))))/B4 -> 0.087000919
A26: Market ATM straddle, % of spot | B26: =($G$41+$G$42)/B4 -> 0.13886387
A27: Options richness (market straddle ÷ model straddle) | B27: =B26/B25 -> 1.5961196
A28: Market snapshot — 11/20/2026 expiry (Cboe delayed quotes, 10/16/2026 close)
A29: Strike | B29: Call bid | C29: Call ask | D29: Call mid | E29: Call IV | F29: Put bid | G29: Put ask | H29: Put mid | I29: Put IV | J29: Call OI | K29: Put OI
A30: 52.5 | B30: 8.5 | C30: 12.6 | D30: =(B30+C30)/2 -> 10.55 | E30: 0.5218 | F30: 0.05 | G30: 2.85 | H30: =(F30+G30)/2 -> 1.45 | I30: 0.6908 | J30: 0 | K30: 0
A31: 55 | B31: 6.7 | C31: 10.6 | D31: =(B31+C31)/2 -> 8.65 | E31: 0.5388 | F31: 1.2 | G31: 2 | H31: =(F31+G31)/2 -> 1.6 | I31: 0.5981 | J31: 22 | K31: 164
A32: 57.5 | B32: 4.8 | C32: 8.8 | D32: =(B32+C32)/2 -> 6.8 | E32: 0.524 | F32: 0.45 | G32: 3.7 | H32: =(F32+G32)/2 -> 2.075 | I32: 0.5484 | J32: 0 | K32: 2
A33: 60 | B33: 4.6 | C33: 6.2 | D33: =(B33+C33)/2 -> 5.4 | E33: 0.5418 | F33: 2.6 | G33: 4.6 | H33: =(F33+G33)/2 -> 3.6 | I33: 0.6217 | J33: 22 | K33: 313
A34: 62.5 | B34: 2.25 | C34: 5 | D34: =(B34+C34)/2 -> 3.625 | E34: 0.4765 | F34: 2.3 | G34: 6.2 | H34: =(F34+G34)/2 -> 4.25 | I34: 0.5427 | J34: 0 | K34: 0
A35: 65 | B35: 1.95 | C35: 4.3 | D35: =(B35+C35)/2 -> 3.125 | E35: 0.5469 | F35: 4 | G35: 6.6 | H35: =(F35+G35)/2 -> 5.3 | I35: 0.4867 | J35: 318 | K35: 124
A36: 67.5 | B36: 2 | C36: 2.8 | D36: =(B36+C36)/2 -> 2.4 | E36: 0.5611 | F36: 5.6 | G36: 9.5 | H36: =(F36+G36)/2 -> 7.55 | I36: 0.5628 | J36: 5 | K36: 0
A37: 70 | B37: 1.4 | C37: 2.1 | D37: =(B37+C37)/2 -> 1.75 | E37: 0.5615 | F37: 7.5 | G37: 11.6 | H37: =(F37+G37)/2 -> 9.55 | I37: 0.5837 | J37: 2702 | K37: 353
A39: Legs (premium = mid when the market is tight, else Black-Scholes at the reference IV)
