Workbook

Sheet Main
B2: Eli Lilly and Company
B3: Price | C3: =INDEX([1]Pharma!$F$1:$F$1000,MATCH("LLY",[1]Pharma!$B$1:$B$1000,0)) -> 1286.835
B4: Shares | C4: =941.357065-50 -> 891.35707
B5: Market Cap. | C5: =C3*C4 -> 1147029.5
B7: Cash | C7: =8950+60 -> 9010
B8: Debt | C8: =7050+47858 -> 54908
B9: Enterprise V. | C9: =C5-C7+C8 -> 1192927.5
B11: rNPV / Share | C11: =NPV!C37 -> 734.21433
B12: Upside | C12: =C11/C3-1 -> -0.42944175
B13: Cash / Share | C13: =(C7-C8)/C4 -> -51.492272
B14: Scenario | C14: =Assumptions!$C$4 -> Base

Sheet Yearly Model
B1: 2016 | C1: 2017 | D1: 2018 | E1: 2019 | F1: 2020 | G1: 2021 | H1: 2022 | I1: 2023 | J1: 2024 | K1: 2025 | L1: 2026 | M1: 2027 | N1: 2028 | O1: 2029 | P1: 2030 | Q1: 2031 | R1: 2032 | S1: 2033 | T1: 2034 | U1: 2035 | V1: 2036 | W1: 2037 | X1: 2038 | Y1: 2039 | Z1: 2040
A2: Revenue | B2: 18312.8 | C2: 19973.8 | D2: 21493.3 | E2: 22319.5 | F2: 24539.8 | G2: 28318.4 | H2: 28541.4 | I2: 34124 | J2: 45043 | K2: 65179 | L2: =SUM('Quarterly Model'!F2:I2) -> 87654 | M2: =Pipeline!D30 -> 99646.55 | N2: =Pipeline!E30 -> 112516.47 | O2: =Pipeline!F30 -> 124914.1 | P2: =Pipeline!G30 -> 133158.01 | Q2: =Pipeline!H30 -> 141782.99 | R2: =Pipeline!I30 -> 147294.06 | S2: =Pipeline!J30 -> 151304.09 | T2: =Pipeline!K30 -> 154744.63 | ... Z2: =Pipeline!Q30 -> 111210.79
A3: Cost of Sales | B3: 4160.5 | C3: 4447.7 | D3: 4681.7 | E3: 4721.2 | F3: 5483.3 | G3: 7312.8 | H3: 6629.8 | I3: 7082 | J3: 8418 | K3: 11052 | L3: =SUM('Quarterly Model'!F3:I3) -> 13801.4 | M3: =M2*Assumptions!$B$21 -> 15943.448 | N3: =N2*Assumptions!$B$21 -> 18002.636 | O3: =O2*Assumptions!$B$21 -> 19986.257 | P3: =P2*Assumptions!$B$21 -> 21305.281 | Q3: =Q2*Assumptions!$B$21 -> 22685.278 | R3: =R2*Assumptions!$B$21 -> 23567.049 | S3: =S2*Assumptions!$B$21 -> 24208.654 | T3: =T2*Assumptions!$B$21 -> 24759.14 | ... Z3: =Z2*Assumptions!$B$21 -> 17793.727
A4: Gross Margin | B4: =B2-B3 -> 14152.3 | C4: =C2-C3 -> 15526.1 | D4: =D2-D3 -> 16811.6 | E4: =E2-E3 -> 17598.3 | F4: =F2-F3 -> 19056.5 | G4: =G2-G3 -> 21005.6 | H4: =H2-H3 -> 21911.6 | I4: =I2-I3 -> 27042 | ... Z4: =Z2-Z3 -> 93417.065
A5: Research & Dev. | B5: =5040+30 -> 5070 | C5: =5096.2+1112.6 -> 6208.8 | D5: =5051.2+1983.9 -> 7035.1 | E5: =5595+239.6 -> 5834.6 | F5: =5976.3+769.8 -> 6746.1 | G5: =6930.7+970.1 -> 7900.8 | H5: =7190.8+908.5 -> 8099.3 | I5: =9313+3800 -> 13113 | J5: =10991+3280 -> 14271 | K5: =13337+2910 -> 16247 | L5: =SUM('Quarterly Model'!F5:I5) -> 19689 | M5: =M2*Assumptions!$B$22+M20 -> 19939.914 | N5: =N2*Assumptions!$B$22+N20 -> 22187.8 | O5: =O2*Assumptions!$B$22+O20 -> 24356.598 | P5: =P2*Assumptions!$B$22+P20 -> 25820.485 | Q5: =Q2*Assumptions!$B$22+Q20 -> 27350.405 | R5: =R2*Assumptions!$B$22+R20 -> 28352.232 | S5: =S2*Assumptions!$B$22+S20 -> 29100.182 | T5: =T2*Assumptions!$B$22+T20 -> 29752.644 | ... Z5: =Z2*Assumptions!$B$22+Z20 -> 22786.654
A6: General & Admin | B6: =5841.9+72.9 -> 5914.8 | C6: =5982.4+1331.6 -> 7314 | D6: =5975.1+266.9 -> 6242 | E6: =6213.8+575.6 -> 6789.4 | F6: =6121.2+131.2 -> 6252.4 | G6: =6431.6+316.1 -> 6747.7 | H6: =6440.4+244.6 -> 6685 | I6: =7404+68 -> 7472 | J6: =8594+861 -> 9455 | K6: =11094+484 -> 11578 | L6: =SUM('Quarterly Model'!F6:I6) -> 14546 | M6: =M2*Assumptions!$B$23+M21 -> 14448.75 | N6: =N2*Assumptions!$B$23+N21 -> 16314.889 | O6: =O2*Assumptions!$B$23+O21 -> 18112.545 | P6: =P2*Assumptions!$B$23+P21 -> 19307.911 | Q6: =Q2*Assumptions!$B$23+Q21 -> 20558.534 | R6: =R2*Assumptions!$B$23+R21 -> 21357.638 | S6: =S2*Assumptions!$B$23+S21 -> 21939.093 | T6: =T2*Assumptions!$B$23+T21 -> 22437.971 | ... Z6: =Z2*Assumptions!$B$23+Z21 -> 16125.565
A7: Operating Expense | B7: =SUM(B5:B6) -> 10984.8 | C7: =SUM(C5:C6) -> 13522.8 | D7: =SUM(D5:D6) -> 13277.1 | E7: =SUM(E5:E6) -> 12624 | F7: =SUM(F5:F6) -> 12998.5 | G7: =SUM(G5:G6) -> 14648.5 | H7: =SUM(H5:H6) -> 14784.3 | I7: =SUM(I5:I6) -> 20585 | ... Z7: =SUM(Z5:Z6) -> 38912.219
A8: Operating Income | B8: =B4-B7 -> 3167.5 | C8: =C4-C7 -> 2003.3 | D8: =D4-D7 -> 3534.5 | E8: =E4-E7 -> 4974.3 | F8: =F4-F7 -> 6058 | G8: =G4-G7 -> 6357.1 | H8: =H4-H7 -> 7127.3 | I8: =I4-I7 -> 6457 | ... Z8: =Z4-Z7 -> 54504.846
A9: Interest | B9: 108.8 | C9: 301.5 | D9: 145.6 | E9: 291.6 | F9: 1171.9 | G9: -201.6 | H9: -320.9 | I9: 97 | J9: -219 | K9: -571 | L9: =SUM('Quarterly Model'!F9:I9) -> -296 | M9: =Assumptions!$B$26 -> -1000 | N9: =Assumptions!$B$26 -> -1000 | O9: =Assumptions!$B$26 -> -1000 | P9: =Assumptions!$B$26 -> -1000 | Q9: =Assumptions!$B$26 -> -1000 | R9: =Assumptions!$B$26 -> -1000 | S9: =Assumptions!$B$26 -> -1000 | T9: =Assumptions!$B$26 -> -1000 | ... Z9: =Assumptions!$B$26 -> -1000
A10: Pretax | B10: =B8+B9 -> 3276.3 | C10: =C8+C9 -> 2304.8 | D10: =D8+D9 -> 3680.1 | E10: =E8+E9 -> 5265.9 | F10: =F8+F9 -> 7229.9 | G10: =G8+G9 -> 6155.5 | H10: =H8+H9 -> 6806.4 | I10: =I8+I9 -> 6554 | ... Z10: =Z8+Z9 -> 53504.846
A11: Taxes | B11: 551.4 | C11: 2391.2 | D11: 529.5 | E11: 628 | F11: 1036.2 | G11: 573.8 | H11: 561.6 | I11: 1314 | J11: 2090 | K11: 5091 | L11: =SUM('Quarterly Model'!F11:I11) -> 7532.366 | M11: =M10*Assumptions!$B$16 -> 9179.7434 | N11: =N10*Assumptions!$B$16 -> 10452.118 | O11: =O10*Assumptions!$B$16 -> 11677.154 | P11: =P10*Assumptions!$B$16 -> 12487.623 | Q11: =Q10*Assumptions!$B$16 -> 13335.867 | R11: =R10*Assumptions!$B$16 -> 13873.256 | S11: =S10*Assumptions!$B$16 -> 14260.67 | T11: =T10*Assumptions!$B$16 -> 14591.026 | ... Z11: =Z10*Assumptions!$B$16 -> 10165.921
A12: Net Income | B12: =B10-B11 -> 2724.9 | C12: =C10-C11 -> -86.4 | D12: =D10-D11 -> 3150.6 | E12: =E10-E11 -> 4637.9 | F12: =F10-F11 -> 6193.7 | G12: =G10-G11 -> 5581.7 | H12: =H10-H11 -> 6244.8 | I12: =I10-I11 -> 5240 | ... Z12: =Z10-Z11 -> 43338.925
A13: Earnings per Share | B13: =B12/B14 -> 2.56623 | C13: =C12/C14 -> -0.082127716 | D13: =D12/D14 -> 3.0479747 | E13: =E12/E14 -> 4.956716 | F13: =F12/F14 -> 6.7876164 | G13: =G12/G14 -> 6.1224333 | H13: =H12/H14 -> 6.9032301 | I13: =I12/I14 -> 5.8009521 | ... Z13: =Z12/Z14 -> 52.058468
A14: Shares | B14: 1061.83 | C14: 1052.02 | D14: 1033.67 | E14: 935.68 | F14: 912.5 | G14: 911.68 | H14: 904.62 | I14: 903.3 | J14: 904.1 | K14: 899.3 | L14: =AVERAGE('Quarterly Model'!F14:I14) -> 893.025 | M14: =L14*(1+Assumptions!$B$27) -> 888.55987 | N14: =M14*(1+Assumptions!$B$27) -> 884.11708 | O14: =N14*(1+Assumptions!$B$27) -> 879.69649 | P14: =O14*(1+Assumptions!$B$27) -> 875.29801 | Q14: =P14*(1+Assumptions!$B$27) -> 870.92152 | R14: =Q14*(1+Assumptions!$B$27) -> 866.56691 | S14: =R14*(1+Assumptions!$B$27) -> 862.23408 | T14: =S14*(1+Assumptions!$B$27) -> 857.92291 | ... Z14: =Y14*(1+Assumptions!$B$27) -> 832.5048
A16: Revenue Change | C16: =C2/B2-1 -> 0.090701586 | D16: =D2/C2-1 -> 0.076074658 | E16: =E2/D2-1 -> 0.038439886 | F16: =F2/E2-1 -> 0.099478035 | G16: =G2/F2-1 -> 0.15397844 | H16: =H2/G2-1 -> 0.0078747387 | I16: =I2/H2-1 -> 0.19559657 | J16: =J2/I2-1 -> 0.31998007 | ... Z16: =Z2/Y2-1 -> -0.043802002
A17: Gross Margin | B17: =B4/B2 -> 0.77280918 | C17: =C4/C2 -> 0.77732329 | D17: =D4/D2 -> 0.78217863 | E17: =E4/E2 -> 0.78847196 | F17: =F4/F2 -> 0.77655482 | G17: =G4/G2 -> 0.74176507 | H17: =H4/H2 -> 0.76771287 | I17: =I4/I2 -> 0.79246278 | ... Z17: =Z4/Z2 -> 0.84
A19: Actual / Estimate | B19: A | C19: A | D19: A | E19: A | F19: A | G19: A | H19: A | I19: A | J19: A | K19: A | L19: A+E | M19: E | N19: E | O19: E | P19: E | Q19: E | R19: E | S19: E | T19: E | U19: E | V19: E | W19: E | X19: E | Y19: E | Z19: E
A20: Acquired IPR&D | B20: 30 | C20: 1112.6 | D20: 1983.9 | E20: 239.6 | F20: 769.8 | G20: 970.1 | H20: 908.5 | I20: 3800 | J20: 3280 | K20: 2910 | L20: =SUM('Quarterly Model'!F20:I20) -> 4360 | M20: =Assumptions!$B$24*(1+Assumptions!$B$25)^(M1-2027) -> 3000 | N20: =Assumptions!$B$24*(1+Assumptions!$B$25)^(N1-2027) -> 3060 | O20: =Assumptions!$B$24*(1+Assumptions!$B$25)^(O1-2027) -> 3121.2 | P20: =Assumptions!$B$24*(1+Assumptions!$B$25)^(P1-2027) -> 3183.624 | Q20: =Assumptions!$B$24*(1+Assumptions!$B$25)^(Q1-2027) -> 3247.2965 | R20: =Assumptions!$B$24*(1+Assumptions!$B$25)^(R1-2027) -> 3312.2424 | S20: =Assumptions!$B$24*(1+Assumptions!$B$25)^(S1-2027) -> 3378.4873 | T20: =Assumptions!$B$24*(1+Assumptions!$B$25)^(T1-2027) -> 3446.057 | ... Z20: =Assumptions!$B$24*(1+Assumptions!$B$25)^(Z1-2027) -> 3880.8199
A21: Special Charges | B21: 72.9 | C21: 1331.6 | D21: 266.9 | E21: 575.6 | F21: 131.2 | G21: 316.1 | H21: 244.6 | I21: 68 | J21: 861 | K21: 484 | L21: =SUM('Quarterly Model'!F21:I21) -> 1182 | M21: 0 | N21: 0 | O21: 0 | P21: 0 | Q21: 0 | R21: 0 | S21: 0 | T21: 0 | U21: 0 | V21: 0 | W21: 0 | X21: 0 | Y21: 0 | Z21: 0
A22: Operating Margin | B22: =B8/B2 -> 0.17296645 | C22: =C8/C2 -> 0.10029639 | D22: =D8/D2 -> 0.16444659 | E22: =E8/E2 -> 0.2228679 | F22: =F8/F2 -> 0.24686428 | G22: =G8/G2 -> 0.22448655 | H22: =H8/H2 -> 0.24971795 | I22: =I8/I2 -> 0.18922166 | ... Z22: =Z8/Z2 -> 0.49010393
A23: Depreciation & Amort. | B23: 1496.6 | C23: 1567.3 | D23: 1609 | E23: 1232.6 | F23: 1323.9 | G23: 1547.6 | H23: 1522.5 | I23: 1527 | J23: 1767 | K23: 1997 | L23: =1043+Assumptions!$B$37 -> 2143 | M23: =M2*Assumptions!$B$28 -> 2989.3965 | N23: =N2*Assumptions!$B$28 -> 3375.4942 | O23: =O2*Assumptions!$B$28 -> 3747.4231 | P23: =P2*Assumptions!$B$28 -> 3994.7402 | Q23: =Q2*Assumptions!$B$28 -> 4253.4897 | R23: =R2*Assumptions!$B$28 -> 4418.8217 | S23: =S2*Assumptions!$B$28 -> 4539.1226 | T23: =T2*Assumptions!$B$28 -> 4642.3388 | ... Z23: =Z2*Assumptions!$B$28 -> 3336.3237
A24: Capital Expenditure | I24: 3448 | J24: 5058 | K24: 7841 | L24: =Assumptions!$B$38 -> 11000 | M24: =M2*MAX(Assumptions!$B$31,Assumptions!$B$29-Assumptions!$B$30*(M1-2027)) -> 11957.586 | N24: =N2*MAX(Assumptions!$B$31,Assumptions!$B$29-Assumptions!$B$30*(N1-2027)) -> 11251.647 | O24: =O2*MAX(Assumptions!$B$31,Assumptions!$B$29-Assumptions!$B$30*(O1-2027)) -> 9993.1283 | P24: =P2*MAX(Assumptions!$B$31,Assumptions!$B$29-Assumptions!$B$30*(P1-2027)) -> 7989.4805 | Q24: =Q2*MAX(Assumptions!$B$31,Assumptions!$B$29-Assumptions!$B$30*(Q1-2027)) -> 7089.1495 | R24: =R2*MAX(Assumptions!$B$31,Assumptions!$B$29-Assumptions!$B$30*(R1-2027)) -> 7364.7028 | S24: =S2*MAX(Assumptions!$B$31,Assumptions!$B$29-Assumptions!$B$30*(S1-2027)) -> 7565.2043 | T24: =T2*MAX(Assumptions!$B$31,Assumptions!$B$29-Assumptions!$B$30*(T1-2027)) -> 7737.2313 | ... Z24: =Z2*MAX(Assumptions!$B$31,Assumptions!$B$29-Assumptions!$B$30*(Z1-2027)) -> 5560.5396

Sheet Quarterly Model
B1: Q1 2025 | C1: Q2 2025 | D1: Q3 2025 | E1: Q4 2025 | F1: Q1 2026 | G1: Q2 2026 | H1: Q3 2026 | I1: Q4 2026
A2: Revenue | B2: =SUM(B24:B35) -> 12728 | C2: =SUM(C24:C35) -> 15557 | D2: =SUM(D24:D35) -> 17600.8 | E2: =SUM(E24:E35) -> 19292.2 | F2: =SUM(F24:F35) -> 19800 | G2: =SUM(G24:G35) -> 22974 | H2: =SUM(H24:H35) -> 22170 | I2: =SUM(I24:I35) -> 22710
A3: Cost of Sales | B3: 2225 | C3: 2448 | D3: 3008.3 | E3: =11052-2225-2448-3008.3 -> 3370.7 | F3: 3577 | G3: 3268 | H3: =H2*Assumptions!$B$35 -> 3436.35 | I3: =I2*Assumptions!$B$35 -> 3520.05
A4: Gross Margin | B4: =B2-B3 -> 10503 | C4: =C2-C3 -> 13109 | D4: =D2-D3 -> 14592.5 | E4: =E2-E3 -> 15921.5 | F4: =F2-F3 -> 16223 | G4: =G2-G3 -> 19706 | H4: =H2-H3 -> 18733.65 | I4: =I2-I3 -> 19189.95
A5: Research & Dev. | B5: =2734+1572 -> 4306 | C5: =3336+154 -> 3490 | D5: =3465.7+655.7 -> 4121.4 | E5: =(13337-2734-3336-3465.7)+(2910-1572-154-655.7) -> 4329.6 | F5: =3510+584 -> 4094 | G5: =3819+2776 -> 6595 | H5: =3900+H20 -> 4500 | I5: =4100+I20 -> 4500
A6: General & Admin | B6: =2468+35 -> 2503 | C6: =2753+0 -> 2753 | D6: =2740.7+364.9 -> 3105.6 | E6: =(11094-2468-2753-2740.7)+(484-35-0-364.9) -> 3216.4 | F6: =2934+279 -> 3213 | G6: =3430+703 -> 4133 | H6: =3400+H21 -> 3500 | I6: =3600+I21 -> 3700
A7: Operating Expense | B7: =SUM(B5:B6) -> 6809 | C7: =SUM(C5:C6) -> 6243 | D7: =SUM(D5:D6) -> 7227 | E7: =SUM(E5:E6) -> 7546 | F7: =SUM(F5:F6) -> 7307 | G7: =SUM(G5:G6) -> 10728 | H7: =SUM(H5:H6) -> 8000 | I7: =SUM(I5:I6) -> 8200
A8: Operating Income | B8: =B4-B7 -> 3694 | C8: =C4-C7 -> 6866 | D8: =D4-D7 -> 7365.5 | E8: =E4-E7 -> 8375.5 | F8: =F4-F7 -> 8916 | G8: =G4-G7 -> 8978 | H8: =H4-H7 -> 10733.65 | I8: =I4-I7 -> 10989.95
A9: Interest | B9: -239 | C9: -90 | D9: -133.1 | E9: =-571+239+90+133.1 -> -108.9 | F9: -65 | G9: 269 | H9: -250 | I9: -250
A10: Pretax | B10: =B8+B9 -> 3455 | C10: =C8+C9 -> 6776 | D10: =D8+D9 -> 7232.4 | E10: =E8+E9 -> 8266.6 | F10: =F8+F9 -> 8851 | G10: =G8+G9 -> 9247 | H10: =H8+H9 -> 10483.65 | I10: =I8+I9 -> 10739.95
A11: Taxes | B11: 697 | C11: 1116 | D11: 1649.9 | E11: =5091-697-1116-1649.9 -> 1628.1 | F11: 1454 | G11: 2152 | H11: =H10*Assumptions!$B$36 -> 1939.4753 | I11: =I10*Assumptions!$B$36 -> 1986.8908
A12: Net Income | B12: =B10-B11 -> 2758 | C12: =C10-C11 -> 5660 | D12: =D10-D11 -> 5582.5 | E12: =E10-E11 -> 6638.5 | F12: =F10-F11 -> 7397 | G12: =G10-G11 -> 7095 | H12: =H10-H11 -> 8544.1748 | I12: =I10-I11 -> 8753.0593
A13: Earnings per Share | B13: =B12/B14 -> 3.0624028 | C13: =C12/C14 -> 6.2902867 | D13: =D12/D14 -> 6.2110592 | E13: =E12/E14 -> 7.392539 | F13: =F12/F14 -> 8.2565018 | G13: =G12/G14 -> 7.9389057 | H13: =H12/H14 -> 9.5786712 | I13: =I12/I14 -> 9.8293759
A14: Shares | B14: 900.6 | C14: 899.8 | D14: 898.8 | E14: =899.3*4-900.6-899.8-898.8 -> 898 | F14: 895.9 | G14: 893.7 | H14: 892 | I14: 890.5
A16: Revenue Change | F16: =F2/B2-1 -> 0.55562539 | G16: =G2/C2-1 -> 0.47676287 | H16: =H2/D2-1 -> 0.25960184 | I16: =I2/E2-1 -> 0.17715968
A17: Gross Margin | B17: =B4/B2 -> 0.82518856 | C17: =C4/C2 -> 0.84264318 | D17: =D4/D2 -> 0.82908163 | E17: =E4/E2 -> 0.82528172 | F17: =F4/F2 -> 0.81934343 | G17: =G4/G2 -> 0.85775224 | H17: =H4/H2 -> 0.845 | I17: =I4/I2 -> 0.845
A19: Actual / Estimate | B19: A | C19: A | D19: A | E19: A | F19: A | G19: A | H19: E | I19: E
A20: Acquired IPR&D | B20: 1572 | C20: 154 | D20: 655.7 | E20: =2910-1572-154-655.7 -> 528.3 | F20: 584 | G20: 2776 | H20: 600 | I20: 400
A21: Special Charges | B21: 35 | C21: 0 | D21: 364.9 | E21: =484-35-0-364.9 -> 84.1 | F21: 279 | G21: 703 | H21: 100 | I21: 100
A23: Revenue by Product
A24: Mounjaro | B24: 3842 | C24: 5199 | D24: 6515.1 | E24: =22966-3842-5199-6515.1 -> 7409.9 | F24: 8662 | G24: 9943 | H24: 9900 | I24: 10150
A25: Zepbound | B25: 2312 | C25: 3381 | D25: 3588.1 | E25: =13542-2312-3381-3588.1 -> 4260.9 | F25: 4160 | G25: 4928 | H25: 4850 | I25: 4950
A26: Foundayo | B26: 0 | C26: 0 | D26: 0 | E26: 0 | F26: 0 | G26: 98 | H26: 280 | I26: 480
A27: Jardiance | B27: 1014 | C27: 690 | D27: 959 | E27: =3431-1014-690-959 -> 768 | F27: 1114 | G27: 1232 | H27: 800 | I27: 700
A28: Trulicity | B28: 1095 | C28: 1092 | D28: 1051.8 | E28: =4276-1095-1092-1051.8 -> 1037.2 | F28: 919 | G28: 1219 | H28: 880 | I28: 820
A29: Other cardiometabolic | B29: 945 | C29: 980 | D29: 1063.9 | E29: =4006-945-980-1063.9 -> 1017.1 | F29: 905 | G29: =1031-98 -> 933 | H29: 880 | I29: 880
A30: Verzenio | B30: 1159 | C30: 1489 | D30: 1470.2 | E30: =5723-1159-1489-1470.2 -> 1604.8 | F30: 1302 | G30: 1474 | H30: 1430 | I30: 1450
A31: Other oncology | B31: 789 | C31: 924 | D31: 937.4 | E31: =3653-789-924-937.4 -> 1002.6 | F31: 966 | G31: 1096 | H31: 1100 | I31: 1150
A32: Taltz | B32: 762 | C32: 848 | D32: 901.5 | E32: =3563-762-848-901.5 -> 1051.5 | F32: 732 | G32: 856 | H32: 840 | I32: 870
A33: Other immunology | B33: 326 | C33: 408 | D33: 460.9 | E33: =1684-326-408-460.9 -> 489.1 | F33: 471 | G33: 561 | H33: 570 | I33: 600
A34: Neuroscience | B34: 272 | C34: 344 | D34: 315.7 | E34: =1391-272-344-315.7 -> 459.3 | F34: 382 | G34: 429 | H34: 440 | I34: 460
A35: Other | B35: 212 | C35: 202 | D35: 337.2 | E35: =943-212-202-337.2 -> 191.8 | F35: 187 | G35: 205 | H35: 200 | I35: 200

Sheet Assumptions
A1: LLY — DCF / rNPV assumptions ($mm unless noted)
A4: Scenario (1 = Bear, 2 = Base, 3 = Bull) | B4: 2 | C4: =CHOOSE($B$4,"Bear","Base","Bull") -> Base
A5: Overrides (blank = scenario value)
A6: WACC override
A7: Terminal growth override
A8: Obesity franchise sales multiplier override
A10: Parameter | B10: Active | C10: Bear | D10: Base | E10: Bull
A12: Valuation
A13: Valuation date | B13: =DATE(2026,10,16) -> 46311
A14: WACC | B14: =IF(ISNUMBER($B$6),$B$6,CHOOSE($B$4,C14,D14,E14)) -> 0.075 | C14: 0.085 | D14: 0.075 | E14: 0.0675
A15: Terminal growth (after 2040) | B15: =IF(ISNUMBER($B$7),$B$7,CHOOSE($B$4,C15,D15,E15)) -> 0.02 | C15: 0.015 | D15: 0.02 | E15: 0.025
A16: Tax rate (2027+) | B16: =CHOOSE($B$4,C16,D16,E16) -> 0.19 | C16: 0.21 | D16: 0.19 | E16: 0.17
A17: Acquisitions closed/agreed after 6/30/26 (upfront cash) | B17: =CHOOSE($B$4,C17,D17,E17) -> 5000 | C17: 5000 | D17: 5000 | E17: 5000
A18: Dilutive securities (mm shares) | B18: =CHOOSE($B$4,C18,D18,E18) -> 2.6 | C18: 2.6 | D18: 2.6 | E18: 2.6
A20: Operating model (2027+)
A21: Cost of sales, % of revenue | B21: =CHOOSE($B$4,C21,D21,E21) -> 0.16 | C21: 0.18 | D21: 0.16 | E21: 0.145
A22: R&D excl. acquired IPR&D, % of revenue | B22: =CHOOSE($B$4,C22,D22,E22) -> 0.17 | C22: 0.18 | D22: 0.17 | E22: 0.16
A23: Marketing, selling & admin, % of revenue | B23: =CHOOSE($B$4,C23,D23,E23) -> 0.145 | C23: 0.155 | D23: 0.145 | E23: 0.135
A24: Acquired IPR&D / BD spend, 2027 ($mm) | B24: =CHOOSE($B$4,C24,D24,E24) -> 3000 | C24: 3000 | D24: 3000 | E24: 3000
A25: BD spend growth | B25: =CHOOSE($B$4,C25,D25,E25) -> 0.02 | C25: 0.02 | D25: 0.02 | E25: 0.02
A26: Net interest & other income ($mm/yr) | B26: =CHOOSE($B$4,C26,D26,E26) -> -1000 | C26: -1000 | D26: -1000 | E26: -1000
A27: Diluted share count change per year | B27: =CHOOSE($B$4,C27,D27,E27) -> -0.005 | C27: -0.005 | D27: -0.005 | E27: -0.005
A28: D&A, % of revenue | B28: =CHOOSE($B$4,C28,D28,E28) -> 0.03 | C28: 0.03 | D28: 0.03 | E28: 0.03
A29: Capex, % of revenue (2027) | B29: =CHOOSE($B$4,C29,D29,E29) -> 0.12 | C29: 0.12 | D29: 0.12 | E29: 0.12
A30: Capex % step-down per year | B30: =CHOOSE($B$4,C30,D30,E30) -> 0.02 | C30: 0.02 | D30: 0.02 | E30: 0.02
A31: Capex, long-run % of revenue | B31: =CHOOSE($B$4,C31,D31,E31) -> 0.05 | C31: 0.06 | D31: 0.05 | E31: 0.045
A32: Working capital, % of revenue change | B32: =CHOOSE($B$4,C32,D32,E32) -> 0.15 | C32: 0.15 | D32: 0.15 | E32: 0.15
A34: 2H 2026 estimates
A35: Cost of sales, % of revenue (2H 2026) | B35: =CHOOSE($B$4,C35,D35,E35) -> 0.155 | C35: 0.155 | D35: 0.155 | E35: 0.155
A36: Tax rate (2H 2026) | B36: =CHOOSE($B$4,C36,D36,E36) -> 0.185 | C36: 0.185 | D36: 0.185 | E36: 0.185
A37: D&A, 2H 2026 ($mm) | B37: =CHOOSE($B$4,C37,D37,E37) -> 1100 | C37: 1100 | D37: 1100 | E37: 1100
A38: Capex, full-year 2026 ($mm) | B38: =CHOOSE($B$4,C38,D38,E38) -> 11000 | C38: 11000 | D38: 11000 | E38: 11000
A40: Tirzepatide (Mounjaro + Zepbound)
A41: Mounjaro revenue growth, 2027 | B41: =CHOOSE($B$4,C41,D41,E41) -> 0.14 | C41: 0.09 | D41: 0.14 | E41: 0.18
A42: Mounjaro growth step-down per year | B42: =CHOOSE($B$4,C42,D42,E42) -> 0.04 | C42: 0.04 | D42: 0.04 | E42: 0.04
A43: Zepbound revenue growth, 2027 | B43: =CHOOSE($B$4,C43,D43,E43) -> 0.2 | C43: 0.12 | D43: 0.2 | E43: 0.27
A44: Zepbound growth step-down per year | B44: =CHOOSE($B$4,C44,D44,E44) -> 0.06 | C44: 0.06 | D44: 0.06 | E44: 0.06
A45: Tirzepatide growth floor (mature years) | B45: =CHOOSE($B$4,C45,D45,E45) -> -0.01 | C45: -0.03 | D45: -0.01 | E45: 0.01
A46: Tirzepatide loss of exclusivity (year) | B46: =CHOOSE($B$4,C46,D46,E46) -> 2036 | C46: 2036 | D46: 2036 | E46: 2036
A47: Tirzepatide post-LOE erosion per year | B47: =CHOOSE($B$4,C47,D47,E47) -> 0.3 | C47: 0.4 | D47: 0.3 | E47: 0.2
...

Sheet Pipeline
A1: LLY — revenue build by product ($mm)
A2: Year | C2: 2026 | D2: 2027 | E2: 2028 | F2: 2029 | G2: 2030 | H2: 2031 | I2: 2032 | J2: 2033 | K2: 2034 | L2: 2035 | M2: 2036 | N2: 2037 | O2: 2038 | P2: 2039 | Q2: 2040
A4: Marketed products
A5: Mounjaro | C5: =SUM('Quarterly Model'!F24:I24) -> 38655 | D5: =IF(D$2>Assumptions!$E$66,C5*(1-Assumptions!$F$66),C5*(1+IF(D$2=2027,Assumptions!$B$66,MAX(Assumptions!$D$66,Assumptions!$B$66-Assumptions!$C$66*(D$2-2027))))) -> 44066.7 | E5: =IF(E$2>Assumptions!$E$66,D5*(1-Assumptions!$F$66),D5*(1+IF(E$2=2027,Assumptions!$B$66,MAX(Assumptions!$D$66,Assumptions!$B$66-Assumptions!$C$66*(E$2-2027))))) -> 48473.37 | F5: =IF(F$2>Assumptions!$E$66,E5*(1-Assumptions!$F$66),E5*(1+IF(F$2=2027,Assumptions!$B$66,MAX(Assumptions!$D$66,Assumptions!$B$66-Assumptions!$C$66*(F$2-2027))))) -> 51381.772 | G5: =IF(G$2>Assumptions!$E$66,F5*(1-Assumptions!$F$66),F5*(1+IF(G$2=2027,Assumptions!$B$66,MAX(Assumptions!$D$66,Assumptions!$B$66-Assumptions!$C$66*(G$2-2027))))) -> 52409.408 | H5: =IF(H$2>Assumptions!$E$66,G5*(1-Assumptions!$F$66),G5*(1+IF(H$2=2027,Assumptions!$B$66,MAX(Assumptions!$D$66,Assumptions!$B$66-Assumptions!$C$66*(H$2-2027))))) -> 51885.314 | I5: =IF(I$2>Assumptions!$E$66,H5*(1-Assumptions!$F$66),H5*(1+IF(I$2=2027,Assumptions!$B$66,MAX(Assumptions!$D$66,Assumptions!$B$66-Assumptions!$C$66*(I$2-2027))))) -> 51366.46 | J5: =IF(J$2>Assumptions!$E$66,I5*(1-Assumptions!$F$66),I5*(1+IF(J$2=2027,Assumptions!$B$66,MAX(Assumptions!$D$66,Assumptions!$B$66-Assumptions!$C$66*(J$2-2027))))) -> 50852.796 | K5: =IF(K$2>Assumptions!$E$66,J5*(1-Assumptions!$F$66),J5*(1+IF(K$2=2027,Assumptions!$B$66,MAX(Assumptions!$D$66,Assumptions!$B$66-Assumptions!$C$66*(K$2-2027))))) -> 50344.268 | ... Q5: =IF(Q$2>Assumptions!$E$66,P5*(1-Assumptions!$F$66),P5*(1+IF(Q$2=2027,Assumptions!$B$66,MAX(Assumptions!$D$66,Assumptions!$B$66-Assumptions!$C$66*(Q$2-2027))))) -> 11847.114
A6: Zepbound | C6: =SUM('Quarterly Model'!F25:I25) -> 18888 | D6: =IF(D$2>Assumptions!$E$67,C6*(1-Assumptions!$F$67),C6*(1+IF(D$2=2027,Assumptions!$B$67,MAX(Assumptions!$D$67,Assumptions!$B$67-Assumptions!$C$67*(D$2-2027))))) -> 22665.6 | E6: =IF(E$2>Assumptions!$E$67,D6*(1-Assumptions!$F$67),D6*(1+IF(E$2=2027,Assumptions!$B$67,MAX(Assumptions!$D$67,Assumptions!$B$67-Assumptions!$C$67*(E$2-2027))))) -> 25838.784 | F6: =IF(F$2>Assumptions!$E$67,E6*(1-Assumptions!$F$67),E6*(1+IF(F$2=2027,Assumptions!$B$67,MAX(Assumptions!$D$67,Assumptions!$B$67-Assumptions!$C$67*(F$2-2027))))) -> 27905.887 | G6: =IF(G$2>Assumptions!$E$67,F6*(1-Assumptions!$F$67),F6*(1+IF(G$2=2027,Assumptions!$B$67,MAX(Assumptions!$D$67,Assumptions!$B$67-Assumptions!$C$67*(G$2-2027))))) -> 28464.004 | H6: =IF(H$2>Assumptions!$E$67,G6*(1-Assumptions!$F$67),G6*(1+IF(H$2=2027,Assumptions!$B$67,MAX(Assumptions!$D$67,Assumptions!$B$67-Assumptions!$C$67*(H$2-2027))))) -> 28179.364 | I6: =IF(I$2>Assumptions!$E$67,H6*(1-Assumptions!$F$67),H6*(1+IF(I$2=2027,Assumptions!$B$67,MAX(Assumptions!$D$67,Assumptions!$B$67-Assumptions!$C$67*(I$2-2027))))) -> 27897.571 | J6: =IF(J$2>Assumptions!$E$67,I6*(1-Assumptions!$F$67),I6*(1+IF(J$2=2027,Assumptions!$B$67,MAX(Assumptions!$D$67,Assumptions!$B$67-Assumptions!$C$67*(J$2-2027))))) -> 27618.595 | K6: =IF(K$2>Assumptions!$E$67,J6*(1-Assumptions!$F$67),J6*(1+IF(K$2=2027,Assumptions!$B$67,MAX(Assumptions!$D$67,Assumptions!$B$67-Assumptions!$C$67*(K$2-2027))))) -> 27342.409 | ... Q6: =IF(Q$2>Assumptions!$E$67,P6*(1-Assumptions!$F$67),P6*(1+IF(Q$2=2027,Assumptions!$B$67,MAX(Assumptions!$D$67,Assumptions!$B$67-Assumptions!$C$67*(Q$2-2027))))) -> 6434.2707
A7: Jardiance | C7: =SUM('Quarterly Model'!F27:I27) -> 3846 | D7: =IF(D$2>Assumptions!$E$68,C7*(1-Assumptions!$F$68),C7*(1+IF(D$2=2027,Assumptions!$B$68,MAX(Assumptions!$D$68,Assumptions!$B$68-Assumptions!$C$68*(D$2-2027))))) -> 2692.2 | E7: =IF(E$2>Assumptions!$E$68,D7*(1-Assumptions!$F$68),D7*(1+IF(E$2=2027,Assumptions!$B$68,MAX(Assumptions!$D$68,Assumptions!$B$68-Assumptions!$C$68*(E$2-2027))))) -> 2422.98 | F7: =IF(F$2>Assumptions!$E$68,E7*(1-Assumptions!$F$68),E7*(1+IF(F$2=2027,Assumptions!$B$68,MAX(Assumptions!$D$68,Assumptions!$B$68-Assumptions!$C$68*(F$2-2027))))) -> 2180.682 | G7: =IF(G$2>Assumptions!$E$68,F7*(1-Assumptions!$F$68),F7*(1+IF(G$2=2027,Assumptions!$B$68,MAX(Assumptions!$D$68,Assumptions!$B$68-Assumptions!$C$68*(G$2-2027))))) -> 1090.341 | H7: =IF(H$2>Assumptions!$E$68,G7*(1-Assumptions!$F$68),G7*(1+IF(H$2=2027,Assumptions!$B$68,MAX(Assumptions!$D$68,Assumptions!$B$68-Assumptions!$C$68*(H$2-2027))))) -> 545.1705 | I7: =IF(I$2>Assumptions!$E$68,H7*(1-Assumptions!$F$68),H7*(1+IF(I$2=2027,Assumptions!$B$68,MAX(Assumptions!$D$68,Assumptions!$B$68-Assumptions!$C$68*(I$2-2027))))) -> 272.58525 | J7: =IF(J$2>Assumptions!$E$68,I7*(1-Assumptions!$F$68),I7*(1+IF(J$2=2027,Assumptions!$B$68,MAX(Assumptions!$D$68,Assumptions!$B$68-Assumptions!$C$68*(J$2-2027))))) -> 136.29263 | K7: =IF(K$2>Assumptions!$E$68,J7*(1-Assumptions!$F$68),J7*(1+IF(K$2=2027,Assumptions!$B$68,MAX(Assumptions!$D$68,Assumptions!$B$68-Assumptions!$C$68*(K$2-2027))))) -> 68.146313 | ... Q7: =IF(Q$2>Assumptions!$E$68,P7*(1-Assumptions!$F$68),P7*(1+IF(Q$2=2027,Assumptions!$B$68,MAX(Assumptions!$D$68,Assumptions!$B$68-Assumptions!$C$68*(Q$2-2027))))) -> 1.0647861
A8: Trulicity | C8: =SUM('Quarterly Model'!F28:I28) -> 3838 | D8: =IF(D$2>Assumptions!$E$69,C8*(1-Assumptions!$F$69),C8*(1+IF(D$2=2027,Assumptions!$B$69,MAX(Assumptions!$D$69,Assumptions!$B$69-Assumptions!$C$69*(D$2-2027))))) -> 3070.4 | E8: =IF(E$2>Assumptions!$E$69,D8*(1-Assumptions!$F$69),D8*(1+IF(E$2=2027,Assumptions!$B$69,MAX(Assumptions!$D$69,Assumptions!$B$69-Assumptions!$C$69*(E$2-2027))))) -> 1842.24 | F8: =IF(F$2>Assumptions!$E$69,E8*(1-Assumptions!$F$69),E8*(1+IF(F$2=2027,Assumptions!$B$69,MAX(Assumptions!$D$69,Assumptions!$B$69-Assumptions!$C$69*(F$2-2027))))) -> 1105.344 | G8: =IF(G$2>Assumptions!$E$69,F8*(1-Assumptions!$F$69),F8*(1+IF(G$2=2027,Assumptions!$B$69,MAX(Assumptions!$D$69,Assumptions!$B$69-Assumptions!$C$69*(G$2-2027))))) -> 663.2064 | H8: =IF(H$2>Assumptions!$E$69,G8*(1-Assumptions!$F$69),G8*(1+IF(H$2=2027,Assumptions!$B$69,MAX(Assumptions!$D$69,Assumptions!$B$69-Assumptions!$C$69*(H$2-2027))))) -> 397.92384 | I8: =IF(I$2>Assumptions!$E$69,H8*(1-Assumptions!$F$69),H8*(1+IF(I$2=2027,Assumptions!$B$69,MAX(Assumptions!$D$69,Assumptions!$B$69-Assumptions!$C$69*(I$2-2027))))) -> 238.7543 | J8: =IF(J$2>Assumptions!$E$69,I8*(1-Assumptions!$F$69),I8*(1+IF(J$2=2027,Assumptions!$B$69,MAX(Assumptions!$D$69,Assumptions!$B$69-Assumptions!$C$69*(J$2-2027))))) -> 143.25258 | K8: =IF(K$2>Assumptions!$E$69,J8*(1-Assumptions!$F$69),J8*(1+IF(K$2=2027,Assumptions!$B$69,MAX(Assumptions!$D$69,Assumptions!$B$69-Assumptions!$C$69*(K$2-2027))))) -> 85.951549 | ... Q8: =IF(Q$2>Assumptions!$E$69,P8*(1-Assumptions!$F$69),P8*(1+IF(Q$2=2027,Assumptions!$B$69,MAX(Assumptions!$D$69,Assumptions!$B$69-Assumptions!$C$69*(Q$2-2027))))) -> 4.0101555
A9: Other cardiometabolic | C9: =SUM('Quarterly Model'!F29:I29) -> 3598 | D9: =IF(D$2>Assumptions!$E$70,C9*(1-Assumptions!$F$70),C9*(1+IF(D$2=2027,Assumptions!$B$70,MAX(Assumptions!$D$70,Assumptions!$B$70-Assumptions!$C$70*(D$2-2027))))) -> 3526.04 | E9: =IF(E$2>Assumptions!$E$70,D9*(1-Assumptions!$F$70),D9*(1+IF(E$2=2027,Assumptions!$B$70,MAX(Assumptions!$D$70,Assumptions!$B$70-Assumptions!$C$70*(E$2-2027))))) -> 3455.5192 | F9: =IF(F$2>Assumptions!$E$70,E9*(1-Assumptions!$F$70),E9*(1+IF(F$2=2027,Assumptions!$B$70,MAX(Assumptions!$D$70,Assumptions!$B$70-Assumptions!$C$70*(F$2-2027))))) -> 3386.4088 | G9: =IF(G$2>Assumptions!$E$70,F9*(1-Assumptions!$F$70),F9*(1+IF(G$2=2027,Assumptions!$B$70,MAX(Assumptions!$D$70,Assumptions!$B$70-Assumptions!$C$70*(G$2-2027))))) -> 3318.6806 | H9: =IF(H$2>Assumptions!$E$70,G9*(1-Assumptions!$F$70),G9*(1+IF(H$2=2027,Assumptions!$B$70,MAX(Assumptions!$D$70,Assumptions!$B$70-Assumptions!$C$70*(H$2-2027))))) -> 3252.307 | I9: =IF(I$2>Assumptions!$E$70,H9*(1-Assumptions!$F$70),H9*(1+IF(I$2=2027,Assumptions!$B$70,MAX(Assumptions!$D$70,Assumptions!$B$70-Assumptions!$C$70*(I$2-2027))))) -> 3187.2609 | J9: =IF(J$2>Assumptions!$E$70,I9*(1-Assumptions!$F$70),I9*(1+IF(J$2=2027,Assumptions!$B$70,MAX(Assumptions!$D$70,Assumptions!$B$70-Assumptions!$C$70*(J$2-2027))))) -> 3123.5157 | K9: =IF(K$2>Assumptions!$E$70,J9*(1-Assumptions!$F$70),J9*(1+IF(K$2=2027,Assumptions!$B$70,MAX(Assumptions!$D$70,Assumptions!$B$70-Assumptions!$C$70*(K$2-2027))))) -> 3061.0454 | ... Q9: =IF(Q$2>Assumptions!$E$70,P9*(1-Assumptions!$F$70),P9*(1+IF(Q$2=2027,Assumptions!$B$70,MAX(Assumptions!$D$70,Assumptions!$B$70-Assumptions!$C$70*(Q$2-2027))))) -> 2711.6037
A10: Verzenio | C10: =SUM('Quarterly Model'!F30:I30) -> 5656 | D10: =IF(D$2>Assumptions!$E$71,C10*(1-Assumptions!$F$71),C10*(1+IF(D$2=2027,Assumptions!$B$71,MAX(Assumptions!$D$71,Assumptions!$B$71-Assumptions!$C$71*(D$2-2027))))) -> 5656 | E10: =IF(E$2>Assumptions!$E$71,D10*(1-Assumptions!$F$71),D10*(1+IF(E$2=2027,Assumptions!$B$71,MAX(Assumptions!$D$71,Assumptions!$B$71-Assumptions!$C$71*(E$2-2027))))) -> 5656 | F10: =IF(F$2>Assumptions!$E$71,E10*(1-Assumptions!$F$71),E10*(1+IF(F$2=2027,Assumptions!$B$71,MAX(Assumptions!$D$71,Assumptions!$B$71-Assumptions!$C$71*(F$2-2027))))) -> 5656 | G10: =IF(G$2>Assumptions!$E$71,F10*(1-Assumptions!$F$71),F10*(1+IF(G$2=2027,Assumptions!$B$71,MAX(Assumptions!$D$71,Assumptions!$B$71-Assumptions!$C$71*(G$2-2027))))) -> 5656 | H10: =IF(H$2>Assumptions!$E$71,G10*(1-Assumptions!$F$71),G10*(1+IF(H$2=2027,Assumptions!$B$71,MAX(Assumptions!$D$71,Assumptions!$B$71-Assumptions!$C$71*(H$2-2027))))) -> 5656 | I10: =IF(I$2>Assumptions!$E$71,H10*(1-Assumptions!$F$71),H10*(1+IF(I$2=2027,Assumptions!$B$71,MAX(Assumptions!$D$71,Assumptions!$B$71-Assumptions!$C$71*(I$2-2027))))) -> 3393.6 | J10: =IF(J$2>Assumptions!$E$71,I10*(1-Assumptions!$F$71),I10*(1+IF(J$2=2027,Assumptions!$B$71,MAX(Assumptions!$D$71,Assumptions!$B$71-Assumptions!$C$71*(J$2-2027))))) -> 2036.16 | K10: =IF(K$2>Assumptions!$E$71,J10*(1-Assumptions!$F$71),J10*(1+IF(K$2=2027,Assumptions!$B$71,MAX(Assumptions!$D$71,Assumptions!$B$71-Assumptions!$C$71*(K$2-2027))))) -> 1221.696 | ... Q10: =IF(Q$2>Assumptions!$E$71,P10*(1-Assumptions!$F$71),P10*(1+IF(Q$2=2027,Assumptions!$B$71,MAX(Assumptions!$D$71,Assumptions!$B$71-Assumptions!$C$71*(Q$2-2027))))) -> 56.999449
A11: Other oncology | C11: =SUM('Quarterly Model'!F31:I31) -> 4312 | D11: =IF(D$2>Assumptions!$E$72,C11*(1-Assumptions!$F$72),C11*(1+IF(D$2=2027,Assumptions!$B$72,MAX(Assumptions!$D$72,Assumptions!$B$72-Assumptions!$C$72*(D$2-2027))))) -> 4829.44 | E11: =IF(E$2>Assumptions!$E$72,D11*(1-Assumptions!$F$72),D11*(1+IF(E$2=2027,Assumptions!$B$72,MAX(Assumptions!$D$72,Assumptions!$B$72-Assumptions!$C$72*(E$2-2027))))) -> 5312.384 | F11: =IF(F$2>Assumptions!$E$72,E11*(1-Assumptions!$F$72),E11*(1+IF(F$2=2027,Assumptions!$B$72,MAX(Assumptions!$D$72,Assumptions!$B$72-Assumptions!$C$72*(F$2-2027))))) -> 5737.3747 | G11: =IF(G$2>Assumptions!$E$72,F11*(1-Assumptions!$F$72),F11*(1+IF(G$2=2027,Assumptions!$B$72,MAX(Assumptions!$D$72,Assumptions!$B$72-Assumptions!$C$72*(G$2-2027))))) -> 6081.6172 | H11: =IF(H$2>Assumptions!$E$72,G11*(1-Assumptions!$F$72),G11*(1+IF(H$2=2027,Assumptions!$B$72,MAX(Assumptions!$D$72,Assumptions!$B$72-Assumptions!$C$72*(H$2-2027))))) -> 6324.8819 | I11: =IF(I$2>Assumptions!$E$72,H11*(1-Assumptions!$F$72),H11*(1+IF(I$2=2027,Assumptions!$B$72,MAX(Assumptions!$D$72,Assumptions!$B$72-Assumptions!$C$72*(I$2-2027))))) -> 6451.3795 | J11: =IF(J$2>Assumptions!$E$72,I11*(1-Assumptions!$F$72),I11*(1+IF(J$2=2027,Assumptions!$B$72,MAX(Assumptions!$D$72,Assumptions!$B$72-Assumptions!$C$72*(J$2-2027))))) -> 6580.4071 | K11: =IF(K$2>Assumptions!$E$72,J11*(1-Assumptions!$F$72),J11*(1+IF(K$2=2027,Assumptions!$B$72,MAX(Assumptions!$D$72,Assumptions!$B$72-Assumptions!$C$72*(K$2-2027))))) -> 6712.0153 | ... Q11: =IF(Q$2>Assumptions!$E$72,P11*(1-Assumptions!$F$72),P11*(1+IF(Q$2=2027,Assumptions!$B$72,MAX(Assumptions!$D$72,Assumptions!$B$72-Assumptions!$C$72*(Q$2-2027))))) -> 7558.8193
A12: Taltz | C12: =SUM('Quarterly Model'!F32:I32) -> 3298 | D12: =IF(D$2>Assumptions!$E$73,C12*(1-Assumptions!$F$73),C12*(1+IF(D$2=2027,Assumptions!$B$73,MAX(Assumptions!$D$73,Assumptions!$B$73-Assumptions!$C$73*(D$2-2027))))) -> 3298 | E12: =IF(E$2>Assumptions!$E$73,D12*(1-Assumptions!$F$73),D12*(1+IF(E$2=2027,Assumptions!$B$73,MAX(Assumptions!$D$73,Assumptions!$B$73-Assumptions!$C$73*(E$2-2027))))) -> 3298 | F12: =IF(F$2>Assumptions!$E$73,E12*(1-Assumptions!$F$73),E12*(1+IF(F$2=2027,Assumptions!$B$73,MAX(Assumptions!$D$73,Assumptions!$B$73-Assumptions!$C$73*(F$2-2027))))) -> 3298 | G12: =IF(G$2>Assumptions!$E$73,F12*(1-Assumptions!$F$73),F12*(1+IF(G$2=2027,Assumptions!$B$73,MAX(Assumptions!$D$73,Assumptions!$B$73-Assumptions!$C$73*(G$2-2027))))) -> 2143.7 | H12: =IF(H$2>Assumptions!$E$73,G12*(1-Assumptions!$F$73),G12*(1+IF(H$2=2027,Assumptions!$B$73,MAX(Assumptions!$D$73,Assumptions!$B$73-Assumptions!$C$73*(H$2-2027))))) -> 1393.405 | I12: =IF(I$2>Assumptions!$E$73,H12*(1-Assumptions!$F$73),H12*(1+IF(I$2=2027,Assumptions!$B$73,MAX(Assumptions!$D$73,Assumptions!$B$73-Assumptions!$C$73*(I$2-2027))))) -> 905.71325 | J12: =IF(J$2>Assumptions!$E$73,I12*(1-Assumptions!$F$73),I12*(1+IF(J$2=2027,Assumptions!$B$73,MAX(Assumptions!$D$73,Assumptions!$B$73-Assumptions!$C$73*(J$2-2027))))) -> 588.71361 | K12: =IF(K$2>Assumptions!$E$73,J12*(1-Assumptions!$F$73),J12*(1+IF(K$2=2027,Assumptions!$B$73,MAX(Assumptions!$D$73,Assumptions!$B$73-Assumptions!$C$73*(K$2-2027))))) -> 382.66385 | ... Q12: =IF(Q$2>Assumptions!$E$73,P12*(1-Assumptions!$F$73),P12*(1+IF(Q$2=2027,Assumptions!$B$73,MAX(Assumptions!$D$73,Assumptions!$B$73-Assumptions!$C$73*(Q$2-2027))))) -> 28.860083
A13: Other immunology | C13: =SUM('Quarterly Model'!F33:I33) -> 2202 | D13: =IF(D$2>Assumptions!$E$74,C13*(1-Assumptions!$F$74),C13*(1+IF(D$2=2027,Assumptions!$B$74,MAX(Assumptions!$D$74,Assumptions!$B$74-Assumptions!$C$74*(D$2-2027))))) -> 2598.36 | E13: =IF(E$2>Assumptions!$E$74,D13*(1-Assumptions!$F$74),D13*(1+IF(E$2=2027,Assumptions!$B$74,MAX(Assumptions!$D$74,Assumptions!$B$74-Assumptions!$C$74*(E$2-2027))))) -> 2988.114 | F13: =IF(F$2>Assumptions!$E$74,E13*(1-Assumptions!$F$74),E13*(1+IF(F$2=2027,Assumptions!$B$74,MAX(Assumptions!$D$74,Assumptions!$B$74-Assumptions!$C$74*(F$2-2027))))) -> 3346.6877 | G13: =IF(G$2>Assumptions!$E$74,F13*(1-Assumptions!$F$74),F13*(1+IF(G$2=2027,Assumptions!$B$74,MAX(Assumptions!$D$74,Assumptions!$B$74-Assumptions!$C$74*(G$2-2027))))) -> 3647.8896 | H13: =IF(H$2>Assumptions!$E$74,G13*(1-Assumptions!$F$74),G13*(1+IF(H$2=2027,Assumptions!$B$74,MAX(Assumptions!$D$74,Assumptions!$B$74-Assumptions!$C$74*(H$2-2027))))) -> 3866.7629 | I13: =IF(I$2>Assumptions!$E$74,H13*(1-Assumptions!$F$74),H13*(1+IF(I$2=2027,Assumptions!$B$74,MAX(Assumptions!$D$74,Assumptions!$B$74-Assumptions!$C$74*(I$2-2027))))) -> 3982.7658 | J13: =IF(J$2>Assumptions!$E$74,I13*(1-Assumptions!$F$74),I13*(1+IF(J$2=2027,Assumptions!$B$74,MAX(Assumptions!$D$74,Assumptions!$B$74-Assumptions!$C$74*(J$2-2027))))) -> 4102.2488 | K13: =IF(K$2>Assumptions!$E$74,J13*(1-Assumptions!$F$74),J13*(1+IF(K$2=2027,Assumptions!$B$74,MAX(Assumptions!$D$74,Assumptions!$B$74-Assumptions!$C$74*(K$2-2027))))) -> 4225.3163 | ... Q13: =IF(Q$2>Assumptions!$E$74,P13*(1-Assumptions!$F$74),P13*(1+IF(Q$2=2027,Assumptions!$B$74,MAX(Assumptions!$D$74,Assumptions!$B$74-Assumptions!$C$74*(Q$2-2027))))) -> 5045.2486
A14: Neuroscience | C14: =SUM('Quarterly Model'!F34:I34) -> 1711 | D14: =IF(D$2>Assumptions!$E$75,C14*(1-Assumptions!$F$75),C14*(1+IF(D$2=2027,Assumptions!$B$75,MAX(Assumptions!$D$75,Assumptions!$B$75-Assumptions!$C$75*(D$2-2027))))) -> 1967.65 | E14: =IF(E$2>Assumptions!$E$75,D14*(1-Assumptions!$F$75),D14*(1+IF(E$2=2027,Assumptions!$B$75,MAX(Assumptions!$D$75,Assumptions!$B$75-Assumptions!$C$75*(E$2-2027))))) -> 2223.4445 | F14: =IF(F$2>Assumptions!$E$75,E14*(1-Assumptions!$F$75),E14*(1+IF(F$2=2027,Assumptions!$B$75,MAX(Assumptions!$D$75,Assumptions!$B$75-Assumptions!$C$75*(F$2-2027))))) -> 2468.0234 | G14: =IF(G$2>Assumptions!$E$75,F14*(1-Assumptions!$F$75),F14*(1+IF(G$2=2027,Assumptions!$B$75,MAX(Assumptions!$D$75,Assumptions!$B$75-Assumptions!$C$75*(G$2-2027))))) -> 2690.1455 | H14: =IF(H$2>Assumptions!$E$75,G14*(1-Assumptions!$F$75),G14*(1+IF(H$2=2027,Assumptions!$B$75,MAX(Assumptions!$D$75,Assumptions!$B$75-Assumptions!$C$75*(H$2-2027))))) -> 2878.4557 | I14: =IF(I$2>Assumptions!$E$75,H14*(1-Assumptions!$F$75),H14*(1+IF(I$2=2027,Assumptions!$B$75,MAX(Assumptions!$D$75,Assumptions!$B$75-Assumptions!$C$75*(I$2-2027))))) -> 3022.3785 | J14: =IF(J$2>Assumptions!$E$75,I14*(1-Assumptions!$F$75),I14*(1+IF(J$2=2027,Assumptions!$B$75,MAX(Assumptions!$D$75,Assumptions!$B$75-Assumptions!$C$75*(J$2-2027))))) -> 3113.0498 | K14: =IF(K$2>Assumptions!$E$75,J14*(1-Assumptions!$F$75),J14*(1+IF(K$2=2027,Assumptions!$B$75,MAX(Assumptions!$D$75,Assumptions!$B$75-Assumptions!$C$75*(K$2-2027))))) -> 3175.3108 | ... Q14: =IF(Q$2>Assumptions!$E$75,P14*(1-Assumptions!$F$75),P14*(1+IF(Q$2=2027,Assumptions!$B$75,MAX(Assumptions!$D$75,Assumptions!$B$75-Assumptions!$C$75*(Q$2-2027))))) -> 3575.9157
A15: Other | C15: =SUM('Quarterly Model'!F35:I35) -> 792 | D15: =IF(D$2>Assumptions!$E$76,C15*(1-Assumptions!$F$76),C15*(1+IF(D$2=2027,Assumptions!$B$76,MAX(Assumptions!$D$76,Assumptions!$B$76-Assumptions!$C$76*(D$2-2027))))) -> 776.16 | E15: =IF(E$2>Assumptions!$E$76,D15*(1-Assumptions!$F$76),D15*(1+IF(E$2=2027,Assumptions!$B$76,MAX(Assumptions!$D$76,Assumptions!$B$76-Assumptions!$C$76*(E$2-2027))))) -> 760.6368 | F15: =IF(F$2>Assumptions!$E$76,E15*(1-Assumptions!$F$76),E15*(1+IF(F$2=2027,Assumptions!$B$76,MAX(Assumptions!$D$76,Assumptions!$B$76-Assumptions!$C$76*(F$2-2027))))) -> 745.42406 | G15: =IF(G$2>Assumptions!$E$76,F15*(1-Assumptions!$F$76),F15*(1+IF(G$2=2027,Assumptions!$B$76,MAX(Assumptions!$D$76,Assumptions!$B$76-Assumptions!$C$76*(G$2-2027))))) -> 730.51558 | H15: =IF(H$2>Assumptions!$E$76,G15*(1-Assumptions!$F$76),G15*(1+IF(H$2=2027,Assumptions!$B$76,MAX(Assumptions!$D$76,Assumptions!$B$76-Assumptions!$C$76*(H$2-2027))))) -> 715.90527 | I15: =IF(I$2>Assumptions!$E$76,H15*(1-Assumptions!$F$76),H15*(1+IF(I$2=2027,Assumptions!$B$76,MAX(Assumptions!$D$76,Assumptions!$B$76-Assumptions!$C$76*(I$2-2027))))) -> 701.58717 | J15: =IF(J$2>Assumptions!$E$76,I15*(1-Assumptions!$F$76),I15*(1+IF(J$2=2027,Assumptions!$B$76,MAX(Assumptions!$D$76,Assumptions!$B$76-Assumptions!$C$76*(J$2-2027))))) -> 687.55542 | K15: =IF(K$2>Assumptions!$E$76,J15*(1-Assumptions!$F$76),J15*(1+IF(K$2=2027,Assumptions!$B$76,MAX(Assumptions!$D$76,Assumptions!$B$76-Assumptions!$C$76*(K$2-2027))))) -> 673.80431 | ... Q15: =IF(Q$2>Assumptions!$E$76,P15*(1-Assumptions!$F$76),P15*(1+IF(Q$2=2027,Assumptions!$B$76,MAX(Assumptions!$D$76,Assumptions!$B$76-Assumptions!$C$76*(Q$2-2027))))) -> 596.88442
A16: Marketed products total | C16: =SUM(C5:C15) -> 86796 | D16: =SUM(D5:D15) -> 95146.55 | E16: =SUM(E5:E15) -> 102271.47 | F16: =SUM(F5:F15) -> 107211.6 | G16: =SUM(G5:G15) -> 106895.51 | H16: =SUM(H5:H15) -> 105095.49 | I16: =SUM(I5:I15) -> 101420.06 | J16: =SUM(J5:J15) -> 98982.587 | ... Q16: =SUM(Q5:Q15) -> 37860.791
A18: Launches & late-stage pipeline (risk-adjusted)
A19: Foundayo | C19: =SUM('Quarterly Model'!F26:I26) -> 858 | D19: =IF(D$2>Assumptions!$E$80,C19*(1-Assumptions!$F$80),IF((D$2-Assumptions!$B$80+1)>=1,Assumptions!$D$80*Assumptions!$C$80*INDEX(Assumptions!$B$88:$H$88,MIN((D$2-Assumptions!$B$80+1),7)),0)) -> 4500 | E19: =IF(E$2>Assumptions!$E$80,D19*(1-Assumptions!$F$80),IF((E$2-Assumptions!$B$80+1)>=1,Assumptions!$D$80*Assumptions!$C$80*INDEX(Assumptions!$B$88:$H$88,MIN((E$2-Assumptions!$B$80+1),7)),0)) -> 8100 | F19: =IF(F$2>Assumptions!$E$80,E19*(1-Assumptions!$F$80),IF((F$2-Assumptions!$B$80+1)>=1,Assumptions!$D$80*Assumptions!$C$80*INDEX(Assumptions!$B$88:$H$88,MIN((F$2-Assumptions!$B$80+1),7)),0)) -> 11700 | G19: =IF(G$2>Assumptions!$E$80,F19*(1-Assumptions!$F$80),IF((G$2-Assumptions!$B$80+1)>=1,Assumptions!$D$80*Assumptions!$C$80*INDEX(Assumptions!$B$88:$H$88,MIN((G$2-Assumptions!$B$80+1),7)),0)) -> 14760 | H19: =IF(H$2>Assumptions!$E$80,G19*(1-Assumptions!$F$80),IF((H$2-Assumptions!$B$80+1)>=1,Assumptions!$D$80*Assumptions!$C$80*INDEX(Assumptions!$B$88:$H$88,MIN((H$2-Assumptions!$B$80+1),7)),0)) -> 16740 | I19: =IF(I$2>Assumptions!$E$80,H19*(1-Assumptions!$F$80),IF((I$2-Assumptions!$B$80+1)>=1,Assumptions!$D$80*Assumptions!$C$80*INDEX(Assumptions!$B$88:$H$88,MIN((I$2-Assumptions!$B$80+1),7)),0)) -> 18000 | J19: =IF(J$2>Assumptions!$E$80,I19*(1-Assumptions!$F$80),IF((J$2-Assumptions!$B$80+1)>=1,Assumptions!$D$80*Assumptions!$C$80*INDEX(Assumptions!$B$88:$H$88,MIN((J$2-Assumptions!$B$80+1),7)),0)) -> 18000 | K19: =IF(K$2>Assumptions!$E$80,J19*(1-Assumptions!$F$80),IF((K$2-Assumptions!$B$80+1)>=1,Assumptions!$D$80*Assumptions!$C$80*INDEX(Assumptions!$B$88:$H$88,MIN((K$2-Assumptions!$B$80+1),7)),0)) -> 18000 | ... Q19: =IF(Q$2>Assumptions!$E$80,P19*(1-Assumptions!$F$80),IF((Q$2-Assumptions!$B$80+1)>=1,Assumptions!$D$80*Assumptions!$C$80*INDEX(Assumptions!$B$88:$H$88,MIN((Q$2-Assumptions!$B$80+1),7)),0)) -> 18000
A20: Retatrutide | C20: 0 | D20: =IF(D$2>Assumptions!$E$81,C20*(1-Assumptions!$F$81),IF((D$2-Assumptions!$B$81+1)>=1,Assumptions!$D$81*Assumptions!$C$81*INDEX(Assumptions!$B$88:$H$88,MIN((D$2-Assumptions!$B$81+1),7)),0)) -> 0 | E20: =IF(E$2>Assumptions!$E$81,D20*(1-Assumptions!$F$81),IF((E$2-Assumptions!$B$81+1)>=1,Assumptions!$D$81*Assumptions!$C$81*INDEX(Assumptions!$B$88:$H$88,MIN((E$2-Assumptions!$B$81+1),7)),0)) -> 1980 | F20: =IF(F$2>Assumptions!$E$81,E20*(1-Assumptions!$F$81),IF((F$2-Assumptions!$B$81+1)>=1,Assumptions!$D$81*Assumptions!$C$81*INDEX(Assumptions!$B$88:$H$88,MIN((F$2-Assumptions!$B$81+1),7)),0)) -> 4950 | G20: =IF(G$2>Assumptions!$E$81,F20*(1-Assumptions!$F$81),IF((G$2-Assumptions!$B$81+1)>=1,Assumptions!$D$81*Assumptions!$C$81*INDEX(Assumptions!$B$88:$H$88,MIN((G$2-Assumptions!$B$81+1),7)),0)) -> 8910 | H20: =IF(H$2>Assumptions!$E$81,G20*(1-Assumptions!$F$81),IF((H$2-Assumptions!$B$81+1)>=1,Assumptions!$D$81*Assumptions!$C$81*INDEX(Assumptions!$B$88:$H$88,MIN((H$2-Assumptions!$B$81+1),7)),0)) -> 12870 | I20: =IF(I$2>Assumptions!$E$81,H20*(1-Assumptions!$F$81),IF((I$2-Assumptions!$B$81+1)>=1,Assumptions!$D$81*Assumptions!$C$81*INDEX(Assumptions!$B$88:$H$88,MIN((I$2-Assumptions!$B$81+1),7)),0)) -> 16236 | J20: =IF(J$2>Assumptions!$E$81,I20*(1-Assumptions!$F$81),IF((J$2-Assumptions!$B$81+1)>=1,Assumptions!$D$81*Assumptions!$C$81*INDEX(Assumptions!$B$88:$H$88,MIN((J$2-Assumptions!$B$81+1),7)),0)) -> 18414 | K20: =IF(K$2>Assumptions!$E$81,J20*(1-Assumptions!$F$81),IF((K$2-Assumptions!$B$81+1)>=1,Assumptions!$D$81*Assumptions!$C$81*INDEX(Assumptions!$B$88:$H$88,MIN((K$2-Assumptions!$B$81+1),7)),0)) -> 19800 | ... Q20: =IF(Q$2>Assumptions!$E$81,P20*(1-Assumptions!$F$81),IF((Q$2-Assumptions!$B$81+1)>=1,Assumptions!$D$81*Assumptions!$C$81*INDEX(Assumptions!$B$88:$H$88,MIN((Q$2-Assumptions!$B$81+1),7)),0)) -> 19800
A21: Eloralintide | C21: 0 | D21: =IF(D$2>Assumptions!$E$82,C21*(1-Assumptions!$F$82),IF((D$2-Assumptions!$B$82+1)>=1,Assumptions!$D$82*Assumptions!$C$82*INDEX(Assumptions!$B$88:$H$88,MIN((D$2-Assumptions!$B$82+1),7)),0)) -> 0 | E21: =IF(E$2>Assumptions!$E$82,D21*(1-Assumptions!$F$82),IF((E$2-Assumptions!$B$82+1)>=1,Assumptions!$D$82*Assumptions!$C$82*INDEX(Assumptions!$B$88:$H$88,MIN((E$2-Assumptions!$B$82+1),7)),0)) -> 0 | F21: =IF(F$2>Assumptions!$E$82,E21*(1-Assumptions!$F$82),IF((F$2-Assumptions!$B$82+1)>=1,Assumptions!$D$82*Assumptions!$C$82*INDEX(Assumptions!$B$88:$H$88,MIN((F$2-Assumptions!$B$82+1),7)),0)) -> 440 | G21: =IF(G$2>Assumptions!$E$82,F21*(1-Assumptions!$F$82),IF((G$2-Assumptions!$B$82+1)>=1,Assumptions!$D$82*Assumptions!$C$82*INDEX(Assumptions!$B$88:$H$88,MIN((G$2-Assumptions!$B$82+1),7)),0)) -> 1100 | H21: =IF(H$2>Assumptions!$E$82,G21*(1-Assumptions!$F$82),IF((H$2-Assumptions!$B$82+1)>=1,Assumptions!$D$82*Assumptions!$C$82*INDEX(Assumptions!$B$88:$H$88,MIN((H$2-Assumptions!$B$82+1),7)),0)) -> 1980 | I21: =IF(I$2>Assumptions!$E$82,H21*(1-Assumptions!$F$82),IF((I$2-Assumptions!$B$82+1)>=1,Assumptions!$D$82*Assumptions!$C$82*INDEX(Assumptions!$B$88:$H$88,MIN((I$2-Assumptions!$B$82+1),7)),0)) -> 2860 | J21: =IF(J$2>Assumptions!$E$82,I21*(1-Assumptions!$F$82),IF((J$2-Assumptions!$B$82+1)>=1,Assumptions!$D$82*Assumptions!$C$82*INDEX(Assumptions!$B$88:$H$88,MIN((J$2-Assumptions!$B$82+1),7)),0)) -> 3608 | K21: =IF(K$2>Assumptions!$E$82,J21*(1-Assumptions!$F$82),IF((K$2-Assumptions!$B$82+1)>=1,Assumptions!$D$82*Assumptions!$C$82*INDEX(Assumptions!$B$88:$H$88,MIN((K$2-Assumptions!$B$82+1),7)),0)) -> 4092 | ... Q21: =IF(Q$2>Assumptions!$E$82,P21*(1-Assumptions!$F$82),IF((Q$2-Assumptions!$B$82+1)>=1,Assumptions!$D$82*Assumptions!$C$82*INDEX(Assumptions!$B$88:$H$88,MIN((Q$2-Assumptions!$B$82+1),7)),0)) -> 4400
A22: Lepodisiran | C22: 0 | D22: =IF(D$2>Assumptions!$E$83,C22*(1-Assumptions!$F$83),IF((D$2-Assumptions!$B$83+1)>=1,Assumptions!$D$83*Assumptions!$C$83*INDEX(Assumptions!$B$88:$H$88,MIN((D$2-Assumptions!$B$83+1),7)),0)) -> 0 | E22: =IF(E$2>Assumptions!$E$83,D22*(1-Assumptions!$F$83),IF((E$2-Assumptions!$B$83+1)>=1,Assumptions!$D$83*Assumptions!$C$83*INDEX(Assumptions!$B$88:$H$88,MIN((E$2-Assumptions!$B$83+1),7)),0)) -> 0 | F22: =IF(F$2>Assumptions!$E$83,E22*(1-Assumptions!$F$83),IF((F$2-Assumptions!$B$83+1)>=1,Assumptions!$D$83*Assumptions!$C$83*INDEX(Assumptions!$B$88:$H$88,MIN((F$2-Assumptions!$B$83+1),7)),0)) -> 0 | G22: =IF(G$2>Assumptions!$E$83,F22*(1-Assumptions!$F$83),IF((G$2-Assumptions!$B$83+1)>=1,Assumptions!$D$83*Assumptions!$C$83*INDEX(Assumptions!$B$88:$H$88,MIN((G$2-Assumptions!$B$83+1),7)),0)) -> 250 | H22: =IF(H$2>Assumptions!$E$83,G22*(1-Assumptions!$F$83),IF((H$2-Assumptions!$B$83+1)>=1,Assumptions!$D$83*Assumptions!$C$83*INDEX(Assumptions!$B$88:$H$88,MIN((H$2-Assumptions!$B$83+1),7)),0)) -> 625 | I22: =IF(I$2>Assumptions!$E$83,H22*(1-Assumptions!$F$83),IF((I$2-Assumptions!$B$83+1)>=1,Assumptions!$D$83*Assumptions!$C$83*INDEX(Assumptions!$B$88:$H$88,MIN((I$2-Assumptions!$B$83+1),7)),0)) -> 1125 | J22: =IF(J$2>Assumptions!$E$83,I22*(1-Assumptions!$F$83),IF((J$2-Assumptions!$B$83+1)>=1,Assumptions!$D$83*Assumptions!$C$83*INDEX(Assumptions!$B$88:$H$88,MIN((J$2-Assumptions!$B$83+1),7)),0)) -> 1625 | K22: =IF(K$2>Assumptions!$E$83,J22*(1-Assumptions!$F$83),IF((K$2-Assumptions!$B$83+1)>=1,Assumptions!$D$83*Assumptions!$C$83*INDEX(Assumptions!$B$88:$H$88,MIN((K$2-Assumptions!$B$83+1),7)),0)) -> 2050 | ... Q22: =IF(Q$2>Assumptions!$E$83,P22*(1-Assumptions!$F$83),IF((Q$2-Assumptions!$B$83+1)>=1,Assumptions!$D$83*Assumptions!$C$83*INDEX(Assumptions!$B$88:$H$88,MIN((Q$2-Assumptions!$B$83+1),7)),0)) -> 2500
A23: Olomorasib | C23: 0 | D23: =IF(D$2>Assumptions!$E$84,C23*(1-Assumptions!$F$84),IF((D$2-Assumptions!$B$84+1)>=1,Assumptions!$D$84*Assumptions!$C$84*INDEX(Assumptions!$B$88:$H$88,MIN((D$2-Assumptions!$B$84+1),7)),0)) -> 0 | E23: =IF(E$2>Assumptions!$E$84,D23*(1-Assumptions!$F$84),IF((E$2-Assumptions!$B$84+1)>=1,Assumptions!$D$84*Assumptions!$C$84*INDEX(Assumptions!$B$88:$H$88,MIN((E$2-Assumptions!$B$84+1),7)),0)) -> 165 | F23: =IF(F$2>Assumptions!$E$84,E23*(1-Assumptions!$F$84),IF((F$2-Assumptions!$B$84+1)>=1,Assumptions!$D$84*Assumptions!$C$84*INDEX(Assumptions!$B$88:$H$88,MIN((F$2-Assumptions!$B$84+1),7)),0)) -> 412.5 | G23: =IF(G$2>Assumptions!$E$84,F23*(1-Assumptions!$F$84),IF((G$2-Assumptions!$B$84+1)>=1,Assumptions!$D$84*Assumptions!$C$84*INDEX(Assumptions!$B$88:$H$88,MIN((G$2-Assumptions!$B$84+1),7)),0)) -> 742.5 | H23: =IF(H$2>Assumptions!$E$84,G23*(1-Assumptions!$F$84),IF((H$2-Assumptions!$B$84+1)>=1,Assumptions!$D$84*Assumptions!$C$84*INDEX(Assumptions!$B$88:$H$88,MIN((H$2-Assumptions!$B$84+1),7)),0)) -> 1072.5 | I23: =IF(I$2>Assumptions!$E$84,H23*(1-Assumptions!$F$84),IF((I$2-Assumptions!$B$84+1)>=1,Assumptions!$D$84*Assumptions!$C$84*INDEX(Assumptions!$B$88:$H$88,MIN((I$2-Assumptions!$B$84+1),7)),0)) -> 1353 | J23: =IF(J$2>Assumptions!$E$84,I23*(1-Assumptions!$F$84),IF((J$2-Assumptions!$B$84+1)>=1,Assumptions!$D$84*Assumptions!$C$84*INDEX(Assumptions!$B$88:$H$88,MIN((J$2-Assumptions!$B$84+1),7)),0)) -> 1534.5 | K23: =IF(K$2>Assumptions!$E$84,J23*(1-Assumptions!$F$84),IF((K$2-Assumptions!$B$84+1)>=1,Assumptions!$D$84*Assumptions!$C$84*INDEX(Assumptions!$B$88:$H$88,MIN((K$2-Assumptions!$B$84+1),7)),0)) -> 1650 | ... Q23: =IF(Q$2>Assumptions!$E$84,P23*(1-Assumptions!$F$84),IF((Q$2-Assumptions!$B$84+1)>=1,Assumptions!$D$84*Assumptions!$C$84*INDEX(Assumptions!$B$88:$H$88,MIN((Q$2-Assumptions!$B$84+1),7)),0)) -> 1650
A24: ORX750 | C24: 0 | D24: =IF(D$2>Assumptions!$E$85,C24*(1-Assumptions!$F$85),IF((D$2-Assumptions!$B$85+1)>=1,Assumptions!$D$85*Assumptions!$C$85*INDEX(Assumptions!$B$88:$H$88,MIN((D$2-Assumptions!$B$85+1),7)),0)) -> 0 | E24: =IF(E$2>Assumptions!$E$85,D24*(1-Assumptions!$F$85),IF((E$2-Assumptions!$B$85+1)>=1,Assumptions!$D$85*Assumptions!$C$85*INDEX(Assumptions!$B$88:$H$88,MIN((E$2-Assumptions!$B$85+1),7)),0)) -> 0 | F24: =IF(F$2>Assumptions!$E$85,E24*(1-Assumptions!$F$85),IF((F$2-Assumptions!$B$85+1)>=1,Assumptions!$D$85*Assumptions!$C$85*INDEX(Assumptions!$B$88:$H$88,MIN((F$2-Assumptions!$B$85+1),7)),0)) -> 200 | G24: =IF(G$2>Assumptions!$E$85,F24*(1-Assumptions!$F$85),IF((G$2-Assumptions!$B$85+1)>=1,Assumptions!$D$85*Assumptions!$C$85*INDEX(Assumptions!$B$88:$H$88,MIN((G$2-Assumptions!$B$85+1),7)),0)) -> 500 | H24: =IF(H$2>Assumptions!$E$85,G24*(1-Assumptions!$F$85),IF((H$2-Assumptions!$B$85+1)>=1,Assumptions!$D$85*Assumptions!$C$85*INDEX(Assumptions!$B$88:$H$88,MIN((H$2-Assumptions!$B$85+1),7)),0)) -> 900 | I24: =IF(I$2>Assumptions!$E$85,H24*(1-Assumptions!$F$85),IF((I$2-Assumptions!$B$85+1)>=1,Assumptions!$D$85*Assumptions!$C$85*INDEX(Assumptions!$B$88:$H$88,MIN((I$2-Assumptions!$B$85+1),7)),0)) -> 1300 | J24: =IF(J$2>Assumptions!$E$85,I24*(1-Assumptions!$F$85),IF((J$2-Assumptions!$B$85+1)>=1,Assumptions!$D$85*Assumptions!$C$85*INDEX(Assumptions!$B$88:$H$88,MIN((J$2-Assumptions!$B$85+1),7)),0)) -> 1640 | K24: =IF(K$2>Assumptions!$E$85,J24*(1-Assumptions!$F$85),IF((K$2-Assumptions!$B$85+1)>=1,Assumptions!$D$85*Assumptions!$C$85*INDEX(Assumptions!$B$88:$H$88,MIN((K$2-Assumptions!$B$85+1),7)),0)) -> 1860 | ... Q24: =IF(Q$2>Assumptions!$E$85,P24*(1-Assumptions!$F$85),IF((Q$2-Assumptions!$B$85+1)>=1,Assumptions!$D$85*Assumptions!$C$85*INDEX(Assumptions!$B$88:$H$88,MIN((Q$2-Assumptions!$B$85+1),7)),0)) -> 2000
A25: Launches & pipeline total | C25: =SUM(C19:C24) -> 858 | D25: =SUM(D19:D24) -> 4500 | E25: =SUM(E19:E24) -> 10245 | F25: =SUM(F19:F24) -> 17702.5 | G25: =SUM(G19:G24) -> 26262.5 | H25: =SUM(H19:H24) -> 34187.5 | I25: =SUM(I19:I24) -> 40874 | J25: =SUM(J19:J24) -> 44821.5 | ... Q25: =SUM(Q19:Q24) -> 48350
A27: Obesity franchise adjustment (multiplier) | C27: 0 | D27: =(Assumptions!$B$48-1)*(D5+D6+D19+D20) -> 0 | E27: =(Assumptions!$B$48-1)*(E5+E6+E19+E20) -> 0 | F27: =(Assumptions!$B$48-1)*(F5+F6+F19+F20) -> 0 | G27: =(Assumptions!$B$48-1)*(G5+G6+G19+G20) -> 0 | H27: =(Assumptions!$B$48-1)*(H5+H6+H19+H20) -> 0 | I27: =(Assumptions!$B$48-1)*(I5+I6+I19+I20) -> 0 | J27: =(Assumptions!$B$48-1)*(J5+J6+J19+J20) -> 0 | K27: =(Assumptions!$B$48-1)*(K5+K6+K19+K20) -> 0 | ... Q27: =(Assumptions!$B$48-1)*(Q5+Q6+Q19+Q20) -> 0
A28: New launches (early pipeline & BD, unidentified) | C28: 0 | D28: =Assumptions!$B$62*MAX(0,(D$2-2030)/10) -> 0 | E28: =Assumptions!$B$62*MAX(0,(E$2-2030)/10) -> 0 | F28: =Assumptions!$B$62*MAX(0,(F$2-2030)/10) -> 0 | G28: =Assumptions!$B$62*MAX(0,(G$2-2030)/10) -> 0 | H28: =Assumptions!$B$62*MAX(0,(H$2-2030)/10) -> 2500 | I28: =Assumptions!$B$62*MAX(0,(I$2-2030)/10) -> 5000 | J28: =Assumptions!$B$62*MAX(0,(J$2-2030)/10) -> 7500 | K28: =Assumptions!$B$62*MAX(0,(K$2-2030)/10) -> 10000 | ... Q28: =Assumptions!$B$62*MAX(0,(Q$2-2030)/10) -> 25000
A30: Total revenue | C30: =C16+C25+C27+C28 -> 87654 | D30: =D16+D25+D27+D28 -> 99646.55 | E30: =E16+E25+E27+E28 -> 112516.47 | F30: =F16+F25+F27+F28 -> 124914.1 | G30: =G16+G25+G27+G28 -> 133158.01 | H30: =H16+H25+H27+H28 -> 141782.99 | I30: =I16+I25+I27+I28 -> 147294.06 | J30: =J16+J25+J27+J28 -> 151304.09 | ... Q30: =Q16+Q25+Q27+Q28 -> 111210.79
A32: Memo
A33: Tirzepatide (Mounjaro + Zepbound) | C33: =C5+C6 -> 57543 | D33: =(D5+D6)*Assumptions!$B$48 -> 66732.3 | E33: =(E5+E6)*Assumptions!$B$48 -> 74312.154 | F33: =(F5+F6)*Assumptions!$B$48 -> 79287.659 | G33: =(G5+G6)*Assumptions!$B$48 -> 80873.412 | H33: =(H5+H6)*Assumptions!$B$48 -> 80064.678 | I33: =(I5+I6)*Assumptions!$B$48 -> 79264.031 | J33: =(J5+J6)*Assumptions!$B$48 -> 78471.391 | K33: =(K5+K6)*Assumptions!$B$48 -> 77686.677 | ... Q33: =(Q5+Q6)*Assumptions!$B$48 -> 18281.385
A34: Incretin franchise (tirzepatide + Foundayo + retatrutide) | C34: =C33+C19+C20 -> 58401 | D34: =D33+(D19+D20)*Assumptions!$B$48 -> 71232.3 | E34: =E33+(E19+E20)*Assumptions!$B$48 -> 84392.154 | F34: =F33+(F19+F20)*Assumptions!$B$48 -> 95937.659 | G34: =G33+(G19+G20)*Assumptions!$B$48 -> 104543.41 | H34: =H33+(H19+H20)*Assumptions!$B$48 -> 109674.68 | I34: =I33+(I19+I20)*Assumptions!$B$48 -> 113500.03 | J34: =J33+(J19+J20)*Assumptions!$B$48 -> 114885.39 | K34: =K33+(K19+K20)*Assumptions!$B$48 -> 115486.68 | ... Q34: =Q33+(Q19+Q20)*Assumptions!$B$48 -> 56081.385
A35: Incretin franchise, % of revenue | C35: =C34/C30 -> 0.66626737 | D35: =D34/D30 -> 0.71484964 | E35: =E34/E30 -> 0.75004266 | F35: =F34/F30 -> 0.76802904 | G35: =G34/G30 -> 0.78510796 | H35: =H34/H30 -> 0.77353904 | I35: =I34/I30 -> 0.77056763 | J35: =J34/J30 -> 0.75930131 | ... Q35: =Q34/Q30 -> 0.50428006

Sheet NPV
A1: LLY — DCF with risk-adjusted pipeline ($mm except per share)
A3: Scenario | B3: =Assumptions!$C$4 -> Base
A4: Valuation date | B4: =Assumptions!$B$13 -> 46311
A5: WACC | B5: =Assumptions!$B$14 -> 0.075
A6: Terminal growth | B6: =Assumptions!$B$15 -> 0.02
A8: Period | C8: 2H 2026 | D8: 2027 | E8: 2028 | F8: 2029 | G8: 2030 | H8: 2031 | I8: 2032 | J8: 2033 | K8: 2034 | L8: 2035 | M8: 2036 | N8: 2037 | O8: 2038 | P8: 2039 | Q8: 2040
A9: Revenue | C9: =SUM('Quarterly Model'!H2:I2) -> 44880 | D9: ='Yearly Model'!M2 -> 99646.55 | E9: ='Yearly Model'!N2 -> 112516.47 | F9: ='Yearly Model'!O2 -> 124914.1 | G9: ='Yearly Model'!P2 -> 133158.01 | H9: ='Yearly Model'!Q2 -> 141782.99 | I9: ='Yearly Model'!R2 -> 147294.06 | J9: ='Yearly Model'!S2 -> 151304.09 | K9: ='Yearly Model'!T2 -> 154744.63 | ... Q9: ='Yearly Model'!Z2 -> 111210.79
A10: Operating income (EBIT) | C10: =SUM('Quarterly Model'!H8:I8) -> 21723.6 | D10: ='Yearly Model'!M8 -> 49314.439 | E10: ='Yearly Model'!N8 -> 56011.148 | F10: ='Yearly Model'!O8 -> 62458.704 | G10: ='Yearly Model'!P8 -> 66724.33 | H10: ='Yearly Model'!Q8 -> 71188.773 | I10: ='Yearly Model'!R8 -> 74017.137 | J10: ='Yearly Model'!S8 -> 76056.158 | K10: ='Yearly Model'!T8 -> 77794.872 | ... Q10: ='Yearly Model'!Z8 -> 54504.846
A11: Taxes on EBIT | C11: =C10*Assumptions!$B$36 -> 4018.866 | D11: =D10*Assumptions!$B$16 -> 9369.7434 | E11: =E10*Assumptions!$B$16 -> 10642.118 | F11: =F10*Assumptions!$B$16 -> 11867.154 | G11: =G10*Assumptions!$B$16 -> 12677.623 | H11: =H10*Assumptions!$B$16 -> 13525.867 | I11: =I10*Assumptions!$B$16 -> 14063.256 | J11: =J10*Assumptions!$B$16 -> 14450.67 | K11: =K10*Assumptions!$B$16 -> 14781.026 | ... Q11: =Q10*Assumptions!$B$16 -> 10355.921
A12: NOPAT | C12: =C10-C11 -> 17704.734 | D12: =D10-D11 -> 39944.695 | E12: =E10-E11 -> 45369.03 | F12: =F10-F11 -> 50591.551 | G12: =G10-G11 -> 54046.707 | H12: =H10-H11 -> 57662.906 | I12: =I10-I11 -> 59953.881 | J12: =J10-J11 -> 61605.488 | ... Q12: =Q10-Q11 -> 44148.925
A13: Depreciation & amortization | C13: =Assumptions!$B$37 -> 1100 | D13: ='Yearly Model'!M23 -> 2989.3965 | E13: ='Yearly Model'!N23 -> 3375.4942 | F13: ='Yearly Model'!O23 -> 3747.4231 | G13: ='Yearly Model'!P23 -> 3994.7402 | H13: ='Yearly Model'!Q23 -> 4253.4897 | I13: ='Yearly Model'!R23 -> 4418.8217 | J13: ='Yearly Model'!S23 -> 4539.1226 | K13: ='Yearly Model'!T23 -> 4642.3388 | ... Q13: ='Yearly Model'!Z23 -> 3336.3237
A14: Capital expenditure | C14: =Assumptions!$B$38-5259 -> 5741 | D14: ='Yearly Model'!M24 -> 11957.586 | E14: ='Yearly Model'!N24 -> 11251.647 | F14: ='Yearly Model'!O24 -> 9993.1283 | G14: ='Yearly Model'!P24 -> 7989.4805 | H14: ='Yearly Model'!Q24 -> 7089.1495 | I14: ='Yearly Model'!R24 -> 7364.7028 | J14: ='Yearly Model'!S24 -> 7565.2043 | K14: ='Yearly Model'!T24 -> 7737.2313 | ... Q14: ='Yearly Model'!Z24 -> 5560.5396
A15: Increase in working capital | C15: =Assumptions!$B$32*('Yearly Model'!L2-'Yearly Model'!K2)/2 -> 1685.625 | D15: =Assumptions!$B$32*('Yearly Model'!M2-'Yearly Model'!L2) -> 1798.8825 | E15: =Assumptions!$B$32*('Yearly Model'!N2-'Yearly Model'!M2) -> 1930.4884 | F15: =Assumptions!$B$32*('Yearly Model'!O2-'Yearly Model'!N2) -> 1859.6447 | G15: =Assumptions!$B$32*('Yearly Model'!P2-'Yearly Model'!O2) -> 1236.5857 | H15: =Assumptions!$B$32*('Yearly Model'!Q2-'Yearly Model'!P2) -> 1293.7473 | I15: =Assumptions!$B$32*('Yearly Model'!R2-'Yearly Model'!Q2) -> 826.65986 | J15: =Assumptions!$B$32*('Yearly Model'!S2-'Yearly Model'!R2) -> 601.5046 | K15: =Assumptions!$B$32*('Yearly Model'!T2-'Yearly Model'!S2) -> 516.08102 | ... Q15: =Assumptions!$B$32*('Yearly Model'!Z2-'Yearly Model'!Y2) -> -764.16003
A16: Unlevered free cash flow | C16: =C12+C13-C14-C15 -> 11378.109 | D16: =D12+D13-D14-D15 -> 29177.623 | E16: =E12+E13-E14-E15 -> 35562.388 | F16: =F12+F13-F14-F15 -> 42486.201 | G16: =G12+G13-G14-G15 -> 48815.382 | H16: =H12+H13-H14-H15 -> 53533.499 | I16: =I12+I13-I14-I15 -> 56181.34 | J16: =J12+J13-J14-J15 -> 57977.902 | ... Q16: =Q12+Q13-Q14-Q15 -> 42688.869
A17: Cash-flow date (mid-period) | C17: =DATE(2026,10,1) -> 46296 | D17: =DATE(D8,7,1) -> 46569 | E17: =DATE(E8,7,1) -> 46935 | F17: =DATE(F8,7,1) -> 47300 | G17: =DATE(G8,7,1) -> 47665 | H17: =DATE(H8,7,1) -> 48030 | I17: =DATE(I8,7,1) -> 48396 | J17: =DATE(J8,7,1) -> 48761 | K17: =DATE(K8,7,1) -> 49126 | ... Q17: =DATE(Q8,7,1) -> 51318
A18: Years from valuation date | C18: =MAX(0,(C17-$B$4)/365.25) -> 0 | D18: =MAX(0,(D17-$B$4)/365.25) -> 0.7063655 | E18: =MAX(0,(E17-$B$4)/365.25) -> 1.7084189 | F18: =MAX(0,(F17-$B$4)/365.25) -> 2.7077344 | G18: =MAX(0,(G17-$B$4)/365.25) -> 3.70705 | H18: =MAX(0,(H17-$B$4)/365.25) -> 4.7063655 | I18: =MAX(0,(I17-$B$4)/365.25) -> 5.7084189 | J18: =MAX(0,(J17-$B$4)/365.25) -> 6.7077344 | ... Q18: =MAX(0,(Q17-$B$4)/365.25) -> 13.708419
A19: Discount factor | C19: =1/(1+$B$5)^C18 -> 1 | D19: =1/(1+$B$5)^D18 -> 0.95019807 | E19: =1/(1+$B$5)^E18 -> 0.88377393 | F19: =1/(1+$B$5)^F18 -> 0.82215598 | G19: =1/(1+$B$5)^G18 -> 0.76483412 | H19: =1/(1+$B$5)^H18 -> 0.71150882 | I19: =1/(1+$B$5)^I18 -> 0.66177039 | J19: =1/(1+$B$5)^J18 -> 0.61563083 | ... Q19: =1/(1+$B$5)^Q18 -> 0.37105613
A20: PV of free cash flow | C20: =C16*C19 -> 11378.109 | D20: =D16*D19 -> 27724.521 | E20: =E16*E19 -> 31429.112 | F20: =F16*F19 -> 34930.284 | G20: =G16*G19 -> 37335.669 | H20: =H16*H19 -> 38089.557 | I20: =I16*I19 -> 37179.147 | J20: =J16*J19 -> 35692.984 | ... Q20: =Q16*Q19 -> 15839.967
A22: Terminal value
A23: Terminal free cash flow (2041) | C23: =(Q10*(1-Assumptions!$B$16)+Q13-Q14-Assumptions!$B$32*$B$6*Q9)*(1+$B$6) -> 42422.898
A24: Terminal value at end-2040 | C24: =C23/($B$5-$B$6) -> 771325.42
A25: Years from valuation date to end-2040 | C25: =(DATE(2040,12,31)-$B$4)/365.25 -> 14.209446
A26: PV of terminal value | C26: =C24/(1+$B$5)^C25 -> 276020.15
A28: Valuation summary
A29: PV of free cash flows, 2H 2026–2040 | C29: =SUM(C20:Q20) -> 431233.94
A30: PV of terminal value | C30: =C26 -> 276020.15
A31: Enterprise value | C31: =C29+C30 -> 707254.09
A32: Less: debt (6/30/2026) | C32: =Main!C8 -> 54908
A33: Plus: cash & short-term investments (6/30/2026) | C33: =Main!C7 -> 9010
A34: Less: acquisitions after 6/30/2026 | C34: =Assumptions!$B$17 -> 5000
A35: Equity value | C35: =C31-C32+C33-C34 -> 656356.09
A36: Diluted shares (mm) | C36: =Main!C4+Assumptions!$B$18 -> 893.95707
A37: Value per share | C37: =C35/C36 -> 734.21433
A38: Current price (Main) | C38: =Main!C3 -> 1286.835
A39: Upside / (downside) | C39: =C37/C38-1 -> -0.42944175
A40: Terminal value, % of enterprise value | C40: =C30/C31 -> 0.39027013
A41: Price / 2027E EPS | C41: =C38/'Yearly Model'!M13 -> 29.217806
A42: Market-implied enterprise value | C42: =C38*C36+C32-C33+C34 -> 1201273.2

Sheet Options
A1: LLY — options strategy analysis (per contract = 100 shares)
A3: Inputs
A4: Spot price (close 10/16/2026) | B4: 1257.03
A5: Pricing date | B5: =DATE(2026,10,16) -> 46311
A6: Expiry | B6: =DATE(2027,1,15) -> 46402
A7: Years to expiry (T) | B7: =(B6-B5)/365 -> 0.24931507
A8: Risk-free rate (put-call parity) | B8: 0.046
A9: Dividend yield | B9: =4*1.73/B4 -> 0.0055050397
A10: Contract multiplier | B10: 100
A12: Model link
