Workbook

Sheet Main
B2: Neurocrine Biosciences, Inc.
B3: Price | C3: =INDEX([1]Pharma!$F$1:$F$1000,MATCH("NBIX",[1]Pharma!$B$1:$B$1000,0)) -> 142
B4: Shares | C4: 101.64918
B5: Market Cap. | C5: =C3*C4 -> 14434.184
B7: Cash | C7: =332.4+57.4 -> 389.8
B8: Debt | C8: 0
B9: Enterprise V. | C9: =C5-C7+C8 -> 14044.384
B11: NPV / Share | C11: =NPV!B28 -> 166.52692
B12: Upside | C12: =IFERROR(C11/C3-1,"") -> 0.1727248
B13: Cash / Share | C13: =IFERROR((C7-C8)/C4,"") -> 3.8347579
B14: Scenario | C14: =Assumptions!C4 -> Base
B15: Model | C15: Reviewed DCF

Sheet Yearly Model
B1: 2009 | C1: 2010 | D1: 2011 | E1: 2012 | F1: 2013 | G1: 2014 | H1: 2015 | I1: 2016 | J1: 2017 | K1: 2018 | L1: 2019 | M1: 2020 | N1: 2021 | O1: 2022 | P1: 2023 | Q1: 2024 | R1: 2025 | S1: 2026 | T1: 2027 | U1: 2028 | V1: 2029 | W1: 2030 | X1: 2031 | Y1: 2032 | Z1: 2033 | AA1: 2034 | AB1: 2035
A2: Revenue | B2: 2.953 | C2: 33.501 | D2: 77.413 | E2: 53.14 | F2: 2.919 | G2: 0 | H2: 19.769 | I2: 15 | J2: 161.626 | K2: 451.2 | L2: 788.1 | M2: 1045.9 | N2: 1133.5 | O2: 1488.7 | P2: 1887.1 | Q2: 2355.3 | R2: 2860.5 | S2: =R2*(1+NPV!C5) -> 3861.675 | T2: =S2*(1+NPV!D5) -> 4440.9262 | U2: =T2*(1+NPV!E5) -> 4796.2004 | V2: =U2*(1+NPV!F5) -> 4892.1244 | W2: =V2*(1+NPV!G5) -> 5038.8881 | X2: =W2*(1+NPV!H5) -> 5240.4436 | Y2: =X2*(1+NPV!I5) -> 5450.0614 | Z2: =Y2*(1+NPV!J5) -> 5613.5632 | ... AB2: =AA2*(1+NPV!L5) -> 5926.5193
A3: Cost of Sales | B3: 0 | C3: 0 | D3: 0 | E3: 0 | F3: 0 | G3: 0 | H3: 0 | I3: 0 | J3: 1.254 | K3: 4.889 | L3: 0 | M3: 10.1 | N3: 14.3 | O3: 23.2 | P3: 39.7 | Q3: 34 | R3: 52.1 | S3: =S2*(1-Assumptions!$B$19) -> 70.282485 | T3: =T2*(1-Assumptions!$B$19) -> 80.824858 | U3: =U2*(1-Assumptions!$B$19) -> 87.290846 | V3: =V2*(1-Assumptions!$B$19) -> 89.036663 | W3: =W2*(1-Assumptions!$B$19) -> 91.707763 | X3: =X2*(1-Assumptions!$B$19) -> 95.376074 | Y3: =Y2*(1-Assumptions!$B$19) -> 99.191117 | Z3: =Z2*(1-Assumptions!$B$19) -> 102.16685 | ... AB3: =AB2*(1-Assumptions!$B$19) -> 107.86265
A4: Gross Margin | B4: =B2-B3 -> 2.953 | C4: =C2-C3 -> 33.501 | D4: =D2-D3 -> 77.413 | E4: =E2-E3 -> 53.14 | F4: =F2-F3 -> 2.919 | G4: =G2-G3 -> 0 | H4: =H2-H3 -> 19.769 | I4: =I2-I3 -> 15 | ... AB4: =AB2-AB3 -> 5818.6567
A5: Research & Dev. | B5: 33.722 | C5: 31.151 | D5: 30.951 | E5: 37.163 | F5: 39.248 | G5: 46.425 | H5: 81.491 | I5: 94.291 | J5: 121.827 | K5: 160.524 | L5: 0 | M5: 275 | N5: 328.1 | O5: 463.8 | P5: 565 | Q5: 731.1 | R5: 1015.7 | S5: =S7*Assumptions!$B$20 -> 1314.5521 | T5: =T7*Assumptions!$B$20 -> 1495.2537 | U5: =U7*Assumptions!$B$20 -> 1597.0744 | V5: =V7*Assumptions!$B$20 -> 1610.8602 | W5: =W7*Assumptions!$B$20 -> 1640.4857 | X5: =X7*Assumptions!$B$20 -> 1686.6568 | Y5: =Y7*Assumptions!$B$20 -> 1733.8968 | Z5: =Z7*Assumptions!$B$20 -> 1765.0806 | ... AB5: =AB7*Assumptions!$B$20 -> 1819.4949
A6: SG&A & Other | B6: 22.901 | C6: 16.072 | D6: 12.54 | E6: 14.529 | F6: 13.349 | G6: 17.986 | H6: 32.48 | I6: 68.081 | J6: 169.906 | K6: 248.987 | L6: 715.8 | M6: 597.8 | N6: 688.6 | O6: 752.7 | P6: 1031.5 | Q6: 1019.7 | R6: 1173.6 | S6: =S7-S5 -> 1519.145 | T6: =T7-T5 -> 1727.9705 | U6: =U7-U5 -> 1845.6382 | V6: =V7-V5 -> 1861.5697 | W6: =W7-W5 -> 1895.806 | X6: =X7-X5 -> 1949.163 | Y6: =Y7-Y5 -> 2003.7553 | Z6: =Z7-Z5 -> 2039.7925 | ... AB6: =AB7-AB5 -> 2102.6756
A7: Operating Expense | B7: =SUM(B5:B6) -> 56.623 | C7: =SUM(C5:C6) -> 47.223 | D7: =SUM(D5:D6) -> 43.491 | E7: =SUM(E5:E6) -> 51.692 | F7: =SUM(F5:F6) -> 52.597 | G7: =SUM(G5:G6) -> 64.411 | H7: =SUM(H5:H6) -> 113.971 | I7: =SUM(I5:I6) -> 162.372 | ... R7: =SUM(R5:R6) -> 2189.3 | S7: =S4-S2*NPV!C6 -> 2833.6971 | T7: =T4-T2*NPV!D6 -> 3223.2243 | U7: =U4-U2*NPV!E6 -> 3442.7126 | V7: =V4-V2*NPV!F6 -> 3472.4299 | W7: =W4-W2*NPV!G6 -> 3536.2917 | X7: =X4-X2*NPV!H6 -> 3635.8198 | Y7: =Y4-Y2*NPV!I6 -> 3737.6521 | Z7: =Z4-Z2*NPV!J6 -> 3804.8731 | ... AB7: =AB4-AB2*NPV!L6 -> 3922.1705
A8: Operating Income | B8: =B4-B7 -> -53.67 | C8: =C4-C7 -> -13.722 | D8: =D4-D7 -> 33.922 | E8: =E4-E7 -> 1.448 | F8: =F4-F7 -> -49.678 | G8: =G4-G7 -> -64.411 | H8: =H4-H7 -> -94.202 | I8: =I4-I7 -> -147.372 | ... AB8: =AB4-AB7 -> 1896.4862
A9: Interest & Other | B9: 2.632 | C9: 5.754 | D9: 3.649 | E9: 3.577 | F9: 3.588 | G9: 3.869 | H9: 5.273 | I9: 6.282 | J9: -11.181 | K9: -15 | L9: -25.8 | M9: -56.3 | N9: -1.1 | O9: -35.1 | P9: 81.2 | Q9: -84.5 | R9: 86.3 | S9: 0 | T9: 0 | U9: 0 | V9: 0 | W9: 0 | X9: 0 | Y9: 0 | Z9: 0 | AA9: 0 | AB9: 0
A10: Pretax | B10: =B8+B9 -> -51.038 | C10: =C8+C9 -> -7.968 | D10: =D8+D9 -> 37.571 | E10: =E8+E9 -> 5.025 | F10: =F8+F9 -> -46.09 | G10: =G8+G9 -> -60.542 | H10: =H8+H9 -> -88.929 | I10: =I8+I9 -> -141.09 | ... AB10: =AB8+AB9 -> 1896.4862
A11: Taxes | B11: 0 | C11: 0 | D11: 0 | E11: 0 | F11: 0 | G11: 0 | H11: 0 | I11: 0 | J11: 0 | K11: 0.7 | L11: 9.5 | M11: -300.6 | N11: 11.8 | O11: 59.4 | P11: 82.4 | Q11: 144.7 | R11: 226.8 | S11: =MAX(0,S10)*Assumptions!$E$14 -> 162.80822 | T11: =MAX(0,T10)*Assumptions!$E$14 -> 193.26911 | U11: =MAX(0,U10)*Assumptions!$E$14 -> 215.25347 | V11: =MAX(0,V10)*Assumptions!$E$14 -> 226.21183 | W11: =MAX(0,W10)*Assumptions!$E$14 -> 239.85107 | X11: =MAX(0,X10)*Assumptions!$E$14 -> 256.57212 | Y11: =MAX(0,Y10)*Assumptions!$E$14 -> 274.24709 | Z11: =MAX(0,Z10)*Assumptions!$E$14 -> 290.10895 | ... AB11: =MAX(0,AB10)*Assumptions!$E$14 -> 322.40265
A12: Net Income | B12: -51.038 | C12: -7.968 | D12: 37.571 | E12: 5.025 | F12: -46.09 | G12: -60.542 | H12: -88.929 | I12: -141.09 | J12: -142.542 | K12: 21.1 | L12: 37 | M12: 407.3 | N12: 89.6 | O12: 154.5 | P12: 249.7 | Q12: 341.3 | R12: 478.6 | S12: =S10-S11 -> 794.88718 | T12: =T10-T11 -> 943.60801 | U12: =U10-U11 -> 1050.9434 | V12: =V10-V11 -> 1104.446 | W12: =W10-W11 -> 1171.0376 | X12: =X10-X11 -> 1252.6756 | Y12: =Y10-Y11 -> 1338.9711 | Z12: =Z10-Z11 -> 1416.4143 | ... AB12: =AB10-AB11 -> 1574.0835
A13: Earnings per Share | B13: =IFERROR(B12/B14,0) -> -1.3040856 | C13: =IFERROR(C12/C14,0) -> -0.15085195 | D13: =IFERROR(D12/D14,0) -> 0.66677907 | E13: =IFERROR(E12/E14,0) -> 0.075060497 | F13: =IFERROR(F12/F14,0) -> -0.68802341 | G13: =IFERROR(G12/G14,0) -> -0.81180525 | H13: =IFERROR(H12/H14,0) -> -1.052464 | I13: =IFERROR(I12/I14,0) -> -1.6270917 | ... AB13: =IFERROR(AB12/AB14,0) -> 15.485452
A14: Shares | B14: 39.137 | C14: 52.82 | D14: 56.347 | E14: 66.946 | F14: 66.989 | G14: 74.577 | H14: 84.496 | I14: 86.713 | J14: 88.089 | K14: 95.4 | L14: 95.7 | M14: 97.8 | N14: 97.9 | O14: 98.9 | P14: 101 | Q14: 103.7 | R14: 102.5 | S14: =Main!$C$4 -> 101.64918 | T14: =Main!$C$4 -> 101.64918 | U14: =Main!$C$4 -> 101.64918 | V14: =Main!$C$4 -> 101.64918 | W14: =Main!$C$4 -> 101.64918 | X14: =Main!$C$4 -> 101.64918 | Y14: =Main!$C$4 -> 101.64918 | Z14: =Main!$C$4 -> 101.64918 | ... AB14: =Main!$C$4 -> 101.64918
A16: Revenue Change | C16: =IFERROR(C2/B2-1,"") -> 10.344734 | D16: =IFERROR(D2/C2-1,"") -> 1.3107668 | E16: =IFERROR(E2/D2-1,"") -> -0.31355199 | F16: =IFERROR(F2/E2-1,"") -> -0.94506963 | G16: =IFERROR(G2/F2-1,"") -> -1 | H16: =IFERROR(H2/G2-1,"") | I16: =IFERROR(I2/H2-1,"") -> -0.24123628 | J16: =IFERROR(J2/I2-1,"") -> 9.7750667 | ... AB16: =IFERROR(AB2/AA2-1,"") -> 0.025
A17: Gross Margin | B17: =IFERROR(B4/B2,"") -> 1 | C17: =IFERROR(C4/C2,"") -> 1 | D17: =IFERROR(D4/D2,"") -> 1 | E17: =IFERROR(E4/E2,"") -> 1 | F17: =IFERROR(F4/F2,"") -> 1 | G17: =IFERROR(G4/G2,"") | H17: =IFERROR(H4/H2,"") -> 1 | I17: =IFERROR(I4/I2,"") -> 1 | ... AB17: =IFERROR(AB4/AB2,"") -> 0.9818
A18: Operating Margin | B18: =IFERROR(B8/B2,"") -> -18.174738 | C18: =IFERROR(C8/C2,"") -> -0.40959971 | D18: =IFERROR(D8/D2,"") -> 0.43819514 | E18: =IFERROR(E8/E2,"") -> 0.027248777 | F18: =IFERROR(F8/F2,"") -> -17.018842 | G18: =IFERROR(G8/G2,"") | H18: =IFERROR(H8/H2,"") -> -4.7651373 | I18: =IFERROR(I8/I2,"") -> -9.8248 | ... AB18: =IFERROR(AB8/AB2,"") -> 0.32
A19: Actual / Estimate | B19: A | C19: A | D19: A | E19: A | F19: A | G19: A | H19: A | I19: A | J19: A | K19: A | L19: A | M19: A | N19: A | O19: A | P19: A | Q19: A | R19: A | S19: E | T19: E | U19: E | V19: E | W19: E | X19: E | Y19: E | Z19: E | AA19: E | AB19: E

Sheet Quarterly Model

Sheet Assumptions
A1: Neurocrine Biosciences, Inc.: basic DCF assumptions
A2: Blue = input, black = formula, green = link. $mm unless noted.
A4: Scenario (1 Bear, 2 Base, 3 Bull) | B4: 2 | C4: =CHOOSE($B$4,"Bear","Base","Bull") -> Base
A6: Discount rate override (blank = scenario)
A7: Terminal growth override (blank = scenario)
A9: Parameter | B9: Bear | C9: Base | D9: Bull | E9: Live
A10: Discount rate | B10: 0.105 | C10: 0.095 | D10: 0.085 | E10: =IF(ISNUMBER($B$6),$B$6,CHOOSE($B$4,B10,C10,D10)) -> 0.095
A11: Terminal growth | B11: 0.02 | C11: 0.025 | D11: 0.03 | E11: =IF(ISNUMBER($B$7),$B$7,CHOOSE($B$4,B11,C11,D11)) -> 0.025
A12: Revenue growth, first forecast year | B12: 0.3 | C12: 0.35 | D12: 0.4 | E12: =CHOOSE($B$4,B12,C12,D12) -> 0.35
A13: Operating margin, year 10 | B13: 0.26 | C13: 0.32 | D13: 0.38 | E13: =CHOOSE($B$4,B13,C13,D13) -> 0.32
A14: Tax rate on operating income | B14: 0.17 | C14: 0.17 | D14: 0.17 | E14: =CHOOSE($B$4,B14,C14,D14) -> 0.17
A15: Reinvestment, % of revenue increase | B15: 0.25 | C15: 0.25 | D15: 0.25 | E15: =CHOOSE($B$4,B15,C15,D15) -> 0.25
A17: Single inputs
A18: Starting operating margin (TTM) | B18: 0.24
A19: Gross margin (forecast) | B19: 0.9818
A20: R&D share of operating expense (forecast) | B20: 0.4639
A21: Forecast years | B21: 10
A22: First forecast year, fraction after balance sheet date | B22: 0.5041
A23: Balance sheet date | B23: 46203
A24: Reporting currency per USD (USD) | B24: 1
A25: Base revenue, FY2025 | B25: ='Yearly Model'!R2 -> 2860.5
A27: Scenario summary
A28: Scenario | B28: Enterprise value | C28: Equity value | D28: NPV / share | E28: Upside
A29: Live | B29: =NPV!B23 -> 16537.525 | C29: =NPV!B26 -> 16927.325 | D29: =NPV!B28 -> 166.52692 | E29: =NPV!B30 -> 0.1727248
A30: 1 | B30: 9798.7977 | C30: 10188.598 | D30: 100.23295 | E30: -0.29413412
A31: 2 | B31: 16537.525 | C31: 16927.325 | D31: 166.52692 | E31: 0.1727248
A32: 3 | B32: 29235.372 | C32: 29625.172 | D32: 291.44526 | E32: 1.0524314
A35: NPV / share: discount rate (rows) x terminal growth (columns)
A36: =NPV!B28 -> 166.52692 | B36: 0.015 | C36: 0.02 | D36: 0.025 | E36: 0.03 | F36: 0.035
A37: 0.075 | B37: 209.30415 | C37: 221.15582 | D37: 235.37783 | E37: 252.76028 | F37: 274.48835
A38: 0.085 | B38: 178.0694 | C38: 185.94561 | D38: 195.13453 | E38: 205.99416 | F38: 219.02571
A39: 0.095 | B39: 154.78993 | C39: 160.26719 | D39: 166.52692 | E39: 173.74968 | F39: 182.17624
A40: 0.105 | B40: 136.80082 | C40: 140.74343 | D40: 145.17886 | E40: 150.20568 | F40: 155.95062
A41: 0.115 | B41: 122.50448 | C41: 125.42049 | D41: 128.6605 | E41: 132.28168 | F41: 136.35552
A44: Reviewed revenue growth by year (base case; blank = fade formula)
A45: Fiscal year | B45: 2026 | C45: 2027 | D45: 2028 | E45: 2029 | F45: 2030 | G45: 2031 | H45: 2032 | I45: 2033 | J45: 2034 | K45: 2035
A46: Growth (bear/bull shift by the row-12 gap, fading to 0 by year 10) | B46: 0.35 | C46: 0.15 | D46: 0.08 | E46: 0.02 | F46: 0.03 | G46: 0.04 | H46: 0.04 | I46: 0.03 | J46: 0.03 | K46: 0.025

Sheet NPV
A1: Neurocrine Biosciences, Inc.: free-cash-flow DCF ($mm)
A3: Fiscal year | B3: ='Yearly Model'!R1 -> 2025 | C3: ='Yearly Model'!S1 -> 2026 | D3: ='Yearly Model'!T1 -> 2027 | E3: ='Yearly Model'!U1 -> 2028 | F3: ='Yearly Model'!V1 -> 2029 | G3: ='Yearly Model'!W1 -> 2030 | H3: ='Yearly Model'!X1 -> 2031 | I3: ='Yearly Model'!Y1 -> 2032 | ... L3: ='Yearly Model'!AB1 -> 2035
A4: Period | B4: Actual | C4: 1 | D4: 2 | E4: 3 | F4: 4 | G4: 5 | H4: 6 | I4: 7 | J4: 8 | K4: 9 | L4: 10
A5: Revenue growth | C5: =IF(ISNUMBER(Assumptions!B$46),Assumptions!B$46+(Assumptions!$E$12-Assumptions!$C$12)*(Assumptions!$B$21-C4)/(Assumptions!$B$21-1),Assumptions!$E$12+(Assumptions!$E$11-Assumptions!$E$12)*(C4-1)/(Assumptions!$B$21-1)) -> 0.35 | D5: =IF(ISNUMBER(Assumptions!C$46),Assumptions!C$46+(Assumptions!$E$12-Assumptions!$C$12)*(Assumptions!$B$21-D4)/(Assumptions!$B$21-1),Assumptions!$E$12+(Assumptions!$E$11-Assumptions!$E$12)*(D4-1)/(Assumptions!$B$21-1)) -> 0.15 | E5: =IF(ISNUMBER(Assumptions!D$46),Assumptions!D$46+(Assumptions!$E$12-Assumptions!$C$12)*(Assumptions!$B$21-E4)/(Assumptions!$B$21-1),Assumptions!$E$12+(Assumptions!$E$11-Assumptions!$E$12)*(E4-1)/(Assumptions!$B$21-1)) -> 0.08 | F5: =IF(ISNUMBER(Assumptions!E$46),Assumptions!E$46+(Assumptions!$E$12-Assumptions!$C$12)*(Assumptions!$B$21-F4)/(Assumptions!$B$21-1),Assumptions!$E$12+(Assumptions!$E$11-Assumptions!$E$12)*(F4-1)/(Assumptions!$B$21-1)) -> 0.02 | G5: =IF(ISNUMBER(Assumptions!F$46),Assumptions!F$46+(Assumptions!$E$12-Assumptions!$C$12)*(Assumptions!$B$21-G4)/(Assumptions!$B$21-1),Assumptions!$E$12+(Assumptions!$E$11-Assumptions!$E$12)*(G4-1)/(Assumptions!$B$21-1)) -> 0.03 | H5: =IF(ISNUMBER(Assumptions!G$46),Assumptions!G$46+(Assumptions!$E$12-Assumptions!$C$12)*(Assumptions!$B$21-H4)/(Assumptions!$B$21-1),Assumptions!$E$12+(Assumptions!$E$11-Assumptions!$E$12)*(H4-1)/(Assumptions!$B$21-1)) -> 0.04 | I5: =IF(ISNUMBER(Assumptions!H$46),Assumptions!H$46+(Assumptions!$E$12-Assumptions!$C$12)*(Assumptions!$B$21-I4)/(Assumptions!$B$21-1),Assumptions!$E$12+(Assumptions!$E$11-Assumptions!$E$12)*(I4-1)/(Assumptions!$B$21-1)) -> 0.04 | J5: =IF(ISNUMBER(Assumptions!I$46),Assumptions!I$46+(Assumptions!$E$12-Assumptions!$C$12)*(Assumptions!$B$21-J4)/(Assumptions!$B$21-1),Assumptions!$E$12+(Assumptions!$E$11-Assumptions!$E$12)*(J4-1)/(Assumptions!$B$21-1)) -> 0.03 | ... L5: =IF(ISNUMBER(Assumptions!K$46),Assumptions!K$46+(Assumptions!$E$12-Assumptions!$C$12)*(Assumptions!$B$21-L4)/(Assumptions!$B$21-1),Assumptions!$E$12+(Assumptions!$E$11-Assumptions!$E$12)*(L4-1)/(Assumptions!$B$21-1)) -> 0.025
A6: Operating margin | B6: =IFERROR(B8/B7,0) -> 0.21643069 | C6: =Assumptions!$B$18+(Assumptions!$E$13-Assumptions!$B$18)*C4/Assumptions!$B$21 -> 0.248 | D6: =Assumptions!$B$18+(Assumptions!$E$13-Assumptions!$B$18)*D4/Assumptions!$B$21 -> 0.256 | E6: =Assumptions!$B$18+(Assumptions!$E$13-Assumptions!$B$18)*E4/Assumptions!$B$21 -> 0.264 | F6: =Assumptions!$B$18+(Assumptions!$E$13-Assumptions!$B$18)*F4/Assumptions!$B$21 -> 0.272 | G6: =Assumptions!$B$18+(Assumptions!$E$13-Assumptions!$B$18)*G4/Assumptions!$B$21 -> 0.28 | H6: =Assumptions!$B$18+(Assumptions!$E$13-Assumptions!$B$18)*H4/Assumptions!$B$21 -> 0.288 | I6: =Assumptions!$B$18+(Assumptions!$E$13-Assumptions!$B$18)*I4/Assumptions!$B$21 -> 0.296 | J6: =Assumptions!$B$18+(Assumptions!$E$13-Assumptions!$B$18)*J4/Assumptions!$B$21 -> 0.304 | ... L6: =Assumptions!$B$18+(Assumptions!$E$13-Assumptions!$B$18)*L4/Assumptions!$B$21 -> 0.32
A7: Revenue | B7: ='Yearly Model'!R2 -> 2860.5 | C7: ='Yearly Model'!S2 -> 3861.675 | D7: ='Yearly Model'!T2 -> 4440.9262 | E7: ='Yearly Model'!U2 -> 4796.2004 | F7: ='Yearly Model'!V2 -> 4892.1244 | G7: ='Yearly Model'!W2 -> 5038.8881 | H7: ='Yearly Model'!X2 -> 5240.4436 | I7: ='Yearly Model'!Y2 -> 5450.0614 | ... L7: ='Yearly Model'!AB2 -> 5926.5193
A8: Operating income | B8: ='Yearly Model'!R8 -> 619.1 | C8: ='Yearly Model'!S8 -> 957.6954 | D8: ='Yearly Model'!T8 -> 1136.8771 | E8: ='Yearly Model'!U8 -> 1266.1969 | F8: ='Yearly Model'!V8 -> 1330.6578 | G8: ='Yearly Model'!W8 -> 1410.8887 | H8: ='Yearly Model'!X8 -> 1509.2478 | I8: ='Yearly Model'!Y8 -> 1613.2182 | ... L8: ='Yearly Model'!AB8 -> 1896.4862
A9: Tax on operating income | C9: =MAX(0,C8)*Assumptions!$E$14 -> 162.80822 | D9: =MAX(0,D8)*Assumptions!$E$14 -> 193.26911 | E9: =MAX(0,E8)*Assumptions!$E$14 -> 215.25347 | F9: =MAX(0,F8)*Assumptions!$E$14 -> 226.21183 | G9: =MAX(0,G8)*Assumptions!$E$14 -> 239.85107 | H9: =MAX(0,H8)*Assumptions!$E$14 -> 256.57212 | I9: =MAX(0,I8)*Assumptions!$E$14 -> 274.24709 | J9: =MAX(0,J8)*Assumptions!$E$14 -> 290.10895 | ... L9: =MAX(0,L8)*Assumptions!$E$14 -> 322.40265
A10: NOPAT | C10: =C8-C9 -> 794.88718 | D10: =D8-D9 -> 943.60801 | E10: =E8-E9 -> 1050.9434 | F10: =F8-F9 -> 1104.446 | G10: =G8-G9 -> 1171.0376 | H10: =H8-H9 -> 1252.6756 | I10: =I8-I9 -> 1338.9711 | J10: =J8-J9 -> 1416.4143 | ... L10: =L8-L9 -> 1574.0835
A11: Reinvestment | C11: =(C7-B7)*Assumptions!$E$15 -> 250.29375 | D11: =(D7-C7)*Assumptions!$E$15 -> 144.81281 | E11: =(E7-D7)*Assumptions!$E$15 -> 88.818525 | F11: =(F7-E7)*Assumptions!$E$15 -> 23.981002 | G11: =(G7-F7)*Assumptions!$E$15 -> 36.690933 | H11: =(H7-G7)*Assumptions!$E$15 -> 50.388881 | I11: =(I7-H7)*Assumptions!$E$15 -> 52.404436 | J11: =(J7-I7)*Assumptions!$E$15 -> 40.87546 | ... L11: =(L7-K7)*Assumptions!$E$15 -> 36.137313
A12: Free cash flow | C12: =C10-C11 -> 544.59343 | D12: =D10-D11 -> 798.7952 | E12: =E10-E11 -> 962.1249 | F12: =F10-F11 -> 1080.465 | G12: =G10-G11 -> 1134.3467 | H12: =H10-H11 -> 1202.2868 | I12: =I10-I11 -> 1286.5666 | J12: =J10-J11 -> 1375.5388 | ... L12: =L10-L11 -> 1537.9462
A13: Year fraction | C13: =Assumptions!$B$22 -> 0.5041 | D13: 1 | E13: 1 | F13: 1 | G13: 1 | H13: 1 | I13: 1 | J13: 1 | K13: 1 | L13: 1
A14: Discount time (mid-period) | C14: =C13/2 -> 0.25205 | D14: =C14+C13/2+D13/2 -> 1.0041 | E14: =D14+D13/2+E13/2 -> 2.0041 | F14: =E14+E13/2+F13/2 -> 3.0041 | G14: =F14+F13/2+G13/2 -> 4.0041 | H14: =G14+G13/2+H13/2 -> 5.0041 | I14: =H14+H13/2+I13/2 -> 6.0041 | J14: =I14+I13/2+J13/2 -> 7.0041 | K14: =J14+J13/2+K13/2 -> 8.0041 | L14: =K14+K13/2+L13/2 -> 9.0041
A15: Discount factor | C15: =1/(1+Assumptions!$E$10)^C14 -> 0.977385 | D15: =1/(1+Assumptions!$E$10)^D14 -> 0.91290226 | E15: =1/(1+Assumptions!$E$10)^E14 -> 0.8337007 | F15: =1/(1+Assumptions!$E$10)^F14 -> 0.7613705 | G15: =1/(1+Assumptions!$E$10)^G14 -> 0.69531552 | H15: =1/(1+Assumptions!$E$10)^H14 -> 0.63499135 | I15: =1/(1+Assumptions!$E$10)^I14 -> 0.57990077 | J15: =1/(1+Assumptions!$E$10)^J14 -> 0.52958975 | ... L15: =1/(1+Assumptions!$E$10)^L14 -> 0.44168366
A16: PV of free cash flow | C16: =C12*C13*C15 -> 268.32106 | D16: =D12*D13*D15 -> 729.22194 | E16: =E12*E13*E15 -> 802.12419 | F16: =F12*F13*F15 -> 822.63417 | G16: =G12*G13*G15 -> 788.72884 | H16: =H12*H13*H15 -> 763.44169 | I16: =I12*I13*I15 -> 746.08099 | J16: =J12*J13*J15 -> 728.47125 | ... L16: =L12*L13*L15 -> 679.28571
A19: PV of forecast free cash flow | B19: =SUM(C16:L16) -> 7032.1067
A20: Terminal free cash flow (year 11) | B20: =L10*(1+Assumptions!$E$11)-L7*Assumptions!$E$11*Assumptions!$E$15 -> 1576.3949
A21: Terminal value | B21: =B20/(Assumptions!$E$10-Assumptions!$E$11) -> 22519.927
A22: PV of terminal value | B22: =B21/(1+Assumptions!$E$10)^(L14+0.5) -> 9505.4186
A23: Enterprise value | B23: =B19+B22 -> 16537.525
A24: Cash & investments | B24: =Main!C7 -> 389.8
A25: Debt | B25: =Main!C8 -> 0
A26: Equity value | B26: =B23+B24-B25 -> 16927.325
A27: Shares (mm) | B27: =Main!C4 -> 101.64918
A28: NPV / share | B28: =B26/B27 -> 166.52692
A29: Price | B29: =Main!C3 -> 142
A30: Upside | B30: =B28/B29-1 -> 0.1727248
A31: Terminal value, % of EV | B31: =IFERROR(B22/B23,0) -> 0.57477878

Sheet Options
A1: NBIX: options vs. the reviewed DCF (per contract = 100 shares)
A2: Market prices are Cboe delayed quotes; blue = input. Probabilities are risk-neutral (lognormal at ATM IV).
A3: Inputs
A4: Spot (close 2026-10-20) | B4: 142
A5: Pricing date | B5: 46315
A6: Near expiry | B6: 46402
A7: Long expiry | B7: 46738
A8: Years to near expiry | B8: =(B6-B5)/365 -> 0.23835616
A9: Years to long expiry | B9: =(B7-B5)/365 -> 1.1589041
A10: Risk-free rate | B10: 0.04
A11: Dividend yield | B11: 0
A12: ATM implied volatility, near | B12: 0.3611
A13: ATM implied volatility, long | B13: 0.494
A14: Contract multiplier | B14: 100
A16: Market expectations, near expiry
A17: ATM strike | B17: 140
A18: ATM call (mid) | B18: 11.5
A19: ATM put (theo) | B19: 8.2819
A20: Straddle, % of spot (expected move) | B20: =(B18+B19)/B4 -> 0.13930915
A21: Expected range, low | B21: =B4*(1-B20) -> 122.2181
A22: Expected range, high | B22: =B4*(1+B20) -> 161.7819
A23: 1-SD move by long expiry (ATM IV) | B23: =B13*SQRT(B9) -> 0.5318029
A25: Model vs. market at the long expiry
A26: Case | B26: Value / share | C26: vs. spot | D26: Annual return needed | E26: Market P(above)
A27: Forward price at long expiry | B27: =B4*EXP((B10-B11)*B9) -> 148.73753
A28: Bear | B28: =Assumptions!D30 -> 100.23295 | C28: =B28/$B$4-1 -> -0.29413412 | D28: =IF(B28>0,(B28/$B$4)^(1/$B$9)-1,"") -> -0.25960279 | E28: =IF(B28>0,NORMSDIST((LN($B$27/B28)-$B$13^2*$B$9/2)/($B$13*SQRT($B$9))),1) -> 0.68305716
A29: Base (reviewed) | B29: =Assumptions!D31 -> 166.52692 | C29: =B29/$B$4-1 -> 0.1727248 | D29: =IF(B29>0,(B29/$B$4)^(1/$B$9)-1,"") -> 0.14738252 | E29: =IF(B29>0,NORMSDIST((LN($B$27/B29)-$B$13^2*$B$9/2)/($B$13*SQRT($B$9))),1) -> 0.31620523
A30: Bull | B30: =Assumptions!D32 -> 291.44526 | C30: =B30/$B$4-1 -> 1.0524314 | D30: =IF(B30>0,(B30/$B$4)^(1/$B$9)-1,"") -> 0.85973763 | E30: =IF(B30>0,NORMSDIST((LN($B$27/B30)-$B$13^2*$B$9/2)/($B$13*SQRT($B$9))),1) -> 0.06291121
A32: Chain, 2027-12-17 expiry
A33: Strike | B33: Call bid | C33: Call ask | D33: Call IV | E33: Put bid | F33: Put ask | G33: Put IV | H33: Call OI | I33: Put OI
A34: 100 | B34: 55 | C34: 60 | D34: 0.5181 | E34: 6.5 | F34: 11.5 | G34: 0.5307 | H34: 25 | I34: 5
A35: 125 | B35: 40 | C35: 45 | D35: 0.5031 | E35: 15 | F35: 20 | G35: 0.5032 | H35: 43 | I35: 21
A36: 130 | B36: 37.5 | C36: 42.2 | D36: 0.4995 | E36: 17.5 | F36: 22.5 | G36: 0.5057 | H36: 41 | I36: 25
A37: 135 | B37: 35 | C37: 39.7 | D37: 0.4965 | E37: 19.5 | F37: 24.5 | G37: 0.4963 | H37: 2 | I37: 3
A38: 140 | B38: 32.5 | C38: 37.5 | D38: 0.4941 | E38: 22 | F38: 27 | G38: 0.4938 | H38: 35 | I38: 12
A39: 145 | B39: 30 | C39: 35 | D39: 0.487 | E39: 24.5 | F39: 29.5 | G39: 0.489 | H39: 44 | I39: 38
A40: 150 | B40: 28 | C40: 33 | D40: 0.4866 | E40: 27 | F40: 32 | G40: 0.4822 | H40: 5023 | I40: 1
A41: 155 | B41: 26 | C41: 31 | D41: 0.4844 | E41: 30.5 | F41: 35 | G41: 0.4858 | H41: 50 | I41: 2
A42: 160 | B42: 24 | C42: 29 | D42: 0.4803 | E42: 33.5 | F42: 38 | G42: 0.4831 | H42: 363 | I42: 19
A43: 165 | B43: 22.5 | C43: 27.5 | D43: 0.4831 | E43: 36.5 | F43: 41 | G43: 0.4784 | H43: 14 | I43: 4
...
