Workbook

Sheet Main
B2: Pfizer Inc.
B3: Price | C3: =INDEX([1]Pharma!$F$1:$F$1000,MATCH("PFE",[1]Pharma!$B$1:$B$1000,0)) -> 30.13
B4: Shares | C4: 5699.6736
B5: Market Cap. | C5: =C3*C4 -> 171731.17
B7: Cash | C7: =976+7281 -> 8257
B8: Debt | C8: =2699+60495 -> 63194
B9: Enterprise V. | C9: =C5-C7+C8 -> 226668.17
B11: NPV / Share | C11: =NPV!B28 -> 27.862901
B12: Upside | C12: =IFERROR(C11/C3-1,"") -> -0.075243906
B13: Cash / Share | C13: =IFERROR((C7-C8)/C4,"") -> -9.6386221
B14: Scenario | C14: =Assumptions!C4 -> Base
B15: Model | C15: Reviewed DCF

Sheet Yearly Model
B1: 2007 | C1: 2008 | D1: 2009 | E1: 2010 | F1: 2011 | G1: 2012 | H1: 2013 | I1: 2014 | J1: 2015 | K1: 2016 | L1: 2017 | M1: 2018 | N1: 2019 | O1: 2020 | P1: 2021 | Q1: 2022 | R1: 2023 | S1: 2024 | T1: 2025 | U1: 2026 | V1: 2027 | W1: 2028 | X1: 2029 | Y1: 2030 | Z1: 2031 | AA1: 2032 | AB1: 2033 | AC1: 2034 | AD1: 2035
A2: Revenue | B2: 48418 | C2: 48296 | D2: 49269 | E2: 65165 | F2: 61035 | G2: 54657 | H2: 51584 | I2: 49605 | J2: 48851 | K2: 52824 | L2: 52546 | M2: 40825 | N2: 40905 | O2: 41651 | P2: 81288 | Q2: 101175 | R2: 59553 | S2: 63627 | T2: 62579 | U2: =T2*(1+NPV!C5) -> 61515.157 | V2: =U2*(1+NPV!D5) -> 59054.551 | W2: =V2*(1+NPV!E5) -> 53739.641 | X2: =W2*(1+NPV!F5) -> 52127.452 | Y2: =X2*(1+NPV!G5) -> 53170.001 | Z2: =Y2*(1+NPV!H5) -> 55296.801 | AA2: =Z2*(1+NPV!I5) -> 57508.673 | AB2: =AA2*(1+NPV!J5) -> 59233.933 | ... AD2: =AC2*(1+NPV!L5) -> 62536.225
A3: Cost of Sales | B3: 11239 | C3: 8112 | D3: 8459 | E3: 14788 | F3: 12500 | G3: 9821 | H3: 9586 | I3: 9577 | J3: 9648 | K3: 12329 | L3: 11240 | M3: 8987 | N3: 8054 | O3: 8484 | P3: 30821 | Q3: 34344 | R3: 24954 | S3: 17851 | T3: 16067 | U3: =U2*(1-Assumptions!$B$19) -> 15790.941 | V3: =V2*(1-Assumptions!$B$19) -> 15159.303 | W3: =W2*(1-Assumptions!$B$19) -> 13794.966 | X3: =X2*(1-Assumptions!$B$19) -> 13381.117 | Y3: =Y2*(1-Assumptions!$B$19) -> 13648.739 | Z3: =Z2*(1-Assumptions!$B$19) -> 14194.689 | AA3: =AA2*(1-Assumptions!$B$19) -> 14762.476 | AB3: =AB2*(1-Assumptions!$B$19) -> 15205.351 | ... AD3: =AD2*(1-Assumptions!$B$19) -> 16053.049
A4: Gross Margin | B4: =B2-B3 -> 37179 | C4: =C2-C3 -> 40184 | D4: =D2-D3 -> 40810 | E4: =E2-E3 -> 50377 | F4: =F2-F3 -> 48535 | G4: =G2-G3 -> 44836 | H4: =H2-H3 -> 41998 | I4: =I2-I3 -> 40028 | ... AD4: =AD2-AD3 -> 46483.176
A5: Research & Dev. | B5: 8089 | C5: 7945 | D5: 7824 | E5: 9483 | F5: 8681 | G5: 7482 | H5: 6678 | I5: 8393 | J5: 7690 | K5: 7892 | L5: 7683 | M5: 7760 | N5: 8385 | O5: 8709 | P5: 10360 | Q5: 11428 | R5: 10679 | S5: 10822 | T5: 10437 | U5: =U7*Assumptions!$B$20 -> 10828.069 | V5: =V7*Assumptions!$B$20 -> 10605.801 | W5: =W7*Assumptions!$B$20 -> 9843.1563 | X5: =X7*Assumptions!$B$20 -> 9733.9828 | Y5: =Y7*Assumptions!$B$20 -> 10118.506 | Z5: =Z7*Assumptions!$B$20 -> 10720.684 | AA5: =AA7*Assumptions!$B$20 -> 11354.846 | AB5: =AB7*Assumptions!$B$20 -> 11906.986 | ... AD5: =AD7*Assumptions!$B$20 -> 13017.372
A6: SG&A & Other | B6: 15626 | C6: 14537 | D6: 14752 | E6: 18973 | F6: 17581 | G6: 15171 | H6: 14355 | I6: 14097 | J6: 14809 | K6: 14844 | L6: 14804 | M6: 12612 | N6: 12726 | O6: 11597 | P6: 12703 | Q6: 13677 | R6: 14771 | S6: 14730 | T6: 13794 | U6: =U7-U5 -> 14312.56 | V6: =V7-V5 -> 14018.766 | W6: =W7-W5 -> 13010.701 | X6: =X7-X5 -> 12866.395 | Y6: =Y7-Y5 -> 13374.659 | Z6: =Z7-Z5 -> 14170.618 | AA6: =AA7-AA5 -> 15008.855 | AB6: =AB7-AB5 -> 15738.675 | ... AD6: =AD7-AD5 -> 17206.385
A7: Operating Expense | B7: =SUM(B5:B6) -> 23715 | C7: =SUM(C5:C6) -> 22482 | D7: =SUM(D5:D6) -> 22576 | E7: =SUM(E5:E6) -> 28456 | F7: =SUM(F5:F6) -> 26262 | G7: =SUM(G5:G6) -> 22653 | H7: =SUM(H5:H6) -> 21033 | I7: =SUM(I5:I6) -> 22490 | ... T7: =SUM(T5:T6) -> 24231 | U7: =U4-U2*NPV!C6 -> 25140.63 | V7: =V4-V2*NPV!D6 -> 24624.567 | W7: =W4-W2*NPV!E6 -> 22853.857 | X7: =X4-X2*NPV!F6 -> 22600.378 | Y7: =Y4-Y2*NPV!G6 -> 23493.165 | Z7: =Z4-Z2*NPV!H6 -> 24891.302 | AA7: =AA4-AA2*NPV!I6 -> 26363.701 | AB7: =AB4-AB2*NPV!J6 -> 27645.661 | ... AD7: =AD4-AD2*NPV!L6 -> 30223.758
A8: Operating Income | B8: =B4-B7 -> 13464 | C8: =C4-C7 -> 17702 | D8: =D4-D7 -> 18234 | E8: =E4-E7 -> 21921 | F8: =F4-F7 -> 22273 | G8: =G4-G7 -> 22183 | H8: =H4-H7 -> 20965 | I8: =I4-I7 -> 17538 | ... AD8: =AD4-AD7 -> 16259.419
A9: Interest & Other | B9: -4297 | C9: -7953 | D9: -7454 | E9: -12511 | F9: -8643 | G9: -5392 | H9: 5344 | I9: -5283 | J9: -7754 | K9: -9421 | L9: -6560 | M9: -579 | N9: 4869 | O9: -3332 | P9: -3573 | Q9: -7026 | R9: -8145 | S9: -12221 | T9: -14776 | U9: 0 | V9: 0 | W9: 0 | X9: 0 | Y9: 0 | Z9: 0 | AA9: 0 | AB9: 0 | AC9: 0 | AD9: 0
A10: Pretax | B10: =B8+B9 -> 9167 | C10: =C8+C9 -> 9749 | D10: =D8+D9 -> 10780 | E10: =E8+E9 -> 9410 | F10: =F8+F9 -> 13630 | G10: =G8+G9 -> 16791 | H10: =H8+H9 -> 26309 | I10: =I8+I9 -> 12255 | ... AD10: =AD8+AD9 -> 16259.419
A11: Taxes | B11: 1023 | C11: 1645 | D11: 2145 | E11: 1153 | F11: 3621 | G11: 2221 | H11: 4306 | I11: 3120 | J11: 1990 | K11: 1123 | L11: -9049 | M11: -266 | N11: 583 | O11: 370 | P11: 1852 | Q11: 3328 | R11: -1115 | S11: -28 | T11: -266 | U11: =MAX(0,U10)*Assumptions!$E$14 -> 3499.2097 | V11: =MAX(0,V10)*Assumptions!$E$14 -> 3276.0158 | W11: =MAX(0,W10)*Assumptions!$E$14 -> 2905.4391 | X11: =MAX(0,X10)*Assumptions!$E$14 -> 2744.8127 | Y11: =MAX(0,Y10)*Assumptions!$E$14 -> 2724.7765 | Z11: =MAX(0,Z10)*Assumptions!$E$14 -> 2755.8377 | AA11: =MAX(0,AA10)*Assumptions!$E$14 -> 2785.0243 | AB11: =MAX(0,AB10)*Assumptions!$E$14 -> 2785.0966 | ... AD11: =MAX(0,AD10)*Assumptions!$E$14 -> 2764.1011
A12: Net Income | B12: 8144 | C12: 8104 | D12: 8635 | E12: 8257 | F12: 10009 | G12: 14570 | H12: 22003 | I12: 9135 | J12: 6960 | K12: 7215 | L12: 21308 | M12: 11153 | N12: 16026 | O12: 9159 | P12: 21979 | Q12: 31372 | R12: 2119 | S12: 8031 | T12: 7771 | U12: =U10-U11 -> 17084.377 | V12: =V10-V11 -> 15994.665 | W12: =W10-W11 -> 14185.379 | X12: =X10-X11 -> 13401.144 | Y12: =Y10-Y11 -> 13303.32 | Z12: =Z10-Z11 -> 13454.972 | AA12: =AA10-AA11 -> 13597.471 | AB12: =AB10-AB11 -> 13597.825 | ... AD12: =AD10-AD11 -> 13495.317
A13: Earnings per Share | B13: =IFERROR(B12/B14,0) -> 1.1736561 | C13: =IFERROR(C12/C14,0) -> 1.2005926 | D13: =IFERROR(D12/D14,0) -> 1.225692 | E13: =IFERROR(E12/E14,0) -> 1.0226653 | F13: =IFERROR(F12/F14,0) -> 1.2717916 | G13: =IFERROR(G12/G14,0) -> 1.9405967 | H13: =IFERROR(H12/H14,0) -> 3.191153 | I13: =IFERROR(I12/I14,0) -> 1.4220112 | ... AD13: =IFERROR(AD12/AD14,0) -> 2.3677351
A14: Shares | B14: 6939 | C14: 6750 | D14: 7045 | E14: 8074 | F14: 7870 | G14: 7508 | H14: 6895 | I14: 6424 | J14: 6257 | K14: 6159 | L14: 6058 | M14: 5977 | N14: 5675 | O14: 5632 | P14: 5708 | Q14: 5733 | R14: 5709 | S14: 5700 | T14: 5713 | U14: =Main!$C$4 -> 5699.6736 | V14: =Main!$C$4 -> 5699.6736 | W14: =Main!$C$4 -> 5699.6736 | X14: =Main!$C$4 -> 5699.6736 | Y14: =Main!$C$4 -> 5699.6736 | Z14: =Main!$C$4 -> 5699.6736 | AA14: =Main!$C$4 -> 5699.6736 | AB14: =Main!$C$4 -> 5699.6736 | ... AD14: =Main!$C$4 -> 5699.6736
A16: Revenue Change | C16: =IFERROR(C2/B2-1,"") -> -0.0025197241 | D16: =IFERROR(D2/C2-1,"") -> 0.020146596 | E16: =IFERROR(E2/D2-1,"") -> 0.32263695 | F16: =IFERROR(F2/E2-1,"") -> -0.06337758 | G16: =IFERROR(G2/F2-1,"") -> -0.10449742 | H16: =IFERROR(H2/G2-1,"") -> -0.056223357 | I16: =IFERROR(I2/H2-1,"") -> -0.038364609 | J16: =IFERROR(J2/I2-1,"") -> -0.015200081 | ... AD16: =IFERROR(AD2/AC2-1,"") -> 0.025
A17: Gross Margin | B17: =IFERROR(B4/B2,"") -> 0.76787558 | C17: =IFERROR(C4/C2,"") -> 0.83203578 | D17: =IFERROR(D4/D2,"") -> 0.82830989 | E17: =IFERROR(E4/E2,"") -> 0.77306836 | F17: =IFERROR(F4/F2,"") -> 0.79519948 | G17: =IFERROR(G4/G2,"") -> 0.82031579 | H17: =IFERROR(H4/H2,"") -> 0.81416718 | I17: =IFERROR(I4/I2,"") -> 0.80693478 | ... AD17: =IFERROR(AD4/AD2,"") -> 0.7433
A18: Operating Margin | B18: =IFERROR(B8/B2,"") -> 0.2780784 | C18: =IFERROR(C8/C2,"") -> 0.36653139 | D18: =IFERROR(D8/D2,"") -> 0.37009073 | E18: =IFERROR(E8/E2,"") -> 0.33639224 | F18: =IFERROR(F8/F2,"") -> 0.36492177 | G18: =IFERROR(G8/G2,"") -> 0.40585835 | H18: =IFERROR(H8/H2,"") -> 0.40642447 | I18: =IFERROR(I8/I2,"") -> 0.35355307 | ... AD18: =IFERROR(AD8/AD2,"") -> 0.26
A19: Actual / Estimate | B19: A | C19: A | D19: A | E19: A | F19: A | G19: A | H19: A | I19: A | J19: A | K19: A | L19: A | M19: A | N19: A | O19: A | P19: A | Q19: A | R19: A | S19: A | T19: A | U19: E | V19: E | W19: E | X19: E | Y19: E | Z19: E | AA19: E | AB19: E | AC19: E | AD19: E

Sheet Quarterly Model

Sheet Assumptions
A1: Pfizer Inc.: basic DCF assumptions
A2: Blue = input, black = formula, green = link. $mm unless noted.
A4: Scenario (1 Bear, 2 Base, 3 Bull) | B4: 2 | C4: =CHOOSE($B$4,"Bear","Base","Bull") -> Base
A6: Discount rate override (blank = scenario)
A7: Terminal growth override (blank = scenario)
A9: Parameter | B9: Bear | C9: Base | D9: Bull | E9: Live
A10: Discount rate | B10: 0.09 | C10: 0.08 | D10: 0.07 | E10: =IF(ISNUMBER($B$6),$B$6,CHOOSE($B$4,B10,C10,D10)) -> 0.08
A11: Terminal growth | B11: 0.02 | C11: 0.025 | D11: 0.03 | E11: =IF(ISNUMBER($B$7),$B$7,CHOOSE($B$4,B11,C11,D11)) -> 0.025
A12: Revenue growth, first forecast year | B12: -0.067 | C12: -0.017 | D12: 0.033 | E12: =CHOOSE($B$4,B12,C12,D12) -> -0.017
A13: Operating margin, year 10 | B13: 0.21 | C13: 0.26 | D13: 0.3 | E13: =CHOOSE($B$4,B13,C13,D13) -> 0.26
A14: Tax rate on operating income | B14: 0.17 | C14: 0.17 | D14: 0.17 | E14: =CHOOSE($B$4,B14,C14,D14) -> 0.17
A15: Reinvestment, % of revenue increase | B15: 0.25 | C15: 0.25 | D15: 0.25 | E15: =CHOOSE($B$4,B15,C15,D15) -> 0.25
A17: Single inputs
A18: Starting operating margin (TTM) | B18: 0.3429
A19: Gross margin (forecast) | B19: 0.7433
A20: R&D share of operating expense (forecast) | B20: 0.4307
A21: Forecast years | B21: 10
A22: First forecast year, fraction after balance sheet date | B22: 0.5096
A23: Balance sheet date | B23: 46201
A24: Reporting currency per USD (USD) | B24: 1
A25: Base revenue, FY2025 | B25: ='Yearly Model'!T2 -> 62579
A27: Scenario summary
A28: Scenario | B28: Enterprise value | C28: Equity value | D28: NPV / share | E28: Upside
A29: Live | B29: =NPV!B23 -> 213746.44 | C29: =NPV!B26 -> 158809.44 | D29: =NPV!B28 -> 27.862901 | E29: =NPV!B30 -> -0.075243906
A30: 1 | B30: 126297.98 | C30: 71360.983 | D30: 12.520188 | E30: -0.58446108
A31: 2 | B31: 213746.44 | C31: 158809.44 | D31: 27.862901 | E31: -0.075243906
A32: 3 | B32: 387482.1 | C32: 332545.1 | D32: 58.344587 | E32: 0.93642837
A35: NPV / share: discount rate (rows) x terminal growth (columns)
A36: =NPV!B28 -> 27.862901 | B36: 0.015 | C36: 0.02 | D36: 0.025 | E36: 0.03 | F36: 0.035
A37: 0.06 | B37: 38.711239 | C37: 42.454349 | D37: 47.266919 | E37: 53.683679 | F37: 62.667143
A38: 0.07 | B38: 30.441928 | C38: 32.679091 | D38: 35.413401 | E38: 38.831289 | F38: 43.225717
A39: 0.08 | B39: 24.71755 | C39: 26.159169 | D39: 27.862901 | E39: 29.907379 | F39: 32.406186
A40: 0.09 | B40: 20.519037 | C40: 21.498513 | D40: 22.628677 | E40: 23.947203 | F40: 25.50546
A41: 0.1 | B41: 17.307054 | C41: 17.999249 | D41: 18.783737 | E41: 19.680294 | F41: 20.714784
A44: Reviewed revenue growth by year (base case; blank = fade formula)
A45: Fiscal year | B45: 2026 | C45: 2027 | D45: 2028 | E45: 2029 | F45: 2030 | G45: 2031 | H45: 2032 | I45: 2033 | J45: 2034 | K45: 2035
A46: Growth (bear/bull shift by the row-12 gap, fading to 0 by year 10) | B46: -0.017 | C46: -0.04 | D46: -0.09 | E46: -0.03 | F46: 0.02 | G46: 0.04 | H46: 0.04 | I46: 0.03 | J46: 0.03 | K46: 0.025

Sheet NPV
A1: Pfizer Inc.: free-cash-flow DCF ($mm)
A3: Fiscal year | B3: ='Yearly Model'!T1 -> 2025 | C3: ='Yearly Model'!U1 -> 2026 | D3: ='Yearly Model'!V1 -> 2027 | E3: ='Yearly Model'!W1 -> 2028 | F3: ='Yearly Model'!X1 -> 2029 | G3: ='Yearly Model'!Y1 -> 2030 | H3: ='Yearly Model'!Z1 -> 2031 | I3: ='Yearly Model'!AA1 -> 2032 | ... L3: ='Yearly Model'!AD1 -> 2035
A4: Period | B4: Actual | C4: 1 | D4: 2 | E4: 3 | F4: 4 | G4: 5 | H4: 6 | I4: 7 | J4: 8 | K4: 9 | L4: 10
A5: Revenue growth | C5: =IF(ISNUMBER(Assumptions!B$46),Assumptions!B$46+(Assumptions!$E$12-Assumptions!$C$12)*(Assumptions!$B$21-C4)/(Assumptions!$B$21-1),Assumptions!$E$12+(Assumptions!$E$11-Assumptions!$E$12)*(C4-1)/(Assumptions!$B$21-1)) -> -0.017 | D5: =IF(ISNUMBER(Assumptions!C$46),Assumptions!C$46+(Assumptions!$E$12-Assumptions!$C$12)*(Assumptions!$B$21-D4)/(Assumptions!$B$21-1),Assumptions!$E$12+(Assumptions!$E$11-Assumptions!$E$12)*(D4-1)/(Assumptions!$B$21-1)) -> -0.04 | E5: =IF(ISNUMBER(Assumptions!D$46),Assumptions!D$46+(Assumptions!$E$12-Assumptions!$C$12)*(Assumptions!$B$21-E4)/(Assumptions!$B$21-1),Assumptions!$E$12+(Assumptions!$E$11-Assumptions!$E$12)*(E4-1)/(Assumptions!$B$21-1)) -> -0.09 | F5: =IF(ISNUMBER(Assumptions!E$46),Assumptions!E$46+(Assumptions!$E$12-Assumptions!$C$12)*(Assumptions!$B$21-F4)/(Assumptions!$B$21-1),Assumptions!$E$12+(Assumptions!$E$11-Assumptions!$E$12)*(F4-1)/(Assumptions!$B$21-1)) -> -0.03 | G5: =IF(ISNUMBER(Assumptions!F$46),Assumptions!F$46+(Assumptions!$E$12-Assumptions!$C$12)*(Assumptions!$B$21-G4)/(Assumptions!$B$21-1),Assumptions!$E$12+(Assumptions!$E$11-Assumptions!$E$12)*(G4-1)/(Assumptions!$B$21-1)) -> 0.02 | H5: =IF(ISNUMBER(Assumptions!G$46),Assumptions!G$46+(Assumptions!$E$12-Assumptions!$C$12)*(Assumptions!$B$21-H4)/(Assumptions!$B$21-1),Assumptions!$E$12+(Assumptions!$E$11-Assumptions!$E$12)*(H4-1)/(Assumptions!$B$21-1)) -> 0.04 | I5: =IF(ISNUMBER(Assumptions!H$46),Assumptions!H$46+(Assumptions!$E$12-Assumptions!$C$12)*(Assumptions!$B$21-I4)/(Assumptions!$B$21-1),Assumptions!$E$12+(Assumptions!$E$11-Assumptions!$E$12)*(I4-1)/(Assumptions!$B$21-1)) -> 0.04 | J5: =IF(ISNUMBER(Assumptions!I$46),Assumptions!I$46+(Assumptions!$E$12-Assumptions!$C$12)*(Assumptions!$B$21-J4)/(Assumptions!$B$21-1),Assumptions!$E$12+(Assumptions!$E$11-Assumptions!$E$12)*(J4-1)/(Assumptions!$B$21-1)) -> 0.03 | ... L5: =IF(ISNUMBER(Assumptions!K$46),Assumptions!K$46+(Assumptions!$E$12-Assumptions!$C$12)*(Assumptions!$B$21-L4)/(Assumptions!$B$21-1),Assumptions!$E$12+(Assumptions!$E$11-Assumptions!$E$12)*(L4-1)/(Assumptions!$B$21-1)) -> 0.025
A6: Operating margin | B6: =IFERROR(B8/B7,0) -> 0.35604596 | C6: =Assumptions!$B$18+(Assumptions!$E$13-Assumptions!$B$18)*C4/Assumptions!$B$21 -> 0.33461 | D6: =Assumptions!$B$18+(Assumptions!$E$13-Assumptions!$B$18)*D4/Assumptions!$B$21 -> 0.32632 | E6: =Assumptions!$B$18+(Assumptions!$E$13-Assumptions!$B$18)*E4/Assumptions!$B$21 -> 0.31803 | F6: =Assumptions!$B$18+(Assumptions!$E$13-Assumptions!$B$18)*F4/Assumptions!$B$21 -> 0.30974 | G6: =Assumptions!$B$18+(Assumptions!$E$13-Assumptions!$B$18)*G4/Assumptions!$B$21 -> 0.30145 | H6: =Assumptions!$B$18+(Assumptions!$E$13-Assumptions!$B$18)*H4/Assumptions!$B$21 -> 0.29316 | I6: =Assumptions!$B$18+(Assumptions!$E$13-Assumptions!$B$18)*I4/Assumptions!$B$21 -> 0.28487 | J6: =Assumptions!$B$18+(Assumptions!$E$13-Assumptions!$B$18)*J4/Assumptions!$B$21 -> 0.27658 | ... L6: =Assumptions!$B$18+(Assumptions!$E$13-Assumptions!$B$18)*L4/Assumptions!$B$21 -> 0.26
A7: Revenue | B7: ='Yearly Model'!T2 -> 62579 | C7: ='Yearly Model'!U2 -> 61515.157 | D7: ='Yearly Model'!V2 -> 59054.551 | E7: ='Yearly Model'!W2 -> 53739.641 | F7: ='Yearly Model'!X2 -> 52127.452 | G7: ='Yearly Model'!Y2 -> 53170.001 | H7: ='Yearly Model'!Z2 -> 55296.801 | I7: ='Yearly Model'!AA2 -> 57508.673 | ... L7: ='Yearly Model'!AD2 -> 62536.225
A8: Operating income | B8: ='Yearly Model'!T8 -> 22281 | C8: ='Yearly Model'!U8 -> 20583.587 | D8: ='Yearly Model'!V8 -> 19270.681 | E8: ='Yearly Model'!W8 -> 17090.818 | F8: ='Yearly Model'!X8 -> 16145.957 | G8: ='Yearly Model'!Y8 -> 16028.097 | H8: ='Yearly Model'!Z8 -> 16210.81 | I8: ='Yearly Model'!AA8 -> 16382.496 | ... L8: ='Yearly Model'!AD8 -> 16259.419
A9: Tax on operating income | C9: =MAX(0,C8)*Assumptions!$E$14 -> 3499.2097 | D9: =MAX(0,D8)*Assumptions!$E$14 -> 3276.0158 | E9: =MAX(0,E8)*Assumptions!$E$14 -> 2905.4391 | F9: =MAX(0,F8)*Assumptions!$E$14 -> 2744.8127 | G9: =MAX(0,G8)*Assumptions!$E$14 -> 2724.7765 | H9: =MAX(0,H8)*Assumptions!$E$14 -> 2755.8377 | I9: =MAX(0,I8)*Assumptions!$E$14 -> 2785.0243 | J9: =MAX(0,J8)*Assumptions!$E$14 -> 2785.0966 | ... L9: =MAX(0,L8)*Assumptions!$E$14 -> 2764.1011
A10: NOPAT | C10: =C8-C9 -> 17084.377 | D10: =D8-D9 -> 15994.665 | E10: =E8-E9 -> 14185.379 | F10: =F8-F9 -> 13401.144 | G10: =G8-G9 -> 13303.32 | H10: =H8-H9 -> 13454.972 | I10: =I8-I9 -> 13597.471 | J10: =J8-J9 -> 13597.825 | ... L10: =L8-L9 -> 13495.317
A11: Reinvestment | C11: =(C7-B7)*Assumptions!$E$15 -> -265.96075 | D11: =(D7-C7)*Assumptions!$E$15 -> -615.15157 | E11: =(E7-D7)*Assumptions!$E$15 -> -1328.7274 | F11: =(F7-E7)*Assumptions!$E$15 -> -403.04731 | G11: =(G7-F7)*Assumptions!$E$15 -> 260.63726 | H11: =(H7-G7)*Assumptions!$E$15 -> 531.70001 | I11: =(I7-H7)*Assumptions!$E$15 -> 552.96801 | J11: =(J7-I7)*Assumptions!$E$15 -> 431.31505 | ... L11: =(L7-K7)*Assumptions!$E$15 -> 381.31845
A12: Free cash flow | C12: =C10-C11 -> 17350.338 | D12: =D10-D11 -> 16609.817 | E12: =E10-E11 -> 15514.106 | F12: =F10-F11 -> 13804.192 | G12: =G10-G11 -> 13042.683 | H12: =H10-H11 -> 12923.272 | I12: =I10-I11 -> 13044.503 | J12: =J10-J11 -> 13166.51 | ... L12: =L10-L11 -> 13113.999
A13: Year fraction | C13: =Assumptions!$B$22 -> 0.5096 | D13: 1 | E13: 1 | F13: 1 | G13: 1 | H13: 1 | I13: 1 | J13: 1 | K13: 1 | L13: 1
A14: Discount time (mid-period) | C14: =C13/2 -> 0.2548 | D14: =C14+C13/2+D13/2 -> 1.0096 | E14: =D14+D13/2+E13/2 -> 2.0096 | F14: =E14+E13/2+F13/2 -> 3.0096 | G14: =F14+F13/2+G13/2 -> 4.0096 | H14: =G14+G13/2+H13/2 -> 5.0096 | I14: =H14+H13/2+I13/2 -> 6.0096 | J14: =I14+I13/2+J13/2 -> 7.0096 | K14: =J14+J13/2+K13/2 -> 8.0096 | L14: =K14+K13/2+L13/2 -> 9.0096
A15: Discount factor | C15: =1/(1+Assumptions!$E$10)^C14 -> 0.98058135 | D15: =1/(1+Assumptions!$E$10)^D14 -> 0.92524208 | E15: =1/(1+Assumptions!$E$10)^E14 -> 0.85670563 | F15: =1/(1+Assumptions!$E$10)^F14 -> 0.79324595 | G15: =1/(1+Assumptions!$E$10)^G14 -> 0.73448699 | H15: =1/(1+Assumptions!$E$10)^H14 -> 0.68008055 | I15: =1/(1+Assumptions!$E$10)^I14 -> 0.62970421 | J15: =1/(1+Assumptions!$E$10)^J14 -> 0.58305946 | ... L15: =1/(1+Assumptions!$E$10)^L14 -> 0.49987951
A16: PV of free cash flow | C16: =C12*C13*C15 -> 8670.0376 | D16: =D12*D13*D15 -> 15368.101 | E16: =E12*E13*E15 -> 13291.022 | F16: =F12*F13*F15 -> 10950.119 | G16: =G12*G13*G15 -> 9579.6811 | H16: =H12*H13*H15 -> 8788.8662 | I16: =I12*I13*I15 -> 8214.1788 | J16: =J12*J13*J15 -> 7676.8579 | ... L16: =L12*L13*L15 -> 6555.4193
A19: PV of forecast free cash flow | B19: =SUM(C16:L16) -> 96189.095
A20: Terminal free cash flow (year 11) | B20: =L10*(1+Assumptions!$E$11)-L7*Assumptions!$E$11*Assumptions!$E$15 -> 13441.849
A21: Terminal value | B21: =B20/(Assumptions!$E$10-Assumptions!$E$11) -> 244397.25
A22: PV of terminal value | B22: =B21/(1+Assumptions!$E$10)^(L14+0.5) -> 117557.35
A23: Enterprise value | B23: =B19+B22 -> 213746.44
A24: Cash & investments | B24: =Main!C7 -> 8257
A25: Debt | B25: =Main!C8 -> 63194
A26: Equity value | B26: =B23+B24-B25 -> 158809.44
A27: Shares (mm) | B27: =Main!C4 -> 5699.6736
A28: NPV / share | B28: =B26/B27 -> 27.862901
A29: Price | B29: =Main!C3 -> 30.13
A30: Upside | B30: =B28/B29-1 -> -0.075243906
A31: Terminal value, % of EV | B31: =IFERROR(B22/B23,0) -> 0.54998505

Sheet Options
A1: PFE: options vs. the reviewed DCF (per contract = 100 shares)
A2: Market prices are Cboe delayed quotes; blue = input. Probabilities are risk-neutral (lognormal at ATM IV).
A3: Inputs
A4: Spot (close 2026-10-20) | B4: 30.11
A5: Pricing date | B5: 46315
A6: Near expiry | B6: 46402
A7: Long expiry | B7: 46773
A8: Years to near expiry | B8: =(B6-B5)/365 -> 0.23835616
A9: Years to long expiry | B9: =(B7-B5)/365 -> 1.2547945
A10: Risk-free rate | B10: 0.04
A11: Dividend yield | B11: 0.058
A12: ATM implied volatility, near | B12: 0.2429
A13: ATM implied volatility, long | B13: 0.2644
A14: Contract multiplier | B14: 100
A16: Market expectations, near expiry
A17: ATM strike | B17: 30
A18: ATM call (mid) | B18: 1.44
A19: ATM put (mid) | B19: 1.405
A20: Straddle, % of spot (expected move) | B20: =(B18+B19)/B4 -> 0.094486881
A21: Expected range, low | B21: =B4*(1-B20) -> 27.265
A22: Expected range, high | B22: =B4*(1+B20) -> 32.955
A23: 1-SD move by long expiry (ATM IV) | B23: =B13*SQRT(B9) -> 0.29617456
A25: Model vs. market at the long expiry
A26: Case | B26: Value / share | C26: vs. spot | D26: Annual return needed | E26: Market P(above)
A27: Forward price at long expiry | B27: =B4*EXP((B10-B11)*B9) -> 29.437549
A28: Bear | B28: =Assumptions!D30 -> 12.520188 | C28: =B28/$B$4-1 -> -0.58418507 | D28: =IF(B28>0,(B28/$B$4)^(1/$B$9)-1,"") -> -0.50308169 | E28: =IF(B28>0,NORMSDIST((LN($B$27/B28)-$B$13^2*$B$9/2)/($B$13*SQRT($B$9))),1) -> 0.99691383
A29: Base (reviewed) | B29: =Assumptions!D31 -> 27.862901 | C29: =B29/$B$4-1 -> -0.074629654 | D29: =IF(B29>0,(B29/$B$4)^(1/$B$9)-1,"") -> -0.059940315 | E29: =IF(B29>0,NORMSDIST((LN($B$27/B29)-$B$13^2*$B$9/2)/($B$13*SQRT($B$9))),1) -> 0.51496856
A30: Bull | B30: =Assumptions!D32 -> 58.344587 | C30: =B30/$B$4-1 -> 0.93771461 | D30: =IF(B30>0,(B30/$B$4)^(1/$B$9)-1,"") -> 0.69415707 | E30: =IF(B30>0,NORMSDIST((LN($B$27/B30)-$B$13^2*$B$9/2)/($B$13*SQRT($B$9))),1) -> 0.0069884077
A32: Chain, 2028-01-21 expiry
A33: Strike | B33: Call bid | C33: Call ask | D33: Call IV | E33: Put bid | F33: Put ask | G33: Put IV | H33: Call OI | I33: Put OI
A34: 13 | B34: 16.8 | C34: 17.55 | D34: 0.5704 | E34: 0.05 | F34: 0.1 | G34: 0.3809 | H34: 347 | I34: 803
A35: 22 | B35: 7.75 | C35: 8.6 | D35: 0 | E35: 0.55 | F35: 0.74 | G35: 0.2778 | H35: 6474 | I35: 18061
A36: 25 | B36: 6.1 | C36: 6.35 | D36: 0.2779 | E36: 1.13 | F36: 1.46 | G36: 0.2657 | H36: 16899 | I36: 31903
A37: 27 | B37: 4.75 | C37: 5 | D37: 0.2652 | E37: 1.73 | F37: 2.05 | G37: 0.2554 | H37: 21872 | I37: 14959
A38: 30 | B38: 3.35 | C38: 3.5 | D38: 0.2681 | E38: 3.2 | F38: 3.5 | G38: 0.2608 | H38: 28623 | I38: 7276
A39: 32 | B39: 2.53 | C39: 2.69 | D39: 0.2637 | E39: 4.3 | F39: 4.6 | G39: 0.2569 | H39: 10825 | I39: 1426
A40: 35 | B40: 1.64 | C40: 1.74 | D40: 0.2602 | E40: 5.95 | F40: 6.95 | G40: 0.2551 | H40: 22025 | I40: 2176
A41: 37 | B41: 1.18 | C41: 1.36 | D41: 0.2602 | E41: 7.75 | F41: 8.2 | G41: 0.2549 | H41: 2939 | I41: 103
A42: 40 | B42: 0.77 | C42: 0.9 | D42: 0.2624 | E42: 10.3 | F42: 11.05 | G42: 0.2787 | H42: 16176 | I42: 62
A44: Strategies, 2028-01-21 expiry (premium: + = credit; P/L at expiry per contract)
...
