Workbook

Sheet Main
B2: Praxis Precision Medicines, Inc.
B3: Price | C3: =INDEX([1]Pharma!$F$1:$F$1000,MATCH("PRAX",[1]Pharma!$B$1:$B$1000,0)) -> 264.49
B4: Shares | C4: =27.919988+0.704225+0.221238+0.31847 -> 29.163921
B5: Market Cap. | C5: =C3*C4 -> 7713.5655
B7: Cash | C7: =474.76+283.79+615.29 -> 1373.84
B8: Debt | C8: 0
B9: Enterprise V. | C9: =C5-C7+C8 -> 6339.7255
B11: rNPV / Share | C11: =NPV!C43 -> 272.58649
B12: Upside | C12: =C11/C3-1 -> 0.030611696
B13: Cash / Share | C13: =(C7-C8)/C4 -> 47.10752
B14: Scenario | C14: =Assumptions!$C$4 -> Base
B16: PDUFA Date | C16: =Assumptions!$B$30 -> 46383
B17: P(Approval) | C17: =Assumptions!$B$32 -> 0.9
B18: If Approved | C18: =Assumptions!$D$142 -> 275.37473
B19: If CRL | C19: =Assumptions!$D$141 -> 247.23121

Sheet Yearly Model
B1: 2021 | C1: 2022 | D1: 2023 | E1: 2024 | F1: 2025 | G1: 2026 | H1: 2027 | I1: 2028 | J1: 2029 | K1: 2030 | L1: 2031 | M1: 2032 | N1: 2033 | O1: 2034 | P1: 2035 | Q1: 2036 | R1: 2037 | S1: 2038 | T1: 2039 | U1: 2040 | V1: 2041 | W1: 2042 | X1: 2043 | Y1: 2044 | Z1: 2045 | AA1: 2046 | AB1: 2047 | AC1: 2048 | AD1: 2049 | AE1: 2050
A2: Revenue | B2: 0 | C2: 0 | D2: 2.447 | E2: 8.553 | F2: 0 | G2: =SUM('Quarterly Model'!F2:I2) -> 0 | H2: =Pipeline!C57 -> 471 | I2: =Pipeline!D57 -> 925.5 | J2: =Pipeline!E57 -> 1683 | K2: =Pipeline!F57 -> 2493 | L2: =Pipeline!G57 -> 3214.5 | M2: =Pipeline!H57 -> 3741.75 | N2: =Pipeline!I57 -> 4072.5 | O2: =Pipeline!J57 -> 4146 | ... AE2: =Pipeline!Z57 -> 2.3338055
A3: Cost of Sales | B3: 0 | C3: 0 | D3: 0 | E3: 0 | F3: 0 | G3: =SUM('Quarterly Model'!F3:I3) -> 0 | H3: =Pipeline!C58 -> 13.44 | I3: =Pipeline!D58 -> 36.57 | J3: =Pipeline!E58 -> 68.67 | K3: =Pipeline!F58 -> 102.87 | L3: =Pipeline!G58 -> 133.53 | M3: =Pipeline!H58 -> 156.42 | N3: =Pipeline!I58 -> 171 | O3: =Pipeline!J58 -> 174.84 | ... AE3: =Pipeline!Z58 -> 0.12850847
A4: Gross Margin | B4: =B2-B3 -> 0 | C4: =C2-C3 -> 0 | D4: =D2-D3 -> 2.447 | E4: =E2-E3 -> 8.553 | F4: =F2-F3 -> 0 | G4: =G2-G3 -> 0 | H4: =H2-H3 -> 457.56 | I4: =I2-I3 -> 888.93 | ... AE4: =AE2-AE3 -> 2.205297
A5: Research & Dev. | B5: 120.257 | C5: 155.04 | D5: 86.766 | E5: 152.413 | F5: 267.115 | G5: =SUM('Quarterly Model'!F5:I5) -> 294.403 | H5: =Pipeline!C61 -> 305 | I5: =Pipeline!D61 -> 254.5 | J5: =Pipeline!E61 -> 221.96 | K5: =Pipeline!F61 -> 299.16 | L5: =Pipeline!G61 -> 385.74 | M5: =Pipeline!H61 -> 449.01 | N5: =Pipeline!I61 -> 488.7 | O5: =Pipeline!J61 -> 497.52 | ... AE5: =Pipeline!Z61 -> 0.28005665
A6: General & Admin | B6: 47.075 | C6: 59.946 | D6: 42.054 | E6: 56.305 | F6: 59.083 | G6: =SUM('Quarterly Model'!F6:I6) -> 125.361 | H6: =Pipeline!C64 -> 433.275 | I6: =Pipeline!D64 -> 663.9 | J6: =Pipeline!E64 -> 863.4275 | K6: =Pipeline!F64 -> 1058.4525 | L6: =Pipeline!G64 -> 1251.69 | M6: =Pipeline!H64 -> 1401.21 | N6: =Pipeline!I64 -> 1464.15 | O6: =Pipeline!J64 -> 1469.73 | ... AE6: =Pipeline!Z64 -> 0.77713196
A7: Operating Expense | B7: =SUM(B5:B6) -> 167.332 | C7: =SUM(C5:C6) -> 214.986 | D7: =SUM(D5:D6) -> 128.82 | E7: =SUM(E5:E6) -> 208.718 | F7: =SUM(F5:F6) -> 326.198 | G7: =SUM(G5:G6) -> 419.764 | H7: =SUM(H5:H6) -> 738.275 | I7: =SUM(I5:I6) -> 918.4 | ... AE7: =SUM(AE5:AE6) -> 1.0571886
A8: Operating Income | B8: =B4-B7 -> -167.332 | C8: =C4-C7 -> -214.986 | D8: =D4-D7 -> -126.373 | E8: =E4-E7 -> -200.165 | F8: =F4-F7 -> -326.198 | G8: =G4-G7 -> -419.764 | H8: =H4-H7 -> -280.715 | I8: =I4-I7 -> -29.47 | ... AE8: =AE4-AE7 -> 1.1481084
A9: Interest & Other | B9: 0.332 | C9: 0.986 | D9: 3.373 | E9: 17.165 | F9: 23.669 | G9: =SUM('Quarterly Model'!F9:I9) -> 51.983 | H9: =Assumptions!$B$16*MAX(0,G20)-Assumptions!$B$17*Main!$C$8 -> 44.33775 | I9: =Assumptions!$B$16*MAX(0,H20)-Assumptions!$B$17*Main!$C$8 -> 35.473603 | J9: =Assumptions!$B$16*MAX(0,I20)-Assumptions!$B$17*Main!$C$8 -> 35.698738 | K9: =Assumptions!$B$16*MAX(0,J20)-Assumptions!$B$17*Main!$C$8 -> 56.872785 | L9: =Assumptions!$B$16*MAX(0,K20)-Assumptions!$B$17*Main!$C$8 -> 97.72492 | M9: =Assumptions!$B$16*MAX(0,L20)-Assumptions!$B$17*Main!$C$8 -> 144.51986 | N9: =Assumptions!$B$16*MAX(0,M20)-Assumptions!$B$17*Main!$C$8 -> 200.2039 | O9: =Assumptions!$B$16*MAX(0,N20)-Assumptions!$B$17*Main!$C$8 -> 263.86369 | ... AE9: =Assumptions!$B$16*MAX(0,AD20)-Assumptions!$B$17*Main!$C$8 -> 1155.9051
A10: Pretax | B10: =B8+B9 -> -167 | C10: =C8+C9 -> -214 | D10: =D8+D9 -> -123 | E10: =E8+E9 -> -183 | F10: =F8+F9 -> -302.529 | G10: =G8+G9 -> -367.781 | H10: =H8+H9 -> -236.37725 | I10: =I8+I9 -> 6.0036031 | ... AE10: =AE8+AE9 -> 1157.0532
A11: Taxes | B11: 0 | C11: 0 | D11: 0 | E11: 0 | F11: 0.471 | G11: =SUM('Quarterly Model'!F11:I11) -> 0 | H11: =MAX(0,H10-G21)*Assumptions!$B$15 -> 0 | I11: =MAX(0,I10-H21)*Assumptions!$B$15 -> 0 | J11: =MAX(0,J10-I21)*Assumptions!$B$15 -> 0 | K11: =MAX(0,K10-J21)*Assumptions!$B$15 -> 0 | L11: =MAX(0,L10-K21)*Assumptions!$B$15 -> 293.39978 | M11: =MAX(0,M10-L21)*Assumptions!$B$15 -> 394.72227 | N11: =MAX(0,N10-M21)*Assumptions!$B$15 -> 451.25932 | O11: =MAX(0,O10-N21)*Assumptions!$B$15 -> 476.23248 | ... AE11: =MAX(0,AE10-AD21)*Assumptions!$B$15 -> 242.98117
A12: Net Income | B12: -167 | C12: -214 | D12: -123 | E12: -183 | F12: -303 | G12: =G10-G11 -> -367.781 | H12: =H10-H11 -> -236.37725 | I12: =I10-I11 -> 6.0036031 | J12: =J10-J11 -> 564.64124 | K12: =K10-K11 -> 1089.3903 | L12: =L10-L11 -> 1247.8651 | M12: =M10-M11 -> 1484.9076 | N12: =N10-N11 -> 1697.5946 | ... AE12: =AE10-AE11 -> 914.07203
A13: Earnings per Share | B13: =IFERROR(B12/B14,0) -> -59.010601 | C13: =IFERROR(C12/C14,0) -> -69.638789 | D13: =IFERROR(D12/D14,0) -> -18.653321 | E13: =IFERROR(E12/E14,0) -> -10.219467 | F13: =IFERROR(F12/F14,0) -> -13.463675 | G13: =IFERROR(G12/G14,0) -> -12.626048 | H13: =IFERROR(H12/H14,0) -> -8.1051259 | I13: =IFERROR(I12/I14,0) -> 0.2058572 | ... AE13: =IFERROR(AE12/AE14,0) -> 31.342563
A14: Shares | B14: 2.83 | C14: 3.073 | D14: 6.594 | E14: 17.907 | F14: 22.505 | G14: =AVERAGE('Quarterly Model'!F14:I14) -> 29.12875 | H14: =Main!$C$4*(1+Assumptions!$B$26)^(H1-2026) -> 29.163921 | I14: =Main!$C$4*(1+Assumptions!$B$26)^(I1-2026) -> 29.163921 | J14: =Main!$C$4*(1+Assumptions!$B$26)^(J1-2026) -> 29.163921 | K14: =Main!$C$4*(1+Assumptions!$B$26)^(K1-2026) -> 29.163921 | L14: =Main!$C$4*(1+Assumptions!$B$26)^(L1-2026) -> 29.163921 | M14: =Main!$C$4*(1+Assumptions!$B$26)^(M1-2026) -> 29.163921 | N14: =Main!$C$4*(1+Assumptions!$B$26)^(N1-2026) -> 29.163921 | O14: =Main!$C$4*(1+Assumptions!$B$26)^(O1-2026) -> 29.163921 | ... AE14: =Main!$C$4*(1+Assumptions!$B$26)^(AE1-2026) -> 29.163921
A16: Revenue Change | C16: =IFERROR(C2/B2-1,"") | D16: =IFERROR(D2/C2-1,"") | E16: =IFERROR(E2/D2-1,"") -> 2.4953004 | F16: =IFERROR(F2/E2-1,"") -> -1 | G16: =IFERROR(G2/F2-1,"") | H16: =IFERROR(H2/G2-1,"") | I16: =IFERROR(I2/H2-1,"") -> 0.96496815 | J16: =IFERROR(J2/I2-1,"") -> 0.8184765 | ... AE16: =IFERROR(AE2/AD2-1,"") -> -0.56741811
A17: Gross Margin | B17: =IFERROR(B4/B2,"") | C17: =IFERROR(C4/C2,"") | D17: =IFERROR(D4/D2,"") -> 1 | E17: =IFERROR(E4/E2,"") -> 1 | F17: =IFERROR(F4/F2,"") | G17: =IFERROR(G4/G2,"") | H17: =IFERROR(H4/H2,"") -> 0.97146497 | I17: =IFERROR(I4/I2,"") -> 0.96048622 | ... AE17: =IFERROR(AE4/AE2,"") -> 0.94493608
A19: Actual / Estimate | B19: A | C19: A | D19: A | E19: A | F19: A | G19: A+E | H19: E | I19: E | J19: E | K19: E | L19: E | M19: E | N19: E | O19: E | P19: E | Q19: E | R19: E | S19: E | T19: E | U19: E | V19: E | W19: E | X19: E | Y19: E | Z19: E | AA19: E | AB19: E | AC19: E | AD19: E | AE19: E
A20: Cash & Investments | G20: ='Quarterly Model'!I20 -> 1182.34 | H20: =G20+H12 -> 945.96275 | I20: =H20+I12 -> 951.96635 | J20: =I20+J12 -> 1516.6076 | K20: =J20+K12 -> 2605.9979 | L20: =K20+L12 -> 3853.863 | M20: =L20+M12 -> 5338.7706 | N20: =M20+N12 -> 7036.3652 | O20: =N20+O12 -> 8827.9064 | ... AE20: =AD20+AE12 -> 31738.208
A21: Tax-Loss Pool | F21: =Assumptions!$B$18 -> 1200 | G21: =F21-MIN(F21,MAX(0,G10))+MAX(0,-G10) -> 1567.781 | H21: =G21-MIN(G21,MAX(0,H10))+MAX(0,-H10) -> 1804.1582 | I21: =H21-MIN(H21,MAX(0,I10))+MAX(0,-I10) -> 1798.1546 | J21: =I21-MIN(I21,MAX(0,J10))+MAX(0,-J10) -> 1233.5134 | K21: =J21-MIN(J21,MAX(0,K10))+MAX(0,-K10) -> 144.12312 | L21: =K21-MIN(K21,MAX(0,L10))+MAX(0,-L10) -> 0 | M21: =L21-MIN(L21,MAX(0,M10))+MAX(0,-M10) -> 0 | N21: =M21-MIN(M21,MAX(0,N10))+MAX(0,-N10) -> 0 | ... AE21: =AD21-MIN(AD21,MAX(0,AE10))+MAX(0,-AE10) -> 0

Sheet Quarterly Model
B1: Q1 2025 | C1: Q2 2025 | D1: Q3 2025 | E1: Q4 2025 | F1: Q1 2026 | G1: Q2 2026 | H1: Q3 2026 | I1: Q4 2026
A2: Revenue | B2: 0 | C2: 0 | D2: 0 | E2: 0 | F2: 0 | G2: 0 | H2: 0 | I2: 0
A3: Cost of Sales | B3: 0 | C3: 0 | D3: 0 | E3: 0 | F3: 0 | G3: 0 | H3: =H2*0.0 -> 0 | I3: =I2*0.0 -> 0
A4: Gross Margin | B4: =B2-B3 -> 0 | C4: =C2-C3 -> 0 | D4: =D2-D3 -> 0 | E4: =E2-E3 -> 0 | F4: =F2-F3 -> 0 | G4: =G2-G3 -> 0 | H4: =H2-H3 -> 0 | I4: =I2-I3 -> 0
A5: Research & Dev. | B5: 60.806 | C5: 63.006 | D5: 65.797 | E5: 77.506 | F5: 77.987 | G5: 69.416 | H5: 72 | I5: 75
A6: General & Admin | B6: 13.922 | C6: 13.061 | D6: 12.562 | E6: 19.538 | F6: 27.873 | G6: 27.488 | H6: 32 | I6: 38
A7: Operating Expense | B7: =SUM(B5:B6) -> 74.728 | C7: =SUM(C5:C6) -> 76.067 | D7: =SUM(D5:D6) -> 78.359 | E7: =SUM(E5:E6) -> 97.044 | F7: =SUM(F5:F6) -> 105.86 | G7: =SUM(G5:G6) -> 96.904 | H7: =SUM(H5:H6) -> 104 | I7: =SUM(I5:I6) -> 113
A8: Operating Income | B8: =B4-B7 -> -74.728 | C8: =C4-C7 -> -76.067 | D8: =D4-D7 -> -78.359 | E8: =E4-E7 -> -97.044 | F8: =F4-F7 -> -105.86 | G8: =G4-G7 -> -96.904 | H8: =H4-H7 -> -104 | I8: =I4-I7 -> -113
A9: Interest & Other | B9: 5.432 | C9: 4.94 | D9: 4.425 | E9: 8.401 | F9: 13.299 | G9: 13.184 | H9: 13 | I9: 12.5
A10: Pretax | B10: =B8+B9 -> -69.296 | C10: =C8+C9 -> -71.127 | D10: =D8+D9 -> -73.934 | E10: =E8+E9 -> -88.643 | F10: =F8+F9 -> -92.561 | G10: =G8+G9 -> -83.72 | H10: =H8+H9 -> -91 | I10: =I8+I9 -> -100.5
A11: Taxes | B11: 0 | C11: 0 | D11: 0 | E11: 0 | F11: 0 | G11: 0 | H11: 0 | I11: 0
A12: Net Income | B12: =B10-B11 -> -69.296 | C12: =C10-C11 -> -71.127 | D12: =D10-D11 -> -73.934 | E12: =E10-E11 -> -88.643 | F12: =F10-F11 -> -92.561 | G12: =G10-G11 -> -83.72 | H12: =H10-H11 -> -91 | I12: =I10-I11 -> -100.5
A13: Earnings per Share | B13: =IFERROR(B12/B14,0) -> -3.2910334 | C13: =IFERROR(C12/C14,0) -> -3.3120838 | D13: =IFERROR(D12/D14,0) -> -3.3641534 | E13: =IFERROR(E12/E14,0) -> -3.4746972 | F13: =IFERROR(F12/F14,0) -> -3.2045769 | G13: =IFERROR(G12/G14,0) -> -2.8739144 | H13: =IFERROR(H12/H14,0) -> -3.1164384 | I13: =IFERROR(I12/I14,0) -> -3.4300341
A14: Shares | B14: 21.056 | C14: 21.475 | D14: 21.977 | E14: 25.511 | F14: 28.884 | G14: 29.131 | H14: 29.2 | I14: 29.3
A16: Revenue Change (YoY) | F16: =IFERROR(F2/B2-1,"") | G16: =IFERROR(G2/C2-1,"") | H16: =IFERROR(H2/D2-1,"") | I16: =IFERROR(I2/E2-1,"")
A17: Gross Margin | B17: =IFERROR(B4/B2,"") | C17: =IFERROR(C4/C2,"") | D17: =IFERROR(D4/D2,"") | E17: =IFERROR(E4/E2,"") | F17: =IFERROR(F4/F2,"") | G17: =IFERROR(G4/G2,"") | H17: =IFERROR(H4/H2,"") | I17: =IFERROR(I4/I2,"")
A19: Actual / Estimate | B19: A | C19: A | D19: A | E19: A | F19: A | G19: A | H19: E | I19: E
A20: Cash & Investments | G20: 1373.84 | H20: =G20+H12+H21 -> 1282.84 | I20: =H20+I12+I21 -> 1182.34
A21: Other Cash Flows (est.) | H21: 0 | I21: 0

Sheet Assumptions
A1: PRAX — rNPV assumptions ($mm unless noted)
A4: Scenario (1 = Bear, 2 = Base, 3 = Bull) | B4: 2 | C4: =CHOOSE($B$4,"Bear","Base","Bull") -> Base
A5: Overrides (blank = scenario value; the sensitivity tables drive these)
A6: Discount rate override
A7: PDUFA approval probability override
A8: PDUFA program peak sales override ($mm)
A10: Parameter | B10: Active | C10: Bear | D10: Base | E10: Bull
A12: Valuation & corporate
A13: Valuation date | B13: =DATE(2026,10,16) -> 46311
A14: Discount rate (cost of equity) | B14: =IF(ISNUMBER($B$6),$B$6,CHOOSE($B$4,C14,D14,E14)) -> 0.11 | C14: 0.125 | D14: 0.11 | E14: 0.095
A15: Tax rate | B15: =CHOOSE($B$4,C15,D15,E15) -> 0.21 | C15: 0.21 | D15: 0.21 | E15: 0.21
A16: Interest yield on cash | B16: =CHOOSE($B$4,C16,D16,E16) -> 0.0375 | C16: 0.0375 | D16: 0.0375 | E16: 0.0375
A17: Average cash cost of debt (P&L display only) | B17: =CHOOSE($B$4,C17,D17,E17) -> 0.025 | C17: 0.025 | D17: 0.025 | E17: 0.025
A18: Tax-loss pool at 12/31/2025 | B18: =CHOOSE($B$4,C18,D18,E18) -> 1200 | C18: 1200 | D18: 1200 | E18: 1200
A19: Corporate G&A, 2027 | B19: =CHOOSE($B$4,C19,D19,E19) -> 120 | C19: 120 | D19: 120 | E19: 120
A20: Platform / unallocated R&D, 2027 | B20: =CHOOSE($B$4,C20,D20,E20) -> 150 | C20: 150 | D20: 150 | E20: 150
A21: Cost inflation | B21: =CHOOSE($B$4,C21,D21,E21) -> 0.03 | C21: 0.03 | D21: 0.03 | E21: 0.03
A22: Corporate G&A floor, % of revenue | B22: =CHOOSE($B$4,C22,D22,E22) -> 0.08 | C22: 0.08 | D22: 0.08 | E22: 0.08
A23: Platform R&D floor, % of revenue | B23: =CHOOSE($B$4,C23,D23,E23) -> 0.12 | C23: 0.12 | D23: 0.12 | E23: 0.12
A24: Corporate cost cut after a CRL (2027+) | B24: =CHOOSE($B$4,C24,D24,E24) -> 0 | C24: 0 | D24: 0 | E24: 0
A25: Last year of base-level corporate costs (then % of revenue only) | B25: =CHOOSE($B$4,C25,D25,E25) -> 2042 | C25: 2042 | D25: 2042 | E25: 2042
A26: Annual share count growth (EPS display only) | B26: =CHOOSE($B$4,C26,D26,E26) -> 0 | C26: 0 | D26: 0 | E26: 0
A27: Wind-down cost for liquidation value | B27: =CHOOSE($B$4,C27,D27,E27) -> 60 | C27: 60 | D27: 60 | E27: 60
A29: PDUFA event
A30: PDUFA target action date | B30: =DATE(2026,12,27) -> 46383
A31: Application | B31: Relutrigine NDA, SCN2A/SCN8A developmental & epileptic encephalopathies
A32: Probability of approval at this PDUFA | B32: =IF(ISNUMBER($B$7),$B$7,CHOOSE($B$4,C32,D32,E32)) -> 0.9 | C32: 0.82 | D32: 0.9 | E32: 0.95
A33: Probability of approval later, after a CRL | B33: =CHOOSE($B$4,C33,D33,E33) -> 0.75 | C33: 0.7 | D33: 0.75 | E33: 0.8
A34: Launch delay after a CRL (years) | B34: =CHOOSE($B$4,C34,D34,E34) -> 1 | C34: 1 | D34: 1 | E34: 1
A35: Probability of approval, scenario value (before override) | B35: =CHOOSE($B$4,C32,D32,E32) -> 0.9
A36: Read-through: relative cut to other programs' PoS after a CRL | B36: =CHOOSE($B$4,C36,D36,E36) -> 0.05 | C36: 0.05 | D36: 0.05 | E36: 0.05
A37: Read-through multiplier on other programs' PoS (1 = none) | B37: =1+$B$36*($B$32-$B$35)/$B$35 -> 1
A38: Expected corporate cost multiplier (2027+) | B38: =$B$32+(1-$B$32)*(1-$B$24) -> 1
A40: Commercial curves (by year since launch)
A41: Year since launch | B41: 1 | C41: 2 | D41: 3 | E41: 4 | F41: 5 | G41: 6 | H41: 7
A42: Ramp 1 — standard launch, % of peak | B42: 0.1 | C42: 0.25 | D42: 0.45 | E42: 0.65 | F42: 0.82 | G42: 0.93 | H42: 1
A43: Ramp 2 — orphan-disease launch, % of peak | B43: 0.15 | C43: 0.35 | D43: 0.55 | E43: 0.75 | F43: 0.9 | G43: 1 | H43: 1
A44: Commercial SG&A, % of sales (years 1–5; floor = program maturity %) | B44: 0.9 | C44: 0.55 | D44: 0.4 | E44: 0.32 | F44: 0.28
A46: Relutrigine — SCN2A / SCN8A DEE (PDUFA)
A47: Launch year (first full year of sales) | B47: =CHOOSE($B$4,C47,D47,E47) -> 2027 | C47: 2027 | D47: 2027 | E47: 2027
...

Sheet Pipeline
A1: PRAX — risk-adjusted program build ($mm)
A2: Year | C2: 2027 | D2: 2028 | E2: 2029 | F2: 2030 | G2: 2031 | H2: 2032 | I2: 2033 | J2: 2034 | K2: 2035 | L2: 2036 | M2: 2037 | N2: 2038 | O2: 2039 | P2: 2040 | Q2: 2041 | R2: 2042 | S2: 2043 | T2: 2044 | U2: 2045 | V2: 2046 | W2: 2047 | X2: 2048 | Y2: 2049 | Z2: 2050
A4: Relutrigine — SCN2A / SCN8A DEE
A5: Years since launch (approved on time) | C5: =C$2-Assumptions!$B$47+1 -> 1 | D5: =D$2-Assumptions!$B$47+1 -> 2 | E5: =E$2-Assumptions!$B$47+1 -> 3 | F5: =F$2-Assumptions!$B$47+1 -> 4 | G5: =G$2-Assumptions!$B$47+1 -> 5 | H5: =H$2-Assumptions!$B$47+1 -> 6 | I5: =I$2-Assumptions!$B$47+1 -> 7 | J5: =J$2-Assumptions!$B$47+1 -> 8 | ... Z5: =Z$2-Assumptions!$B$47+1 -> 24
A6: Net sales, unrisked (approved on time) | C6: =IF(C$2>Assumptions!$B$56,0*(1-Assumptions!$B$57),IF(C5>=1,Assumptions!$B$48*CHOOSE(Assumptions!$B$55,INDEX(Assumptions!$B$42:$H$42,MIN(C5,7)),INDEX(Assumptions!$B$43:$H$43,MIN(C5,7))),0)) -> 90 | D6: =IF(D$2>Assumptions!$B$56,C6*(1-Assumptions!$B$57),IF(D5>=1,Assumptions!$B$48*CHOOSE(Assumptions!$B$55,INDEX(Assumptions!$B$42:$H$42,MIN(D5,7)),INDEX(Assumptions!$B$43:$H$43,MIN(D5,7))),0)) -> 210 | E6: =IF(E$2>Assumptions!$B$56,D6*(1-Assumptions!$B$57),IF(E5>=1,Assumptions!$B$48*CHOOSE(Assumptions!$B$55,INDEX(Assumptions!$B$42:$H$42,MIN(E5,7)),INDEX(Assumptions!$B$43:$H$43,MIN(E5,7))),0)) -> 330 | F6: =IF(F$2>Assumptions!$B$56,E6*(1-Assumptions!$B$57),IF(F5>=1,Assumptions!$B$48*CHOOSE(Assumptions!$B$55,INDEX(Assumptions!$B$42:$H$42,MIN(F5,7)),INDEX(Assumptions!$B$43:$H$43,MIN(F5,7))),0)) -> 450 | G6: =IF(G$2>Assumptions!$B$56,F6*(1-Assumptions!$B$57),IF(G5>=1,Assumptions!$B$48*CHOOSE(Assumptions!$B$55,INDEX(Assumptions!$B$42:$H$42,MIN(G5,7)),INDEX(Assumptions!$B$43:$H$43,MIN(G5,7))),0)) -> 540 | H6: =IF(H$2>Assumptions!$B$56,G6*(1-Assumptions!$B$57),IF(H5>=1,Assumptions!$B$48*CHOOSE(Assumptions!$B$55,INDEX(Assumptions!$B$42:$H$42,MIN(H5,7)),INDEX(Assumptions!$B$43:$H$43,MIN(H5,7))),0)) -> 600 | I6: =IF(I$2>Assumptions!$B$56,H6*(1-Assumptions!$B$57),IF(I5>=1,Assumptions!$B$48*CHOOSE(Assumptions!$B$55,INDEX(Assumptions!$B$42:$H$42,MIN(I5,7)),INDEX(Assumptions!$B$43:$H$43,MIN(I5,7))),0)) -> 600 | J6: =IF(J$2>Assumptions!$B$56,I6*(1-Assumptions!$B$57),IF(J5>=1,Assumptions!$B$48*CHOOSE(Assumptions!$B$55,INDEX(Assumptions!$B$42:$H$42,MIN(J5,7)),INDEX(Assumptions!$B$43:$H$43,MIN(J5,7))),0)) -> 600 | K6: =IF(K$2>Assumptions!$B$56,J6*(1-Assumptions!$B$57),IF(K5>=1,Assumptions!$B$48*CHOOSE(Assumptions!$B$55,INDEX(Assumptions!$B$42:$H$42,MIN(K5,7)),INDEX(Assumptions!$B$43:$H$43,MIN(K5,7))),0)) -> 600 | ... Z6: =IF(Z$2>Assumptions!$B$56,Y6*(1-Assumptions!$B$57),IF(Z5>=1,Assumptions!$B$48*CHOOSE(Assumptions!$B$55,INDEX(Assumptions!$B$42:$H$42,MIN(Z5,7)),INDEX(Assumptions!$B$43:$H$43,MIN(Z5,7))),0)) -> 0.1572864
A7: Years since launch (approved after a CRL) | C7: =C$2-(Assumptions!$B$47+Assumptions!$B$34)+1 -> 0 | D7: =D$2-(Assumptions!$B$47+Assumptions!$B$34)+1 -> 1 | E7: =E$2-(Assumptions!$B$47+Assumptions!$B$34)+1 -> 2 | F7: =F$2-(Assumptions!$B$47+Assumptions!$B$34)+1 -> 3 | G7: =G$2-(Assumptions!$B$47+Assumptions!$B$34)+1 -> 4 | H7: =H$2-(Assumptions!$B$47+Assumptions!$B$34)+1 -> 5 | I7: =I$2-(Assumptions!$B$47+Assumptions!$B$34)+1 -> 6 | J7: =J$2-(Assumptions!$B$47+Assumptions!$B$34)+1 -> 7 | ... Z7: =Z$2-(Assumptions!$B$47+Assumptions!$B$34)+1 -> 23
A8: Net sales, unrisked (approved after a CRL) | C8: =IF(C$2>Assumptions!$B$56,0*(1-Assumptions!$B$57),IF(C7>=1,Assumptions!$B$48*CHOOSE(Assumptions!$B$55,INDEX(Assumptions!$B$42:$H$42,MIN(C7,7)),INDEX(Assumptions!$B$43:$H$43,MIN(C7,7))),0)) -> 0 | D8: =IF(D$2>Assumptions!$B$56,C8*(1-Assumptions!$B$57),IF(D7>=1,Assumptions!$B$48*CHOOSE(Assumptions!$B$55,INDEX(Assumptions!$B$42:$H$42,MIN(D7,7)),INDEX(Assumptions!$B$43:$H$43,MIN(D7,7))),0)) -> 90 | E8: =IF(E$2>Assumptions!$B$56,D8*(1-Assumptions!$B$57),IF(E7>=1,Assumptions!$B$48*CHOOSE(Assumptions!$B$55,INDEX(Assumptions!$B$42:$H$42,MIN(E7,7)),INDEX(Assumptions!$B$43:$H$43,MIN(E7,7))),0)) -> 210 | F8: =IF(F$2>Assumptions!$B$56,E8*(1-Assumptions!$B$57),IF(F7>=1,Assumptions!$B$48*CHOOSE(Assumptions!$B$55,INDEX(Assumptions!$B$42:$H$42,MIN(F7,7)),INDEX(Assumptions!$B$43:$H$43,MIN(F7,7))),0)) -> 330 | G8: =IF(G$2>Assumptions!$B$56,F8*(1-Assumptions!$B$57),IF(G7>=1,Assumptions!$B$48*CHOOSE(Assumptions!$B$55,INDEX(Assumptions!$B$42:$H$42,MIN(G7,7)),INDEX(Assumptions!$B$43:$H$43,MIN(G7,7))),0)) -> 450 | H8: =IF(H$2>Assumptions!$B$56,G8*(1-Assumptions!$B$57),IF(H7>=1,Assumptions!$B$48*CHOOSE(Assumptions!$B$55,INDEX(Assumptions!$B$42:$H$42,MIN(H7,7)),INDEX(Assumptions!$B$43:$H$43,MIN(H7,7))),0)) -> 540 | I8: =IF(I$2>Assumptions!$B$56,H8*(1-Assumptions!$B$57),IF(I7>=1,Assumptions!$B$48*CHOOSE(Assumptions!$B$55,INDEX(Assumptions!$B$42:$H$42,MIN(I7,7)),INDEX(Assumptions!$B$43:$H$43,MIN(I7,7))),0)) -> 600 | J8: =IF(J$2>Assumptions!$B$56,I8*(1-Assumptions!$B$57),IF(J7>=1,Assumptions!$B$48*CHOOSE(Assumptions!$B$55,INDEX(Assumptions!$B$42:$H$42,MIN(J7,7)),INDEX(Assumptions!$B$43:$H$43,MIN(J7,7))),0)) -> 600 | K8: =IF(K$2>Assumptions!$B$56,J8*(1-Assumptions!$B$57),IF(K7>=1,Assumptions!$B$48*CHOOSE(Assumptions!$B$55,INDEX(Assumptions!$B$42:$H$42,MIN(K7,7)),INDEX(Assumptions!$B$43:$H$43,MIN(K7,7))),0)) -> 600 | ... Z8: =IF(Z$2>Assumptions!$B$56,Y8*(1-Assumptions!$B$57),IF(Z7>=1,Assumptions!$B$48*CHOOSE(Assumptions!$B$55,INDEX(Assumptions!$B$42:$H$42,MIN(Z7,7)),INDEX(Assumptions!$B$43:$H$43,MIN(Z7,7))),0)) -> 0.1572864
A9: Product net sales, risk-adjusted | C9: =Assumptions!$B$32*C6+(1-Assumptions!$B$32)*Assumptions!$B$33*C8 -> 81 | D9: =Assumptions!$B$32*D6+(1-Assumptions!$B$32)*Assumptions!$B$33*D8 -> 195.75 | E9: =Assumptions!$B$32*E6+(1-Assumptions!$B$32)*Assumptions!$B$33*E8 -> 312.75 | F9: =Assumptions!$B$32*F6+(1-Assumptions!$B$32)*Assumptions!$B$33*F8 -> 429.75 | G9: =Assumptions!$B$32*G6+(1-Assumptions!$B$32)*Assumptions!$B$33*G8 -> 519.75 | H9: =Assumptions!$B$32*H6+(1-Assumptions!$B$32)*Assumptions!$B$33*H8 -> 580.5 | I9: =Assumptions!$B$32*I6+(1-Assumptions!$B$32)*Assumptions!$B$33*I8 -> 585 | J9: =Assumptions!$B$32*J6+(1-Assumptions!$B$32)*Assumptions!$B$33*J8 -> 585 | ... Z9: =Assumptions!$B$32*Z6+(1-Assumptions!$B$32)*Assumptions!$B$33*Z8 -> 0.15335424
A10: Company revenue, risk-adjusted (incl. milestones) | C10: =C9*Assumptions!$B$50+Assumptions!$B$32*IFERROR(INDEX(Assumptions!$B$62:$K$62,MATCH(C$2-Assumptions!$B$47,Assumptions!$B$61:$K$61,0)),0)+(1-Assumptions!$B$32)*Assumptions!$B$33*IFERROR(INDEX(Assumptions!$B$62:$K$62,MATCH(C$2-Assumptions!$B$47-Assumptions!$B$34,Assumptions!$B$61:$K$61,0)),0) -> 216 | D10: =D9*Assumptions!$B$50+Assumptions!$B$32*IFERROR(INDEX(Assumptions!$B$62:$K$62,MATCH(D$2-Assumptions!$B$47,Assumptions!$B$61:$K$61,0)),0)+(1-Assumptions!$B$32)*Assumptions!$B$33*IFERROR(INDEX(Assumptions!$B$62:$K$62,MATCH(D$2-Assumptions!$B$47-Assumptions!$B$34,Assumptions!$B$61:$K$61,0)),0) -> 207 | E10: =E9*Assumptions!$B$50+Assumptions!$B$32*IFERROR(INDEX(Assumptions!$B$62:$K$62,MATCH(E$2-Assumptions!$B$47,Assumptions!$B$61:$K$61,0)),0)+(1-Assumptions!$B$32)*Assumptions!$B$33*IFERROR(INDEX(Assumptions!$B$62:$K$62,MATCH(E$2-Assumptions!$B$47-Assumptions!$B$34,Assumptions!$B$61:$K$61,0)),0) -> 312.75 | F10: =F9*Assumptions!$B$50+Assumptions!$B$32*IFERROR(INDEX(Assumptions!$B$62:$K$62,MATCH(F$2-Assumptions!$B$47,Assumptions!$B$61:$K$61,0)),0)+(1-Assumptions!$B$32)*Assumptions!$B$33*IFERROR(INDEX(Assumptions!$B$62:$K$62,MATCH(F$2-Assumptions!$B$47-Assumptions!$B$34,Assumptions!$B$61:$K$61,0)),0) -> 429.75 | G10: =G9*Assumptions!$B$50+Assumptions!$B$32*IFERROR(INDEX(Assumptions!$B$62:$K$62,MATCH(G$2-Assumptions!$B$47,Assumptions!$B$61:$K$61,0)),0)+(1-Assumptions!$B$32)*Assumptions!$B$33*IFERROR(INDEX(Assumptions!$B$62:$K$62,MATCH(G$2-Assumptions!$B$47-Assumptions!$B$34,Assumptions!$B$61:$K$61,0)),0) -> 519.75 | H10: =H9*Assumptions!$B$50+Assumptions!$B$32*IFERROR(INDEX(Assumptions!$B$62:$K$62,MATCH(H$2-Assumptions!$B$47,Assumptions!$B$61:$K$61,0)),0)+(1-Assumptions!$B$32)*Assumptions!$B$33*IFERROR(INDEX(Assumptions!$B$62:$K$62,MATCH(H$2-Assumptions!$B$47-Assumptions!$B$34,Assumptions!$B$61:$K$61,0)),0) -> 580.5 | I10: =I9*Assumptions!$B$50+Assumptions!$B$32*IFERROR(INDEX(Assumptions!$B$62:$K$62,MATCH(I$2-Assumptions!$B$47,Assumptions!$B$61:$K$61,0)),0)+(1-Assumptions!$B$32)*Assumptions!$B$33*IFERROR(INDEX(Assumptions!$B$62:$K$62,MATCH(I$2-Assumptions!$B$47-Assumptions!$B$34,Assumptions!$B$61:$K$61,0)),0) -> 585 | J10: =J9*Assumptions!$B$50+Assumptions!$B$32*IFERROR(INDEX(Assumptions!$B$62:$K$62,MATCH(J$2-Assumptions!$B$47,Assumptions!$B$61:$K$61,0)),0)+(1-Assumptions!$B$32)*Assumptions!$B$33*IFERROR(INDEX(Assumptions!$B$62:$K$62,MATCH(J$2-Assumptions!$B$47-Assumptions!$B$34,Assumptions!$B$61:$K$61,0)),0) -> 585 | ... Z10: =Z9*Assumptions!$B$50+Assumptions!$B$32*IFERROR(INDEX(Assumptions!$B$62:$K$62,MATCH(Z$2-Assumptions!$B$47,Assumptions!$B$61:$K$61,0)),0)+(1-Assumptions!$B$32)*Assumptions!$B$33*IFERROR(INDEX(Assumptions!$B$62:$K$62,MATCH(Z$2-Assumptions!$B$47-Assumptions!$B$34,Assumptions!$B$61:$K$61,0)),0) -> 0.15335424
A11: COGS + royalties, risk-adjusted | C11: =C9*(Assumptions!$B$51+Assumptions!$B$52) -> 3.24 | D11: =D9*(Assumptions!$B$51+Assumptions!$B$52) -> 7.83 | E11: =E9*(Assumptions!$B$51+Assumptions!$B$52) -> 12.51 | F11: =F9*(Assumptions!$B$51+Assumptions!$B$52) -> 17.19 | G11: =G9*(Assumptions!$B$51+Assumptions!$B$52) -> 20.79 | H11: =H9*(Assumptions!$B$51+Assumptions!$B$52) -> 23.22 | I11: =I9*(Assumptions!$B$51+Assumptions!$B$52) -> 23.4 | J11: =J9*(Assumptions!$B$51+Assumptions!$B$52) -> 23.4 | ... Z11: =Z9*(Assumptions!$B$51+Assumptions!$B$52) -> 0.0061341696
A12: Commercial SG&A, risk-adjusted | C12: =Assumptions!$B$32*IF(Assumptions!$B$53=0,0,IF(C5=0,Assumptions!$B$54,IF(C5>=1,C6*IF(OR(Assumptions!$B$50<1,C5>5),Assumptions!$B$53,MAX(Assumptions!$B$53,INDEX(Assumptions!$B$44:$F$44,C5))),0)))+(1-Assumptions!$B$32)*Assumptions!$B$33*IF(Assumptions!$B$53=0,0,IF(C7=0,Assumptions!$B$54,IF(C7>=1,C8*IF(OR(Assumptions!$B$50<1,C7>5),Assumptions!$B$53,MAX(Assumptions!$B$53,INDEX(Assumptions!$B$44:$F$44,C7))),0))) -> 74.775 | D12: =Assumptions!$B$32*IF(Assumptions!$B$53=0,0,IF(D5=0,Assumptions!$B$54,IF(D5>=1,D6*IF(OR(Assumptions!$B$50<1,D5>5),Assumptions!$B$53,MAX(Assumptions!$B$53,INDEX(Assumptions!$B$44:$F$44,D5))),0)))+(1-Assumptions!$B$32)*Assumptions!$B$33*IF(Assumptions!$B$53=0,0,IF(D7=0,Assumptions!$B$54,IF(D7>=1,D8*IF(OR(Assumptions!$B$50<1,D7>5),Assumptions!$B$53,MAX(Assumptions!$B$53,INDEX(Assumptions!$B$44:$F$44,D7))),0))) -> 110.025 | E12: =Assumptions!$B$32*IF(Assumptions!$B$53=0,0,IF(E5=0,Assumptions!$B$54,IF(E5>=1,E6*IF(OR(Assumptions!$B$50<1,E5>5),Assumptions!$B$53,MAX(Assumptions!$B$53,INDEX(Assumptions!$B$44:$F$44,E5))),0)))+(1-Assumptions!$B$32)*Assumptions!$B$33*IF(Assumptions!$B$53=0,0,IF(E7=0,Assumptions!$B$54,IF(E7>=1,E8*IF(OR(Assumptions!$B$50<1,E7>5),Assumptions!$B$53,MAX(Assumptions!$B$53,INDEX(Assumptions!$B$44:$F$44,E7))),0))) -> 127.4625 | F12: =Assumptions!$B$32*IF(Assumptions!$B$53=0,0,IF(F5=0,Assumptions!$B$54,IF(F5>=1,F6*IF(OR(Assumptions!$B$50<1,F5>5),Assumptions!$B$53,MAX(Assumptions!$B$53,INDEX(Assumptions!$B$44:$F$44,F5))),0)))+(1-Assumptions!$B$32)*Assumptions!$B$33*IF(Assumptions!$B$53=0,0,IF(F7=0,Assumptions!$B$54,IF(F7>=1,F8*IF(OR(Assumptions!$B$50<1,F7>5),Assumptions!$B$53,MAX(Assumptions!$B$53,INDEX(Assumptions!$B$44:$F$44,F7))),0))) -> 139.5 | G12: =Assumptions!$B$32*IF(Assumptions!$B$53=0,0,IF(G5=0,Assumptions!$B$54,IF(G5>=1,G6*IF(OR(Assumptions!$B$50<1,G5>5),Assumptions!$B$53,MAX(Assumptions!$B$53,INDEX(Assumptions!$B$44:$F$44,G5))),0)))+(1-Assumptions!$B$32)*Assumptions!$B$33*IF(Assumptions!$B$53=0,0,IF(G7=0,Assumptions!$B$54,IF(G7>=1,G8*IF(OR(Assumptions!$B$50<1,G7>5),Assumptions!$B$53,MAX(Assumptions!$B$53,INDEX(Assumptions!$B$44:$F$44,G7))),0))) -> 146.88 | H12: =Assumptions!$B$32*IF(Assumptions!$B$53=0,0,IF(H5=0,Assumptions!$B$54,IF(H5>=1,H6*IF(OR(Assumptions!$B$50<1,H5>5),Assumptions!$B$53,MAX(Assumptions!$B$53,INDEX(Assumptions!$B$44:$F$44,H5))),0)))+(1-Assumptions!$B$32)*Assumptions!$B$33*IF(Assumptions!$B$53=0,0,IF(H7=0,Assumptions!$B$54,IF(H7>=1,H8*IF(OR(Assumptions!$B$50<1,H7>5),Assumptions!$B$53,MAX(Assumptions!$B$53,INDEX(Assumptions!$B$44:$F$44,H7))),0))) -> 146.34 | I12: =Assumptions!$B$32*IF(Assumptions!$B$53=0,0,IF(I5=0,Assumptions!$B$54,IF(I5>=1,I6*IF(OR(Assumptions!$B$50<1,I5>5),Assumptions!$B$53,MAX(Assumptions!$B$53,INDEX(Assumptions!$B$44:$F$44,I5))),0)))+(1-Assumptions!$B$32)*Assumptions!$B$33*IF(Assumptions!$B$53=0,0,IF(I7=0,Assumptions!$B$54,IF(I7>=1,I8*IF(OR(Assumptions!$B$50<1,I7>5),Assumptions!$B$53,MAX(Assumptions!$B$53,INDEX(Assumptions!$B$44:$F$44,I7))),0))) -> 146.25 | J12: =Assumptions!$B$32*IF(Assumptions!$B$53=0,0,IF(J5=0,Assumptions!$B$54,IF(J5>=1,J6*IF(OR(Assumptions!$B$50<1,J5>5),Assumptions!$B$53,MAX(Assumptions!$B$53,INDEX(Assumptions!$B$44:$F$44,J5))),0)))+(1-Assumptions!$B$32)*Assumptions!$B$33*IF(Assumptions!$B$53=0,0,IF(J7=0,Assumptions!$B$54,IF(J7>=1,J8*IF(OR(Assumptions!$B$50<1,J7>5),Assumptions!$B$53,MAX(Assumptions!$B$53,INDEX(Assumptions!$B$44:$F$44,J7))),0))) -> 146.25 | ... Z12: =Assumptions!$B$32*IF(Assumptions!$B$53=0,0,IF(Z5=0,Assumptions!$B$54,IF(Z5>=1,Z6*IF(OR(Assumptions!$B$50<1,Z5>5),Assumptions!$B$53,MAX(Assumptions!$B$53,INDEX(Assumptions!$B$44:$F$44,Z5))),0)))+(1-Assumptions!$B$32)*Assumptions!$B$33*IF(Assumptions!$B$53=0,0,IF(Z7=0,Assumptions!$B$54,IF(Z7>=1,Z8*IF(OR(Assumptions!$B$50<1,Z7>5),Assumptions!$B$53,MAX(Assumptions!$B$53,INDEX(Assumptions!$B$44:$F$44,Z7))),0))) -> 0.03833856
A13: Development R&D, risk-adjusted | C13: =IFERROR(INDEX(Assumptions!$B$59:$I$59,MATCH(C$2,Assumptions!$B$58:$I$58,0))*INDEX(Assumptions!$B$60:$I$60,MATCH(C$2,Assumptions!$B$58:$I$58,0)),0) -> 10 | D13: =IFERROR(INDEX(Assumptions!$B$59:$I$59,MATCH(D$2,Assumptions!$B$58:$I$58,0))*INDEX(Assumptions!$B$60:$I$60,MATCH(D$2,Assumptions!$B$58:$I$58,0)),0) -> 0 | E13: =IFERROR(INDEX(Assumptions!$B$59:$I$59,MATCH(E$2,Assumptions!$B$58:$I$58,0))*INDEX(Assumptions!$B$60:$I$60,MATCH(E$2,Assumptions!$B$58:$I$58,0)),0) -> 0 | F13: =IFERROR(INDEX(Assumptions!$B$59:$I$59,MATCH(F$2,Assumptions!$B$58:$I$58,0))*INDEX(Assumptions!$B$60:$I$60,MATCH(F$2,Assumptions!$B$58:$I$58,0)),0) -> 0 | G13: =IFERROR(INDEX(Assumptions!$B$59:$I$59,MATCH(G$2,Assumptions!$B$58:$I$58,0))*INDEX(Assumptions!$B$60:$I$60,MATCH(G$2,Assumptions!$B$58:$I$58,0)),0) -> 0 | H13: =IFERROR(INDEX(Assumptions!$B$59:$I$59,MATCH(H$2,Assumptions!$B$58:$I$58,0))*INDEX(Assumptions!$B$60:$I$60,MATCH(H$2,Assumptions!$B$58:$I$58,0)),0) -> 0 | I13: =IFERROR(INDEX(Assumptions!$B$59:$I$59,MATCH(I$2,Assumptions!$B$58:$I$58,0))*INDEX(Assumptions!$B$60:$I$60,MATCH(I$2,Assumptions!$B$58:$I$58,0)),0) -> 0 | J13: =IFERROR(INDEX(Assumptions!$B$59:$I$59,MATCH(J$2,Assumptions!$B$58:$I$58,0))*INDEX(Assumptions!$B$60:$I$60,MATCH(J$2,Assumptions!$B$58:$I$58,0)),0) -> 0 | ... Z13: =IFERROR(INDEX(Assumptions!$B$59:$I$59,MATCH(Z$2,Assumptions!$B$58:$I$58,0))*INDEX(Assumptions!$B$60:$I$60,MATCH(Z$2,Assumptions!$B$58:$I$58,0)),0) -> 0
A14: Program contribution (pre-tax) | C14: =C10-C11-C12-C13 -> 127.985 | D14: =D10-D11-D12-D13 -> 89.145 | E14: =E10-E11-E12-E13 -> 172.7775 | F14: =F10-F11-F12-F13 -> 273.06 | G14: =G10-G11-G12-G13 -> 352.08 | H14: =H10-H11-H12-H13 -> 410.94 | I14: =I10-I11-I12-I13 -> 415.35 | J14: =J10-J11-J12-J13 -> 415.35 | ... Z14: =Z10-Z11-Z12-Z13 -> 0.10888151
A16: Ulixacaltamide — essential tremor (PDUFA Jan 29, 2027)
A17: Years since launch | C17: =C$2-Assumptions!$B$65+1 -> 1 | D17: =D$2-Assumptions!$B$65+1 -> 2 | E17: =E$2-Assumptions!$B$65+1 -> 3 | F17: =F$2-Assumptions!$B$65+1 -> 4 | G17: =G$2-Assumptions!$B$65+1 -> 5 | H17: =H$2-Assumptions!$B$65+1 -> 6 | I17: =I$2-Assumptions!$B$65+1 -> 7 | J17: =J$2-Assumptions!$B$65+1 -> 8 | ... Z17: =Z$2-Assumptions!$B$65+1 -> 24
A18: Net sales, unrisked | C18: =IF(C$2>Assumptions!$B$74,0*(1-Assumptions!$B$75),IF(C17>=1,Assumptions!$B$66*CHOOSE(Assumptions!$B$73,INDEX(Assumptions!$B$42:$H$42,MIN(C17,7)),INDEX(Assumptions!$B$43:$H$43,MIN(C17,7))),0)) -> 300 | D18: =IF(D$2>Assumptions!$B$74,C18*(1-Assumptions!$B$75),IF(D17>=1,Assumptions!$B$66*CHOOSE(Assumptions!$B$73,INDEX(Assumptions!$B$42:$H$42,MIN(D17,7)),INDEX(Assumptions!$B$43:$H$43,MIN(D17,7))),0)) -> 750 | E18: =IF(E$2>Assumptions!$B$74,D18*(1-Assumptions!$B$75),IF(E17>=1,Assumptions!$B$66*CHOOSE(Assumptions!$B$73,INDEX(Assumptions!$B$42:$H$42,MIN(E17,7)),INDEX(Assumptions!$B$43:$H$43,MIN(E17,7))),0)) -> 1350 | F18: =IF(F$2>Assumptions!$B$74,E18*(1-Assumptions!$B$75),IF(F17>=1,Assumptions!$B$66*CHOOSE(Assumptions!$B$73,INDEX(Assumptions!$B$42:$H$42,MIN(F17,7)),INDEX(Assumptions!$B$43:$H$43,MIN(F17,7))),0)) -> 1950 | G18: =IF(G$2>Assumptions!$B$74,F18*(1-Assumptions!$B$75),IF(G17>=1,Assumptions!$B$66*CHOOSE(Assumptions!$B$73,INDEX(Assumptions!$B$42:$H$42,MIN(G17,7)),INDEX(Assumptions!$B$43:$H$43,MIN(G17,7))),0)) -> 2460 | H18: =IF(H$2>Assumptions!$B$74,G18*(1-Assumptions!$B$75),IF(H17>=1,Assumptions!$B$66*CHOOSE(Assumptions!$B$73,INDEX(Assumptions!$B$42:$H$42,MIN(H17,7)),INDEX(Assumptions!$B$43:$H$43,MIN(H17,7))),0)) -> 2790 | I18: =IF(I$2>Assumptions!$B$74,H18*(1-Assumptions!$B$75),IF(I17>=1,Assumptions!$B$66*CHOOSE(Assumptions!$B$73,INDEX(Assumptions!$B$42:$H$42,MIN(I17,7)),INDEX(Assumptions!$B$43:$H$43,MIN(I17,7))),0)) -> 3000 | J18: =IF(J$2>Assumptions!$B$74,I18*(1-Assumptions!$B$75),IF(J17>=1,Assumptions!$B$66*CHOOSE(Assumptions!$B$73,INDEX(Assumptions!$B$42:$H$42,MIN(J17,7)),INDEX(Assumptions!$B$43:$H$43,MIN(J17,7))),0)) -> 3000 | K18: =IF(K$2>Assumptions!$B$74,J18*(1-Assumptions!$B$75),IF(K17>=1,Assumptions!$B$66*CHOOSE(Assumptions!$B$73,INDEX(Assumptions!$B$42:$H$42,MIN(K17,7)),INDEX(Assumptions!$B$43:$H$43,MIN(K17,7))),0)) -> 3000 | ... Z18: =IF(Z$2>Assumptions!$B$74,Y18*(1-Assumptions!$B$75),IF(Z17>=1,Assumptions!$B$66*CHOOSE(Assumptions!$B$73,INDEX(Assumptions!$B$42:$H$42,MIN(Z17,7)),INDEX(Assumptions!$B$43:$H$43,MIN(Z17,7))),0)) -> 0.786432
A19: Product net sales, risk-adjusted | C19: =C18*MIN(1,Assumptions!$B$67*Assumptions!$B$37) -> 255 | D19: =D18*MIN(1,Assumptions!$B$67*Assumptions!$B$37) -> 637.5 | E19: =E18*MIN(1,Assumptions!$B$67*Assumptions!$B$37) -> 1147.5 | F19: =F18*MIN(1,Assumptions!$B$67*Assumptions!$B$37) -> 1657.5 | G19: =G18*MIN(1,Assumptions!$B$67*Assumptions!$B$37) -> 2091 | H19: =H18*MIN(1,Assumptions!$B$67*Assumptions!$B$37) -> 2371.5 | I19: =I18*MIN(1,Assumptions!$B$67*Assumptions!$B$37) -> 2550 | J19: =J18*MIN(1,Assumptions!$B$67*Assumptions!$B$37) -> 2550 | ... Z19: =Z18*MIN(1,Assumptions!$B$67*Assumptions!$B$37) -> 0.6684672
A20: Company revenue, risk-adjusted (incl. milestones) | C20: =C19*Assumptions!$B$68 -> 255 | D20: =D19*Assumptions!$B$68 -> 637.5 | E20: =E19*Assumptions!$B$68 -> 1147.5 | F20: =F19*Assumptions!$B$68 -> 1657.5 | G20: =G19*Assumptions!$B$68 -> 2091 | H20: =H19*Assumptions!$B$68 -> 2371.5 | I20: =I19*Assumptions!$B$68 -> 2550 | J20: =J19*Assumptions!$B$68 -> 2550 | ... Z20: =Z19*Assumptions!$B$68 -> 0.6684672
A21: COGS + royalties, risk-adjusted | C21: =C19*(Assumptions!$B$69+Assumptions!$B$70) -> 10.2 | D21: =D19*(Assumptions!$B$69+Assumptions!$B$70) -> 25.5 | E21: =E19*(Assumptions!$B$69+Assumptions!$B$70) -> 45.9 | F21: =F19*(Assumptions!$B$69+Assumptions!$B$70) -> 66.3 | G21: =G19*(Assumptions!$B$69+Assumptions!$B$70) -> 83.64 | H21: =H19*(Assumptions!$B$69+Assumptions!$B$70) -> 94.86 | I21: =I19*(Assumptions!$B$69+Assumptions!$B$70) -> 102 | J21: =J19*(Assumptions!$B$69+Assumptions!$B$70) -> 102 | ... Z21: =Z19*(Assumptions!$B$69+Assumptions!$B$70) -> 0.026738688
A22: Commercial SG&A, risk-adjusted | C22: =MIN(1,Assumptions!$B$67*Assumptions!$B$37)*IF(Assumptions!$B$71=0,0,IF(C17=0,Assumptions!$B$72,IF(C17>=1,C18*IF(OR(Assumptions!$B$68<1,C17>5),Assumptions!$B$71,MAX(Assumptions!$B$71,INDEX(Assumptions!$B$44:$F$44,C17))),0))) -> 229.5 | D22: =MIN(1,Assumptions!$B$67*Assumptions!$B$37)*IF(Assumptions!$B$71=0,0,IF(D17=0,Assumptions!$B$72,IF(D17>=1,D18*IF(OR(Assumptions!$B$68<1,D17>5),Assumptions!$B$71,MAX(Assumptions!$B$71,INDEX(Assumptions!$B$44:$F$44,D17))),0))) -> 350.625 | E22: =MIN(1,Assumptions!$B$67*Assumptions!$B$37)*IF(Assumptions!$B$71=0,0,IF(E17=0,Assumptions!$B$72,IF(E17>=1,E18*IF(OR(Assumptions!$B$68<1,E17>5),Assumptions!$B$71,MAX(Assumptions!$B$71,INDEX(Assumptions!$B$44:$F$44,E17))),0))) -> 459 | F22: =MIN(1,Assumptions!$B$67*Assumptions!$B$37)*IF(Assumptions!$B$71=0,0,IF(F17=0,Assumptions!$B$72,IF(F17>=1,F18*IF(OR(Assumptions!$B$68<1,F17>5),Assumptions!$B$71,MAX(Assumptions!$B$71,INDEX(Assumptions!$B$44:$F$44,F17))),0))) -> 530.4 | G22: =MIN(1,Assumptions!$B$67*Assumptions!$B$37)*IF(Assumptions!$B$71=0,0,IF(G17=0,Assumptions!$B$72,IF(G17>=1,G18*IF(OR(Assumptions!$B$68<1,G17>5),Assumptions!$B$71,MAX(Assumptions!$B$71,INDEX(Assumptions!$B$44:$F$44,G17))),0))) -> 627.3 | H22: =MIN(1,Assumptions!$B$67*Assumptions!$B$37)*IF(Assumptions!$B$71=0,0,IF(H17=0,Assumptions!$B$72,IF(H17>=1,H18*IF(OR(Assumptions!$B$68<1,H17>5),Assumptions!$B$71,MAX(Assumptions!$B$71,INDEX(Assumptions!$B$44:$F$44,H17))),0))) -> 711.45 | I22: =MIN(1,Assumptions!$B$67*Assumptions!$B$37)*IF(Assumptions!$B$71=0,0,IF(I17=0,Assumptions!$B$72,IF(I17>=1,I18*IF(OR(Assumptions!$B$68<1,I17>5),Assumptions!$B$71,MAX(Assumptions!$B$71,INDEX(Assumptions!$B$44:$F$44,I17))),0))) -> 765 | J22: =MIN(1,Assumptions!$B$67*Assumptions!$B$37)*IF(Assumptions!$B$71=0,0,IF(J17=0,Assumptions!$B$72,IF(J17>=1,J18*IF(OR(Assumptions!$B$68<1,J17>5),Assumptions!$B$71,MAX(Assumptions!$B$71,INDEX(Assumptions!$B$44:$F$44,J17))),0))) -> 765 | ... Z22: =MIN(1,Assumptions!$B$67*Assumptions!$B$37)*IF(Assumptions!$B$71=0,0,IF(Z17=0,Assumptions!$B$72,IF(Z17>=1,Z18*IF(OR(Assumptions!$B$68<1,Z17>5),Assumptions!$B$71,MAX(Assumptions!$B$71,INDEX(Assumptions!$B$44:$F$44,Z17))),0))) -> 0.20054016
A23: Development R&D, risk-adjusted | C23: =IFERROR(INDEX(Assumptions!$B$77:$I$77,MATCH(C$2,Assumptions!$B$76:$I$76,0))*INDEX(Assumptions!$B$78:$I$78,MATCH(C$2,Assumptions!$B$76:$I$76,0)),0) -> 20 | D23: =IFERROR(INDEX(Assumptions!$B$77:$I$77,MATCH(D$2,Assumptions!$B$76:$I$76,0))*INDEX(Assumptions!$B$78:$I$78,MATCH(D$2,Assumptions!$B$76:$I$76,0)),0) -> 0 | E23: =IFERROR(INDEX(Assumptions!$B$77:$I$77,MATCH(E$2,Assumptions!$B$76:$I$76,0))*INDEX(Assumptions!$B$78:$I$78,MATCH(E$2,Assumptions!$B$76:$I$76,0)),0) -> 0 | F23: =IFERROR(INDEX(Assumptions!$B$77:$I$77,MATCH(F$2,Assumptions!$B$76:$I$76,0))*INDEX(Assumptions!$B$78:$I$78,MATCH(F$2,Assumptions!$B$76:$I$76,0)),0) -> 0 | G23: =IFERROR(INDEX(Assumptions!$B$77:$I$77,MATCH(G$2,Assumptions!$B$76:$I$76,0))*INDEX(Assumptions!$B$78:$I$78,MATCH(G$2,Assumptions!$B$76:$I$76,0)),0) -> 0 | H23: =IFERROR(INDEX(Assumptions!$B$77:$I$77,MATCH(H$2,Assumptions!$B$76:$I$76,0))*INDEX(Assumptions!$B$78:$I$78,MATCH(H$2,Assumptions!$B$76:$I$76,0)),0) -> 0 | I23: =IFERROR(INDEX(Assumptions!$B$77:$I$77,MATCH(I$2,Assumptions!$B$76:$I$76,0))*INDEX(Assumptions!$B$78:$I$78,MATCH(I$2,Assumptions!$B$76:$I$76,0)),0) -> 0 | J23: =IFERROR(INDEX(Assumptions!$B$77:$I$77,MATCH(J$2,Assumptions!$B$76:$I$76,0))*INDEX(Assumptions!$B$78:$I$78,MATCH(J$2,Assumptions!$B$76:$I$76,0)),0) -> 0 | ... Z23: =IFERROR(INDEX(Assumptions!$B$77:$I$77,MATCH(Z$2,Assumptions!$B$76:$I$76,0))*INDEX(Assumptions!$B$78:$I$78,MATCH(Z$2,Assumptions!$B$76:$I$76,0)),0) -> 0
A24: Program contribution (pre-tax) | C24: =C20-C21-C22-C23 -> -4.7 | D24: =D20-D21-D22-D23 -> 261.375 | E24: =E20-E21-E22-E23 -> 642.6 | F24: =F20-F21-F22-F23 -> 1060.8 | G24: =G20-G21-G22-G23 -> 1380.06 | H24: =H20-H21-H22-H23 -> 1565.19 | I24: =I20-I21-I22-I23 -> 1683 | J24: =J20-J21-J22-J23 -> 1683 | ... Z24: =Z20-Z21-Z22-Z23 -> 0.44118835
A26: Relutrigine — broad DEEs (EMERALD, data Q4 2026)
A27: Years since launch | C27: =C$2-Assumptions!$B$81+1 -> 0 | D27: =D$2-Assumptions!$B$81+1 -> 1 | E27: =E$2-Assumptions!$B$81+1 -> 2 | F27: =F$2-Assumptions!$B$81+1 -> 3 | G27: =G$2-Assumptions!$B$81+1 -> 4 | H27: =H$2-Assumptions!$B$81+1 -> 5 | I27: =I$2-Assumptions!$B$81+1 -> 6 | J27: =J$2-Assumptions!$B$81+1 -> 7 | ... Z27: =Z$2-Assumptions!$B$81+1 -> 23
A28: Net sales, unrisked | C28: =IF(C$2>Assumptions!$B$90,0*(1-Assumptions!$B$91),IF(C27>=1,Assumptions!$B$82*CHOOSE(Assumptions!$B$89,INDEX(Assumptions!$B$42:$H$42,MIN(C27,7)),INDEX(Assumptions!$B$43:$H$43,MIN(C27,7))),0)) -> 0 | D28: =IF(D$2>Assumptions!$B$90,C28*(1-Assumptions!$B$91),IF(D27>=1,Assumptions!$B$82*CHOOSE(Assumptions!$B$89,INDEX(Assumptions!$B$42:$H$42,MIN(D27,7)),INDEX(Assumptions!$B$43:$H$43,MIN(D27,7))),0)) -> 180 | E28: =IF(E$2>Assumptions!$B$90,D28*(1-Assumptions!$B$91),IF(E27>=1,Assumptions!$B$82*CHOOSE(Assumptions!$B$89,INDEX(Assumptions!$B$42:$H$42,MIN(E27,7)),INDEX(Assumptions!$B$43:$H$43,MIN(E27,7))),0)) -> 420 | F28: =IF(F$2>Assumptions!$B$90,E28*(1-Assumptions!$B$91),IF(F27>=1,Assumptions!$B$82*CHOOSE(Assumptions!$B$89,INDEX(Assumptions!$B$42:$H$42,MIN(F27,7)),INDEX(Assumptions!$B$43:$H$43,MIN(F27,7))),0)) -> 660 | G28: =IF(G$2>Assumptions!$B$90,F28*(1-Assumptions!$B$91),IF(G27>=1,Assumptions!$B$82*CHOOSE(Assumptions!$B$89,INDEX(Assumptions!$B$42:$H$42,MIN(G27,7)),INDEX(Assumptions!$B$43:$H$43,MIN(G27,7))),0)) -> 900 | H28: =IF(H$2>Assumptions!$B$90,G28*(1-Assumptions!$B$91),IF(H27>=1,Assumptions!$B$82*CHOOSE(Assumptions!$B$89,INDEX(Assumptions!$B$42:$H$42,MIN(H27,7)),INDEX(Assumptions!$B$43:$H$43,MIN(H27,7))),0)) -> 1080 | I28: =IF(I$2>Assumptions!$B$90,H28*(1-Assumptions!$B$91),IF(I27>=1,Assumptions!$B$82*CHOOSE(Assumptions!$B$89,INDEX(Assumptions!$B$42:$H$42,MIN(I27,7)),INDEX(Assumptions!$B$43:$H$43,MIN(I27,7))),0)) -> 1200 | J28: =IF(J$2>Assumptions!$B$90,I28*(1-Assumptions!$B$91),IF(J27>=1,Assumptions!$B$82*CHOOSE(Assumptions!$B$89,INDEX(Assumptions!$B$42:$H$42,MIN(J27,7)),INDEX(Assumptions!$B$43:$H$43,MIN(J27,7))),0)) -> 1200 | K28: =IF(K$2>Assumptions!$B$90,J28*(1-Assumptions!$B$91),IF(K27>=1,Assumptions!$B$82*CHOOSE(Assumptions!$B$89,INDEX(Assumptions!$B$42:$H$42,MIN(K27,7)),INDEX(Assumptions!$B$43:$H$43,MIN(K27,7))),0)) -> 1200 | ... Z28: =IF(Z$2>Assumptions!$B$90,Y28*(1-Assumptions!$B$91),IF(Z27>=1,Assumptions!$B$82*CHOOSE(Assumptions!$B$89,INDEX(Assumptions!$B$42:$H$42,MIN(Z27,7)),INDEX(Assumptions!$B$43:$H$43,MIN(Z27,7))),0)) -> 0.3145728
A29: Product net sales, risk-adjusted | C29: =C28*MIN(1,Assumptions!$B$83*Assumptions!$B$37) -> 0 | D29: =D28*MIN(1,Assumptions!$B$83*Assumptions!$B$37) -> 81 | E29: =E28*MIN(1,Assumptions!$B$83*Assumptions!$B$37) -> 189 | F29: =F28*MIN(1,Assumptions!$B$83*Assumptions!$B$37) -> 297 | G29: =G28*MIN(1,Assumptions!$B$83*Assumptions!$B$37) -> 405 | H29: =H28*MIN(1,Assumptions!$B$83*Assumptions!$B$37) -> 486 | I29: =I28*MIN(1,Assumptions!$B$83*Assumptions!$B$37) -> 540 | J29: =J28*MIN(1,Assumptions!$B$83*Assumptions!$B$37) -> 540 | ... Z29: =Z28*MIN(1,Assumptions!$B$83*Assumptions!$B$37) -> 0.14155776
A30: Company revenue, risk-adjusted (incl. milestones) | C30: =C29*Assumptions!$B$84 -> 0 | D30: =D29*Assumptions!$B$84 -> 81 | E30: =E29*Assumptions!$B$84 -> 189 | F30: =F29*Assumptions!$B$84 -> 297 | G30: =G29*Assumptions!$B$84 -> 405 | H30: =H29*Assumptions!$B$84 -> 486 | I30: =I29*Assumptions!$B$84 -> 540 | J30: =J29*Assumptions!$B$84 -> 540 | ... Z30: =Z29*Assumptions!$B$84 -> 0.14155776
A31: COGS + royalties, risk-adjusted | C31: =C29*(Assumptions!$B$85+Assumptions!$B$86) -> 0 | D31: =D29*(Assumptions!$B$85+Assumptions!$B$86) -> 3.24 | E31: =E29*(Assumptions!$B$85+Assumptions!$B$86) -> 7.56 | F31: =F29*(Assumptions!$B$85+Assumptions!$B$86) -> 11.88 | G31: =G29*(Assumptions!$B$85+Assumptions!$B$86) -> 16.2 | H31: =H29*(Assumptions!$B$85+Assumptions!$B$86) -> 19.44 | I31: =I29*(Assumptions!$B$85+Assumptions!$B$86) -> 21.6 | J31: =J29*(Assumptions!$B$85+Assumptions!$B$86) -> 21.6 | ... Z31: =Z29*(Assumptions!$B$85+Assumptions!$B$86) -> 0.0056623104
A32: Commercial SG&A, risk-adjusted | C32: =MIN(1,Assumptions!$B$83*Assumptions!$B$37)*IF(Assumptions!$B$87=0,0,IF(C27=0,Assumptions!$B$88,IF(C27>=1,C28*IF(OR(Assumptions!$B$84<1,C27>5),Assumptions!$B$87,MAX(Assumptions!$B$87,INDEX(Assumptions!$B$44:$F$44,C27))),0))) -> 9 | D32: =MIN(1,Assumptions!$B$83*Assumptions!$B$37)*IF(Assumptions!$B$87=0,0,IF(D27=0,Assumptions!$B$88,IF(D27>=1,D28*IF(OR(Assumptions!$B$84<1,D27>5),Assumptions!$B$87,MAX(Assumptions!$B$87,INDEX(Assumptions!$B$44:$F$44,D27))),0))) -> 72.9 | E32: =MIN(1,Assumptions!$B$83*Assumptions!$B$37)*IF(Assumptions!$B$87=0,0,IF(E27=0,Assumptions!$B$88,IF(E27>=1,E28*IF(OR(Assumptions!$B$84<1,E27>5),Assumptions!$B$87,MAX(Assumptions!$B$87,INDEX(Assumptions!$B$44:$F$44,E27))),0))) -> 103.95 | F32: =MIN(1,Assumptions!$B$83*Assumptions!$B$37)*IF(Assumptions!$B$87=0,0,IF(F27=0,Assumptions!$B$88,IF(F27>=1,F28*IF(OR(Assumptions!$B$84<1,F27>5),Assumptions!$B$87,MAX(Assumptions!$B$87,INDEX(Assumptions!$B$44:$F$44,F27))),0))) -> 118.8 | G32: =MIN(1,Assumptions!$B$83*Assumptions!$B$37)*IF(Assumptions!$B$87=0,0,IF(G27=0,Assumptions!$B$88,IF(G27>=1,G28*IF(OR(Assumptions!$B$84<1,G27>5),Assumptions!$B$87,MAX(Assumptions!$B$87,INDEX(Assumptions!$B$44:$F$44,G27))),0))) -> 129.6 | H32: =MIN(1,Assumptions!$B$83*Assumptions!$B$37)*IF(Assumptions!$B$87=0,0,IF(H27=0,Assumptions!$B$88,IF(H27>=1,H28*IF(OR(Assumptions!$B$84<1,H27>5),Assumptions!$B$87,MAX(Assumptions!$B$87,INDEX(Assumptions!$B$44:$F$44,H27))),0))) -> 136.08 | I32: =MIN(1,Assumptions!$B$83*Assumptions!$B$37)*IF(Assumptions!$B$87=0,0,IF(I27=0,Assumptions!$B$88,IF(I27>=1,I28*IF(OR(Assumptions!$B$84<1,I27>5),Assumptions!$B$87,MAX(Assumptions!$B$87,INDEX(Assumptions!$B$44:$F$44,I27))),0))) -> 108 | J32: =MIN(1,Assumptions!$B$83*Assumptions!$B$37)*IF(Assumptions!$B$87=0,0,IF(J27=0,Assumptions!$B$88,IF(J27>=1,J28*IF(OR(Assumptions!$B$84<1,J27>5),Assumptions!$B$87,MAX(Assumptions!$B$87,INDEX(Assumptions!$B$44:$F$44,J27))),0))) -> 108 | ... Z32: =MIN(1,Assumptions!$B$83*Assumptions!$B$37)*IF(Assumptions!$B$87=0,0,IF(Z27=0,Assumptions!$B$88,IF(Z27>=1,Z28*IF(OR(Assumptions!$B$84<1,Z27>5),Assumptions!$B$87,MAX(Assumptions!$B$87,INDEX(Assumptions!$B$44:$F$44,Z27))),0))) -> 0.028311552
A33: Development R&D, risk-adjusted | C33: =IFERROR(INDEX(Assumptions!$B$93:$I$93,MATCH(C$2,Assumptions!$B$92:$I$92,0))*INDEX(Assumptions!$B$94:$I$94,MATCH(C$2,Assumptions!$B$92:$I$92,0)),0) -> 15 | D33: =IFERROR(INDEX(Assumptions!$B$93:$I$93,MATCH(D$2,Assumptions!$B$92:$I$92,0))*INDEX(Assumptions!$B$94:$I$94,MATCH(D$2,Assumptions!$B$92:$I$92,0)),0) -> 0 | E33: =IFERROR(INDEX(Assumptions!$B$93:$I$93,MATCH(E$2,Assumptions!$B$92:$I$92,0))*INDEX(Assumptions!$B$94:$I$94,MATCH(E$2,Assumptions!$B$92:$I$92,0)),0) -> 0 | F33: =IFERROR(INDEX(Assumptions!$B$93:$I$93,MATCH(F$2,Assumptions!$B$92:$I$92,0))*INDEX(Assumptions!$B$94:$I$94,MATCH(F$2,Assumptions!$B$92:$I$92,0)),0) -> 0 | G33: =IFERROR(INDEX(Assumptions!$B$93:$I$93,MATCH(G$2,Assumptions!$B$92:$I$92,0))*INDEX(Assumptions!$B$94:$I$94,MATCH(G$2,Assumptions!$B$92:$I$92,0)),0) -> 0 | H33: =IFERROR(INDEX(Assumptions!$B$93:$I$93,MATCH(H$2,Assumptions!$B$92:$I$92,0))*INDEX(Assumptions!$B$94:$I$94,MATCH(H$2,Assumptions!$B$92:$I$92,0)),0) -> 0 | I33: =IFERROR(INDEX(Assumptions!$B$93:$I$93,MATCH(I$2,Assumptions!$B$92:$I$92,0))*INDEX(Assumptions!$B$94:$I$94,MATCH(I$2,Assumptions!$B$92:$I$92,0)),0) -> 0 | J33: =IFERROR(INDEX(Assumptions!$B$93:$I$93,MATCH(J$2,Assumptions!$B$92:$I$92,0))*INDEX(Assumptions!$B$94:$I$94,MATCH(J$2,Assumptions!$B$92:$I$92,0)),0) -> 0 | ... Z33: =IFERROR(INDEX(Assumptions!$B$93:$I$93,MATCH(Z$2,Assumptions!$B$92:$I$92,0))*INDEX(Assumptions!$B$94:$I$94,MATCH(Z$2,Assumptions!$B$92:$I$92,0)),0) -> 0
A34: Program contribution (pre-tax) | C34: =C30-C31-C32-C33 -> -24 | D34: =D30-D31-D32-D33 -> 4.86 | E34: =E30-E31-E32-E33 -> 77.49 | F34: =F30-F31-F32-F33 -> 166.32 | G34: =G30-G31-G32-G33 -> 259.2 | H34: =H30-H31-H32-H33 -> 330.48 | I34: =I30-I31-I32-I33 -> 410.4 | J34: =J30-J31-J32-J33 -> 410.4 | ... Z34: =Z30-Z31-Z32-Z33 -> 0.1075839
A36: Vormatrigine — focal / generalized epilepsy (POWER2/3)
A37: Years since launch | C37: =C$2-Assumptions!$B$97+1 -> -2 | D37: =D$2-Assumptions!$B$97+1 -> -1 | E37: =E$2-Assumptions!$B$97+1 -> 0 | F37: =F$2-Assumptions!$B$97+1 -> 1 | G37: =G$2-Assumptions!$B$97+1 -> 2 | H37: =H$2-Assumptions!$B$97+1 -> 3 | I37: =I$2-Assumptions!$B$97+1 -> 4 | J37: =J$2-Assumptions!$B$97+1 -> 5 | ... Z37: =Z$2-Assumptions!$B$97+1 -> 21
A38: Net sales, unrisked | C38: =IF(C$2>Assumptions!$B$106,0*(1-Assumptions!$B$107),IF(C37>=1,Assumptions!$B$98*CHOOSE(Assumptions!$B$105,INDEX(Assumptions!$B$42:$H$42,MIN(C37,7)),INDEX(Assumptions!$B$43:$H$43,MIN(C37,7))),0)) -> 0 | D38: =IF(D$2>Assumptions!$B$106,C38*(1-Assumptions!$B$107),IF(D37>=1,Assumptions!$B$98*CHOOSE(Assumptions!$B$105,INDEX(Assumptions!$B$42:$H$42,MIN(D37,7)),INDEX(Assumptions!$B$43:$H$43,MIN(D37,7))),0)) -> 0 | E38: =IF(E$2>Assumptions!$B$106,D38*(1-Assumptions!$B$107),IF(E37>=1,Assumptions!$B$98*CHOOSE(Assumptions!$B$105,INDEX(Assumptions!$B$42:$H$42,MIN(E37,7)),INDEX(Assumptions!$B$43:$H$43,MIN(E37,7))),0)) -> 0 | F38: =IF(F$2>Assumptions!$B$106,E38*(1-Assumptions!$B$107),IF(F37>=1,Assumptions!$B$98*CHOOSE(Assumptions!$B$105,INDEX(Assumptions!$B$42:$H$42,MIN(F37,7)),INDEX(Assumptions!$B$43:$H$43,MIN(F37,7))),0)) -> 150 | G38: =IF(G$2>Assumptions!$B$106,F38*(1-Assumptions!$B$107),IF(G37>=1,Assumptions!$B$98*CHOOSE(Assumptions!$B$105,INDEX(Assumptions!$B$42:$H$42,MIN(G37,7)),INDEX(Assumptions!$B$43:$H$43,MIN(G37,7))),0)) -> 375 | H38: =IF(H$2>Assumptions!$B$106,G38*(1-Assumptions!$B$107),IF(H37>=1,Assumptions!$B$98*CHOOSE(Assumptions!$B$105,INDEX(Assumptions!$B$42:$H$42,MIN(H37,7)),INDEX(Assumptions!$B$43:$H$43,MIN(H37,7))),0)) -> 675 | I38: =IF(I$2>Assumptions!$B$106,H38*(1-Assumptions!$B$107),IF(I37>=1,Assumptions!$B$98*CHOOSE(Assumptions!$B$105,INDEX(Assumptions!$B$42:$H$42,MIN(I37,7)),INDEX(Assumptions!$B$43:$H$43,MIN(I37,7))),0)) -> 975 | J38: =IF(J$2>Assumptions!$B$106,I38*(1-Assumptions!$B$107),IF(J37>=1,Assumptions!$B$98*CHOOSE(Assumptions!$B$105,INDEX(Assumptions!$B$42:$H$42,MIN(J37,7)),INDEX(Assumptions!$B$43:$H$43,MIN(J37,7))),0)) -> 1230 | K38: =IF(K$2>Assumptions!$B$106,J38*(1-Assumptions!$B$107),IF(K37>=1,Assumptions!$B$98*CHOOSE(Assumptions!$B$105,INDEX(Assumptions!$B$42:$H$42,MIN(K37,7)),INDEX(Assumptions!$B$43:$H$43,MIN(K37,7))),0)) -> 1395 | ... Z38: =IF(Z$2>Assumptions!$B$106,Y38*(1-Assumptions!$B$107),IF(Z37>=1,Assumptions!$B$98*CHOOSE(Assumptions!$B$105,INDEX(Assumptions!$B$42:$H$42,MIN(Z37,7)),INDEX(Assumptions!$B$43:$H$43,MIN(Z37,7))),0)) -> 2.4576
A39: Product net sales, risk-adjusted | C39: =C38*MIN(1,Assumptions!$B$99*Assumptions!$B$37) -> 0 | D39: =D38*MIN(1,Assumptions!$B$99*Assumptions!$B$37) -> 0 | E39: =E38*MIN(1,Assumptions!$B$99*Assumptions!$B$37) -> 0 | F39: =F38*MIN(1,Assumptions!$B$99*Assumptions!$B$37) -> 30 | G39: =G38*MIN(1,Assumptions!$B$99*Assumptions!$B$37) -> 75 | H39: =H38*MIN(1,Assumptions!$B$99*Assumptions!$B$37) -> 135 | I39: =I38*MIN(1,Assumptions!$B$99*Assumptions!$B$37) -> 195 | J39: =J38*MIN(1,Assumptions!$B$99*Assumptions!$B$37) -> 246 | ... Z39: =Z38*MIN(1,Assumptions!$B$99*Assumptions!$B$37) -> 0.49152
A40: Company revenue, risk-adjusted (incl. milestones) | C40: =C39*Assumptions!$B$100 -> 0 | D40: =D39*Assumptions!$B$100 -> 0 | E40: =E39*Assumptions!$B$100 -> 0 | F40: =F39*Assumptions!$B$100 -> 30 | G40: =G39*Assumptions!$B$100 -> 75 | H40: =H39*Assumptions!$B$100 -> 135 | I40: =I39*Assumptions!$B$100 -> 195 | J40: =J39*Assumptions!$B$100 -> 246 | ... Z40: =Z39*Assumptions!$B$100 -> 0.49152
A41: COGS + royalties, risk-adjusted | C41: =C39*(Assumptions!$B$101+Assumptions!$B$102) -> 0 | D41: =D39*(Assumptions!$B$101+Assumptions!$B$102) -> 0 | E41: =E39*(Assumptions!$B$101+Assumptions!$B$102) -> 0 | F41: =F39*(Assumptions!$B$101+Assumptions!$B$102) -> 1.2 | G41: =G39*(Assumptions!$B$101+Assumptions!$B$102) -> 3 | H41: =H39*(Assumptions!$B$101+Assumptions!$B$102) -> 5.4 | I41: =I39*(Assumptions!$B$101+Assumptions!$B$102) -> 7.8 | J41: =J39*(Assumptions!$B$101+Assumptions!$B$102) -> 9.84 | ... Z41: =Z39*(Assumptions!$B$101+Assumptions!$B$102) -> 0.0196608
A42: Commercial SG&A, risk-adjusted | C42: =MIN(1,Assumptions!$B$99*Assumptions!$B$37)*IF(Assumptions!$B$103=0,0,IF(C37=0,Assumptions!$B$104,IF(C37>=1,C38*IF(OR(Assumptions!$B$100<1,C37>5),Assumptions!$B$103,MAX(Assumptions!$B$103,INDEX(Assumptions!$B$44:$F$44,C37))),0))) -> 0 | D42: =MIN(1,Assumptions!$B$99*Assumptions!$B$37)*IF(Assumptions!$B$103=0,0,IF(D37=0,Assumptions!$B$104,IF(D37>=1,D38*IF(OR(Assumptions!$B$100<1,D37>5),Assumptions!$B$103,MAX(Assumptions!$B$103,INDEX(Assumptions!$B$44:$F$44,D37))),0))) -> 0 | E42: =MIN(1,Assumptions!$B$99*Assumptions!$B$37)*IF(Assumptions!$B$103=0,0,IF(E37=0,Assumptions!$B$104,IF(E37>=1,E38*IF(OR(Assumptions!$B$100<1,E37>5),Assumptions!$B$103,MAX(Assumptions!$B$103,INDEX(Assumptions!$B$44:$F$44,E37))),0))) -> 8 | F42: =MIN(1,Assumptions!$B$99*Assumptions!$B$37)*IF(Assumptions!$B$103=0,0,IF(F37=0,Assumptions!$B$104,IF(F37>=1,F38*IF(OR(Assumptions!$B$100<1,F37>5),Assumptions!$B$103,MAX(Assumptions!$B$103,INDEX(Assumptions!$B$44:$F$44,F37))),0))) -> 27 | G42: =MIN(1,Assumptions!$B$99*Assumptions!$B$37)*IF(Assumptions!$B$103=0,0,IF(G37=0,Assumptions!$B$104,IF(G37>=1,G38*IF(OR(Assumptions!$B$100<1,G37>5),Assumptions!$B$103,MAX(Assumptions!$B$103,INDEX(Assumptions!$B$44:$F$44,G37))),0))) -> 41.25 | H42: =MIN(1,Assumptions!$B$99*Assumptions!$B$37)*IF(Assumptions!$B$103=0,0,IF(H37=0,Assumptions!$B$104,IF(H37>=1,H38*IF(OR(Assumptions!$B$100<1,H37>5),Assumptions!$B$103,MAX(Assumptions!$B$103,INDEX(Assumptions!$B$44:$F$44,H37))),0))) -> 54 | I42: =MIN(1,Assumptions!$B$99*Assumptions!$B$37)*IF(Assumptions!$B$103=0,0,IF(I37=0,Assumptions!$B$104,IF(I37>=1,I38*IF(OR(Assumptions!$B$100<1,I37>5),Assumptions!$B$103,MAX(Assumptions!$B$103,INDEX(Assumptions!$B$44:$F$44,I37))),0))) -> 62.4 | J42: =MIN(1,Assumptions!$B$99*Assumptions!$B$37)*IF(Assumptions!$B$103=0,0,IF(J37=0,Assumptions!$B$104,IF(J37>=1,J38*IF(OR(Assumptions!$B$100<1,J37>5),Assumptions!$B$103,MAX(Assumptions!$B$103,INDEX(Assumptions!$B$44:$F$44,J37))),0))) -> 73.8 | ... Z42: =MIN(1,Assumptions!$B$99*Assumptions!$B$37)*IF(Assumptions!$B$103=0,0,IF(Z37=0,Assumptions!$B$104,IF(Z37>=1,Z38*IF(OR(Assumptions!$B$100<1,Z37>5),Assumptions!$B$103,MAX(Assumptions!$B$103,INDEX(Assumptions!$B$44:$F$44,Z37))),0))) -> 0.147456
A43: Development R&D, risk-adjusted | C43: =IFERROR(INDEX(Assumptions!$B$109:$I$109,MATCH(C$2,Assumptions!$B$108:$I$108,0))*INDEX(Assumptions!$B$110:$I$110,MATCH(C$2,Assumptions!$B$108:$I$108,0)),0) -> 80 | D43: =IFERROR(INDEX(Assumptions!$B$109:$I$109,MATCH(D$2,Assumptions!$B$108:$I$108,0))*INDEX(Assumptions!$B$110:$I$110,MATCH(D$2,Assumptions!$B$108:$I$108,0)),0) -> 80 | E43: =IFERROR(INDEX(Assumptions!$B$109:$I$109,MATCH(E$2,Assumptions!$B$108:$I$108,0))*INDEX(Assumptions!$B$110:$I$110,MATCH(E$2,Assumptions!$B$108:$I$108,0)),0) -> 20 | F43: =IFERROR(INDEX(Assumptions!$B$109:$I$109,MATCH(F$2,Assumptions!$B$108:$I$108,0))*INDEX(Assumptions!$B$110:$I$110,MATCH(F$2,Assumptions!$B$108:$I$108,0)),0) -> 0 | G43: =IFERROR(INDEX(Assumptions!$B$109:$I$109,MATCH(G$2,Assumptions!$B$108:$I$108,0))*INDEX(Assumptions!$B$110:$I$110,MATCH(G$2,Assumptions!$B$108:$I$108,0)),0) -> 0 | H43: =IFERROR(INDEX(Assumptions!$B$109:$I$109,MATCH(H$2,Assumptions!$B$108:$I$108,0))*INDEX(Assumptions!$B$110:$I$110,MATCH(H$2,Assumptions!$B$108:$I$108,0)),0) -> 0 | I43: =IFERROR(INDEX(Assumptions!$B$109:$I$109,MATCH(I$2,Assumptions!$B$108:$I$108,0))*INDEX(Assumptions!$B$110:$I$110,MATCH(I$2,Assumptions!$B$108:$I$108,0)),0) -> 0 | J43: =IFERROR(INDEX(Assumptions!$B$109:$I$109,MATCH(J$2,Assumptions!$B$108:$I$108,0))*INDEX(Assumptions!$B$110:$I$110,MATCH(J$2,Assumptions!$B$108:$I$108,0)),0) -> 0 | ... Z43: =IFERROR(INDEX(Assumptions!$B$109:$I$109,MATCH(Z$2,Assumptions!$B$108:$I$108,0))*INDEX(Assumptions!$B$110:$I$110,MATCH(Z$2,Assumptions!$B$108:$I$108,0)),0) -> 0
A44: Program contribution (pre-tax) | C44: =C40-C41-C42-C43 -> -80 | D44: =D40-D41-D42-D43 -> -80 | E44: =E40-E41-E42-E43 -> -28 | F44: =F40-F41-F42-F43 -> 1.8 | G44: =G40-G41-G42-G43 -> 30.75 | H44: =H40-H41-H42-H43 -> 75.6 | I44: =I40-I41-I42-I43 -> 124.8 | J44: =J40-J41-J42-J43 -> 162.36 | ... Z44: =Z40-Z41-Z42-Z43 -> 0.3244032
...

Sheet NPV
A1: PRAX — risk-adjusted NPV (rNPV), $mm except per share
A3: Scenario | B3: =Assumptions!$C$4 -> Base
A4: Valuation date | B4: =Assumptions!$B$13 -> 46311
A5: Discount rate | B5: =Assumptions!$B$14 -> 0.11
A7: Period | C7: 2H 2026 | D7: 2027 | E7: 2028 | F7: 2029 | G7: 2030 | H7: 2031 | I7: 2032 | J7: 2033 | K7: 2034 | L7: 2035 | M7: 2036 | N7: 2037 | O7: 2038 | P7: 2039 | Q7: 2040 | R7: 2041 | S7: 2042 | T7: 2043 | U7: 2044 | V7: 2045 | W7: 2046 | X7: 2047 | Y7: 2048 | Z7: 2049 | AA7: 2050
A8: Revenue, risk-adjusted | C8: =SUM('Quarterly Model'!H2:I2) -> 0 | D8: ='Yearly Model'!H2 -> 471 | E8: ='Yearly Model'!I2 -> 925.5 | F8: ='Yearly Model'!J2 -> 1683 | G8: ='Yearly Model'!K2 -> 2493 | H8: ='Yearly Model'!L2 -> 3214.5 | I8: ='Yearly Model'!M2 -> 3741.75 | J8: ='Yearly Model'!N2 -> 4072.5 | K8: ='Yearly Model'!O2 -> 4146 | ... AA8: ='Yearly Model'!AE2 -> 2.3338055
A9: Operating income (EBIT) | C9: =SUM('Quarterly Model'!H8:I8) -> -217 | D9: ='Yearly Model'!H8 -> -280.715 | E9: ='Yearly Model'!I8 -> -29.47 | F9: ='Yearly Model'!J8 -> 528.9425 | G9: ='Yearly Model'!K8 -> 1032.5175 | H9: ='Yearly Model'!L8 -> 1443.54 | I9: ='Yearly Model'!M8 -> 1735.11 | J9: ='Yearly Model'!N8 -> 1948.65 | K9: ='Yearly Model'!O8 -> 2003.91 | ... AA9: ='Yearly Model'!AE8 -> 1.1481084
A10: Taxes on EBIT (after tax-loss pool) | C10: 0 | D10: =IF(D9>0,MAX(0,D9-'Yearly Model'!G21)*Assumptions!$B$15,0) -> 0 | E10: =IF(E9>0,MAX(0,E9-'Yearly Model'!H21)*Assumptions!$B$15,0) -> 0 | F10: =IF(F9>0,MAX(0,F9-'Yearly Model'!I21)*Assumptions!$B$15,0) -> 0 | G10: =IF(G9>0,MAX(0,G9-'Yearly Model'!J21)*Assumptions!$B$15,0) -> 0 | H10: =IF(H9>0,MAX(0,H9-'Yearly Model'!K21)*Assumptions!$B$15,0) -> 272.87754 | I10: =IF(I9>0,MAX(0,I9-'Yearly Model'!L21)*Assumptions!$B$15,0) -> 364.3731 | J10: =IF(J9>0,MAX(0,J9-'Yearly Model'!M21)*Assumptions!$B$15,0) -> 409.2165 | K10: =IF(K9>0,MAX(0,K9-'Yearly Model'!N21)*Assumptions!$B$15,0) -> 420.8211 | ... AA10: =IF(AA9>0,MAX(0,AA9-'Yearly Model'!AD21)*Assumptions!$B$15,0) -> 0.24110276
A11: Unlevered free cash flow | C11: =C9-C10 -> -217 | D11: =D9-D10 -> -280.715 | E11: =E9-E10 -> -29.47 | F11: =F9-F10 -> 528.9425 | G11: =G9-G10 -> 1032.5175 | H11: =H9-H10 -> 1170.6625 | I11: =I9-I10 -> 1370.7369 | J11: =J9-J10 -> 1539.4335 | ... AA11: =AA9-AA10 -> 0.90700561
A12: Cash-flow date (mid-period) | C12: =DATE(2026,10,1) -> 46296 | D12: =DATE(D7,7,1) -> 46569 | E12: =DATE(E7,7,1) -> 46935 | F12: =DATE(F7,7,1) -> 47300 | G12: =DATE(G7,7,1) -> 47665 | H12: =DATE(H7,7,1) -> 48030 | I12: =DATE(I7,7,1) -> 48396 | J12: =DATE(J7,7,1) -> 48761 | K12: =DATE(K7,7,1) -> 49126 | ... AA12: =DATE(AA7,7,1) -> 54970
A13: Years from valuation date | C13: =MAX(0,(C12-$B$4)/365.25) -> 0 | D13: =MAX(0,(D12-$B$4)/365.25) -> 0.7063655 | E13: =MAX(0,(E12-$B$4)/365.25) -> 1.7084189 | F13: =MAX(0,(F12-$B$4)/365.25) -> 2.7077344 | G13: =MAX(0,(G12-$B$4)/365.25) -> 3.70705 | H13: =MAX(0,(H12-$B$4)/365.25) -> 4.7063655 | I13: =MAX(0,(I12-$B$4)/365.25) -> 5.7084189 | J13: =MAX(0,(J12-$B$4)/365.25) -> 6.7077344 | ... AA13: =MAX(0,(AA12-$B$4)/365.25) -> 23.70705
A14: Discount factor | C14: =1/(1+$B$5)^C13 -> 1 | D14: =1/(1+$B$5)^D13 -> 0.92893518 | E14: =1/(1+$B$5)^E13 -> 0.83669923 | F14: =1/(1+$B$5)^F13 -> 0.75383693 | G14: =1/(1+$B$5)^G13 -> 0.67918088 | H14: =1/(1+$B$5)^H13 -> 0.61191838 | I14: =1/(1+$B$5)^I13 -> 0.5511597 | J14: =1/(1+$B$5)^J13 -> 0.49657574 | ... AA14: =1/(1+$B$5)^AA13 -> 0.084241458
A15: PV of free cash flow | C15: =C11*C14 -> -217 | D15: =D11*D14 -> -260.76604 | E15: =E11*E14 -> -24.657526 | F15: =F11*F14 -> 398.73639 | G15: =G11*G14 -> 701.26615 | H15: =H11*H14 -> 716.34987 | I15: =I11*I14 -> 755.49493 | J15: =J11*J14 -> 764.44532 | ... AA15: =AA11*AA14 -> 0.076407476
A17: Valuation summary
A18: PV of risk-adjusted free cash flows | C18: =SUM(C15:AA15) -> 7167.3182
A19: Cash & investments (Main; incl. post-quarter financing) | C19: =Main!C7 -> 1373.84
A20: Debt, convertibles & preferred at face (Main) | C20: =Main!C8 -> 0
A21: Equity value, all claims treated as debt | C21: =C18+C19-C20 -> 8541.1582
A22: Basic shares incl. pre-funded / as-converted (Main) | C22: =Main!C4 -> 29.163921
A23: Value / share before conversions | C23: =C21/C22 -> 292.86728
A25: Convertible instruments (converted if value / share before conversions > conversion price) | B25: Face ($mm) | C25: Shares (mm) | D25: Conv. price | E25: Converted?
A26: — | B26: 0 | C26: 0 | D26: 0 | E26: =IF(AND(C26>0,$C$23>D26),1,0) -> 0
A27: — | B27: 0 | C27: 0 | D27: 0 | E27: =IF(AND(C27>0,$C$23>D27),1,0) -> 0
A28: — | B28: 0 | C28: 0 | D28: 0 | E28: =IF(AND(C28>0,$C$23>D28),1,0) -> 0
A29: — | B29: 0 | C29: 0 | D29: 0 | E29: =IF(AND(C29>0,$C$23>D29),1,0) -> 0
A30: — | B30: 0 | C30: 0 | D30: 0 | E30: =IF(AND(C30>0,$C$23>D30),1,0) -> 0
A31: Equity value (rNPV) after conversions | C31: =C21+SUMPRODUCT(B26:B30,E26:E30) -> 8541.1582
A32: Shares after conversions (mm) | C32: =C22+SUMPRODUCT(C26:C30,E26:E30) -> 29.163921
A33: Value / share before options & warrants | C33: =C31/C32 -> 292.86728
