Workbook

Sheet Main
B2: PolyPid Ltd
B3: Price | C3: =INDEX([1]Pharma!$F$1:$F$1000,MATCH("PYPD",[1]Pharma!$B$1:$B$1000,0)) -> 5.15
B4: Shares | C4: =20.311766+2.828319 -> 23.140085
B5: Market Cap. | C5: =C3*C4 -> 119.17144
B7: Cash | C7: =6.563+30 -> 36.563
B8: Debt | C8: 0
B9: Enterprise V. | C9: =C5-C7+C8 -> 82.608438
B11: rNPV / Share | C11: =NPV!C43 -> 7.0697126
B12: Upside | C12: =C11/C3-1 -> 0.37275972
B13: Cash / Share | C13: =(C7-C8)/C4 -> 1.580072
B14: Scenario | C14: =Assumptions!$C$4 -> Base
B16: PDUFA Date | C16: =Assumptions!$B$30 -> 46354
B17: P(Approval) | C17: =Assumptions!$B$32 -> 0.8
B18: If Approved | C18: =Assumptions!$D$94 -> 7.4673244
B19: If CRL | C19: =Assumptions!$D$93 -> 5.3812697

Sheet Yearly Model
B1: 2021 | C1: 2022 | D1: 2023 | E1: 2024 | F1: 2025 | G1: 2026 | H1: 2027 | I1: 2028 | J1: 2029 | K1: 2030 | L1: 2031 | M1: 2032 | N1: 2033 | O1: 2034 | P1: 2035 | Q1: 2036 | R1: 2037 | S1: 2038 | T1: 2039 | U1: 2040 | V1: 2041 | W1: 2042 | X1: 2043 | Y1: 2044 | Z1: 2045 | AA1: 2046 | AB1: 2047 | AC1: 2048 | AD1: 2049 | AE1: 2050
A2: Revenue | B2: 0 | C2: 0 | D2: 0 | E2: 0 | F2: 0 | G2: =SUM('Quarterly Model'!F2:I2) -> 0 | H2: =Pipeline!C27 -> 35.52 | I2: =Pipeline!D27 -> 10.3 | J2: =Pipeline!E27 -> 24.918 | K2: =Pipeline!F27 -> 50.95 | L2: =Pipeline!G27 -> 40.99 | M2: =Pipeline!H27 -> 71.468 | N2: =Pipeline!I27 -> 53.4796 | O2: =Pipeline!J27 -> 78.1104 | ... AE2: =Pipeline!Z27 -> 0.054179687
A3: Cost of Sales | B3: 0 | C3: 0 | D3: 0 | E3: 0 | F3: 0 | G3: =SUM('Quarterly Model'!F3:I3) -> 0 | H3: =Pipeline!C28 -> 0 | I3: =Pipeline!D28 -> 0 | J3: =Pipeline!E28 -> 0 | K3: =Pipeline!F28 -> 0 | L3: =Pipeline!G28 -> 0 | M3: =Pipeline!H28 -> 0 | N3: =Pipeline!I28 -> 0 | O3: =Pipeline!J28 -> 0 | ... AE3: =Pipeline!Z28 -> 0
A4: Gross Margin | B4: =B2-B3 -> 0 | C4: =C2-C3 -> 0 | D4: =D2-D3 -> 0 | E4: =E2-E3 -> 0 | F4: =F2-F3 -> 0 | G4: =G2-G3 -> 0 | H4: =H2-H3 -> 35.52 | I4: =I2-I3 -> 10.3 | ... AE4: =AE2-AE3 -> 0.054179687
A5: Research & Dev. | B5: 30.553 | C5: 27.99 | D5: 16.148 | E5: 22.811 | F5: 23.807 | G5: =SUM('Quarterly Model'!F5:I5) -> 23.881 | H5: =Pipeline!C31 -> 12.16 | I5: =Pipeline!D31 -> 7.3148 | J5: =Pipeline!E31 -> 5.474244 | K5: =Pipeline!F31 -> 5.6384713 | L5: =Pipeline!G31 -> 5.8076255 | M5: =Pipeline!H31 -> 5.9818542 | N5: =Pipeline!I31 -> 6.1613099 | O5: =Pipeline!J31 -> 6.3461491 | ... AE5: =Pipeline!Z31 -> 0.0032507812
A6: General & Admin | B6: 12.592 | C6: 10.898 | D6: 6.719 | E6: 5.218 | F6: 9.16 | G6: =SUM('Quarterly Model'!F6:I6) -> 8.328 | H6: =Pipeline!C34 -> 6.02 | I6: =Pipeline!D34 -> 6.2006 | J6: =Pipeline!E34 -> 6.386618 | K6: =Pipeline!F34 -> 6.5782165 | L6: =Pipeline!G34 -> 6.775563 | M6: =Pipeline!H34 -> 6.9788299 | N6: =Pipeline!I34 -> 7.1881948 | O6: =Pipeline!J34 -> 7.4038407 | ... AE6: =Pipeline!Z34 -> 0.004334375
A7: Operating Expense | B7: =SUM(B5:B6) -> 43.145 | C7: =SUM(C5:C6) -> 38.888 | D7: =SUM(D5:D6) -> 22.867 | E7: =SUM(E5:E6) -> 28.029 | F7: =SUM(F5:F6) -> 32.967 | G7: =SUM(G5:G6) -> 32.209 | H7: =SUM(H5:H6) -> 18.18 | I7: =SUM(I5:I6) -> 13.5154 | ... AE7: =SUM(AE5:AE6) -> 0.0075851562
A8: Operating Income | B8: =B4-B7 -> -43.145 | C8: =C4-C7 -> -38.888 | D8: =D4-D7 -> -22.867 | E8: =E4-E7 -> -28.029 | F8: =F4-F7 -> -32.967 | G8: =G4-G7 -> -32.209 | H8: =H4-H7 -> 17.34 | I8: =I4-I7 -> -3.2154 | ... AE8: =AE4-AE7 -> 0.046594531
A9: Interest & Other | B9: 0.544 | C9: -0.54 | D9: -0.929 | E9: -0.951 | F9: -1.197 | G9: =SUM('Quarterly Model'!F9:I9) -> 0.36600808 | H9: =Assumptions!$B$16*MAX(0,G20)-Assumptions!$B$17*Main!$C$8 -> 0.7609128 | I9: =Assumptions!$B$16*MAX(0,H20)-Assumptions!$B$17*Main!$C$8 -> 1.439697 | J9: =Assumptions!$B$16*MAX(0,I20)-Assumptions!$B$17*Main!$C$8 -> 1.3731082 | K9: =Assumptions!$B$16*MAX(0,J20)-Assumptions!$B$17*Main!$C$8 -> 1.9142424 | L9: =Assumptions!$B$16*MAX(0,K20)-Assumptions!$B$17*Main!$C$8 -> 3.4385257 | M9: =Assumptions!$B$16*MAX(0,L20)-Assumptions!$B$17*Main!$C$8 -> 4.6327258 | N9: =Assumptions!$B$16*MAX(0,M20)-Assumptions!$B$17*Main!$C$8 -> 7.0004774 | O9: =Assumptions!$B$16*MAX(0,N20)-Assumptions!$B$17*Main!$C$8 -> 8.7678739 | ... AE9: =Assumptions!$B$16*MAX(0,AD20)-Assumptions!$B$17*Main!$C$8 -> 28.59609
A10: Pretax | B10: =B8+B9 -> -42.601 | C10: =C8+C9 -> -39.428 | D10: =D8+D9 -> -23.796 | E10: =E8+E9 -> -28.98 | F10: =F8+F9 -> -34.164 | G10: =G8+G9 -> -31.842992 | H10: =H8+H9 -> 18.100913 | I10: =I8+I9 -> -1.775703 | ... AE10: =AE8+AE9 -> 28.642684
A11: Taxes | B11: 0 | C11: 0.129 | D11: 0.069 | E11: 0.042 | F11: 0.005 | G11: =SUM('Quarterly Model'!F11:I11) -> 0.006 | H11: =MAX(0,H10-G21)*Assumptions!$B$15 -> 0 | I11: =MAX(0,I10-H21)*Assumptions!$B$15 -> 0 | J11: =MAX(0,J10-I21)*Assumptions!$B$15 -> 0 | K11: =MAX(0,K10-J21)*Assumptions!$B$15 -> 0 | L11: =MAX(0,L10-K21)*Assumptions!$B$15 -> 0 | M11: =MAX(0,M10-L21)*Assumptions!$B$15 -> 0 | N11: =MAX(0,N10-M21)*Assumptions!$B$15 -> 0 | O11: =MAX(0,O10-N21)*Assumptions!$B$15 -> 1.1049785 | ... AE11: =MAX(0,AE10-AD21)*Assumptions!$B$15 -> 6.5878173
A12: Net Income | B12: -42.601 | C12: -39.557 | D12: -23.865 | E12: -29.022 | F12: -34.169 | G12: =G10-G11 -> -31.848992 | H12: =H10-H11 -> 18.100913 | I12: =I10-I11 -> -1.775703 | J12: =J10-J11 -> 14.430246 | K12: =K10-K11 -> 40.647555 | L12: =L10-L11 -> 31.845337 | M12: =M10-M11 -> 63.140042 | N12: =N10-N11 -> 47.130573 | ... AE12: =AE10-AE11 -> 22.054867
A13: Earnings per Share | B13: =IFERROR(B12/B14,0) -> -68.270833 | C13: =IFERROR(C12/C14,0) -> -61.044753 | D13: =IFERROR(D12/D14,0) -> -16.794511 | E13: =IFERROR(E12/E14,0) -> -4.9081684 | F13: =IFERROR(F12/F14,0) -> -2.0895915 | G13: =IFERROR(G12/G14,0) -> -1.3990332 | H13: =IFERROR(H12/H14,0) -> 0.78223191 | I13: =IFERROR(I12/I14,0) -> -0.076737098 | ... AE13: =IFERROR(AE12/AE14,0) -> 0.95310224
A14: Shares | B14: 0.624 | C14: 0.648 | D14: 1.421 | E14: 5.913 | F14: 16.352 | G14: =AVERAGE('Quarterly Model'!F14:I14) -> 22.765 | H14: =Main!$C$4*(1+Assumptions!$B$26)^(H1-2026) -> 23.140085 | I14: =Main!$C$4*(1+Assumptions!$B$26)^(I1-2026) -> 23.140085 | J14: =Main!$C$4*(1+Assumptions!$B$26)^(J1-2026) -> 23.140085 | K14: =Main!$C$4*(1+Assumptions!$B$26)^(K1-2026) -> 23.140085 | L14: =Main!$C$4*(1+Assumptions!$B$26)^(L1-2026) -> 23.140085 | M14: =Main!$C$4*(1+Assumptions!$B$26)^(M1-2026) -> 23.140085 | N14: =Main!$C$4*(1+Assumptions!$B$26)^(N1-2026) -> 23.140085 | O14: =Main!$C$4*(1+Assumptions!$B$26)^(O1-2026) -> 23.140085 | ... AE14: =Main!$C$4*(1+Assumptions!$B$26)^(AE1-2026) -> 23.140085
A16: Revenue Change | C16: =IFERROR(C2/B2-1,"") | D16: =IFERROR(D2/C2-1,"") | E16: =IFERROR(E2/D2-1,"") | F16: =IFERROR(F2/E2-1,"") | G16: =IFERROR(G2/F2-1,"") | H16: =IFERROR(H2/G2-1,"") | I16: =IFERROR(I2/H2-1,"") -> -0.71002252 | J16: =IFERROR(J2/I2-1,"") -> 1.4192233 | ... AE16: =IFERROR(AE2/AD2-1,"") -> -0.5
A17: Gross Margin | B17: =IFERROR(B4/B2,"") | C17: =IFERROR(C4/C2,"") | D17: =IFERROR(D4/D2,"") | E17: =IFERROR(E4/E2,"") | F17: =IFERROR(F4/F2,"") | G17: =IFERROR(G4/G2,"") | H17: =IFERROR(H4/H2,"") -> 1 | I17: =IFERROR(I4/I2,"") -> 1 | ... AE17: =IFERROR(AE4/AE2,"") -> 1
A19: Actual / Estimate | B19: A | C19: A | D19: A | E19: A | F19: A | G19: A+E | H19: E | I19: E | J19: E | K19: E | L19: E | M19: E | N19: E | O19: E | P19: E | Q19: E | R19: E | S19: E | T19: E | U19: E | V19: E | W19: E | X19: E | Y19: E | Z19: E | AA19: E | AB19: E | AC19: E | AD19: E | AE19: E
A20: Cash & Investments | G20: ='Quarterly Model'!I20 -> 20.291008 | H20: =G20+H12 -> 38.391921 | I20: =H20+I12 -> 36.616218 | J20: =I20+J12 -> 51.046464 | K20: =J20+K12 -> 91.694019 | L20: =K20+L12 -> 123.53936 | M20: =L20+M12 -> 186.6794 | N20: =M20+N12 -> 233.80997 | O20: =N20+O12 -> 305.83328 | ... AE20: =AD20+AE12 -> 784.61725
A21: Tax-Loss Pool | F21: =Assumptions!$B$18 -> 250 | G21: =F21-MIN(F21,MAX(0,G10))+MAX(0,-G10) -> 281.84299 | H21: =G21-MIN(G21,MAX(0,H10))+MAX(0,-H10) -> 263.74208 | I21: =H21-MIN(H21,MAX(0,I10))+MAX(0,-I10) -> 265.51778 | J21: =I21-MIN(I21,MAX(0,J10))+MAX(0,-J10) -> 251.08754 | K21: =J21-MIN(J21,MAX(0,K10))+MAX(0,-K10) -> 210.43998 | L21: =K21-MIN(K21,MAX(0,L10))+MAX(0,-L10) -> 178.59464 | M21: =L21-MIN(L21,MAX(0,M10))+MAX(0,-M10) -> 115.4546 | N21: =M21-MIN(M21,MAX(0,N10))+MAX(0,-N10) -> 68.32403 | ... AE21: =AD21-MIN(AD21,MAX(0,AE10))+MAX(0,-AE10) -> 0

Sheet Quarterly Model
B1: Q1 2025 | C1: Q2 2025 | D1: Q3 2025 | E1: Q4 2025 | F1: Q1 2026 | G1: Q2 2026 | H1: Q3 2026 | I1: Q4 2026
A2: Revenue | B2: 0 | C2: 0 | D2: 0 | E2: 0 | F2: 0 | G2: 0 | H2: 0 | I2: 0
A3: Cost of Sales | B3: 0 | C3: 0 | D3: 0 | E3: 0 | F3: 0 | G3: 0 | H3: =H2*0.0 -> 0 | I3: =I2*0.0 -> 0
A4: Gross Margin | B4: =B2-B3 -> 0 | C4: =C2-C3 -> 0 | D4: =D2-D3 -> 0 | E4: =E2-E3 -> 0 | F4: =F2-F3 -> 0 | G4: =G2-G3 -> 0 | H4: =H2-H3 -> 0 | I4: =I2-I3 -> 0
A5: Research & Dev. | B5: 6.122 | C5: 6.21 | D5: 5.74 | E5: 5.738 | F5: 5.781 | G5: 6.1 | H5: 6 | I5: 6
A6: General & Admin | B6: 1.461 | C6: 3.189 | D6: 2.25 | E6: 2.26 | F6: 1.928 | G6: 1.8 | H6: 2.2 | I6: 2.4
A7: Operating Expense | B7: =SUM(B5:B6) -> 7.583 | C7: =SUM(C5:C6) -> 9.399 | D7: =SUM(D5:D6) -> 7.99 | E7: =SUM(E5:E6) -> 7.998 | F7: =SUM(F5:F6) -> 7.709 | G7: =SUM(G5:G6) -> 7.9 | H7: =SUM(H5:H6) -> 8.2 | I7: =SUM(I5:I6) -> 8.4
A8: Operating Income | B8: =B4-B7 -> -7.583 | C8: =C4-C7 -> -9.399 | D8: =D4-D7 -> -7.99 | E8: =E4-E7 -> -7.998 | F8: =F4-F7 -> -7.709 | G8: =G4-G7 -> -7.9 | H8: =H4-H7 -> -8.2 | I8: =I4-I7 -> -8.4
A9: Interest & Other | B9: -0.668 | C9: -0.531 | D9: 0.03 | E9: 0.033 | F9: -0.065 | G9: 0.103 | H9: =Assumptions!$B$16*G20/4 -> 0.061528125 | I9: =Assumptions!$B$16*H20/4 -> 0.26647995
A10: Pretax | B10: =B8+B9 -> -8.251 | C10: =C8+C9 -> -9.93 | D10: =D8+D9 -> -7.96 | E10: =E8+E9 -> -7.965 | F10: =F8+F9 -> -7.774 | G10: =G8+G9 -> -7.797 | H10: =H8+H9 -> -8.1384719 | I10: =I8+I9 -> -8.13352
A11: Taxes | B11: 0.014 | C11: 0.05 | D11: 0 | E11: 0 | F11: 0.003 | G11: 0.003 | H11: 0 | I11: 0
A12: Net Income | B12: =B10-B11 -> -8.265 | C12: =C10-C11 -> -9.98 | D12: =D10-D11 -> -7.96 | E12: =E10-E11 -> -7.965 | F12: =F10-F11 -> -7.777 | G12: =G10-G11 -> -7.8 | H12: =H10-H11 -> -8.1384719 | I12: =I10-I11 -> -8.13352
A13: Earnings per Share | B13: =IFERROR(B12/B14,0) -> -0.70340426 | C13: =IFERROR(C12/C14,0) -> -0.77725857 | D13: =IFERROR(D12/D14,0) -> -0.4020202 | E13: =IFERROR(E12/E14,0) -> -0.37928571 | F13: =IFERROR(F12/F14,0) -> -0.34937107 | G13: =IFERROR(G12/G14,0) -> -0.34977578 | H13: =IFERROR(H12/H14,0) -> -0.3507962 | I13: =IFERROR(I12/I14,0) -> -0.34907811
A14: Shares | B14: 11.75 | C14: 12.84 | D14: 19.8 | E14: 21 | F14: 22.26 | G14: 22.3 | H14: 23.2 | I14: 23.3
A16: Revenue Change (YoY) | F16: =IFERROR(F2/B2-1,"") | G16: =IFERROR(G2/C2-1,"") | H16: =IFERROR(H2/D2-1,"") | I16: =IFERROR(I2/E2-1,"")
A17: Gross Margin | B17: =IFERROR(B4/B2,"") | C17: =IFERROR(C4/C2,"") | D17: =IFERROR(D4/D2,"") | E17: =IFERROR(E4/E2,"") | F17: =IFERROR(F4/F2,"") | G17: =IFERROR(G4/G2,"") | H17: =IFERROR(H4/H2,"") | I17: =IFERROR(I4/I2,"")
A19: Actual / Estimate | B19: A | C19: A | D19: A | E19: A | F19: A | G19: A | H19: E | I19: E
A20: Cash & Investments | G20: 6.563 | H20: =G20+H12+H21 -> 28.424528 | I20: =H20+I12+I21 -> 20.291008
A21: Other Cash Flows (est.) | H21: 30 | I21: 0

Sheet Assumptions
A1: PYPD — rNPV assumptions ($mm unless noted)
A4: Scenario (1 = Bear, 2 = Base, 3 = Bull) | B4: 2 | C4: =CHOOSE($B$4,"Bear","Base","Bull") -> Base
A5: Overrides (blank = scenario value; the sensitivity tables drive these)
A6: Discount rate override
A7: PDUFA approval probability override
A8: PDUFA program peak sales override ($mm)
A10: Parameter | B10: Active | C10: Bear | D10: Base | E10: Bull
A12: Valuation & corporate
A13: Valuation date | B13: =DATE(2026,10,16) -> 46311
A14: Discount rate (cost of equity) | B14: =IF(ISNUMBER($B$6),$B$6,CHOOSE($B$4,C14,D14,E14)) -> 0.14 | C14: 0.16 | D14: 0.14 | E14: 0.12
A15: Tax rate | B15: =CHOOSE($B$4,C15,D15,E15) -> 0.23 | C15: 0.23 | D15: 0.23 | E15: 0.23
A16: Interest yield on cash | B16: =CHOOSE($B$4,C16,D16,E16) -> 0.0375 | C16: 0.0375 | D16: 0.0375 | E16: 0.0375
A17: Average cash cost of debt (P&L display only) | B17: =CHOOSE($B$4,C17,D17,E17) -> 0.025 | C17: 0.025 | D17: 0.025 | E17: 0.025
A18: Tax-loss pool at 12/31/2025 | B18: =CHOOSE($B$4,C18,D18,E18) -> 250 | C18: 250 | D18: 250 | E18: 250
A19: Corporate G&A, 2027 | B19: =CHOOSE($B$4,C19,D19,E19) -> 7 | C19: 7 | D19: 7 | E19: 7
A20: Platform / unallocated R&D, 2027 | B20: =CHOOSE($B$4,C20,D20,E20) -> 6 | C20: 6 | D20: 6 | E20: 6
A21: Cost inflation | B21: =CHOOSE($B$4,C21,D21,E21) -> 0.03 | C21: 0.03 | D21: 0.03 | E21: 0.03
A22: Corporate G&A floor, % of revenue | B22: =CHOOSE($B$4,C22,D22,E22) -> 0.08 | C22: 0.08 | D22: 0.08 | E22: 0.08
A23: Platform R&D floor, % of revenue | B23: =CHOOSE($B$4,C23,D23,E23) -> 0.06 | C23: 0.06 | D23: 0.06 | E23: 0.06
A24: Corporate cost cut after a CRL (2027+) | B24: =CHOOSE($B$4,C24,D24,E24) -> 0.7 | C24: 0.7 | D24: 0.7 | E24: 0.7
A25: Last year of base-level corporate costs (then % of revenue only) | B25: =CHOOSE($B$4,C25,D25,E25) -> 2041 | C25: 2041 | D25: 2041 | E25: 2041
A26: Annual share count growth (EPS display only) | B26: =CHOOSE($B$4,C26,D26,E26) -> 0 | C26: 0 | D26: 0 | E26: 0
A27: Wind-down cost for liquidation value | B27: =CHOOSE($B$4,C27,D27,E27) -> 8 | C27: 8 | D27: 8 | E27: 8
A29: PDUFA event
A30: PDUFA target action date | B30: =DATE(2026,11,28) -> 46354
A31: Application | B31: D-PLEX100 NDA, surgical-site infection prevention (priority)
A32: Probability of approval at this PDUFA | B32: =IF(ISNUMBER($B$7),$B$7,CHOOSE($B$4,C32,D32,E32)) -> 0.8 | C32: 0.7 | D32: 0.8 | E32: 0.88
A33: Probability of approval later, after a CRL | B33: =CHOOSE($B$4,C33,D33,E33) -> 0.6 | C33: 0.55 | D33: 0.6 | E33: 0.7
A34: Launch delay after a CRL (years) | B34: =CHOOSE($B$4,C34,D34,E34) -> 2 | C34: 2 | D34: 2 | E34: 2
A35: Probability of approval, scenario value (before override) | B35: =CHOOSE($B$4,C32,D32,E32) -> 0.8
A36: Read-through: relative cut to other programs' PoS after a CRL | B36: =CHOOSE($B$4,C36,D36,E36) -> 0 | C36: 0 | D36: 0 | E36: 0
A37: Read-through multiplier on other programs' PoS (1 = none) | B37: =1+$B$36*($B$32-$B$35)/$B$35 -> 1
A38: Expected corporate cost multiplier (2027+) | B38: =$B$32+(1-$B$32)*(1-$B$24) -> 0.86
A40: Commercial curves (by year since launch)
A41: Year since launch | B41: 1 | C41: 2 | D41: 3 | E41: 4 | F41: 5 | G41: 6 | H41: 7
A42: Ramp 1 — standard launch, % of peak | B42: 0.1 | C42: 0.25 | D42: 0.45 | E42: 0.65 | F42: 0.82 | G42: 0.93 | H42: 1
A43: Ramp 2 — orphan-disease launch, % of peak | B43: 0.15 | C43: 0.35 | D43: 0.55 | E43: 0.75 | F43: 0.9 | G43: 1 | H43: 1
A44: Commercial SG&A, % of sales (years 1–5; floor = program maturity %) | B44: 0.9 | C44: 0.55 | D44: 0.4 | E44: 0.32 | F44: 0.28
A46: D-PLEX100 — U.S./Canada via Azurity (royalty + supply) (PDUFA)
A47: Launch year (first full year of sales) | B47: =CHOOSE($B$4,C47,D47,E47) -> 2027 | C47: 2027 | D47: 2027 | E47: 2027
...

Sheet Pipeline
A1: PYPD — risk-adjusted program build ($mm)
A2: Year | C2: 2027 | D2: 2028 | E2: 2029 | F2: 2030 | G2: 2031 | H2: 2032 | I2: 2033 | J2: 2034 | K2: 2035 | L2: 2036 | M2: 2037 | N2: 2038 | O2: 2039 | P2: 2040 | Q2: 2041 | R2: 2042 | S2: 2043 | T2: 2044 | U2: 2045 | V2: 2046 | W2: 2047 | X2: 2048 | Y2: 2049 | Z2: 2050
A4: D-PLEX100 — U.S./Canada via Azurity (royalty + supply)
A5: Years since launch (approved on time) | C5: =C$2-Assumptions!$B$47+1 -> 1 | D5: =D$2-Assumptions!$B$47+1 -> 2 | E5: =E$2-Assumptions!$B$47+1 -> 3 | F5: =F$2-Assumptions!$B$47+1 -> 4 | G5: =G$2-Assumptions!$B$47+1 -> 5 | H5: =H$2-Assumptions!$B$47+1 -> 6 | I5: =I$2-Assumptions!$B$47+1 -> 7 | J5: =J$2-Assumptions!$B$47+1 -> 8 | ... Z5: =Z$2-Assumptions!$B$47+1 -> 24
A6: Net sales, unrisked (approved on time) | C6: =IF(C$2>Assumptions!$B$56,0*(1-Assumptions!$B$57),IF(C5>=1,Assumptions!$B$48*CHOOSE(Assumptions!$B$55,INDEX(Assumptions!$B$42:$H$42,MIN(C5,7)),INDEX(Assumptions!$B$43:$H$43,MIN(C5,7))),0)) -> 20 | D6: =IF(D$2>Assumptions!$B$56,C6*(1-Assumptions!$B$57),IF(D5>=1,Assumptions!$B$48*CHOOSE(Assumptions!$B$55,INDEX(Assumptions!$B$42:$H$42,MIN(D5,7)),INDEX(Assumptions!$B$43:$H$43,MIN(D5,7))),0)) -> 50 | E6: =IF(E$2>Assumptions!$B$56,D6*(1-Assumptions!$B$57),IF(E5>=1,Assumptions!$B$48*CHOOSE(Assumptions!$B$55,INDEX(Assumptions!$B$42:$H$42,MIN(E5,7)),INDEX(Assumptions!$B$43:$H$43,MIN(E5,7))),0)) -> 90 | F6: =IF(F$2>Assumptions!$B$56,E6*(1-Assumptions!$B$57),IF(F5>=1,Assumptions!$B$48*CHOOSE(Assumptions!$B$55,INDEX(Assumptions!$B$42:$H$42,MIN(F5,7)),INDEX(Assumptions!$B$43:$H$43,MIN(F5,7))),0)) -> 130 | G6: =IF(G$2>Assumptions!$B$56,F6*(1-Assumptions!$B$57),IF(G5>=1,Assumptions!$B$48*CHOOSE(Assumptions!$B$55,INDEX(Assumptions!$B$42:$H$42,MIN(G5,7)),INDEX(Assumptions!$B$43:$H$43,MIN(G5,7))),0)) -> 164 | H6: =IF(H$2>Assumptions!$B$56,G6*(1-Assumptions!$B$57),IF(H5>=1,Assumptions!$B$48*CHOOSE(Assumptions!$B$55,INDEX(Assumptions!$B$42:$H$42,MIN(H5,7)),INDEX(Assumptions!$B$43:$H$43,MIN(H5,7))),0)) -> 186 | I6: =IF(I$2>Assumptions!$B$56,H6*(1-Assumptions!$B$57),IF(I5>=1,Assumptions!$B$48*CHOOSE(Assumptions!$B$55,INDEX(Assumptions!$B$42:$H$42,MIN(I5,7)),INDEX(Assumptions!$B$43:$H$43,MIN(I5,7))),0)) -> 200 | J6: =IF(J$2>Assumptions!$B$56,I6*(1-Assumptions!$B$57),IF(J5>=1,Assumptions!$B$48*CHOOSE(Assumptions!$B$55,INDEX(Assumptions!$B$42:$H$42,MIN(J5,7)),INDEX(Assumptions!$B$43:$H$43,MIN(J5,7))),0)) -> 200 | K6: =IF(K$2>Assumptions!$B$56,J6*(1-Assumptions!$B$57),IF(K5>=1,Assumptions!$B$48*CHOOSE(Assumptions!$B$55,INDEX(Assumptions!$B$42:$H$42,MIN(K5,7)),INDEX(Assumptions!$B$43:$H$43,MIN(K5,7))),0)) -> 200 | ... Z6: =IF(Z$2>Assumptions!$B$56,Y6*(1-Assumptions!$B$57),IF(Z5>=1,Assumptions!$B$48*CHOOSE(Assumptions!$B$55,INDEX(Assumptions!$B$42:$H$42,MIN(Z5,7)),INDEX(Assumptions!$B$43:$H$43,MIN(Z5,7))),0)) -> 0.1953125
A7: Years since launch (approved after a CRL) | C7: =C$2-(Assumptions!$B$47+Assumptions!$B$34)+1 -> -1 | D7: =D$2-(Assumptions!$B$47+Assumptions!$B$34)+1 -> 0 | E7: =E$2-(Assumptions!$B$47+Assumptions!$B$34)+1 -> 1 | F7: =F$2-(Assumptions!$B$47+Assumptions!$B$34)+1 -> 2 | G7: =G$2-(Assumptions!$B$47+Assumptions!$B$34)+1 -> 3 | H7: =H$2-(Assumptions!$B$47+Assumptions!$B$34)+1 -> 4 | I7: =I$2-(Assumptions!$B$47+Assumptions!$B$34)+1 -> 5 | J7: =J$2-(Assumptions!$B$47+Assumptions!$B$34)+1 -> 6 | ... Z7: =Z$2-(Assumptions!$B$47+Assumptions!$B$34)+1 -> 22
A8: Net sales, unrisked (approved after a CRL) | C8: =IF(C$2>Assumptions!$B$56,0*(1-Assumptions!$B$57),IF(C7>=1,Assumptions!$B$48*CHOOSE(Assumptions!$B$55,INDEX(Assumptions!$B$42:$H$42,MIN(C7,7)),INDEX(Assumptions!$B$43:$H$43,MIN(C7,7))),0)) -> 0 | D8: =IF(D$2>Assumptions!$B$56,C8*(1-Assumptions!$B$57),IF(D7>=1,Assumptions!$B$48*CHOOSE(Assumptions!$B$55,INDEX(Assumptions!$B$42:$H$42,MIN(D7,7)),INDEX(Assumptions!$B$43:$H$43,MIN(D7,7))),0)) -> 0 | E8: =IF(E$2>Assumptions!$B$56,D8*(1-Assumptions!$B$57),IF(E7>=1,Assumptions!$B$48*CHOOSE(Assumptions!$B$55,INDEX(Assumptions!$B$42:$H$42,MIN(E7,7)),INDEX(Assumptions!$B$43:$H$43,MIN(E7,7))),0)) -> 20 | F8: =IF(F$2>Assumptions!$B$56,E8*(1-Assumptions!$B$57),IF(F7>=1,Assumptions!$B$48*CHOOSE(Assumptions!$B$55,INDEX(Assumptions!$B$42:$H$42,MIN(F7,7)),INDEX(Assumptions!$B$43:$H$43,MIN(F7,7))),0)) -> 50 | G8: =IF(G$2>Assumptions!$B$56,F8*(1-Assumptions!$B$57),IF(G7>=1,Assumptions!$B$48*CHOOSE(Assumptions!$B$55,INDEX(Assumptions!$B$42:$H$42,MIN(G7,7)),INDEX(Assumptions!$B$43:$H$43,MIN(G7,7))),0)) -> 90 | H8: =IF(H$2>Assumptions!$B$56,G8*(1-Assumptions!$B$57),IF(H7>=1,Assumptions!$B$48*CHOOSE(Assumptions!$B$55,INDEX(Assumptions!$B$42:$H$42,MIN(H7,7)),INDEX(Assumptions!$B$43:$H$43,MIN(H7,7))),0)) -> 130 | I8: =IF(I$2>Assumptions!$B$56,H8*(1-Assumptions!$B$57),IF(I7>=1,Assumptions!$B$48*CHOOSE(Assumptions!$B$55,INDEX(Assumptions!$B$42:$H$42,MIN(I7,7)),INDEX(Assumptions!$B$43:$H$43,MIN(I7,7))),0)) -> 164 | J8: =IF(J$2>Assumptions!$B$56,I8*(1-Assumptions!$B$57),IF(J7>=1,Assumptions!$B$48*CHOOSE(Assumptions!$B$55,INDEX(Assumptions!$B$42:$H$42,MIN(J7,7)),INDEX(Assumptions!$B$43:$H$43,MIN(J7,7))),0)) -> 186 | K8: =IF(K$2>Assumptions!$B$56,J8*(1-Assumptions!$B$57),IF(K7>=1,Assumptions!$B$48*CHOOSE(Assumptions!$B$55,INDEX(Assumptions!$B$42:$H$42,MIN(K7,7)),INDEX(Assumptions!$B$43:$H$43,MIN(K7,7))),0)) -> 200 | ... Z8: =IF(Z$2>Assumptions!$B$56,Y8*(1-Assumptions!$B$57),IF(Z7>=1,Assumptions!$B$48*CHOOSE(Assumptions!$B$55,INDEX(Assumptions!$B$42:$H$42,MIN(Z7,7)),INDEX(Assumptions!$B$43:$H$43,MIN(Z7,7))),0)) -> 0.1953125
A9: Product net sales, risk-adjusted | C9: =Assumptions!$B$32*C6+(1-Assumptions!$B$32)*Assumptions!$B$33*C8 -> 16 | D9: =Assumptions!$B$32*D6+(1-Assumptions!$B$32)*Assumptions!$B$33*D8 -> 40 | E9: =Assumptions!$B$32*E6+(1-Assumptions!$B$32)*Assumptions!$B$33*E8 -> 74.4 | F9: =Assumptions!$B$32*F6+(1-Assumptions!$B$32)*Assumptions!$B$33*F8 -> 110 | G9: =Assumptions!$B$32*G6+(1-Assumptions!$B$32)*Assumptions!$B$33*G8 -> 142 | H9: =Assumptions!$B$32*H6+(1-Assumptions!$B$32)*Assumptions!$B$33*H8 -> 164.4 | I9: =Assumptions!$B$32*I6+(1-Assumptions!$B$32)*Assumptions!$B$33*I8 -> 179.68 | J9: =Assumptions!$B$32*J6+(1-Assumptions!$B$32)*Assumptions!$B$33*J8 -> 182.32 | ... Z9: =Assumptions!$B$32*Z6+(1-Assumptions!$B$32)*Assumptions!$B$33*Z8 -> 0.1796875
A10: Company revenue, risk-adjusted (incl. milestones) | C10: =C9*Assumptions!$B$50+Assumptions!$B$32*IFERROR(INDEX(Assumptions!$B$62:$K$62,MATCH(C$2-Assumptions!$B$47,Assumptions!$B$61:$K$61,0)),0)+(1-Assumptions!$B$32)*Assumptions!$B$33*IFERROR(INDEX(Assumptions!$B$62:$K$62,MATCH(C$2-Assumptions!$B$47-Assumptions!$B$34,Assumptions!$B$61:$K$61,0)),0) -> 35.52 | D10: =D9*Assumptions!$B$50+Assumptions!$B$32*IFERROR(INDEX(Assumptions!$B$62:$K$62,MATCH(D$2-Assumptions!$B$47,Assumptions!$B$61:$K$61,0)),0)+(1-Assumptions!$B$32)*Assumptions!$B$33*IFERROR(INDEX(Assumptions!$B$62:$K$62,MATCH(D$2-Assumptions!$B$47-Assumptions!$B$34,Assumptions!$B$61:$K$61,0)),0) -> 8.8 | E10: =E9*Assumptions!$B$50+Assumptions!$B$32*IFERROR(INDEX(Assumptions!$B$62:$K$62,MATCH(E$2-Assumptions!$B$47,Assumptions!$B$61:$K$61,0)),0)+(1-Assumptions!$B$32)*Assumptions!$B$33*IFERROR(INDEX(Assumptions!$B$62:$K$62,MATCH(E$2-Assumptions!$B$47-Assumptions!$B$34,Assumptions!$B$61:$K$61,0)),0) -> 21.168 | F10: =F9*Assumptions!$B$50+Assumptions!$B$32*IFERROR(INDEX(Assumptions!$B$62:$K$62,MATCH(F$2-Assumptions!$B$47,Assumptions!$B$61:$K$61,0)),0)+(1-Assumptions!$B$32)*Assumptions!$B$33*IFERROR(INDEX(Assumptions!$B$62:$K$62,MATCH(F$2-Assumptions!$B$47-Assumptions!$B$34,Assumptions!$B$61:$K$61,0)),0) -> 44.2 | G10: =G9*Assumptions!$B$50+Assumptions!$B$32*IFERROR(INDEX(Assumptions!$B$62:$K$62,MATCH(G$2-Assumptions!$B$47,Assumptions!$B$61:$K$61,0)),0)+(1-Assumptions!$B$32)*Assumptions!$B$33*IFERROR(INDEX(Assumptions!$B$62:$K$62,MATCH(G$2-Assumptions!$B$47-Assumptions!$B$34,Assumptions!$B$61:$K$61,0)),0) -> 31.24 | H10: =H9*Assumptions!$B$50+Assumptions!$B$32*IFERROR(INDEX(Assumptions!$B$62:$K$62,MATCH(H$2-Assumptions!$B$47,Assumptions!$B$61:$K$61,0)),0)+(1-Assumptions!$B$32)*Assumptions!$B$33*IFERROR(INDEX(Assumptions!$B$62:$K$62,MATCH(H$2-Assumptions!$B$47-Assumptions!$B$34,Assumptions!$B$61:$K$61,0)),0) -> 59.168 | I10: =I9*Assumptions!$B$50+Assumptions!$B$32*IFERROR(INDEX(Assumptions!$B$62:$K$62,MATCH(I$2-Assumptions!$B$47,Assumptions!$B$61:$K$61,0)),0)+(1-Assumptions!$B$32)*Assumptions!$B$33*IFERROR(INDEX(Assumptions!$B$62:$K$62,MATCH(I$2-Assumptions!$B$47-Assumptions!$B$34,Assumptions!$B$61:$K$61,0)),0) -> 39.5296 | J10: =J9*Assumptions!$B$50+Assumptions!$B$32*IFERROR(INDEX(Assumptions!$B$62:$K$62,MATCH(J$2-Assumptions!$B$47,Assumptions!$B$61:$K$61,0)),0)+(1-Assumptions!$B$32)*Assumptions!$B$33*IFERROR(INDEX(Assumptions!$B$62:$K$62,MATCH(J$2-Assumptions!$B$47-Assumptions!$B$34,Assumptions!$B$61:$K$61,0)),0) -> 63.1104 | ... Z10: =Z9*Assumptions!$B$50+Assumptions!$B$32*IFERROR(INDEX(Assumptions!$B$62:$K$62,MATCH(Z$2-Assumptions!$B$47,Assumptions!$B$61:$K$61,0)),0)+(1-Assumptions!$B$32)*Assumptions!$B$33*IFERROR(INDEX(Assumptions!$B$62:$K$62,MATCH(Z$2-Assumptions!$B$47-Assumptions!$B$34,Assumptions!$B$61:$K$61,0)),0) -> 0.03953125
A11: COGS + royalties, risk-adjusted | C11: =C9*(Assumptions!$B$51+Assumptions!$B$52) -> 0 | D11: =D9*(Assumptions!$B$51+Assumptions!$B$52) -> 0 | E11: =E9*(Assumptions!$B$51+Assumptions!$B$52) -> 0 | F11: =F9*(Assumptions!$B$51+Assumptions!$B$52) -> 0 | G11: =G9*(Assumptions!$B$51+Assumptions!$B$52) -> 0 | H11: =H9*(Assumptions!$B$51+Assumptions!$B$52) -> 0 | I11: =I9*(Assumptions!$B$51+Assumptions!$B$52) -> 0 | J11: =J9*(Assumptions!$B$51+Assumptions!$B$52) -> 0 | ... Z11: =Z9*(Assumptions!$B$51+Assumptions!$B$52) -> 0
A12: Commercial SG&A, risk-adjusted | C12: =Assumptions!$B$32*IF(Assumptions!$B$53=0,0,IF(C5=0,Assumptions!$B$54,IF(C5>=1,C6*IF(OR(Assumptions!$B$50<1,C5>5),Assumptions!$B$53,MAX(Assumptions!$B$53,INDEX(Assumptions!$B$44:$F$44,C5))),0)))+(1-Assumptions!$B$32)*Assumptions!$B$33*IF(Assumptions!$B$53=0,0,IF(C7=0,Assumptions!$B$54,IF(C7>=1,C8*IF(OR(Assumptions!$B$50<1,C7>5),Assumptions!$B$53,MAX(Assumptions!$B$53,INDEX(Assumptions!$B$44:$F$44,C7))),0))) -> 0 | D12: =Assumptions!$B$32*IF(Assumptions!$B$53=0,0,IF(D5=0,Assumptions!$B$54,IF(D5>=1,D6*IF(OR(Assumptions!$B$50<1,D5>5),Assumptions!$B$53,MAX(Assumptions!$B$53,INDEX(Assumptions!$B$44:$F$44,D5))),0)))+(1-Assumptions!$B$32)*Assumptions!$B$33*IF(Assumptions!$B$53=0,0,IF(D7=0,Assumptions!$B$54,IF(D7>=1,D8*IF(OR(Assumptions!$B$50<1,D7>5),Assumptions!$B$53,MAX(Assumptions!$B$53,INDEX(Assumptions!$B$44:$F$44,D7))),0))) -> 0 | E12: =Assumptions!$B$32*IF(Assumptions!$B$53=0,0,IF(E5=0,Assumptions!$B$54,IF(E5>=1,E6*IF(OR(Assumptions!$B$50<1,E5>5),Assumptions!$B$53,MAX(Assumptions!$B$53,INDEX(Assumptions!$B$44:$F$44,E5))),0)))+(1-Assumptions!$B$32)*Assumptions!$B$33*IF(Assumptions!$B$53=0,0,IF(E7=0,Assumptions!$B$54,IF(E7>=1,E8*IF(OR(Assumptions!$B$50<1,E7>5),Assumptions!$B$53,MAX(Assumptions!$B$53,INDEX(Assumptions!$B$44:$F$44,E7))),0))) -> 0 | F12: =Assumptions!$B$32*IF(Assumptions!$B$53=0,0,IF(F5=0,Assumptions!$B$54,IF(F5>=1,F6*IF(OR(Assumptions!$B$50<1,F5>5),Assumptions!$B$53,MAX(Assumptions!$B$53,INDEX(Assumptions!$B$44:$F$44,F5))),0)))+(1-Assumptions!$B$32)*Assumptions!$B$33*IF(Assumptions!$B$53=0,0,IF(F7=0,Assumptions!$B$54,IF(F7>=1,F8*IF(OR(Assumptions!$B$50<1,F7>5),Assumptions!$B$53,MAX(Assumptions!$B$53,INDEX(Assumptions!$B$44:$F$44,F7))),0))) -> 0 | G12: =Assumptions!$B$32*IF(Assumptions!$B$53=0,0,IF(G5=0,Assumptions!$B$54,IF(G5>=1,G6*IF(OR(Assumptions!$B$50<1,G5>5),Assumptions!$B$53,MAX(Assumptions!$B$53,INDEX(Assumptions!$B$44:$F$44,G5))),0)))+(1-Assumptions!$B$32)*Assumptions!$B$33*IF(Assumptions!$B$53=0,0,IF(G7=0,Assumptions!$B$54,IF(G7>=1,G8*IF(OR(Assumptions!$B$50<1,G7>5),Assumptions!$B$53,MAX(Assumptions!$B$53,INDEX(Assumptions!$B$44:$F$44,G7))),0))) -> 0 | H12: =Assumptions!$B$32*IF(Assumptions!$B$53=0,0,IF(H5=0,Assumptions!$B$54,IF(H5>=1,H6*IF(OR(Assumptions!$B$50<1,H5>5),Assumptions!$B$53,MAX(Assumptions!$B$53,INDEX(Assumptions!$B$44:$F$44,H5))),0)))+(1-Assumptions!$B$32)*Assumptions!$B$33*IF(Assumptions!$B$53=0,0,IF(H7=0,Assumptions!$B$54,IF(H7>=1,H8*IF(OR(Assumptions!$B$50<1,H7>5),Assumptions!$B$53,MAX(Assumptions!$B$53,INDEX(Assumptions!$B$44:$F$44,H7))),0))) -> 0 | I12: =Assumptions!$B$32*IF(Assumptions!$B$53=0,0,IF(I5=0,Assumptions!$B$54,IF(I5>=1,I6*IF(OR(Assumptions!$B$50<1,I5>5),Assumptions!$B$53,MAX(Assumptions!$B$53,INDEX(Assumptions!$B$44:$F$44,I5))),0)))+(1-Assumptions!$B$32)*Assumptions!$B$33*IF(Assumptions!$B$53=0,0,IF(I7=0,Assumptions!$B$54,IF(I7>=1,I8*IF(OR(Assumptions!$B$50<1,I7>5),Assumptions!$B$53,MAX(Assumptions!$B$53,INDEX(Assumptions!$B$44:$F$44,I7))),0))) -> 0 | J12: =Assumptions!$B$32*IF(Assumptions!$B$53=0,0,IF(J5=0,Assumptions!$B$54,IF(J5>=1,J6*IF(OR(Assumptions!$B$50<1,J5>5),Assumptions!$B$53,MAX(Assumptions!$B$53,INDEX(Assumptions!$B$44:$F$44,J5))),0)))+(1-Assumptions!$B$32)*Assumptions!$B$33*IF(Assumptions!$B$53=0,0,IF(J7=0,Assumptions!$B$54,IF(J7>=1,J8*IF(OR(Assumptions!$B$50<1,J7>5),Assumptions!$B$53,MAX(Assumptions!$B$53,INDEX(Assumptions!$B$44:$F$44,J7))),0))) -> 0 | ... Z12: =Assumptions!$B$32*IF(Assumptions!$B$53=0,0,IF(Z5=0,Assumptions!$B$54,IF(Z5>=1,Z6*IF(OR(Assumptions!$B$50<1,Z5>5),Assumptions!$B$53,MAX(Assumptions!$B$53,INDEX(Assumptions!$B$44:$F$44,Z5))),0)))+(1-Assumptions!$B$32)*Assumptions!$B$33*IF(Assumptions!$B$53=0,0,IF(Z7=0,Assumptions!$B$54,IF(Z7>=1,Z8*IF(OR(Assumptions!$B$50<1,Z7>5),Assumptions!$B$53,MAX(Assumptions!$B$53,INDEX(Assumptions!$B$44:$F$44,Z7))),0))) -> 0
A13: Development R&D, risk-adjusted | C13: =IFERROR(INDEX(Assumptions!$B$59:$I$59,MATCH(C$2,Assumptions!$B$58:$I$58,0))*INDEX(Assumptions!$B$60:$I$60,MATCH(C$2,Assumptions!$B$58:$I$58,0)),0) -> 3 | D13: =IFERROR(INDEX(Assumptions!$B$59:$I$59,MATCH(D$2,Assumptions!$B$58:$I$58,0))*INDEX(Assumptions!$B$60:$I$60,MATCH(D$2,Assumptions!$B$58:$I$58,0)),0) -> 0 | E13: =IFERROR(INDEX(Assumptions!$B$59:$I$59,MATCH(E$2,Assumptions!$B$58:$I$58,0))*INDEX(Assumptions!$B$60:$I$60,MATCH(E$2,Assumptions!$B$58:$I$58,0)),0) -> 0 | F13: =IFERROR(INDEX(Assumptions!$B$59:$I$59,MATCH(F$2,Assumptions!$B$58:$I$58,0))*INDEX(Assumptions!$B$60:$I$60,MATCH(F$2,Assumptions!$B$58:$I$58,0)),0) -> 0 | G13: =IFERROR(INDEX(Assumptions!$B$59:$I$59,MATCH(G$2,Assumptions!$B$58:$I$58,0))*INDEX(Assumptions!$B$60:$I$60,MATCH(G$2,Assumptions!$B$58:$I$58,0)),0) -> 0 | H13: =IFERROR(INDEX(Assumptions!$B$59:$I$59,MATCH(H$2,Assumptions!$B$58:$I$58,0))*INDEX(Assumptions!$B$60:$I$60,MATCH(H$2,Assumptions!$B$58:$I$58,0)),0) -> 0 | I13: =IFERROR(INDEX(Assumptions!$B$59:$I$59,MATCH(I$2,Assumptions!$B$58:$I$58,0))*INDEX(Assumptions!$B$60:$I$60,MATCH(I$2,Assumptions!$B$58:$I$58,0)),0) -> 0 | J13: =IFERROR(INDEX(Assumptions!$B$59:$I$59,MATCH(J$2,Assumptions!$B$58:$I$58,0))*INDEX(Assumptions!$B$60:$I$60,MATCH(J$2,Assumptions!$B$58:$I$58,0)),0) -> 0 | ... Z13: =IFERROR(INDEX(Assumptions!$B$59:$I$59,MATCH(Z$2,Assumptions!$B$58:$I$58,0))*INDEX(Assumptions!$B$60:$I$60,MATCH(Z$2,Assumptions!$B$58:$I$58,0)),0) -> 0
A14: Program contribution (pre-tax) | C14: =C10-C11-C12-C13 -> 32.52 | D14: =D10-D11-D12-D13 -> 8.8 | E14: =E10-E11-E12-E13 -> 21.168 | F14: =F10-F11-F12-F13 -> 44.2 | G14: =G10-G11-G12-G13 -> 31.24 | H14: =H10-H11-H12-H13 -> 59.168 | I14: =I10-I11-I12-I13 -> 39.5296 | J14: =J10-J11-J12-J13 -> 63.1104 | ... Z14: =Z10-Z11-Z12-Z13 -> 0.03953125
A16: D-PLEX100 — Europe & RoW (partner to be found)
A17: Years since launch | C17: =C$2-Assumptions!$B$65+1 -> 0 | D17: =D$2-Assumptions!$B$65+1 -> 1 | E17: =E$2-Assumptions!$B$65+1 -> 2 | F17: =F$2-Assumptions!$B$65+1 -> 3 | G17: =G$2-Assumptions!$B$65+1 -> 4 | H17: =H$2-Assumptions!$B$65+1 -> 5 | I17: =I$2-Assumptions!$B$65+1 -> 6 | J17: =J$2-Assumptions!$B$65+1 -> 7 | ... Z17: =Z$2-Assumptions!$B$65+1 -> 23
A18: Net sales, unrisked | C18: =IF(C$2>Assumptions!$B$74,0*(1-Assumptions!$B$75),IF(C17>=1,Assumptions!$B$66*CHOOSE(Assumptions!$B$73,INDEX(Assumptions!$B$42:$H$42,MIN(C17,7)),INDEX(Assumptions!$B$43:$H$43,MIN(C17,7))),0)) -> 0 | D18: =IF(D$2>Assumptions!$B$74,C18*(1-Assumptions!$B$75),IF(D17>=1,Assumptions!$B$66*CHOOSE(Assumptions!$B$73,INDEX(Assumptions!$B$42:$H$42,MIN(D17,7)),INDEX(Assumptions!$B$43:$H$43,MIN(D17,7))),0)) -> 10 | E18: =IF(E$2>Assumptions!$B$74,D18*(1-Assumptions!$B$75),IF(E17>=1,Assumptions!$B$66*CHOOSE(Assumptions!$B$73,INDEX(Assumptions!$B$42:$H$42,MIN(E17,7)),INDEX(Assumptions!$B$43:$H$43,MIN(E17,7))),0)) -> 25 | F18: =IF(F$2>Assumptions!$B$74,E18*(1-Assumptions!$B$75),IF(F17>=1,Assumptions!$B$66*CHOOSE(Assumptions!$B$73,INDEX(Assumptions!$B$42:$H$42,MIN(F17,7)),INDEX(Assumptions!$B$43:$H$43,MIN(F17,7))),0)) -> 45 | G18: =IF(G$2>Assumptions!$B$74,F18*(1-Assumptions!$B$75),IF(G17>=1,Assumptions!$B$66*CHOOSE(Assumptions!$B$73,INDEX(Assumptions!$B$42:$H$42,MIN(G17,7)),INDEX(Assumptions!$B$43:$H$43,MIN(G17,7))),0)) -> 65 | H18: =IF(H$2>Assumptions!$B$74,G18*(1-Assumptions!$B$75),IF(H17>=1,Assumptions!$B$66*CHOOSE(Assumptions!$B$73,INDEX(Assumptions!$B$42:$H$42,MIN(H17,7)),INDEX(Assumptions!$B$43:$H$43,MIN(H17,7))),0)) -> 82 | I18: =IF(I$2>Assumptions!$B$74,H18*(1-Assumptions!$B$75),IF(I17>=1,Assumptions!$B$66*CHOOSE(Assumptions!$B$73,INDEX(Assumptions!$B$42:$H$42,MIN(I17,7)),INDEX(Assumptions!$B$43:$H$43,MIN(I17,7))),0)) -> 93 | J18: =IF(J$2>Assumptions!$B$74,I18*(1-Assumptions!$B$75),IF(J17>=1,Assumptions!$B$66*CHOOSE(Assumptions!$B$73,INDEX(Assumptions!$B$42:$H$42,MIN(J17,7)),INDEX(Assumptions!$B$43:$H$43,MIN(J17,7))),0)) -> 100 | K18: =IF(K$2>Assumptions!$B$74,J18*(1-Assumptions!$B$75),IF(K17>=1,Assumptions!$B$66*CHOOSE(Assumptions!$B$73,INDEX(Assumptions!$B$42:$H$42,MIN(K17,7)),INDEX(Assumptions!$B$43:$H$43,MIN(K17,7))),0)) -> 100 | ... Z18: =IF(Z$2>Assumptions!$B$74,Y18*(1-Assumptions!$B$75),IF(Z17>=1,Assumptions!$B$66*CHOOSE(Assumptions!$B$73,INDEX(Assumptions!$B$42:$H$42,MIN(Z17,7)),INDEX(Assumptions!$B$43:$H$43,MIN(Z17,7))),0)) -> 0.09765625
A19: Product net sales, risk-adjusted | C19: =C18*MIN(1,Assumptions!$B$67*Assumptions!$B$37) -> 0 | D19: =D18*MIN(1,Assumptions!$B$67*Assumptions!$B$37) -> 6 | E19: =E18*MIN(1,Assumptions!$B$67*Assumptions!$B$37) -> 15 | F19: =F18*MIN(1,Assumptions!$B$67*Assumptions!$B$37) -> 27 | G19: =G18*MIN(1,Assumptions!$B$67*Assumptions!$B$37) -> 39 | H19: =H18*MIN(1,Assumptions!$B$67*Assumptions!$B$37) -> 49.2 | I19: =I18*MIN(1,Assumptions!$B$67*Assumptions!$B$37) -> 55.8 | J19: =J18*MIN(1,Assumptions!$B$67*Assumptions!$B$37) -> 60 | ... Z19: =Z18*MIN(1,Assumptions!$B$67*Assumptions!$B$37) -> 0.05859375
A20: Company revenue, risk-adjusted (incl. milestones) | C20: =C19*Assumptions!$B$68 -> 0 | D20: =D19*Assumptions!$B$68 -> 1.5 | E20: =E19*Assumptions!$B$68 -> 3.75 | F20: =F19*Assumptions!$B$68 -> 6.75 | G20: =G19*Assumptions!$B$68 -> 9.75 | H20: =H19*Assumptions!$B$68 -> 12.3 | I20: =I19*Assumptions!$B$68 -> 13.95 | J20: =J19*Assumptions!$B$68 -> 15 | ... Z20: =Z19*Assumptions!$B$68 -> 0.014648438
A21: COGS + royalties, risk-adjusted | C21: =C19*(Assumptions!$B$69+Assumptions!$B$70) -> 0 | D21: =D19*(Assumptions!$B$69+Assumptions!$B$70) -> 0 | E21: =E19*(Assumptions!$B$69+Assumptions!$B$70) -> 0 | F21: =F19*(Assumptions!$B$69+Assumptions!$B$70) -> 0 | G21: =G19*(Assumptions!$B$69+Assumptions!$B$70) -> 0 | H21: =H19*(Assumptions!$B$69+Assumptions!$B$70) -> 0 | I21: =I19*(Assumptions!$B$69+Assumptions!$B$70) -> 0 | J21: =J19*(Assumptions!$B$69+Assumptions!$B$70) -> 0 | ... Z21: =Z19*(Assumptions!$B$69+Assumptions!$B$70) -> 0
A22: Commercial SG&A, risk-adjusted | C22: =MIN(1,Assumptions!$B$67*Assumptions!$B$37)*IF(Assumptions!$B$71=0,0,IF(C17=0,Assumptions!$B$72,IF(C17>=1,C18*IF(OR(Assumptions!$B$68<1,C17>5),Assumptions!$B$71,MAX(Assumptions!$B$71,INDEX(Assumptions!$B$44:$F$44,C17))),0))) -> 0 | D22: =MIN(1,Assumptions!$B$67*Assumptions!$B$37)*IF(Assumptions!$B$71=0,0,IF(D17=0,Assumptions!$B$72,IF(D17>=1,D18*IF(OR(Assumptions!$B$68<1,D17>5),Assumptions!$B$71,MAX(Assumptions!$B$71,INDEX(Assumptions!$B$44:$F$44,D17))),0))) -> 0 | E22: =MIN(1,Assumptions!$B$67*Assumptions!$B$37)*IF(Assumptions!$B$71=0,0,IF(E17=0,Assumptions!$B$72,IF(E17>=1,E18*IF(OR(Assumptions!$B$68<1,E17>5),Assumptions!$B$71,MAX(Assumptions!$B$71,INDEX(Assumptions!$B$44:$F$44,E17))),0))) -> 0 | F22: =MIN(1,Assumptions!$B$67*Assumptions!$B$37)*IF(Assumptions!$B$71=0,0,IF(F17=0,Assumptions!$B$72,IF(F17>=1,F18*IF(OR(Assumptions!$B$68<1,F17>5),Assumptions!$B$71,MAX(Assumptions!$B$71,INDEX(Assumptions!$B$44:$F$44,F17))),0))) -> 0 | G22: =MIN(1,Assumptions!$B$67*Assumptions!$B$37)*IF(Assumptions!$B$71=0,0,IF(G17=0,Assumptions!$B$72,IF(G17>=1,G18*IF(OR(Assumptions!$B$68<1,G17>5),Assumptions!$B$71,MAX(Assumptions!$B$71,INDEX(Assumptions!$B$44:$F$44,G17))),0))) -> 0 | H22: =MIN(1,Assumptions!$B$67*Assumptions!$B$37)*IF(Assumptions!$B$71=0,0,IF(H17=0,Assumptions!$B$72,IF(H17>=1,H18*IF(OR(Assumptions!$B$68<1,H17>5),Assumptions!$B$71,MAX(Assumptions!$B$71,INDEX(Assumptions!$B$44:$F$44,H17))),0))) -> 0 | I22: =MIN(1,Assumptions!$B$67*Assumptions!$B$37)*IF(Assumptions!$B$71=0,0,IF(I17=0,Assumptions!$B$72,IF(I17>=1,I18*IF(OR(Assumptions!$B$68<1,I17>5),Assumptions!$B$71,MAX(Assumptions!$B$71,INDEX(Assumptions!$B$44:$F$44,I17))),0))) -> 0 | J22: =MIN(1,Assumptions!$B$67*Assumptions!$B$37)*IF(Assumptions!$B$71=0,0,IF(J17=0,Assumptions!$B$72,IF(J17>=1,J18*IF(OR(Assumptions!$B$68<1,J17>5),Assumptions!$B$71,MAX(Assumptions!$B$71,INDEX(Assumptions!$B$44:$F$44,J17))),0))) -> 0 | ... Z22: =MIN(1,Assumptions!$B$67*Assumptions!$B$37)*IF(Assumptions!$B$71=0,0,IF(Z17=0,Assumptions!$B$72,IF(Z17>=1,Z18*IF(OR(Assumptions!$B$68<1,Z17>5),Assumptions!$B$71,MAX(Assumptions!$B$71,INDEX(Assumptions!$B$44:$F$44,Z17))),0))) -> 0
A23: Development R&D, risk-adjusted | C23: =IFERROR(INDEX(Assumptions!$B$77:$I$77,MATCH(C$2,Assumptions!$B$76:$I$76,0))*INDEX(Assumptions!$B$78:$I$78,MATCH(C$2,Assumptions!$B$76:$I$76,0)),0) -> 4 | D23: =IFERROR(INDEX(Assumptions!$B$77:$I$77,MATCH(D$2,Assumptions!$B$76:$I$76,0))*INDEX(Assumptions!$B$78:$I$78,MATCH(D$2,Assumptions!$B$76:$I$76,0)),0) -> 2 | E23: =IFERROR(INDEX(Assumptions!$B$77:$I$77,MATCH(E$2,Assumptions!$B$76:$I$76,0))*INDEX(Assumptions!$B$78:$I$78,MATCH(E$2,Assumptions!$B$76:$I$76,0)),0) -> 0 | F23: =IFERROR(INDEX(Assumptions!$B$77:$I$77,MATCH(F$2,Assumptions!$B$76:$I$76,0))*INDEX(Assumptions!$B$78:$I$78,MATCH(F$2,Assumptions!$B$76:$I$76,0)),0) -> 0 | G23: =IFERROR(INDEX(Assumptions!$B$77:$I$77,MATCH(G$2,Assumptions!$B$76:$I$76,0))*INDEX(Assumptions!$B$78:$I$78,MATCH(G$2,Assumptions!$B$76:$I$76,0)),0) -> 0 | H23: =IFERROR(INDEX(Assumptions!$B$77:$I$77,MATCH(H$2,Assumptions!$B$76:$I$76,0))*INDEX(Assumptions!$B$78:$I$78,MATCH(H$2,Assumptions!$B$76:$I$76,0)),0) -> 0 | I23: =IFERROR(INDEX(Assumptions!$B$77:$I$77,MATCH(I$2,Assumptions!$B$76:$I$76,0))*INDEX(Assumptions!$B$78:$I$78,MATCH(I$2,Assumptions!$B$76:$I$76,0)),0) -> 0 | J23: =IFERROR(INDEX(Assumptions!$B$77:$I$77,MATCH(J$2,Assumptions!$B$76:$I$76,0))*INDEX(Assumptions!$B$78:$I$78,MATCH(J$2,Assumptions!$B$76:$I$76,0)),0) -> 0 | ... Z23: =IFERROR(INDEX(Assumptions!$B$77:$I$77,MATCH(Z$2,Assumptions!$B$76:$I$76,0))*INDEX(Assumptions!$B$78:$I$78,MATCH(Z$2,Assumptions!$B$76:$I$76,0)),0) -> 0
A24: Program contribution (pre-tax) | C24: =C20-C21-C22-C23 -> -4 | D24: =D20-D21-D22-D23 -> -0.5 | E24: =E20-E21-E22-E23 -> 3.75 | F24: =F20-F21-F22-F23 -> 6.75 | G24: =G20-G21-G22-G23 -> 9.75 | H24: =H20-H21-H22-H23 -> 12.3 | I24: =I20-I21-I22-I23 -> 13.95 | J24: =J20-J21-J22-J23 -> 15 | ... Z24: =Z20-Z21-Z22-Z23 -> 0.014648438
A26: Company totals (risk-adjusted)
A27: Revenue | C27: =C10+C20 -> 35.52 | D27: =D10+D20 -> 10.3 | E27: =E10+E20 -> 24.918 | F27: =F10+F20 -> 50.95 | G27: =G10+G20 -> 40.99 | H27: =H10+H20 -> 71.468 | I27: =I10+I20 -> 53.4796 | J27: =J10+J20 -> 78.1104 | ... Z27: =Z10+Z20 -> 0.054179687
A28: Cost of sales (COGS + royalties) | C28: =C11+C21 -> 0 | D28: =D11+D21 -> 0 | E28: =E11+E21 -> 0 | F28: =F11+F21 -> 0 | G28: =G11+G21 -> 0 | H28: =H11+H21 -> 0 | I28: =I11+I21 -> 0 | J28: =J11+J21 -> 0 | ... Z28: =Z11+Z21 -> 0
A29: Program development R&D | C29: =C13+C23 -> 7 | D29: =D13+D23 -> 2 | E29: =E13+E23 -> 0 | F29: =F13+F23 -> 0 | G29: =G13+G23 -> 0 | H29: =H13+H23 -> 0 | I29: =I13+I23 -> 0 | J29: =J13+J23 -> 0 | ... Z29: =Z13+Z23 -> 0
A30: Platform / unallocated R&D | C30: =IF(C$2>Assumptions!$B$25,Assumptions!$B$23*C27,MAX(Assumptions!$B$20*(1+Assumptions!$B$21)^(C$2-2027)*Assumptions!$B$38,Assumptions!$B$23*C27)) -> 5.16 | D30: =IF(D$2>Assumptions!$B$25,Assumptions!$B$23*D27,MAX(Assumptions!$B$20*(1+Assumptions!$B$21)^(D$2-2027)*Assumptions!$B$38,Assumptions!$B$23*D27)) -> 5.3148 | E30: =IF(E$2>Assumptions!$B$25,Assumptions!$B$23*E27,MAX(Assumptions!$B$20*(1+Assumptions!$B$21)^(E$2-2027)*Assumptions!$B$38,Assumptions!$B$23*E27)) -> 5.474244 | F30: =IF(F$2>Assumptions!$B$25,Assumptions!$B$23*F27,MAX(Assumptions!$B$20*(1+Assumptions!$B$21)^(F$2-2027)*Assumptions!$B$38,Assumptions!$B$23*F27)) -> 5.6384713 | G30: =IF(G$2>Assumptions!$B$25,Assumptions!$B$23*G27,MAX(Assumptions!$B$20*(1+Assumptions!$B$21)^(G$2-2027)*Assumptions!$B$38,Assumptions!$B$23*G27)) -> 5.8076255 | H30: =IF(H$2>Assumptions!$B$25,Assumptions!$B$23*H27,MAX(Assumptions!$B$20*(1+Assumptions!$B$21)^(H$2-2027)*Assumptions!$B$38,Assumptions!$B$23*H27)) -> 5.9818542 | I30: =IF(I$2>Assumptions!$B$25,Assumptions!$B$23*I27,MAX(Assumptions!$B$20*(1+Assumptions!$B$21)^(I$2-2027)*Assumptions!$B$38,Assumptions!$B$23*I27)) -> 6.1613099 | J30: =IF(J$2>Assumptions!$B$25,Assumptions!$B$23*J27,MAX(Assumptions!$B$20*(1+Assumptions!$B$21)^(J$2-2027)*Assumptions!$B$38,Assumptions!$B$23*J27)) -> 6.3461491 | ... Z30: =IF(Z$2>Assumptions!$B$25,Assumptions!$B$23*Z27,MAX(Assumptions!$B$20*(1+Assumptions!$B$21)^(Z$2-2027)*Assumptions!$B$38,Assumptions!$B$23*Z27)) -> 0.0032507812
A31: Total R&D | C31: =C29+C30 -> 12.16 | D31: =D29+D30 -> 7.3148 | E31: =E29+E30 -> 5.474244 | F31: =F29+F30 -> 5.6384713 | G31: =G29+G30 -> 5.8076255 | H31: =H29+H30 -> 5.9818542 | I31: =I29+I30 -> 6.1613099 | J31: =J29+J30 -> 6.3461491 | ... Z31: =Z29+Z30 -> 0.0032507812
A32: Commercial SG&A | C32: =C12+C22 -> 0 | D32: =D12+D22 -> 0 | E32: =E12+E22 -> 0 | F32: =F12+F22 -> 0 | G32: =G12+G22 -> 0 | H32: =H12+H22 -> 0 | I32: =I12+I22 -> 0 | J32: =J12+J22 -> 0 | ... Z32: =Z12+Z22 -> 0
A33: Corporate G&A | C33: =IF(C$2>Assumptions!$B$25,Assumptions!$B$22*C27,MAX(Assumptions!$B$19*(1+Assumptions!$B$21)^(C$2-2027)*Assumptions!$B$38,Assumptions!$B$22*C27)) -> 6.02 | D33: =IF(D$2>Assumptions!$B$25,Assumptions!$B$22*D27,MAX(Assumptions!$B$19*(1+Assumptions!$B$21)^(D$2-2027)*Assumptions!$B$38,Assumptions!$B$22*D27)) -> 6.2006 | E33: =IF(E$2>Assumptions!$B$25,Assumptions!$B$22*E27,MAX(Assumptions!$B$19*(1+Assumptions!$B$21)^(E$2-2027)*Assumptions!$B$38,Assumptions!$B$22*E27)) -> 6.386618 | F33: =IF(F$2>Assumptions!$B$25,Assumptions!$B$22*F27,MAX(Assumptions!$B$19*(1+Assumptions!$B$21)^(F$2-2027)*Assumptions!$B$38,Assumptions!$B$22*F27)) -> 6.5782165 | G33: =IF(G$2>Assumptions!$B$25,Assumptions!$B$22*G27,MAX(Assumptions!$B$19*(1+Assumptions!$B$21)^(G$2-2027)*Assumptions!$B$38,Assumptions!$B$22*G27)) -> 6.775563 | H33: =IF(H$2>Assumptions!$B$25,Assumptions!$B$22*H27,MAX(Assumptions!$B$19*(1+Assumptions!$B$21)^(H$2-2027)*Assumptions!$B$38,Assumptions!$B$22*H27)) -> 6.9788299 | I33: =IF(I$2>Assumptions!$B$25,Assumptions!$B$22*I27,MAX(Assumptions!$B$19*(1+Assumptions!$B$21)^(I$2-2027)*Assumptions!$B$38,Assumptions!$B$22*I27)) -> 7.1881948 | J33: =IF(J$2>Assumptions!$B$25,Assumptions!$B$22*J27,MAX(Assumptions!$B$19*(1+Assumptions!$B$21)^(J$2-2027)*Assumptions!$B$38,Assumptions!$B$22*J27)) -> 7.4038407 | ... Z33: =IF(Z$2>Assumptions!$B$25,Assumptions!$B$22*Z27,MAX(Assumptions!$B$19*(1+Assumptions!$B$21)^(Z$2-2027)*Assumptions!$B$38,Assumptions!$B$22*Z27)) -> 0.004334375
A34: Total G&A incl. SG&A | C34: =C32+C33 -> 6.02 | D34: =D32+D33 -> 6.2006 | E34: =E32+E33 -> 6.386618 | F34: =F32+F33 -> 6.5782165 | G34: =G32+G33 -> 6.775563 | H34: =H32+H33 -> 6.9788299 | I34: =I32+I33 -> 7.1881948 | J34: =J32+J33 -> 7.4038407 | ... Z34: =Z32+Z33 -> 0.004334375
A35: Operating income (EBIT) | C35: =C27-C28-C31-C34 -> 17.34 | D35: =D27-D28-D31-D34 -> -3.2154 | E35: =E27-E28-E31-E34 -> 13.057138 | F35: =F27-F28-F31-F34 -> 38.733312 | G35: =G27-G28-G31-G34 -> 28.406812 | H35: =H27-H28-H31-H34 -> 58.507316 | I35: =I27-I28-I31-I34 -> 40.130095 | J35: =J27-J28-J31-J34 -> 64.36041 | ... Z35: =Z27-Z28-Z31-Z34 -> 0.046594531

Sheet NPV
A1: PYPD — risk-adjusted NPV (rNPV), $mm except per share
A3: Scenario | B3: =Assumptions!$C$4 -> Base
A4: Valuation date | B4: =Assumptions!$B$13 -> 46311
A5: Discount rate | B5: =Assumptions!$B$14 -> 0.14
A7: Period | C7: 2H 2026 | D7: 2027 | E7: 2028 | F7: 2029 | G7: 2030 | H7: 2031 | I7: 2032 | J7: 2033 | K7: 2034 | L7: 2035 | M7: 2036 | N7: 2037 | O7: 2038 | P7: 2039 | Q7: 2040 | R7: 2041 | S7: 2042 | T7: 2043 | U7: 2044 | V7: 2045 | W7: 2046 | X7: 2047 | Y7: 2048 | Z7: 2049 | AA7: 2050
A8: Revenue, risk-adjusted | C8: =SUM('Quarterly Model'!H2:I2) -> 0 | D8: ='Yearly Model'!H2 -> 35.52 | E8: ='Yearly Model'!I2 -> 10.3 | F8: ='Yearly Model'!J2 -> 24.918 | G8: ='Yearly Model'!K2 -> 50.95 | H8: ='Yearly Model'!L2 -> 40.99 | I8: ='Yearly Model'!M2 -> 71.468 | J8: ='Yearly Model'!N2 -> 53.4796 | K8: ='Yearly Model'!O2 -> 78.1104 | ... AA8: ='Yearly Model'!AE2 -> 0.054179687
A9: Operating income (EBIT) | C9: =SUM('Quarterly Model'!H8:I8) -> -16.6 | D9: ='Yearly Model'!H8 -> 17.34 | E9: ='Yearly Model'!I8 -> -3.2154 | F9: ='Yearly Model'!J8 -> 13.057138 | G9: ='Yearly Model'!K8 -> 38.733312 | H9: ='Yearly Model'!L8 -> 28.406812 | I9: ='Yearly Model'!M8 -> 58.507316 | J9: ='Yearly Model'!N8 -> 40.130095 | K9: ='Yearly Model'!O8 -> 64.36041 | ... AA9: ='Yearly Model'!AE8 -> 0.046594531
A10: Taxes on EBIT (after tax-loss pool) | C10: 0 | D10: =IF(D9>0,MAX(0,D9-'Yearly Model'!G21)*Assumptions!$B$15,0) -> 0 | E10: =IF(E9>0,MAX(0,E9-'Yearly Model'!H21)*Assumptions!$B$15,0) -> 0 | F10: =IF(F9>0,MAX(0,F9-'Yearly Model'!I21)*Assumptions!$B$15,0) -> 0 | G10: =IF(G9>0,MAX(0,G9-'Yearly Model'!J21)*Assumptions!$B$15,0) -> 0 | H10: =IF(H9>0,MAX(0,H9-'Yearly Model'!K21)*Assumptions!$B$15,0) -> 0 | I10: =IF(I9>0,MAX(0,I9-'Yearly Model'!L21)*Assumptions!$B$15,0) -> 0 | J10: =IF(J9>0,MAX(0,J9-'Yearly Model'!M21)*Assumptions!$B$15,0) -> 0 | K10: =IF(K9>0,MAX(0,K9-'Yearly Model'!N21)*Assumptions!$B$15,0) -> 0 | ... AA10: =IF(AA9>0,MAX(0,AA9-'Yearly Model'!AD21)*Assumptions!$B$15,0) -> 0.010716742
A11: Unlevered free cash flow | C11: =C9-C10 -> -16.6 | D11: =D9-D10 -> 17.34 | E11: =E9-E10 -> -3.2154 | F11: =F9-F10 -> 13.057138 | G11: =G9-G10 -> 38.733312 | H11: =H9-H10 -> 28.406812 | I11: =I9-I10 -> 58.507316 | J11: =J9-J10 -> 40.130095 | ... AA11: =AA9-AA10 -> 0.035877789
A12: Cash-flow date (mid-period) | C12: =DATE(2026,10,1) -> 46296 | D12: =DATE(D7,7,1) -> 46569 | E12: =DATE(E7,7,1) -> 46935 | F12: =DATE(F7,7,1) -> 47300 | G12: =DATE(G7,7,1) -> 47665 | H12: =DATE(H7,7,1) -> 48030 | I12: =DATE(I7,7,1) -> 48396 | J12: =DATE(J7,7,1) -> 48761 | K12: =DATE(K7,7,1) -> 49126 | ... AA12: =DATE(AA7,7,1) -> 54970
A13: Years from valuation date | C13: =MAX(0,(C12-$B$4)/365.25) -> 0 | D13: =MAX(0,(D12-$B$4)/365.25) -> 0.7063655 | E13: =MAX(0,(E12-$B$4)/365.25) -> 1.7084189 | F13: =MAX(0,(F12-$B$4)/365.25) -> 2.7077344 | G13: =MAX(0,(G12-$B$4)/365.25) -> 3.70705 | H13: =MAX(0,(H12-$B$4)/365.25) -> 4.7063655 | I13: =MAX(0,(I12-$B$4)/365.25) -> 5.7084189 | J13: =MAX(0,(J12-$B$4)/365.25) -> 6.7077344 | ... AA13: =MAX(0,(AA12-$B$4)/365.25) -> 23.70705
A14: Discount factor | C14: =1/(1+$B$5)^C13 -> 1 | D14: =1/(1+$B$5)^D13 -> 0.91160012 | E14: =1/(1+$B$5)^E13 -> 0.79943411 | F14: =1/(1+$B$5)^F13 -> 0.70132089 | G14: =1/(1+$B$5)^G13 -> 0.61524894 | H14: =1/(1+$B$5)^H13 -> 0.53974045 | I14: =1/(1+$B$5)^I13 -> 0.47332917 | J14: =1/(1+$B$5)^J13 -> 0.41523827 | ... AA14: =1/(1+$B$5)^AA13 -> 0.044766573
A15: PV of free cash flow | C15: =C11*C14 -> -16.6 | D15: =D11*D14 -> 15.807146 | E15: =E11*E14 -> -2.5705005 | F15: =F11*F14 -> 9.1572436 | G15: =G11*G14 -> 23.830629 | H15: =H11*H14 -> 15.332305 | I15: =I11*I14 -> 27.693219 | J15: =J11*J14 -> 16.663551 | ... AA15: =AA11*AA14 -> 0.0016061257
A17: Valuation summary
A18: PV of risk-adjusted free cash flows | C18: =SUM(C15:AA15) -> 160.75254
A19: Cash & investments (Main; incl. post-quarter financing) | C19: =Main!C7 -> 36.563
A20: Debt, convertibles & preferred at face (Main) | C20: =Main!C8 -> 0
A21: Equity value, all claims treated as debt | C21: =C18+C19-C20 -> 197.31554
A22: Basic shares incl. pre-funded / as-converted (Main) | C22: =Main!C4 -> 23.140085
A23: Value / share before conversions | C23: =C21/C22 -> 8.5270017
A25: Convertible instruments (converted if value / share before conversions > conversion price) | B25: Face ($mm) | C25: Shares (mm) | D25: Conv. price | E25: Converted?
A26: — | B26: 0 | C26: 0 | D26: 0 | E26: =IF(AND(C26>0,$C$23>D26),1,0) -> 0
A27: — | B27: 0 | C27: 0 | D27: 0 | E27: =IF(AND(C27>0,$C$23>D27),1,0) -> 0
A28: — | B28: 0 | C28: 0 | D28: 0 | E28: =IF(AND(C28>0,$C$23>D28),1,0) -> 0
A29: — | B29: 0 | C29: 0 | D29: 0 | E29: =IF(AND(C29>0,$C$23>D29),1,0) -> 0
A30: — | B30: 0 | C30: 0 | D30: 0 | E30: =IF(AND(C30>0,$C$23>D30),1,0) -> 0
A31: Equity value (rNPV) after conversions | C31: =C21+SUMPRODUCT(B26:B30,E26:E30) -> 197.31554
A32: Shares after conversions (mm) | C32: =C22+SUMPRODUCT(C26:C30,E26:E30) -> 23.140085
A33: Value / share before options & warrants | C33: =C31/C32 -> 8.5270017
A35: Options, warrants & RSUs (treasury-stock method) | B35: Count (mm) | C35: Strike | D35: Dilution (mm)
A36: New warrants | B36: 7.289644 | C36: 4.5 | D36: =IF(AND(B36>0,$C$33>C36),B36*(1-C36/$C$33),0) -> 3.4426414
A37: Options (estimate) | B37: 2.5 | C37: 4 | D37: =IF(AND(B37>0,$C$33>C37),B37*(1-C37/$C$33),0) -> 1.3272548
A38: — | B38: 0 | C38: 0 | D38: =IF(AND(B38>0,$C$33>C38),B38*(1-C38/$C$33),0) -> 0
A39: — | B39: 0 | C39: 0 | D39: =IF(AND(B39>0,$C$33>C39),B39*(1-C39/$C$33),0) -> 0
A40: — | B40: 0 | C40: 0 | D40: =IF(AND(B40>0,$C$33>C40),B40*(1-C40/$C$33),0) -> 0
A41: — | B41: 0 | C41: 0 | D41: =IF(AND(B41>0,$C$33>C41),B41*(1-C41/$C$33),0) -> 0
A42: Diluted shares (mm) | C42: =C32+SUM(D36:D41) -> 27.909981
A43: rNPV / share, diluted | C43: =C31/C42 -> 7.0697126
A44: Current price (Main) | C44: =Main!C3 -> 5.15
A45: Upside / (downside) to rNPV | C45: =C43/C44-1 -> 0.37275972
...

Sheet Options
A1: PYPD — PDUFA options analysis (per contract = 100 shares)
A3: Inputs
A4: Spot price (close 10/16/2026) | B4: 4.72
A5: Pricing date | B5: =DATE(2026,10,16) -> 46311
A6: PDUFA date | B6: =Assumptions!$B$30 -> 46354
A7: Expiry (first monthly after the PDUFA date) | B7: =DATE(2026,12,18) -> 46374
A8: Years to expiry (T) | B8: =(B7-B5)/365 -> 0.17260274
A9: Risk-free rate | B9: 0.04
A10: Reference IV for wide quotes (theo prices) | B10: 1.05
A11: Contract multiplier | B11: 100
A13: Event model (two outcomes at the PDUFA)
A14: Model value / share, probability-weighted | B14: =NPV!C43 -> 7.0697126
A15: Model value / share if approved | B15: =Assumptions!$D$94 -> 7.4673244
A16: Model value / share if CRL | B16: =Assumptions!$D$93 -> 5.3812697
A17: Model probability of approval | B17: =Assumptions!$B$32 -> 0.8
A18: Event-move scale (share of model jump priced at expiry) | B18: 1
A19: Floor after a CRL, % of est. 12/31/2026 net cash / share | B19: 0.5
A20: Floor price after a CRL | B20: =MAX(0,B19*(NPV!C47-NPV!C20)/NPV!C22) -> 0.43843849
A21: Price if approved (center of outcome) | B21: =IF(B14>0,B4*(1+B18*(B15/B14-1)),B4+B18*(B15-B14)) -> 4.9854603
A22: Price if CRL (center of outcome) | B22: =MAX(B20,IF(B14>0,B4*(1+B18*(B16/B14-1)),B4+B18*(B16-B14))) -> 3.5927334
A23: Model expected price after the decision | B23: =B17*B21+(1-B17)*B22 -> 4.7069149
A24: Non-event volatility (6-month realized, 3 largest days removed) | B24: 0.498
A25: Model fair ATM straddle, % of spot (jump + non-event volatility) | B25: =(B17*((B21*NORMSDIST(((LN(B21/5.0)+$B$24^2*$B$8/2)/($B$24*SQRT($B$8))))-5.0*NORMSDIST((((LN(B21/5.0)+$B$24^2*$B$8/2)/($B$24*SQRT($B$8)))-$B$24*SQRT($B$8))))+(5.0*NORMSDIST(-(((LN(B21/5.0)+$B$24^2*$B$8/2)/($B$24*SQRT($B$8)))-$B$24*SQRT($B$8)))-B21*NORMSDIST(-((LN(B21/5.0)+$B$24^2*$B$8/2)/($B$24*SQRT($B$8))))))+(1-B17)*((B22*NORMSDIST(((LN(B22/5.0)+$B$24^2*$B$8/2)/($B$24*SQRT($B$8))))-5.0*NORMSDIST((((LN(B22/5.0)+$B$24^2*$B$8/2)/($B$24*SQRT($B$8)))-$B$24*SQRT($B$8))))+(5.0*NORMSDIST(-(((LN(B22/5.0)+$B$24^2*$B$8/2)/($B$24*SQRT($B$8)))-$B$24*SQRT($B$8)))-B22*NORMSDIST(-((LN(B22/5.0)+$B$24^2*$B$8/2)/($B$24*SQRT($B$8)))))))/B4 -> 0.20081987
A26: Market ATM straddle, % of spot | B26: =($G$37+$G$38)/B4 -> 0.35665749
A27: Options richness (market straddle ÷ model straddle) | B27: =B26/B25 -> 1.776007
A28: Market snapshot — 12/18/2026 expiry (Cboe delayed quotes, 10/16/2026 close)
A29: Strike | B29: Call bid | C29: Call ask | D29: Call mid | E29: Call IV | F29: Put bid | G29: Put ask | H29: Put mid | I29: Put IV | J29: Call OI | K29: Put OI
A30: 2.5 | B30: 1.15 | C30: 3.7 | D30: =(B30+C30)/2 -> 2.425 | E30: 1.2023 | F30: 0 | G30: 1.85 | H30: =(F30+G30)/2 -> 0.925 | I30: 3.4737 | J30: 0 | K30: 0
A31: 5 | B31: 0.3 | C31: 1.25 | D31: =(B31+C31)/2 -> 0.775 | E31: 1.038 | F31: 0.05 | G31: 1.85 | H31: =(F31+G31)/2 -> 0.95 | I31: 1.0864 | J31: 1 | K31: 0
A32: 7.5 | B32: 0 | C32: 1.85 | D32: =(B32+C32)/2 -> 0.925 | E32: 2.0111 | F32: 2.2 | G32: 3.5 | H32: =(F32+G32)/2 -> 2.85 | I32: 1.0073 | J32: 0 | K32: 0
A33: 10 | B33: 0 | C33: 1.85 | D33: =(B33+C33)/2 -> 0.925 | E33: 2.4475 | F33: 4.3 | G33: 6.7 | H33: =(F33+G33)/2 -> 5.5 | I33: 1.6788 | J33: 0 | K33: 0
A35: Legs (premium = mid when the market is tight, else Black-Scholes at the reference IV)
A36: Leg | B36: Type | C36: Strike | D36: Mid | E36: Spread % of mid | F36: BS value | G36: Premium used | H36: Source | I36: d1 | J36: Delta | K36: E[payoff] if approved | L36: E[payoff] if CRL
A37: Dec-26 $5 call | B37: C | C37: =A31 -> 5 | D37: =(B31+C31)/2 -> 0.775 | E37: =IF(B31>0,(C31-B31)/D37,9.99) -> 1.2258065 | F37: =IF(B37="C",$B$4*NORMSDIST((LN($B$4/C37)+($B$9+$B$10^2/2)*$B$8)/($B$10*SQRT($B$8)))-C37*EXP(-$B$9*$B$8)*NORMSDIST((LN($B$4/C37)+($B$9+$B$10^2/2)*$B$8)/($B$10*SQRT($B$8))-$B$10*SQRT($B$8)),C37*EXP(-$B$9*$B$8)*NORMSDIST(-((LN($B$4/C37)+($B$9+$B$10^2/2)*$B$8)/($B$10*SQRT($B$8))-$B$10*SQRT($B$8)))-$B$4*NORMSDIST(-(LN($B$4/C37)+($B$9+$B$10^2/2)*$B$8)/($B$10*SQRT($B$8)))) -> 0.7189125 | G37: =IF(AND(B31>0,E37<=0.6),D37,F37) -> 0.7189125 | H37: =IF(AND(B31>0,E37<=0.6),"market","theo") -> theo | I37: =(LN($B$4/C37)+($B$9+$B$10^2/2)*$B$8)/($B$10*SQRT($B$8)) -> 0.10183275 | J37: =IF(B37="C",NORMSDIST(I37),NORMSDIST(I37)-1) -> 0.54055529 | K37: =IF(B37="C",($B$21*NORMSDIST(((LN($B$21/C37)+$B$24^2*$B$8/2)/($B$24*SQRT($B$8))))-C37*NORMSDIST((((LN($B$21/C37)+$B$24^2*$B$8/2)/($B$24*SQRT($B$8)))-$B$24*SQRT($B$8)))),(C37*NORMSDIST(-(((LN($B$21/C37)+$B$24^2*$B$8/2)/($B$24*SQRT($B$8)))-$B$24*SQRT($B$8)))-$B$21*NORMSDIST(-((LN($B$21/C37)+$B$24^2*$B$8/2)/($B$24*SQRT($B$8)))))) -> 0.4041357 | L37: =IF(B37="C",($B$22*NORMSDIST(((LN($B$22/C37)+$B$24^2*$B$8/2)/($B$24*SQRT($B$8))))-C37*NORMSDIST((((LN($B$22/C37)+$B$24^2*$B$8/2)/($B$24*SQRT($B$8)))-$B$24*SQRT($B$8)))),(C37*NORMSDIST(-(((LN($B$22/C37)+$B$24^2*$B$8/2)/($B$24*SQRT($B$8)))-$B$24*SQRT($B$8)))-$B$22*NORMSDIST(-((LN($B$22/C37)+$B$24^2*$B$8/2)/($B$24*SQRT($B$8)))))) -> 0.020418934
A38: Dec-26 $5 put | B38: P | C38: =A31 -> 5 | D38: =(F31+G31)/2 -> 0.95 | E38: =IF(F31>0,(G31-F31)/D38,9.99) -> 1.8947368 | F38: =IF(B38="C",$B$4*NORMSDIST((LN($B$4/C38)+($B$9+$B$10^2/2)*$B$8)/($B$10*SQRT($B$8)))-C38*EXP(-$B$9*$B$8)*NORMSDIST((LN($B$4/C38)+($B$9+$B$10^2/2)*$B$8)/($B$10*SQRT($B$8))-$B$10*SQRT($B$8)),C38*EXP(-$B$9*$B$8)*NORMSDIST(-((LN($B$4/C38)+($B$9+$B$10^2/2)*$B$8)/($B$10*SQRT($B$8))-$B$10*SQRT($B$8)))-$B$4*NORMSDIST(-(LN($B$4/C38)+($B$9+$B$10^2/2)*$B$8)/($B$10*SQRT($B$8)))) -> 0.96451085 | G38: =IF(AND(F31>0,E38<=0.6),D38,F38) -> 0.96451085 | H38: =IF(AND(F31>0,E38<=0.6),"market","theo") -> theo | I38: =(LN($B$4/C38)+($B$9+$B$10^2/2)*$B$8)/($B$10*SQRT($B$8)) -> 0.10183275 | J38: =IF(B38="C",NORMSDIST(I38),NORMSDIST(I38)-1) -> -0.45944471 | K38: =IF(B38="C",($B$21*NORMSDIST(((LN($B$21/C38)+$B$24^2*$B$8/2)/($B$24*SQRT($B$8))))-C38*NORMSDIST((((LN($B$21/C38)+$B$24^2*$B$8/2)/($B$24*SQRT($B$8)))-$B$24*SQRT($B$8)))),(C38*NORMSDIST(-(((LN($B$21/C38)+$B$24^2*$B$8/2)/($B$24*SQRT($B$8)))-$B$24*SQRT($B$8)))-$B$21*NORMSDIST(-((LN($B$21/C38)+$B$24^2*$B$8/2)/($B$24*SQRT($B$8)))))) -> 0.41867542 | L38: =IF(B38="C",($B$22*NORMSDIST(((LN($B$22/C38)+$B$24^2*$B$8/2)/($B$24*SQRT($B$8))))-C38*NORMSDIST((((LN($B$22/C38)+$B$24^2*$B$8/2)/($B$24*SQRT($B$8)))-$B$24*SQRT($B$8)))),(C38*NORMSDIST(-(((LN($B$22/C38)+$B$24^2*$B$8/2)/($B$24*SQRT($B$8)))-$B$24*SQRT($B$8)))-$B$22*NORMSDIST(-((LN($B$22/C38)+$B$24^2*$B$8/2)/($B$24*SQRT($B$8)))))) -> 1.4276855
A39: Dec-26 $7.50 call | B39: C | C39: =A32 -> 7.5 | D39: =(B32+C32)/2 -> 0.925 | E39: =IF(B32>0,(C32-B32)/D39,9.99) -> 9.99 | F39: =IF(B39="C",$B$4*NORMSDIST((LN($B$4/C39)+($B$9+$B$10^2/2)*$B$8)/($B$10*SQRT($B$8)))-C39*EXP(-$B$9*$B$8)*NORMSDIST((LN($B$4/C39)+($B$9+$B$10^2/2)*$B$8)/($B$10*SQRT($B$8))-$B$10*SQRT($B$8)),C39*EXP(-$B$9*$B$8)*NORMSDIST(-((LN($B$4/C39)+($B$9+$B$10^2/2)*$B$8)/($B$10*SQRT($B$8))-$B$10*SQRT($B$8)))-$B$4*NORMSDIST(-(LN($B$4/C39)+($B$9+$B$10^2/2)*$B$8)/($B$10*SQRT($B$8)))) -> 0.194365 | G39: =IF(AND(B32>0,E39<=0.6),D39,F39) -> 0.194365 | H39: =IF(AND(B32>0,E39<=0.6),"market","theo") -> theo | I39: =(LN($B$4/C39)+($B$9+$B$10^2/2)*$B$8)/($B$10*SQRT($B$8)) -> -0.82764788 | J39: =IF(B39="C",NORMSDIST(I39),NORMSDIST(I39)-1) -> 0.20393497 | K39: =IF(B39="C",($B$21*NORMSDIST(((LN($B$21/C39)+$B$24^2*$B$8/2)/($B$24*SQRT($B$8))))-C39*NORMSDIST((((LN($B$21/C39)+$B$24^2*$B$8/2)/($B$24*SQRT($B$8)))-$B$24*SQRT($B$8)))),(C39*NORMSDIST(-(((LN($B$21/C39)+$B$24^2*$B$8/2)/($B$24*SQRT($B$8)))-$B$24*SQRT($B$8)))-$B$21*NORMSDIST(-((LN($B$21/C39)+$B$24^2*$B$8/2)/($B$24*SQRT($B$8)))))) -> 0.011470904 | L39: =IF(B39="C",($B$22*NORMSDIST(((LN($B$22/C39)+$B$24^2*$B$8/2)/($B$24*SQRT($B$8))))-C39*NORMSDIST((((LN($B$22/C39)+$B$24^2*$B$8/2)/($B$24*SQRT($B$8)))-$B$24*SQRT($B$8)))),(C39*NORMSDIST(-(((LN($B$22/C39)+$B$24^2*$B$8/2)/($B$24*SQRT($B$8)))-$B$24*SQRT($B$8)))-$B$22*NORMSDIST(-((LN($B$22/C39)+$B$24^2*$B$8/2)/($B$24*SQRT($B$8)))))) -> 4.9697016e-05
A40: Dec-26 $2.50 put | B40: P | C40: =A30 -> 2.5 | D40: =(F30+G30)/2 -> 0.925 | E40: =IF(F30>0,(G30-F30)/D40,9.99) -> 9.99 | F40: =IF(B40="C",$B$4*NORMSDIST((LN($B$4/C40)+($B$9+$B$10^2/2)*$B$8)/($B$10*SQRT($B$8)))-C40*EXP(-$B$9*$B$8)*NORMSDIST((LN($B$4/C40)+($B$9+$B$10^2/2)*$B$8)/($B$10*SQRT($B$8))-$B$10*SQRT($B$8)),C40*EXP(-$B$9*$B$8)*NORMSDIST(-((LN($B$4/C40)+($B$9+$B$10^2/2)*$B$8)/($B$10*SQRT($B$8))-$B$10*SQRT($B$8)))-$B$4*NORMSDIST(-(LN($B$4/C40)+($B$9+$B$10^2/2)*$B$8)/($B$10*SQRT($B$8)))) -> 0.045774579 | G40: =IF(AND(F30>0,E40<=0.6),D40,F40) -> 0.045774579 | H40: =IF(AND(F30>0,E40<=0.6),"market","theo") -> theo | I40: =(LN($B$4/C40)+($B$9+$B$10^2/2)*$B$8)/($B$10*SQRT($B$8)) -> 1.6907904 | J40: =IF(B40="C",NORMSDIST(I40),NORMSDIST(I40)-1) -> -0.045438421 | K40: =IF(B40="C",($B$21*NORMSDIST(((LN($B$21/C40)+$B$24^2*$B$8/2)/($B$24*SQRT($B$8))))-C40*NORMSDIST((((LN($B$21/C40)+$B$24^2*$B$8/2)/($B$24*SQRT($B$8)))-$B$24*SQRT($B$8)))),(C40*NORMSDIST(-(((LN($B$21/C40)+$B$24^2*$B$8/2)/($B$24*SQRT($B$8)))-$B$24*SQRT($B$8)))-$B$21*NORMSDIST(-((LN($B$21/C40)+$B$24^2*$B$8/2)/($B$24*SQRT($B$8)))))) -> 8.0608585e-05 | L40: =IF(B40="C",($B$22*NORMSDIST(((LN($B$22/C40)+$B$24^2*$B$8/2)/($B$24*SQRT($B$8))))-C40*NORMSDIST((((LN($B$22/C40)+$B$24^2*$B$8/2)/($B$24*SQRT($B$8)))-$B$24*SQRT($B$8)))),(C40*NORMSDIST(-(((LN($B$22/C40)+$B$24^2*$B$8/2)/($B$24*SQRT($B$8)))-$B$24*SQRT($B$8)))-$B$22*NORMSDIST(-((LN($B$22/C40)+$B$24^2*$B$8/2)/($B$24*SQRT($B$8)))))) -> 0.0099221862
A42: Strategies (+ = credit received, − = debit paid; per share unless noted)
A43: Metric | B43: Long straddle | C43: Bull call spread | D43: Bear put spread | E43: Iron butterfly
A44: Structure | B44: Buy $5 call + $5 put | C44: Buy $5 / sell $7.50 call | D44: Buy $5 / sell $2.50 put | E44: Sell $5 straddle, buy $2.50 put + $7.50 call
...
