Workbook

Sheet Main
B2: Dr. Reddy's Laboratories Limited
B3: Price | C3: =INDEX([1]Pharma!$F$1:$F$1000,MATCH("RDY",[1]Pharma!$B$1:$B$1000,0)) -> 13.26
B4: Shares | C4: 834.65697
B5: Market Cap. | C5: =C3*C4 -> 11067.551
B7: Cash | C7: =(14654+43254)/94.96 -> 609.81466
B8: Debt | C8: =(38045+857+7864)/94.96 -> 492.48104
B9: Enterprise V. | C9: =C5-C7+C8 -> 10950.218
B11: NPV / Share | C11: =NPV!B28 -> 9.8620066
B12: Upside | C12: =IFERROR(C11/C3-1,"") -> -0.25625893
B13: Cash / Share | C13: =IFERROR((C7-C8)/C4,"") -> 0.14057705
B14: Scenario | C14: =Assumptions!C4 -> Base
B15: Model | C15: Reviewed DCF

Sheet Yearly Model
B1: 2016 | C1: 2017 | D1: 2018 | E1: 2019 | F1: 2020 | G1: 2021 | H1: 2022 | I1: 2023 | J1: 2024 | K1: 2025 | L1: 2026 | M1: 2027 | N1: 2028 | O1: 2029 | P1: 2030 | Q1: 2031 | R1: 2032 | S1: 2033 | T1: 2034 | U1: 2035
A2: Revenue | B2: 1629.191 | C2: 1482.824 | D2: 1495.661 | E2: 1620.166 | F2: 1838.669 | G2: 1997.915 | H2: 2257.698 | I2: 2589.29 | J2: 2939.806 | K2: 3428.128 | L2: =K2*(1+NPV!C5) -> 3537.8281 | M2: =L2*(1+NPV!D5) -> 3431.6933 | N2: =M2*(1+NPV!E5) -> 3671.9118 | O2: =N2*(1+NPV!F5) -> 3928.9456 | P2: =O2*(1+NPV!G5) -> 4164.6823 | Q2: =P2*(1+NPV!H5) -> 4372.9165 | R2: =Q2*(1+NPV!I5) -> 4547.8331 | S2: =R2*(1+NPV!J5) -> 4707.0073 | ... U2: =T2*(1+NPV!L5) -> 4969.4229
A3: Cost of Sales | B3: 657.403 | C3: 657.677 | D3: 692.123 | E3: 741.586 | F3: 848.684 | G3: 912.437 | H3: 1058.877 | I3: 1121.904 | J3: 1216.902 | K3: 1422.778 | L3: =L2*(1-Assumptions!$B$19) -> 1468.1987 | M3: =M2*(1-Assumptions!$B$19) -> 1424.1527 | N3: =N2*(1-Assumptions!$B$19) -> 1523.8434 | O3: =O2*(1-Assumptions!$B$19) -> 1630.5124 | P3: =P2*(1-Assumptions!$B$19) -> 1728.3432 | Q3: =Q2*(1-Assumptions!$B$19) -> 1814.7603 | R3: =R2*(1-Assumptions!$B$19) -> 1887.3507 | S3: =S2*(1-Assumptions!$B$19) -> 1953.408 | ... U3: =U2*(1-Assumptions!$B$19) -> 2062.3105
A4: Gross Margin | B4: =B2-B3 -> 971.788 | C4: =C2-C3 -> 825.147 | D4: =D2-D3 -> 803.538 | E4: =E2-E3 -> 878.58 | F4: =F2-F3 -> 989.985 | G4: =G2-G3 -> 1085.478 | H4: =H2-H3 -> 1198.821 | I4: =I2-I3 -> 1467.386 | ... U4: =U2-U3 -> 2907.1124
A5: Research & Dev. | B5: 187.805 | C5: 205.887 | D5: 192.344 | E5: 164.353 | F5: 162.279 | G5: 174.189 | H5: 184.099 | I5: 204.096 | J5: 240.87 | K5: 288.332 | L5: =L7*Assumptions!$B$20 -> 344.72526 | M5: =M7*Assumptions!$B$20 -> 332.00637 | N5: =N7*Assumptions!$B$20 -> 352.70328 | O5: =O7*Assumptions!$B$20 -> 374.67093 | P5: =P7*Assumptions!$B$20 -> 394.26631 | Q5: =Q7*Assumptions!$B$20 -> 410.95051 | R5: =R7*Assumptions!$B$20 -> 424.23825 | S5: =S7*Assumptions!$B$20 -> 435.82604 | ... U5: =U7*Assumptions!$B$20 -> 453.2387
A6: SG&A & Other | B6: 472.072 | C6: 477.117 | D6: 485.699 | E6: 494.261 | F6: 659.288 | G6: 655.602 | H6: 704.318 | I6: 661.521 | J6: 768.797 | K6: 960.457 | L6: =L7-L5 -> 1148.2382 | M6: =M7-M5 -> 1105.8731 | N6: =N7-N5 -> 1174.812 | O6: =O7-O5 -> 1247.9836 | P6: =P7-P5 -> 1313.2534 | Q6: =Q7-Q5 -> 1368.8265 | R6: =R7-R5 -> 1413.0863 | S6: =S7-S5 -> 1451.6839 | ... U6: =U7-U5 -> 1509.6834
A7: Operating Expense | B7: =SUM(B5:B6) -> 659.877 | C7: =SUM(C5:C6) -> 683.004 | D7: =SUM(D5:D6) -> 678.043 | E7: =SUM(E5:E6) -> 658.614 | F7: =SUM(F5:F6) -> 821.567 | G7: =SUM(G5:G6) -> 829.791 | H7: =SUM(H5:H6) -> 888.417 | I7: =SUM(I5:I6) -> 865.617 | ... K7: =SUM(K5:K6) -> 1248.789 | L7: =L4-L2*NPV!C6 -> 1492.9635 | M7: =M4-M2*NPV!D6 -> 1437.8795 | N7: =N4-N2*NPV!E6 -> 1527.5153 | O7: =O4-O2*NPV!F6 -> 1622.6545 | P7: =P4-P2*NPV!G6 -> 1707.5198 | Q7: =Q4-Q2*NPV!H6 -> 1779.777 | R7: =R4-R2*NPV!I6 -> 1837.3246 | S7: =S4-S2*NPV!J6 -> 1887.5099 | ... U7: =U4-U2*NPV!L6 -> 1962.9221
A8: Operating Income | B8: =B4-B7 -> 311.911 | C8: =C4-C7 -> 142.143 | D8: =D4-D7 -> 125.495 | E8: =E4-E7 -> 219.966 | F8: =F4-F7 -> 168.418 | G8: =G4-G7 -> 255.687 | H8: =H4-H7 -> 310.404 | I8: =I4-I7 -> 601.769 | ... U8: =U4-U7 -> 944.19036
A9: Interest & Other | B9: -26.106 | C9: 12.163 | D9: 25.527 | E9: 16.375 | F9: 21.472 | G9: 22.462 | H9: 29.718 | I9: 33.941 | J9: 43.608 | K9: 44.65 | L9: 0 | M9: 0 | N9: 0 | O9: 0 | P9: 0 | Q9: 0 | R9: 0 | S9: 0 | T9: 0 | U9: 0
A10: Pretax | B10: =B8+B9 -> 285.805 | C10: =C8+C9 -> 154.306 | D10: =D8+D9 -> 151.022 | E10: =E8+E9 -> 236.341 | F10: =F8+F9 -> 189.89 | G10: =G8+G9 -> 278.149 | H10: =H8+H9 -> 340.122 | I10: =I8+I9 -> 635.71 | ... U10: =U8+U9 -> 944.19036
A11: Taxes | B11: 75.053 | C11: 27.527 | D11: 47.757 | E11: 38.416 | F11: -15.438 | G11: 96.62 | H11: 91.933 | I11: 161.12 | J11: 170.451 | K11: 205.76 | L11: =MAX(0,L10)*Assumptions!$E$14 -> 98.033217 | M11: =MAX(0,M10)*Assumptions!$E$14 -> 96.842384 | N11: =MAX(0,N10)*Assumptions!$E$14 -> 105.49403 | O11: =MAX(0,O10)*Assumptions!$E$14 -> 114.88237 | P11: =MAX(0,P10)*Assumptions!$E$14 -> 123.8993 | Q11: =MAX(0,Q10)*Assumptions!$E$14 -> 132.32445 | R11: =MAX(0,R10)*Assumptions!$E$14 -> 139.93683 | S11: =MAX(0,S10)*Assumptions!$E$14 -> 147.23519 | ... U11: =MAX(0,U10)*Assumptions!$E$14 -> 160.51236
A12: Net Income | B12: 210.752 | C12: 126.78 | D12: 103.265 | E12: 197.925 | F12: 205.329 | G12: 181.529 | H12: 248.189 | I12: 474.589 | J12: 586.394 | K12: 595.451 | L12: =L10-L11 -> 478.63276 | M12: =M10-M11 -> 472.8187 | N12: =N10-N11 -> 515.05907 | O12: =O10-O11 -> 560.89627 | P12: =P10-P11 -> 604.92011 | Q12: =Q10-Q11 -> 646.05468 | R12: =R10-R11 -> 683.22097 | S12: =S10-S11 -> 718.85415 | ... U12: =U10-U11 -> 783.678
A13: Earnings per Share | B13: =IFERROR(B12/B14,0) -> 0.24638867 | C13: =IFERROR(C12/C14,0) -> 0.15183452 | D13: =IFERROR(D12/D14,0) -> 0.12427671 | E13: =IFERROR(E12/E14,0) -> 0.23818721 | F13: =IFERROR(F12/F14,0) -> 0.2472622 | G13: =IFERROR(G12/G14,0) -> 0.21829409 | H13: =IFERROR(H12/H14,0) -> 0.2984142 | I13: =IFERROR(I12/I14,0) -> 0.57045992 | ... U13: =IFERROR(U12/U14,0) -> 0.93892225
A14: Shares | B14: 855.364 | C14: 834.988 | D14: 830.928 | E14: 830.964 | F14: 830.41 | G14: 831.58 | H14: 831.693 | I14: 831.941 | J14: 833.538 | K14: 834.179 | L14: =Main!$C$4 -> 834.65697 | M14: =Main!$C$4 -> 834.65697 | N14: =Main!$C$4 -> 834.65697 | O14: =Main!$C$4 -> 834.65697 | P14: =Main!$C$4 -> 834.65697 | Q14: =Main!$C$4 -> 834.65697 | R14: =Main!$C$4 -> 834.65697 | S14: =Main!$C$4 -> 834.65697 | ... U14: =Main!$C$4 -> 834.65697
A16: Revenue Change | C16: =IFERROR(C2/B2-1,"") -> -0.089840295 | D16: =IFERROR(D2/C2-1,"") -> 0.0086571299 | E16: =IFERROR(E2/D2-1,"") -> 0.083244131 | F16: =IFERROR(F2/E2-1,"") -> 0.13486458 | G16: =IFERROR(G2/F2-1,"") -> 0.08660939 | H16: =IFERROR(H2/G2-1,"") -> 0.13002705 | I16: =IFERROR(I2/H2-1,"") -> 0.14687173 | J16: =IFERROR(J2/I2-1,"") -> 0.13537147 | ... U16: =IFERROR(U2/T2-1,"") -> 0.025
A17: Gross Margin | B17: =IFERROR(B4/B2,"") -> 0.596485 | C17: =IFERROR(C4/C2,"") -> 0.55646995 | D17: =IFERROR(D4/D2,"") -> 0.53724607 | E17: =IFERROR(E4/E2,"") -> 0.54227777 | F17: =IFERROR(F4/F2,"") -> 0.53842481 | G17: =IFERROR(G4/G2,"") -> 0.5433054 | H17: =IFERROR(H4/H2,"") -> 0.53099263 | I17: =IFERROR(I4/I2,"") -> 0.56671366 | ... U17: =IFERROR(U4/U2,"") -> 0.585
A18: Operating Margin | B18: =IFERROR(B8/B2,"") -> 0.19145146 | C18: =IFERROR(C8/C2,"") -> 0.095859657 | D18: =IFERROR(D8/D2,"") -> 0.083906046 | E18: =IFERROR(E8/E2,"") -> 0.13576757 | F18: =IFERROR(F8/F2,"") -> 0.091597781 | G18: =IFERROR(G8/G2,"") -> 0.12797692 | H18: =IFERROR(H8/H2,"") -> 0.13748694 | I18: =IFERROR(I8/I2,"") -> 0.23240695 | ... U18: =IFERROR(U8/U2,"") -> 0.19
A19: Actual / Estimate | B19: A | C19: A | D19: A | E19: A | F19: A | G19: A | H19: A | I19: A | J19: A | K19: A | L19: E | M19: E | N19: E | O19: E | P19: E | Q19: E | R19: E | S19: E | T19: E | U19: E

Sheet Quarterly Model

Sheet Assumptions
A1: Dr. Reddy's Laboratories Limited: basic DCF assumptions
A2: Blue = input, black = formula, green = link. $mm unless noted.
A4: Scenario (1 Bear, 2 Base, 3 Bull) | B4: 2 | C4: =CHOOSE($B$4,"Bear","Base","Bull") -> Base
A6: Discount rate override (blank = scenario)
A7: Terminal growth override (blank = scenario)
A9: Parameter | B9: Bear | C9: Base | D9: Bull | E9: Live
A10: Discount rate | B10: 0.105 | C10: 0.095 | D10: 0.085 | E10: =IF(ISNUMBER($B$6),$B$6,CHOOSE($B$4,B10,C10,D10)) -> 0.095
A11: Terminal growth | B11: 0.02 | C11: 0.025 | D11: 0.03 | E11: =IF(ISNUMBER($B$7),$B$7,CHOOSE($B$4,B11,C11,D11)) -> 0.025
A12: Revenue growth, first forecast year | B12: -0.018 | C12: 0.032 | D12: 0.082 | E12: =CHOOSE($B$4,B12,C12,D12) -> 0.032
A13: Operating margin, year 10 | B13: 0.15 | C13: 0.19 | D13: 0.22 | E13: =CHOOSE($B$4,B13,C13,D13) -> 0.19
A14: Tax rate on operating income | B14: 0.17 | C14: 0.17 | D14: 0.17 | E14: =CHOOSE($B$4,B14,C14,D14) -> 0.17
A15: Reinvestment, % of revenue increase | B15: 0.25 | C15: 0.25 | D15: 0.25 | E15: =CHOOSE($B$4,B15,C15,D15) -> 0.25
A17: Single inputs
A18: Starting operating margin (TTM) | B18: 0.16
A19: Gross margin (forecast) | B19: 0.585
A20: R&D share of operating expense (forecast) | B20: 0.2309
A21: Forecast years | B21: 10
A22: First forecast year, fraction after balance sheet date | B22: 1
A23: Balance sheet date | B23: 45747
A24: Reporting currency per USD (INR) | B24: 94.96
A25: Base revenue, FY2025 | B25: ='Yearly Model'!K2 -> 3428.128
A27: Scenario summary
A28: Scenario | B28: Enterprise value | C28: Equity value | D28: NPV / share | E28: Upside
A29: Live | B29: =NPV!B23 -> 8114.059 | C29: =NPV!B26 -> 8231.3926 | D29: =NPV!B28 -> 9.8620066 | E29: =NPV!B30 -> -0.25625893
A30: 1 | B30: 4813.2371 | C30: 4930.5707 | D30: 5.9073019 | E30: -0.55450212
A31: 2 | B31: 8114.059 | C31: 8231.3926 | D31: 9.8620066 | E31: -0.25625893
A32: 3 | B32: 13945.689 | C32: 14063.022 | D32: 16.848865 | E32: 0.27065344
A35: NPV / share: discount rate (rows) x terminal growth (columns)
A36: =NPV!B28 -> 9.8620066 | B36: 0.015 | C36: 0.02 | D36: 0.025 | E36: 0.03 | F36: 0.035
A37: 0.075 | B37: 12.462749 | C37: 13.122691 | D37: 13.914622 | E37: 14.882537 | F37: 16.092431
A38: 0.085 | B38: 10.606043 | C38: 11.039682 | D38: 11.545595 | E38: 12.143492 | F38: 12.860969
A39: 0.095 | B39: 9.2230737 | C39: 9.5212424 | D39: 9.8620066 | E39: 10.255196 | F39: 10.713917
A40: 0.105 | B40: 8.1550422 | C40: 8.3672544 | D40: 8.6059932 | E40: 8.8765638 | F40: 9.1857873
A41: 0.115 | B41: 7.306762 | C41: 7.4619527 | D41: 7.6343867 | E41: 7.8271071 | F41: 8.0439176
A44: Reviewed revenue growth by year (base case; blank = fade formula)
A45: Fiscal year | B45: 2026 | C45: 2027 | D45: 2028 | E45: 2029 | F45: 2030 | G45: 2031 | H45: 2032 | I45: 2033 | J45: 2034 | K45: 2035
A46: Growth (bear/bull shift by the row-12 gap, fading to 0 by year 10) | B46: 0.032 | C46: -0.03 | D46: 0.07 | E46: 0.07 | F46: 0.06 | G46: 0.05 | H46: 0.04 | I46: 0.035 | J46: 0.03 | K46: 0.025

Sheet NPV
A1: Dr. Reddy's Laboratories Limited: free-cash-flow DCF ($mm)
A3: Fiscal year | B3: ='Yearly Model'!K1 -> 2025 | C3: ='Yearly Model'!L1 -> 2026 | D3: ='Yearly Model'!M1 -> 2027 | E3: ='Yearly Model'!N1 -> 2028 | F3: ='Yearly Model'!O1 -> 2029 | G3: ='Yearly Model'!P1 -> 2030 | H3: ='Yearly Model'!Q1 -> 2031 | I3: ='Yearly Model'!R1 -> 2032 | ... L3: ='Yearly Model'!U1 -> 2035
A4: Period | B4: Actual | C4: 1 | D4: 2 | E4: 3 | F4: 4 | G4: 5 | H4: 6 | I4: 7 | J4: 8 | K4: 9 | L4: 10
A5: Revenue growth | C5: =IF(ISNUMBER(Assumptions!B$46),Assumptions!B$46+(Assumptions!$E$12-Assumptions!$C$12)*(Assumptions!$B$21-C4)/(Assumptions!$B$21-1),Assumptions!$E$12+(Assumptions!$E$11-Assumptions!$E$12)*(C4-1)/(Assumptions!$B$21-1)) -> 0.032 | D5: =IF(ISNUMBER(Assumptions!C$46),Assumptions!C$46+(Assumptions!$E$12-Assumptions!$C$12)*(Assumptions!$B$21-D4)/(Assumptions!$B$21-1),Assumptions!$E$12+(Assumptions!$E$11-Assumptions!$E$12)*(D4-1)/(Assumptions!$B$21-1)) -> -0.03 | E5: =IF(ISNUMBER(Assumptions!D$46),Assumptions!D$46+(Assumptions!$E$12-Assumptions!$C$12)*(Assumptions!$B$21-E4)/(Assumptions!$B$21-1),Assumptions!$E$12+(Assumptions!$E$11-Assumptions!$E$12)*(E4-1)/(Assumptions!$B$21-1)) -> 0.07 | F5: =IF(ISNUMBER(Assumptions!E$46),Assumptions!E$46+(Assumptions!$E$12-Assumptions!$C$12)*(Assumptions!$B$21-F4)/(Assumptions!$B$21-1),Assumptions!$E$12+(Assumptions!$E$11-Assumptions!$E$12)*(F4-1)/(Assumptions!$B$21-1)) -> 0.07 | G5: =IF(ISNUMBER(Assumptions!F$46),Assumptions!F$46+(Assumptions!$E$12-Assumptions!$C$12)*(Assumptions!$B$21-G4)/(Assumptions!$B$21-1),Assumptions!$E$12+(Assumptions!$E$11-Assumptions!$E$12)*(G4-1)/(Assumptions!$B$21-1)) -> 0.06 | H5: =IF(ISNUMBER(Assumptions!G$46),Assumptions!G$46+(Assumptions!$E$12-Assumptions!$C$12)*(Assumptions!$B$21-H4)/(Assumptions!$B$21-1),Assumptions!$E$12+(Assumptions!$E$11-Assumptions!$E$12)*(H4-1)/(Assumptions!$B$21-1)) -> 0.05 | I5: =IF(ISNUMBER(Assumptions!H$46),Assumptions!H$46+(Assumptions!$E$12-Assumptions!$C$12)*(Assumptions!$B$21-I4)/(Assumptions!$B$21-1),Assumptions!$E$12+(Assumptions!$E$11-Assumptions!$E$12)*(I4-1)/(Assumptions!$B$21-1)) -> 0.04 | J5: =IF(ISNUMBER(Assumptions!I$46),Assumptions!I$46+(Assumptions!$E$12-Assumptions!$C$12)*(Assumptions!$B$21-J4)/(Assumptions!$B$21-1),Assumptions!$E$12+(Assumptions!$E$11-Assumptions!$E$12)*(J4-1)/(Assumptions!$B$21-1)) -> 0.035 | ... L5: =IF(ISNUMBER(Assumptions!K$46),Assumptions!K$46+(Assumptions!$E$12-Assumptions!$C$12)*(Assumptions!$B$21-L4)/(Assumptions!$B$21-1),Assumptions!$E$12+(Assumptions!$E$11-Assumptions!$E$12)*(L4-1)/(Assumptions!$B$21-1)) -> 0.025
A6: Operating margin | B6: =IFERROR(B8/B7,0) -> 0.22069217 | C6: =Assumptions!$B$18+(Assumptions!$E$13-Assumptions!$B$18)*C4/Assumptions!$B$21 -> 0.163 | D6: =Assumptions!$B$18+(Assumptions!$E$13-Assumptions!$B$18)*D4/Assumptions!$B$21 -> 0.166 | E6: =Assumptions!$B$18+(Assumptions!$E$13-Assumptions!$B$18)*E4/Assumptions!$B$21 -> 0.169 | F6: =Assumptions!$B$18+(Assumptions!$E$13-Assumptions!$B$18)*F4/Assumptions!$B$21 -> 0.172 | G6: =Assumptions!$B$18+(Assumptions!$E$13-Assumptions!$B$18)*G4/Assumptions!$B$21 -> 0.175 | H6: =Assumptions!$B$18+(Assumptions!$E$13-Assumptions!$B$18)*H4/Assumptions!$B$21 -> 0.178 | I6: =Assumptions!$B$18+(Assumptions!$E$13-Assumptions!$B$18)*I4/Assumptions!$B$21 -> 0.181 | J6: =Assumptions!$B$18+(Assumptions!$E$13-Assumptions!$B$18)*J4/Assumptions!$B$21 -> 0.184 | ... L6: =Assumptions!$B$18+(Assumptions!$E$13-Assumptions!$B$18)*L4/Assumptions!$B$21 -> 0.19
A7: Revenue | B7: ='Yearly Model'!K2 -> 3428.128 | C7: ='Yearly Model'!L2 -> 3537.8281 | D7: ='Yearly Model'!M2 -> 3431.6933 | E7: ='Yearly Model'!N2 -> 3671.9118 | F7: ='Yearly Model'!O2 -> 3928.9456 | G7: ='Yearly Model'!P2 -> 4164.6823 | H7: ='Yearly Model'!Q2 -> 4372.9165 | I7: ='Yearly Model'!R2 -> 4547.8331 | ... L7: ='Yearly Model'!U2 -> 4969.4229
A8: Operating income | B8: ='Yearly Model'!K8 -> 756.561 | C8: ='Yearly Model'!L8 -> 576.66598 | D8: ='Yearly Model'!M8 -> 569.66108 | E8: ='Yearly Model'!N8 -> 620.55309 | F8: ='Yearly Model'!O8 -> 675.77864 | G8: ='Yearly Model'!P8 -> 728.81941 | H8: ='Yearly Model'!Q8 -> 778.37913 | I8: ='Yearly Model'!R8 -> 823.15779 | ... L8: ='Yearly Model'!U8 -> 944.19036
A9: Tax on operating income | C9: =MAX(0,C8)*Assumptions!$E$14 -> 98.033217 | D9: =MAX(0,D8)*Assumptions!$E$14 -> 96.842384 | E9: =MAX(0,E8)*Assumptions!$E$14 -> 105.49403 | F9: =MAX(0,F8)*Assumptions!$E$14 -> 114.88237 | G9: =MAX(0,G8)*Assumptions!$E$14 -> 123.8993 | H9: =MAX(0,H8)*Assumptions!$E$14 -> 132.32445 | I9: =MAX(0,I8)*Assumptions!$E$14 -> 139.93683 | J9: =MAX(0,J8)*Assumptions!$E$14 -> 147.23519 | ... L9: =MAX(0,L8)*Assumptions!$E$14 -> 160.51236
A10: NOPAT | C10: =C8-C9 -> 478.63276 | D10: =D8-D9 -> 472.8187 | E10: =E8-E9 -> 515.05907 | F10: =F8-F9 -> 560.89627 | G10: =G8-G9 -> 604.92011 | H10: =H8-H9 -> 646.05468 | I10: =I8-I9 -> 683.22097 | J10: =J8-J9 -> 718.85415 | ... L10: =L8-L9 -> 783.678
A11: Reinvestment | C11: =(C7-B7)*Assumptions!$E$15 -> 27.425024 | D11: =(D7-C7)*Assumptions!$E$15 -> -26.533711 | E11: =(E7-D7)*Assumptions!$E$15 -> 60.054632 | F11: =(F7-E7)*Assumptions!$E$15 -> 64.258456 | G11: =(G7-F7)*Assumptions!$E$15 -> 58.934184 | H11: =(H7-G7)*Assumptions!$E$15 -> 52.058529 | I11: =(I7-H7)*Assumptions!$E$15 -> 43.729165 | J11: =(J7-I7)*Assumptions!$E$15 -> 39.79354 | ... L11: =(L7-K7)*Assumptions!$E$15 -> 30.301359
A12: Free cash flow | C12: =C10-C11 -> 451.20774 | D12: =D10-D11 -> 499.35241 | E12: =E10-E11 -> 455.00443 | F12: =F10-F11 -> 496.63782 | G12: =G10-G11 -> 545.98593 | H12: =H10-H11 -> 593.99615 | I12: =I10-I11 -> 639.4918 | J12: =J10-J11 -> 679.06061 | ... L12: =L10-L11 -> 753.37664
A13: Year fraction | C13: =Assumptions!$B$22 -> 1 | D13: 1 | E13: 1 | F13: 1 | G13: 1 | H13: 1 | I13: 1 | J13: 1 | K13: 1 | L13: 1
A14: Discount time (mid-period) | C14: =C13/2 -> 0.5 | D14: =C14+C13/2+D13/2 -> 1.5 | E14: =D14+D13/2+E13/2 -> 2.5 | F14: =E14+E13/2+F13/2 -> 3.5 | G14: =F14+F13/2+G13/2 -> 4.5 | H14: =G14+G13/2+H13/2 -> 5.5 | I14: =H14+H13/2+I13/2 -> 6.5 | J14: =I14+I13/2+J13/2 -> 7.5 | K14: =J14+J13/2+K13/2 -> 8.5 | L14: =K14+K13/2+L13/2 -> 9.5
A15: Discount factor | C15: =1/(1+Assumptions!$E$10)^C14 -> 0.95563697 | D15: =1/(1+Assumptions!$E$10)^D14 -> 0.87272782 | E15: =1/(1+Assumptions!$E$10)^E14 -> 0.79701171 | F15: =1/(1+Assumptions!$E$10)^F14 -> 0.72786458 | G15: =1/(1+Assumptions!$E$10)^G14 -> 0.66471651 | H15: =1/(1+Assumptions!$E$10)^H14 -> 0.60704704 | I15: =1/(1+Assumptions!$E$10)^I14 -> 0.55438086 | J15: =1/(1+Assumptions!$E$10)^J14 -> 0.50628389 | ... L15: =1/(1+Assumptions!$E$10)^L14 -> 0.42224631
A16: PV of free cash flow | C16: =C12*C13*C15 -> 431.19079 | D16: =D12*D13*D15 -> 435.79874 | E16: =E12*E13*E15 -> 362.64386 | F16: =F12*F13*F15 -> 361.48507 | G16: =G12*G13*G15 -> 362.92586 | H16: =H12*H13*H15 -> 360.5836 | I16: =I12*I13*I15 -> 354.52201 | J16: =J12*J13*J15 -> 343.79745 | ... L16: =L12*L13*L15 -> 318.11051
A19: PV of forecast free cash flow | B19: =SUM(C16:L16) -> 3662.6573
A20: Terminal free cash flow (year 11) | B20: =L10*(1+Assumptions!$E$11)-L7*Assumptions!$E$11*Assumptions!$E$15 -> 772.21105
A21: Terminal value | B21: =B20/(Assumptions!$E$10-Assumptions!$E$11) -> 11031.586
A22: PV of terminal value | B22: =B21/(1+Assumptions!$E$10)^(L14+0.5) -> 4451.4016
A23: Enterprise value | B23: =B19+B22 -> 8114.059
A24: Cash & investments | B24: =Main!C7 -> 609.81466
A25: Debt | B25: =Main!C8 -> 492.48104
A26: Equity value | B26: =B23+B24-B25 -> 8231.3926
A27: Shares (mm) | B27: =Main!C4 -> 834.65697
A28: NPV / share | B28: =B26/B27 -> 9.8620066
A29: Price | B29: =Main!C3 -> 13.26
A30: Upside | B30: =B28/B29-1 -> -0.25625893
A31: Terminal value, % of EV | B31: =IFERROR(B22/B23,0) -> 0.54860356

Sheet Options
A1: RDY: options vs. the reviewed DCF (per contract = 100 shares)
A2: Market prices are Cboe delayed quotes; blue = input. Probabilities are risk-neutral (lognormal at ATM IV).
A3: Inputs
A4: Spot (close 2026-10-20) | B4: 13.26
A5: Pricing date | B5: 46315
A6: Near expiry | B6: 46374
A7: Long expiry | B7: 46465
A8: Years to near expiry | B8: =(B6-B5)/365 -> 0.16164384
A9: Years to long expiry | B9: =(B7-B5)/365 -> 0.4109589
A10: Risk-free rate | B10: 0.04
A11: Dividend yield | B11: 0.0065
A12: ATM implied volatility, near | B12: 0.442
A13: ATM implied volatility, long | B13: 0.3177
A14: Contract multiplier | B14: 100
A16: Market expectations, near expiry
A17: ATM strike | B17: 12.5
A18: ATM call (theo) | B18: 1.3808
A19: ATM put (theo) | B19: 0.5542
A20: Straddle, % of spot (expected move) | B20: =(B18+B19)/B4 -> 0.1459276
A21: Expected range, low | B21: =B4*(1-B20) -> 11.325
A22: Expected range, high | B22: =B4*(1+B20) -> 15.195
A23: 1-SD move by long expiry (ATM IV) | B23: =B13*SQRT(B9) -> 0.203665
A25: Model vs. market at the long expiry
A26: Case | B26: Value / share | C26: vs. spot | D26: Annual return needed | E26: Market P(above)
A27: Forward price at long expiry | B27: =B4*EXP((B10-B11)*B9) -> 13.443814
A28: Bear | B28: =Assumptions!D30 -> 5.9073019 | C28: =B28/$B$4-1 -> -0.55450212 | D28: =IF(B28>0,(B28/$B$4)^(1/$B$9)-1,"") -> -0.86019445 | E28: =IF(B28>0,NORMSDIST((LN($B$27/B28)-$B$13^2*$B$9/2)/($B$13*SQRT($B$9))),1) -> 0.99995854
A29: Base (reviewed) | B29: =Assumptions!D31 -> 9.8620066 | C29: =B29/$B$4-1 -> -0.25625893 | D29: =IF(B29>0,(B29/$B$4)^(1/$B$9)-1,"") -> -0.51345132 | E29: =IF(B29>0,NORMSDIST((LN($B$27/B29)-$B$13^2*$B$9/2)/($B$13*SQRT($B$9))),1) -> 0.92211424
A30: Bull | B30: =Assumptions!D32 -> 16.848865 | C30: =B30/$B$4-1 -> 0.27065344 | D30: =IF(B30>0,(B30/$B$4)^(1/$B$9)-1,"") -> 0.79115285 | E30: =IF(B30>0,NORMSDIST((LN($B$27/B30)-$B$13^2*$B$9/2)/($B$13*SQRT($B$9))),1) -> 0.11307425
A32: Chain, 2027-03-19 expiry
A33: Strike | B33: Call bid | C33: Call ask | D33: Call IV | E33: Put bid | F33: Put ask | G33: Put IV | H33: Call OI | I33: Put OI
A34: 5 | B34: 6.6 | C34: 10.1 | D34: 0.9905 | E34: 0 | F34: 1 | G34: 1.4293 | H34: 0 | I34: 0
A35: 7.5 | B35: 4.2 | C35: 7.5 | D35: 0.5992 | E35: 0 | F35: 1.7 | G35: 1.1391 | H35: 2 | I35: 350
A36: 10 | B36: 1.95 | C36: 4.9 | D36: 0.3799 | E36: 0 | F36: 0.75 | G36: 0.5042 | H36: 3 | I36: 154
A37: 12.5 | B37: 0.15 | C37: 1.95 | D37: 0.1551 | E37: 0.2 | F37: 2.3 | G37: 0.5081 | H37: 166 | I37: 2
A38: 15 | B38: 0.15 | C38: 1.2 | D38: 0.3792 | E38: 0.8 | F38: 4.2 | G38: 0.428 | H38: 13 | I38: 11
A39: 17.5 | B39: 0 | C39: 0.75 | D39: 0.4418 | E39: 2.15 | F39: 6.4 | G39: 0.3005 | H39: 4 | I39: 0
A40: 20 | B40: 0 | C40: 2.2 | D40: 0.8407 | E40: 5.1 | F40: 8.4 | G40: 0.3825 | H40: 0 | I40: 0
A41: 22.5 | B41: 0 | C41: 2.2 | D41: 0.9556 | E41: 7.5 | F41: 10.9 | G41: 0 | H41: 0 | I41: 0
A43: Strategies, 2027-03-19 expiry (premium: + = credit; P/L at expiry per contract)
A44: Leg prices
...
