Workbook

Sheet Main
B2: Summit Therapeutics Inc.
B3: Price | C3: =INDEX([1]Pharma!$F$1:$F$1000,MATCH("SMMT",[1]Pharma!$B$1:$B$1000,0)) -> 16.09
B4: Shares | C4: =797.749602+108.956 -> 906.7056
B5: Market Cap. | C5: =C3*C4 -> 14588.893
B7: Cash | C7: =419.365+271.313+2000 -> 2690.678
B8: Debt | C8: 0
B9: Enterprise V. | C9: =C5-C7+C8 -> 11898.215
B11: rNPV / Share | C11: =NPV!C43 -> 5.475264
B12: Upside | C12: =C11/C3-1 -> -0.65971013
B13: Cash / Share | C13: =(C7-C8)/C4 -> 2.9675321
B14: Scenario | C14: =Assumptions!$C$4 -> Base
B16: PDUFA Date | C16: =Assumptions!$B$30 -> 46340
B17: P(Approval) | C17: =Assumptions!$B$32 -> 0.4
B18: If Approved | C18: =Assumptions!$D$121 -> 7.3408048
B19: If CRL | C19: =Assumptions!$D$120 -> 4.047792

Sheet Yearly Model
B1: 2021 | C1: 2022 | D1: 2023 | E1: 2024 | F1: 2025 | G1: 2026 | H1: 2027 | I1: 2028 | J1: 2029 | K1: 2030 | L1: 2031 | M1: 2032 | N1: 2033 | O1: 2034 | P1: 2035 | Q1: 2036 | R1: 2037 | S1: 2038 | T1: 2039 | U1: 2040 | V1: 2041 | W1: 2042 | X1: 2043 | Y1: 2044 | Z1: 2045 | AA1: 2046 | AB1: 2047 | AC1: 2048 | AD1: 2049 | AE1: 2050
A2: Revenue | B2: 1.809 | C2: 0.705 | D2: 0 | E2: 0 | F2: 0 | G2: =SUM('Quarterly Model'!F2:I2) -> 0 | H2: =Pipeline!C47 -> 28 | I2: =Pipeline!D47 -> 70 | J2: =Pipeline!E47 -> 463.5 | K2: =Pipeline!F47 -> 1036.25 | L2: =Pipeline!G47 -> 1849.6 | M2: =Pipeline!H47 -> 2688.9 | N2: =Pipeline!I47 -> 3453.25 | O2: =Pipeline!J47 -> 3992.35 | ... AE2: =Pipeline!Z47 -> 9.8974609
A3: Cost of Sales | B3: 0 | C3: 0 | D3: 0 | E3: 0 | F3: 0 | G3: =SUM('Quarterly Model'!F3:I3) -> 0 | H3: =Pipeline!C48 -> 5.04 | I3: =Pipeline!D48 -> 12.6 | J3: =Pipeline!E48 -> 90.18 | K3: =Pipeline!F48 -> 203.4 | L3: =Pipeline!G48 -> 364.803 | M3: =Pipeline!H48 -> 531.627 | N3: =Pipeline!I48 -> 683.685 | O3: =Pipeline!J48 -> 791.148 | ... AE3: =Pipeline!Z48 -> 1.9719727
A4: Gross Margin | B4: =B2-B3 -> 1.809 | C4: =C2-C3 -> 0.705 | D4: =D2-D3 -> 0 | E4: =E2-E3 -> 0 | F4: =F2-F3 -> 0 | G4: =G2-G3 -> 0 | H4: =H2-H3 -> 22.96 | I4: =I2-I3 -> 57.4 | ... AE4: =AE2-AE3 -> 7.9254883
A5: Research & Dev. | B5: 64.39 | C5: 51.999 | D5: 59.471 | E5: 150.777 | F5: 537.674 | G5: =SUM('Quarterly Model'!F5:I5) -> 615.36 | H5: =Pipeline!C51 -> 670 | I5: =Pipeline!D51 -> 634.5 | J5: =Pipeline!E51 -> 331.635 | K5: =Pipeline!F51 -> 223.90905 | L5: =Pipeline!G51 -> 221.952 | M5: =Pipeline!H51 -> 322.668 | N5: =Pipeline!I51 -> 414.39 | O5: =Pipeline!J51 -> 479.082 | ... AE5: =Pipeline!Z51 -> 1.1876953
A6: General & Admin | B6: 23.61 | C6: 20.795 | D6: 550.179 | E6: 75.221 | F6: 556.75 | G6: =SUM('Quarterly Model'!F6:I6) -> 260.35 | H6: =Pipeline!C54 -> 225.2 | I6: =Pipeline!D54 -> 298.5 | J6: =Pipeline!E54 -> 575.33 | K6: =Pipeline!F54 -> 757.7979 | L6: =Pipeline!G54 -> 983.41926 | M6: =Pipeline!H54 -> 1133.9998 | N6: =Pipeline!I54 -> 1254.5505 | O6: =Pipeline!J54 -> 1244.1798 | ... AE6: =Pipeline!Z54 -> 2.8306641
A7: Operating Expense | B7: =SUM(B5:B6) -> 88 | C7: =SUM(C5:C6) -> 72.794 | D7: =SUM(D5:D6) -> 609.65 | E7: =SUM(E5:E6) -> 225.998 | F7: =SUM(F5:F6) -> 1094.424 | G7: =SUM(G5:G6) -> 875.71 | H7: =SUM(H5:H6) -> 895.2 | I7: =SUM(I5:I6) -> 933 | ... AE7: =SUM(AE5:AE6) -> 4.0183594
A8: Operating Income | B8: =B4-B7 -> -86.191 | C8: =C4-C7 -> -72.089 | D8: =D4-D7 -> -609.65 | E8: =E4-E7 -> -225.998 | F8: =F4-F7 -> -1094.424 | G8: =G4-G7 -> -875.71 | H8: =H4-H7 -> -872.24 | I8: =I4-I7 -> -875.6 | ... AE8: =AE4-AE7 -> 3.9071289
A9: Interest & Other | B9: -2.416 | C9: -6.693 | D9: -5.278 | E9: 4.683 | F9: 14.838 | G9: =SUM('Quarterly Model'!F9:I9) -> 30.59 | H9: =Assumptions!$B$16*MAX(0,G20)-Assumptions!$B$17*Main!$C$8 -> 84.400425 | I9: =Assumptions!$B$16*MAX(0,H20)-Assumptions!$B$17*Main!$C$8 -> 54.856441 | J9: =Assumptions!$B$16*MAX(0,I20)-Assumptions!$B$17*Main!$C$8 -> 24.078557 | K9: =Assumptions!$B$16*MAX(0,J20)-Assumptions!$B$17*Main!$C$8 -> 4.9698159 | L9: =Assumptions!$B$16*MAX(0,K20)-Assumptions!$B$17*Main!$C$8 -> 0 | M9: =Assumptions!$B$16*MAX(0,L20)-Assumptions!$B$17*Main!$C$8 -> 10.052514 | N9: =Assumptions!$B$16*MAX(0,M20)-Assumptions!$B$17*Main!$C$8 -> 36.702177 | O9: =Assumptions!$B$16*MAX(0,N20)-Assumptions!$B$17*Main!$C$8 -> 79.351929 | ... AE9: =Assumptions!$B$16*MAX(0,AD20)-Assumptions!$B$17*Main!$C$8 -> 775.3326
A10: Pretax | B10: =B8+B9 -> -88.607 | C10: =C8+C9 -> -78.782 | D10: =D8+D9 -> -614.928 | E10: =E8+E9 -> -221.315 | F10: =F8+F9 -> -1079.586 | G10: =G8+G9 -> -845.12 | H10: =H8+H9 -> -787.83957 | I10: =I8+I9 -> -820.74356 | ... AE10: =AE8+AE9 -> 779.23973
A11: Taxes | B11: 0 | C11: 0 | D11: 0 | E11: 0 | F11: 0 | G11: =SUM('Quarterly Model'!F11:I11) -> 0 | H11: =MAX(0,H10-G21)*Assumptions!$B$15 -> 0 | I11: =MAX(0,I10-H21)*Assumptions!$B$15 -> 0 | J11: =MAX(0,J10-I21)*Assumptions!$B$15 -> 0 | K11: =MAX(0,K10-J21)*Assumptions!$B$15 -> 0 | L11: =MAX(0,L10-K21)*Assumptions!$B$15 -> 0 | M11: =MAX(0,M10-L21)*Assumptions!$B$15 -> 0 | N11: =MAX(0,N10-M21)*Assumptions!$B$15 -> 0 | O11: =MAX(0,O10-N21)*Assumptions!$B$15 -> 0 | ... AE11: =MAX(0,AE10-AD21)*Assumptions!$B$15 -> 163.64034
A12: Net Income | B12: -88.602 | C12: -78.782 | D12: -614.928 | E12: -221.315 | F12: -1079.586 | G12: =G10-G11 -> -845.12 | H12: =H10-H11 -> -787.83957 | I12: =I10-I11 -> -820.74356 | J12: =J10-J11 -> -509.56644 | K12: =K10-K11 -> -143.88713 | L12: =L10-L11 -> 279.42574 | M12: =M10-M11 -> 710.6577 | N12: =N10-N11 -> 1137.3267 | ... AE12: =AE10-AE11 -> 615.59939
A13: Earnings per Share | B13: =IFERROR(B12/B14,0) -> -0.67268476 | C13: =IFERROR(C12/C14,0) -> -0.40748748 | D13: =IFERROR(D12/D14,0) -> -0.99238598 | E13: =IFERROR(E12/E14,0) -> -0.30800566 | F13: =IFERROR(F12/F14,0) -> -1.443872 | G13: =IFERROR(G12/G14,0) -> -1.0709098 | H13: =IFERROR(H12/H14,0) -> -0.86890339 | I13: =IFERROR(I12/I14,0) -> -0.90519299 | ... AE13: =IFERROR(AE12/AE14,0) -> 0.67894075
A14: Shares | B14: 131.714 | C14: 193.336 | D14: 619.646 | E14: 718.542 | F14: 747.702 | G14: =AVERAGE('Quarterly Model'!F14:I14) -> 789.16075 | H14: =Main!$C$4*(1+Assumptions!$B$26)^(H1-2026) -> 906.7056 | I14: =Main!$C$4*(1+Assumptions!$B$26)^(I1-2026) -> 906.7056 | J14: =Main!$C$4*(1+Assumptions!$B$26)^(J1-2026) -> 906.7056 | K14: =Main!$C$4*(1+Assumptions!$B$26)^(K1-2026) -> 906.7056 | L14: =Main!$C$4*(1+Assumptions!$B$26)^(L1-2026) -> 906.7056 | M14: =Main!$C$4*(1+Assumptions!$B$26)^(M1-2026) -> 906.7056 | N14: =Main!$C$4*(1+Assumptions!$B$26)^(N1-2026) -> 906.7056 | O14: =Main!$C$4*(1+Assumptions!$B$26)^(O1-2026) -> 906.7056 | ... AE14: =Main!$C$4*(1+Assumptions!$B$26)^(AE1-2026) -> 906.7056
A16: Revenue Change | C16: =IFERROR(C2/B2-1,"") -> -0.61028192 | D16: =IFERROR(D2/C2-1,"") -> -1 | E16: =IFERROR(E2/D2-1,"") | F16: =IFERROR(F2/E2-1,"") | G16: =IFERROR(G2/F2-1,"") | H16: =IFERROR(H2/G2-1,"") | I16: =IFERROR(I2/H2-1,"") -> 1.5 | J16: =IFERROR(J2/I2-1,"") -> 5.6214286 | ... AE16: =IFERROR(AE2/AD2-1,"") -> -0.5
A17: Gross Margin | B17: =IFERROR(B4/B2,"") -> 1 | C17: =IFERROR(C4/C2,"") -> 1 | D17: =IFERROR(D4/D2,"") | E17: =IFERROR(E4/E2,"") | F17: =IFERROR(F4/F2,"") | G17: =IFERROR(G4/G2,"") | H17: =IFERROR(H4/H2,"") -> 0.82 | I17: =IFERROR(I4/I2,"") -> 0.82 | ... AE17: =IFERROR(AE4/AE2,"") -> 0.80075974
A19: Actual / Estimate | B19: A | C19: A | D19: A | E19: A | F19: A | G19: A+E | H19: E | I19: E | J19: E | K19: E | L19: E | M19: E | N19: E | O19: E | P19: E | Q19: E | R19: E | S19: E | T19: E | U19: E | V19: E | W19: E | X19: E | Y19: E | Z19: E | AA19: E | AB19: E | AC19: E | AD19: E | AE19: E
A20: Cash & Investments | G20: ='Quarterly Model'!I20 -> 2250.678 | H20: =G20+H12 -> 1462.8384 | I20: =H20+I12 -> 642.09487 | J20: =I20+J12 -> 132.52842 | K20: =J20+K12 -> -11.358711 | L20: =K20+L12 -> 268.06703 | M20: =L20+M12 -> 978.72473 | N20: =M20+N12 -> 2116.0514 | O20: =N20+O12 -> 3673.3436 | ... AE20: =AD20+AE12 -> 21291.135
A21: Tax-Loss Pool | F21: =Assumptions!$B$18 -> 1200 | G21: =F21-MIN(F21,MAX(0,G10))+MAX(0,-G10) -> 2045.12 | H21: =G21-MIN(G21,MAX(0,H10))+MAX(0,-H10) -> 2832.9596 | I21: =H21-MIN(H21,MAX(0,I10))+MAX(0,-I10) -> 3653.7031 | J21: =I21-MIN(I21,MAX(0,J10))+MAX(0,-J10) -> 4163.2696 | K21: =J21-MIN(J21,MAX(0,K10))+MAX(0,-K10) -> 4307.1567 | L21: =K21-MIN(K21,MAX(0,L10))+MAX(0,-L10) -> 4027.731 | M21: =L21-MIN(L21,MAX(0,M10))+MAX(0,-M10) -> 3317.0733 | N21: =M21-MIN(M21,MAX(0,N10))+MAX(0,-N10) -> 2179.7466 | ... AE21: =AD21-MIN(AD21,MAX(0,AE10))+MAX(0,-AE10) -> 0

Sheet Quarterly Model
B1: Q1 2025 | C1: Q2 2025 | D1: Q3 2025 | E1: Q4 2025 | F1: Q1 2026 | G1: Q2 2026 | H1: Q3 2026 | I1: Q4 2026
A2: Revenue | B2: 0 | C2: 0 | D2: 0 | E2: 0 | F2: 0 | G2: 0 | H2: 0 | I2: 0
A3: Cost of Sales | B3: 0 | C3: 0 | D3: 0 | E3: 0 | F3: 0 | G3: 0 | H3: =H2*0.0 -> 0 | I3: =I2*0.0 -> 0
A4: Gross Margin | B4: =B2-B3 -> 0 | C4: =C2-C3 -> 0 | D4: =D2-D3 -> 0 | E4: =E2-E3 -> 0 | F4: =F2-F3 -> 0 | G4: =G2-G3 -> 0 | H4: =H2-H3 -> 0 | I4: =I2-I3 -> 0
A5: Research & Dev. | B5: 51.265 | C5: 208.021 | D5: 131.096 | E5: 147.292 | F5: 132.62 | G5: 157.74 | H5: 160 | I5: 165
A6: General & Admin | B6: 15.586 | C6: 360.416 | D6: 103.115 | E6: 77.633 | F6: 62.59 | G6: 62.76 | H6: 65 | I6: 70
A7: Operating Expense | B7: =SUM(B5:B6) -> 66.851 | C7: =SUM(C5:C6) -> 568.437 | D7: =SUM(D5:D6) -> 234.211 | E7: =SUM(E5:E6) -> 224.925 | F7: =SUM(F5:F6) -> 195.21 | G7: =SUM(G5:G6) -> 220.5 | H7: =SUM(H5:H6) -> 225 | I7: =SUM(I5:I6) -> 235
A8: Operating Income | B8: =B4-B7 -> -66.851 | C8: =C4-C7 -> -568.437 | D8: =D4-D7 -> -234.211 | E8: =E4-E7 -> -224.925 | F8: =F4-F7 -> -195.21 | G8: =G4-G7 -> -220.5 | H8: =H4-H7 -> -225 | I8: =I4-I7 -> -235
A9: Interest & Other | B9: 3.938 | C9: 2.729 | D9: 2.418 | E9: 5.753 | F9: 5.79 | G9: 4.8 | H9: 5 | I9: 15
A10: Pretax | B10: =B8+B9 -> -62.913 | C10: =C8+C9 -> -565.708 | D10: =D8+D9 -> -231.793 | E10: =E8+E9 -> -219.172 | F10: =F8+F9 -> -189.42 | G10: =G8+G9 -> -215.7 | H10: =H8+H9 -> -220 | I10: =I8+I9 -> -220
A11: Taxes | B11: 0 | C11: 0 | D11: 0 | E11: 0 | F11: 0 | G11: 0 | H11: 0 | I11: 0
A12: Net Income | B12: =B10-B11 -> -62.913 | C12: =C10-C11 -> -565.708 | D12: =D10-D11 -> -231.793 | E12: =E10-E11 -> -219.172 | F12: =F10-F11 -> -189.42 | G12: =G10-G11 -> -215.7 | H12: =H10-H11 -> -220 | I12: =I10-I11 -> -220
A13: Earnings per Share | B13: =IFERROR(B12/B14,0) -> -0.085239189 | C13: =IFERROR(C12/C14,0) -> -0.76177831 | D13: =IFERROR(D12/D14,0) -> -0.31179447 | E13: =IFERROR(E12/E14,0) -> -0.28586335 | F13: =IFERROR(F12/F14,0) -> -0.24426855 | G13: =IFERROR(G12/G14,0) -> -0.27718345 | H13: =IFERROR(H12/H14,0) -> -0.275 | I13: =IFERROR(I12/I14,0) -> -0.2739726
A14: Shares | B14: 738.076 | C14: 742.615 | D14: 743.416 | E14: 766.702 | F14: 775.458 | G14: 778.185 | H14: 800 | I14: 803
A16: Revenue Change (YoY) | F16: =IFERROR(F2/B2-1,"") | G16: =IFERROR(G2/C2-1,"") | H16: =IFERROR(H2/D2-1,"") | I16: =IFERROR(I2/E2-1,"")
A17: Gross Margin | B17: =IFERROR(B4/B2,"") | C17: =IFERROR(C4/C2,"") | D17: =IFERROR(D4/D2,"") | E17: =IFERROR(E4/E2,"") | F17: =IFERROR(F4/F2,"") | G17: =IFERROR(G4/G2,"") | H17: =IFERROR(H4/H2,"") | I17: =IFERROR(I4/I2,"")
A19: Actual / Estimate | B19: A | C19: A | D19: A | E19: A | F19: A | G19: A | H19: E | I19: E
A20: Cash & Investments | G20: 690.678 | H20: =G20+H12+H21 -> 470.678 | I20: =H20+I12+I21 -> 2250.678
A21: Other Cash Flows (est.) | H21: 0 | I21: 2000

Sheet Assumptions
A1: SMMT — rNPV assumptions ($mm unless noted)
A4: Scenario (1 = Bear, 2 = Base, 3 = Bull) | B4: 2 | C4: =CHOOSE($B$4,"Bear","Base","Bull") -> Base
A5: Overrides (blank = scenario value; the sensitivity tables drive these)
A6: Discount rate override
A7: PDUFA approval probability override
A8: PDUFA program peak sales override ($mm)
A10: Parameter | B10: Active | C10: Bear | D10: Base | E10: Bull
A12: Valuation & corporate
A13: Valuation date | B13: =DATE(2026,10,16) -> 46311
A14: Discount rate (cost of equity) | B14: =IF(ISNUMBER($B$6),$B$6,CHOOSE($B$4,C14,D14,E14)) -> 0.11 | C14: 0.13 | D14: 0.11 | E14: 0.095
A15: Tax rate | B15: =CHOOSE($B$4,C15,D15,E15) -> 0.21 | C15: 0.21 | D15: 0.21 | E15: 0.21
A16: Interest yield on cash | B16: =CHOOSE($B$4,C16,D16,E16) -> 0.0375 | C16: 0.0375 | D16: 0.0375 | E16: 0.0375
A17: Average cash cost of debt (P&L display only) | B17: =CHOOSE($B$4,C17,D17,E17) -> 0.025 | C17: 0.025 | D17: 0.025 | E17: 0.025
A18: Tax-loss pool at 12/31/2025 | B18: =CHOOSE($B$4,C18,D18,E18) -> 1200 | C18: 1200 | D18: 1200 | E18: 1200
A19: Corporate G&A, 2027 | B19: =CHOOSE($B$4,C19,D19,E19) -> 200 | C19: 200 | D19: 200 | E19: 200
A20: Platform / unallocated R&D, 2027 | B20: =CHOOSE($B$4,C20,D20,E20) -> 150 | C20: 150 | D20: 150 | E20: 150
A21: Cost inflation | B21: =CHOOSE($B$4,C21,D21,E21) -> 0.03 | C21: 0.03 | D21: 0.03 | E21: 0.03
A22: Corporate G&A floor, % of revenue | B22: =CHOOSE($B$4,C22,D22,E22) -> 0.06 | C22: 0.06 | D22: 0.06 | E22: 0.06
A23: Platform R&D floor, % of revenue | B23: =CHOOSE($B$4,C23,D23,E23) -> 0.12 | C23: 0.12 | D23: 0.12 | E23: 0.12
A24: Corporate cost cut after a CRL (2027+) | B24: =CHOOSE($B$4,C24,D24,E24) -> 0 | C24: 0 | D24: 0 | E24: 0
A25: Last year of base-level corporate costs (then % of revenue only) | B25: =CHOOSE($B$4,C25,D25,E25) -> 2042 | C25: 2042 | D25: 2042 | E25: 2042
A26: Annual share count growth (EPS display only) | B26: =CHOOSE($B$4,C26,D26,E26) -> 0 | C26: 0 | D26: 0 | E26: 0
A27: Wind-down cost for liquidation value | B27: =CHOOSE($B$4,C27,D27,E27) -> 150 | C27: 150 | D27: 150 | E27: 150
A29: PDUFA event
A30: PDUFA target action date | B30: =DATE(2026,11,14) -> 46340
A31: Application | B31: Ivonescimab + chemo BLA, EGFRm NSCLC after TKI (HARMONi)
A32: Probability of approval at this PDUFA | B32: =IF(ISNUMBER($B$7),$B$7,CHOOSE($B$4,C32,D32,E32)) -> 0.4 | C32: 0.25 | D32: 0.4 | E32: 0.55
A33: Probability of approval later, after a CRL | B33: =CHOOSE($B$4,C33,D33,E33) -> 0.25 | C33: 0.15 | D33: 0.25 | E33: 0.35
A34: Launch delay after a CRL (years) | B34: =CHOOSE($B$4,C34,D34,E34) -> 3 | C34: 3 | D34: 3 | E34: 3
A35: Probability of approval, scenario value (before override) | B35: =CHOOSE($B$4,C32,D32,E32) -> 0.4
A36: Read-through: relative cut to other programs' PoS after a CRL | B36: =CHOOSE($B$4,C36,D36,E36) -> 0.2 | C36: 0.2 | D36: 0.2 | E36: 0.2
A37: Read-through multiplier on other programs' PoS (1 = none) | B37: =1+$B$36*($B$32-$B$35)/$B$35 -> 1
A38: Expected corporate cost multiplier (2027+) | B38: =$B$32+(1-$B$32)*(1-$B$24) -> 1
A40: Commercial curves (by year since launch)
A41: Year since launch | B41: 1 | C41: 2 | D41: 3 | E41: 4 | F41: 5 | G41: 6 | H41: 7
A42: Ramp 1 — standard launch, % of peak | B42: 0.1 | C42: 0.25 | D42: 0.45 | E42: 0.65 | F42: 0.82 | G42: 0.93 | H42: 1
A43: Ramp 2 — orphan-disease launch, % of peak | B43: 0.15 | C43: 0.35 | D43: 0.55 | E43: 0.75 | F43: 0.9 | G43: 1 | H43: 1
A44: Commercial SG&A, % of sales (years 1–5; floor = program maturity %) | B44: 0.9 | C44: 0.55 | D44: 0.4 | E44: 0.32 | F44: 0.28
A46: Ivonescimab — EGFRm NSCLC after TKI (HARMONi) (PDUFA)
A47: Launch year (first full year of sales) | B47: =CHOOSE($B$4,C47,D47,E47) -> 2027 | C47: 2027 | D47: 2027 | E47: 2027
...

Sheet Pipeline
A1: SMMT — risk-adjusted program build ($mm)
A2: Year | C2: 2027 | D2: 2028 | E2: 2029 | F2: 2030 | G2: 2031 | H2: 2032 | I2: 2033 | J2: 2034 | K2: 2035 | L2: 2036 | M2: 2037 | N2: 2038 | O2: 2039 | P2: 2040 | Q2: 2041 | R2: 2042 | S2: 2043 | T2: 2044 | U2: 2045 | V2: 2046 | W2: 2047 | X2: 2048 | Y2: 2049 | Z2: 2050
A4: Ivonescimab — EGFRm NSCLC after TKI (HARMONi)
A5: Years since launch (approved on time) | C5: =C$2-Assumptions!$B$47+1 -> 1 | D5: =D$2-Assumptions!$B$47+1 -> 2 | E5: =E$2-Assumptions!$B$47+1 -> 3 | F5: =F$2-Assumptions!$B$47+1 -> 4 | G5: =G$2-Assumptions!$B$47+1 -> 5 | H5: =H$2-Assumptions!$B$47+1 -> 6 | I5: =I$2-Assumptions!$B$47+1 -> 7 | J5: =J$2-Assumptions!$B$47+1 -> 8 | ... Z5: =Z$2-Assumptions!$B$47+1 -> 24
A6: Net sales, unrisked (approved on time) | C6: =IF(C$2>Assumptions!$B$56,0*(1-Assumptions!$B$57),IF(C5>=1,Assumptions!$B$48*CHOOSE(Assumptions!$B$55,INDEX(Assumptions!$B$42:$H$42,MIN(C5,7)),INDEX(Assumptions!$B$43:$H$43,MIN(C5,7))),0)) -> 70 | D6: =IF(D$2>Assumptions!$B$56,C6*(1-Assumptions!$B$57),IF(D5>=1,Assumptions!$B$48*CHOOSE(Assumptions!$B$55,INDEX(Assumptions!$B$42:$H$42,MIN(D5,7)),INDEX(Assumptions!$B$43:$H$43,MIN(D5,7))),0)) -> 175 | E6: =IF(E$2>Assumptions!$B$56,D6*(1-Assumptions!$B$57),IF(E5>=1,Assumptions!$B$48*CHOOSE(Assumptions!$B$55,INDEX(Assumptions!$B$42:$H$42,MIN(E5,7)),INDEX(Assumptions!$B$43:$H$43,MIN(E5,7))),0)) -> 315 | F6: =IF(F$2>Assumptions!$B$56,E6*(1-Assumptions!$B$57),IF(F5>=1,Assumptions!$B$48*CHOOSE(Assumptions!$B$55,INDEX(Assumptions!$B$42:$H$42,MIN(F5,7)),INDEX(Assumptions!$B$43:$H$43,MIN(F5,7))),0)) -> 455 | G6: =IF(G$2>Assumptions!$B$56,F6*(1-Assumptions!$B$57),IF(G5>=1,Assumptions!$B$48*CHOOSE(Assumptions!$B$55,INDEX(Assumptions!$B$42:$H$42,MIN(G5,7)),INDEX(Assumptions!$B$43:$H$43,MIN(G5,7))),0)) -> 574 | H6: =IF(H$2>Assumptions!$B$56,G6*(1-Assumptions!$B$57),IF(H5>=1,Assumptions!$B$48*CHOOSE(Assumptions!$B$55,INDEX(Assumptions!$B$42:$H$42,MIN(H5,7)),INDEX(Assumptions!$B$43:$H$43,MIN(H5,7))),0)) -> 651 | I6: =IF(I$2>Assumptions!$B$56,H6*(1-Assumptions!$B$57),IF(I5>=1,Assumptions!$B$48*CHOOSE(Assumptions!$B$55,INDEX(Assumptions!$B$42:$H$42,MIN(I5,7)),INDEX(Assumptions!$B$43:$H$43,MIN(I5,7))),0)) -> 700 | J6: =IF(J$2>Assumptions!$B$56,I6*(1-Assumptions!$B$57),IF(J5>=1,Assumptions!$B$48*CHOOSE(Assumptions!$B$55,INDEX(Assumptions!$B$42:$H$42,MIN(J5,7)),INDEX(Assumptions!$B$43:$H$43,MIN(J5,7))),0)) -> 700 | K6: =IF(K$2>Assumptions!$B$56,J6*(1-Assumptions!$B$57),IF(K5>=1,Assumptions!$B$48*CHOOSE(Assumptions!$B$55,INDEX(Assumptions!$B$42:$H$42,MIN(K5,7)),INDEX(Assumptions!$B$43:$H$43,MIN(K5,7))),0)) -> 700 | ... Z6: =IF(Z$2>Assumptions!$B$56,Y6*(1-Assumptions!$B$57),IF(Z5>=1,Assumptions!$B$48*CHOOSE(Assumptions!$B$55,INDEX(Assumptions!$B$42:$H$42,MIN(Z5,7)),INDEX(Assumptions!$B$43:$H$43,MIN(Z5,7))),0)) -> 0.68359375
A7: Years since launch (approved after a CRL) | C7: =C$2-(Assumptions!$B$47+Assumptions!$B$34)+1 -> -2 | D7: =D$2-(Assumptions!$B$47+Assumptions!$B$34)+1 -> -1 | E7: =E$2-(Assumptions!$B$47+Assumptions!$B$34)+1 -> 0 | F7: =F$2-(Assumptions!$B$47+Assumptions!$B$34)+1 -> 1 | G7: =G$2-(Assumptions!$B$47+Assumptions!$B$34)+1 -> 2 | H7: =H$2-(Assumptions!$B$47+Assumptions!$B$34)+1 -> 3 | I7: =I$2-(Assumptions!$B$47+Assumptions!$B$34)+1 -> 4 | J7: =J$2-(Assumptions!$B$47+Assumptions!$B$34)+1 -> 5 | ... Z7: =Z$2-(Assumptions!$B$47+Assumptions!$B$34)+1 -> 21
A8: Net sales, unrisked (approved after a CRL) | C8: =IF(C$2>Assumptions!$B$56,0*(1-Assumptions!$B$57),IF(C7>=1,Assumptions!$B$48*CHOOSE(Assumptions!$B$55,INDEX(Assumptions!$B$42:$H$42,MIN(C7,7)),INDEX(Assumptions!$B$43:$H$43,MIN(C7,7))),0)) -> 0 | D8: =IF(D$2>Assumptions!$B$56,C8*(1-Assumptions!$B$57),IF(D7>=1,Assumptions!$B$48*CHOOSE(Assumptions!$B$55,INDEX(Assumptions!$B$42:$H$42,MIN(D7,7)),INDEX(Assumptions!$B$43:$H$43,MIN(D7,7))),0)) -> 0 | E8: =IF(E$2>Assumptions!$B$56,D8*(1-Assumptions!$B$57),IF(E7>=1,Assumptions!$B$48*CHOOSE(Assumptions!$B$55,INDEX(Assumptions!$B$42:$H$42,MIN(E7,7)),INDEX(Assumptions!$B$43:$H$43,MIN(E7,7))),0)) -> 0 | F8: =IF(F$2>Assumptions!$B$56,E8*(1-Assumptions!$B$57),IF(F7>=1,Assumptions!$B$48*CHOOSE(Assumptions!$B$55,INDEX(Assumptions!$B$42:$H$42,MIN(F7,7)),INDEX(Assumptions!$B$43:$H$43,MIN(F7,7))),0)) -> 70 | G8: =IF(G$2>Assumptions!$B$56,F8*(1-Assumptions!$B$57),IF(G7>=1,Assumptions!$B$48*CHOOSE(Assumptions!$B$55,INDEX(Assumptions!$B$42:$H$42,MIN(G7,7)),INDEX(Assumptions!$B$43:$H$43,MIN(G7,7))),0)) -> 175 | H8: =IF(H$2>Assumptions!$B$56,G8*(1-Assumptions!$B$57),IF(H7>=1,Assumptions!$B$48*CHOOSE(Assumptions!$B$55,INDEX(Assumptions!$B$42:$H$42,MIN(H7,7)),INDEX(Assumptions!$B$43:$H$43,MIN(H7,7))),0)) -> 315 | I8: =IF(I$2>Assumptions!$B$56,H8*(1-Assumptions!$B$57),IF(I7>=1,Assumptions!$B$48*CHOOSE(Assumptions!$B$55,INDEX(Assumptions!$B$42:$H$42,MIN(I7,7)),INDEX(Assumptions!$B$43:$H$43,MIN(I7,7))),0)) -> 455 | J8: =IF(J$2>Assumptions!$B$56,I8*(1-Assumptions!$B$57),IF(J7>=1,Assumptions!$B$48*CHOOSE(Assumptions!$B$55,INDEX(Assumptions!$B$42:$H$42,MIN(J7,7)),INDEX(Assumptions!$B$43:$H$43,MIN(J7,7))),0)) -> 574 | K8: =IF(K$2>Assumptions!$B$56,J8*(1-Assumptions!$B$57),IF(K7>=1,Assumptions!$B$48*CHOOSE(Assumptions!$B$55,INDEX(Assumptions!$B$42:$H$42,MIN(K7,7)),INDEX(Assumptions!$B$43:$H$43,MIN(K7,7))),0)) -> 651 | ... Z8: =IF(Z$2>Assumptions!$B$56,Y8*(1-Assumptions!$B$57),IF(Z7>=1,Assumptions!$B$48*CHOOSE(Assumptions!$B$55,INDEX(Assumptions!$B$42:$H$42,MIN(Z7,7)),INDEX(Assumptions!$B$43:$H$43,MIN(Z7,7))),0)) -> 0.68359375
A9: Product net sales, risk-adjusted | C9: =Assumptions!$B$32*C6+(1-Assumptions!$B$32)*Assumptions!$B$33*C8 -> 28 | D9: =Assumptions!$B$32*D6+(1-Assumptions!$B$32)*Assumptions!$B$33*D8 -> 70 | E9: =Assumptions!$B$32*E6+(1-Assumptions!$B$32)*Assumptions!$B$33*E8 -> 126 | F9: =Assumptions!$B$32*F6+(1-Assumptions!$B$32)*Assumptions!$B$33*F8 -> 192.5 | G9: =Assumptions!$B$32*G6+(1-Assumptions!$B$32)*Assumptions!$B$33*G8 -> 255.85 | H9: =Assumptions!$B$32*H6+(1-Assumptions!$B$32)*Assumptions!$B$33*H8 -> 307.65 | I9: =Assumptions!$B$32*I6+(1-Assumptions!$B$32)*Assumptions!$B$33*I8 -> 348.25 | J9: =Assumptions!$B$32*J6+(1-Assumptions!$B$32)*Assumptions!$B$33*J8 -> 366.1 | ... Z9: =Assumptions!$B$32*Z6+(1-Assumptions!$B$32)*Assumptions!$B$33*Z8 -> 0.37597656
A10: Company revenue, risk-adjusted (incl. milestones) | C10: =C9*Assumptions!$B$50 -> 28 | D10: =D9*Assumptions!$B$50 -> 70 | E10: =E9*Assumptions!$B$50 -> 126 | F10: =F9*Assumptions!$B$50 -> 192.5 | G10: =G9*Assumptions!$B$50 -> 255.85 | H10: =H9*Assumptions!$B$50 -> 307.65 | I10: =I9*Assumptions!$B$50 -> 348.25 | J10: =J9*Assumptions!$B$50 -> 366.1 | ... Z10: =Z9*Assumptions!$B$50 -> 0.37597656
A11: COGS + royalties, risk-adjusted | C11: =C9*(Assumptions!$B$51+Assumptions!$B$52) -> 5.04 | D11: =D9*(Assumptions!$B$51+Assumptions!$B$52) -> 12.6 | E11: =E9*(Assumptions!$B$51+Assumptions!$B$52) -> 22.68 | F11: =F9*(Assumptions!$B$51+Assumptions!$B$52) -> 34.65 | G11: =G9*(Assumptions!$B$51+Assumptions!$B$52) -> 46.053 | H11: =H9*(Assumptions!$B$51+Assumptions!$B$52) -> 55.377 | I11: =I9*(Assumptions!$B$51+Assumptions!$B$52) -> 62.685 | J11: =J9*(Assumptions!$B$51+Assumptions!$B$52) -> 65.898 | ... Z11: =Z9*(Assumptions!$B$51+Assumptions!$B$52) -> 0.067675781
A12: Commercial SG&A, risk-adjusted | C12: =Assumptions!$B$32*IF(Assumptions!$B$53=0,0,IF(C5=0,Assumptions!$B$54,IF(C5>=1,C6*IF(OR(Assumptions!$B$50<1,C5>5),Assumptions!$B$53,MAX(Assumptions!$B$53,INDEX(Assumptions!$B$44:$F$44,C5))),0)))+(1-Assumptions!$B$32)*Assumptions!$B$33*IF(Assumptions!$B$53=0,0,IF(C7=0,Assumptions!$B$54,IF(C7>=1,C8*IF(OR(Assumptions!$B$50<1,C7>5),Assumptions!$B$53,MAX(Assumptions!$B$53,INDEX(Assumptions!$B$44:$F$44,C7))),0))) -> 25.2 | D12: =Assumptions!$B$32*IF(Assumptions!$B$53=0,0,IF(D5=0,Assumptions!$B$54,IF(D5>=1,D6*IF(OR(Assumptions!$B$50<1,D5>5),Assumptions!$B$53,MAX(Assumptions!$B$53,INDEX(Assumptions!$B$44:$F$44,D5))),0)))+(1-Assumptions!$B$32)*Assumptions!$B$33*IF(Assumptions!$B$53=0,0,IF(D7=0,Assumptions!$B$54,IF(D7>=1,D8*IF(OR(Assumptions!$B$50<1,D7>5),Assumptions!$B$53,MAX(Assumptions!$B$53,INDEX(Assumptions!$B$44:$F$44,D7))),0))) -> 38.5 | E12: =Assumptions!$B$32*IF(Assumptions!$B$53=0,0,IF(E5=0,Assumptions!$B$54,IF(E5>=1,E6*IF(OR(Assumptions!$B$50<1,E5>5),Assumptions!$B$53,MAX(Assumptions!$B$53,INDEX(Assumptions!$B$44:$F$44,E5))),0)))+(1-Assumptions!$B$32)*Assumptions!$B$33*IF(Assumptions!$B$53=0,0,IF(E7=0,Assumptions!$B$54,IF(E7>=1,E8*IF(OR(Assumptions!$B$50<1,E7>5),Assumptions!$B$53,MAX(Assumptions!$B$53,INDEX(Assumptions!$B$44:$F$44,E7))),0))) -> 59.4 | F12: =Assumptions!$B$32*IF(Assumptions!$B$53=0,0,IF(F5=0,Assumptions!$B$54,IF(F5>=1,F6*IF(OR(Assumptions!$B$50<1,F5>5),Assumptions!$B$53,MAX(Assumptions!$B$53,INDEX(Assumptions!$B$44:$F$44,F5))),0)))+(1-Assumptions!$B$32)*Assumptions!$B$33*IF(Assumptions!$B$53=0,0,IF(F7=0,Assumptions!$B$54,IF(F7>=1,F8*IF(OR(Assumptions!$B$50<1,F7>5),Assumptions!$B$53,MAX(Assumptions!$B$53,INDEX(Assumptions!$B$44:$F$44,F7))),0))) -> 67.69 | G12: =Assumptions!$B$32*IF(Assumptions!$B$53=0,0,IF(G5=0,Assumptions!$B$54,IF(G5>=1,G6*IF(OR(Assumptions!$B$50<1,G5>5),Assumptions!$B$53,MAX(Assumptions!$B$53,INDEX(Assumptions!$B$44:$F$44,G5))),0)))+(1-Assumptions!$B$32)*Assumptions!$B$33*IF(Assumptions!$B$53=0,0,IF(G7=0,Assumptions!$B$54,IF(G7>=1,G8*IF(OR(Assumptions!$B$50<1,G7>5),Assumptions!$B$53,MAX(Assumptions!$B$53,INDEX(Assumptions!$B$44:$F$44,G7))),0))) -> 83.3175 | H12: =Assumptions!$B$32*IF(Assumptions!$B$53=0,0,IF(H5=0,Assumptions!$B$54,IF(H5>=1,H6*IF(OR(Assumptions!$B$50<1,H5>5),Assumptions!$B$53,MAX(Assumptions!$B$53,INDEX(Assumptions!$B$44:$F$44,H5))),0)))+(1-Assumptions!$B$32)*Assumptions!$B$33*IF(Assumptions!$B$53=0,0,IF(H7=0,Assumptions!$B$54,IF(H7>=1,H8*IF(OR(Assumptions!$B$50<1,H7>5),Assumptions!$B$53,MAX(Assumptions!$B$53,INDEX(Assumptions!$B$44:$F$44,H7))),0))) -> 97.02 | I12: =Assumptions!$B$32*IF(Assumptions!$B$53=0,0,IF(I5=0,Assumptions!$B$54,IF(I5>=1,I6*IF(OR(Assumptions!$B$50<1,I5>5),Assumptions!$B$53,MAX(Assumptions!$B$53,INDEX(Assumptions!$B$44:$F$44,I5))),0)))+(1-Assumptions!$B$32)*Assumptions!$B$33*IF(Assumptions!$B$53=0,0,IF(I7=0,Assumptions!$B$54,IF(I7>=1,I8*IF(OR(Assumptions!$B$50<1,I7>5),Assumptions!$B$53,MAX(Assumptions!$B$53,INDEX(Assumptions!$B$44:$F$44,I7))),0))) -> 105.84 | J12: =Assumptions!$B$32*IF(Assumptions!$B$53=0,0,IF(J5=0,Assumptions!$B$54,IF(J5>=1,J6*IF(OR(Assumptions!$B$50<1,J5>5),Assumptions!$B$53,MAX(Assumptions!$B$53,INDEX(Assumptions!$B$44:$F$44,J5))),0)))+(1-Assumptions!$B$32)*Assumptions!$B$33*IF(Assumptions!$B$53=0,0,IF(J7=0,Assumptions!$B$54,IF(J7>=1,J8*IF(OR(Assumptions!$B$50<1,J7>5),Assumptions!$B$53,MAX(Assumptions!$B$53,INDEX(Assumptions!$B$44:$F$44,J7))),0))) -> 109.83 | ... Z12: =Assumptions!$B$32*IF(Assumptions!$B$53=0,0,IF(Z5=0,Assumptions!$B$54,IF(Z5>=1,Z6*IF(OR(Assumptions!$B$50<1,Z5>5),Assumptions!$B$53,MAX(Assumptions!$B$53,INDEX(Assumptions!$B$44:$F$44,Z5))),0)))+(1-Assumptions!$B$32)*Assumptions!$B$33*IF(Assumptions!$B$53=0,0,IF(Z7=0,Assumptions!$B$54,IF(Z7>=1,Z8*IF(OR(Assumptions!$B$50<1,Z7>5),Assumptions!$B$53,MAX(Assumptions!$B$53,INDEX(Assumptions!$B$44:$F$44,Z7))),0))) -> 0.11279297
A13: Development R&D, risk-adjusted | C13: =0 -> 0 | D13: =0 -> 0 | E13: =0 -> 0 | F13: =0 -> 0 | G13: =0 -> 0 | H13: =0 -> 0 | I13: =0 -> 0 | J13: =0 -> 0 | ... Z13: =0 -> 0
A14: Program contribution (pre-tax) | C14: =C10-C11-C12-C13 -> -2.24 | D14: =D10-D11-D12-D13 -> 18.9 | E14: =E10-E11-E12-E13 -> 43.92 | F14: =F10-F11-F12-F13 -> 90.16 | G14: =G10-G11-G12-G13 -> 126.4795 | H14: =H10-H11-H12-H13 -> 155.253 | I14: =I10-I11-I12-I13 -> 179.725 | J14: =J10-J11-J12-J13 -> 190.372 | ... Z14: =Z10-Z11-Z12-Z13 -> 0.19550781
A16: Ivonescimab — 1L NSCLC with chemo (HARMONi-3)
A17: Years since launch | C17: =C$2-Assumptions!$B$60+1 -> -1 | D17: =D$2-Assumptions!$B$60+1 -> 0 | E17: =E$2-Assumptions!$B$60+1 -> 1 | F17: =F$2-Assumptions!$B$60+1 -> 2 | G17: =G$2-Assumptions!$B$60+1 -> 3 | H17: =H$2-Assumptions!$B$60+1 -> 4 | I17: =I$2-Assumptions!$B$60+1 -> 5 | J17: =J$2-Assumptions!$B$60+1 -> 6 | ... Z17: =Z$2-Assumptions!$B$60+1 -> 22
A18: Net sales, unrisked | C18: =IF(C$2>Assumptions!$B$69,0*(1-Assumptions!$B$70),IF(C17>=1,Assumptions!$B$61*CHOOSE(Assumptions!$B$68,INDEX(Assumptions!$B$42:$H$42,MIN(C17,7)),INDEX(Assumptions!$B$43:$H$43,MIN(C17,7))),0)) -> 0 | D18: =IF(D$2>Assumptions!$B$69,C18*(1-Assumptions!$B$70),IF(D17>=1,Assumptions!$B$61*CHOOSE(Assumptions!$B$68,INDEX(Assumptions!$B$42:$H$42,MIN(D17,7)),INDEX(Assumptions!$B$43:$H$43,MIN(D17,7))),0)) -> 0 | E18: =IF(E$2>Assumptions!$B$69,D18*(1-Assumptions!$B$70),IF(E17>=1,Assumptions!$B$61*CHOOSE(Assumptions!$B$68,INDEX(Assumptions!$B$42:$H$42,MIN(E17,7)),INDEX(Assumptions!$B$43:$H$43,MIN(E17,7))),0)) -> 500 | F18: =IF(F$2>Assumptions!$B$69,E18*(1-Assumptions!$B$70),IF(F17>=1,Assumptions!$B$61*CHOOSE(Assumptions!$B$68,INDEX(Assumptions!$B$42:$H$42,MIN(F17,7)),INDEX(Assumptions!$B$43:$H$43,MIN(F17,7))),0)) -> 1250 | G18: =IF(G$2>Assumptions!$B$69,F18*(1-Assumptions!$B$70),IF(G17>=1,Assumptions!$B$61*CHOOSE(Assumptions!$B$68,INDEX(Assumptions!$B$42:$H$42,MIN(G17,7)),INDEX(Assumptions!$B$43:$H$43,MIN(G17,7))),0)) -> 2250 | H18: =IF(H$2>Assumptions!$B$69,G18*(1-Assumptions!$B$70),IF(H17>=1,Assumptions!$B$61*CHOOSE(Assumptions!$B$68,INDEX(Assumptions!$B$42:$H$42,MIN(H17,7)),INDEX(Assumptions!$B$43:$H$43,MIN(H17,7))),0)) -> 3250 | I18: =IF(I$2>Assumptions!$B$69,H18*(1-Assumptions!$B$70),IF(I17>=1,Assumptions!$B$61*CHOOSE(Assumptions!$B$68,INDEX(Assumptions!$B$42:$H$42,MIN(I17,7)),INDEX(Assumptions!$B$43:$H$43,MIN(I17,7))),0)) -> 4100 | J18: =IF(J$2>Assumptions!$B$69,I18*(1-Assumptions!$B$70),IF(J17>=1,Assumptions!$B$61*CHOOSE(Assumptions!$B$68,INDEX(Assumptions!$B$42:$H$42,MIN(J17,7)),INDEX(Assumptions!$B$43:$H$43,MIN(J17,7))),0)) -> 4650 | K18: =IF(K$2>Assumptions!$B$69,J18*(1-Assumptions!$B$70),IF(K17>=1,Assumptions!$B$61*CHOOSE(Assumptions!$B$68,INDEX(Assumptions!$B$42:$H$42,MIN(K17,7)),INDEX(Assumptions!$B$43:$H$43,MIN(K17,7))),0)) -> 5000 | ... Z18: =IF(Z$2>Assumptions!$B$69,Y18*(1-Assumptions!$B$70),IF(Z17>=1,Assumptions!$B$61*CHOOSE(Assumptions!$B$68,INDEX(Assumptions!$B$42:$H$42,MIN(Z17,7)),INDEX(Assumptions!$B$43:$H$43,MIN(Z17,7))),0)) -> 9.765625
A19: Product net sales, risk-adjusted | C19: =C18*MIN(1,Assumptions!$B$62*Assumptions!$B$37) -> 0 | D19: =D18*MIN(1,Assumptions!$B$62*Assumptions!$B$37) -> 0 | E19: =E18*MIN(1,Assumptions!$B$62*Assumptions!$B$37) -> 225 | F19: =F18*MIN(1,Assumptions!$B$62*Assumptions!$B$37) -> 562.5 | G19: =G18*MIN(1,Assumptions!$B$62*Assumptions!$B$37) -> 1012.5 | H19: =H18*MIN(1,Assumptions!$B$62*Assumptions!$B$37) -> 1462.5 | I19: =I18*MIN(1,Assumptions!$B$62*Assumptions!$B$37) -> 1845 | J19: =J18*MIN(1,Assumptions!$B$62*Assumptions!$B$37) -> 2092.5 | ... Z19: =Z18*MIN(1,Assumptions!$B$62*Assumptions!$B$37) -> 4.3945312
A20: Company revenue, risk-adjusted (incl. milestones) | C20: =C19*Assumptions!$B$63 -> 0 | D20: =D19*Assumptions!$B$63 -> 0 | E20: =E19*Assumptions!$B$63 -> 225 | F20: =F19*Assumptions!$B$63 -> 562.5 | G20: =G19*Assumptions!$B$63 -> 1012.5 | H20: =H19*Assumptions!$B$63 -> 1462.5 | I20: =I19*Assumptions!$B$63 -> 1845 | J20: =J19*Assumptions!$B$63 -> 2092.5 | ... Z20: =Z19*Assumptions!$B$63 -> 4.3945312
A21: COGS + royalties, risk-adjusted | C21: =C19*(Assumptions!$B$64+Assumptions!$B$65) -> 0 | D21: =D19*(Assumptions!$B$64+Assumptions!$B$65) -> 0 | E21: =E19*(Assumptions!$B$64+Assumptions!$B$65) -> 45 | F21: =F19*(Assumptions!$B$64+Assumptions!$B$65) -> 112.5 | G21: =G19*(Assumptions!$B$64+Assumptions!$B$65) -> 202.5 | H21: =H19*(Assumptions!$B$64+Assumptions!$B$65) -> 292.5 | I21: =I19*(Assumptions!$B$64+Assumptions!$B$65) -> 369 | J21: =J19*(Assumptions!$B$64+Assumptions!$B$65) -> 418.5 | ... Z21: =Z19*(Assumptions!$B$64+Assumptions!$B$65) -> 0.87890625
A22: Commercial SG&A, risk-adjusted | C22: =MIN(1,Assumptions!$B$62*Assumptions!$B$37)*IF(Assumptions!$B$66=0,0,IF(C17=0,Assumptions!$B$67,IF(C17>=1,C18*IF(OR(Assumptions!$B$63<1,C17>5),Assumptions!$B$66,MAX(Assumptions!$B$66,INDEX(Assumptions!$B$44:$F$44,C17))),0))) -> 0 | D22: =MIN(1,Assumptions!$B$62*Assumptions!$B$37)*IF(Assumptions!$B$66=0,0,IF(D17=0,Assumptions!$B$67,IF(D17>=1,D18*IF(OR(Assumptions!$B$63<1,D17>5),Assumptions!$B$66,MAX(Assumptions!$B$66,INDEX(Assumptions!$B$44:$F$44,D17))),0))) -> 45 | E22: =MIN(1,Assumptions!$B$62*Assumptions!$B$37)*IF(Assumptions!$B$66=0,0,IF(E17=0,Assumptions!$B$67,IF(E17>=1,E18*IF(OR(Assumptions!$B$63<1,E17>5),Assumptions!$B$66,MAX(Assumptions!$B$66,INDEX(Assumptions!$B$44:$F$44,E17))),0))) -> 202.5 | F22: =MIN(1,Assumptions!$B$62*Assumptions!$B$37)*IF(Assumptions!$B$66=0,0,IF(F17=0,Assumptions!$B$67,IF(F17>=1,F18*IF(OR(Assumptions!$B$63<1,F17>5),Assumptions!$B$66,MAX(Assumptions!$B$66,INDEX(Assumptions!$B$44:$F$44,F17))),0))) -> 309.375 | G22: =MIN(1,Assumptions!$B$62*Assumptions!$B$37)*IF(Assumptions!$B$66=0,0,IF(G17=0,Assumptions!$B$67,IF(G17>=1,G18*IF(OR(Assumptions!$B$63<1,G17>5),Assumptions!$B$66,MAX(Assumptions!$B$66,INDEX(Assumptions!$B$44:$F$44,G17))),0))) -> 405 | H22: =MIN(1,Assumptions!$B$62*Assumptions!$B$37)*IF(Assumptions!$B$66=0,0,IF(H17=0,Assumptions!$B$67,IF(H17>=1,H18*IF(OR(Assumptions!$B$63<1,H17>5),Assumptions!$B$66,MAX(Assumptions!$B$66,INDEX(Assumptions!$B$44:$F$44,H17))),0))) -> 468 | I22: =MIN(1,Assumptions!$B$62*Assumptions!$B$37)*IF(Assumptions!$B$66=0,0,IF(I17=0,Assumptions!$B$67,IF(I17>=1,I18*IF(OR(Assumptions!$B$63<1,I17>5),Assumptions!$B$66,MAX(Assumptions!$B$66,INDEX(Assumptions!$B$44:$F$44,I17))),0))) -> 516.6 | J22: =MIN(1,Assumptions!$B$62*Assumptions!$B$37)*IF(Assumptions!$B$66=0,0,IF(J17=0,Assumptions!$B$67,IF(J17>=1,J18*IF(OR(Assumptions!$B$63<1,J17>5),Assumptions!$B$66,MAX(Assumptions!$B$66,INDEX(Assumptions!$B$44:$F$44,J17))),0))) -> 523.125 | ... Z22: =MIN(1,Assumptions!$B$62*Assumptions!$B$37)*IF(Assumptions!$B$66=0,0,IF(Z17=0,Assumptions!$B$67,IF(Z17>=1,Z18*IF(OR(Assumptions!$B$63<1,Z17>5),Assumptions!$B$66,MAX(Assumptions!$B$66,INDEX(Assumptions!$B$44:$F$44,Z17))),0))) -> 1.0986328
A23: Development R&D, risk-adjusted | C23: =IFERROR(INDEX(Assumptions!$B$72:$I$72,MATCH(C$2,Assumptions!$B$71:$I$71,0))*INDEX(Assumptions!$B$73:$I$73,MATCH(C$2,Assumptions!$B$71:$I$71,0)),0) -> 250 | D23: =IFERROR(INDEX(Assumptions!$B$72:$I$72,MATCH(D$2,Assumptions!$B$71:$I$71,0))*INDEX(Assumptions!$B$73:$I$73,MATCH(D$2,Assumptions!$B$71:$I$71,0)),0) -> 150 | E23: =IFERROR(INDEX(Assumptions!$B$72:$I$72,MATCH(E$2,Assumptions!$B$71:$I$71,0))*INDEX(Assumptions!$B$73:$I$73,MATCH(E$2,Assumptions!$B$71:$I$71,0)),0) -> 22.5 | F23: =IFERROR(INDEX(Assumptions!$B$72:$I$72,MATCH(F$2,Assumptions!$B$71:$I$71,0))*INDEX(Assumptions!$B$73:$I$73,MATCH(F$2,Assumptions!$B$71:$I$71,0)),0) -> 0 | G23: =IFERROR(INDEX(Assumptions!$B$72:$I$72,MATCH(G$2,Assumptions!$B$71:$I$71,0))*INDEX(Assumptions!$B$73:$I$73,MATCH(G$2,Assumptions!$B$71:$I$71,0)),0) -> 0 | H23: =IFERROR(INDEX(Assumptions!$B$72:$I$72,MATCH(H$2,Assumptions!$B$71:$I$71,0))*INDEX(Assumptions!$B$73:$I$73,MATCH(H$2,Assumptions!$B$71:$I$71,0)),0) -> 0 | I23: =IFERROR(INDEX(Assumptions!$B$72:$I$72,MATCH(I$2,Assumptions!$B$71:$I$71,0))*INDEX(Assumptions!$B$73:$I$73,MATCH(I$2,Assumptions!$B$71:$I$71,0)),0) -> 0 | J23: =IFERROR(INDEX(Assumptions!$B$72:$I$72,MATCH(J$2,Assumptions!$B$71:$I$71,0))*INDEX(Assumptions!$B$73:$I$73,MATCH(J$2,Assumptions!$B$71:$I$71,0)),0) -> 0 | ... Z23: =IFERROR(INDEX(Assumptions!$B$72:$I$72,MATCH(Z$2,Assumptions!$B$71:$I$71,0))*INDEX(Assumptions!$B$73:$I$73,MATCH(Z$2,Assumptions!$B$71:$I$71,0)),0) -> 0
A24: Program contribution (pre-tax) | C24: =C20-C21-C22-C23 -> -250 | D24: =D20-D21-D22-D23 -> -195 | E24: =E20-E21-E22-E23 -> -45 | F24: =F20-F21-F22-F23 -> 140.625 | G24: =G20-G21-G22-G23 -> 405 | H24: =H20-H21-H22-H23 -> 702 | I24: =I20-I21-I22-I23 -> 959.4 | J24: =J20-J21-J22-J23 -> 1150.875 | ... Z24: =Z20-Z21-Z22-Z23 -> 2.4169922
A26: Ivonescimab — PD-L1-high 1L monotherapy (HARMONi-7)
A27: Years since launch | C27: =C$2-Assumptions!$B$76+1 -> -1 | D27: =D$2-Assumptions!$B$76+1 -> 0 | E27: =E$2-Assumptions!$B$76+1 -> 1 | F27: =F$2-Assumptions!$B$76+1 -> 2 | G27: =G$2-Assumptions!$B$76+1 -> 3 | H27: =H$2-Assumptions!$B$76+1 -> 4 | I27: =I$2-Assumptions!$B$76+1 -> 5 | J27: =J$2-Assumptions!$B$76+1 -> 6 | ... Z27: =Z$2-Assumptions!$B$76+1 -> 22
A28: Net sales, unrisked | C28: =IF(C$2>Assumptions!$B$85,0*(1-Assumptions!$B$86),IF(C27>=1,Assumptions!$B$77*CHOOSE(Assumptions!$B$84,INDEX(Assumptions!$B$42:$H$42,MIN(C27,7)),INDEX(Assumptions!$B$43:$H$43,MIN(C27,7))),0)) -> 0 | D28: =IF(D$2>Assumptions!$B$85,C28*(1-Assumptions!$B$86),IF(D27>=1,Assumptions!$B$77*CHOOSE(Assumptions!$B$84,INDEX(Assumptions!$B$42:$H$42,MIN(D27,7)),INDEX(Assumptions!$B$43:$H$43,MIN(D27,7))),0)) -> 0 | E28: =IF(E$2>Assumptions!$B$85,D28*(1-Assumptions!$B$86),IF(E27>=1,Assumptions!$B$77*CHOOSE(Assumptions!$B$84,INDEX(Assumptions!$B$42:$H$42,MIN(E27,7)),INDEX(Assumptions!$B$43:$H$43,MIN(E27,7))),0)) -> 250 | F28: =IF(F$2>Assumptions!$B$85,E28*(1-Assumptions!$B$86),IF(F27>=1,Assumptions!$B$77*CHOOSE(Assumptions!$B$84,INDEX(Assumptions!$B$42:$H$42,MIN(F27,7)),INDEX(Assumptions!$B$43:$H$43,MIN(F27,7))),0)) -> 625 | G28: =IF(G$2>Assumptions!$B$85,F28*(1-Assumptions!$B$86),IF(G27>=1,Assumptions!$B$77*CHOOSE(Assumptions!$B$84,INDEX(Assumptions!$B$42:$H$42,MIN(G27,7)),INDEX(Assumptions!$B$43:$H$43,MIN(G27,7))),0)) -> 1125 | H28: =IF(H$2>Assumptions!$B$85,G28*(1-Assumptions!$B$86),IF(H27>=1,Assumptions!$B$77*CHOOSE(Assumptions!$B$84,INDEX(Assumptions!$B$42:$H$42,MIN(H27,7)),INDEX(Assumptions!$B$43:$H$43,MIN(H27,7))),0)) -> 1625 | I28: =IF(I$2>Assumptions!$B$85,H28*(1-Assumptions!$B$86),IF(I27>=1,Assumptions!$B$77*CHOOSE(Assumptions!$B$84,INDEX(Assumptions!$B$42:$H$42,MIN(I27,7)),INDEX(Assumptions!$B$43:$H$43,MIN(I27,7))),0)) -> 2050 | J28: =IF(J$2>Assumptions!$B$85,I28*(1-Assumptions!$B$86),IF(J27>=1,Assumptions!$B$77*CHOOSE(Assumptions!$B$84,INDEX(Assumptions!$B$42:$H$42,MIN(J27,7)),INDEX(Assumptions!$B$43:$H$43,MIN(J27,7))),0)) -> 2325 | K28: =IF(K$2>Assumptions!$B$85,J28*(1-Assumptions!$B$86),IF(K27>=1,Assumptions!$B$77*CHOOSE(Assumptions!$B$84,INDEX(Assumptions!$B$42:$H$42,MIN(K27,7)),INDEX(Assumptions!$B$43:$H$43,MIN(K27,7))),0)) -> 2500 | ... Z28: =IF(Z$2>Assumptions!$B$85,Y28*(1-Assumptions!$B$86),IF(Z27>=1,Assumptions!$B$77*CHOOSE(Assumptions!$B$84,INDEX(Assumptions!$B$42:$H$42,MIN(Z27,7)),INDEX(Assumptions!$B$43:$H$43,MIN(Z27,7))),0)) -> 4.8828125
A29: Product net sales, risk-adjusted | C29: =C28*MIN(1,Assumptions!$B$78*Assumptions!$B$37) -> 0 | D29: =D28*MIN(1,Assumptions!$B$78*Assumptions!$B$37) -> 0 | E29: =E28*MIN(1,Assumptions!$B$78*Assumptions!$B$37) -> 112.5 | F29: =F28*MIN(1,Assumptions!$B$78*Assumptions!$B$37) -> 281.25 | G29: =G28*MIN(1,Assumptions!$B$78*Assumptions!$B$37) -> 506.25 | H29: =H28*MIN(1,Assumptions!$B$78*Assumptions!$B$37) -> 731.25 | I29: =I28*MIN(1,Assumptions!$B$78*Assumptions!$B$37) -> 922.5 | J29: =J28*MIN(1,Assumptions!$B$78*Assumptions!$B$37) -> 1046.25 | ... Z29: =Z28*MIN(1,Assumptions!$B$78*Assumptions!$B$37) -> 2.1972656
A30: Company revenue, risk-adjusted (incl. milestones) | C30: =C29*Assumptions!$B$79 -> 0 | D30: =D29*Assumptions!$B$79 -> 0 | E30: =E29*Assumptions!$B$79 -> 112.5 | F30: =F29*Assumptions!$B$79 -> 281.25 | G30: =G29*Assumptions!$B$79 -> 506.25 | H30: =H29*Assumptions!$B$79 -> 731.25 | I30: =I29*Assumptions!$B$79 -> 922.5 | J30: =J29*Assumptions!$B$79 -> 1046.25 | ... Z30: =Z29*Assumptions!$B$79 -> 2.1972656
A31: COGS + royalties, risk-adjusted | C31: =C29*(Assumptions!$B$80+Assumptions!$B$81) -> 0 | D31: =D29*(Assumptions!$B$80+Assumptions!$B$81) -> 0 | E31: =E29*(Assumptions!$B$80+Assumptions!$B$81) -> 22.5 | F31: =F29*(Assumptions!$B$80+Assumptions!$B$81) -> 56.25 | G31: =G29*(Assumptions!$B$80+Assumptions!$B$81) -> 101.25 | H31: =H29*(Assumptions!$B$80+Assumptions!$B$81) -> 146.25 | I31: =I29*(Assumptions!$B$80+Assumptions!$B$81) -> 184.5 | J31: =J29*(Assumptions!$B$80+Assumptions!$B$81) -> 209.25 | ... Z31: =Z29*(Assumptions!$B$80+Assumptions!$B$81) -> 0.43945312
A32: Commercial SG&A, risk-adjusted | C32: =MIN(1,Assumptions!$B$78*Assumptions!$B$37)*IF(Assumptions!$B$82=0,0,IF(C27=0,Assumptions!$B$83,IF(C27>=1,C28*IF(OR(Assumptions!$B$79<1,C27>5),Assumptions!$B$82,MAX(Assumptions!$B$82,INDEX(Assumptions!$B$44:$F$44,C27))),0))) -> 0 | D32: =MIN(1,Assumptions!$B$78*Assumptions!$B$37)*IF(Assumptions!$B$82=0,0,IF(D27=0,Assumptions!$B$83,IF(D27>=1,D28*IF(OR(Assumptions!$B$79<1,D27>5),Assumptions!$B$82,MAX(Assumptions!$B$82,INDEX(Assumptions!$B$44:$F$44,D27))),0))) -> 9 | E32: =MIN(1,Assumptions!$B$78*Assumptions!$B$37)*IF(Assumptions!$B$82=0,0,IF(E27=0,Assumptions!$B$83,IF(E27>=1,E28*IF(OR(Assumptions!$B$79<1,E27>5),Assumptions!$B$82,MAX(Assumptions!$B$82,INDEX(Assumptions!$B$44:$F$44,E27))),0))) -> 101.25 | F32: =MIN(1,Assumptions!$B$78*Assumptions!$B$37)*IF(Assumptions!$B$82=0,0,IF(F27=0,Assumptions!$B$83,IF(F27>=1,F28*IF(OR(Assumptions!$B$79<1,F27>5),Assumptions!$B$82,MAX(Assumptions!$B$82,INDEX(Assumptions!$B$44:$F$44,F27))),0))) -> 154.6875 | G32: =MIN(1,Assumptions!$B$78*Assumptions!$B$37)*IF(Assumptions!$B$82=0,0,IF(G27=0,Assumptions!$B$83,IF(G27>=1,G28*IF(OR(Assumptions!$B$79<1,G27>5),Assumptions!$B$82,MAX(Assumptions!$B$82,INDEX(Assumptions!$B$44:$F$44,G27))),0))) -> 202.5 | H32: =MIN(1,Assumptions!$B$78*Assumptions!$B$37)*IF(Assumptions!$B$82=0,0,IF(H27=0,Assumptions!$B$83,IF(H27>=1,H28*IF(OR(Assumptions!$B$79<1,H27>5),Assumptions!$B$82,MAX(Assumptions!$B$82,INDEX(Assumptions!$B$44:$F$44,H27))),0))) -> 234 | I32: =MIN(1,Assumptions!$B$78*Assumptions!$B$37)*IF(Assumptions!$B$82=0,0,IF(I27=0,Assumptions!$B$83,IF(I27>=1,I28*IF(OR(Assumptions!$B$79<1,I27>5),Assumptions!$B$82,MAX(Assumptions!$B$82,INDEX(Assumptions!$B$44:$F$44,I27))),0))) -> 258.3 | J32: =MIN(1,Assumptions!$B$78*Assumptions!$B$37)*IF(Assumptions!$B$82=0,0,IF(J27=0,Assumptions!$B$83,IF(J27>=1,J28*IF(OR(Assumptions!$B$79<1,J27>5),Assumptions!$B$82,MAX(Assumptions!$B$82,INDEX(Assumptions!$B$44:$F$44,J27))),0))) -> 209.25 | ... Z32: =MIN(1,Assumptions!$B$78*Assumptions!$B$37)*IF(Assumptions!$B$82=0,0,IF(Z27=0,Assumptions!$B$83,IF(Z27>=1,Z28*IF(OR(Assumptions!$B$79<1,Z27>5),Assumptions!$B$82,MAX(Assumptions!$B$82,INDEX(Assumptions!$B$44:$F$44,Z27))),0))) -> 0.43945312
A33: Development R&D, risk-adjusted | C33: =IFERROR(INDEX(Assumptions!$B$88:$I$88,MATCH(C$2,Assumptions!$B$87:$I$87,0))*INDEX(Assumptions!$B$89:$I$89,MATCH(C$2,Assumptions!$B$87:$I$87,0)),0) -> 120 | D33: =IFERROR(INDEX(Assumptions!$B$88:$I$88,MATCH(D$2,Assumptions!$B$87:$I$87,0))*INDEX(Assumptions!$B$89:$I$89,MATCH(D$2,Assumptions!$B$87:$I$87,0)),0) -> 80 | E33: =IFERROR(INDEX(Assumptions!$B$88:$I$88,MATCH(E$2,Assumptions!$B$87:$I$87,0))*INDEX(Assumptions!$B$89:$I$89,MATCH(E$2,Assumptions!$B$87:$I$87,0)),0) -> 0 | F33: =IFERROR(INDEX(Assumptions!$B$88:$I$88,MATCH(F$2,Assumptions!$B$87:$I$87,0))*INDEX(Assumptions!$B$89:$I$89,MATCH(F$2,Assumptions!$B$87:$I$87,0)),0) -> 0 | G33: =IFERROR(INDEX(Assumptions!$B$88:$I$88,MATCH(G$2,Assumptions!$B$87:$I$87,0))*INDEX(Assumptions!$B$89:$I$89,MATCH(G$2,Assumptions!$B$87:$I$87,0)),0) -> 0 | H33: =IFERROR(INDEX(Assumptions!$B$88:$I$88,MATCH(H$2,Assumptions!$B$87:$I$87,0))*INDEX(Assumptions!$B$89:$I$89,MATCH(H$2,Assumptions!$B$87:$I$87,0)),0) -> 0 | I33: =IFERROR(INDEX(Assumptions!$B$88:$I$88,MATCH(I$2,Assumptions!$B$87:$I$87,0))*INDEX(Assumptions!$B$89:$I$89,MATCH(I$2,Assumptions!$B$87:$I$87,0)),0) -> 0 | J33: =IFERROR(INDEX(Assumptions!$B$88:$I$88,MATCH(J$2,Assumptions!$B$87:$I$87,0))*INDEX(Assumptions!$B$89:$I$89,MATCH(J$2,Assumptions!$B$87:$I$87,0)),0) -> 0 | ... Z33: =IFERROR(INDEX(Assumptions!$B$88:$I$88,MATCH(Z$2,Assumptions!$B$87:$I$87,0))*INDEX(Assumptions!$B$89:$I$89,MATCH(Z$2,Assumptions!$B$87:$I$87,0)),0) -> 0
A34: Program contribution (pre-tax) | C34: =C30-C31-C32-C33 -> -120 | D34: =D30-D31-D32-D33 -> -89 | E34: =E30-E31-E32-E33 -> -11.25 | F34: =F30-F31-F32-F33 -> 70.3125 | G34: =G30-G31-G32-G33 -> 202.5 | H34: =H30-H31-H32-H33 -> 351 | I34: =I30-I31-I32-I33 -> 479.7 | J34: =J30-J31-J32-J33 -> 627.75 | ... Z34: =Z30-Z31-Z32-Z33 -> 1.3183594
A36: Ivonescimab — other tumors (CRC, bladder, BTC, ADC combos)
A37: Years since launch | C37: =C$2-Assumptions!$B$92+1 -> -3 | D37: =D$2-Assumptions!$B$92+1 -> -2 | E37: =E$2-Assumptions!$B$92+1 -> -1 | F37: =F$2-Assumptions!$B$92+1 -> 0 | G37: =G$2-Assumptions!$B$92+1 -> 1 | H37: =H$2-Assumptions!$B$92+1 -> 2 | I37: =I$2-Assumptions!$B$92+1 -> 3 | J37: =J$2-Assumptions!$B$92+1 -> 4 | ... Z37: =Z$2-Assumptions!$B$92+1 -> 20
A38: Net sales, unrisked | C38: =IF(C$2>Assumptions!$B$101,0*(1-Assumptions!$B$102),IF(C37>=1,Assumptions!$B$93*CHOOSE(Assumptions!$B$100,INDEX(Assumptions!$B$42:$H$42,MIN(C37,7)),INDEX(Assumptions!$B$43:$H$43,MIN(C37,7))),0)) -> 0 | D38: =IF(D$2>Assumptions!$B$101,C38*(1-Assumptions!$B$102),IF(D37>=1,Assumptions!$B$93*CHOOSE(Assumptions!$B$100,INDEX(Assumptions!$B$42:$H$42,MIN(D37,7)),INDEX(Assumptions!$B$43:$H$43,MIN(D37,7))),0)) -> 0 | E38: =IF(E$2>Assumptions!$B$101,D38*(1-Assumptions!$B$102),IF(E37>=1,Assumptions!$B$93*CHOOSE(Assumptions!$B$100,INDEX(Assumptions!$B$42:$H$42,MIN(E37,7)),INDEX(Assumptions!$B$43:$H$43,MIN(E37,7))),0)) -> 0 | F38: =IF(F$2>Assumptions!$B$101,E38*(1-Assumptions!$B$102),IF(F37>=1,Assumptions!$B$93*CHOOSE(Assumptions!$B$100,INDEX(Assumptions!$B$42:$H$42,MIN(F37,7)),INDEX(Assumptions!$B$43:$H$43,MIN(F37,7))),0)) -> 0 | G38: =IF(G$2>Assumptions!$B$101,F38*(1-Assumptions!$B$102),IF(G37>=1,Assumptions!$B$93*CHOOSE(Assumptions!$B$100,INDEX(Assumptions!$B$42:$H$42,MIN(G37,7)),INDEX(Assumptions!$B$43:$H$43,MIN(G37,7))),0)) -> 300 | H38: =IF(H$2>Assumptions!$B$101,G38*(1-Assumptions!$B$102),IF(H37>=1,Assumptions!$B$93*CHOOSE(Assumptions!$B$100,INDEX(Assumptions!$B$42:$H$42,MIN(H37,7)),INDEX(Assumptions!$B$43:$H$43,MIN(H37,7))),0)) -> 750 | I38: =IF(I$2>Assumptions!$B$101,H38*(1-Assumptions!$B$102),IF(I37>=1,Assumptions!$B$93*CHOOSE(Assumptions!$B$100,INDEX(Assumptions!$B$42:$H$42,MIN(I37,7)),INDEX(Assumptions!$B$43:$H$43,MIN(I37,7))),0)) -> 1350 | J38: =IF(J$2>Assumptions!$B$101,I38*(1-Assumptions!$B$102),IF(J37>=1,Assumptions!$B$93*CHOOSE(Assumptions!$B$100,INDEX(Assumptions!$B$42:$H$42,MIN(J37,7)),INDEX(Assumptions!$B$43:$H$43,MIN(J37,7))),0)) -> 1950 | K38: =IF(K$2>Assumptions!$B$101,J38*(1-Assumptions!$B$102),IF(K37>=1,Assumptions!$B$93*CHOOSE(Assumptions!$B$100,INDEX(Assumptions!$B$42:$H$42,MIN(K37,7)),INDEX(Assumptions!$B$43:$H$43,MIN(K37,7))),0)) -> 2460 | ... Z38: =IF(Z$2>Assumptions!$B$101,Y38*(1-Assumptions!$B$102),IF(Z37>=1,Assumptions!$B$93*CHOOSE(Assumptions!$B$100,INDEX(Assumptions!$B$42:$H$42,MIN(Z37,7)),INDEX(Assumptions!$B$43:$H$43,MIN(Z37,7))),0)) -> 11.71875
A39: Product net sales, risk-adjusted | C39: =C38*MIN(1,Assumptions!$B$94*Assumptions!$B$37) -> 0 | D39: =D38*MIN(1,Assumptions!$B$94*Assumptions!$B$37) -> 0 | E39: =E38*MIN(1,Assumptions!$B$94*Assumptions!$B$37) -> 0 | F39: =F38*MIN(1,Assumptions!$B$94*Assumptions!$B$37) -> 0 | G39: =G38*MIN(1,Assumptions!$B$94*Assumptions!$B$37) -> 75 | H39: =H38*MIN(1,Assumptions!$B$94*Assumptions!$B$37) -> 187.5 | I39: =I38*MIN(1,Assumptions!$B$94*Assumptions!$B$37) -> 337.5 | J39: =J38*MIN(1,Assumptions!$B$94*Assumptions!$B$37) -> 487.5 | ... Z39: =Z38*MIN(1,Assumptions!$B$94*Assumptions!$B$37) -> 2.9296875
A40: Company revenue, risk-adjusted (incl. milestones) | C40: =C39*Assumptions!$B$95 -> 0 | D40: =D39*Assumptions!$B$95 -> 0 | E40: =E39*Assumptions!$B$95 -> 0 | F40: =F39*Assumptions!$B$95 -> 0 | G40: =G39*Assumptions!$B$95 -> 75 | H40: =H39*Assumptions!$B$95 -> 187.5 | I40: =I39*Assumptions!$B$95 -> 337.5 | J40: =J39*Assumptions!$B$95 -> 487.5 | ... Z40: =Z39*Assumptions!$B$95 -> 2.9296875
A41: COGS + royalties, risk-adjusted | C41: =C39*(Assumptions!$B$96+Assumptions!$B$97) -> 0 | D41: =D39*(Assumptions!$B$96+Assumptions!$B$97) -> 0 | E41: =E39*(Assumptions!$B$96+Assumptions!$B$97) -> 0 | F41: =F39*(Assumptions!$B$96+Assumptions!$B$97) -> 0 | G41: =G39*(Assumptions!$B$96+Assumptions!$B$97) -> 15 | H41: =H39*(Assumptions!$B$96+Assumptions!$B$97) -> 37.5 | I41: =I39*(Assumptions!$B$96+Assumptions!$B$97) -> 67.5 | J41: =J39*(Assumptions!$B$96+Assumptions!$B$97) -> 97.5 | ... Z41: =Z39*(Assumptions!$B$96+Assumptions!$B$97) -> 0.5859375
A42: Commercial SG&A, risk-adjusted | C42: =MIN(1,Assumptions!$B$94*Assumptions!$B$37)*IF(Assumptions!$B$98=0,0,IF(C37=0,Assumptions!$B$99,IF(C37>=1,C38*IF(OR(Assumptions!$B$95<1,C37>5),Assumptions!$B$98,MAX(Assumptions!$B$98,INDEX(Assumptions!$B$44:$F$44,C37))),0))) -> 0 | D42: =MIN(1,Assumptions!$B$94*Assumptions!$B$37)*IF(Assumptions!$B$98=0,0,IF(D37=0,Assumptions!$B$99,IF(D37>=1,D38*IF(OR(Assumptions!$B$95<1,D37>5),Assumptions!$B$98,MAX(Assumptions!$B$98,INDEX(Assumptions!$B$44:$F$44,D37))),0))) -> 0 | E42: =MIN(1,Assumptions!$B$94*Assumptions!$B$37)*IF(Assumptions!$B$98=0,0,IF(E37=0,Assumptions!$B$99,IF(E37>=1,E38*IF(OR(Assumptions!$B$95<1,E37>5),Assumptions!$B$98,MAX(Assumptions!$B$98,INDEX(Assumptions!$B$44:$F$44,E37))),0))) -> 0 | F42: =MIN(1,Assumptions!$B$94*Assumptions!$B$37)*IF(Assumptions!$B$98=0,0,IF(F37=0,Assumptions!$B$99,IF(F37>=1,F38*IF(OR(Assumptions!$B$95<1,F37>5),Assumptions!$B$98,MAX(Assumptions!$B$98,INDEX(Assumptions!$B$44:$F$44,F37))),0))) -> 7.5 | G42: =MIN(1,Assumptions!$B$94*Assumptions!$B$37)*IF(Assumptions!$B$98=0,0,IF(G37=0,Assumptions!$B$99,IF(G37>=1,G38*IF(OR(Assumptions!$B$95<1,G37>5),Assumptions!$B$98,MAX(Assumptions!$B$98,INDEX(Assumptions!$B$44:$F$44,G37))),0))) -> 67.5 | H42: =MIN(1,Assumptions!$B$94*Assumptions!$B$37)*IF(Assumptions!$B$98=0,0,IF(H37=0,Assumptions!$B$99,IF(H37>=1,H38*IF(OR(Assumptions!$B$95<1,H37>5),Assumptions!$B$98,MAX(Assumptions!$B$98,INDEX(Assumptions!$B$44:$F$44,H37))),0))) -> 103.125 | I42: =MIN(1,Assumptions!$B$94*Assumptions!$B$37)*IF(Assumptions!$B$98=0,0,IF(I37=0,Assumptions!$B$99,IF(I37>=1,I38*IF(OR(Assumptions!$B$95<1,I37>5),Assumptions!$B$98,MAX(Assumptions!$B$98,INDEX(Assumptions!$B$44:$F$44,I37))),0))) -> 135 | J42: =MIN(1,Assumptions!$B$94*Assumptions!$B$37)*IF(Assumptions!$B$98=0,0,IF(J37=0,Assumptions!$B$99,IF(J37>=1,J38*IF(OR(Assumptions!$B$95<1,J37>5),Assumptions!$B$98,MAX(Assumptions!$B$98,INDEX(Assumptions!$B$44:$F$44,J37))),0))) -> 156 | ... Z42: =MIN(1,Assumptions!$B$94*Assumptions!$B$37)*IF(Assumptions!$B$98=0,0,IF(Z37=0,Assumptions!$B$99,IF(Z37>=1,Z38*IF(OR(Assumptions!$B$95<1,Z37>5),Assumptions!$B$98,MAX(Assumptions!$B$98,INDEX(Assumptions!$B$44:$F$44,Z37))),0))) -> 0.5859375
A43: Development R&D, risk-adjusted | C43: =IFERROR(INDEX(Assumptions!$B$104:$I$104,MATCH(C$2,Assumptions!$B$103:$I$103,0))*INDEX(Assumptions!$B$105:$I$105,MATCH(C$2,Assumptions!$B$103:$I$103,0)),0) -> 150 | D43: =IFERROR(INDEX(Assumptions!$B$104:$I$104,MATCH(D$2,Assumptions!$B$103:$I$103,0))*INDEX(Assumptions!$B$105:$I$105,MATCH(D$2,Assumptions!$B$103:$I$103,0)),0) -> 250 | E43: =IFERROR(INDEX(Assumptions!$B$104:$I$104,MATCH(E$2,Assumptions!$B$103:$I$103,0))*INDEX(Assumptions!$B$105:$I$105,MATCH(E$2,Assumptions!$B$103:$I$103,0)),0) -> 150 | F43: =IFERROR(INDEX(Assumptions!$B$104:$I$104,MATCH(F$2,Assumptions!$B$103:$I$103,0))*INDEX(Assumptions!$B$105:$I$105,MATCH(F$2,Assumptions!$B$103:$I$103,0)),0) -> 60 | G43: =IFERROR(INDEX(Assumptions!$B$104:$I$104,MATCH(G$2,Assumptions!$B$103:$I$103,0))*INDEX(Assumptions!$B$105:$I$105,MATCH(G$2,Assumptions!$B$103:$I$103,0)),0) -> 0 | H43: =IFERROR(INDEX(Assumptions!$B$104:$I$104,MATCH(H$2,Assumptions!$B$103:$I$103,0))*INDEX(Assumptions!$B$105:$I$105,MATCH(H$2,Assumptions!$B$103:$I$103,0)),0) -> 0 | I43: =IFERROR(INDEX(Assumptions!$B$104:$I$104,MATCH(I$2,Assumptions!$B$103:$I$103,0))*INDEX(Assumptions!$B$105:$I$105,MATCH(I$2,Assumptions!$B$103:$I$103,0)),0) -> 0 | J43: =IFERROR(INDEX(Assumptions!$B$104:$I$104,MATCH(J$2,Assumptions!$B$103:$I$103,0))*INDEX(Assumptions!$B$105:$I$105,MATCH(J$2,Assumptions!$B$103:$I$103,0)),0) -> 0 | ... Z43: =IFERROR(INDEX(Assumptions!$B$104:$I$104,MATCH(Z$2,Assumptions!$B$103:$I$103,0))*INDEX(Assumptions!$B$105:$I$105,MATCH(Z$2,Assumptions!$B$103:$I$103,0)),0) -> 0
A44: Program contribution (pre-tax) | C44: =C40-C41-C42-C43 -> -150 | D44: =D40-D41-D42-D43 -> -250 | E44: =E40-E41-E42-E43 -> -150 | F44: =F40-F41-F42-F43 -> -67.5 | G44: =G40-G41-G42-G43 -> -7.5 | H44: =H40-H41-H42-H43 -> 46.875 | I44: =I40-I41-I42-I43 -> 135 | J44: =J40-J41-J42-J43 -> 234 | ... Z44: =Z40-Z41-Z42-Z43 -> 1.7578125
...

Sheet NPV
A1: SMMT — risk-adjusted NPV (rNPV), $mm except per share
A3: Scenario | B3: =Assumptions!$C$4 -> Base
A4: Valuation date | B4: =Assumptions!$B$13 -> 46311
A5: Discount rate | B5: =Assumptions!$B$14 -> 0.11
A7: Period | C7: 2H 2026 | D7: 2027 | E7: 2028 | F7: 2029 | G7: 2030 | H7: 2031 | I7: 2032 | J7: 2033 | K7: 2034 | L7: 2035 | M7: 2036 | N7: 2037 | O7: 2038 | P7: 2039 | Q7: 2040 | R7: 2041 | S7: 2042 | T7: 2043 | U7: 2044 | V7: 2045 | W7: 2046 | X7: 2047 | Y7: 2048 | Z7: 2049 | AA7: 2050
A8: Revenue, risk-adjusted | C8: =SUM('Quarterly Model'!H2:I2) -> 0 | D8: ='Yearly Model'!H2 -> 28 | E8: ='Yearly Model'!I2 -> 70 | F8: ='Yearly Model'!J2 -> 463.5 | G8: ='Yearly Model'!K2 -> 1036.25 | H8: ='Yearly Model'!L2 -> 1849.6 | I8: ='Yearly Model'!M2 -> 2688.9 | J8: ='Yearly Model'!N2 -> 3453.25 | K8: ='Yearly Model'!O2 -> 3992.35 | ... AA8: ='Yearly Model'!AE2 -> 9.8974609
A9: Operating income (EBIT) | C9: =SUM('Quarterly Model'!H8:I8) -> -460 | D9: ='Yearly Model'!H8 -> -872.24 | E9: ='Yearly Model'!I8 -> -875.6 | F9: ='Yearly Model'!J8 -> -533.645 | G9: ='Yearly Model'!K8 -> -148.85695 | H9: ='Yearly Model'!L8 -> 279.42574 | I9: ='Yearly Model'!M8 -> 700.60519 | J9: ='Yearly Model'!N8 -> 1100.6245 | K9: ='Yearly Model'!O8 -> 1477.9402 | ... AA9: ='Yearly Model'!AE8 -> 3.9071289
A10: Taxes on EBIT (after tax-loss pool) | C10: 0 | D10: =IF(D9>0,MAX(0,D9-'Yearly Model'!G21)*Assumptions!$B$15,0) -> 0 | E10: =IF(E9>0,MAX(0,E9-'Yearly Model'!H21)*Assumptions!$B$15,0) -> 0 | F10: =IF(F9>0,MAX(0,F9-'Yearly Model'!I21)*Assumptions!$B$15,0) -> 0 | G10: =IF(G9>0,MAX(0,G9-'Yearly Model'!J21)*Assumptions!$B$15,0) -> 0 | H10: =IF(H9>0,MAX(0,H9-'Yearly Model'!K21)*Assumptions!$B$15,0) -> 0 | I10: =IF(I9>0,MAX(0,I9-'Yearly Model'!L21)*Assumptions!$B$15,0) -> 0 | J10: =IF(J9>0,MAX(0,J9-'Yearly Model'!M21)*Assumptions!$B$15,0) -> 0 | K10: =IF(K9>0,MAX(0,K9-'Yearly Model'!N21)*Assumptions!$B$15,0) -> 0 | ... AA10: =IF(AA9>0,MAX(0,AA9-'Yearly Model'!AD21)*Assumptions!$B$15,0) -> 0.82049707
A11: Unlevered free cash flow | C11: =C9-C10 -> -460 | D11: =D9-D10 -> -872.24 | E11: =E9-E10 -> -875.6 | F11: =F9-F10 -> -533.645 | G11: =G9-G10 -> -148.85695 | H11: =H9-H10 -> 279.42574 | I11: =I9-I10 -> 700.60519 | J11: =J9-J10 -> 1100.6245 | ... AA11: =AA9-AA10 -> 3.0866318
A12: Cash-flow date (mid-period) | C12: =DATE(2026,10,1) -> 46296 | D12: =DATE(D7,7,1) -> 46569 | E12: =DATE(E7,7,1) -> 46935 | F12: =DATE(F7,7,1) -> 47300 | G12: =DATE(G7,7,1) -> 47665 | H12: =DATE(H7,7,1) -> 48030 | I12: =DATE(I7,7,1) -> 48396 | J12: =DATE(J7,7,1) -> 48761 | K12: =DATE(K7,7,1) -> 49126 | ... AA12: =DATE(AA7,7,1) -> 54970
A13: Years from valuation date | C13: =MAX(0,(C12-$B$4)/365.25) -> 0 | D13: =MAX(0,(D12-$B$4)/365.25) -> 0.7063655 | E13: =MAX(0,(E12-$B$4)/365.25) -> 1.7084189 | F13: =MAX(0,(F12-$B$4)/365.25) -> 2.7077344 | G13: =MAX(0,(G12-$B$4)/365.25) -> 3.70705 | H13: =MAX(0,(H12-$B$4)/365.25) -> 4.7063655 | I13: =MAX(0,(I12-$B$4)/365.25) -> 5.7084189 | J13: =MAX(0,(J12-$B$4)/365.25) -> 6.7077344 | ... AA13: =MAX(0,(AA12-$B$4)/365.25) -> 23.70705
A14: Discount factor | C14: =1/(1+$B$5)^C13 -> 1 | D14: =1/(1+$B$5)^D13 -> 0.92893518 | E14: =1/(1+$B$5)^E13 -> 0.83669923 | F14: =1/(1+$B$5)^F13 -> 0.75383693 | G14: =1/(1+$B$5)^G13 -> 0.67918088 | H14: =1/(1+$B$5)^H13 -> 0.61191838 | I14: =1/(1+$B$5)^I13 -> 0.5511597 | J14: =1/(1+$B$5)^J13 -> 0.49657574 | ... AA14: =1/(1+$B$5)^AA13 -> 0.084241458
A15: PV of free cash flow | C15: =C11*C14 -> -460 | D15: =D11*D14 -> -810.25442 | E15: =E11*E14 -> -732.61384 | F15: =F11*F14 -> -402.28131 | G15: =G11*G14 -> -101.10079 | H15: =H11*H14 -> 170.98574 | I15: =I11*I14 -> 386.14534 | J15: =J11*J14 -> 546.54344 | ... AA15: =AA11*AA14 -> 0.26002237
A17: Valuation summary
A18: PV of risk-adjusted free cash flows | C18: =SUM(C15:AA15) -> 2413.5545
A19: Cash & investments (Main; incl. post-quarter financing) | C19: =Main!C7 -> 2690.678
A20: Debt, convertibles & preferred at face (Main) | C20: =Main!C8 -> 0
A21: Equity value, all claims treated as debt | C21: =C18+C19-C20 -> 5104.2325
A22: Basic shares incl. pre-funded / as-converted (Main) | C22: =Main!C4 -> 906.7056
A23: Value / share before conversions | C23: =C21/C22 -> 5.6294265
A25: Convertible instruments (converted if value / share before conversions > conversion price) | B25: Face ($mm) | C25: Shares (mm) | D25: Conv. price | E25: Converted?
A26: — | B26: 0 | C26: 0 | D26: 0 | E26: =IF(AND(C26>0,$C$23>D26),1,0) -> 0
A27: — | B27: 0 | C27: 0 | D27: 0 | E27: =IF(AND(C27>0,$C$23>D27),1,0) -> 0
A28: — | B28: 0 | C28: 0 | D28: 0 | E28: =IF(AND(C28>0,$C$23>D28),1,0) -> 0
A29: — | B29: 0 | C29: 0 | D29: 0 | E29: =IF(AND(C29>0,$C$23>D29),1,0) -> 0
A30: — | B30: 0 | C30: 0 | D30: 0 | E30: =IF(AND(C30>0,$C$23>D30),1,0) -> 0
A31: Equity value (rNPV) after conversions | C31: =C21+SUMPRODUCT(B26:B30,E26:E30) -> 5104.2325
A32: Shares after conversions (mm) | C32: =C22+SUMPRODUCT(C26:C30,E26:E30) -> 906.7056
A33: Value / share before options & warrants | C33: =C31/C32 -> 5.6294265
A35: Options, warrants & RSUs (treasury-stock method) | B35: Count (mm) | C35: Strike | D35: Dilution (mm)
A36: Options | B36: 118.36781 | C36: 4.45 | D36: =IF(AND(B36>0,$C$33>C36),B36*(1-C36/$C$33),0) -> 24.799353
A37: RSUs | B37: 0.73 | C37: 0 | D37: =IF(AND(B37>0,$C$33>C37),B37*(1-C37/$C$33),0) -> 0.73
A38: — | B38: 0 | C38: 0 | D38: =IF(AND(B38>0,$C$33>C38),B38*(1-C38/$C$33),0) -> 0
A39: — | B39: 0 | C39: 0 | D39: =IF(AND(B39>0,$C$33>C39),B39*(1-C39/$C$33),0) -> 0
A40: — | B40: 0 | C40: 0 | D40: =IF(AND(B40>0,$C$33>C40),B40*(1-C40/$C$33),0) -> 0
A41: — | B41: 0 | C41: 0 | D41: =IF(AND(B41>0,$C$33>C41),B41*(1-C41/$C$33),0) -> 0
A42: Diluted shares (mm) | C42: =C32+SUM(D36:D41) -> 932.23496
A43: rNPV / share, diluted | C43: =C31/C42 -> 5.475264
A44: Current price (Main) | C44: =Main!C3 -> 16.09
A45: Upside / (downside) to rNPV | C45: =C43/C44-1 -> -0.65971013
...

Sheet Options
A1: SMMT — PDUFA options analysis (per contract = 100 shares)
A3: Inputs
A4: Spot price (close 10/16/2026) | B4: 14.63
A5: Pricing date | B5: =DATE(2026,10,16) -> 46311
A6: PDUFA date | B6: =Assumptions!$B$30 -> 46340
A7: Expiry (first monthly after the PDUFA date) | B7: =DATE(2026,11,20) -> 46346
A8: Years to expiry (T) | B8: =(B7-B5)/365 -> 0.095890411
A9: Risk-free rate | B9: 0.04
A10: Reference IV for wide quotes (theo prices) | B10: 1.2151
A11: Contract multiplier | B11: 100
A13: Event model (two outcomes at the PDUFA)
A14: Model value / share, probability-weighted | B14: =NPV!C43 -> 5.475264
A15: Model value / share if approved | B15: =Assumptions!$D$121 -> 7.3408048
A16: Model value / share if CRL | B16: =Assumptions!$D$120 -> 4.047792
A17: Model probability of approval | B17: =Assumptions!$B$32 -> 0.4
A18: Event-move scale (share of model jump priced at expiry) | B18: 1
A19: Floor after a CRL, % of est. 12/31/2026 net cash / share | B19: 0.5
A20: Floor price after a CRL | B20: =MAX(0,B19*(NPV!C47-NPV!C20)/NPV!C22) -> 1.2411294
A21: Price if approved (center of outcome) | B21: =IF(B14>0,B4*(1+B18*(B15/B14-1)),B4+B18*(B15-B14)) -> 19.614757
A22: Price if CRL (center of outcome) | B22: =MAX(B20,IF(B14>0,B4*(1+B18*(B16/B14-1)),B4+B18*(B16-B14))) -> 10.81577
A23: Model expected price after the decision | B23: =B17*B21+(1-B17)*B22 -> 14.335365
A24: Non-event volatility (6-month realized, 3 largest days removed) | B24: 0.625
A25: Model fair ATM straddle, % of spot (jump + non-event volatility) | B25: =(B17*((B21*NORMSDIST(((LN(B21/15.0)+$B$24^2*$B$8/2)/($B$24*SQRT($B$8))))-15.0*NORMSDIST((((LN(B21/15.0)+$B$24^2*$B$8/2)/($B$24*SQRT($B$8)))-$B$24*SQRT($B$8))))+(15.0*NORMSDIST(-(((LN(B21/15.0)+$B$24^2*$B$8/2)/($B$24*SQRT($B$8)))-$B$24*SQRT($B$8)))-B21*NORMSDIST(-((LN(B21/15.0)+$B$24^2*$B$8/2)/($B$24*SQRT($B$8))))))+(1-B17)*((B22*NORMSDIST(((LN(B22/15.0)+$B$24^2*$B$8/2)/($B$24*SQRT($B$8))))-15.0*NORMSDIST((((LN(B22/15.0)+$B$24^2*$B$8/2)/($B$24*SQRT($B$8)))-$B$24*SQRT($B$8))))+(15.0*NORMSDIST(-(((LN(B22/15.0)+$B$24^2*$B$8/2)/($B$24*SQRT($B$8)))-$B$24*SQRT($B$8)))-B22*NORMSDIST(-((LN(B22/15.0)+$B$24^2*$B$8/2)/($B$24*SQRT($B$8)))))))/B4 -> 0.30839438
A26: Market ATM straddle, % of spot | B26: =($G$43+$G$44)/B4 -> 0.3024607
A27: Options richness (market straddle ÷ model straddle) | B27: =B26/B25 -> 0.98075943
A28: Market snapshot — 11/20/2026 expiry (Cboe delayed quotes, 10/16/2026 close)
A29: Strike | B29: Call bid | C29: Call ask | D29: Call mid | E29: Call IV | F29: Put bid | G29: Put ask | H29: Put mid | I29: Put IV | J29: Call OI | K29: Put OI
A30: 10 | B30: 4.1 | C30: 7 | D30: =(B30+C30)/2 -> 5.55 | E30: 1.7514 | F30: 0.25 | G30: 0.5 | H30: =(F30+G30)/2 -> 0.375 | I30: 1.229 | J30: 39 | K30: 16
A31: 11 | B31: 3.2 | C31: 5.1 | D31: =(B31+C31)/2 -> 4.15 | E31: 1.1254 | F31: 0.35 | G31: 2.4 | H31: =(F31+G31)/2 -> 1.375 | I31: 1.8283 | J31: 1 | K31: 78
