Workbook

Sheet Main
B2: Sanofi SA
B3: Price | C3: =INDEX([1]Pharma!$F$1:$F$1000,MATCH("SNY",[1]Pharma!$B$1:$B$1000,0)) -> 41.4
B4: Shares | C4: =1219.427096/0.5 -> 2438.8542
B5: Market Cap. | C5: =C3*C4 -> 100968.56
B7: Cash | C7: =(7657+793)/0.88865 -> 9508.8055
B8: Debt | C8: =(4342+14248)/0.88865 -> 20919.372
B9: Enterprise V. | C9: =C5-C7+C8 -> 112379.13
B11: NPV / Share | C11: =NPV!B28 -> 66.822469
B12: Upside | C12: =IFERROR(C11/C3-1,"") -> 0.61406931
B13: Cash / Share | C13: =IFERROR((C7-C8)/C4,"") -> -4.6786588
B14: Scenario | C14: =Assumptions!C4 -> Base
B15: Model | C15: Reviewed DCF

Sheet Yearly Model
B1: 2015 | C1: 2016 | D1: 2017 | E1: 2018 | F1: 2019 | G1: 2020 | H1: 2021 | I1: 2022 | J1: 2023 | K1: 2024 | L1: 2025 | M1: 2026 | N1: 2027 | O1: 2028 | P1: 2029 | Q1: 2030 | R1: 2031 | S1: 2032 | T1: 2033 | U1: 2034 | V1: 2035
A2: Revenue | B2: 38327.801 | C2: 38045.35 | D2: 39466.607 | E2: 38781.297 | F2: 40652.675 | G2: 40557.025 | H2: 42492.545 | I2: 42368.762 | J2: 42555.562 | K2: 46228.549 | L2: 49092.444 | M2: =L2*(1+NPV!C5) -> 54001.688 | N2: =M2*(1+NPV!D5) -> 57781.807 | O2: =N2*(1+NPV!E5) -> 61248.715 | P2: =O2*(1+NPV!F5) -> 64311.151 | Q2: =P2*(1+NPV!G5) -> 66883.597 | R2: =Q2*(1+NPV!H5) -> 65545.925 | S2: =R2*(1+NPV!I5) -> 63579.547 | T2: =S2*(1+NPV!J5) -> 64215.343 | ... V2: =U2*(1+NPV!L5) -> 67137.141
A3: Cost of Sales | B3: 12287.177 | C3: 12041.861 | D3: 13068.137 | E3: 12867.833 | F3: 13479.998 | G3: 13682.552 | H3: 13790.581 | I3: 13370.843 | J3: 14210.319 | K3: 14859.619 | L3: 14684.071 | M3: =M2*(1-Assumptions!$B$19) -> 16151.905 | N3: =N2*(1-Assumptions!$B$19) -> 17282.538 | O3: =O2*(1-Assumptions!$B$19) -> 18319.491 | P3: =P2*(1-Assumptions!$B$19) -> 19235.465 | Q3: =Q2*(1-Assumptions!$B$19) -> 20004.884 | R3: =R2*(1-Assumptions!$B$19) -> 19604.786 | S3: =S2*(1-Assumptions!$B$19) -> 19016.643 | T3: =T2*(1-Assumptions!$B$19) -> 19206.809 | ... V3: =V2*(1-Assumptions!$B$19) -> 20080.719
A4: Gross Margin | B4: =B2-B3 -> 26040.624 | C4: =C2-C3 -> 26003.489 | D4: =D2-D3 -> 26398.47 | E4: =E2-E3 -> 25913.464 | F4: =F2-F3 -> 27172.677 | G4: =G2-G3 -> 26874.473 | H4: =H2-H3 -> 28701.964 | I4: =I2-I3 -> 28997.919 | ... V4: =V2-V3 -> 47056.422
A5: Research & Dev. | B5: 5718.787 | C5: 5820.064 | D5: 6157.655 | E5: 6632.532 | F5: 6774.321 | G5: 6222.922 | H5: 6405.221 | I5: 7315.591 | J5: 7322.343 | K5: 8320.486 | L5: 8824.622 | M5: =M7*Assumptions!$B$20 -> 8980.3749 | N5: =N7*Assumptions!$B$20 -> 9478.1138 | O5: =O7*Assumptions!$B$20 -> 9908.0601 | P5: =P7*Assumptions!$B$20 -> 10257.785 | Q5: =Q7*Assumptions!$B$20 -> 10516.592 | R5: =R7*Assumptions!$B$20 -> 10157.786 | S5: =S7*Assumptions!$B$20 -> 9709.0317 | T5: =T7*Assumptions!$B$20 -> 9660.6614 | ... V5: =V7*Assumptions!$B$20 -> 9796.0634
A6: SG&A & Other | B6: 13993.136 | C6: 12834.074 | D6: 13709.559 | E6: 14019.018 | F6: 16965.059 | G6: 4770.157 | H6: 13152.535 | I6: 10247.004 | J6: 13190.795 | K6: 14887.751 | L6: 18444.832 | M6: =M7-M5 -> 18771.093 | N6: =N7-N5 -> 19811.484 | O6: =O7-O5 -> 20710.173 | P6: =P7-P5 -> 21441.181 | Q6: =Q7-Q5 -> 21982.148 | R6: =R7-R5 -> 21232.158 | S6: =S7-S5 -> 20294.157 | T6: =T7-T5 -> 20193.051 | ... V6: =V7-V5 -> 20476.073
A7: Operating Expense | B7: =SUM(B5:B6) -> 19711.923 | C7: =SUM(C5:C6) -> 18654.138 | D7: =SUM(D5:D6) -> 19867.214 | E7: =SUM(E5:E6) -> 20651.55 | F7: =SUM(F5:F6) -> 23739.38 | G7: =SUM(G5:G6) -> 10993.079 | H7: =SUM(H5:H6) -> 19557.756 | I7: =SUM(I5:I6) -> 17562.595 | ... L7: =SUM(L5:L6) -> 27269.454 | M7: =M4-M2*NPV!C6 -> 27751.468 | N7: =N4-N2*NPV!D6 -> 29289.598 | O7: =O4-O2*NPV!E6 -> 30618.233 | P7: =P4-P2*NPV!F6 -> 31698.966 | Q7: =Q4-Q2*NPV!G6 -> 32498.74 | R7: =R4-R2*NPV!H6 -> 31389.943 | S7: =S4-S2*NPV!I6 -> 30003.188 | T7: =T4-T2*NPV!J6 -> 29853.713 | ... V7: =V4-V2*NPV!L6 -> 30272.137
A8: Operating Income | B8: =B4-B7 -> 6328.701 | C8: =C4-C7 -> 7349.351 | D8: =D4-D7 -> 6531.256 | E8: =E4-E7 -> 5261.914 | F8: =F4-F7 -> 3433.297 | G8: =G4-G7 -> 15881.394 | H8: =H4-H7 -> 9144.208 | I8: =I4-I7 -> 11435.324 | ... V8: =V4-V7 -> 16784.285
A9: Interest & Other | B9: -706.69 | C9: -559.275 | D9: 4877.061 | E9: 124.909 | F9: -198.053 | G9: -13.504 | H9: -388.229 | I9: 132.786 | J9: -611.039 | K9: -549.148 | L9: 2826.76 | M9: 0 | N9: 0 | O9: 0 | P9: 0 | Q9: 0 | R9: 0 | S9: 0 | T9: 0 | U9: 0 | V9: 0
A10: Pretax | B10: =B8+B9 -> 5622.011 | C10: =C8+C9 -> 6790.076 | D10: =D8+D9 -> 11408.317 | E10: =E8+E9 -> 5386.823 | F10: =F8+F9 -> 3235.244 | G10: =G8+G9 -> 15867.89 | H10: =H8+H9 -> 8755.979 | I10: =I8+I9 -> 11568.11 | ... V10: =V8+V9 -> 16784.285
A11: Taxes | B11: 797.839 | C11: 1491.026 | D11: 1937.771 | E11: 541.27 | F11: 136.162 | G11: 2033.421 | H11: 1753.221 | I11: 2148.202 | J11: 1144.433 | K11: 1354.864 | L11: 1173.69 | M11: =MAX(0,M10)*Assumptions!$E$14 -> 1716.7137 | N11: =MAX(0,N10)*Assumptions!$E$14 -> 1905.644 | O11: =MAX(0,O10)*Assumptions!$E$14 -> 2092.8686 | P11: =MAX(0,P10)*Assumptions!$E$14 -> 2274.0423 | Q11: =MAX(0,Q10)*Assumptions!$E$14 -> 2444.5955 | R11: =MAX(0,R10)*Assumptions!$E$14 -> 2473.7032 | S11: =MAX(0,S10)*Assumptions!$E$14 -> 2475.1518 | T11: =MAX(0,T10)*Assumptions!$E$14 -> 2576.3195 | ... V11: =MAX(0,V10)*Assumptions!$E$14 -> 2853.3285
A12: Net Income | B12: 4824.171 | C12: 5299.049 | D12: 9470.545 | E12: 4845.552 | F12: 3099.083 | G12: 13834.468 | H12: 7002.757 | I12: 9419.907 | J12: 6076.633 | K12: 6256.681 | L12: 8791.988 | M12: =M10-M11 -> 8381.6021 | N12: =N10-N11 -> 9304.0265 | O12: =O10-O11 -> 10218.123 | P12: =P10-P11 -> 11102.677 | Q12: =Q10-Q11 -> 11935.378 | R12: =R10-R11 -> 12077.492 | S12: =S10-S11 -> 12084.565 | T12: =T10-T11 -> 12578.501 | ... V12: =V10-V11 -> 13930.957
A13: Earnings per Share | B13: =IFERROR(B12/B14,0) -> 3.6527379 | C13: =IFERROR(C12/C14,0) -> 4.0887724 | D13: =IFERROR(D12/D14,0) -> 7.4759591 | E13: =IFERROR(E12/E14,0) -> 3.8603824 | F13: =IFERROR(F12/F14,0) -> 2.4652637 | G13: =IFERROR(G12/G14,0) -> 10.978865 | H13: =IFERROR(H12/H14,0) -> 5.5714512 | I13: =IFERROR(I12/I14,0) -> 7.4945557 | ... V13: =IFERROR(V12/V14,0) -> 5.7120908
A14: Shares | B14: 1320.7 | C14: 1296 | D14: 1266.8 | E14: 1255.2 | F14: 1257.1 | G14: 1260.1 | H14: 1256.9 | I14: 1256.9 | J14: 1256.4 | K14: 1256.1 | L14: 1225.6 | M14: =Main!$C$4 -> 2438.8542 | N14: =Main!$C$4 -> 2438.8542 | O14: =Main!$C$4 -> 2438.8542 | P14: =Main!$C$4 -> 2438.8542 | Q14: =Main!$C$4 -> 2438.8542 | R14: =Main!$C$4 -> 2438.8542 | S14: =Main!$C$4 -> 2438.8542 | T14: =Main!$C$4 -> 2438.8542 | ... V14: =Main!$C$4 -> 2438.8542
A16: Revenue Change | C16: =IFERROR(C2/B2-1,"") -> -0.0073693505 | D16: =IFERROR(D2/C2-1,"") -> 0.037356917 | E16: =IFERROR(E2/D2-1,"") -> -0.0173643 | F16: =IFERROR(F2/E2-1,"") -> 0.048254652 | G16: =IFERROR(G2/F2-1,"") -> -0.0023528587 | H16: =IFERROR(H2/G2-1,"") -> 0.047723422 | I16: =IFERROR(I2/H2-1,"") -> -0.0029130522 | J16: =IFERROR(J2/I2-1,"") -> 0.0044089086 | ... V16: =IFERROR(V2/U2-1,"") -> 0.025
A17: Gross Margin | B17: =IFERROR(B4/B2,"") -> 0.67941868 | C17: =IFERROR(C4/C2,"") -> 0.68348665 | D17: =IFERROR(D4/D2,"") -> 0.66888116 | E17: =IFERROR(E4/E2,"") -> 0.66819488 | F17: =IFERROR(F4/F2,"") -> 0.66841055 | G17: =IFERROR(G4/G2,"") -> 0.66263423 | H17: =IFERROR(H4/H2,"") -> 0.67545881 | I17: =IFERROR(I4/I2,"") -> 0.68441743 | ... V17: =IFERROR(V4/V2,"") -> 0.7009
A18: Operating Margin | B18: =IFERROR(B8/B2,"") -> 0.16512038 | C18: =IFERROR(C8/C2,"") -> 0.19317344 | D18: =IFERROR(D8/D2,"") -> 0.16548816 | E18: =IFERROR(E8/E2,"") -> 0.13568174 | F18: =IFERROR(F8/F2,"") -> 0.084454393 | G18: =IFERROR(G8/G2,"") -> 0.39158183 | H18: =IFERROR(H8/H2,"") -> 0.21519558 | I18: =IFERROR(I8/I2,"") -> 0.26989989 | ... V18: =IFERROR(V8/V2,"") -> 0.25
A19: Actual / Estimate | B19: A | C19: A | D19: A | E19: A | F19: A | G19: A | H19: A | I19: A | J19: A | K19: A | L19: A | M19: E | N19: E | O19: E | P19: E | Q19: E | R19: E | S19: E | T19: E | U19: E | V19: E

Sheet Quarterly Model

Sheet Assumptions
A1: Sanofi SA: basic DCF assumptions
A2: Blue = input, black = formula, green = link. $mm unless noted.
A4: Scenario (1 Bear, 2 Base, 3 Bull) | B4: 2 | C4: =CHOOSE($B$4,"Bear","Base","Bull") -> Base
A6: Discount rate override (blank = scenario)
A7: Terminal growth override (blank = scenario)
A9: Parameter | B9: Bear | C9: Base | D9: Bull | E9: Live
A10: Discount rate | B10: 0.095 | C10: 0.085 | D10: 0.075 | E10: =IF(ISNUMBER($B$6),$B$6,CHOOSE($B$4,B10,C10,D10)) -> 0.085
A11: Terminal growth | B11: 0.02 | C11: 0.025 | D11: 0.03 | E11: =IF(ISNUMBER($B$7),$B$7,CHOOSE($B$4,B11,C11,D11)) -> 0.025
A12: Revenue growth, first forecast year | B12: 0.05 | C12: 0.1 | D12: 0.15 | E12: =CHOOSE($B$4,B12,C12,D12) -> 0.1
A13: Operating margin, year 10 | B13: 0.2 | C13: 0.25 | D13: 0.3 | E13: =CHOOSE($B$4,B13,C13,D13) -> 0.25
A14: Tax rate on operating income | B14: 0.17 | C14: 0.17 | D14: 0.17 | E14: =CHOOSE($B$4,B14,C14,D14) -> 0.17
A15: Reinvestment, % of revenue increase | B15: 0.25 | C15: 0.25 | D15: 0.25 | E15: =CHOOSE($B$4,B15,C15,D15) -> 0.25
A17: Single inputs
A18: Starting operating margin (TTM) | B18: 0.18
A19: Gross margin (forecast) | B19: 0.7009
A20: R&D share of operating expense (forecast) | B20: 0.3236
A21: Forecast years | B21: 10
A22: First forecast year, fraction after balance sheet date | B22: 1
A23: Balance sheet date | B23: 46022
A24: Reporting currency per USD (EUR) | B24: 0.88865
A25: Base revenue, FY2025 | B25: ='Yearly Model'!L2 -> 49092.444
A27: Scenario summary
A28: Scenario | B28: Enterprise value | C28: Equity value | D28: NPV / share | E28: Upside
A29: Live | B29: =NPV!B23 -> 174380.83 | C29: =NPV!B26 -> 162970.26 | D29: =NPV!B28 -> 66.822469 | E29: =NPV!B30 -> 0.61406931
A30: 1 | B30: 100322.3 | C30: 88911.737 | D30: 36.456356 | E30: -0.11941169
A31: 2 | B31: 174380.83 | C31: 162970.26 | D31: 66.822469 | E31: 0.61406931
A32: 3 | B32: 325956.63 | C32: 314546.07 | D32: 128.97289 | E32: 2.1152871
A35: NPV / share: discount rate (rows) x terminal growth (columns)
A36: =NPV!B28 -> 66.822469 | B36: 0.015 | C36: 0.02 | D36: 0.025 | E36: 0.03 | F36: 0.035
A37: 0.065 | B37: 88.460105 | C37: 95.132255 | D37: 103.47244 | E37: 114.19554 | F37: 128.49301
A38: 0.075 | B38: 72.359011 | C38: 76.493705 | D38: 81.455338 | E38: 87.519556 | F38: 95.099828
A39: 0.085 | B39: 60.912014 | C39: 63.639917 | D39: 66.822469 | E39: 70.583668 | F39: 75.097107
A40: 0.095 | B40: 52.368483 | C40: 54.251868 | D40: 56.404307 | E40: 58.887891 | F40: 61.785405
A41: 0.105 | B41: 45.756453 | C41: 47.102434 | D41: 48.616663 | E41: 50.332789 | F41: 52.294077
A44: Reviewed revenue growth by year (base case; blank = fade formula)
A45: Fiscal year | B45: 2026 | C45: 2027 | D45: 2028 | E45: 2029 | F45: 2030 | G45: 2031 | H45: 2032 | I45: 2033 | J45: 2034 | K45: 2035
A46: Growth (bear/bull shift by the row-12 gap, fading to 0 by year 10) | B46: 0.1 | C46: 0.07 | D46: 0.06 | E46: 0.05 | F46: 0.04 | G46: -0.02 | H46: -0.03 | I46: 0.01 | J46: 0.02 | K46: 0.025

Sheet NPV
A1: Sanofi SA: free-cash-flow DCF ($mm)
A3: Fiscal year | B3: ='Yearly Model'!L1 -> 2025 | C3: ='Yearly Model'!M1 -> 2026 | D3: ='Yearly Model'!N1 -> 2027 | E3: ='Yearly Model'!O1 -> 2028 | F3: ='Yearly Model'!P1 -> 2029 | G3: ='Yearly Model'!Q1 -> 2030 | H3: ='Yearly Model'!R1 -> 2031 | I3: ='Yearly Model'!S1 -> 2032 | ... L3: ='Yearly Model'!V1 -> 2035
A4: Period | B4: Actual | C4: 1 | D4: 2 | E4: 3 | F4: 4 | G4: 5 | H4: 6 | I4: 7 | J4: 8 | K4: 9 | L4: 10
A5: Revenue growth | C5: =IF(ISNUMBER(Assumptions!B$46),Assumptions!B$46+(Assumptions!$E$12-Assumptions!$C$12)*(Assumptions!$B$21-C4)/(Assumptions!$B$21-1),Assumptions!$E$12+(Assumptions!$E$11-Assumptions!$E$12)*(C4-1)/(Assumptions!$B$21-1)) -> 0.1 | D5: =IF(ISNUMBER(Assumptions!C$46),Assumptions!C$46+(Assumptions!$E$12-Assumptions!$C$12)*(Assumptions!$B$21-D4)/(Assumptions!$B$21-1),Assumptions!$E$12+(Assumptions!$E$11-Assumptions!$E$12)*(D4-1)/(Assumptions!$B$21-1)) -> 0.07 | E5: =IF(ISNUMBER(Assumptions!D$46),Assumptions!D$46+(Assumptions!$E$12-Assumptions!$C$12)*(Assumptions!$B$21-E4)/(Assumptions!$B$21-1),Assumptions!$E$12+(Assumptions!$E$11-Assumptions!$E$12)*(E4-1)/(Assumptions!$B$21-1)) -> 0.06 | F5: =IF(ISNUMBER(Assumptions!E$46),Assumptions!E$46+(Assumptions!$E$12-Assumptions!$C$12)*(Assumptions!$B$21-F4)/(Assumptions!$B$21-1),Assumptions!$E$12+(Assumptions!$E$11-Assumptions!$E$12)*(F4-1)/(Assumptions!$B$21-1)) -> 0.05 | G5: =IF(ISNUMBER(Assumptions!F$46),Assumptions!F$46+(Assumptions!$E$12-Assumptions!$C$12)*(Assumptions!$B$21-G4)/(Assumptions!$B$21-1),Assumptions!$E$12+(Assumptions!$E$11-Assumptions!$E$12)*(G4-1)/(Assumptions!$B$21-1)) -> 0.04 | H5: =IF(ISNUMBER(Assumptions!G$46),Assumptions!G$46+(Assumptions!$E$12-Assumptions!$C$12)*(Assumptions!$B$21-H4)/(Assumptions!$B$21-1),Assumptions!$E$12+(Assumptions!$E$11-Assumptions!$E$12)*(H4-1)/(Assumptions!$B$21-1)) -> -0.02 | I5: =IF(ISNUMBER(Assumptions!H$46),Assumptions!H$46+(Assumptions!$E$12-Assumptions!$C$12)*(Assumptions!$B$21-I4)/(Assumptions!$B$21-1),Assumptions!$E$12+(Assumptions!$E$11-Assumptions!$E$12)*(I4-1)/(Assumptions!$B$21-1)) -> -0.03 | J5: =IF(ISNUMBER(Assumptions!I$46),Assumptions!I$46+(Assumptions!$E$12-Assumptions!$C$12)*(Assumptions!$B$21-J4)/(Assumptions!$B$21-1),Assumptions!$E$12+(Assumptions!$E$11-Assumptions!$E$12)*(J4-1)/(Assumptions!$B$21-1)) -> 0.01 | ... L5: =IF(ISNUMBER(Assumptions!K$46),Assumptions!K$46+(Assumptions!$E$12-Assumptions!$C$12)*(Assumptions!$B$21-L4)/(Assumptions!$B$21-1),Assumptions!$E$12+(Assumptions!$E$11-Assumptions!$E$12)*(L4-1)/(Assumptions!$B$21-1)) -> 0.025
A6: Operating margin | B6: =IFERROR(B8/B7,0) -> 0.14541788 | C6: =Assumptions!$B$18+(Assumptions!$E$13-Assumptions!$B$18)*C4/Assumptions!$B$21 -> 0.187 | D6: =Assumptions!$B$18+(Assumptions!$E$13-Assumptions!$B$18)*D4/Assumptions!$B$21 -> 0.194 | E6: =Assumptions!$B$18+(Assumptions!$E$13-Assumptions!$B$18)*E4/Assumptions!$B$21 -> 0.201 | F6: =Assumptions!$B$18+(Assumptions!$E$13-Assumptions!$B$18)*F4/Assumptions!$B$21 -> 0.208 | G6: =Assumptions!$B$18+(Assumptions!$E$13-Assumptions!$B$18)*G4/Assumptions!$B$21 -> 0.215 | H6: =Assumptions!$B$18+(Assumptions!$E$13-Assumptions!$B$18)*H4/Assumptions!$B$21 -> 0.222 | I6: =Assumptions!$B$18+(Assumptions!$E$13-Assumptions!$B$18)*I4/Assumptions!$B$21 -> 0.229 | J6: =Assumptions!$B$18+(Assumptions!$E$13-Assumptions!$B$18)*J4/Assumptions!$B$21 -> 0.236 | ... L6: =Assumptions!$B$18+(Assumptions!$E$13-Assumptions!$B$18)*L4/Assumptions!$B$21 -> 0.25
A7: Revenue | B7: ='Yearly Model'!L2 -> 49092.444 | C7: ='Yearly Model'!M2 -> 54001.688 | D7: ='Yearly Model'!N2 -> 57781.807 | E7: ='Yearly Model'!O2 -> 61248.715 | F7: ='Yearly Model'!P2 -> 64311.151 | G7: ='Yearly Model'!Q2 -> 66883.597 | H7: ='Yearly Model'!R2 -> 65545.925 | I7: ='Yearly Model'!S2 -> 63579.547 | ... L7: ='Yearly Model'!V2 -> 67137.141
A8: Operating income | B8: ='Yearly Model'!L8 -> 7138.919 | C8: ='Yearly Model'!M8 -> 10098.316 | D8: ='Yearly Model'!N8 -> 11209.67 | E8: ='Yearly Model'!O8 -> 12310.992 | F8: ='Yearly Model'!P8 -> 13376.719 | G8: ='Yearly Model'!Q8 -> 14379.973 | H8: ='Yearly Model'!R8 -> 14551.195 | I8: ='Yearly Model'!S8 -> 14559.716 | ... L8: ='Yearly Model'!V8 -> 16784.285
A9: Tax on operating income | C9: =MAX(0,C8)*Assumptions!$E$14 -> 1716.7137 | D9: =MAX(0,D8)*Assumptions!$E$14 -> 1905.644 | E9: =MAX(0,E8)*Assumptions!$E$14 -> 2092.8686 | F9: =MAX(0,F8)*Assumptions!$E$14 -> 2274.0423 | G9: =MAX(0,G8)*Assumptions!$E$14 -> 2444.5955 | H9: =MAX(0,H8)*Assumptions!$E$14 -> 2473.7032 | I9: =MAX(0,I8)*Assumptions!$E$14 -> 2475.1518 | J9: =MAX(0,J8)*Assumptions!$E$14 -> 2576.3195 | ... L9: =MAX(0,L8)*Assumptions!$E$14 -> 2853.3285
A10: NOPAT | C10: =C8-C9 -> 8381.6021 | D10: =D8-D9 -> 9304.0265 | E10: =E8-E9 -> 10218.123 | F10: =F8-F9 -> 11102.677 | G10: =G8-G9 -> 11935.378 | H10: =H8-H9 -> 12077.492 | I10: =I8-I9 -> 12084.565 | J10: =J8-J9 -> 12578.501 | ... L10: =L8-L9 -> 13930.957
A11: Reinvestment | C11: =(C7-B7)*Assumptions!$E$15 -> 1227.3111 | D11: =(D7-C7)*Assumptions!$E$15 -> 945.02955 | E11: =(E7-D7)*Assumptions!$E$15 -> 866.7271 | F11: =(F7-E7)*Assumptions!$E$15 -> 765.60894 | G11: =(G7-F7)*Assumptions!$E$15 -> 643.11151 | H11: =(H7-G7)*Assumptions!$E$15 -> -334.41798 | I11: =(I7-H7)*Assumptions!$E$15 -> -491.59444 | J11: =(J7-I7)*Assumptions!$E$15 -> 158.94887 | ... L11: =(L7-K7)*Assumptions!$E$15 -> 409.37281
A12: Free cash flow | C12: =C10-C11 -> 7154.291 | D12: =D10-D11 -> 8358.9969 | E12: =E10-E11 -> 9351.396 | F12: =F10-F11 -> 10337.068 | G12: =G10-G11 -> 11292.266 | H12: =H10-H11 -> 12411.91 | I12: =I10-I11 -> 12576.159 | J12: =J10-J11 -> 12419.552 | ... L12: =L10-L11 -> 13521.584
A13: Year fraction | C13: =Assumptions!$B$22 -> 1 | D13: 1 | E13: 1 | F13: 1 | G13: 1 | H13: 1 | I13: 1 | J13: 1 | K13: 1 | L13: 1
A14: Discount time (mid-period) | C14: =C13/2 -> 0.5 | D14: =C14+C13/2+D13/2 -> 1.5 | E14: =D14+D13/2+E13/2 -> 2.5 | F14: =E14+E13/2+F13/2 -> 3.5 | G14: =F14+F13/2+G13/2 -> 4.5 | H14: =G14+G13/2+H13/2 -> 5.5 | I14: =H14+H13/2+I13/2 -> 6.5 | J14: =I14+I13/2+J13/2 -> 7.5 | K14: =J14+J13/2+K13/2 -> 8.5 | L14: =K14+K13/2+L13/2 -> 9.5
A15: Discount factor | C15: =1/(1+Assumptions!$E$10)^C14 -> 0.96003072 | D15: =1/(1+Assumptions!$E$10)^D14 -> 0.88482094 | E15: =1/(1+Assumptions!$E$10)^E14 -> 0.81550317 | F15: =1/(1+Assumptions!$E$10)^F14 -> 0.75161583 | G15: =1/(1+Assumptions!$E$10)^G14 -> 0.69273348 | H15: =1/(1+Assumptions!$E$10)^H14 -> 0.63846404 | I15: =1/(1+Assumptions!$E$10)^I14 -> 0.58844612 | J15: =1/(1+Assumptions!$E$10)^J14 -> 0.54234665 | ... L15: =1/(1+Assumptions!$E$10)^L14 -> 0.46069923
A16: PV of free cash flow | C16: =C12*C13*C15 -> 6868.3391 | D16: =D12*D13*D15 -> 7396.2156 | E16: =E12*E13*E15 -> 7626.0931 | F16: =F12*F13*F15 -> 7769.504 | G16: =G12*G13*G15 -> 7822.531 | H16: =H12*H13*H15 -> 7924.5582 | I16: =I12*I13*I15 -> 7400.3919 | J16: =J12*J13*J15 -> 6735.7027 | ... L16: =L12*L13*L15 -> 6229.3833
A19: PV of forecast free cash flow | B19: =SUM(C16:L16) -> 72215.671
A20: Terminal free cash flow (year 11) | B20: =L10*(1+Assumptions!$E$11)-L7*Assumptions!$E$11*Assumptions!$E$15 -> 13859.623
A21: Terminal value | B21: =B20/(Assumptions!$E$10-Assumptions!$E$11) -> 230993.72
A22: PV of terminal value | B22: =B21/(1+Assumptions!$E$10)^(L14+0.5) -> 102165.16
A23: Enterprise value | B23: =B19+B22 -> 174380.83
A24: Cash & investments | B24: =Main!C7 -> 9508.8055
A25: Debt | B25: =Main!C8 -> 20919.372
A26: Equity value | B26: =B23+B24-B25 -> 162970.26
A27: Shares (mm) | B27: =Main!C4 -> 2438.8542
A28: NPV / share | B28: =B26/B27 -> 66.822469
A29: Price | B29: =Main!C3 -> 41.4
A30: Upside | B30: =B28/B29-1 -> 0.61406931
A31: Terminal value, % of EV | B31: =IFERROR(B22/B23,0) -> 0.58587379

Sheet Options
A1: SNY: options vs. the reviewed DCF (per contract = 100 shares)
A2: Market prices are Cboe delayed quotes; blue = input. Probabilities are risk-neutral (lognormal at ATM IV).
A3: Inputs
A4: Spot (close 2026-10-20) | B4: 41.4
A5: Pricing date | B5: 46315
A6: Near expiry | B6: 46402
A7: Long expiry | B7: 46773
A8: Years to near expiry | B8: =(B6-B5)/365 -> 0.23835616
A9: Years to long expiry | B9: =(B7-B5)/365 -> 1.2547945
A10: Risk-free rate | B10: 0.04
A11: Dividend yield | B11: 0.054
A12: ATM implied volatility, near | B12: 0.2641
A13: ATM implied volatility, long | B13: 0.2496
A14: Contract multiplier | B14: 100
A16: Market expectations, near expiry
A17: ATM strike | B17: 42.5
A18: ATM call (mid) | B18: 1.875
A19: ATM put (mid) | B19: 2.5
A20: Straddle, % of spot (expected move) | B20: =(B18+B19)/B4 -> 0.10567633
A21: Expected range, low | B21: =B4*(1-B20) -> 37.025
A22: Expected range, high | B22: =B4*(1+B20) -> 45.775
A23: 1-SD move by long expiry (ATM IV) | B23: =B13*SQRT(B9) -> 0.27959596
A25: Model vs. market at the long expiry
A26: Case | B26: Value / share | C26: vs. spot | D26: Annual return needed | E26: Market P(above)
A27: Forward price at long expiry | B27: =B4*EXP((B10-B11)*B9) -> 40.679072
A28: Bear | B28: =Assumptions!D30 -> 36.456356 | C28: =B28/$B$4-1 -> -0.11941169 | D28: =IF(B28>0,(B28/$B$4)^(1/$B$9)-1,"") -> -0.096377264 | E28: =IF(B28>0,NORMSDIST((LN($B$27/B28)-$B$13^2*$B$9/2)/($B$13*SQRT($B$9))),1) -> 0.59955246
A29: Base (reviewed) | B29: =Assumptions!D31 -> 66.822469 | C29: =B29/$B$4-1 -> 0.61406931 | D29: =IF(B29>0,(B29/$B$4)^(1/$B$9)-1,"") -> 0.46454316 | E29: =IF(B29>0,NORMSDIST((LN($B$27/B29)-$B$13^2*$B$9/2)/($B$13*SQRT($B$9))),1) -> 0.02774937
A30: Bull | B30: =Assumptions!D32 -> 128.97289 | C30: =B30/$B$4-1 -> 2.1152871 | D30: =IF(B30>0,(B30/$B$4)^(1/$B$9)-1,"") -> 1.4733749 | E30: =IF(B30>0,NORMSDIST((LN($B$27/B30)-$B$13^2*$B$9/2)/($B$13*SQRT($B$9))),1) -> 9.9155745e-06
A32: Chain, 2028-01-21 expiry
A33: Strike | B33: Call bid | C33: Call ask | D33: Call IV | E33: Put bid | F33: Put ask | G33: Put IV | H33: Call OI | I33: Put OI
A34: 32.5 | B34: 10.3 | C34: 11 | D34: 0.2804 | E34: 0.2 | F34: 1.5 | G34: 0.2361 | H34: 145 | I34: 158
A35: 35 | B35: 8.4 | C35: 9 | D35: 0.2701 | E35: 0.8 | F35: 2.1 | G35: 0.2343 | H35: 66 | I35: 222
A36: 37.5 | B36: 6.7 | C36: 7.3 | D36: 0.2635 | E36: 2.35 | F36: 2.9 | G36: 0.2544 | H36: 147 | I36: 690
A37: 40 | B37: 5.3 | C37: 5.7 | D37: 0.2553 | E37: 2.4 | F37: 4 | G37: 0.2198 | H37: 102 | I37: 508
A38: 42.5 | B38: 4.1 | C38: 4.5 | D38: 0.2517 | E38: 4.8 | F38: 5.3 | G38: 0.2475 | H38: 120 | I38: 487
A39: 45 | B39: 3.2 | C39: 3.5 | D39: 0.2507 | E39: 5.3 | F39: 6.9 | G39: 0.2116 | H39: 534 | I39: 784
A40: 47.5 | B40: 2.45 | C40: 2.7 | D40: 0.2493 | E40: 6.7 | F40: 8.7 | G40: 0.1892 | H40: 164 | I40: 2847
A41: 50 | B41: 1.85 | C41: 2.1 | D41: 0.2491 | E41: 10.1 | F41: 10.7 | G41: 0.2441 | H41: 660 | I41: 2099
A42: 65 | B42: 0.1 | C42: 1.55 | D42: 0.307 | E42: 23.5 | F42: 24.4 | G42: 0 | H42: 188 | I42: 53
A43: 75 | B43: 0.1 | C43: 1.35 | D43: 0.361 | E43: 31 | F43: 36 | G43: 0 | H43: 105 | I43: 0
...
