Workbook

Sheet Main
B2: Savara Inc.
B3: Price | C3: =INDEX([1]Pharma!$F$1:$F$1000,MATCH("SVRA",[1]Pharma!$B$1:$B$1000,0)) -> 4.76
B4: Shares | C4: =205.460015+48.600212 -> 254.06023
B5: Market Cap. | C5: =C3*C4 -> 1209.3267
B7: Cash | C7: =41.800+131.234 -> 173.034
B8: Debt | C8: 30.109
B9: Enterprise V. | C9: =C5-C7+C8 -> 1066.4017
B11: rNPV / Share | C11: =NPV!C43 -> 3.6845618
B12: Upside | C12: =C11/C3-1 -> -0.2259324
B13: Cash / Share | C13: =(C7-C8)/C4 -> 0.56256346
B14: Scenario | C14: =Assumptions!$C$4 -> Base
B16: PDUFA Date | C16: =Assumptions!$B$30 -> 46348
B17: P(Approval) | C17: =Assumptions!$B$32 -> 0.8
B18: If Approved | C18: =Assumptions!$D$76 -> 4.0513129
B19: If CRL | C19: =Assumptions!$D$75 -> 2.1236806

Sheet Yearly Model
B1: 2021 | C1: 2022 | D1: 2023 | E1: 2024 | F1: 2025 | G1: 2026 | H1: 2027 | I1: 2028 | J1: 2029 | K1: 2030 | L1: 2031 | M1: 2032 | N1: 2033 | O1: 2034 | P1: 2035 | Q1: 2036 | R1: 2037 | S1: 2038 | T1: 2039 | U1: 2040 | V1: 2041 | W1: 2042 | X1: 2043 | Y1: 2044 | Z1: 2045 | AA1: 2046 | AB1: 2047 | AC1: 2048 | AD1: 2049 | AE1: 2050
A2: Revenue | B2: 0 | C2: 0 | D2: 0 | E2: 0 | F2: 0 | G2: =SUM('Quarterly Model'!F2:I2) -> 0 | H2: =Pipeline!C17 -> 90 | I2: =Pipeline!D17 -> 210 | J2: =Pipeline!E17 -> 346.875 | K2: =Pipeline!F17 -> 489.375 | L2: =Pipeline!G17 -> 601.875 | M2: =Pipeline!H17 -> 684.375 | N2: =Pipeline!I17 -> 701.25 | O2: =Pipeline!J17 -> 712.5 | ... AE2: =Pipeline!Z17 -> 1.5509574
A3: Cost of Sales | B3: 0 | C3: 0 | D3: 0 | E3: 0 | F3: 0 | G3: =SUM('Quarterly Model'!F3:I3) -> 0 | H3: =Pipeline!C18 -> 15.3 | I3: =Pipeline!D18 -> 35.7 | J3: =Pipeline!E18 -> 58.96875 | K3: =Pipeline!F18 -> 83.19375 | L3: =Pipeline!G18 -> 102.31875 | M3: =Pipeline!H18 -> 116.34375 | N3: =Pipeline!I18 -> 119.2125 | O3: =Pipeline!J18 -> 121.125 | ... AE3: =Pipeline!Z18 -> 0.26366276
A4: Gross Margin | B4: =B2-B3 -> 0 | C4: =C2-C3 -> 0 | D4: =D2-D3 -> 0 | E4: =E2-E3 -> 0 | F4: =F2-F3 -> 0 | G4: =G2-G3 -> 0 | H4: =H2-H3 -> 74.7 | I4: =I2-I3 -> 174.3 | ... AE4: =AE2-AE3 -> 1.2872947
A5: Research & Dev. | B5: 28.991 | C5: 27.879 | D5: 44.262 | E5: 78.029 | F5: 81.404 | G5: =SUM('Quarterly Model'!F5:I5) -> 88.349 | H5: =Pipeline!C21 -> 28.2 | I5: =Pipeline!D21 -> 23.596 | J5: =Pipeline!E21 -> 20.8125 | K5: =Pipeline!F21 -> 29.3625 | L5: =Pipeline!G21 -> 36.1125 | M5: =Pipeline!H21 -> 41.0625 | N5: =Pipeline!I21 -> 42.075 | O5: =Pipeline!J21 -> 42.75 | ... AE5: =Pipeline!Z21 -> 0.093057445
A6: General & Admin | B6: 12.486 | C6: 10.96 | D6: 15.745 | E6: 25.167 | F6: 42.143 | G6: =SUM('Quarterly Model'!F6:I6) -> 78.606 | H6: =Pipeline!C24 -> 107.4 | I6: =Pipeline!D24 -> 146.442 | J6: =Pipeline!E24 -> 181.875 | K6: =Pipeline!F24 -> 214.59375 | L6: =Pipeline!G24 -> 236.1375 | M6: =Pipeline!H24 -> 245.4375 | N6: =Pipeline!I24 -> 248.475 | O6: =Pipeline!J24 -> 249.375 | ... AE6: =Pipeline!Z24 -> 0.5428351
A7: Operating Expense | B7: =SUM(B5:B6) -> 41.477 | C7: =SUM(C5:C6) -> 38.839 | D7: =SUM(D5:D6) -> 60.007 | E7: =SUM(E5:E6) -> 103.196 | F7: =SUM(F5:F6) -> 123.547 | G7: =SUM(G5:G6) -> 166.955 | H7: =SUM(H5:H6) -> 135.6 | I7: =SUM(I5:I6) -> 170.038 | ... AE7: =SUM(AE5:AE6) -> 0.63589254
A8: Operating Income | B8: =B4-B7 -> -41.477 | C8: =C4-C7 -> -38.839 | D8: =D4-D7 -> -60.007 | E8: =E4-E7 -> -103.196 | F8: =F4-F7 -> -123.547 | G8: =G4-G7 -> -166.955 | H8: =H4-H7 -> -60.9 | I8: =I4-I7 -> 4.262 | ... AE8: =AE4-AE7 -> 0.65140211
A9: Interest & Other | B9: -1.537 | C9: 0.689 | D9: 5.309 | E9: 7.324 | F9: 4.71 | G9: =SUM('Quarterly Model'!F9:I9) -> 5.2994706 | H9: =Assumptions!$B$16*MAX(0,G20)-Assumptions!$B$17*Main!$C$8 -> 2.5806676 | I9: =Assumptions!$B$16*MAX(0,H20)-Assumptions!$B$17*Main!$C$8 -> 0.39369268 | J9: =Assumptions!$B$16*MAX(0,I20)-Assumptions!$B$17*Main!$C$8 -> 0.56828116 | K9: =Assumptions!$B$16*MAX(0,J20)-Assumptions!$B$17*Main!$C$8 -> 3.7852948 | L9: =Assumptions!$B$16*MAX(0,K20)-Assumptions!$B$17*Main!$C$8 -> 10.010681 | M9: =Assumptions!$B$16*MAX(0,L20)-Assumptions!$B$17*Main!$C$8 -> 18.910066 | N9: =Assumptions!$B$16*MAX(0,M20)-Assumptions!$B$17*Main!$C$8 -> 29.592003 | O9: =Assumptions!$B$16*MAX(0,N20)-Assumptions!$B$17*Main!$C$8 -> 39.103984 | ... AE9: =Assumptions!$B$16*MAX(0,AD20)-Assumptions!$B$17*Main!$C$8 -> 144.25322
A10: Pretax | B10: =B8+B9 -> -43.014 | C10: =C8+C9 -> -38.15 | D10: =D8+D9 -> -54.698 | E10: =E8+E9 -> -95.872 | F10: =F8+F9 -> -118.837 | G10: =G8+G9 -> -161.65553 | H10: =H8+H9 -> -58.319332 | I10: =I8+I9 -> 4.6556927 | ... AE10: =AE8+AE9 -> 144.90462
A11: Taxes | B11: 0 | C11: 0 | D11: 0 | E11: 0.009 | F11: 0 | G11: =SUM('Quarterly Model'!F11:I11) -> 0 | H11: =MAX(0,H10-G21)*Assumptions!$B$15 -> 0 | I11: =MAX(0,I10-H21)*Assumptions!$B$15 -> 0 | J11: =MAX(0,J10-I21)*Assumptions!$B$15 -> 0 | K11: =MAX(0,K10-J21)*Assumptions!$B$15 -> 0 | L11: =MAX(0,L10-K21)*Assumptions!$B$15 -> 0 | M11: =MAX(0,M10-L21)*Assumptions!$B$15 -> 15.589645 | N11: =MAX(0,N10-M21)*Assumptions!$B$15 -> 67.426696 | O11: =MAX(0,O10-N21)*Assumptions!$B$15 -> 71.054337 | ... AE11: =MAX(0,AE10-AD21)*Assumptions!$B$15 -> 30.429971
A12: Net Income | B12: -43.014 | C12: -38.15 | D12: -54.698 | E12: -95.881 | F12: -118.837 | G12: =G10-G11 -> -161.65553 | H12: =H10-H11 -> -58.319332 | I12: =I10-I11 -> 4.6556927 | J12: =J10-J11 -> 85.787031 | K12: =K10-K11 -> 166.01029 | L12: =L10-L11 -> 237.31693 | M12: =M10-M11 -> 284.85167 | N12: =N10-N11 -> 253.65281 | ... AE12: =AE10-AE11 -> 114.47465
A13: Earnings per Share | B13: =IFERROR(B12/B14,0) -> -0.32119415 | C13: =IFERROR(C12/C14,0) -> -0.24971853 | D13: =IFERROR(D12/D14,0) -> -0.33109167 | E13: =IFERROR(E12/E14,0) -> -0.48377836 | F13: =IFERROR(F12/F14,0) -> -0.53436786 | G13: =IFERROR(G12/G14,0) -> -0.63697136 | H13: =IFERROR(H12/H14,0) -> -0.22954924 | I13: =IFERROR(I12/I14,0) -> 0.018325154 | ... AE13: =IFERROR(AE12/AE14,0) -> 0.45058076
A14: Shares | B14: 133.919 | C14: 152.772 | D14: 165.205 | E14: 198.192 | F14: 222.388 | G14: =AVERAGE('Quarterly Model'!F14:I14) -> 253.78775 | H14: =Main!$C$4*(1+Assumptions!$B$26)^(H1-2026) -> 254.06023 | I14: =Main!$C$4*(1+Assumptions!$B$26)^(I1-2026) -> 254.06023 | J14: =Main!$C$4*(1+Assumptions!$B$26)^(J1-2026) -> 254.06023 | K14: =Main!$C$4*(1+Assumptions!$B$26)^(K1-2026) -> 254.06023 | L14: =Main!$C$4*(1+Assumptions!$B$26)^(L1-2026) -> 254.06023 | M14: =Main!$C$4*(1+Assumptions!$B$26)^(M1-2026) -> 254.06023 | N14: =Main!$C$4*(1+Assumptions!$B$26)^(N1-2026) -> 254.06023 | O14: =Main!$C$4*(1+Assumptions!$B$26)^(O1-2026) -> 254.06023 | ... AE14: =Main!$C$4*(1+Assumptions!$B$26)^(AE1-2026) -> 254.06023
A16: Revenue Change | C16: =IFERROR(C2/B2-1,"") | D16: =IFERROR(D2/C2-1,"") | E16: =IFERROR(E2/D2-1,"") | F16: =IFERROR(F2/E2-1,"") | G16: =IFERROR(G2/F2-1,"") | H16: =IFERROR(H2/G2-1,"") | I16: =IFERROR(I2/H2-1,"") -> 1.3333333 | J16: =IFERROR(J2/I2-1,"") -> 0.65178571 | ... AE16: =IFERROR(AE2/AD2-1,"") -> -0.4
A17: Gross Margin | B17: =IFERROR(B4/B2,"") | C17: =IFERROR(C4/C2,"") | D17: =IFERROR(D4/D2,"") | E17: =IFERROR(E4/E2,"") | F17: =IFERROR(F4/F2,"") | G17: =IFERROR(G4/G2,"") | H17: =IFERROR(H4/H2,"") -> 0.83 | I17: =IFERROR(I4/I2,"") -> 0.83 | ... AE17: =IFERROR(AE4/AE2,"") -> 0.83
A19: Actual / Estimate | B19: A | C19: A | D19: A | E19: A | F19: A | G19: A+E | H19: E | I19: E | J19: E | K19: E | L19: E | M19: E | N19: E | O19: E | P19: E | Q19: E | R19: E | S19: E | T19: E | U19: E | V19: E | W19: E | X19: E | Y19: E | Z19: E | AA19: E | AB19: E | AC19: E | AD19: E | AE19: E
A20: Cash & Investments | G20: ='Quarterly Model'!I20 -> 88.890471 | H20: =G20+H12 -> 30.571138 | I20: =H20+I12 -> 35.226831 | J20: =I20+J12 -> 121.01386 | K20: =J20+K12 -> 287.02416 | L20: =K20+L12 -> 524.34109 | M20: =L20+M12 -> 809.19276 | N20: =M20+N12 -> 1062.8456 | O20: =N20+O12 -> 1330.1452 | ... AE20: =AD20+AE12 -> 3981.2998
A21: Tax-Loss Pool | F21: =Assumptions!$B$18 -> 500 | G21: =F21-MIN(F21,MAX(0,G10))+MAX(0,-G10) -> 661.65553 | H21: =G21-MIN(G21,MAX(0,H10))+MAX(0,-H10) -> 719.97486 | I21: =H21-MIN(H21,MAX(0,I10))+MAX(0,-I10) -> 715.31917 | J21: =I21-MIN(I21,MAX(0,J10))+MAX(0,-J10) -> 629.53214 | K21: =J21-MIN(J21,MAX(0,K10))+MAX(0,-K10) -> 463.52184 | L21: =K21-MIN(K21,MAX(0,L10))+MAX(0,-L10) -> 226.20491 | M21: =L21-MIN(L21,MAX(0,M10))+MAX(0,-M10) -> 0 | N21: =M21-MIN(M21,MAX(0,N10))+MAX(0,-N10) -> 0 | ... AE21: =AD21-MIN(AD21,MAX(0,AE10))+MAX(0,-AE10) -> 0

Sheet Quarterly Model
B1: Q1 2025 | C1: Q2 2025 | D1: Q3 2025 | E1: Q4 2025 | F1: Q1 2026 | G1: Q2 2026 | H1: Q3 2026 | I1: Q4 2026
A2: Revenue | B2: 0 | C2: 0 | D2: 0 | E2: 0 | F2: 0 | G2: 0 | H2: 0 | I2: 0
A3: Cost of Sales | B3: 0 | C3: 0 | D3: 0 | E3: 0 | F3: 0 | G3: 0 | H3: =H2*0.0 -> 0 | I3: =I2*0.0 -> 0
A4: Gross Margin | B4: =B2-B3 -> 0 | C4: =C2-C3 -> 0 | D4: =D2-D3 -> 0 | E4: =E2-E3 -> 0 | F4: =F2-F3 -> 0 | G4: =G2-G3 -> 0 | H4: =H2-H3 -> 0 | I4: =I2-I3 -> 0
A5: Research & Dev. | B5: 19.159 | C5: 20.751 | D5: 20.592 | E5: 20.902 | F5: 23.398 | G5: 21.951 | H5: 22 | I5: 21
A6: General & Admin | B6: 9.276 | C6: 10.689 | D6: 9.663 | E6: 12.517 | F6: 15.592 | G6: 19.014 | H6: 21 | I6: 23
A7: Operating Expense | B7: =SUM(B5:B6) -> 28.435 | C7: =SUM(C5:C6) -> 31.44 | D7: =SUM(D5:D6) -> 30.255 | E7: =SUM(E5:E6) -> 33.419 | F7: =SUM(F5:F6) -> 38.99 | G7: =SUM(G5:G6) -> 40.965 | H7: =SUM(H5:H6) -> 43 | I7: =SUM(I5:I6) -> 44
A8: Operating Income | B8: =B4-B7 -> -28.435 | C8: =C4-C7 -> -31.44 | D8: =D4-D7 -> -30.255 | E8: =E4-E7 -> -33.419 | F8: =F4-F7 -> -38.99 | G8: =G4-G7 -> -40.965 | H8: =H4-H7 -> -43 | I8: =I4-I7 -> -44
A9: Interest & Other | B9: 1.796 | C9: 1.039 | D9: 0.694 | E9: 1.183 | F9: 1.706 | G9: 0.737 | H9: =Assumptions!$B$16*G20/4 -> 1.6221937 | I9: =Assumptions!$B$16*H20/4 -> 1.2342768
A10: Pretax | B10: =B8+B9 -> -26.639 | C10: =C8+C9 -> -30.401 | D10: =D8+D9 -> -29.561 | E10: =E8+E9 -> -32.236 | F10: =F8+F9 -> -37.284 | G10: =G8+G9 -> -40.228 | H10: =H8+H9 -> -41.377806 | I10: =I8+I9 -> -42.765723
A11: Taxes | B11: 0 | C11: 0 | D11: 0 | E11: 0 | F11: 0 | G11: 0 | H11: 0 | I11: 0
A12: Net Income | B12: =B10-B11 -> -26.639 | C12: =C10-C11 -> -30.401 | D12: =D10-D11 -> -29.561 | E12: =E10-E11 -> -32.236 | F12: =F10-F11 -> -37.284 | G12: =G10-G11 -> -40.228 | H12: =H10-H11 -> -41.377806 | I12: =I10-I11 -> -42.765723
A13: Earnings per Share | B13: =IFERROR(B12/B14,0) -> -0.12324483 | C13: =IFERROR(C12/C14,0) -> -0.14046509 | D13: =IFERROR(D12/D14,0) -> -0.13656439 | E13: =IFERROR(E12/E14,0) -> -0.13403185 | F13: =IFERROR(F12/F14,0) -> -0.14720409 | G13: =IFERROR(G12/G14,0) -> -0.15864653 | H13: =IFERROR(H12/H14,0) -> -0.16284064 | I13: =IFERROR(I12/I14,0) -> -0.16823652
A14: Shares | B14: 216.147 | C14: 216.431 | D14: 216.462 | E14: 240.51 | F14: 253.281 | G14: 253.57 | H14: 254.1 | I14: 254.2
A16: Revenue Change (YoY) | F16: =IFERROR(F2/B2-1,"") | G16: =IFERROR(G2/C2-1,"") | H16: =IFERROR(H2/D2-1,"") | I16: =IFERROR(I2/E2-1,"")
A17: Gross Margin | B17: =IFERROR(B4/B2,"") | C17: =IFERROR(C4/C2,"") | D17: =IFERROR(D4/D2,"") | E17: =IFERROR(E4/E2,"") | F17: =IFERROR(F4/F2,"") | G17: =IFERROR(G4/G2,"") | H17: =IFERROR(H4/H2,"") | I17: =IFERROR(I4/I2,"")
A19: Actual / Estimate | B19: A | C19: A | D19: A | E19: A | F19: A | G19: A | H19: E | I19: E
A20: Cash & Investments | G20: 173.034 | H20: =G20+H12+H21 -> 131.65619 | I20: =H20+I12+I21 -> 88.890471
A21: Other Cash Flows (est.) | H21: 0 | I21: 0

Sheet Assumptions
A1: SVRA — rNPV assumptions ($mm unless noted)
A4: Scenario (1 = Bear, 2 = Base, 3 = Bull) | B4: 2 | C4: =CHOOSE($B$4,"Bear","Base","Bull") -> Base
A5: Overrides (blank = scenario value; the sensitivity tables drive these)
A6: Discount rate override
A7: PDUFA approval probability override
A8: PDUFA program peak sales override ($mm)
A10: Parameter | B10: Active | C10: Bear | D10: Base | E10: Bull
A12: Valuation & corporate
A13: Valuation date | B13: =DATE(2026,10,16) -> 46311
A14: Discount rate (cost of equity) | B14: =IF(ISNUMBER($B$6),$B$6,CHOOSE($B$4,C14,D14,E14)) -> 0.13 | C14: 0.15 | D14: 0.13 | E14: 0.11
A15: Tax rate | B15: =CHOOSE($B$4,C15,D15,E15) -> 0.21 | C15: 0.21 | D15: 0.21 | E15: 0.21
A16: Interest yield on cash | B16: =CHOOSE($B$4,C16,D16,E16) -> 0.0375 | C16: 0.0375 | D16: 0.0375 | E16: 0.0375
A17: Average cash cost of debt (P&L display only) | B17: =CHOOSE($B$4,C17,D17,E17) -> 0.025 | C17: 0.025 | D17: 0.025 | E17: 0.025
A18: Tax-loss pool at 12/31/2025 | B18: =CHOOSE($B$4,C18,D18,E18) -> 500 | C18: 500 | D18: 500 | E18: 500
A19: Corporate G&A, 2027 | B19: =CHOOSE($B$4,C19,D19,E19) -> 30 | C19: 30 | D19: 30 | E19: 30
A20: Platform / unallocated R&D, 2027 | B20: =CHOOSE($B$4,C20,D20,E20) -> 15 | C20: 15 | D20: 15 | E20: 15
A21: Cost inflation | B21: =CHOOSE($B$4,C21,D21,E21) -> 0.03 | C21: 0.03 | D21: 0.03 | E21: 0.03
A22: Corporate G&A floor, % of revenue | B22: =CHOOSE($B$4,C22,D22,E22) -> 0.1 | C22: 0.1 | D22: 0.1 | E22: 0.1
A23: Platform R&D floor, % of revenue | B23: =CHOOSE($B$4,C23,D23,E23) -> 0.06 | C23: 0.06 | D23: 0.06 | E23: 0.06
A24: Corporate cost cut after a CRL (2027+) | B24: =CHOOSE($B$4,C24,D24,E24) -> 0.6 | C24: 0.6 | D24: 0.6 | E24: 0.6
A25: Last year of base-level corporate costs (then % of revenue only) | B25: =CHOOSE($B$4,C25,D25,E25) -> 2039 | C25: 2039 | D25: 2039 | E25: 2039
A26: Annual share count growth (EPS display only) | B26: =CHOOSE($B$4,C26,D26,E26) -> 0 | C26: 0 | D26: 0 | E26: 0
A27: Wind-down cost for liquidation value | B27: =CHOOSE($B$4,C27,D27,E27) -> 15 | C27: 15 | D27: 15 | E27: 15
A29: PDUFA event
A30: PDUFA target action date | B30: =DATE(2026,11,22) -> 46348
A31: Application | B31: MOLBREEVI (molgramostim) BLA, autoimmune PAP
A32: Probability of approval at this PDUFA | B32: =IF(ISNUMBER($B$7),$B$7,CHOOSE($B$4,C32,D32,E32)) -> 0.8 | C32: 0.7 | D32: 0.8 | E32: 0.88
A33: Probability of approval later, after a CRL | B33: =CHOOSE($B$4,C33,D33,E33) -> 0.75 | C33: 0.65 | D33: 0.75 | E33: 0.85
A34: Launch delay after a CRL (years) | B34: =CHOOSE($B$4,C34,D34,E34) -> 2 | C34: 2 | D34: 2 | E34: 1
A35: Probability of approval, scenario value (before override) | B35: =CHOOSE($B$4,C32,D32,E32) -> 0.8
A36: Read-through: relative cut to other programs' PoS after a CRL | B36: =CHOOSE($B$4,C36,D36,E36) -> 0 | C36: 0 | D36: 0 | E36: 0
A37: Read-through multiplier on other programs' PoS (1 = none) | B37: =1+$B$36*($B$32-$B$35)/$B$35 -> 1
A38: Expected corporate cost multiplier (2027+) | B38: =$B$32+(1-$B$32)*(1-$B$24) -> 0.88
A40: Commercial curves (by year since launch)
A41: Year since launch | B41: 1 | C41: 2 | D41: 3 | E41: 4 | F41: 5 | G41: 6 | H41: 7
A42: Ramp 1 — standard launch, % of peak | B42: 0.1 | C42: 0.25 | D42: 0.45 | E42: 0.65 | F42: 0.82 | G42: 0.93 | H42: 1
A43: Ramp 2 — orphan-disease launch, % of peak | B43: 0.15 | C43: 0.35 | D43: 0.55 | E43: 0.75 | F43: 0.9 | G43: 1 | H43: 1
A44: Commercial SG&A, % of sales (years 1–5; floor = program maturity %) | B44: 0.9 | C44: 0.55 | D44: 0.4 | E44: 0.32 | F44: 0.28
A46: MOLBREEVI — autoimmune pulmonary alveolar proteinosis (PDUFA)
A47: Launch year (first full year of sales) | B47: =CHOOSE($B$4,C47,D47,E47) -> 2027 | C47: 2027 | D47: 2027 | E47: 2027
...

Sheet Pipeline
A1: SVRA — risk-adjusted program build ($mm)
A2: Year | C2: 2027 | D2: 2028 | E2: 2029 | F2: 2030 | G2: 2031 | H2: 2032 | I2: 2033 | J2: 2034 | K2: 2035 | L2: 2036 | M2: 2037 | N2: 2038 | O2: 2039 | P2: 2040 | Q2: 2041 | R2: 2042 | S2: 2043 | T2: 2044 | U2: 2045 | V2: 2046 | W2: 2047 | X2: 2048 | Y2: 2049 | Z2: 2050
A4: MOLBREEVI — autoimmune pulmonary alveolar proteinosis
A5: Years since launch (approved on time) | C5: =C$2-Assumptions!$B$47+1 -> 1 | D5: =D$2-Assumptions!$B$47+1 -> 2 | E5: =E$2-Assumptions!$B$47+1 -> 3 | F5: =F$2-Assumptions!$B$47+1 -> 4 | G5: =G$2-Assumptions!$B$47+1 -> 5 | H5: =H$2-Assumptions!$B$47+1 -> 6 | I5: =I$2-Assumptions!$B$47+1 -> 7 | J5: =J$2-Assumptions!$B$47+1 -> 8 | ... Z5: =Z$2-Assumptions!$B$47+1 -> 24
A6: Net sales, unrisked (approved on time) | C6: =IF(C$2>Assumptions!$B$56,0*(1-Assumptions!$B$57),IF(C5>=1,Assumptions!$B$48*CHOOSE(Assumptions!$B$55,INDEX(Assumptions!$B$42:$H$42,MIN(C5,7)),INDEX(Assumptions!$B$43:$H$43,MIN(C5,7))),0)) -> 112.5 | D6: =IF(D$2>Assumptions!$B$56,C6*(1-Assumptions!$B$57),IF(D5>=1,Assumptions!$B$48*CHOOSE(Assumptions!$B$55,INDEX(Assumptions!$B$42:$H$42,MIN(D5,7)),INDEX(Assumptions!$B$43:$H$43,MIN(D5,7))),0)) -> 262.5 | E6: =IF(E$2>Assumptions!$B$56,D6*(1-Assumptions!$B$57),IF(E5>=1,Assumptions!$B$48*CHOOSE(Assumptions!$B$55,INDEX(Assumptions!$B$42:$H$42,MIN(E5,7)),INDEX(Assumptions!$B$43:$H$43,MIN(E5,7))),0)) -> 412.5 | F6: =IF(F$2>Assumptions!$B$56,E6*(1-Assumptions!$B$57),IF(F5>=1,Assumptions!$B$48*CHOOSE(Assumptions!$B$55,INDEX(Assumptions!$B$42:$H$42,MIN(F5,7)),INDEX(Assumptions!$B$43:$H$43,MIN(F5,7))),0)) -> 562.5 | G6: =IF(G$2>Assumptions!$B$56,F6*(1-Assumptions!$B$57),IF(G5>=1,Assumptions!$B$48*CHOOSE(Assumptions!$B$55,INDEX(Assumptions!$B$42:$H$42,MIN(G5,7)),INDEX(Assumptions!$B$43:$H$43,MIN(G5,7))),0)) -> 675 | H6: =IF(H$2>Assumptions!$B$56,G6*(1-Assumptions!$B$57),IF(H5>=1,Assumptions!$B$48*CHOOSE(Assumptions!$B$55,INDEX(Assumptions!$B$42:$H$42,MIN(H5,7)),INDEX(Assumptions!$B$43:$H$43,MIN(H5,7))),0)) -> 750 | I6: =IF(I$2>Assumptions!$B$56,H6*(1-Assumptions!$B$57),IF(I5>=1,Assumptions!$B$48*CHOOSE(Assumptions!$B$55,INDEX(Assumptions!$B$42:$H$42,MIN(I5,7)),INDEX(Assumptions!$B$43:$H$43,MIN(I5,7))),0)) -> 750 | J6: =IF(J$2>Assumptions!$B$56,I6*(1-Assumptions!$B$57),IF(J5>=1,Assumptions!$B$48*CHOOSE(Assumptions!$B$55,INDEX(Assumptions!$B$42:$H$42,MIN(J5,7)),INDEX(Assumptions!$B$43:$H$43,MIN(J5,7))),0)) -> 750 | K6: =IF(K$2>Assumptions!$B$56,J6*(1-Assumptions!$B$57),IF(K5>=1,Assumptions!$B$48*CHOOSE(Assumptions!$B$55,INDEX(Assumptions!$B$42:$H$42,MIN(K5,7)),INDEX(Assumptions!$B$43:$H$43,MIN(K5,7))),0)) -> 750 | ... Z6: =IF(Z$2>Assumptions!$B$56,Y6*(1-Assumptions!$B$57),IF(Z5>=1,Assumptions!$B$48*CHOOSE(Assumptions!$B$55,INDEX(Assumptions!$B$42:$H$42,MIN(Z5,7)),INDEX(Assumptions!$B$43:$H$43,MIN(Z5,7))),0)) -> 1.6325868
A7: Years since launch (approved after a CRL) | C7: =C$2-(Assumptions!$B$47+Assumptions!$B$34)+1 -> -1 | D7: =D$2-(Assumptions!$B$47+Assumptions!$B$34)+1 -> 0 | E7: =E$2-(Assumptions!$B$47+Assumptions!$B$34)+1 -> 1 | F7: =F$2-(Assumptions!$B$47+Assumptions!$B$34)+1 -> 2 | G7: =G$2-(Assumptions!$B$47+Assumptions!$B$34)+1 -> 3 | H7: =H$2-(Assumptions!$B$47+Assumptions!$B$34)+1 -> 4 | I7: =I$2-(Assumptions!$B$47+Assumptions!$B$34)+1 -> 5 | J7: =J$2-(Assumptions!$B$47+Assumptions!$B$34)+1 -> 6 | ... Z7: =Z$2-(Assumptions!$B$47+Assumptions!$B$34)+1 -> 22
A8: Net sales, unrisked (approved after a CRL) | C8: =IF(C$2>Assumptions!$B$56,0*(1-Assumptions!$B$57),IF(C7>=1,Assumptions!$B$48*CHOOSE(Assumptions!$B$55,INDEX(Assumptions!$B$42:$H$42,MIN(C7,7)),INDEX(Assumptions!$B$43:$H$43,MIN(C7,7))),0)) -> 0 | D8: =IF(D$2>Assumptions!$B$56,C8*(1-Assumptions!$B$57),IF(D7>=1,Assumptions!$B$48*CHOOSE(Assumptions!$B$55,INDEX(Assumptions!$B$42:$H$42,MIN(D7,7)),INDEX(Assumptions!$B$43:$H$43,MIN(D7,7))),0)) -> 0 | E8: =IF(E$2>Assumptions!$B$56,D8*(1-Assumptions!$B$57),IF(E7>=1,Assumptions!$B$48*CHOOSE(Assumptions!$B$55,INDEX(Assumptions!$B$42:$H$42,MIN(E7,7)),INDEX(Assumptions!$B$43:$H$43,MIN(E7,7))),0)) -> 112.5 | F8: =IF(F$2>Assumptions!$B$56,E8*(1-Assumptions!$B$57),IF(F7>=1,Assumptions!$B$48*CHOOSE(Assumptions!$B$55,INDEX(Assumptions!$B$42:$H$42,MIN(F7,7)),INDEX(Assumptions!$B$43:$H$43,MIN(F7,7))),0)) -> 262.5 | G8: =IF(G$2>Assumptions!$B$56,F8*(1-Assumptions!$B$57),IF(G7>=1,Assumptions!$B$48*CHOOSE(Assumptions!$B$55,INDEX(Assumptions!$B$42:$H$42,MIN(G7,7)),INDEX(Assumptions!$B$43:$H$43,MIN(G7,7))),0)) -> 412.5 | H8: =IF(H$2>Assumptions!$B$56,G8*(1-Assumptions!$B$57),IF(H7>=1,Assumptions!$B$48*CHOOSE(Assumptions!$B$55,INDEX(Assumptions!$B$42:$H$42,MIN(H7,7)),INDEX(Assumptions!$B$43:$H$43,MIN(H7,7))),0)) -> 562.5 | I8: =IF(I$2>Assumptions!$B$56,H8*(1-Assumptions!$B$57),IF(I7>=1,Assumptions!$B$48*CHOOSE(Assumptions!$B$55,INDEX(Assumptions!$B$42:$H$42,MIN(I7,7)),INDEX(Assumptions!$B$43:$H$43,MIN(I7,7))),0)) -> 675 | J8: =IF(J$2>Assumptions!$B$56,I8*(1-Assumptions!$B$57),IF(J7>=1,Assumptions!$B$48*CHOOSE(Assumptions!$B$55,INDEX(Assumptions!$B$42:$H$42,MIN(J7,7)),INDEX(Assumptions!$B$43:$H$43,MIN(J7,7))),0)) -> 750 | K8: =IF(K$2>Assumptions!$B$56,J8*(1-Assumptions!$B$57),IF(K7>=1,Assumptions!$B$48*CHOOSE(Assumptions!$B$55,INDEX(Assumptions!$B$42:$H$42,MIN(K7,7)),INDEX(Assumptions!$B$43:$H$43,MIN(K7,7))),0)) -> 750 | ... Z8: =IF(Z$2>Assumptions!$B$56,Y8*(1-Assumptions!$B$57),IF(Z7>=1,Assumptions!$B$48*CHOOSE(Assumptions!$B$55,INDEX(Assumptions!$B$42:$H$42,MIN(Z7,7)),INDEX(Assumptions!$B$43:$H$43,MIN(Z7,7))),0)) -> 1.6325868
A9: Product net sales, risk-adjusted | C9: =Assumptions!$B$32*C6+(1-Assumptions!$B$32)*Assumptions!$B$33*C8 -> 90 | D9: =Assumptions!$B$32*D6+(1-Assumptions!$B$32)*Assumptions!$B$33*D8 -> 210 | E9: =Assumptions!$B$32*E6+(1-Assumptions!$B$32)*Assumptions!$B$33*E8 -> 346.875 | F9: =Assumptions!$B$32*F6+(1-Assumptions!$B$32)*Assumptions!$B$33*F8 -> 489.375 | G9: =Assumptions!$B$32*G6+(1-Assumptions!$B$32)*Assumptions!$B$33*G8 -> 601.875 | H9: =Assumptions!$B$32*H6+(1-Assumptions!$B$32)*Assumptions!$B$33*H8 -> 684.375 | I9: =Assumptions!$B$32*I6+(1-Assumptions!$B$32)*Assumptions!$B$33*I8 -> 701.25 | J9: =Assumptions!$B$32*J6+(1-Assumptions!$B$32)*Assumptions!$B$33*J8 -> 712.5 | ... Z9: =Assumptions!$B$32*Z6+(1-Assumptions!$B$32)*Assumptions!$B$33*Z8 -> 1.5509574
A10: Company revenue, risk-adjusted (incl. milestones) | C10: =C9*Assumptions!$B$50 -> 90 | D10: =D9*Assumptions!$B$50 -> 210 | E10: =E9*Assumptions!$B$50 -> 346.875 | F10: =F9*Assumptions!$B$50 -> 489.375 | G10: =G9*Assumptions!$B$50 -> 601.875 | H10: =H9*Assumptions!$B$50 -> 684.375 | I10: =I9*Assumptions!$B$50 -> 701.25 | J10: =J9*Assumptions!$B$50 -> 712.5 | ... Z10: =Z9*Assumptions!$B$50 -> 1.5509574
A11: COGS + royalties, risk-adjusted | C11: =C9*(Assumptions!$B$51+Assumptions!$B$52) -> 15.3 | D11: =D9*(Assumptions!$B$51+Assumptions!$B$52) -> 35.7 | E11: =E9*(Assumptions!$B$51+Assumptions!$B$52) -> 58.96875 | F11: =F9*(Assumptions!$B$51+Assumptions!$B$52) -> 83.19375 | G11: =G9*(Assumptions!$B$51+Assumptions!$B$52) -> 102.31875 | H11: =H9*(Assumptions!$B$51+Assumptions!$B$52) -> 116.34375 | I11: =I9*(Assumptions!$B$51+Assumptions!$B$52) -> 119.2125 | J11: =J9*(Assumptions!$B$51+Assumptions!$B$52) -> 121.125 | ... Z11: =Z9*(Assumptions!$B$51+Assumptions!$B$52) -> 0.26366276
A12: Commercial SG&A, risk-adjusted | C12: =Assumptions!$B$32*IF(Assumptions!$B$53=0,0,IF(C5=0,Assumptions!$B$54,IF(C5>=1,C6*IF(OR(Assumptions!$B$50<1,C5>5),Assumptions!$B$53,MAX(Assumptions!$B$53,INDEX(Assumptions!$B$44:$F$44,C5))),0)))+(1-Assumptions!$B$32)*Assumptions!$B$33*IF(Assumptions!$B$53=0,0,IF(C7=0,Assumptions!$B$54,IF(C7>=1,C8*IF(OR(Assumptions!$B$50<1,C7>5),Assumptions!$B$53,MAX(Assumptions!$B$53,INDEX(Assumptions!$B$44:$F$44,C7))),0))) -> 81 | D12: =Assumptions!$B$32*IF(Assumptions!$B$53=0,0,IF(D5=0,Assumptions!$B$54,IF(D5>=1,D6*IF(OR(Assumptions!$B$50<1,D5>5),Assumptions!$B$53,MAX(Assumptions!$B$53,INDEX(Assumptions!$B$44:$F$44,D5))),0)))+(1-Assumptions!$B$32)*Assumptions!$B$33*IF(Assumptions!$B$53=0,0,IF(D7=0,Assumptions!$B$54,IF(D7>=1,D8*IF(OR(Assumptions!$B$50<1,D7>5),Assumptions!$B$53,MAX(Assumptions!$B$53,INDEX(Assumptions!$B$44:$F$44,D7))),0))) -> 119.25 | E12: =Assumptions!$B$32*IF(Assumptions!$B$53=0,0,IF(E5=0,Assumptions!$B$54,IF(E5>=1,E6*IF(OR(Assumptions!$B$50<1,E5>5),Assumptions!$B$53,MAX(Assumptions!$B$53,INDEX(Assumptions!$B$44:$F$44,E5))),0)))+(1-Assumptions!$B$32)*Assumptions!$B$33*IF(Assumptions!$B$53=0,0,IF(E7=0,Assumptions!$B$54,IF(E7>=1,E8*IF(OR(Assumptions!$B$50<1,E7>5),Assumptions!$B$53,MAX(Assumptions!$B$53,INDEX(Assumptions!$B$44:$F$44,E7))),0))) -> 147.1875 | F12: =Assumptions!$B$32*IF(Assumptions!$B$53=0,0,IF(F5=0,Assumptions!$B$54,IF(F5>=1,F6*IF(OR(Assumptions!$B$50<1,F5>5),Assumptions!$B$53,MAX(Assumptions!$B$53,INDEX(Assumptions!$B$44:$F$44,F5))),0)))+(1-Assumptions!$B$32)*Assumptions!$B$33*IF(Assumptions!$B$53=0,0,IF(F7=0,Assumptions!$B$54,IF(F7>=1,F8*IF(OR(Assumptions!$B$50<1,F7>5),Assumptions!$B$53,MAX(Assumptions!$B$53,INDEX(Assumptions!$B$44:$F$44,F7))),0))) -> 165.65625 | G12: =Assumptions!$B$32*IF(Assumptions!$B$53=0,0,IF(G5=0,Assumptions!$B$54,IF(G5>=1,G6*IF(OR(Assumptions!$B$50<1,G5>5),Assumptions!$B$53,MAX(Assumptions!$B$53,INDEX(Assumptions!$B$44:$F$44,G5))),0)))+(1-Assumptions!$B$32)*Assumptions!$B$33*IF(Assumptions!$B$53=0,0,IF(G7=0,Assumptions!$B$54,IF(G7>=1,G8*IF(OR(Assumptions!$B$50<1,G7>5),Assumptions!$B$53,MAX(Assumptions!$B$53,INDEX(Assumptions!$B$44:$F$44,G7))),0))) -> 175.95 | H12: =Assumptions!$B$32*IF(Assumptions!$B$53=0,0,IF(H5=0,Assumptions!$B$54,IF(H5>=1,H6*IF(OR(Assumptions!$B$50<1,H5>5),Assumptions!$B$53,MAX(Assumptions!$B$53,INDEX(Assumptions!$B$44:$F$44,H5))),0)))+(1-Assumptions!$B$32)*Assumptions!$B$33*IF(Assumptions!$B$53=0,0,IF(H7=0,Assumptions!$B$54,IF(H7>=1,H8*IF(OR(Assumptions!$B$50<1,H7>5),Assumptions!$B$53,MAX(Assumptions!$B$53,INDEX(Assumptions!$B$44:$F$44,H7))),0))) -> 177 | I12: =Assumptions!$B$32*IF(Assumptions!$B$53=0,0,IF(I5=0,Assumptions!$B$54,IF(I5>=1,I6*IF(OR(Assumptions!$B$50<1,I5>5),Assumptions!$B$53,MAX(Assumptions!$B$53,INDEX(Assumptions!$B$44:$F$44,I5))),0)))+(1-Assumptions!$B$32)*Assumptions!$B$33*IF(Assumptions!$B$53=0,0,IF(I7=0,Assumptions!$B$54,IF(I7>=1,I8*IF(OR(Assumptions!$B$50<1,I7>5),Assumptions!$B$53,MAX(Assumptions!$B$53,INDEX(Assumptions!$B$44:$F$44,I7))),0))) -> 178.35 | J12: =Assumptions!$B$32*IF(Assumptions!$B$53=0,0,IF(J5=0,Assumptions!$B$54,IF(J5>=1,J6*IF(OR(Assumptions!$B$50<1,J5>5),Assumptions!$B$53,MAX(Assumptions!$B$53,INDEX(Assumptions!$B$44:$F$44,J5))),0)))+(1-Assumptions!$B$32)*Assumptions!$B$33*IF(Assumptions!$B$53=0,0,IF(J7=0,Assumptions!$B$54,IF(J7>=1,J8*IF(OR(Assumptions!$B$50<1,J7>5),Assumptions!$B$53,MAX(Assumptions!$B$53,INDEX(Assumptions!$B$44:$F$44,J7))),0))) -> 178.125 | ... Z12: =Assumptions!$B$32*IF(Assumptions!$B$53=0,0,IF(Z5=0,Assumptions!$B$54,IF(Z5>=1,Z6*IF(OR(Assumptions!$B$50<1,Z5>5),Assumptions!$B$53,MAX(Assumptions!$B$53,INDEX(Assumptions!$B$44:$F$44,Z5))),0)))+(1-Assumptions!$B$32)*Assumptions!$B$33*IF(Assumptions!$B$53=0,0,IF(Z7=0,Assumptions!$B$54,IF(Z7>=1,Z8*IF(OR(Assumptions!$B$50<1,Z7>5),Assumptions!$B$53,MAX(Assumptions!$B$53,INDEX(Assumptions!$B$44:$F$44,Z7))),0))) -> 0.38773935
A13: Development R&D, risk-adjusted | C13: =IFERROR(INDEX(Assumptions!$B$59:$I$59,MATCH(C$2,Assumptions!$B$58:$I$58,0))*INDEX(Assumptions!$B$60:$I$60,MATCH(C$2,Assumptions!$B$58:$I$58,0)),0) -> 15 | D13: =IFERROR(INDEX(Assumptions!$B$59:$I$59,MATCH(D$2,Assumptions!$B$58:$I$58,0))*INDEX(Assumptions!$B$60:$I$60,MATCH(D$2,Assumptions!$B$58:$I$58,0)),0) -> 10 | E13: =IFERROR(INDEX(Assumptions!$B$59:$I$59,MATCH(E$2,Assumptions!$B$58:$I$58,0))*INDEX(Assumptions!$B$60:$I$60,MATCH(E$2,Assumptions!$B$58:$I$58,0)),0) -> 0 | F13: =IFERROR(INDEX(Assumptions!$B$59:$I$59,MATCH(F$2,Assumptions!$B$58:$I$58,0))*INDEX(Assumptions!$B$60:$I$60,MATCH(F$2,Assumptions!$B$58:$I$58,0)),0) -> 0 | G13: =IFERROR(INDEX(Assumptions!$B$59:$I$59,MATCH(G$2,Assumptions!$B$58:$I$58,0))*INDEX(Assumptions!$B$60:$I$60,MATCH(G$2,Assumptions!$B$58:$I$58,0)),0) -> 0 | H13: =IFERROR(INDEX(Assumptions!$B$59:$I$59,MATCH(H$2,Assumptions!$B$58:$I$58,0))*INDEX(Assumptions!$B$60:$I$60,MATCH(H$2,Assumptions!$B$58:$I$58,0)),0) -> 0 | I13: =IFERROR(INDEX(Assumptions!$B$59:$I$59,MATCH(I$2,Assumptions!$B$58:$I$58,0))*INDEX(Assumptions!$B$60:$I$60,MATCH(I$2,Assumptions!$B$58:$I$58,0)),0) -> 0 | J13: =IFERROR(INDEX(Assumptions!$B$59:$I$59,MATCH(J$2,Assumptions!$B$58:$I$58,0))*INDEX(Assumptions!$B$60:$I$60,MATCH(J$2,Assumptions!$B$58:$I$58,0)),0) -> 0 | ... Z13: =IFERROR(INDEX(Assumptions!$B$59:$I$59,MATCH(Z$2,Assumptions!$B$58:$I$58,0))*INDEX(Assumptions!$B$60:$I$60,MATCH(Z$2,Assumptions!$B$58:$I$58,0)),0) -> 0
A14: Program contribution (pre-tax) | C14: =C10-C11-C12-C13 -> -21.3 | D14: =D10-D11-D12-D13 -> 45.05 | E14: =E10-E11-E12-E13 -> 140.71875 | F14: =F10-F11-F12-F13 -> 240.525 | G14: =G10-G11-G12-G13 -> 323.60625 | H14: =H10-H11-H12-H13 -> 391.03125 | I14: =I10-I11-I12-I13 -> 403.6875 | J14: =J10-J11-J12-J13 -> 413.25 | ... Z14: =Z10-Z11-Z12-Z13 -> 0.8995553
A16: Company totals (risk-adjusted)
A17: Revenue | C17: =C10 -> 90 | D17: =D10 -> 210 | E17: =E10 -> 346.875 | F17: =F10 -> 489.375 | G17: =G10 -> 601.875 | H17: =H10 -> 684.375 | I17: =I10 -> 701.25 | J17: =J10 -> 712.5 | ... Z17: =Z10 -> 1.5509574
A18: Cost of sales (COGS + royalties) | C18: =C11 -> 15.3 | D18: =D11 -> 35.7 | E18: =E11 -> 58.96875 | F18: =F11 -> 83.19375 | G18: =G11 -> 102.31875 | H18: =H11 -> 116.34375 | I18: =I11 -> 119.2125 | J18: =J11 -> 121.125 | ... Z18: =Z11 -> 0.26366276
A19: Program development R&D | C19: =C13 -> 15 | D19: =D13 -> 10 | E19: =E13 -> 0 | F19: =F13 -> 0 | G19: =G13 -> 0 | H19: =H13 -> 0 | I19: =I13 -> 0 | J19: =J13 -> 0 | ... Z19: =Z13 -> 0
A20: Platform / unallocated R&D | C20: =IF(C$2>Assumptions!$B$25,Assumptions!$B$23*C17,MAX(Assumptions!$B$20*(1+Assumptions!$B$21)^(C$2-2027)*Assumptions!$B$38,Assumptions!$B$23*C17)) -> 13.2 | D20: =IF(D$2>Assumptions!$B$25,Assumptions!$B$23*D17,MAX(Assumptions!$B$20*(1+Assumptions!$B$21)^(D$2-2027)*Assumptions!$B$38,Assumptions!$B$23*D17)) -> 13.596 | E20: =IF(E$2>Assumptions!$B$25,Assumptions!$B$23*E17,MAX(Assumptions!$B$20*(1+Assumptions!$B$21)^(E$2-2027)*Assumptions!$B$38,Assumptions!$B$23*E17)) -> 20.8125 | F20: =IF(F$2>Assumptions!$B$25,Assumptions!$B$23*F17,MAX(Assumptions!$B$20*(1+Assumptions!$B$21)^(F$2-2027)*Assumptions!$B$38,Assumptions!$B$23*F17)) -> 29.3625 | G20: =IF(G$2>Assumptions!$B$25,Assumptions!$B$23*G17,MAX(Assumptions!$B$20*(1+Assumptions!$B$21)^(G$2-2027)*Assumptions!$B$38,Assumptions!$B$23*G17)) -> 36.1125 | H20: =IF(H$2>Assumptions!$B$25,Assumptions!$B$23*H17,MAX(Assumptions!$B$20*(1+Assumptions!$B$21)^(H$2-2027)*Assumptions!$B$38,Assumptions!$B$23*H17)) -> 41.0625 | I20: =IF(I$2>Assumptions!$B$25,Assumptions!$B$23*I17,MAX(Assumptions!$B$20*(1+Assumptions!$B$21)^(I$2-2027)*Assumptions!$B$38,Assumptions!$B$23*I17)) -> 42.075 | J20: =IF(J$2>Assumptions!$B$25,Assumptions!$B$23*J17,MAX(Assumptions!$B$20*(1+Assumptions!$B$21)^(J$2-2027)*Assumptions!$B$38,Assumptions!$B$23*J17)) -> 42.75 | ... Z20: =IF(Z$2>Assumptions!$B$25,Assumptions!$B$23*Z17,MAX(Assumptions!$B$20*(1+Assumptions!$B$21)^(Z$2-2027)*Assumptions!$B$38,Assumptions!$B$23*Z17)) -> 0.093057445
A21: Total R&D | C21: =C19+C20 -> 28.2 | D21: =D19+D20 -> 23.596 | E21: =E19+E20 -> 20.8125 | F21: =F19+F20 -> 29.3625 | G21: =G19+G20 -> 36.1125 | H21: =H19+H20 -> 41.0625 | I21: =I19+I20 -> 42.075 | J21: =J19+J20 -> 42.75 | ... Z21: =Z19+Z20 -> 0.093057445
A22: Commercial SG&A | C22: =C12 -> 81 | D22: =D12 -> 119.25 | E22: =E12 -> 147.1875 | F22: =F12 -> 165.65625 | G22: =G12 -> 175.95 | H22: =H12 -> 177 | I22: =I12 -> 178.35 | J22: =J12 -> 178.125 | ... Z22: =Z12 -> 0.38773935
A23: Corporate G&A | C23: =IF(C$2>Assumptions!$B$25,Assumptions!$B$22*C17,MAX(Assumptions!$B$19*(1+Assumptions!$B$21)^(C$2-2027)*Assumptions!$B$38,Assumptions!$B$22*C17)) -> 26.4 | D23: =IF(D$2>Assumptions!$B$25,Assumptions!$B$22*D17,MAX(Assumptions!$B$19*(1+Assumptions!$B$21)^(D$2-2027)*Assumptions!$B$38,Assumptions!$B$22*D17)) -> 27.192 | E23: =IF(E$2>Assumptions!$B$25,Assumptions!$B$22*E17,MAX(Assumptions!$B$19*(1+Assumptions!$B$21)^(E$2-2027)*Assumptions!$B$38,Assumptions!$B$22*E17)) -> 34.6875 | F23: =IF(F$2>Assumptions!$B$25,Assumptions!$B$22*F17,MAX(Assumptions!$B$19*(1+Assumptions!$B$21)^(F$2-2027)*Assumptions!$B$38,Assumptions!$B$22*F17)) -> 48.9375 | G23: =IF(G$2>Assumptions!$B$25,Assumptions!$B$22*G17,MAX(Assumptions!$B$19*(1+Assumptions!$B$21)^(G$2-2027)*Assumptions!$B$38,Assumptions!$B$22*G17)) -> 60.1875 | H23: =IF(H$2>Assumptions!$B$25,Assumptions!$B$22*H17,MAX(Assumptions!$B$19*(1+Assumptions!$B$21)^(H$2-2027)*Assumptions!$B$38,Assumptions!$B$22*H17)) -> 68.4375 | I23: =IF(I$2>Assumptions!$B$25,Assumptions!$B$22*I17,MAX(Assumptions!$B$19*(1+Assumptions!$B$21)^(I$2-2027)*Assumptions!$B$38,Assumptions!$B$22*I17)) -> 70.125 | J23: =IF(J$2>Assumptions!$B$25,Assumptions!$B$22*J17,MAX(Assumptions!$B$19*(1+Assumptions!$B$21)^(J$2-2027)*Assumptions!$B$38,Assumptions!$B$22*J17)) -> 71.25 | ... Z23: =IF(Z$2>Assumptions!$B$25,Assumptions!$B$22*Z17,MAX(Assumptions!$B$19*(1+Assumptions!$B$21)^(Z$2-2027)*Assumptions!$B$38,Assumptions!$B$22*Z17)) -> 0.15509574
A24: Total G&A incl. SG&A | C24: =C22+C23 -> 107.4 | D24: =D22+D23 -> 146.442 | E24: =E22+E23 -> 181.875 | F24: =F22+F23 -> 214.59375 | G24: =G22+G23 -> 236.1375 | H24: =H22+H23 -> 245.4375 | I24: =I22+I23 -> 248.475 | J24: =J22+J23 -> 249.375 | ... Z24: =Z22+Z23 -> 0.5428351
A25: Operating income (EBIT) | C25: =C17-C18-C21-C24 -> -60.9 | D25: =D17-D18-D21-D24 -> 4.262 | E25: =E17-E18-E21-E24 -> 85.21875 | F25: =F17-F18-F21-F24 -> 162.225 | G25: =G17-G18-G21-G24 -> 227.30625 | H25: =H17-H18-H21-H24 -> 281.53125 | I25: =I17-I18-I21-I24 -> 291.4875 | J25: =J17-J18-J21-J24 -> 299.25 | ... Z25: =Z17-Z18-Z21-Z24 -> 0.65140211

Sheet NPV
A1: SVRA — risk-adjusted NPV (rNPV), $mm except per share
A3: Scenario | B3: =Assumptions!$C$4 -> Base
A4: Valuation date | B4: =Assumptions!$B$13 -> 46311
A5: Discount rate | B5: =Assumptions!$B$14 -> 0.13
A7: Period | C7: 2H 2026 | D7: 2027 | E7: 2028 | F7: 2029 | G7: 2030 | H7: 2031 | I7: 2032 | J7: 2033 | K7: 2034 | L7: 2035 | M7: 2036 | N7: 2037 | O7: 2038 | P7: 2039 | Q7: 2040 | R7: 2041 | S7: 2042 | T7: 2043 | U7: 2044 | V7: 2045 | W7: 2046 | X7: 2047 | Y7: 2048 | Z7: 2049 | AA7: 2050
A8: Revenue, risk-adjusted | C8: =SUM('Quarterly Model'!H2:I2) -> 0 | D8: ='Yearly Model'!H2 -> 90 | E8: ='Yearly Model'!I2 -> 210 | F8: ='Yearly Model'!J2 -> 346.875 | G8: ='Yearly Model'!K2 -> 489.375 | H8: ='Yearly Model'!L2 -> 601.875 | I8: ='Yearly Model'!M2 -> 684.375 | J8: ='Yearly Model'!N2 -> 701.25 | K8: ='Yearly Model'!O2 -> 712.5 | ... AA8: ='Yearly Model'!AE2 -> 1.5509574
A9: Operating income (EBIT) | C9: =SUM('Quarterly Model'!H8:I8) -> -87 | D9: ='Yearly Model'!H8 -> -60.9 | E9: ='Yearly Model'!I8 -> 4.262 | F9: ='Yearly Model'!J8 -> 85.21875 | G9: ='Yearly Model'!K8 -> 162.225 | H9: ='Yearly Model'!L8 -> 227.30625 | I9: ='Yearly Model'!M8 -> 281.53125 | J9: ='Yearly Model'!N8 -> 291.4875 | K9: ='Yearly Model'!O8 -> 299.25 | ... AA9: ='Yearly Model'!AE8 -> 0.65140211
A10: Taxes on EBIT (after tax-loss pool) | C10: 0 | D10: =IF(D9>0,MAX(0,D9-'Yearly Model'!G21)*Assumptions!$B$15,0) -> 0 | E10: =IF(E9>0,MAX(0,E9-'Yearly Model'!H21)*Assumptions!$B$15,0) -> 0 | F10: =IF(F9>0,MAX(0,F9-'Yearly Model'!I21)*Assumptions!$B$15,0) -> 0 | G10: =IF(G9>0,MAX(0,G9-'Yearly Model'!J21)*Assumptions!$B$15,0) -> 0 | H10: =IF(H9>0,MAX(0,H9-'Yearly Model'!K21)*Assumptions!$B$15,0) -> 0 | I10: =IF(I9>0,MAX(0,I9-'Yearly Model'!L21)*Assumptions!$B$15,0) -> 11.618531 | J10: =IF(J9>0,MAX(0,J9-'Yearly Model'!M21)*Assumptions!$B$15,0) -> 61.212375 | K10: =IF(K9>0,MAX(0,K9-'Yearly Model'!N21)*Assumptions!$B$15,0) -> 62.8425 | ... AA10: =IF(AA9>0,MAX(0,AA9-'Yearly Model'!AD21)*Assumptions!$B$15,0) -> 0.13679444
A11: Unlevered free cash flow | C11: =C9-C10 -> -87 | D11: =D9-D10 -> -60.9 | E11: =E9-E10 -> 4.262 | F11: =F9-F10 -> 85.21875 | G11: =G9-G10 -> 162.225 | H11: =H9-H10 -> 227.30625 | I11: =I9-I10 -> 269.91272 | J11: =J9-J10 -> 230.27513 | ... AA11: =AA9-AA10 -> 0.51460767
A12: Cash-flow date (mid-period) | C12: =DATE(2026,10,1) -> 46296 | D12: =DATE(D7,7,1) -> 46569 | E12: =DATE(E7,7,1) -> 46935 | F12: =DATE(F7,7,1) -> 47300 | G12: =DATE(G7,7,1) -> 47665 | H12: =DATE(H7,7,1) -> 48030 | I12: =DATE(I7,7,1) -> 48396 | J12: =DATE(J7,7,1) -> 48761 | K12: =DATE(K7,7,1) -> 49126 | ... AA12: =DATE(AA7,7,1) -> 54970
A13: Years from valuation date | C13: =MAX(0,(C12-$B$4)/365.25) -> 0 | D13: =MAX(0,(D12-$B$4)/365.25) -> 0.7063655 | E13: =MAX(0,(E12-$B$4)/365.25) -> 1.7084189 | F13: =MAX(0,(F12-$B$4)/365.25) -> 2.7077344 | G13: =MAX(0,(G12-$B$4)/365.25) -> 3.70705 | H13: =MAX(0,(H12-$B$4)/365.25) -> 4.7063655 | I13: =MAX(0,(I12-$B$4)/365.25) -> 5.7084189 | J13: =MAX(0,(J12-$B$4)/365.25) -> 6.7077344 | ... AA13: =MAX(0,(AA12-$B$4)/365.25) -> 23.70705
A14: Discount factor | C14: =1/(1+$B$5)^C13 -> 1 | D14: =1/(1+$B$5)^D13 -> 0.91729118 | E14: =1/(1+$B$5)^E13 -> 0.81155841 | F14: =1/(1+$B$5)^F13 -> 0.71825337 | G14: =1/(1+$B$5)^G13 -> 0.63567562 | H14: =1/(1+$B$5)^H13 -> 0.56259186 | I14: =1/(1+$B$5)^I13 -> 0.49774397 | J14: =1/(1+$B$5)^J13 -> 0.44051824 | ... AA14: =1/(1+$B$5)^AA13 -> 0.055165389
A15: PV of free cash flow | C15: =C11*C14 -> -87 | D15: =D11*D14 -> -55.863033 | E15: =E11*E14 -> 3.458862 | F15: =F11*F14 -> 61.208654 | G15: =G11*G14 -> 103.12248 | H15: =H11*H14 -> 127.88065 | I15: =I11*I14 -> 134.34743 | J15: =J11*J14 -> 101.44039 | ... AA15: =AA11*AA14 -> 0.028388533
A17: Valuation summary
A18: PV of risk-adjusted free cash flows | C18: =SUM(C15:AA15) -> 818.86805
A19: Cash & investments (Main; incl. post-quarter financing) | C19: =Main!C7 -> 173.034
A20: Debt, convertibles & preferred at face (Main) | C20: =Main!C8 -> 30.109
A21: Equity value, all claims treated as debt | C21: =C18+C19-C20 -> 961.79305
A22: Basic shares incl. pre-funded / as-converted (Main) | C22: =Main!C4 -> 254.06023
A23: Value / share before conversions | C23: =C21/C22 -> 3.7856892
A25: Convertible instruments (converted if value / share before conversions > conversion price) | B25: Face ($mm) | C25: Shares (mm) | D25: Conv. price | E25: Converted?
A26: — | B26: 0 | C26: 0 | D26: 0 | E26: =IF(AND(C26>0,$C$23>D26),1,0) -> 0
A27: — | B27: 0 | C27: 0 | D27: 0 | E27: =IF(AND(C27>0,$C$23>D27),1,0) -> 0
A28: — | B28: 0 | C28: 0 | D28: 0 | E28: =IF(AND(C28>0,$C$23>D28),1,0) -> 0
A29: — | B29: 0 | C29: 0 | D29: 0 | E29: =IF(AND(C29>0,$C$23>D29),1,0) -> 0
A30: — | B30: 0 | C30: 0 | D30: 0 | E30: =IF(AND(C30>0,$C$23>D30),1,0) -> 0
A31: Equity value (rNPV) after conversions | C31: =C21+SUMPRODUCT(B26:B30,E26:E30) -> 961.79305
A32: Shares after conversions (mm) | C32: =C22+SUMPRODUCT(C26:C30,E26:E30) -> 254.06023
A33: Value / share before options & warrants | C33: =C31/C32 -> 3.7856892
A35: Options, warrants & RSUs (treasury-stock method) | B35: Count (mm) | C35: Strike | D35: Dilution (mm)
A36: Options (strike assumed) | B36: 12.227121 | C36: 4 | D36: =IF(AND(B36>0,$C$33>C36),B36*(1-C36/$C$33),0) -> 0
A37: RSUs | B37: 6.973 | C37: 0 | D37: =IF(AND(B37>0,$C$33>C37),B37*(1-C37/$C$33),0) -> 6.973
A38: Legacy warrants | B38: 0.077793 | C38: 10 | D38: =IF(AND(B38>0,$C$33>C38),B38*(1-C38/$C$33),0) -> 0
A39: — | B39: 0 | C39: 0 | D39: =IF(AND(B39>0,$C$33>C39),B39*(1-C39/$C$33),0) -> 0
A40: — | B40: 0 | C40: 0 | D40: =IF(AND(B40>0,$C$33>C40),B40*(1-C40/$C$33),0) -> 0
A41: — | B41: 0 | C41: 0 | D41: =IF(AND(B41>0,$C$33>C41),B41*(1-C41/$C$33),0) -> 0
A42: Diluted shares (mm) | C42: =C32+SUM(D36:D41) -> 261.03323
A43: rNPV / share, diluted | C43: =C31/C42 -> 3.6845618
A44: Current price (Main) | C44: =Main!C3 -> 4.76
A45: Upside / (downside) to rNPV | C45: =C43/C44-1 -> -0.2259324
...

Sheet Options
A1: SVRA — PDUFA options analysis (per contract = 100 shares)
A3: Inputs
A4: Spot price (close 10/16/2026) | B4: 4.45
A5: Pricing date | B5: =DATE(2026,10,16) -> 46311
A6: PDUFA date | B6: =Assumptions!$B$30 -> 46348
A7: Expiry (first monthly after the PDUFA date) | B7: =DATE(2026,12,18) -> 46374
A8: Years to expiry (T) | B8: =(B7-B5)/365 -> 0.17260274
A9: Risk-free rate | B9: 0.04
A10: Reference IV for wide quotes (theo prices) | B10: 1.2
A11: Contract multiplier | B11: 100
A13: Event model (two outcomes at the PDUFA)
A14: Model value / share, probability-weighted | B14: =NPV!C43 -> 3.6845618
A15: Model value / share if approved | B15: =Assumptions!$D$76 -> 4.0513129
A16: Model value / share if CRL | B16: =Assumptions!$D$75 -> 2.1236806
A17: Model probability of approval | B17: =Assumptions!$B$32 -> 0.8
A18: Event-move scale (share of model jump priced at expiry) | B18: 1
A19: Floor after a CRL, % of est. 12/31/2026 net cash / share | B19: 0.5
A20: Floor price after a CRL | B20: =MAX(0,B19*(NPV!C47-NPV!C20)/NPV!C22) -> 0.11568413
A21: Price if approved (center of outcome) | B21: =IF(B14>0,B4*(1+B18*(B15/B14-1)),B4+B18*(B15-B14)) -> 4.8929408
A22: Price if CRL (center of outcome) | B22: =MAX(B20,IF(B14>0,B4*(1+B18*(B16/B14-1)),B4+B18*(B16-B14))) -> 2.5648583
A23: Model expected price after the decision | B23: =B17*B21+(1-B17)*B22 -> 4.4273243
A24: Non-event volatility (6-month realized, 3 largest days removed) | B24: 0.411
A25: Model fair ATM straddle, % of spot (jump + non-event volatility) | B25: =(B17*((B21*NORMSDIST(((LN(B21/4.0)+$B$24^2*$B$8/2)/($B$24*SQRT($B$8))))-4.0*NORMSDIST((((LN(B21/4.0)+$B$24^2*$B$8/2)/($B$24*SQRT($B$8)))-$B$24*SQRT($B$8))))+(4.0*NORMSDIST(-(((LN(B21/4.0)+$B$24^2*$B$8/2)/($B$24*SQRT($B$8)))-$B$24*SQRT($B$8)))-B21*NORMSDIST(-((LN(B21/4.0)+$B$24^2*$B$8/2)/($B$24*SQRT($B$8))))))+(1-B17)*((B22*NORMSDIST(((LN(B22/4.0)+$B$24^2*$B$8/2)/($B$24*SQRT($B$8))))-4.0*NORMSDIST((((LN(B22/4.0)+$B$24^2*$B$8/2)/($B$24*SQRT($B$8)))-$B$24*SQRT($B$8))))+(4.0*NORMSDIST(-(((LN(B22/4.0)+$B$24^2*$B$8/2)/($B$24*SQRT($B$8)))-$B$24*SQRT($B$8)))-B22*NORMSDIST(-((LN(B22/4.0)+$B$24^2*$B$8/2)/($B$24*SQRT($B$8)))))))/B4 -> 0.24093316
A26: Market ATM straddle, % of spot | B26: =($G$41+$G$42)/B4 -> 0.38198303
A27: Options richness (market straddle ÷ model straddle) | B27: =B26/B25 -> 1.5854315
A28: Market snapshot — 12/18/2026 expiry (Cboe delayed quotes, 10/16/2026 close)
A29: Strike | B29: Call bid | C29: Call ask | D29: Call mid | E29: Call IV | F29: Put bid | G29: Put ask | H29: Put mid | I29: Put IV | J29: Call OI | K29: Put OI
A30: 1 | B30: 1.5 | C30: 6 | D30: =(B30+C30)/2 -> 3.75 | E30: 4.4626 | F30: 0 | G30: 4.3 | H30: =(F30+G30)/2 -> 2.15 | I30: 0 | J30: 0 | K30: 0
A31: 2 | B31: 0.7 | C31: 4.9 | D31: =(B31+C31)/2 -> 2.8 | E31: 2.6556 | F31: 0 | G31: 4.3 | H31: =(F31+G31)/2 -> 2.15 | I31: 0 | J31: 0 | K31: 0
A32: 3 | B32: 0.2 | C32: 4.9 | D32: =(B32+C32)/2 -> 2.55 | E32: 3.1645 | F32: 0 | G32: 0.85 | H32: =(F32+G32)/2 -> 0.425 | I32: 1.6222 | J32: 0 | K32: 0
A33: 4 | B33: 0 | C33: 4.8 | D33: =(B33+C33)/2 -> 2.4 | E33: 3.4698 | F33: 0 | G33: 4.6 | H33: =(F33+G33)/2 -> 2.3 | I33: 4.022 | J33: 0 | K33: 0
A34: 5 | B34: 0 | C34: 4.5 | D34: =(B34+C34)/2 -> 2.25 | E34: 3.608 | F34: 0.3 | G34: 4.7 | H34: =(F34+G34)/2 -> 2.5 | I34: 3.0037 | J34: 0 | K34: 0
A35: 6 | B35: 0.1 | C35: 1.05 | D35: =(B35+C35)/2 -> 0.575 | E35: 1.455 | F35: 0.95 | G35: 4.9 | H35: =(F35+G35)/2 -> 2.925 | I35: 2.4819 | J35: 0 | K35: 0
A36: 7 | B36: 0 | C36: 4.3 | D36: =(B36+C36)/2 -> 2.15 | E36: 3.9828 | F36: 0.8 | G36: 4.8 | H36: =(F36+G36)/2 -> 2.8 | I36: 1.0895 | J36: 0 | K36: 0
A37: 8 | B37: 0 | C37: 4.3 | D37: =(B37+C37)/2 -> 2.15 | E37: 4.1776 | F37: 2.8 | G37: 5.9 | H37: =(F37+G37)/2 -> 4.35 | I37: 2.159 | J37: 0 | K37: 0
A39: Legs (premium = mid when the market is tight, else Black-Scholes at the reference IV)
A40: Leg | B40: Type | C40: Strike | D40: Mid | E40: Spread % of mid | F40: BS value | G40: Premium used | H40: Source | I40: d1 | J40: Delta | K40: E[payoff] if approved | L40: E[payoff] if CRL
A41: Dec-26 $4 call | B41: C | C41: =A33 -> 4 | D41: =(B33+C33)/2 -> 2.4 | E41: =IF(B33>0,(C33-B33)/D41,9.99) -> 9.99 | F41: =IF(B41="C",$B$4*NORMSDIST((LN($B$4/C41)+($B$9+$B$10^2/2)*$B$8)/($B$10*SQRT($B$8)))-C41*EXP(-$B$9*$B$8)*NORMSDIST((LN($B$4/C41)+($B$9+$B$10^2/2)*$B$8)/($B$10*SQRT($B$8))-$B$10*SQRT($B$8)),C41*EXP(-$B$9*$B$8)*NORMSDIST(-((LN($B$4/C41)+($B$9+$B$10^2/2)*$B$8)/($B$10*SQRT($B$8))-$B$10*SQRT($B$8)))-$B$4*NORMSDIST(-(LN($B$4/C41)+($B$9+$B$10^2/2)*$B$8)/($B$10*SQRT($B$8)))) -> 1.0886729 | G41: =IF(AND(B33>0,E41<=0.6),D41,F41) -> 1.0886729 | H41: =IF(AND(B33>0,E41<=0.6),"market","theo") -> theo | I41: =(LN($B$4/C41)+($B$9+$B$10^2/2)*$B$8)/($B$10*SQRT($B$8)) -> 0.4769628 | J41: =IF(B41="C",NORMSDIST(I41),NORMSDIST(I41)-1) -> 0.6833057 | K41: =IF(B41="C",($B$21*NORMSDIST(((LN($B$21/C41)+$B$24^2*$B$8/2)/($B$24*SQRT($B$8))))-C41*NORMSDIST((((LN($B$21/C41)+$B$24^2*$B$8/2)/($B$24*SQRT($B$8)))-$B$24*SQRT($B$8)))),(C41*NORMSDIST(-(((LN($B$21/C41)+$B$24^2*$B$8/2)/($B$24*SQRT($B$8)))-$B$24*SQRT($B$8)))-$B$21*NORMSDIST(-((LN($B$21/C41)+$B$24^2*$B$8/2)/($B$24*SQRT($B$8)))))) -> 0.93697511 | L41: =IF(B41="C",($B$22*NORMSDIST(((LN($B$22/C41)+$B$24^2*$B$8/2)/($B$24*SQRT($B$8))))-C41*NORMSDIST((((LN($B$22/C41)+$B$24^2*$B$8/2)/($B$24*SQRT($B$8)))-$B$24*SQRT($B$8)))),(C41*NORMSDIST(-(((LN($B$22/C41)+$B$24^2*$B$8/2)/($B$24*SQRT($B$8)))-$B$24*SQRT($B$8)))-$B$22*NORMSDIST(-((LN($B$22/C41)+$B$24^2*$B$8/2)/($B$24*SQRT($B$8)))))) -> 0.00079171882
A42: Dec-26 $4 put | B42: P | C42: =A33 -> 4 | D42: =(F33+G33)/2 -> 2.3 | E42: =IF(F33>0,(G33-F33)/D42,9.99) -> 9.99 | F42: =IF(B42="C",$B$4*NORMSDIST((LN($B$4/C42)+($B$9+$B$10^2/2)*$B$8)/($B$10*SQRT($B$8)))-C42*EXP(-$B$9*$B$8)*NORMSDIST((LN($B$4/C42)+($B$9+$B$10^2/2)*$B$8)/($B$10*SQRT($B$8))-$B$10*SQRT($B$8)),C42*EXP(-$B$9*$B$8)*NORMSDIST(-((LN($B$4/C42)+($B$9+$B$10^2/2)*$B$8)/($B$10*SQRT($B$8))-$B$10*SQRT($B$8)))-$B$4*NORMSDIST(-(LN($B$4/C42)+($B$9+$B$10^2/2)*$B$8)/($B$10*SQRT($B$8)))) -> 0.61115159 | G42: =IF(AND(F33>0,E42<=0.6),D42,F42) -> 0.61115159 | H42: =IF(AND(F33>0,E42<=0.6),"market","theo") -> theo | I42: =(LN($B$4/C42)+($B$9+$B$10^2/2)*$B$8)/($B$10*SQRT($B$8)) -> 0.4769628 | J42: =IF(B42="C",NORMSDIST(I42),NORMSDIST(I42)-1) -> -0.3166943 | K42: =IF(B42="C",($B$21*NORMSDIST(((LN($B$21/C42)+$B$24^2*$B$8/2)/($B$24*SQRT($B$8))))-C42*NORMSDIST((((LN($B$21/C42)+$B$24^2*$B$8/2)/($B$24*SQRT($B$8)))-$B$24*SQRT($B$8)))),(C42*NORMSDIST(-(((LN($B$21/C42)+$B$24^2*$B$8/2)/($B$24*SQRT($B$8)))-$B$24*SQRT($B$8)))-$B$21*NORMSDIST(-((LN($B$21/C42)+$B$24^2*$B$8/2)/($B$24*SQRT($B$8)))))) -> 0.044034307 | L42: =IF(B42="C",($B$22*NORMSDIST(((LN($B$22/C42)+$B$24^2*$B$8/2)/($B$24*SQRT($B$8))))-C42*NORMSDIST((((LN($B$22/C42)+$B$24^2*$B$8/2)/($B$24*SQRT($B$8)))-$B$24*SQRT($B$8)))),(C42*NORMSDIST(-(((LN($B$22/C42)+$B$24^2*$B$8/2)/($B$24*SQRT($B$8)))-$B$24*SQRT($B$8)))-$B$22*NORMSDIST(-((LN($B$22/C42)+$B$24^2*$B$8/2)/($B$24*SQRT($B$8)))))) -> 1.4359334
A43: Dec-26 $6 call | B43: C | C43: =A35 -> 6 | D43: =(B35+C35)/2 -> 0.575 | E43: =IF(B35>0,(C35-B35)/D43,9.99) -> 1.6521739 | F43: =IF(B43="C",$B$4*NORMSDIST((LN($B$4/C43)+($B$9+$B$10^2/2)*$B$8)/($B$10*SQRT($B$8)))-C43*EXP(-$B$9*$B$8)*NORMSDIST((LN($B$4/C43)+($B$9+$B$10^2/2)*$B$8)/($B$10*SQRT($B$8))-$B$10*SQRT($B$8)),C43*EXP(-$B$9*$B$8)*NORMSDIST(-((LN($B$4/C43)+($B$9+$B$10^2/2)*$B$8)/($B$10*SQRT($B$8))-$B$10*SQRT($B$8)))-$B$4*NORMSDIST(-(LN($B$4/C43)+($B$9+$B$10^2/2)*$B$8)/($B$10*SQRT($B$8)))) -> 0.43595572 | G43: =IF(AND(B35>0,E43<=0.6),D43,F43) -> 0.43595572 | H43: =IF(AND(B35>0,E43<=0.6),"market","theo") -> theo | I43: =(LN($B$4/C43)+($B$9+$B$10^2/2)*$B$8)/($B$10*SQRT($B$8)) -> -0.33633275 | J43: =IF(B43="C",NORMSDIST(I43),NORMSDIST(I43)-1) -> 0.36830998 | K43: =IF(B43="C",($B$21*NORMSDIST(((LN($B$21/C43)+$B$24^2*$B$8/2)/($B$24*SQRT($B$8))))-C43*NORMSDIST((((LN($B$21/C43)+$B$24^2*$B$8/2)/($B$24*SQRT($B$8)))-$B$24*SQRT($B$8)))),(C43*NORMSDIST(-(((LN($B$21/C43)+$B$24^2*$B$8/2)/($B$24*SQRT($B$8)))-$B$24*SQRT($B$8)))-$B$21*NORMSDIST(-((LN($B$21/C43)+$B$24^2*$B$8/2)/($B$24*SQRT($B$8)))))) -> 0.052362861 | L43: =IF(B43="C",($B$22*NORMSDIST(((LN($B$22/C43)+$B$24^2*$B$8/2)/($B$24*SQRT($B$8))))-C43*NORMSDIST((((LN($B$22/C43)+$B$24^2*$B$8/2)/($B$24*SQRT($B$8)))-$B$24*SQRT($B$8)))),(C43*NORMSDIST(-(((LN($B$22/C43)+$B$24^2*$B$8/2)/($B$24*SQRT($B$8)))-$B$24*SQRT($B$8)))-$B$22*NORMSDIST(-((LN($B$22/C43)+$B$24^2*$B$8/2)/($B$24*SQRT($B$8)))))) -> 4.0333017e-08
...
