Workbook

Sheet Main
B2: Zoetis Inc
B3: Price | C3: =INDEX([1]Pharma!$F$1:$F$1000,MATCH("ZTS",[1]Pharma!$B$1:$B$1000,0)) -> 80.04
B4: Shares | C4: 413.2236
B5: Market Cap. | C5: =C3*C4 -> 33074.417
B7: Cash | C7: =1476+200 -> 1676
B8: Debt | C8: 9048
B9: Enterprise V. | C9: =C5-C7+C8 -> 40446.417
B11: NPV / Share | C11: =NPV!B28 -> 103.19817
B12: Upside | C12: =IFERROR(C11/C3-1,"") -> 0.28933251
B13: Cash / Share | C13: =IFERROR((C7-C8)/C4,"") -> -17.84022
B14: Scenario | C14: =Assumptions!C4 -> Base
B15: Model | C15: Reviewed DCF

Sheet Yearly Model
B1: 2011 | C1: 2012 | D1: 2013 | E1: 2014 | F1: 2015 | G1: 2016 | H1: 2017 | I1: 2018 | J1: 2019 | K1: 2020 | L1: 2021 | M1: 2022 | N1: 2023 | O1: 2024 | P1: 2025 | Q1: 2026 | R1: 2027 | S1: 2028 | T1: 2029 | U1: 2030 | V1: 2031 | W1: 2032 | X1: 2033 | Y1: 2034 | Z1: 2035
A2: Revenue | B2: 4233 | C2: 4336 | D2: 4561 | E2: 4785 | F2: 4765 | G2: 4888 | H2: 5307 | I2: 5825 | J2: 6260 | K2: 6675 | L2: 7776 | M2: 8080 | N2: 8544 | O2: 9256 | P2: 9467 | Q2: =P2*(1+NPV!C5) -> 9220.858 | R2: =Q2*(1+NPV!D5) -> 9405.2752 | S2: =R2*(1+NPV!E5) -> 9781.4862 | T2: =S2*(1+NPV!F5) -> 10270.56 | U2: =T2*(1+NPV!G5) -> 10784.088 | V2: =U2*(1+NPV!H5) -> 11269.372 | W2: =V2*(1+NPV!I5) -> 11720.147 | X2: =W2*(1+NPV!J5) -> 12130.353 | ... Z2: =Y2*(1+NPV!L5) -> 12806.62
A3: Cost of Sales | B3: 1652 | C3: 1563 | D3: 1669 | E3: 1717 | F3: 1738 | G3: 1666 | H3: 1775 | I3: 1911 | J3: 1992 | K3: 2057 | L3: 2303 | M3: 2454 | N3: 2561 | O3: 2719 | P3: 2666 | Q3: =Q2*(1-Assumptions!$B$19) -> 2596.5936 | R3: =R2*(1-Assumptions!$B$19) -> 2648.5255 | S3: =S2*(1-Assumptions!$B$19) -> 2754.4665 | T3: =T2*(1-Assumptions!$B$19) -> 2892.1898 | U3: =U2*(1-Assumptions!$B$19) -> 3036.7993 | V3: =V2*(1-Assumptions!$B$19) -> 3173.4553 | W3: =W2*(1-Assumptions!$B$19) -> 3300.3935 | X3: =X2*(1-Assumptions!$B$19) -> 3415.9073 | ... Z3: =Z2*(1-Assumptions!$B$19) -> 3606.3441
A4: Gross Margin | B4: =B2-B3 -> 2581 | C4: =C2-C3 -> 2773 | D4: =D2-D3 -> 2892 | E4: =E2-E3 -> 3068 | F4: =F2-F3 -> 3027 | G4: =G2-G3 -> 3222 | H4: =H2-H3 -> 3532 | I4: =I2-I3 -> 3914 | ... Z4: =Z2-Z3 -> 9200.2756
A5: Research & Dev. | B5: 427 | C5: 409 | D5: 399 | E5: 396 | F5: 364 | G5: 376 | H5: 382 | I5: 432 | J5: 457 | K5: 463 | L5: 508 | M5: 539 | N5: 614 | O5: 686 | P5: 698 | Q5: =Q7*Assumptions!$B$20 -> 768.67894 | R5: =R7*Assumptions!$B$20 -> 781.91846 | S5: =S7*Assumptions!$B$20 -> 810.97578 | T5: =T7*Assumptions!$B$20 -> 849.19418 | U5: =U7*Assumptions!$B$20 -> 889.20698 | V5: =V7*Assumptions!$B$20 -> 926.66427 | W5: =W7*Assumptions!$B$20 -> 961.07154 | X5: =X7*Assumptions!$B$20 -> 991.95667 | ... Z5: =Z7*Assumptions!$B$20 -> 1041.4466
A6: SG&A & Other | B6: 1453 | C6: 1470 | D6: 1613 | E6: 1643 | F6: 1532 | G6: 1364 | H6: 1334 | I6: 1484 | J6: 1638 | K6: 1726 | L6: 2001 | M6: 2009 | N6: 2151 | O6: 2318 | P6: 2378 | Q6: =Q7-Q5 -> 2619.0643 | R6: =R7-R5 -> 2664.1744 | S6: =S7-S5 -> 2763.1793 | T6: =T7-T5 -> 2893.3981 | U6: =U7-U5 -> 3029.7308 | V6: =V7-V5 -> 3157.3563 | W6: =W7-W5 -> 3274.5897 | X6: =X7-X5 -> 3379.8224 | ... Z6: =Z7-Z5 -> 3548.4459
A7: Operating Expense | B7: =SUM(B5:B6) -> 1880 | C7: =SUM(C5:C6) -> 1879 | D7: =SUM(D5:D6) -> 2012 | E7: =SUM(E5:E6) -> 2039 | F7: =SUM(F5:F6) -> 1896 | G7: =SUM(G5:G6) -> 1740 | H7: =SUM(H5:H6) -> 1716 | I7: =SUM(I5:I6) -> 1916 | ... P7: =SUM(P5:P6) -> 3076 | Q7: =Q4-Q2*NPV!C6 -> 3387.7432 | R7: =R4-R2*NPV!D6 -> 3446.0928 | S7: =S4-S2*NPV!E6 -> 3574.155 | T7: =T4-T2*NPV!F6 -> 3742.5922 | U7: =U4-U2*NPV!G6 -> 3918.9378 | V7: =V4-V2*NPV!H6 -> 4084.0206 | W7: =W4-W2*NPV!I6 -> 4235.6613 | X7: =X4-X2*NPV!J6 -> 4371.7791 | ... Z7: =Z4-Z2*NPV!L6 -> 4589.8925
A8: Operating Income | B8: =B4-B7 -> 701 | C8: =C4-C7 -> 894 | D8: =D4-D7 -> 880 | E8: =E4-E7 -> 1029 | F8: =F4-F7 -> 1131 | G8: =G4-G7 -> 1482 | H8: =H4-H7 -> 1816 | I8: =I4-I7 -> 1998 | ... Z8: =Z4-Z7 -> 4610.3831
A9: Interest & Other | B9: -310 | C9: -184 | D9: -189 | E9: -213 | F9: -586 | G9: -252 | H9: -289 | I9: -304 | J9: -372 | K9: -431 | L9: -473 | M9: -419 | N9: -278 | O9: -410 | P9: -365 | Q9: 0 | R9: 0 | S9: 0 | T9: 0 | U9: 0 | V9: 0 | W9: 0 | X9: 0 | Y9: 0 | Z9: 0
A10: Pretax | B10: =B8+B9 -> 391 | C10: =C8+C9 -> 710 | D10: =D8+D9 -> 691 | E10: =E8+E9 -> 816 | F10: =F8+F9 -> 545 | G10: =G8+G9 -> 1230 | H10: =H8+H9 -> 1527 | I10: =I8+I9 -> 1694 | ... Z10: =Z8+Z9 -> 4610.3831
A11: Taxes | B11: 146 | C11: 274 | D11: 187 | E11: 233 | F11: 206 | G11: 409 | H11: 663 | I11: 266 | J11: 301 | K11: 360 | L11: 454 | M11: 545 | N11: 596 | O11: 637 | P11: 687 | Q11: =MAX(0,Q10)*Assumptions!$E$14 -> 550.2086 | R11: =MAX(0,R10)*Assumptions!$E$14 -> 562.81167 | S11: =MAX(0,S10)*Assumptions!$E$14 -> 586.98698 | T11: =MAX(0,T10)*Assumptions!$E$14 -> 618.08233 | U11: =MAX(0,U10)*Assumptions!$E$14 -> 650.81974 | V11: =MAX(0,V10)*Assumptions!$E$14 -> 682.02242 | W11: =MAX(0,W10)*Assumptions!$E$14 -> 711.29574 | X11: =MAX(0,X10)*Assumptions!$E$14 -> 738.25326 | ... Z11: =MAX(0,Z10)*Assumptions!$E$14 -> 783.76513
A12: Net Income | B12: 245 | C12: 436 | D12: 504 | E12: 583 | F12: 339 | G12: 821 | H12: 864 | I12: 1428 | J12: 1500 | K12: 1638 | L12: 2037 | M12: 2114 | N12: 2344 | O12: 2486 | P12: 2673 | Q12: =Q10-Q11 -> 2686.3126 | R12: =R10-R11 -> 2747.8452 | S12: =S10-S11 -> 2865.8776 | T12: =T10-T11 -> 3017.6961 | U12: =U10-U11 -> 3177.5317 | V12: =V10-V11 -> 3329.8742 | W12: =W10-W11 -> 3472.7969 | X12: =X10-X11 -> 3604.413 | ... Z12: =Z10-Z11 -> 3826.618
A13: Earnings per Share | B13: =IFERROR(B12/B14,0) -> 0.49 | C13: =IFERROR(C12/C14,0) -> 0.872 | D13: =IFERROR(D12/D14,0) -> 1.0073613 | E13: =IFERROR(E12/E14,0) -> 1.1612967 | F13: =IFERROR(F12/F14,0) -> 0.67527325 | G13: =IFERROR(G12/G14,0) -> 1.6478499 | H13: =IFERROR(H12/H14,0) -> 1.7519634 | I13: =IFERROR(I12/I14,0) -> 2.9328525 | ... Z13: =IFERROR(Z12/Z14,0) -> 9.2604051
A14: Shares | B14: 500 | C14: 500 | D14: 500.317 | E14: 502.025 | F14: 502.019 | G14: 498.225 | H14: 493.161 | I14: 486.898 | J14: 481.787 | K14: 478.569 | L14: 476.717 | M14: 470.385 | N14: 462.269 | O14: 454.848 | P14: 443.835 | Q14: =Main!$C$4 -> 413.2236 | R14: =Main!$C$4 -> 413.2236 | S14: =Main!$C$4 -> 413.2236 | T14: =Main!$C$4 -> 413.2236 | U14: =Main!$C$4 -> 413.2236 | V14: =Main!$C$4 -> 413.2236 | W14: =Main!$C$4 -> 413.2236 | X14: =Main!$C$4 -> 413.2236 | ... Z14: =Main!$C$4 -> 413.2236
A16: Revenue Change | C16: =IFERROR(C2/B2-1,"") -> 0.024332625 | D16: =IFERROR(D2/C2-1,"") -> 0.051891144 | E16: =IFERROR(E2/D2-1,"") -> 0.049112037 | F16: =IFERROR(F2/E2-1,"") -> -0.0041797283 | G16: =IFERROR(G2/F2-1,"") -> 0.025813221 | H16: =IFERROR(H2/G2-1,"") -> 0.085720131 | I16: =IFERROR(I2/H2-1,"") -> 0.097606934 | J16: =IFERROR(J2/I2-1,"") -> 0.074678112 | ... Z16: =IFERROR(Z2/Y2-1,"") -> 0.025
A17: Gross Margin | B17: =IFERROR(B4/B2,"") -> 0.60973305 | C17: =IFERROR(C4/C2,"") -> 0.63952952 | D17: =IFERROR(D4/D2,"") -> 0.63407148 | E17: =IFERROR(E4/E2,"") -> 0.64117032 | F17: =IFERROR(F4/F2,"") -> 0.63525708 | G17: =IFERROR(G4/G2,"") -> 0.6591653 | H17: =IFERROR(H4/H2,"") -> 0.66553608 | I17: =IFERROR(I4/I2,"") -> 0.67193133 | ... Z17: =IFERROR(Z4/Z2,"") -> 0.7184
A18: Operating Margin | B18: =IFERROR(B8/B2,"") -> 0.16560359 | C18: =IFERROR(C8/C2,"") -> 0.20618081 | D18: =IFERROR(D8/D2,"") -> 0.19294014 | E18: =IFERROR(E8/E2,"") -> 0.21504702 | F18: =IFERROR(F8/F2,"") -> 0.23735572 | G18: =IFERROR(G8/G2,"") -> 0.30319149 | H18: =IFERROR(H8/H2,"") -> 0.34218956 | I18: =IFERROR(I8/I2,"") -> 0.34300429 | ... Z18: =IFERROR(Z8/Z2,"") -> 0.36
A19: Actual / Estimate | B19: A | C19: A | D19: A | E19: A | F19: A | G19: A | H19: A | I19: A | J19: A | K19: A | L19: A | M19: A | N19: A | O19: A | P19: A | Q19: E | R19: E | S19: E | T19: E | U19: E | V19: E | W19: E | X19: E | Y19: E | Z19: E

Sheet Quarterly Model

Sheet Assumptions
A1: Zoetis Inc: basic DCF assumptions
A2: Blue = input, black = formula, green = link. $mm unless noted.
A4: Scenario (1 Bear, 2 Base, 3 Bull) | B4: 2 | C4: =CHOOSE($B$4,"Bear","Base","Bull") -> Base
A6: Discount rate override (blank = scenario)
A7: Terminal growth override (blank = scenario)
A9: Parameter | B9: Bear | C9: Base | D9: Bull | E9: Live
A10: Discount rate | B10: 0.095 | C10: 0.085 | D10: 0.075 | E10: =IF(ISNUMBER($B$6),$B$6,CHOOSE($B$4,B10,C10,D10)) -> 0.085
A11: Terminal growth | B11: 0.02 | C11: 0.025 | D11: 0.03 | E11: =IF(ISNUMBER($B$7),$B$7,CHOOSE($B$4,B11,C11,D11)) -> 0.025
A12: Revenue growth, first forecast year | B12: -0.076 | C12: -0.026 | D12: 0.024 | E12: =CHOOSE($B$4,B12,C12,D12) -> -0.026
A13: Operating margin, year 10 | B13: 0.32 | C13: 0.36 | D13: 0.39 | E13: =CHOOSE($B$4,B13,C13,D13) -> 0.36
A14: Tax rate on operating income | B14: 0.17 | C14: 0.17 | D14: 0.17 | E14: =CHOOSE($B$4,B14,C14,D14) -> 0.17
A15: Reinvestment, % of revenue increase | B15: 0.25 | C15: 0.25 | D15: 0.25 | E15: =CHOOSE($B$4,B15,C15,D15) -> 0.25
A17: Single inputs
A18: Starting operating margin (TTM) | B18: 0.35
A19: Gross margin (forecast) | B19: 0.7184
A20: R&D share of operating expense (forecast) | B20: 0.2269
A21: Forecast years | B21: 10
A22: First forecast year, fraction after balance sheet date | B22: 0.5041
A23: Balance sheet date | B23: 46203
A24: Reporting currency per USD (USD) | B24: 1
A25: Base revenue, FY2025 | B25: ='Yearly Model'!P2 -> 9467
A27: Scenario summary
A28: Scenario | B28: Enterprise value | C28: Equity value | D28: NPV / share | E28: Upside
A29: Live | B29: =NPV!B23 -> 50015.921 | C29: =NPV!B26 -> 42643.921 | D29: =NPV!B28 -> 103.19817 | E29: =NPV!B30 -> 0.28933251
A30: 1 | B30: 30792.073 | C30: 23420.073 | D30: 56.676513 | E30: -0.29189764
A31: 2 | B31: 50015.921 | C31: 42643.921 | D31: 103.19817 | E31: 0.28933251
A32: 3 | B32: 85662.818 | C32: 78290.818 | D32: 189.46357 | E32: 1.3671111
A35: NPV / share: discount rate (rows) x terminal growth (columns)
A36: =NPV!B28 -> 103.19817 | B36: 0.015 | C36: 0.02 | D36: 0.025 | E36: 0.03 | F36: 0.035
A37: 0.065 | B37: 138.23102 | C37: 149.66165 | D37: 163.94993 | E37: 182.32059 | F37: 206.81479
A38: 0.075 | B38: 111.74376 | C38: 118.88649 | D38: 127.45776 | E38: 137.93377 | F38: 151.02877
A39: 0.085 | B39: 92.90284 | C39: 97.654533 | D39: 103.19817 | E39: 109.74975 | F39: 117.61164
A40: 0.095 | B40: 78.832917 | C40: 82.140719 | D40: 85.921064 | E40: 90.283001 | F40: 95.371928
A41: 0.105 | B41: 67.937454 | C41: 70.32089 | D41: 73.002256 | E41: 76.041137 | F41: 79.514144
A44: Reviewed revenue growth by year (base case; blank = fade formula)
A45: Fiscal year | B45: 2026 | C45: 2027 | D45: 2028 | E45: 2029 | F45: 2030 | G45: 2031 | H45: 2032 | I45: 2033 | J45: 2034 | K45: 2035
A46: Growth (bear/bull shift by the row-12 gap, fading to 0 by year 10) | B46: -0.026 | C46: 0.02 | D46: 0.04 | E46: 0.05 | F46: 0.05 | G46: 0.045 | H46: 0.04 | I46: 0.035 | J46: 0.03 | K46: 0.025

Sheet NPV
A1: Zoetis Inc: free-cash-flow DCF ($mm)
A3: Fiscal year | B3: ='Yearly Model'!P1 -> 2025 | C3: ='Yearly Model'!Q1 -> 2026 | D3: ='Yearly Model'!R1 -> 2027 | E3: ='Yearly Model'!S1 -> 2028 | F3: ='Yearly Model'!T1 -> 2029 | G3: ='Yearly Model'!U1 -> 2030 | H3: ='Yearly Model'!V1 -> 2031 | I3: ='Yearly Model'!W1 -> 2032 | ... L3: ='Yearly Model'!Z1 -> 2035
A4: Period | B4: Actual | C4: 1 | D4: 2 | E4: 3 | F4: 4 | G4: 5 | H4: 6 | I4: 7 | J4: 8 | K4: 9 | L4: 10
A5: Revenue growth | C5: =IF(ISNUMBER(Assumptions!B$46),Assumptions!B$46+(Assumptions!$E$12-Assumptions!$C$12)*(Assumptions!$B$21-C4)/(Assumptions!$B$21-1),Assumptions!$E$12+(Assumptions!$E$11-Assumptions!$E$12)*(C4-1)/(Assumptions!$B$21-1)) -> -0.026 | D5: =IF(ISNUMBER(Assumptions!C$46),Assumptions!C$46+(Assumptions!$E$12-Assumptions!$C$12)*(Assumptions!$B$21-D4)/(Assumptions!$B$21-1),Assumptions!$E$12+(Assumptions!$E$11-Assumptions!$E$12)*(D4-1)/(Assumptions!$B$21-1)) -> 0.02 | E5: =IF(ISNUMBER(Assumptions!D$46),Assumptions!D$46+(Assumptions!$E$12-Assumptions!$C$12)*(Assumptions!$B$21-E4)/(Assumptions!$B$21-1),Assumptions!$E$12+(Assumptions!$E$11-Assumptions!$E$12)*(E4-1)/(Assumptions!$B$21-1)) -> 0.04 | F5: =IF(ISNUMBER(Assumptions!E$46),Assumptions!E$46+(Assumptions!$E$12-Assumptions!$C$12)*(Assumptions!$B$21-F4)/(Assumptions!$B$21-1),Assumptions!$E$12+(Assumptions!$E$11-Assumptions!$E$12)*(F4-1)/(Assumptions!$B$21-1)) -> 0.05 | G5: =IF(ISNUMBER(Assumptions!F$46),Assumptions!F$46+(Assumptions!$E$12-Assumptions!$C$12)*(Assumptions!$B$21-G4)/(Assumptions!$B$21-1),Assumptions!$E$12+(Assumptions!$E$11-Assumptions!$E$12)*(G4-1)/(Assumptions!$B$21-1)) -> 0.05 | H5: =IF(ISNUMBER(Assumptions!G$46),Assumptions!G$46+(Assumptions!$E$12-Assumptions!$C$12)*(Assumptions!$B$21-H4)/(Assumptions!$B$21-1),Assumptions!$E$12+(Assumptions!$E$11-Assumptions!$E$12)*(H4-1)/(Assumptions!$B$21-1)) -> 0.045 | I5: =IF(ISNUMBER(Assumptions!H$46),Assumptions!H$46+(Assumptions!$E$12-Assumptions!$C$12)*(Assumptions!$B$21-I4)/(Assumptions!$B$21-1),Assumptions!$E$12+(Assumptions!$E$11-Assumptions!$E$12)*(I4-1)/(Assumptions!$B$21-1)) -> 0.04 | J5: =IF(ISNUMBER(Assumptions!I$46),Assumptions!I$46+(Assumptions!$E$12-Assumptions!$C$12)*(Assumptions!$B$21-J4)/(Assumptions!$B$21-1),Assumptions!$E$12+(Assumptions!$E$11-Assumptions!$E$12)*(J4-1)/(Assumptions!$B$21-1)) -> 0.035 | ... L5: =IF(ISNUMBER(Assumptions!K$46),Assumptions!K$46+(Assumptions!$E$12-Assumptions!$C$12)*(Assumptions!$B$21-L4)/(Assumptions!$B$21-1),Assumptions!$E$12+(Assumptions!$E$11-Assumptions!$E$12)*(L4-1)/(Assumptions!$B$21-1)) -> 0.025
A6: Operating margin | B6: =IFERROR(B8/B7,0) -> 0.39347206 | C6: =Assumptions!$B$18+(Assumptions!$E$13-Assumptions!$B$18)*C4/Assumptions!$B$21 -> 0.351 | D6: =Assumptions!$B$18+(Assumptions!$E$13-Assumptions!$B$18)*D4/Assumptions!$B$21 -> 0.352 | E6: =Assumptions!$B$18+(Assumptions!$E$13-Assumptions!$B$18)*E4/Assumptions!$B$21 -> 0.353 | F6: =Assumptions!$B$18+(Assumptions!$E$13-Assumptions!$B$18)*F4/Assumptions!$B$21 -> 0.354 | G6: =Assumptions!$B$18+(Assumptions!$E$13-Assumptions!$B$18)*G4/Assumptions!$B$21 -> 0.355 | H6: =Assumptions!$B$18+(Assumptions!$E$13-Assumptions!$B$18)*H4/Assumptions!$B$21 -> 0.356 | I6: =Assumptions!$B$18+(Assumptions!$E$13-Assumptions!$B$18)*I4/Assumptions!$B$21 -> 0.357 | J6: =Assumptions!$B$18+(Assumptions!$E$13-Assumptions!$B$18)*J4/Assumptions!$B$21 -> 0.358 | ... L6: =Assumptions!$B$18+(Assumptions!$E$13-Assumptions!$B$18)*L4/Assumptions!$B$21 -> 0.36
A7: Revenue | B7: ='Yearly Model'!P2 -> 9467 | C7: ='Yearly Model'!Q2 -> 9220.858 | D7: ='Yearly Model'!R2 -> 9405.2752 | E7: ='Yearly Model'!S2 -> 9781.4862 | F7: ='Yearly Model'!T2 -> 10270.56 | G7: ='Yearly Model'!U2 -> 10784.088 | H7: ='Yearly Model'!V2 -> 11269.372 | I7: ='Yearly Model'!W2 -> 11720.147 | ... L7: ='Yearly Model'!Z2 -> 12806.62
A8: Operating income | B8: ='Yearly Model'!P8 -> 3725 | C8: ='Yearly Model'!Q8 -> 3236.5212 | D8: ='Yearly Model'!R8 -> 3310.6569 | E8: ='Yearly Model'!S8 -> 3452.8646 | F8: ='Yearly Model'!T8 -> 3635.7784 | G8: ='Yearly Model'!U8 -> 3828.3514 | H8: ='Yearly Model'!V8 -> 4011.8966 | I8: ='Yearly Model'!W8 -> 4184.0926 | ... L8: ='Yearly Model'!Z8 -> 4610.3831
A9: Tax on operating income | C9: =MAX(0,C8)*Assumptions!$E$14 -> 550.2086 | D9: =MAX(0,D8)*Assumptions!$E$14 -> 562.81167 | E9: =MAX(0,E8)*Assumptions!$E$14 -> 586.98698 | F9: =MAX(0,F8)*Assumptions!$E$14 -> 618.08233 | G9: =MAX(0,G8)*Assumptions!$E$14 -> 650.81974 | H9: =MAX(0,H8)*Assumptions!$E$14 -> 682.02242 | I9: =MAX(0,I8)*Assumptions!$E$14 -> 711.29574 | J9: =MAX(0,J8)*Assumptions!$E$14 -> 738.25326 | ... L9: =MAX(0,L8)*Assumptions!$E$14 -> 783.76513
A10: NOPAT | C10: =C8-C9 -> 2686.3126 | D10: =D8-D9 -> 2747.8452 | E10: =E8-E9 -> 2865.8776 | F10: =F8-F9 -> 3017.6961 | G10: =G8-G9 -> 3177.5317 | H10: =H8-H9 -> 3329.8742 | I10: =I8-I9 -> 3472.7969 | J10: =J8-J9 -> 3604.413 | ... L10: =L8-L9 -> 3826.618
A11: Reinvestment | C11: =(C7-B7)*Assumptions!$E$15 -> -61.5355 | D11: =(D7-C7)*Assumptions!$E$15 -> 46.10429 | E11: =(E7-D7)*Assumptions!$E$15 -> 94.052752 | F11: =(F7-E7)*Assumptions!$E$15 -> 122.26858 | G11: =(G7-F7)*Assumptions!$E$15 -> 128.38201 | H11: =(H7-G7)*Assumptions!$E$15 -> 121.321 | I11: =(I7-H7)*Assumptions!$E$15 -> 112.69372 | J11: =(J7-I7)*Assumptions!$E$15 -> 102.55129 | ... L11: =(L7-K7)*Assumptions!$E$15 -> 78.089144
A12: Free cash flow | C12: =C10-C11 -> 2747.8481 | D12: =D10-D11 -> 2701.7409 | E12: =E10-E11 -> 2771.8249 | F12: =F10-F11 -> 2895.4275 | G12: =G10-G11 -> 3049.1497 | H12: =H10-H11 -> 3208.5532 | I12: =I10-I11 -> 3360.1031 | J12: =J10-J11 -> 3501.8617 | ... L12: =L10-L11 -> 3748.5288
A13: Year fraction | C13: =Assumptions!$B$22 -> 0.5041 | D13: 1 | E13: 1 | F13: 1 | G13: 1 | H13: 1 | I13: 1 | J13: 1 | K13: 1 | L13: 1
A14: Discount time (mid-period) | C14: =C13/2 -> 0.25205 | D14: =C14+C13/2+D13/2 -> 1.0041 | E14: =D14+D13/2+E13/2 -> 2.0041 | F14: =E14+E13/2+F13/2 -> 3.0041 | G14: =F14+F13/2+G13/2 -> 4.0041 | H14: =G14+G13/2+H13/2 -> 5.0041 | I14: =H14+H13/2+I13/2 -> 6.0041 | J14: =I14+I13/2+J13/2 -> 7.0041 | K14: =J14+J13/2+K13/2 -> 8.0041 | L14: =K14+K13/2+L13/2 -> 9.0041
A15: Discount factor | C15: =1/(1+Assumptions!$E$10)^C14 -> 0.97964773 | D15: =1/(1+Assumptions!$E$10)^D14 -> 0.92135076 | E15: =1/(1+Assumptions!$E$10)^E14 -> 0.84917121 | F15: =1/(1+Assumptions!$E$10)^F14 -> 0.78264628 | G15: =1/(1+Assumptions!$E$10)^G14 -> 0.72133297 | H15: =1/(1+Assumptions!$E$10)^H14 -> 0.66482302 | I15: =1/(1+Assumptions!$E$10)^I14 -> 0.61274011 | J15: =1/(1+Assumptions!$E$10)^J14 -> 0.56473743 | ... L15: =1/(1+Assumptions!$E$10)^L14 -> 0.47971919
A16: PV of free cash flow | C16: =C12*C13*C15 -> 1356.9984 | D16: =D12*D13*D15 -> 2489.251 | E16: =E12*E13*E15 -> 2353.7539 | F16: =F12*F13*F15 -> 2266.0956 | G16: =G12*G13*G15 -> 2199.4522 | H16: =H12*H13*H15 -> 2133.12 | I16: =I12*I13*I15 -> 2058.87 | J16: =J12*J13*J15 -> 1977.6323 | ... L16: =L12*L13*L15 -> 1798.2412
A19: PV of forecast free cash flow | B19: =SUM(C16:L16) -> 20523.821
A20: Terminal free cash flow (year 11) | B20: =L10*(1+Assumptions!$E$11)-L7*Assumptions!$E$11*Assumptions!$E$15 -> 3842.242
A21: Terminal value | B21: =B20/(Assumptions!$E$10-Assumptions!$E$11) -> 64037.367
A22: PV of terminal value | B22: =B21/(1+Assumptions!$E$10)^(L14+0.5) -> 29492.1
A23: Enterprise value | B23: =B19+B22 -> 50015.921
A24: Cash & investments | B24: =Main!C7 -> 1676
A25: Debt | B25: =Main!C8 -> 9048
A26: Equity value | B26: =B23+B24-B25 -> 42643.921
A27: Shares (mm) | B27: =Main!C4 -> 413.2236
A28: NPV / share | B28: =B26/B27 -> 103.19817
A29: Price | B29: =Main!C3 -> 80.04
A30: Upside | B30: =B28/B29-1 -> 0.28933251
A31: Terminal value, % of EV | B31: =IFERROR(B22/B23,0) -> 0.58965424

Sheet Options
A1: ZTS: options vs. the reviewed DCF (per contract = 100 shares)
A2: Market prices are Cboe delayed quotes; blue = input. Probabilities are risk-neutral (lognormal at ATM IV).
A3: Inputs
A4: Spot (close 2026-10-20) | B4: 80.04
A5: Pricing date | B5: 46315
A6: Near expiry | B6: 46402
A7: Long expiry | B7: 46773
A8: Years to near expiry | B8: =(B6-B5)/365 -> 0.23835616
A9: Years to long expiry | B9: =(B7-B5)/365 -> 1.2547945
A10: Risk-free rate | B10: 0.04
A11: Dividend yield | B11: 0.025
A12: ATM implied volatility, near | B12: 0.3796
A13: ATM implied volatility, long | B13: 0.3901
A14: Contract multiplier | B14: 100
A16: Market expectations, near expiry
A17: ATM strike | B17: 80
A18: ATM call (mid) | B18: 5.9
A19: ATM put (mid) | B19: 5.9
A20: Straddle, % of spot (expected move) | B20: =(B18+B19)/B4 -> 0.14742629
A21: Expected range, low | B21: =B4*(1-B20) -> 68.24
A22: Expected range, high | B22: =B4*(1+B20) -> 91.84
A23: 1-SD move by long expiry (ATM IV) | B23: =B13*SQRT(B9) -> 0.4369807
A25: Model vs. market at the long expiry
A26: Case | B26: Value / share | C26: vs. spot | D26: Annual return needed | E26: Market P(above)
A27: Forward price at long expiry | B27: =B4*EXP((B10-B11)*B9) -> 81.560773
A28: Bear | B28: =Assumptions!D30 -> 56.676513 | C28: =B28/$B$4-1 -> -0.29189764 | D28: =IF(B28>0,(B28/$B$4)^(1/$B$9)-1,"") -> -0.24048727 | E28: =IF(B28>0,NORMSDIST((LN($B$27/B28)-$B$13^2*$B$9/2)/($B$13*SQRT($B$9))),1) -> 0.73054831
A29: Base (reviewed) | B29: =Assumptions!D31 -> 103.19817 | C29: =B29/$B$4-1 -> 0.28933251 | D29: =IF(B29>0,(B29/$B$4)^(1/$B$9)-1,"") -> 0.22448815 | E29: =IF(B29>0,NORMSDIST((LN($B$27/B29)-$B$13^2*$B$9/2)/($B$13*SQRT($B$9))),1) -> 0.22453562
A30: Bull | B30: =Assumptions!D32 -> 189.46357 | C30: =B30/$B$4-1 -> 1.3671111 | D30: =IF(B30>0,(B30/$B$4)^(1/$B$9)-1,"") -> 0.98715163 | E30: =IF(B30>0,NORMSDIST((LN($B$27/B30)-$B$13^2*$B$9/2)/($B$13*SQRT($B$9))),1) -> 0.015885091
A32: Chain, 2028-01-21 expiry
A33: Strike | B33: Call bid | C33: Call ask | D33: Call IV | E33: Put bid | F33: Put ask | G33: Put IV | H33: Call OI | I33: Put OI
A34: 55 | B34: 27.7 | C34: 30.5 | D34: 0.3993 | E34: 2.45 | F34: 3.7 | G34: 0.4171 | H34: 122 | I34: 89
A35: 65 | B35: 21.2 | C35: 24.3 | D35: 0.4066 | E35: 5.1 | F35: 6.6 | G35: 0.4047 | H35: 90 | I35: 149
A36: 70 | B36: 18.3 | C36: 20.4 | D36: 0.3854 | E36: 7.1 | F36: 8.3 | G36: 0.4004 | H36: 318 | I36: 544
A37: 75 | B37: 16.8 | C37: 17.7 | D37: 0.3998 | E37: 9 | F37: 10 | G37: 0.3854 | H37: 36774 | I37: 798
A38: 80 | B38: 14.4 | C38: 15.4 | D38: 0.3959 | E38: 11.5 | F38: 12.5 | G38: 0.3842 | H38: 520 | I38: 416
A39: 85 | B39: 12.2 | C39: 13.3 | D39: 0.3907 | E39: 14.3 | F39: 17.1 | G39: 0.3815 | H39: 128 | I39: 317
A40: 90 | B40: 9.6 | C40: 12.2 | D40: 0.3918 | E40: 17.5 | F40: 18.8 | G40: 0.3824 | H40: 982 | I40: 355
A41: 95 | B41: 9.2 | C41: 9.7 | D41: 0.3893 | E41: 20.7 | F41: 22.6 | G41: 0.3936 | H41: 249 | I41: 100
A42: 100 | B42: 7.6 | C42: 8.3 | D42: 0.3838 | E42: 24.3 | F42: 26.1 | G42: 0.3919 | H42: 962 | I42: 304
A43: 105 | B43: 6.4 | C43: 7.4 | D43: 0.382 | E43: 28 | F43: 30 | G43: 0.3914 | H43: 900 | I43: 44
...
